Workbook
Name FS_MODEL_ID: 'Institutional Surface'!$C$4
Name FS_DOMAIN: 'Institutional Surface'!$C$5
Name FS_MATURITY: 'Institutional Surface'!$C$6

Sheet Cover
B2: [TOKEN] — Crypto / Digital Asset Model
B4: Protocol: | C4: [fill in]
B5: Chain / L1-L2: | C5: [fill in]
B6: Last refreshed: | C6: [date]
B7: Next unlock/emission event: | C7: [date]
B8: Refresh cadence: | C8: Weekly (daily around unlocks)

Sheet Institutional Surface
B2: Crypto & Digital Assets — Institutional Decision Surface
B4: Model ID | C4: 16
B5: Domain | C5: Crypto & Digital Assets
B6: Declared maturity | C6: M2
B7: Canonical builder | C7: tools/builders/build_crypto_release.py
B8: Decision arena | C8: protocol treasury, investment committee, market making, risk and custody
B9: Committee artifact | C9: token economics and treasury risk pack
B10: Operating cadence | C10: intraday liquidity; daily treasury; governance-event driven
B12: Key decision outputs
B13: # | C13: Requirement | D13: Owner | E13: Evidence / location | F13: Status
B14: 1 | C14: circulating and fully diluted supply | F14: OPEN
B15: 2 | C15: unlock and sell-pressure schedule | F15: OPEN
B16: 3 | C16: staking yield net of dilution | F16: OPEN
B17: 4 | C17: base, downside and break-even outputs | F17: OPEN
B18: 5 | C18: liquidity / funding requirement and binding constraint | F18: OPEN
B20: Insider questions
B21: # | C21: Requirement | D21: Owner | E21: Evidence / location | F21: Status
B22: 1 | C22: Who can actually sell at each unlock? | F22: OPEN
B23: 2 | C23: What yield remains after dilution? | F23: OPEN
B24: 3 | C24: Which wallets and bridges are critical dependencies? | F24: OPEN
B25: 4 | C25: Which assumption is owner-approved versus modeler judgement? | F25: OPEN
B26: 5 | C26: What fails first and who must act? | F26: OPEN
B28: Scenario families
B29: # | C29: Requirement | D29: Owner | E29: Evidence / location | F29: Status
B30: 1 | C30: unlock cliff | F30: OPEN
B31: 2 | C31: validator / staking shock | F31: OPEN
B32: 3 | C32: depeg or bridge failure | F32: OPEN
B33: 4 | C33: data freshness / source failure | F33: OPEN
B34: 5 | C34: combined severe-but-plausible downside | F34: OPEN
B36: Primary diligence documents
B37: # | C37: Requirement | D37: Owner | E37: Evidence / location | F37: Status
B38: 1 | C38: token allocation and vesting contracts | F38: OPEN
B39: 2 | C39: governance proposals | F39: OPEN
B40: 3 | C40: custody and staking agreements | F40: OPEN
B41: 4 | C41: approved model card and assumption register | F41: OPEN
B42: 5 | C42: independent validation and challenge record | F42: OPEN
B44: Challenge tests
B45: # | C45: Requirement | D45: Owner | E45: Evidence / location | F45: Status
B46: 1 | C46: supply roll-forward conserves | F46: OPEN
B47: 2 | C47: staking yield separates real yield and dilution | F47: OPEN
...

Sheet Challenge Log
B2: Independent Challenge, Override and Closure Log
B4: Date | C4: Reviewer | D4: Challenge | E4: Owner response | F4: Evidence | G4: Impact | H4: Status | I4: Closure
D5: supply roll-forward conserves | H5: OPEN
D6: staking yield separates real yield and dilution | H6: OPEN
D7: treasury wallets reconcile | H7: OPEN
D8: source-to-model lineage is reproducible | H8: OPEN
D9: units, signs, dates and legal definitions reconcile | H9: OPEN

Sheet Lineage Map
B2: Source, Transformation, Ownership and Refresh Map
B4: Source class | C4: Cadence | D4: Control | E4: System / provider | F4: As-of | G4: Owner | H4: Transform | I4: Downstream | J4: Status
B5: on-chain supply | C5: block/daily | D5: contract and address provenance | J5: TO MAP
B6: exchange liquidity | C6: intraday/daily | D6: venue and pair normalization | J6: TO MAP
B7: model governance evidence | C7: per release | D7: version, reviewer, sign-off and change log | J7: TO MAP
B8: decision-use snapshot | C8: per decision | D8: immutable as-of date and source receipt | J8: TO MAP

Sheet Tokenomics
B2: Tokenomics — Supply Schedule
B4: Allocation | C4: Tokens | D4: % of max supply | E4: Unlock start | F4: Vesting notes
B5: Public / community | C5: 0 | D5: =IFERROR(C5/$C$10,"-") | E5: [date] | F5: [cliff / linear vesting terms]
B6: Team & advisors | C6: 0 | D6: =IFERROR(C6/$C$10,"-") | E6: [date] | F6: [cliff / linear vesting terms]
B7: Investors (seed/private) | C7: 0 | D7: =IFERROR(C7/$C$10,"-") | E7: [date] | F7: [cliff / linear vesting terms]
B8: Treasury / foundation | C8: 0 | D8: =IFERROR(C8/$C$10,"-") | E8: [date] | F8: [cliff / linear vesting terms]
B9: Ecosystem incentives / staking rewards | C9: 0 | D9: =IFERROR(C9/$C$10,"-") | E9: [date] | F9: [cliff / linear vesting terms]
B10: Max supply | C10: =SUM(C5:C9)
B12: Circulating supply (today) | C12: 0
B13: Circulating / max supply % | C13: =IFERROR(C12/C10,"-")

Sheet Supply Rollforward & Unlocks
B2: Token Supply Conservation, Unlocks, and Dilution
B3: Active scenario | C3: Base
B4: Metric | C4: Base | D4: Downside | E4: Active | F4: Owner / interpretation
B5: Beginning total supply | C5: 1000 | D5: 1000 | E5: =IF($C$3="Downside",D5,C5) | F5: opening on-chain total supply
B6: Protocol issuance | C6: 20 | D6: 50 | E6: =IF($C$3="Downside",D6,C6) | F6: newly minted non-staking issuance
B7: Scheduled token unlocks | C7: 30 | D7: 250 | E7: =IF($C$3="Downside",D7,C7) | F7: vested tokens becoming transferable
B8: Staking / validator rewards | C8: 10 | D8: 40 | E8: =IF($C$3="Downside",D8,C8) | F8: inflationary security rewards
B9: Burns | C9: 5 | D9: 0 | E9: =IF($C$3="Downside",D9,C9) | F9: verifiably destroyed supply
B10: Locked / non-circulating supply | C10: 300 | D10: 100 | E10: =IF($C$3="Downside",D10,C10) | F10: contractually or technically restricted
B11: Maximum one-period unlock rate | C11: 0.1 | D11: 0.1 | E11: =IF($C$3="Downside",D11,C11) | F11: unlocks / beginning supply
B12: Maximum annualized staking dilution | C12: 0.08 | D12: 0.08 | E12: =IF($C$3="Downside",D12,C12) | F12: staking rewards / pre-reward circulating supply
B15: Derived outputs
B16: Ending total supply | E16: =E5+E6+E7+E8-E9
B17: Circulating supply | E17: =E16-E10
B18: Unlock rate | E18: =IFERROR(E7/E5,0)
B19: Staking dilution | E19: =IFERROR(E8/MAX(E17-E8,0.000001),0)
B20: Locked supply % | E20: =IFERROR(E10/E16,0)
B21: Net supply growth | E21: =IFERROR(E16/E5-1,0)
B23: Unlocks are a transferability event, not new issuance. They still create float, liquidity, governance, and price-pressure risk and must remain separate from minting.

Sheet Valuation
B2: On-Chain Valuation Multiples
B4: Inputs
B5: Token price | C5: 0
B6: Total value locked (TVL, $) | C6: 0
B7: Annualized protocol revenue/fees ($) | C7: 0
B8: Daily transaction volume ($, trailing 30d avg) | C8: 0
B10: Outputs
B11: Market cap (circulating) | C11: =C5*Tokenomics!C12
B12: Fully diluted valuation (FDV) | C12: =C5*Tokenomics!C10
B13: Market cap / TVL | C13: =IFERROR(C11/C6,"-")
B14: FDV / TVL | C14: =IFERROR(C12/C6,"-")
B15: P/S equivalent (Mkt cap / annualized revenue) | C15: =IFERROR(C11/C7,"-")
B16: Network value / annualized transaction volume | C16: =IFERROR(C11/(C8*365),"-") | D16: Market cap divided by trailing daily transaction volume annualized; this is a valuation-to-usage ratio, not transaction velocity.

Sheet Treasury & Runway
B2: Treasury Composition, Operating Runway, and Obligations
B4: Metric | C4: Base | D4: Downside | E4: Control / interpretation
B5: Cash and insured deposits | C5: 30 | D5: 10 | E5: unrestricted operating cash
B6: High-quality stablecoins | C6: 10 | D6: 3 | E6: haircut for issuer, reserve, and redemption risk
B7: Native / treasury token value | C7: 80 | D7: 20 | E7: mark separately from liquid operating resources
B8: Other liquid digital assets | C8: 10 | D8: 2 | E8: haircut for volatility and market depth
B9: Restricted / earmarked assets | C9: 20 | D9: 20 | E9: not available for general operations
B10: Monthly operating burn | C10: 5 | D10: 7 | E10: cash operating outflow
B11: Thirty-day contractual obligations | C11: 20 | D11: 25 | E11: payroll, vendors, debt, grants, and settlement
B12: Minimum cash runway (months) | C12: 18 | D12: 18 | E12: approved warning threshold
B13: Minimum liquid coverage | C13: 1.25 | D13: 1.25 | E13: liquid resources / thirty-day obligations
B14: Stablecoin haircut | C14: 0.15 | D14: 0.35 | E14: issuer and redemption stress
B15: Other digital-asset haircut | C15: 0.35 | D15: 0.65 | E15: market-depth and volatility stress
B18: Haircut-adjusted liquid resources | C18: =C5+C6*(1-C14)+C8*(1-C15) | D18: =D5+D6*(1-D14)+D8*(1-D15)
B19: Operating runway (months) | C19: =IFERROR(C18/C10,0) | D19: =IFERROR(D18/D10,0)
B20: Thirty-day liquid coverage | C20: =IFERROR(C18/C11,0) | D20: =IFERROR(D18/D11,0)
B21: Treasury-token concentration | C21: =IFERROR(C7/SUM(C5:C9),0) | D21: =IFERROR(D7/SUM(D5:D9),0)
B22: Downside status | C22: =IF(AND(D19>=D12,D20>=D13),"PASS","BREACH")
B24: Native-token marks may support long-horizon optionality but are excluded from operating runway unless monetization capacity and governance authority are documented.

Sheet Custody & Liquidity
B2: Custody, Key Management, Counterparty, and Market-Liquidity Controls
B4: Control / metric | C4: Input | D4: Status | E4: Evidence / action
B5: Material wallets using approved multi-party authorization (%) | C5: 1 | D5: =IF(C5=1,"PASS","BREACH") | E5: retain signer policy, quorum, key rotation, and recovery evidence
B6: Private-key recovery exercise completed within policy period | C6: 1 | D6: =IF(C6=1,"PASS","BREACH") | E6: 1=yes; retain dated recovery test
B7: Assets held with unapproved custodians / exchanges (%) | C7: 0 | D7: =IF(C7=0,"PASS","BREACH") | E7: separate custody, venue, settlement, and rehypothecation exposure
B8: Largest custodian / venue concentration (%) | C8: 0.25 | D8: =IF(C8<=0.40,"PASS","REVIEW") | E8: review legal entity, jurisdiction, segregation, and withdrawal capacity
B9: Thirty-day unlocks / trailing daily market volume | C9: 5 | D9: =IF(C9<=10,"PASS",IF(C9<=25,"REVIEW","BREACH")) | E9: days of volume before haircut, participation, and price impact
B10: Smart-contract / bridge concentration (%) | C10: 0.2 | D10: =IF(C10<=0.35,"PASS","REVIEW") | E10: measure assets dependent on a single contract, oracle, bridge, or admin key
B11: Stablecoin issuer concentration (%) | C11: 0.3 | D11: =IF(C11<=0.50,"PASS","REVIEW") | E11: look through issuer, reserve, banking, and redemption dependencies
B12: Critical incident remediation overdue | C12: 0 | D12: =IF(C12=0,"PASS","BREACH") | E12: retain owner, severity, containment, remediation, and verification
B14: Control completion must be supported by retained operational evidence. This sheet is not a representation of regulatory compliance or asset safety.

Sheet Decision & Checks
B2: Crypto / Digital Asset Decision Dashboard and Independent Checks
B4: Check / decision | C4: Metric | D4: Status | E4: Interpretation / action
B5: Supply-conservation residual | C5: ='Supply Rollforward & Unlocks'!E16-('Supply Rollforward & Unlocks'!E5+'Supply Rollforward & Unlocks'!E6+'Supply Rollforward & Unlocks'!E7+'Supply Rollforward & Unlocks'!E8-'Supply Rollforward & Unlocks'!E9) | D5: =IF(ABS(C5)<0.000001,"PASS","FAIL") | E5: Total supply must reconcile across issuance, unlocks, rewards, and burns.
B6: Locked-supply bound | C6: ='Supply Rollforward & Unlocks'!E16-'Supply Rollforward & Unlocks'!E10 | D6: =IF(C6>=0,"PASS","FAIL") | E6: Locked supply may not exceed ending total supply.
B7: Unlock rate | C7: ='Supply Rollforward & Unlocks'!E18 | D7: =IF(C7<='Supply Rollforward & Unlocks'!E11,"PASS","BREACH") | E7: Escalate unlock cliffs and market-liquidity mismatch.
B8: Staking dilution | C8: ='Supply Rollforward & Unlocks'!E19 | D8: =IF(C8<='Supply Rollforward & Unlocks'!E12,"PASS","REVIEW") | E8: Inflationary staking yield is not equivalent to real economic yield.
B9: Net staking yield | C9: ='Staking Yield'!C14 | D9: =IF(ISNUMBER(C9),IF(C9>=0,"PASS","REVIEW"),"REVIEW") | E9: Separate fee-funded yield from dilution and price risk.
B10: Downside operating runway | C10: ='Treasury & Runway'!D19 | D10: =IF(C10>='Treasury & Runway'!D12,"PASS","BREACH") | E10: Treasury-token marks and restricted funds do not fund payroll or obligations by themselves.
B11: Downside liquid coverage | C11: ='Treasury & Runway'!D20 | D11: =IF(C11>='Treasury & Runway'!D13,"PASS","BREACH") | E11: Haircut-adjusted liquid resources must cover near-term obligations.
B12: Custody / liquidity exceptions | C12: =COUNTIF('Custody & Liquidity'!D5:D12,"<>PASS") | D12: =IF(C12=0,"PASS","REVIEW") | E12: Valuation and tokenomics do not override unresolved key, venue, bridge, or incident risk.
B13: FDV / circulating market cap | C13: =IFERROR(Valuation!C12/Valuation!C11,"-") | D13: =IF(ISNUMBER(C13),IF(C13<=2,"PASS",IF(C13<=5,"REVIEW","BREACH")),"REVIEW") | E13: Large FDV overhang requires explicit unlock, liquidity, and incentive analysis.
B15: Overall model status | C15: =IF(COUNTIF(D5:D13,"FAIL")+COUNTIF(D5:D13,"BREACH")>0,"BREACH",IF(COUNTIF(D5:D13,"REVIEW")>0,"REVIEW","PASS"))
B17: Primary decision outputs
B18: Ending total supply | C18: ='Supply Rollforward & Unlocks'!E16
B19: Circulating supply | C19: ='Supply Rollforward & Unlocks'!E17
B20: Unlock rate | C20: ='Supply Rollforward & Unlocks'!E18
B21: Circulating market cap | C21: =Valuation!C11
B22: Fully diluted valuation | C22: =Valuation!C12
B23: Net staking yield | C23: ='Staking Yield'!C14
B24: Downside runway | C24: ='Treasury & Runway'!D19
B25: Downside liquid coverage | C25: ='Treasury & Runway'!D20

Sheet Staking Yield
B2: Staking / Yield Model
B4: Inputs
B5: % of supply staked | C5: 0
B6: Annual token emissions (new supply, tokens) | C6: 0
B7: Protocol fee revenue distributed to stakers ($) | C7: 0
B8: Token price (for $ yield calc) | C8: 0
B10: Outputs
B11: Tokens staked | C11: =C5*Tokenomics!C12
B12: Inflationary yield (emissions / staked) | C12: =IFERROR(C6/C11,"-")
B13: Real yield (fee revenue / staked value) | C13: =IFERROR(C7/(C11*C8),"-")
B14: Net staking yield (real - inflation dilution) | C14: =IFERROR(C13-C12,"-") | D14: Negative = staking rewards are pure dilution, not real cash flow

Sheet Comparable Protocols
B2: Comparable Protocols
B4: Protocol | C4: Mkt cap | D4: FDV | E4: TVL | F4: Daily volume | G4: Mkt/TVL | H4: FDV/TVL | I4: NVT
B5: This protocol | C5: =Valuation!C11 | D5: =Valuation!C12 | E5: =Valuation!C6 | F5: =Valuation!C8 | G5: =IFERROR(C5/E5,"-") | H5: =IFERROR(D5/E5,"-") | I5: =IFERROR(C5/(F5*365),"-")
B6: [fill in] | C6: 0 | D6: 0 | E6: 0 | F6: 0 | G6: =IFERROR(C6/E6,"-") | H6: =IFERROR(D6/E6,"-") | I6: =IFERROR(C6/(F6*365),"-")
B7: [fill in] | C7: 0 | D7: 0 | E7: 0 | F7: 0 | G7: =IFERROR(C7/E7,"-") | H7: =IFERROR(D7/E7,"-") | I7: =IFERROR(C7/(F7*365),"-")
B8: [fill in] | C8: 0 | D8: 0 | E8: 0 | F8: 0 | G8: =IFERROR(C8/E8,"-") | H8: =IFERROR(D8/E8,"-") | I8: =IFERROR(C8/(F8*365),"-")
B9: [fill in] | C9: 0 | D9: 0 | E9: 0 | F9: 0 | G9: =IFERROR(C9/E9,"-") | H9: =IFERROR(D9/E9,"-") | I9: =IFERROR(C9/(F9*365),"-")
B10: [fill in] | C10: 0 | D10: 0 | E10: 0 | F10: 0 | G10: =IFERROR(C10/E10,"-") | H10: =IFERROR(D10/E10,"-") | I10: =IFERROR(C10/(F10*365),"-")
B11: [fill in] | C11: 0 | D11: 0 | E11: 0 | F11: 0 | G11: =IFERROR(C11/E11,"-") | H11: =IFERROR(D11/E11,"-") | I11: =IFERROR(C11/(F11*365),"-")

Sheet Supply Emission Schedule
B2: Forward Supply Emission & Dilution
B4: Annual emission rate (% of max supply issued/yr) | C4: 0.05 | D4: Simplified: assumes a flat schedule. Real unlocks are usually cliff + linear per allocation — treat this as a planning approximation, not a substitute for the actual unlock table.
C6: Period 0 | D6: Period 1 | E6: Period 2 | F6: Period 3 | G6: Period 4
B7: Circulating supply | C7: =Tokenomics!C12 | D7: =MIN(Tokenomics!$C$10,C7+Tokenomics!$C$10*$C$4) | E7: =MIN(Tokenomics!$C$10,D7+Tokenomics!$C$10*$C$4) | F7: =MIN(Tokenomics!$C$10,E7+Tokenomics!$C$10*$C$4) | G7: =MIN(Tokenomics!$C$10,F7+Tokenomics!$C$10*$C$4)
B8: Cumulative dilution vs. today | C8: =IFERROR(1-$C$7/C7,"-") | D8: =IFERROR(1-$C$7/D7,"-") | E8: =IFERROR(1-$C$7/E7,"-") | F8: =IFERROR(1-$C$7/F7,"-") | G8: =IFERROR(1-$C$7/G7,"-")
B9: Implied mkt cap at today's price (if price held flat) | C9: =Valuation!$C$5*C7 | D9: =Valuation!$C$5*D7 | E9: =Valuation!$C$5*E7 | F9: =Valuation!$C$5*F7 | G9: =Valuation!$C$5*G7
B10: A holder who doesn't add to their position loses this much ownership share to new issuance over time -- the price needs to grow faster than dilution just to keep the position's dollar value from falling.

Sheet RefreshLog
B2: Refresh Log
B4: Date | C4: Trigger | D4: What changed | E4: Reviewer notes | F4: Next check
