Workbook
Name FS_MODEL_ID: 'Institutional Surface'!$C$4
Name FS_DOMAIN: 'Institutional Surface'!$C$5
Name FS_MATURITY: 'Institutional Surface'!$C$6

Sheet Cover
B2: [TICKER] — Company Name
B4: Sector: | C4: [fill in]
B5: Coverage started: | C5: [date]
B6: Last refreshed: | C6: [date]
B7: Next earnings date: | C7: [date]
B8: Refresh cadence: | C8: Weekly
B10: Thesis (2-3 sentences):
B11: [fill in]
B16: COLOR LEGEND
B17: Blue text | C17: Hardcoded input / scenario lever — edit freely
B18: Black text | C18: Formula — do not overwrite
B19: Green text | C19: Link to another sheet in this workbook
B20: Yellow fill | C20: Key assumption — review every refresh

Sheet Institutional Surface
B2: Investment Banking — Institutional Decision Surface
B4: Model ID | C4: 01
B5: Domain | C5: Investment Banking
B6: Declared maturity | C6: M2
B7: Canonical builder | C7: tools/builders/build_investment_banking_release.py
B8: Decision arena | C8: board, special committee, fairness committee and sell-side deal team
B9: Committee artifact | C9: board / fairness-book output pack
B10: Operating cadence | C10: live deal: daily; watchlist: weekly
B12: Key decision outputs
B13: # | C13: Requirement | D13: Owner | E13: Evidence / location | F13: Status
B14: 1 | C14: enterprise and equity value bridge | F14: OPEN
B15: 2 | C15: DCF and WACC range | F15: OPEN
B16: 3 | C16: trading and transaction multiple dispersion | F16: OPEN
B17: 4 | C17: base, downside and break-even outputs | F17: OPEN
B18: 5 | C18: liquidity / funding requirement and binding constraint | F18: OPEN
B20: Insider questions
B21: # | C21: Requirement | D21: Owner | E21: Evidence / location | F21: Status
B22: 1 | C22: What is the unaffected date and why? | F22: OPEN
B23: 2 | C23: Which bidders can actually finance at the headline price? | F23: OPEN
B24: 3 | C24: Where do QoE adjustments flow through EBITDA and debt capacity? | F24: OPEN
B25: 4 | C25: Which assumption is owner-approved versus modeler judgement? | F25: OPEN
B26: 5 | C26: What fails first and who must act? | F26: OPEN
B28: Scenario families
B29: # | C29: Requirement | D29: Owner | E29: Evidence / location | F29: Status
B30: 1 | C30: revenue/margin miss | F30: OPEN
B31: 2 | C31: WACC and terminal-value expansion | F31: OPEN
B32: 3 | C32: multiple compression | F32: OPEN
B33: 4 | C33: data freshness / source failure | F33: OPEN
B34: 5 | C34: combined severe-but-plausible downside | F34: OPEN
B36: Primary diligence documents
B37: # | C37: Requirement | D37: Owner | E37: Evidence / location | F37: Status
B38: 1 | C38: quality of earnings | F38: OPEN
B39: 2 | C39: management projections | F39: OPEN
B40: 3 | C40: CIM and data-room index | F40: OPEN
B41: 4 | C41: approved model card and assumption register | F41: OPEN
B42: 5 | C42: independent validation and challenge record | F42: OPEN
B44: Challenge tests
B45: # | C45: Requirement | D45: Owner | E45: Evidence / location | F45: Status
B46: 1 | C46: EV-to-equity bridge reconciles | F46: OPEN
B47: 2 | C47: DCF terminal value share bounded | F47: OPEN
...

Sheet Challenge Log
B2: Independent Challenge, Override and Closure Log
B4: Date | C4: Reviewer | D4: Challenge | E4: Owner response | F4: Evidence | G4: Impact | H4: Status | I4: Closure
D5: EV-to-equity bridge reconciles | H5: OPEN
D6: DCF terminal value share bounded | H6: OPEN
D7: comps screening is reproducible | H7: OPEN
D8: source-to-model lineage is reproducible | H8: OPEN
D9: units, signs, dates and legal definitions reconcile | H9: OPEN

Sheet Lineage Map
B2: Source, Transformation, Ownership and Refresh Map
B4: Source class | C4: Cadence | D4: Control | E4: System / provider | F4: As-of | G4: Owner | H4: Transform | I4: Downstream | J4: Status
B5: company reporting | C5: monthly/quarterly | D5: tie to filed or management financials | J5: TO MAP
B6: market data | C6: daily | D6: timestamp and security identifier | J6: TO MAP
B7: model governance evidence | C7: per release | D7: version, reviewer, sign-off and change log | J7: TO MAP
B8: decision-use snapshot | C8: per decision | D8: immutable as-of date and source receipt | J8: TO MAP

Sheet Assumptions
B2: Assumptions
B4: Driver | C4: FY1 | D4: FY2 | E4: FY3 | F4: FY4 | G4: FY5 | H4: Source / notes
B5: Revenue growth % | C5: 0 | D5: 0 | E5: 0 | F5: 0 | G5: 0 | H5: Source: [10-K/10-Q cite or user estimate]
B6: Gross margin % | C6: 0 | D6: 0 | E6: 0 | F6: 0 | G6: 0 | H6: Source: [10-K/10-Q cite or user estimate]
B7: Opex % of revenue | C7: 0 | D7: 0 | E7: 0 | F7: 0 | G7: 0 | H7: Source: [10-K/10-Q cite or user estimate]
B8: Tax rate % | C8: 0 | D8: 0 | E8: 0 | F8: 0 | G8: 0 | H8: Source: [10-K/10-Q cite or user estimate]
B9: D&A % of capex | C9: 0 | D9: 0 | E9: 0 | F9: 0 | G9: 0 | H9: Source: [10-K/10-Q cite or user estimate]
B10: Capex % of revenue | C10: 0 | D10: 0 | E10: 0 | F10: 0 | G10: 0 | H10: Source: [10-K/10-Q cite or user estimate]
B11: NWC % of revenue chg | C11: 0 | D11: 0 | E11: 0 | F11: 0 | G11: 0 | H11: Source: [10-K/10-Q cite or user estimate]
B12: Shares outstanding (mm) | C12: 0 | D12: 0 | E12: 0 | F12: 0 | G12: 0 | H12: Source: [10-K/10-Q cite or user estimate]
B13: WACC % | C13: 0 | D13: 0 | E13: 0 | F13: 0 | G13: 0 | H13: Source: [10-K/10-Q cite or user estimate]
B14: Terminal growth % | C14: 0 | D14: 0 | E14: 0 | F14: 0 | G14: 0 | H14: Source: [10-K/10-Q cite or user estimate]

Sheet IS
B2: Income Statement ($mm)
B4: Line item | C4: FY-2A | D4: FY-1A | E4: FY0A | F4: FY1E | G4: FY2E | H4: FY3E | I4: FY4E
B5: Revenue | F5: =E5*(1+Assumptions!C5) | G5: =F5*(1+Assumptions!D5) | H5: =G5*(1+Assumptions!E5) | I5: =H5*(1+Assumptions!F5)
B6: Revenue growth % | D6: =IFERROR(D5/C5-1,"-") | E6: =IFERROR(E5/D5-1,"-") | F6: =IFERROR(F5/E5-1,"-") | G6: =IFERROR(G5/F5-1,"-") | H6: =IFERROR(H5/G5-1,"-") | I6: =IFERROR(I5/H5-1,"-")
B7: COGS | F7: =F5*(1-Assumptions!C6) | G7: =G5*(1-Assumptions!D6) | H7: =H5*(1-Assumptions!E6) | I7: =I5*(1-Assumptions!F6)
B8: Gross profit | C8: =C5-C7 | D8: =D5-D7 | E8: =E5-E7 | F8: =F5-F7 | G8: =G5-G7 | H8: =H5-H7 | I8: =I5-I7
B9: Gross margin % | C9: =IFERROR(C8/C5,"-") | D9: =IFERROR(D8/D5,"-") | E9: =IFERROR(E8/E5,"-") | F9: =IFERROR(F8/F5,"-") | G9: =IFERROR(G8/G5,"-") | H9: =IFERROR(H8/H5,"-") | I9: =IFERROR(I8/I5,"-")
B10: Opex | F10: =F5*Assumptions!C7 | G10: =G5*Assumptions!D7 | H10: =H5*Assumptions!E7 | I10: =I5*Assumptions!F7
B11: EBITDA | C11: =C8-C10 | D11: =D8-D10 | E11: =E8-E10 | F11: =F8-F10 | G11: =G8-G10 | H11: =H8-H10 | I11: =I8-I10
B12: EBITDA margin % | C12: =IFERROR(C11/C5,"-") | D12: =IFERROR(D11/D5,"-") | E12: =IFERROR(E11/E5,"-") | F12: =IFERROR(F11/F5,"-") | G12: =IFERROR(G11/G5,"-") | H12: =IFERROR(H11/H5,"-") | I12: =IFERROR(I11/I5,"-")
B13: D&A | F13: =F5*Assumptions!C10*Assumptions!C9 | G13: =G5*Assumptions!D10*Assumptions!D9 | H13: =H5*Assumptions!E10*Assumptions!E9 | I13: =I5*Assumptions!F10*Assumptions!F9
B14: EBIT | C14: =C11-C13 | D14: =D11-D13 | E14: =E11-E13 | F14: =F11-F13 | G14: =G11-G13 | H14: =H11-H13 | I14: =I11-I13
B15: Interest expense | F15: =$E$15 | G15: =$E$15 | H15: =$E$15 | I15: =$E$15
B16: Pre-tax income | C16: =C14-C15 | D16: =D14-D15 | E16: =E14-E15 | F16: =F14-F15 | G16: =G14-G15 | H16: =H14-H15 | I16: =I14-I15
B17: Tax | F17: =F16*Assumptions!C8 | G17: =G16*Assumptions!D8 | H17: =H16*Assumptions!E8 | I17: =I16*Assumptions!F8
B18: Net income | C18: =C16-C17 | D18: =D16-D17 | E18: =E16-E17 | F18: =F16-F17 | G18: =G16-G17 | H18: =H16-H17 | I18: =I16-I17
B19: Diluted shares | F19: =Assumptions!C12 | G19: =Assumptions!D12 | H19: =Assumptions!E12 | I19: =Assumptions!F12
B20: Diluted EPS | C20: =IFERROR(C18/C19,"-") | D20: =IFERROR(D18/D19,"-") | E20: =IFERROR(E18/E19,"-") | F20: =IFERROR(F18/F19,"-") | G20: =IFERROR(G18/G19,"-") | H20: =IFERROR(H18/H19,"-") | I20: =IFERROR(I18/I19,"-")

Sheet BS
B2: Balance Sheet ($mm)
B4: Line item | C4: FY-1A | D4: FY0A | E4: FY1E | F4: FY2E | G4: FY3E
B5: Cash & equivalents
B6: Accounts receivable
B7: Inventory
B8: Total current assets | C8: =C5+C6+C7 | D8: =D5+D6+D7 | E8: =E5+E6+E7 | F8: =F5+F6+F7 | G8: =G5+G6+G7
B9: PP&E net
B10: Goodwill & intangibles
B11: Total assets | C11: =C8+C9+C10 | D11: =D8+D9+D10 | E11: =E8+E9+E10 | F11: =F8+F9+F10 | G11: =G8+G9+G10
B12: Accounts payable
B13: Debt (current)
B14: Total current liabilities | C14: =C12+C13 | D14: =D12+D13 | E14: =E12+E13 | F14: =F12+F13 | G14: =G12+G13
B15: Long-term debt
B16: Total liabilities | C16: =C14+C15 | D16: =D14+D15 | E16: =E14+E15 | F16: =F14+F15 | G16: =G14+G15
B17: Total equity
B19: Balance check (Total assets - Total liabilities - Total equity, should = 0) | C19: =C11-C16-C17 | D19: =D11-D16-D17 | E19: =E11-E16-E17 | F19: =F11-F16-F17 | G19: =G11-G16-G17

Sheet CF
B2: Cash Flow ($mm)
B4: Line item | C4: FY-1A | D4: FY0A | E4: FY1E | F4: FY2E | G4: FY3E
B5: Net income | E5: =IS!F18 | F5: =IS!G18 | G5: =IS!H18
B6: + D&A | E6: =IS!F13 | F6: =IS!G13 | G6: =IS!H13
B7: +/- Change in NWC
B8: Cash flow from operations | C8: =C5+C6+C7 | D8: =D5+D6+D7 | E8: =E5+E6+E7 | F8: =F5+F6+F7 | G8: =G5+G6+G7
B9: Capex
B10: Free cash flow | C10: =C8+C9 | D10: =D8+D9 | E10: =E8+E9 | F10: =F8+F9 | G10: =G8+G9
B11: Debt issuance/(repayment)
B12: Dividends/buybacks
B13: Net change in cash | C13: =C10+C11+C12 | D13: =D10+D11+D12 | E13: =E10+E11+E12 | F13: =F10+F11+F12 | G13: =G10+G11+G12

Sheet DCF
B2: DCF Valuation
C4: FY1E | D4: FY2E | E4: FY3E | F4: FY4E | G4: FY5E | H4: Key outputs
B5: Unlevered FCF | C5: =IS!F14*(1-Assumptions!C8)+IS!F13-IS!F5*Assumptions!C10 | D5: =IS!G14*(1-Assumptions!D8)+IS!G13-IS!G5*Assumptions!D10 | E5: =IS!H14*(1-Assumptions!E8)+IS!H13-IS!H5*Assumptions!E10 | F5: =IS!I14*(1-Assumptions!F8)+IS!I13-IS!I5*Assumptions!F10 | G5: =F5*(1+Assumptions!G5) | H5: WACC | I5: 0.1
B6: Discount factor | C6: =1/(1+$I$5)^(1) | D6: =1/(1+$I$5)^(2) | E6: =1/(1+$I$5)^(3) | F6: =1/(1+$I$5)^(4) | G6: =1/(1+$I$5)^(5) | H6: Terminal growth | I6: 0.025
B7: PV of FCF | C7: =C5*C6 | D7: =D5*D6 | E7: =E5*E6 | F7: =F5*F6 | G7: =G5*G6 | H7: Terminal value | I7: =G5*(1+I6)/(I5-I6)
H8: PV of terminal value | I8: =I7*G6
H9: Sum PV of FCF | I9: =SUM(C7:G7)
H10: Enterprise value | I10: =I8+I9
H11: Less: net debt | I11: 0
H12: Equity value | I12: =I10-I11
H13: Diluted shares (mm) | I13: 1
H14: Implied value/share | I14: =I12/I13

Sheet Comps
B2: Comparable Companies
B4: Ticker | C4: Price | D4: Mkt Cap | E4: EV | F4: EV/Rev | G4: EV/EBITDA | H4: P/E
B5: [TICKER] | C5: 0 | D5: 0 | E5: 0 | F5: 0 | G5: 0 | H5: 0
B6: [TICKER] | C6: 0 | D6: 0 | E6: 0 | F6: 0 | G6: 0 | H6: 0
B7: [TICKER] | C7: 0 | D7: 0 | E7: 0 | F7: 0 | G7: 0 | H7: 0
B8: [TICKER] | C8: 0 | D8: 0 | E8: 0 | F8: 0 | G8: 0 | H8: 0
B9: [TICKER] | C9: 0 | D9: 0 | E9: 0 | F9: 0 | G9: 0 | H9: 0
B10: [TICKER] | C10: 0 | D10: 0 | E10: 0 | F10: 0 | G10: 0 | H10: 0
B11: [TICKER] | C11: 0 | D11: 0 | E11: 0 | F11: 0 | G11: 0 | H11: 0
B13: Median | C13: =MEDIAN(C5:C12) | D13: =MEDIAN(D5:D12) | E13: =MEDIAN(E5:E12) | F13: =MEDIAN(F5:F12) | G13: =MEDIAN(G5:G12) | H13: =MEDIAN(H5:H12)

Sheet Sensitivity
B2: Sensitivity — Implied Value/Share
B4: WACC \ Term. growth | C4: 0.015 | D4: 0.02 | E4: 0.025 | F4: 0.03 | G4: 0.035
B5: 0.08 | C5: [data table — Excel What-If Analysis] | D5: [data table — Excel What-If Analysis] | E5: [data table — Excel What-If Analysis] | F5: [data table — Excel What-If Analysis] | G5: [data table — Excel What-If Analysis]
B6: 0.09 | C6: [data table — Excel What-If Analysis] | D6: [data table — Excel What-If Analysis] | E6: [data table — Excel What-If Analysis] | F6: [data table — Excel What-If Analysis] | G6: [data table — Excel What-If Analysis]
B7: 0.1 | C7: [data table — Excel What-If Analysis] | D7: [data table — Excel What-If Analysis] | E7: [data table — Excel What-If Analysis] | F7: [data table — Excel What-If Analysis] | G7: [data table — Excel What-If Analysis]
B8: 0.11 | C8: [data table — Excel What-If Analysis] | D8: [data table — Excel What-If Analysis] | E8: [data table — Excel What-If Analysis] | F8: [data table — Excel What-If Analysis] | G8: [data table — Excel What-If Analysis]
B9: 0.12 | C9: [data table — Excel What-If Analysis] | D9: [data table — Excel What-If Analysis] | E9: [data table — Excel What-If Analysis] | F9: [data table — Excel What-If Analysis] | G9: [data table — Excel What-If Analysis]

Sheet RefreshLog
B2: Refresh Log
B4: Date | C4: Trigger | D4: What changed | E4: Reviewer notes | F4: Next check

Sheet Transaction Analysis
B2: Transaction Valuation, Offer Premium, and DCF Reconciliation
B4: Metric | C4: Base | D4: Adversarial | E4: Units / control
B5: Enterprise value | C5: 1000 | D5: 1000 | E5: transaction enterprise value
B6: Debt | C6: 200 | D6: 200 | E6: debt assumed or refinanced
B7: Cash | C7: 100 | D7: 100 | E7: cash retained in equity bridge
B8: Diluted shares | C8: 100 | D8: 100 | E8: fully diluted shares
B9: Offer price | C9: 9.5 | D9: 15 | E9: consideration per share
B10: Discount rate | C10: 0.1 | D10: 0.05 | E10: WACC / required return
B11: Terminal growth | C11: 0.03 | D11: 0.06 | E11: must remain below discount rate
B12: FCF Year 1 | C12: 70 | D12: 70 | E12: unlevered free cash flow
B13: FCF Year 2 | C13: 75 | D13: 65 | E13: unlevered free cash flow
B14: FCF Year 3 | C14: 80 | D14: 60 | E14: unlevered free cash flow
B15: FCF Year 4 | C15: 85 | D15: 55 | E15: unlevered free cash flow
B16: FCF Year 5 | C16: 90 | D16: 50 | E16: unlevered free cash flow
... B18: Valuation-dispersion warning | C18: 0.5 | D18: 0.5 | E18: maximum DCF / bridge dispersion
B21: Equity value | C21: =C5-C6+C7 | D21: =D5-D6+D7
B22: Bridge value / share | C22: =IFERROR(C21/C8,0) | D22: =IFERROR(D21/D8,0)
B23: Offer premium | C23: =IFERROR(C9/C22-1,0) | D23: =IFERROR(D9/D22-1,0)
B24: PV of forecast FCF | C24: =C12/(1+C10)+C13/(1+C10)^2+C14/(1+C10)^3+C15/(1+C10)^4+C16/(1+C10)^5 | D24: =D12/(1+D10)+D13/(1+D10)^2+D14/(1+D10)^3+D15/(1+D10)^4+D16/(1+D10)^5
B25: Terminal value | C25: =IF(C10<=C11,"-",C16*(1+C11)/(C10-C11)) | D25: =IF(D10<=D11,"-",D16*(1+D11)/(D10-D11))
B26: PV of terminal value | C26: =IF(ISNUMBER(C25),C25/(1+C10)^5,"-") | D26: =IF(ISNUMBER(D25),D25/(1+D10)^5,"-")
B27: DCF enterprise value | C27: =IF(AND(ISNUMBER(C24),ISNUMBER(C26)),C24+C26,"-") | D27: =IF(AND(ISNUMBER(D24),ISNUMBER(D26)),D24+D26,"-")
B28: DCF equity value | C28: =IF(ISNUMBER(C27),C27-C6+C7,"-") | D28: =IF(ISNUMBER(D27),D27-D6+D7,"-")
B29: DCF value / share | C29: =IF(ISNUMBER(C28),C28/C8,"-") | D29: =IF(ISNUMBER(D28),D28/D8,"-")
B30: DCF / bridge dispersion | C30: =IF(ISNUMBER(C29),ABS(C29-C22)/MAX(ABS(C22),1),"-") | D30: =IF(ISNUMBER(D29),ABS(D29-D22)/MAX(ABS(D22),1),"-")
B32: Terminal value is invalid whenever terminal growth is greater than or equal to the discount rate.

Sheet Accretion Dilution
B2: Pro Forma EPS, Synergy, Financing, and Share Issuance
B4: Metric | C4: Base | D4: Adversarial | E4: Units / control
B5: Buyer earnings | C5: 100 | D5: 100
B6: Buyer diluted shares | C6: 100 | D6: 100
B7: Target earnings | C7: 10 | D7: 5
B8: After-tax synergies | C8: 5 | D8: 0
B9: Incremental financing cost | C9: 3 | D9: 20
B10: Shares issued | C10: 10 | D10: 50
B11: Minimum accretion | C11: 0 | D11: 0
B14: Standalone EPS | C14: =IFERROR(C5/C6,0) | D14: =IFERROR(D5/D6,0)
B15: Pro forma earnings | C15: =C5+C7+C8-C9 | D15: =D5+D7+D8-D9
B16: Pro forma shares | C16: =C6+C10 | D16: =D6+D10
B17: Pro forma EPS | C17: =IFERROR(C15/C16,0) | D17: =IFERROR(D15/D16,0)
B18: EPS accretion / dilution | C18: =IFERROR(C17/C14-1,0) | D18: =IFERROR(D17/D14-1,0)

Sheet Valuation Reconciliation
B2: Bridge, DCF, Offer, and Transaction Decision Reconciliation
B4: Valuation method | C4: Base | D4: Adversarial | E4: Decision use
B5: Enterprise-to-equity bridge / share | C5: ='Transaction Analysis'!C22 | D5: ='Transaction Analysis'!D22 | E5: capital-structure bridge
B6: DCF value / share | C6: ='Transaction Analysis'!C29 | D6: ='Transaction Analysis'!D29 | E6: intrinsic value and terminal-value sensitivity
B7: Offer price | C7: ='Transaction Analysis'!C9 | D7: ='Transaction Analysis'!D9 | E7: consideration and premium
B8: EPS accretion / dilution | C8: ='Accretion Dilution'!C18 | D8: ='Accretion Dilution'!D18 | E8: buyer shareholder impact

Sheet Decision & Checks
B2: Investment Banking Decision Dashboard and Independent Checks
B4: Check / decision | C4: Metric | D4: Status | E4: Interpretation / action
B5: Enterprise-to-equity bridge residual | C5: ='Transaction Analysis'!C5-'Transaction Analysis'!C6+'Transaction Analysis'!C7-'Transaction Analysis'!C21 | D5: =IF(ABS(C5)<0.01,"PASS","FAIL") | E5: Enterprise value must reconcile to equity value through debt and cash.
B6: Per-share residual | C6: ='Transaction Analysis'!C21-'Transaction Analysis'!C22*'Transaction Analysis'!C8 | D6: =IF(ABS(C6)<0.01,"PASS","FAIL") | E6: Equity value must equal diluted shares times per-share value.
B7: Terminal-value validity | C7: ='Transaction Analysis'!D10-'Transaction Analysis'!D11 | D7: =IF(C7>0,"PASS","BREACH") | E7: Discount rate must exceed terminal growth.
B8: Adversarial offer premium | C8: ='Transaction Analysis'!D23 | D8: =IF(C8<='Transaction Analysis'!D17,"PASS","BREACH") | E8: Escalate premiums above the approved transaction threshold.
B9: Adversarial EPS accretion | C9: ='Accretion Dilution'!D18 | D9: =IF(C9>='Accretion Dilution'!D11,"PASS","BREACH") | E9: Transaction economics must not dilute buyer EPS beyond the approved boundary.
B10: Adversarial valuation dispersion | C10: ='Transaction Analysis'!D30 | D10: =IF(AND(ISNUMBER(C10),C10<='Transaction Analysis'!D18),"PASS","BREACH") | E10: Bridge and DCF values require reconciliation before committee use.
B12: Overall model status | C12: =IF(COUNTIF(D5:D10,"FAIL")+COUNTIF(D5:D10,"BREACH")>0,"BREACH",IF(COUNTIF(D5:D10,"REVIEW")>0,"REVIEW","PASS"))
