Workbook

Sheet Cover
B2: [FUND] — Asset Management Model
B4: Fund structure: | C4: Hedge fund / PE fund / mutual fund
B5: Vintage / inception: | C5: [date]
B6: Last refreshed: | C6: 2026-08-04
B7: Next capital call/distribution: | C7: [date]
B8: Refresh cadence: | C8: Weekly (monthly NAV strike)

Sheet Institutional Surface
B2: Asset Management — Institutional Decision Surface
B4: Model ID | C4: 08
B5: Domain | C5: Asset Management
B6: Declared maturity | C6: M2
B7: Canonical builder | C7: tools/builders/build_asset_management_release.py
B8: Decision arena | C8: portfolio manager, risk, valuation committee, operations and fund board
B9: Committee artifact | C9: portfolio, liquidity and valuation committee pack
B10: Operating cadence | C10: daily portfolio; weekly liquidity; monthly valuation
B12: Key decision outputs
B13: # | C13: Requirement | D13: Owner | E13: Evidence / location | F13: Status
B14: 1 | C14: NAV and performance attribution | F14: OPEN
B15: 2 | C15: gross-to-net return bridge | F15: OPEN
B16: 3 | C16: liquidity buckets and redemption coverage | F16: OPEN
B17: 4 | C17: base, downside and break-even outputs | F17: OPEN
B18: 5 | C18: liquidity / funding requirement and binding constraint | F18: OPEN
B20: Insider questions
B21: # | C21: Requirement | D21: Owner | E21: Evidence / location | F21: Status
B22: 1 | C22: How much can be liquidated without moving the market? | F22: OPEN
B23: 2 | C23: Which investors have better liquidity terms? | F23: OPEN
B24: 3 | C24: What prices are model-based or challenged? | F24: OPEN
B25: 4 | C25: Which assumption is owner-approved versus modeler judgement? | F25: OPEN
B26: 5 | C26: What fails first and who must act? | F26: OPEN
B28: Scenario families
B29: # | C29: Requirement | D29: Owner | E29: Evidence / location | F29: Status
B30: 1 | C30: redemption wave | F30: OPEN
B31: 2 | C31: market gap and liquidity haircut | F31: OPEN
B32: 3 | C32: stale or challenged valuation | F32: OPEN
B33: 4 | C33: data freshness / source failure | F33: OPEN
B34: 5 | C34: combined severe-but-plausible downside | F34: OPEN
B36: Primary diligence documents
B37: # | C37: Requirement | D37: Owner | E37: Evidence / location | F37: Status
B38: 1 | C38: investment management agreement | F38: OPEN
B39: 2 | C39: valuation policy | F39: OPEN
B40: 3 | C40: administrator NAV package | F40: OPEN
B41: 4 | C41: approved model card and assumption register | F41: OPEN
B42: 5 | C42: independent validation and challenge record | F42: OPEN
B44: Challenge tests
B45: # | C45: Requirement | D45: Owner | E45: Evidence / location | F45: Status
B46: 1 | C46: NAV roll-forward reconciles | F46: OPEN
B47: 2 | C47: fees follow governing documents | F47: OPEN
...

Sheet Challenge Log
B2: Independent Challenge, Override and Closure Log
B4: Date | C4: Reviewer | D4: Challenge | E4: Owner response | F4: Evidence | G4: Impact | H4: Status | I4: Closure
D5: NAV roll-forward reconciles | H5: OPEN
D6: fees follow governing documents | H6: OPEN
D7: liquidity buckets reflect time-to-cash | H7: OPEN
D8: source-to-model lineage is reproducible | H8: OPEN
D9: units, signs, dates and legal definitions reconcile | H9: OPEN

Sheet Lineage Map
B2: Source, Transformation, Ownership and Refresh Map
B4: Source class | C4: Cadence | D4: Control | E4: System / provider | F4: As-of | G4: Owner | H4: Transform | I4: Downstream | J4: Status
B5: positions and cash | C5: daily | D5: custodian and administrator reconciliation | J5: TO MAP
B6: prices | C6: daily | D6: source hierarchy and stale-price controls | J6: TO MAP
B7: model governance evidence | C7: per release | D7: version, reviewer, sign-off and change log | J7: TO MAP
B8: decision-use snapshot | C8: per decision | D8: immutable as-of date and source receipt | J8: TO MAP

Sheet Fund NAV
B2: Fund NAV Build
C4: Period 0 | D4: Period 1 | E4: Period 2 | F4: Period 3
B5: Beginning NAV | C5: 100 | D5: =C10 -> 128 | E5: =D10 -> 139 | F5: =E10 -> 143
B6: + Capital contributions | C6: 20 | D6: 10 | E6: 5 | F6: 0
B7: + Realized/unrealized gains | C7: 15 | D7: 7 | E7: 5 | F7: 4
B8: - Fees & expenses | C8: 2 | D8: 2 | E8: 2 | F8: 2
B9: - Distributions | C9: 5 | D9: 4 | E9: 4 | F9: 6
B10: Ending NAV | C10: =C5+C6+C7-C8-C9 -> 128 | D10: =D5+D6+D7-D8-D9 -> 139 | E10: =E5+E6+E7-E8-E9 -> 143 | F10: =F5+F6+F7-F8-F9 -> 139

Sheet Fee Waterfall
B2: Fee Waterfall — Mgmt Fee + Carry w/ Hurdle
B4: Inputs
B5: Committed capital | C5: 100
B6: Management fee % | C6: 80
B7: Preferred return / hurdle % | C7: 0.08
B8: Carry / promote % | C8: 0.2
B9: GP catch-up % | C9: 1
B10: Gross fund profit (this period) | C10: 100
B11: Capital invested (basis for hurdle) | C11: 0
B13: Waterfall
B14: 1. Return of capital | C14: =MIN(C10,C11) -> 0
B15: 2. Preferred return (hurdle) to LPs | C15: =MIN(MAX(C10-C14,0),C11*C7) -> 0
B16: 3. GP catch-up | C16: =MIN(MAX(C10-C14-C15,0),C15*C8/(1-C8)*C9) -> 0
B17: 4. Remaining profit split (LP/GP per carry%) | C17: =MAX(C10-C14-C15-C16,0) -> 100
B18: GP share of remainder | C18: =C17*C8 -> 20
B19: LP share of remainder | C19: =C17*(1-C8) -> 80
B21: Total GP take (carry + catch-up) | C21: =C16+C18 -> 20
B22: Total LP take | C22: =C14+C15+C19 -> 80
B23: Annual management fee (separate from carry) | C23: =C5*C6 -> 8000
B24: Waterfall conservation residual | C24: =C10-C21-C22 -> 0 | D24: Gross profit must equal GP take plus LP take; management fee remains separate.

Sheet Performance Attribution
B2: Performance Attribution
B4: Position/Strategy | C4: Contribution ($) | D4: Contribution (%) | E4: Weight (%) | F4: Notes
B5: [fill in] | C5: 0 | D5: 0 | E5: 0
B6: [fill in] | C6: 0 | D6: 0 | E6: 0
B7: [fill in] | C7: 0 | D7: 0 | E7: 0
B8: [fill in] | C8: 0 | D8: 0 | E8: 0
B9: [fill in] | C9: 0 | D9: 0 | E9: 0
B10: [fill in] | C10: 0 | D10: 0 | E10: 0
B11: [fill in] | C11: 0 | D11: 0 | E11: 0
B12: Total fund return | C12: =SUM(C5:C11) -> 0

Sheet Fund Performance
B2: Fund Performance — LP Reporting Metrics
B4: Uses the period cash flows and ending NAV from the Fund NAV tab.
C6: Period 0 | D6: Period 1 | E6: Period 2 | F6: Period 3
B7: LP net cash flow (distributions - contributions) | C7: ='Fund NAV'!C9-'Fund NAV'!C6 -> -15 | D7: ='Fund NAV'!D9-'Fund NAV'!D6 -> -6 | E7: ='Fund NAV'!E9-'Fund NAV'!E6 -> -1 | F7: ='Fund NAV'!F9-'Fund NAV'!F6 -> 6
B8: + terminal NAV added to final period | C8: ='Fund NAV'!F10 -> 139
B9: LP cash flow incl. terminal value (for IRR) | C9: =C7 -> -15 | D9: =D7 -> -6 | E9: =E7 -> -1 | F9: =F7+C8 -> 145
B12: Outputs
B13: Cumulative capital called | C13: =SUM('Fund NAV'!C6:F6) -> 35
B14: Cumulative distributions | C14: =SUM('Fund NAV'!C9:F9) -> 19
B15: Current NAV (residual value) | C15: ='Fund NAV'!F10 -> 139
B16: DPI (Distributions to Paid-In) | C16: =IFERROR(C14/C13,"-") -> 0.54285714
B17: RVPI (Residual Value to Paid-In) | C17: =IFERROR(C15/C13,"-") -> 3.9714286
B18: TVPI (Total Value to Paid-In = DPI + RVPI) | C18: =IFERROR(C16+C17,"-") -> 4.5142857 | D18: Headline LP metric — total value (realized + unrealized) per dollar called
B19: Net IRR to LPs (periodic, undated) | C19: =IFERROR(IRR(C9:F9),"-") -> 0.99511077 | D19: Treats each period as evenly spaced — use XIRR with real dates for called capital at irregular intervals

Sheet Return Measurement
B2: Time-Weighted, Money-Weighted, and Benchmark Return Controls
B4: Metric | C4: Period 0 | D4: Period 1 | E4: Period 2 | F4: Period 3 | G4: Interpretation
B5: Beginning NAV | C5: ='Fund NAV'!C5 -> 100 | D5: ='Fund NAV'!D5 -> 128 | E5: ='Fund NAV'!E5 -> 139 | F5: ='Fund NAV'!F5 -> 143
B6: Contributions | C6: ='Fund NAV'!C6 -> 20 | D6: ='Fund NAV'!D6 -> 10 | E6: ='Fund NAV'!E6 -> 5 | F6: ='Fund NAV'!F6 -> 0
B7: Distributions | C7: ='Fund NAV'!C9 -> 5 | D7: ='Fund NAV'!D9 -> 4 | E7: ='Fund NAV'!E9 -> 4 | F7: ='Fund NAV'!F9 -> 6
B8: Ending NAV | C8: ='Fund NAV'!C10 -> 128 | D8: ='Fund NAV'!D10 -> 139 | E8: ='Fund NAV'!E10 -> 143 | F8: ='Fund NAV'!F10 -> 139
B9: Subperiod return | C9: =IFERROR((C8+C7-C6)/C5-1,"-") -> 0.13 | D9: =IFERROR((D8+D7-D6)/D5-1,"-") -> 0.0390625 | E9: =IFERROR((E8+E7-E6)/E5-1,"-") -> 0.021582734 | F9: =IFERROR((F8+F7-F6)/F5-1,"-") -> 0.013986014
B12: Time-weighted return | C12: =IF(COUNT(C9:F9)<4,"-",PRODUCT(1+C9:F9)-1) -> 0.13
B13: Money-weighted return / IRR | C13: ='Fund Performance'!C19 -> 0.99511077
B14: Benchmark return | C14: 0.08
B15: Excess return | C15: =IF(AND(ISNUMBER(C12),ISNUMBER(C14)),C12-C14,"-") -> 0.05
B17: Time-weighted return neutralizes external cash flows at each subperiod boundary; irregular intra-period flows require dated or daily valuation methods.

Sheet Exposure & Liquidity
B2: Exposure, Concentration, Redemptions, and Liquidity Coverage
B4: Metric | C4: Base | D4: Downside | E4: Control / interpretation
B5: Gross exposure | C5: 150 | D5: 180 | E5: sum of absolute long and short market exposures
B6: Net exposure | C6: 60 | D6: 100 | E6: long less short exposure
B7: Current NAV | C7: ='Fund NAV'!F10 -> 139 | D7: ='Fund NAV'!F10 -> 139 | E7: linked to current residual value
B8: Top-10 position exposure | C8: 35 | D8: 55 | E8: concentration numerator
B9: Illiquid / gated NAV | C9: 15 | D9: 35 | E9: assets not monetizable inside the review horizon
B10: Thirty-day redemption / distribution demand | C10: 12 | D10: 40 | E10: expected cash demand
B11: Unfunded commitments | C11: 8 | D11: 20 | E11: contractual capital-call exposure
B12: Unrestricted liquid assets | C12: 30 | D12: 15 | E12: cash plus assets monetizable inside thirty days
B13: Maximum top-10 concentration | C13: 0.4 | D13: 0.4 | E13: approved limit
B14: Maximum illiquid NAV | C14: 0.25 | D14: 0.25 | E14: approved limit
B15: Minimum liquidity coverage | C15: 1.2 | D15: 1.2 | E15: liquid assets / redemption plus commitments
B18: Gross leverage | C18: =IFERROR(C5/C7,0) -> 1.0791367 | D18: =IFERROR(D5/D7,0) -> 1.294964
B19: Net exposure / NAV | C19: =IFERROR(C6/C7,0) -> 0.43165468 | D19: =IFERROR(D6/D7,0) -> 0.71942446
B20: Top-10 concentration | C20: =IFERROR(C8/C7,0) -> 0.25179856 | D20: =IFERROR(D8/D7,0) -> 0.39568345
B21: Illiquid NAV | C21: =IFERROR(C9/C7,0) -> 0.10791367 | D21: =IFERROR(D9/D7,0) -> 0.25179856
B22: Liquidity coverage | C22: =IFERROR(C12/(C10+C11),0) -> 1.5 | D22: =IFERROR(D12/(D10+D11),0) -> 0.25
B23: Downside status | C23: =IF(AND(D20<=D13,D21<=D14,D22>=D15),"PASS","BREACH") -> BREACH

Sheet Decision & Checks
B2: Asset Management Decision Dashboard and Independent Checks
B4: Check / decision | C4: Metric | D4: Status | E4: Interpretation / action
B5: NAV rollforward residual | C5: ='Fund NAV'!F10-('Fund NAV'!F5+'Fund NAV'!F6+'Fund NAV'!F7-'Fund NAV'!F8-'Fund NAV'!F9) -> 0 | D5: =IF(ABS(C5)<0.01,"PASS","FAIL") -> PASS | E5: Ending NAV must conserve beginning NAV, flows, gains, fees, and distributions.
B6: TVPI identity residual | C6: =IF(AND(ISNUMBER('Fund Performance'!C18),ISNUMBER('Fund Performance'!C16),ISNUMBER('Fund Performance'!C17)),'Fund Performance'!C18-'Fund Performance'!C16-'Fund Performance'!C17,0) -> 0 | D6: =IF(AND(ISNUMBER('Fund Performance'!C18),ISNUMBER('Fund Performance'!C16),ISNUMBER('Fund Performance'!C17)),IF(ABS(C6)<0.000001,"PASS","FAIL"),"REVIEW") -> PASS | E6: TVPI must equal DPI plus RVPI.
B7: Waterfall conservation residual | C7: ='Fee Waterfall'!C24 -> 0 | D7: =IF(ABS(C7)<0.01,"PASS","FAIL") -> PASS | E7: Gross profit must reconcile between LP and GP allocations.
B8: Carry-rate bounds | C8: ='Fee Waterfall'!C8 -> 0.2 | D8: =IF(AND(C8>=0,C8<1),"PASS","FAIL") -> PASS | E8: Carry outside zero to one invalidates the waterfall.
B9: Time-weighted return | C9: ='Return Measurement'!C12 -> 0.13 | D9: =IF(ISNUMBER(C9),"PASS","REVIEW") -> PASS | E9: Use valuation-consistent subperiods and disclose benchmark and composite policy.
B10: Excess return | C10: ='Return Measurement'!C15 -> 0.05 | D10: =IF(ISNUMBER(C10),"PASS","REVIEW") -> PASS | E10: Benchmark-relative performance must use a documented and appropriate comparison.
B11: Downside top-10 concentration | C11: ='Exposure & Liquidity'!D20 -> 0.39568345 | D11: =IF(C11<='Exposure & Liquidity'!D13,"PASS","BREACH") -> PASS | E11: Escalate concentration and correlated exit risk.
B12: Downside illiquid NAV | C12: ='Exposure & Liquidity'!D21 -> 0.25179856 | D12: =IF(C12<='Exposure & Liquidity'!D14,"PASS","BREACH") -> BREACH | E12: Illiquidity must be reconciled against gates, notice periods, and unfunded obligations.
B13: Downside liquidity coverage | C13: ='Exposure & Liquidity'!D22 -> 0.25 | D13: =IF(C13>='Exposure & Liquidity'!D15,"PASS","BREACH") -> BREACH | E13: Liquid resources must cover modeled redemptions, distributions, and capital calls.
B15: Overall model status | C15: =IF(COUNTIF(D5:D13,"FAIL")+COUNTIF(D5:D13,"BREACH")>0,"BREACH",IF(COUNTIF(D5:D13,"REVIEW")>0,"REVIEW","PASS")) -> BREACH
B17: Primary decision outputs
B18: Ending NAV | C18: ='Fund NAV'!F10 -> 139
B19: DPI | C19: ='Fund Performance'!C16 -> 0.54285714
B20: RVPI | C20: ='Fund Performance'!C17 -> 3.9714286
B21: TVPI | C21: ='Fund Performance'!C18 -> 4.5142857
B22: Net IRR | C22: ='Fund Performance'!C19 -> 0.99511077
B23: Time-weighted return | C23: ='Return Measurement'!C12 -> 0.13
B24: Downside liquidity coverage | C24: ='Exposure & Liquidity'!D22 -> 0.25

Sheet RefreshLog
B2: Refresh Log
B4: Date | C4: Trigger | D4: What changed | E4: Reviewer notes | F4: Next check
B5: 2026-08-04 | C5: M1-to-M2 domain hardening benchmark | D5: Generated conventional benchmark am-reference-fund from the canonical hardened release template | E5: Synthetic engineering fixture only; does not count toward M4 or live approval | F5: On builder, reference-check, formula, or contract change
