Workbook

Sheet Cover
B2: [PORTFOLIO / SECURITY] — Fixed Income & Rates Model
B4: Portfolio / security: | C4: [Name]
B5: Currency / curve: | C5: [Currency and benchmark]
B6: Last refreshed: | C6: 2025-12-01
B7: Next coupon / auction / event: | C7: [date]
B8: Refresh cadence: | C8: Daily
B9: Active scenario: | C9: Base
B10: Units: | C10: $ in millions; yields in percent
B13: Modeling conventions
B14: Blue text / yellow fill | C14: Hardcoded input or selected scenario
B15: Black text | C15: Formula / same-sheet calculation
B16: Green text | C16: Cross-sheet formula / link
B17: Checks | C17: PASS / REVIEW / FAIL must remain visible

Sheet Institutional Surface
B2: Fixed Income & Rates — Institutional Decision Surface
B4: Model ID | C4: 21
B5: Domain | C5: Fixed Income & Rates
B6: Declared maturity | C6: M2
B7: Canonical builder | C7: tools/builders/build_fixed_income_release.py
B8: Decision arena | C8: trading desk, portfolio management, treasury, ALCO and independent risk
B9: Committee artifact | C9: curve, carry and risk pack
B10: Operating cadence | C10: intraday desk; daily risk; monthly ALCO
B12: Key decision outputs
B13: # | C13: Requirement | D13: Owner | E13: Evidence / location | F13: Status
B14: 1 | C14: price, yield, duration and convexity | F14: OPEN
B15: 2 | C15: key-rate and spread DV01 | F15: OPEN
B16: 3 | C16: carry and roll-down | F16: OPEN
B17: 4 | C17: base, downside and break-even outputs | F17: OPEN
B18: 5 | C18: liquidity / funding requirement and binding constraint | F18: OPEN
B20: Insider questions
B21: # | C21: Requirement | D21: Owner | E21: Evidence / location | F21: Status
B22: 1 | C22: What part of carry is rolldown versus credit? | F22: OPEN
B23: 2 | C23: Which curve and interpolation method is authoritative? | F23: OPEN
B24: 3 | C24: Where does optionality invalidate duration? | F24: OPEN
B25: 4 | C25: Which assumption is owner-approved versus modeler judgement? | F25: OPEN
B26: 5 | C26: What fails first and who must act? | F26: OPEN
B28: Scenario families
B29: # | C29: Requirement | D29: Owner | E29: Evidence / location | F29: Status
B30: 1 | C30: parallel and nonparallel curve shocks | F30: OPEN
B31: 2 | C31: spread widening | F31: OPEN
B32: 3 | C32: basis and swap-spread move | F32: OPEN
B33: 4 | C33: data freshness / source failure | F33: OPEN
B34: 5 | C34: combined severe-but-plausible downside | F34: OPEN
B36: Primary diligence documents
B37: # | C37: Requirement | D37: Owner | E37: Evidence / location | F37: Status
B38: 1 | C38: security terms and prospectus | F38: OPEN
B39: 2 | C39: curve construction policy | F39: OPEN
B40: 3 | C40: repo / financing agreements | F40: OPEN
B41: 4 | C41: approved model card and assumption register | F41: OPEN
B42: 5 | C42: independent validation and challenge record | F42: OPEN
B44: Challenge tests
B45: # | C45: Requirement | D45: Owner | E45: Evidence / location | F45: Status
B46: 1 | C46: price-yield monotonicity | F46: OPEN
B47: 2 | C47: duration and convexity signs | F47: OPEN
...

Sheet Challenge Log
B2: Independent Challenge, Override and Closure Log
B4: Date | C4: Reviewer | D4: Challenge | E4: Owner response | F4: Evidence | G4: Impact | H4: Status | I4: Closure
D5: price-yield monotonicity | H5: OPEN
D6: duration and convexity signs | H6: OPEN
D7: key-rate DV01 reconciles to parallel risk | H7: OPEN
D8: source-to-model lineage is reproducible | H8: OPEN
D9: units, signs, dates and legal definitions reconcile | H9: OPEN

Sheet Lineage Map
B2: Source, Transformation, Ownership and Refresh Map
B4: Source class | C4: Cadence | D4: Control | E4: System / provider | F4: As-of | G4: Owner | H4: Transform | I4: Downstream | J4: Status
B5: prices and curves | C5: intraday/daily | D5: source and interpolation control | J5: TO MAP
B6: positions | C6: intraday/daily | D6: security and lot reconciliation | J6: TO MAP
B7: model governance evidence | C7: per release | D7: version, reviewer, sign-off and change log | J7: TO MAP
B8: decision-use snapshot | C8: per decision | D8: immutable as-of date and source receipt | J8: TO MAP

Sheet Assumptions
B2: Pricing and Risk Assumptions
B4: Assumption | C4: Base | D4: Downside | E4: Active | F4: Units / note
B5: Face value | C5: 1000 | D5: 1000 | E5: =IF(Cover!$C$9="Downside",D5,C5) -> 1000 | F5: currency
B6: Coupon rate | C6: 0.05 | D6: 0.05 | E6: =IF(Cover!$C$9="Downside",D6,C6) -> 0.05 | F6: %
B7: Yield to maturity | C7: 0.0409 | D7: 0.07 | E7: =IF(Cover!$C$9="Downside",D7,C7) -> 0.0409 | F7: %
B8: Maturity | C8: 10 | D8: 10 | E8: =IF(Cover!$C$9="Downside",D8,C8) -> 10 | F8: years
B9: Coupon frequency | C9: 2 | D9: 2 | E9: =IF(Cover!$C$9="Downside",D9,C9) -> 2 | F9: per year
B10: Parallel yield shock | C10: 0.01 | D10: 0.02 | E10: =IF(Cover!$C$9="Downside",D10,C10) -> 0.01 | F10: %
B11: One-basis-point bump | C11: 0.0001 | D11: 0.0001 | E11: =IF(Cover!$C$9="Downside",D11,C11) -> 0.0001 | F11: %
B12: Holding period | C12: 1 | D12: 1 | E12: =IF(Cover!$C$9="Downside",D12,C12) -> 1 | F12: years
B13: Financing / repo rate | C13: 0.045 | D13: 0.06 | E13: =IF(Cover!$C$9="Downside",D13,C13) -> 0.045 | F13: %
B14: Position market value | C14: 50 | D14: 50 | E14: =IF(Cover!$C$9="Downside",D14,C14) -> 50 | F14: $mm

Sheet Zero Curve
B2: Zero Curve and Discount Factors
B4: Tenor | C4: Base zero | D4: Downside zero | E4: Active zero | F4: Discount factor | G4: 1Y forward
B5: 0.25 | C5: 0.048 | D5: 0.053 | E5: =IF(Cover!$C$9="Downside",D5,C5) -> 0.048 | F5: =EXP(-E5*B5) -> 0.98807171 | G5: =E5 -> 0.048
B6: 0.5 | C6: 0.047 | D6: 0.052 | E6: =IF(Cover!$C$9="Downside",D6,C6) -> 0.047 | F6: =EXP(-E6*B6) -> 0.97677397 | G6: =IFERROR(-LN(F6/F5)/(B6-B5),0) -> 0.046
B7: 1 | C7: 0.045 | D7: 0.05 | E7: =IF(Cover!$C$9="Downside",D7,C7) -> 0.045 | F7: =EXP(-E7*B7) -> 0.95599748 | G7: =IFERROR(-LN(F7/F6)/(B7-B6),0) -> 0.043
B8: 2 | C8: 0.043 | D8: 0.048 | E8: =IF(Cover!$C$9="Downside",D8,C8) -> 0.043 | F8: =EXP(-E8*B8) -> 0.91759423 | G8: =IFERROR(-LN(F8/F7)/(B8-B7),0) -> 0.041
B9: 3 | C9: 0.042 | D9: 0.047 | E9: =IF(Cover!$C$9="Downside",D9,C9) -> 0.042 | F9: =EXP(-E9*B9) -> 0.88161485 | G9: =IFERROR(-LN(F9/F8)/(B9-B8),0) -> 0.04
B10: 5 | C10: 0.043 | D10: 0.055 | E10: =IF(Cover!$C$9="Downside",D10,C10) -> 0.043 | F10: =EXP(-E10*B10) -> 0.80654144 | G10: =IFERROR(-LN(F10/F9)/(B10-B9),0) -> 0.0445
B11: 7 | C11: 0.045 | D11: 0.057 | E11: =IF(Cover!$C$9="Downside",D11,C11) -> 0.045 | F11: =EXP(-E11*B11) -> 0.72978887 | G11: =IFERROR(-LN(F11/F10)/(B11-B10),0) -> 0.05
B12: 10 | C12: 0.047 | D12: 0.059 | E12: =IF(Cover!$C$9="Downside",D12,C12) -> 0.047 | F12: =EXP(-E12*B12) -> 0.62500227 | G12: =IFERROR(-LN(F12/F11)/(B12-B11),0) -> 0.051666667
B13: 20 | C13: 0.049 | D13: 0.061 | E13: =IF(Cover!$C$9="Downside",D13,C13) -> 0.049 | F13: =EXP(-E13*B13) -> 0.3753111 | G13: =IFERROR(-LN(F13/F12)/(B13-B12),0) -> 0.051
B14: 30 | C14: 0.05 | D14: 0.062 | E14: =IF(Cover!$C$9="Downside",D14,C14) -> 0.05 | F14: =EXP(-E14*B14) -> 0.22313016 | G14: =IFERROR(-LN(F14/F13)/(B14-B13),0) -> 0.052

Sheet Bond Analytics
B2: Bond Price, Duration, and Convexity
B4: Metric | C4: Value | D4: Units | E4: Method
B5: Price | C5: =-PV(Assumptions!E7/Assumptions!E9,Assumptions!E8*Assumptions!E9,Assumptions!E5*Assumptions!E6/Assumptions!E9,Assumptions!E5) -> 1074.0769 | D5: currency | E5: coupon annuity plus principal
B6: Price +1bp | C6: =-PV((Assumptions!E7+Assumptions!E11)/Assumptions!E9,Assumptions!E8*Assumptions!E9,Assumptions!E5*Assumptions!E6/Assumptions!E9,Assumptions!E5) -> 1073.2276 | D6: currency | E6: finite difference
B7: Price -1bp | C7: =-PV((Assumptions!E7-Assumptions!E11)/Assumptions!E9,Assumptions!E8*Assumptions!E9,Assumptions!E5*Assumptions!E6/Assumptions!E9,Assumptions!E5) -> 1074.9271 | D7: currency | E7: finite difference
B8: Numerical modified duration | C8: =IFERROR((C7-C6)/(2*C5*Assumptions!E11),0) -> 7.9110447 | D8: years | E8: central difference
B9: Numerical convexity | C9: =IFERROR((C6+C7-2*C5)/(C5*Assumptions!E11^2),0) -> 75.306548 | D9: years^2 | E9: second difference
B10: DV01 | C10: =(C7-C6)/2 -> 0.84970707 | D10: currency | E10: price value of 1bp
B11: Current yield | C11: =Assumptions!E5*Assumptions!E6/C5 -> 0.0465516 | D11: % | E11: annual coupon / price
B12: Price under parallel shock | C12: =-PV((Assumptions!E7+Assumptions!E10)/Assumptions!E9,Assumptions!E8*Assumptions!E9,Assumptions!E5*Assumptions!E6/Assumptions!E9,Assumptions!E5) -> 993.0146 | D12: currency | E12: full repricing
B13: Duration-convexity estimate | C13: =C5*(1-C8*Assumptions!E10+0.5*C9*Assumptions!E10^2) -> 993.15049 | D13: currency | E13: second-order approximation
B14: Approximation residual | C14: =C12-C13 -> -0.1358835 | D14: currency | E14: full price less estimate

Sheet Portfolio
B2: Fixed-Income Portfolio Analytics
B4: Security | C4: Market value | D4: Coupon | E4: Yield | F4: Maturity | G4: Spread duration | H4: Price | I4: Mod duration | J4: Convexity | K4: DV01
B5: 2Y Treasury | C5: 30 | D5: 0.045 | E5: 0.044 | F5: 2 | G5: 0 | H5: =-PV(E5/2,F5*2,100*D5/2,100) -> 100.18947 | I5: =IFERROR(((-PV((E5-0.0001)/2,F5*2,100*D5/2,100))-(-PV((E5+0.0001)/2,F5*2,100*D5/2,100)))/(2*H5*0.0001),0) -> 1.8933649 | J5: =IFERROR(((-PV((E5+0.0001)/2,F5*2,100*D5/2,100))+(-PV((E5-0.0001)/2,F5*2,100*D5/2,100))-2*H5)/(H5*0.0001^2),0) -> 4.5800483 | K5: =C5*I5*0.0001 -> 0.0056800946
B6: 5Y Treasury | C6: 40 | D6: 0.043 | E6: 0.045 | F6: 5 | G6: 0 | H6: =-PV(E6/2,F6*2,100*D6/2,100) -> 99.113378 | I6: =IFERROR(((-PV((E6-0.0001)/2,F6*2,100*D6/2,100))-(-PV((E6+0.0001)/2,F6*2,100*D6/2,100)))/(2*H6*0.0001),0) -> 4.4495083 | J6: =IFERROR(((-PV((E6+0.0001)/2,F6*2,100*D6/2,100))+(-PV((E6-0.0001)/2,F6*2,100*D6/2,100))-2*H6)/(H6*0.0001^2),0) -> 23.167125 | K6: =C6*I6*0.0001 -> 0.017798033
B7: 10Y Treasury | C7: 50 | D7: 0.05 | E7: 0.055 | F7: 10 | G7: 0 | H7: =-PV(E7/2,F7*2,100*D7/2,100) -> 96.193187 | I7: =IFERROR(((-PV((E7-0.0001)/2,F7*2,100*D7/2,100))-(-PV((E7+0.0001)/2,F7*2,100*D7/2,100)))/(2*H7*0.0001),0) -> 7.7300139 | J7: =IFERROR(((-PV((E7+0.0001)/2,F7*2,100*D7/2,100))+(-PV((E7-0.0001)/2,F7*2,100*D7/2,100))-2*H7)/(H7*0.0001^2),0) -> 72.706953 | K7: =C7*I7*0.0001 -> 0.038650069
B8: IG Corporate | C8: 45 | D8: 0.06 | E8: 0.068 | F8: 7 | G8: 5.5 | H8: =-PV(E8/2,F8*2,100*D8/2,100) -> 95.602343 | I8: =IFERROR(((-PV((E8-0.0001)/2,F8*2,100*D8/2,100))-(-PV((E8+0.0001)/2,F8*2,100*D8/2,100)))/(2*H8*0.0001),0) -> 5.5951497 | J8: =IFERROR(((-PV((E8+0.0001)/2,F8*2,100*D8/2,100))+(-PV((E8-0.0001)/2,F8*2,100*D8/2,100))-2*H8)/(H8*0.0001^2),0) -> 37.927652 | K8: =C8*I8*0.0001 -> 0.025178174
B9: HY Corporate | C9: 25 | D9: 0.085 | E9: 0.105 | F9: 5 | G9: 3.8 | H9: =-PV(E9/2,F9*2,100*D9/2,100) -> 92.37116 | I9: =IFERROR(((-PV((E9-0.0001)/2,F9*2,100*D9/2,100))-(-PV((E9+0.0001)/2,F9*2,100*D9/2,100)))/(2*H9*0.0001),0) -> 3.9301487 | J9: =IFERROR(((-PV((E9+0.0001)/2,F9*2,100*D9/2,100))+(-PV((E9-0.0001)/2,F9*2,100*D9/2,100))-2*H9)/(H9*0.0001^2),0) -> 19.202696 | K9: =C9*I9*0.0001 -> 0.0098253718
B10: Municipal | C10: 20 | D10: 0.04 | E10: 0.046 | F10: 12 | G10: 7.5 | H10: =-PV(E10/2,F10*2,100*D10/2,100) -> 94.514023 | I10: =IFERROR(((-PV((E10-0.0001)/2,F10*2,100*D10/2,100))-(-PV((E10+0.0001)/2,F10*2,100*D10/2,100)))/(2*H10*0.0001),0) -> 9.3501514 | J10: =IFERROR(((-PV((E10+0.0001)/2,F10*2,100*D10/2,100))+(-PV((E10-0.0001)/2,F10*2,100*D10/2,100))-2*H10)/(H10*0.0001^2),0) -> 105.33355 | K10: =C10*I10*0.0001 -> 0.018700303
B12: Portfolio total / weighted | C12: =SUM(C5:C10) -> 210 | G12: =SUMPRODUCT(C5:C10,G5:G10)/SUM(C5:C10) -> 2.3452381 | I12: =SUMPRODUCT(C5:C10,I5:I10)/SUM(C5:C10) -> 5.5158117 | J12: =SUMPRODUCT(C5:C10,J5:J10)/SUM(C5:C10) -> 42.823413 | K12: =SUM(K5:K10) -> 0.11583205

Sheet Key Rate Risk
B2: Key-Rate DV01 Approximation
B4: Security | C4: 2Y | D4: 5Y | E4: 10Y | F4: 20Y | G4: 30Y | H4: Total DV01
B5: =Portfolio!B5 -> 2Y Treasury | C5: =Portfolio!K5*MAX(0,1-ABS(Portfolio!F5-2)/MAX(2,2)) -> 0.0056800946 | D5: =Portfolio!K5*MAX(0,1-ABS(Portfolio!F5-5)/MAX(2,5)) -> 0.0022720379 | E5: =Portfolio!K5*MAX(0,1-ABS(Portfolio!F5-10)/MAX(2,10)) -> 0.0011360189 | F5: =Portfolio!K5*MAX(0,1-ABS(Portfolio!F5-20)/MAX(2,20)) -> 0.00056800946 | G5: =Portfolio!K5*MAX(0,1-ABS(Portfolio!F5-30)/MAX(2,30)) -> 0.00037867298 | H5: =SUM(C5:G5) -> 0.010034834
B6: =Portfolio!B6 -> 5Y Treasury | C6: =Portfolio!K6*MAX(0,1-ABS(Portfolio!F6-2)/MAX(2,2)) -> 0 | D6: =Portfolio!K6*MAX(0,1-ABS(Portfolio!F6-5)/MAX(2,5)) -> 0.017798033 | E6: =Portfolio!K6*MAX(0,1-ABS(Portfolio!F6-10)/MAX(2,10)) -> 0.0088990167 | F6: =Portfolio!K6*MAX(0,1-ABS(Portfolio!F6-20)/MAX(2,20)) -> 0.0044495083 | G6: =Portfolio!K6*MAX(0,1-ABS(Portfolio!F6-30)/MAX(2,30)) -> 0.0029663389 | H6: =SUM(C6:G6) -> 0.034112897
B7: =Portfolio!B7 -> 10Y Treasury | C7: =Portfolio!K7*MAX(0,1-ABS(Portfolio!F7-2)/MAX(2,2)) -> 0 | D7: =Portfolio!K7*MAX(0,1-ABS(Portfolio!F7-5)/MAX(2,5)) -> 0 | E7: =Portfolio!K7*MAX(0,1-ABS(Portfolio!F7-10)/MAX(2,10)) -> 0.038650069 | F7: =Portfolio!K7*MAX(0,1-ABS(Portfolio!F7-20)/MAX(2,20)) -> 0.019325035 | G7: =Portfolio!K7*MAX(0,1-ABS(Portfolio!F7-30)/MAX(2,30)) -> 0.012883356 | H7: =SUM(C7:G7) -> 0.07085846
B8: =Portfolio!B8 -> IG Corporate | C8: =Portfolio!K8*MAX(0,1-ABS(Portfolio!F8-2)/MAX(2,2)) -> 0 | D8: =Portfolio!K8*MAX(0,1-ABS(Portfolio!F8-5)/MAX(2,5)) -> 0.015106904 | E8: =Portfolio!K8*MAX(0,1-ABS(Portfolio!F8-10)/MAX(2,10)) -> 0.017624721 | F8: =Portfolio!K8*MAX(0,1-ABS(Portfolio!F8-20)/MAX(2,20)) -> 0.0088123607 | G8: =Portfolio!K8*MAX(0,1-ABS(Portfolio!F8-30)/MAX(2,30)) -> 0.0058749072 | H8: =SUM(C8:G8) -> 0.047418894
B9: =Portfolio!B9 -> HY Corporate | C9: =Portfolio!K9*MAX(0,1-ABS(Portfolio!F9-2)/MAX(2,2)) -> 0 | D9: =Portfolio!K9*MAX(0,1-ABS(Portfolio!F9-5)/MAX(2,5)) -> 0.0098253718 | E9: =Portfolio!K9*MAX(0,1-ABS(Portfolio!F9-10)/MAX(2,10)) -> 0.0049126859 | F9: =Portfolio!K9*MAX(0,1-ABS(Portfolio!F9-20)/MAX(2,20)) -> 0.002456343 | G9: =Portfolio!K9*MAX(0,1-ABS(Portfolio!F9-30)/MAX(2,30)) -> 0.001637562 | H9: =SUM(C9:G9) -> 0.018831963
B10: =Portfolio!B10 -> Municipal | C10: =Portfolio!K10*MAX(0,1-ABS(Portfolio!F10-2)/MAX(2,2)) -> 0 | D10: =Portfolio!K10*MAX(0,1-ABS(Portfolio!F10-5)/MAX(2,5)) -> 0 | E10: =Portfolio!K10*MAX(0,1-ABS(Portfolio!F10-10)/MAX(2,10)) -> 0.014960242 | F10: =Portfolio!K10*MAX(0,1-ABS(Portfolio!F10-20)/MAX(2,20)) -> 0.011220182 | G10: =Portfolio!K10*MAX(0,1-ABS(Portfolio!F10-30)/MAX(2,30)) -> 0.0074801211 | H10: =SUM(C10:G10) -> 0.033660545
B12: Portfolio key-rate DV01 | C12: =SUM(C5:C10) -> 0.0056800946 | D12: =SUM(D5:D10) -> 0.045002347 | E12: =SUM(E5:E10) -> 0.086182755 | F12: =SUM(F5:F10) -> 0.046831438 | G12: =SUM(G5:G10) -> 0.031220959 | H12: =SUM(H5:H10) -> 0.21491759

Sheet Carry & Roll
B2: One-Year Carry and Roll-Down
B4: Security | C4: Coupon carry | D4: Financing cost | E4: Yield after roll | F4: Roll P&L | G4: Total carry + roll
B5: =Portfolio!B5 -> 2Y Treasury | C5: =Portfolio!C5*Portfolio!D5 -> 1.35 | D5: =Portfolio!C5*Assumptions!E13 -> 1.35 | E5: =MAX(0,Portfolio!E5-0.002) -> 0.042 | F5: =Portfolio!C5*Portfolio!I5*(Portfolio!E5-E5) -> 0.11360189 | G5: =C5-D5+F5 -> 0.11360189
B6: =Portfolio!B6 -> 5Y Treasury | C6: =Portfolio!C6*Portfolio!D6 -> 1.72 | D6: =Portfolio!C6*Assumptions!E13 -> 1.8 | E6: =MAX(0,Portfolio!E6-0.002) -> 0.043 | F6: =Portfolio!C6*Portfolio!I6*(Portfolio!E6-E6) -> 0.35596067 | G6: =C6-D6+F6 -> 0.27596067
B7: =Portfolio!B7 -> 10Y Treasury | C7: =Portfolio!C7*Portfolio!D7 -> 2.5 | D7: =Portfolio!C7*Assumptions!E13 -> 2.25 | E7: =MAX(0,Portfolio!E7-0.002) -> 0.053 | F7: =Portfolio!C7*Portfolio!I7*(Portfolio!E7-E7) -> 0.77300139 | G7: =C7-D7+F7 -> 1.0230014
B8: =Portfolio!B8 -> IG Corporate | C8: =Portfolio!C8*Portfolio!D8 -> 2.7 | D8: =Portfolio!C8*Assumptions!E13 -> 2.025 | E8: =MAX(0,Portfolio!E8-0.002) -> 0.066 | F8: =Portfolio!C8*Portfolio!I8*(Portfolio!E8-E8) -> 0.50356347 | G8: =C8-D8+F8 -> 1.1785635
B9: =Portfolio!B9 -> HY Corporate | C9: =Portfolio!C9*Portfolio!D9 -> 2.125 | D9: =Portfolio!C9*Assumptions!E13 -> 1.125 | E9: =MAX(0,Portfolio!E9-0.002) -> 0.103 | F9: =Portfolio!C9*Portfolio!I9*(Portfolio!E9-E9) -> 0.19650744 | G9: =C9-D9+F9 -> 1.1965074
B10: =Portfolio!B10 -> Municipal | C10: =Portfolio!C10*Portfolio!D10 -> 0.8 | D10: =Portfolio!C10*Assumptions!E13 -> 0.9 | E10: =MAX(0,Portfolio!E10-0.002) -> 0.044 | F10: =Portfolio!C10*Portfolio!I10*(Portfolio!E10-E10) -> 0.37400605 | G10: =C10-D10+F10 -> 0.27400605
B12: Portfolio total | C12: =SUM(C5:C10) -> 11.195 | D12: =SUM(D5:D10) -> 9.45 | F12: =SUM(F5:F10) -> 2.3166409 | G12: =SUM(G5:G10) -> 4.0616409

Sheet Scenarios
B2: Curve and Spread Scenarios
B4: Scenario | C4: 2Y | D4: 5Y | E4: 10Y | F4: 20Y | G4: 30Y | H4: Credit spread | I4: Estimated P&L
B5: Parallel +100bp | C5: 0.01 | D5: 0.01 | E5: 0.01 | F5: 0.01 | G5: 0.01 | H5: 0 | I5: =-SUMPRODUCT('Key Rate Risk'!C12:G12,C5:G5)/0.0001-SUMPRODUCT(Portfolio!C5:C10,Portfolio!G5:G10)*H5 -> -21.491759
B6: Parallel -100bp | C6: -0.01 | D6: -0.01 | E6: -0.01 | F6: -0.01 | G6: -0.01 | H6: 0 | I6: =-SUMPRODUCT('Key Rate Risk'!C12:G12,C6:G6)/0.0001-SUMPRODUCT(Portfolio!C5:C10,Portfolio!G5:G10)*H6 -> 21.491759
B7: Bear steepener | C7: 0.005 | D7: 0.008 | E7: 0.012 | F7: 0.015 | G7: 0.018 | H7: 0.002 | I7: =-SUMPRODUCT('Key Rate Risk'!C12:G12,C7:G7)/0.0001-SUMPRODUCT(Portfolio!C5:C10,Portfolio!G5:G10)*H7 -> -27.855611
B8: Bull flattener | C8: -0.012 | D8: -0.01 | E8: -0.008 | F8: -0.006 | G8: -0.005 | H8: -0.001 | I8: =-SUMPRODUCT('Key Rate Risk'!C12:G12,C8:G8)/0.0001-SUMPRODUCT(Portfolio!C5:C10,Portfolio!G5:G10)*H8 -> 16.939901
B9: Credit widening | C9: 0.002 | D9: 0.003 | E9: 0.004 | F9: 0.005 | G9: 0.005 | H9: 0.015 | I9: =-SUMPRODUCT('Key Rate Risk'!C12:G12,C9:G9)/0.0001-SUMPRODUCT(Portfolio!C5:C10,Portfolio!G5:G10)*H9 -> -16.201102
B10: Risk-off rally | C10: -0.008 | D10: -0.01 | E10: -0.012 | F10: -0.01 | G10: -0.008 | H10: 0.02 | I10: =-SUMPRODUCT('Key Rate Risk'!C12:G12,C10:G10)/0.0001-SUMPRODUCT(Portfolio!C5:C10,Portfolio!G5:G10)*H10 -> 12.627393

Sheet P&L Explain
B2: Rates Portfolio P&L Explain
B4: Driver | C4: Exposure | D4: Move | E4: P&L | F4: Notes
B5: Carry | C5: ='Carry & Roll'!C12-'Carry & Roll'!D12 -> 1.745 | D5: 1 | E5: =C5*D5 -> 1.745 | F5: coupon less financing
B6: Roll-down | C6: ='Carry & Roll'!F12 -> 2.3166409 | D6: 1 | E6: =C6*D6 -> 2.3166409 | F6: curve roll
B7: Parallel rates | C7: =-Portfolio!K12/0.0001 -> -1158.3205 | D7: 0.0005 | E7: =C7*D7 -> -0.57916023 | F7: DV01 x move
B8: Curve shape | C8: =-('Key Rate Risk'!C12*0.0002+'Key Rate Risk'!D12*0.0001-'Key Rate Risk'!F12*0.0001)/0.0001 -> -0.0095310986 | D8: 1 | E8: =C8*D8 -> -0.0095310986 | F8: key-rate attribution
B9: Credit spread | C9: =-SUMPRODUCT(Portfolio!C5:C10,Portfolio!G5:G10) -> -492.5 | D9: 0.0015 | E9: =C9*D9 -> -0.73875 | F9: spread duration
B10: Convexity | C10: =0.5*SUMPRODUCT(Portfolio!C5:C10,Portfolio!J5:J10) -> 4496.4584 | D10: 2.5e-07 | E10: =C10*D10 -> 0.0011241146 | F10: second order
B13: Explained P&L | E13: =SUM(E5:E10) -> 2.7353237
B14: Actual P&L | E14: 1.2
B15: Unexplained P&L | E15: =E14-E13 -> -1.5353237

Sheet Checks
B2: Fixed-Income Model Checks
B4: Check | C4: Status
B5: Price positive | C5: =IF('Bond Analytics'!C5>0,"PASS","FAIL") -> PASS
B6: Price decreases as yield rises | C6: =IF('Bond Analytics'!C6<'Bond Analytics'!C5,"PASS","FAIL") -> PASS
B7: Duration positive | C7: =IF('Bond Analytics'!C8>0,"PASS","FAIL") -> PASS
B8: Convexity positive | C8: =IF('Bond Analytics'!C9>0,"PASS","FAIL") -> PASS
B9: Key-rate DV01 reconciles | C9: =IF(ABS('Key Rate Risk'!H12-Portfolio!K12)<0.1,"PASS","REVIEW") -> PASS
B10: Curve discount factors decreasing | C10: =IF(MAX('Zero Curve'!F6:F14-'Zero Curve'!F5:F13)<=0,"PASS","REVIEW") -> PASS
B11: P&L explain populated | C11: =IF(COUNT('P&L Explain'!E5:E10)=6,"PASS","FAIL") -> PASS
B12: Overall | C12: =IF(COUNTIF(C5:C11,"FAIL")=0,"PASS","FAIL") -> PASS

Sheet Sources
B2: Source Register
B4: Input / dataset | C4: Source URL or document | D4: As-of | E4: Notes / transformation
B5: Security terms and cash flows | C5: [prospectus / terms URL] | D5: [date] | E5: Coupon, maturity, callability, indexation
B6: Benchmark and zero curves | C6: https://home.treasury.gov/resource-center/data-chart-center/interest-rates | D6: [timestamp] | E6: Document interpolation and compounding
B7: Credit spreads and prices | C7: [market data URL] | D7: [timestamp] | E7: Bid/ask, liquidity, source hierarchy
B8: Financing and repo | C8: [broker / central bank source] | D8: [date] | E8: Haircuts, specials, term, and currency basis
B9: Portfolio positions | C9: [OMS / custody source] | D9: [timestamp] | E9: Reconcile quantities, accrued interest, and market value
B10: Daily Treasury Par Yield Curve Rates | C10: https://home.treasury.gov/resource-center/data-chart-center/interest-rates/TextView?field_tdr_date_value_month=202512&type=daily_treasury_yield_curve | D10: 2025-12-01 | E10: U.S. Department of the Treasury; frozen curated observation as of case date
B11: Frozen source snapshot | C11: repo://21_Fixed_Income_Rates/sources/snapshots/rates-treasury-2025-12-01.json | D11: 2025-12-01 | E11: Immutable curated observation package with SHA-256 digest

Sheet RefreshLog
B2: Refresh Log
B4: Date | C4: Trigger | D4: Source snapshot | E4: What changed | F4: Reviewer / challenge | G4: Next check
B5: 2026-08-04 | C5: External historical evidence materialization | D5: repo://21_Fixed_Income_Rates/sources/snapshots/rates-treasury-2025-12-01.json | E5: Generated public case rates-treasury-2025-12-01 from canonical release template | F5: External historical case; human stakeholder approval remains pending | G5: On source revision, builder change, monitoring breach, or annual review
