Workbook

Sheet Cover
B2: [TARGET] — LBO Underwriting Model
B4: Target / transaction: | C4: Macy's, Inc. -- FY2020 pandemic contraction (adversarial case)
B5: Sponsor / principal: | C5: [Fund / merchant bank]
B6: Entry / close date: | C6: [date]
B7: Last refreshed: | C7: 2021-03-30
B8: Next IC / financing event: | C8: [date]
B9: Active scenario: | C9: Downside
B10: Units: | C10: $ in millions unless noted
B13: Modeling conventions
B14: Blue text / yellow fill | C14: Hardcoded input or selected scenario
B15: Black text | C15: Formula / same-sheet calculation
B16: Green text | C16: Cross-sheet formula / link
B17: Checks | C17: PASS / REVIEW / FAIL must remain visible

Sheet Institutional Surface
B2: Private Equity — Institutional Decision Surface
B4: Model ID | C4: 03
B5: Domain | C5: Private Equity
B6: Declared maturity | C6: M2
B7: Canonical builder | C7: tools/builders/build_lbo_release.py
B8: Decision arena | C8: deal team, operating partner, financing team, investment committee and LPAC
B9: Committee artifact | C9: investment committee underwriting memo
B10: Operating cadence | C10: weekly pre-close; monthly portfolio; quarterly IC
B12: Key decision outputs
B13: # | C13: Requirement | D13: Owner | E13: Evidence / location | F13: Status
B14: 1 | C14: sponsor MOIC and IRR | F14: OPEN
B15: 2 | C15: debt paydown and covenant headroom | F15: OPEN
B16: 3 | C16: management equity waterfall | F16: OPEN
B17: 4 | C17: base, downside and break-even outputs | F17: OPEN
B18: 5 | C18: liquidity / funding requirement and binding constraint | F18: OPEN
B20: Insider questions
B21: # | C21: Requirement | D21: Owner | E21: Evidence / location | F21: Status
B22: 1 | C22: What EBITDA add-backs survive lender diligence? | F22: OPEN
B23: 2 | C23: Where does the business need cash before it generates cash? | F23: OPEN
B24: 3 | C24: Which covenant is springing and when? | F24: OPEN
B25: 4 | C25: Which assumption is owner-approved versus modeler judgement? | F25: OPEN
B26: 5 | C26: What fails first and who must act? | F26: OPEN
B28: Scenario families
B29: # | C29: Requirement | D29: Owner | E29: Evidence / location | F29: Status
B30: 1 | C30: volume/price/mix miss | F30: OPEN
B31: 2 | C31: margin plan delay | F31: OPEN
B32: 3 | C32: working-capital leakage | F32: OPEN
B33: 4 | C33: data freshness / source failure | F33: OPEN
B34: 5 | C34: combined severe-but-plausible downside | F34: OPEN
B36: Primary diligence documents
B37: # | C37: Requirement | D37: Owner | E37: Evidence / location | F37: Status
B38: 1 | C38: QoE and net working capital report | F38: OPEN
B39: 2 | C39: market / commercial diligence | F39: OPEN
B40: 3 | C40: debt term sheets and commitment papers | F40: OPEN
B41: 4 | C41: approved model card and assumption register | F41: OPEN
B42: 5 | C42: independent validation and challenge record | F42: OPEN
B44: Challenge tests
B45: # | C45: Requirement | D45: Owner | E45: Evidence / location | F45: Status
B46: 1 | C46: sources equal uses | F46: OPEN
B47: 2 | C47: minimum cash never breached without explicit cure | F47: OPEN
...

Sheet Challenge Log
B2: Independent Challenge, Override and Closure Log
B4: Date | C4: Reviewer | D4: Challenge | E4: Owner response | F4: Evidence | G4: Impact | H4: Status | I4: Closure
D5: sources equal uses | H5: OPEN
D6: minimum cash never breached without explicit cure | H6: OPEN
D7: debt tranches conserve | H7: OPEN
D8: source-to-model lineage is reproducible | H8: OPEN
D9: units, signs, dates and legal definitions reconcile | H9: OPEN

Sheet Lineage Map
B2: Source, Transformation, Ownership and Refresh Map
B4: Source class | C4: Cadence | D4: Control | E4: System / provider | F4: As-of | G4: Owner | H4: Transform | I4: Downstream | J4: Status
B5: operating KPI pack | C5: monthly | D5: reported-to-underwritten bridge | J5: TO MAP
B6: debt balances | C6: monthly | D6: agent statement tie-out | J6: TO MAP
B7: model governance evidence | C7: per release | D7: version, reviewer, sign-off and change log | J7: TO MAP
B8: decision-use snapshot | C8: per decision | D8: immutable as-of date and source receipt | J8: TO MAP

Sheet Assumptions
B2: Transaction, Operating, and Financing Assumptions
B4: Assumption | C4: Base | D4: Downside | E4: Active | F4: Units / note
B5: LTM revenue | C5: 600 | D5: 600 | E5: =IF(Cover!$C$9="Downside",D5,C5) -> 600 | F5: $mm
B6: LTM EBITDA margin | C6: 0.2 | D6: 0.02 | E6: =IF(Cover!$C$9="Downside",D6,C6) -> 0.02 | F6: %
B7: Annual revenue growth | C7: 0.06 | D7: -0.291 | E7: =IF(Cover!$C$9="Downside",D7,C7) -> -0.291 | F7: %
B8: Annual EBITDA margin expansion | C8: 0.005 | D8: -0.003 | E8: =IF(Cover!$C$9="Downside",D8,C8) -> -0.003 | F8: % points
B9: D&A / revenue | C9: 0.025 | D9: 0.025 | E9: =IF(Cover!$C$9="Downside",D9,C9) -> 0.025 | F9: %
B10: Capex / revenue | C10: 0.035 | D10: 0.045 | E10: =IF(Cover!$C$9="Downside",D10,C10) -> 0.045 | F10: %
B11: NWC / revenue | C11: 0.08 | D11: 0.1 | E11: =IF(Cover!$C$9="Downside",D11,C11) -> 0.1 | F11: %
B12: Cash tax rate | C12: 0.25 | D12: 0.2 | E12: =IF(Cover!$C$9="Downside",D12,C12) -> 0.2 | F12: %
B13: Entry EBITDA multiple | C13: 10 | D13: 9 | E13: =IF(Cover!$C$9="Downside",D13,C13) -> 9 | F13: x
B14: Transaction fees / enterprise value | C14: 0.02 | D14: 0.025 | E14: =IF(Cover!$C$9="Downside",D14,C14) -> 0.025 | F14: %
B15: Existing net debt refinanced | C15: 100 | D15: 100 | E15: =IF(Cover!$C$9="Downside",D15,C15) -> 100 | F15: $mm
B16: Minimum cash | C16: 20 | D16: 25 | E16: =IF(Cover!$C$9="Downside",D16,C16) -> 25 | F16: $mm
... B33: Revolver commitment fee (undrawn balance) | C33: 0.00375 | D33: 0.005 | E33: =IF(Cover!$C$9="Downside",D33,C33) -> 0.005 | F33: % p.a.

Sheet Sources & Uses
B2: Transaction Sources & Uses
B4: Uses | C4: Amount | E4: Sources | F4: Amount
B5: Purchase enterprise value | C5: =Assumptions!E5*Assumptions!E6*Assumptions!E13 -> 108 | E5: Revolver at close | F5: 0
B6: Refinance existing net debt | C6: =Assumptions!E15 -> 100 | E6: Term loan B | F6: =Assumptions!E5*Assumptions!E6*Assumptions!E19 -> 42
B7: Transaction fees | C7: =C5*Assumptions!E14 -> 2.7 | E7: Second-lien / holdco debt | F7: =Assumptions!E5*Assumptions!E6*Assumptions!E22 -> 12
B8: Minimum cash funded | C8: =Assumptions!E16 -> 25 | E8: Sponsor equity | F8: =C9-SUM(F5:F7) -> 181.7
B9: Total uses | C9: =SUM(C5:C8) -> 235.7 | E9: Total sources | F9: =SUM(F5:F8) -> 235.7
E10: Sources less uses | F10: =F9-C9 -> 0

Sheet Operating Model
B2: Seven-Year Operating, Tax, and Cash Flow Model
B4: $mm / % | C4: LTM | D4: Year 1 | E4: Year 2 | F4: Year 3 | G4: Year 4 | H4: Year 5 | I4: Year 6 | J4: Year 7
B5: Revenue | C5: =Assumptions!E5 -> 600 | D5: =C5*(1+Assumptions!$E$7) -> 425.4 | E5: =D5*(1+Assumptions!$E$7) -> 301.6086 | F5: =E5*(1+Assumptions!$E$7) -> 213.8405 | G5: =F5*(1+Assumptions!$E$7) -> 151.61291 | H5: =G5*(1+Assumptions!$E$7) -> 107.49356 | I5: =H5*(1+Assumptions!$E$7) -> 76.212931 | J5: =I5*(1+Assumptions!$E$7) -> 54.034968
B6: Revenue growth | D6: =IFERROR(D5/C5-1,0) -> -0.291 | E6: =IFERROR(E5/D5-1,0) -> -0.291 | F6: =IFERROR(F5/E5-1,0) -> -0.291 | G6: =IFERROR(G5/F5-1,0) -> -0.291 | H6: =IFERROR(H5/G5-1,0) -> -0.291 | I6: =IFERROR(I5/H5-1,0) -> -0.291 | J6: =IFERROR(J5/I5-1,0) -> -0.291
B7: EBITDA margin | C7: =Assumptions!E6 -> 0.02 | D7: =MAX(0,MIN(0.6,C7+Assumptions!$E$8)) -> 0.017 | E7: =MAX(0,MIN(0.6,D7+Assumptions!$E$8)) -> 0.014 | F7: =MAX(0,MIN(0.6,E7+Assumptions!$E$8)) -> 0.011 | G7: =MAX(0,MIN(0.6,F7+Assumptions!$E$8)) -> 0.008 | H7: =MAX(0,MIN(0.6,G7+Assumptions!$E$8)) -> 0.005 | I7: =MAX(0,MIN(0.6,H7+Assumptions!$E$8)) -> 0.002 | J7: =MAX(0,MIN(0.6,I7+Assumptions!$E$8)) -> 0
B8: EBITDA | C8: =C5*C7 -> 12 | D8: =D5*D7 -> 7.2318 | E8: =E5*E7 -> 4.2225204 | F8: =F5*F7 -> 2.3522455 | G8: =G5*G7 -> 1.2129033 | H8: =H5*H7 -> 0.53746778 | I8: =I5*I7 -> 0.15242586 | J8: =J5*J7 -> 0
B9: D&A | C9: =C5*Assumptions!E9 -> 15 | D9: =D5*Assumptions!$E$9 -> 10.635 | E9: =E5*Assumptions!$E$9 -> 7.540215 | F9: =F5*Assumptions!$E$9 -> 5.3460124 | G9: =G5*Assumptions!$E$9 -> 3.7903228 | H9: =H5*Assumptions!$E$9 -> 2.6873389 | I9: =I5*Assumptions!$E$9 -> 1.9053233 | J9: =J5*Assumptions!$E$9 -> 1.3508742
B10: EBIT | C10: =C8-C9 -> -3 | D10: =D8-D9 -> -3.4032 | E10: =E8-E9 -> -3.3176946 | F10: =F8-F9 -> -2.993767 | G10: =G8-G9 -> -2.5774195 | H10: =H8-H9 -> -2.1498711 | I10: =I8-I9 -> -1.7528974 | J10: =J8-J9 -> -1.3508742
B11: Cash interest | D11: ='Debt Schedule'!D7 -> 6.345 | E11: ='Debt Schedule'!E7 -> 6.512682 | F11: ='Debt Schedule'!F7 -> 6.9798569 | G11: ='Debt Schedule'!G7 -> 7.6700505 | H11: ='Debt Schedule'!H7 -> 8.538712 | I11: ='Debt Schedule'!I7 -> 9.5625385 | J11: ='Debt Schedule'!J7 -> 10.732468
B12: EBT | D12: =D10-D11 -> -9.7482 | E12: =E10-E11 -> -9.8303766 | F12: =F10-F11 -> -9.9736239 | G12: =G10-G11 -> -10.24747 | H12: =H10-H11 -> -10.688583 | I12: =I10-I11 -> -11.315436 | J12: =J10-J11 -> -12.083342
B13: Cash taxes | D13: =MAX(0,D12*Assumptions!$E$12) -> 0 | E13: =MAX(0,E12*Assumptions!$E$12) -> 0 | F13: =MAX(0,F12*Assumptions!$E$12) -> 0 | G13: =MAX(0,G12*Assumptions!$E$12) -> 0 | H13: =MAX(0,H12*Assumptions!$E$12) -> 0 | I13: =MAX(0,I12*Assumptions!$E$12) -> 0 | J13: =MAX(0,J12*Assumptions!$E$12) -> 0
B14: Net income | D14: =D12-D13 -> -9.7482 | E14: =E12-E13 -> -9.8303766 | F14: =F12-F13 -> -9.9736239 | G14: =G12-G13 -> -10.24747 | H14: =H12-H13 -> -10.688583 | I14: =I12-I13 -> -11.315436 | J14: =J12-J13 -> -12.083342
B15: Capex | D15: =D5*Assumptions!$E$10 -> 19.143 | E15: =E5*Assumptions!$E$10 -> 13.572387 | F15: =F5*Assumptions!$E$10 -> 9.6228224 | G15: =G5*Assumptions!$E$10 -> 6.8225811 | H15: =H5*Assumptions!$E$10 -> 4.83721 | I15: =I5*Assumptions!$E$10 -> 3.4295819 | J15: =J5*Assumptions!$E$10 -> 2.4315735
B16: NWC | C16: =C5*Assumptions!E11 -> 60 | D16: =D5*Assumptions!$E$11 -> 42.54 | E16: =E5*Assumptions!$E$11 -> 30.16086 | F16: =F5*Assumptions!$E$11 -> 21.38405 | G16: =G5*Assumptions!$E$11 -> 15.161291 | H16: =H5*Assumptions!$E$11 -> 10.749356 | I16: =I5*Assumptions!$E$11 -> 7.6212931 | J16: =J5*Assumptions!$E$11 -> 5.4034968
B17: Change in NWC | D17: =D16-C16 -> -17.46 | E17: =E16-D16 -> -12.37914 | F17: =F16-E16 -> -8.7768103 | G17: =G16-F16 -> -6.2227585 | H17: =H16-G16 -> -4.4119358 | I17: =I16-H16 -> -3.1280625 | J17: =J16-I16 -> -2.2177963
B18: FCF before financing | D18: =D14+D9-D15-D17 -> -0.7962 | E18: =E14+E9-E15-E17 -> -3.4834086 | F18: =F14+F9-F15-F17 -> -5.4736236 | G18: =G14+G9-G15-G17 -> -7.0569698 | H18: =H14+H9-H15-H17 -> -8.4265184 | I18: =I14+I9-I15-I17 -> -9.711632 | J18: =J14+J9-J15-J17 -> -10.946245
B19: FCF before interest | D19: =D8-D13-D15-D17 -> 5.5488 | E19: =E8-E13-E15-E17 -> 3.0292734 | F19: =F8-F13-F15-F17 -> 1.5062333 | G19: =G8-G13-G15-G17 -> 0.61308071 | H19: =H8-H13-H15-H17 -> 0.11219356 | I19: =I8-I13-I15-I17 -> -0.14909356 | J19: =J8-J13-J15-J17 -> -0.21377727

Sheet Debt Schedule
B2: Multi-Tranche Debt and Cash Sweep
B4: $mm / % | C4: Close | D4: Year 1 | E4: Year 2 | F4: Year 3 | G4: Year 4 | H4: Year 5 | I4: Year 6 | J4: Year 7
B5: Beginning cash | C5: =Assumptions!E16 -> 25 | D5: =C13 -> 25 | E5: =D13 -> 25 | F5: =E13 -> 25 | G5: =F13 -> 25 | H5: =G13 -> 25 | I5: =H13 -> 25 | J5: =I13 -> 25
B6: FCF before interest | D6: ='Operating Model'!D19 -> 5.5488 | E6: ='Operating Model'!E19 -> 3.0292734 | F6: ='Operating Model'!F19 -> 1.5062333 | G6: ='Operating Model'!G19 -> 0.61308071 | H6: ='Operating Model'!H19 -> 0.11219356 | I6: ='Operating Model'!I19 -> -0.14909356 | J6: ='Operating Model'!J19 -> -0.21377727
B7: Cash interest | D7: =SUM(D15,D18,D23,D29) -> 6.345 | E7: =SUM(E15,E18,E23,E29) -> 6.512682 | F7: =SUM(F15,F18,F23,F29) -> 6.9798569 | G7: =SUM(G15,G18,G23,G29) -> 7.6700505 | H7: =SUM(H15,H18,H23,H29) -> 8.538712 | I7: =SUM(I15,I18,I23,I29) -> 9.5625385 | J7: =SUM(J15,J18,J23,J29) -> 10.732468
B8: Mandatory TLB amortization | D8: =D19 -> 0.42 | E8: =E19 -> 0.42 | F8: =F19 -> 0.42 | G8: =G19 -> 0.42 | H8: =H19 -> 0.42 | I8: =I19 -> 0.42 | J8: =J19 -> 0.42
B9: Cash before revolver / sweep | D9: =D5+D6-D7-D8 -> 23.7838 | E9: =E5+E6-E7-E8 -> 21.096591 | F9: =F5+F6-F7-F8 -> 19.106376 | G9: =G5+G6-G7-G8 -> 17.52303 | H9: =H5+H6-H7-H8 -> 16.153482 | I9: =I5+I6-I7-I8 -> 14.868368 | J9: =J5+J6-J7-J8 -> 13.633755
B10: Revolver draw / (repayment) | D10: =IF(D9<Assumptions!$E$16,MIN(Assumptions!$E$17-D14,Assumptions!$E$16-D9),-MIN(D14,MAX(0,D9-Assumptions!$E$16))) -> 1.2162 | E10: =IF(E9<Assumptions!$E$16,MIN(Assumptions!$E$17-E14,Assumptions!$E$16-E9),-MIN(E14,MAX(0,E9-Assumptions!$E$16))) -> 3.9034086 | F10: =IF(F9<Assumptions!$E$16,MIN(Assumptions!$E$17-F14,Assumptions!$E$16-F9),-MIN(F14,MAX(0,F9-Assumptions!$E$16))) -> 5.8936236 | G10: =IF(G9<Assumptions!$E$16,MIN(Assumptions!$E$17-G14,Assumptions!$E$16-G9),-MIN(G14,MAX(0,G9-Assumptions!$E$16))) -> 7.4769698 | H10: =IF(H9<Assumptions!$E$16,MIN(Assumptions!$E$17-H14,Assumptions!$E$16-H9),-MIN(H14,MAX(0,H9-Assumptions!$E$16))) -> 8.8465184 | I10: =IF(I9<Assumptions!$E$16,MIN(Assumptions!$E$17-I14,Assumptions!$E$16-I9),-MIN(I14,MAX(0,I9-Assumptions!$E$16))) -> 10.131632 | J10: =IF(J9<Assumptions!$E$16,MIN(Assumptions!$E$17-J14,Assumptions!$E$16-J9),-MIN(J14,MAX(0,J9-Assumptions!$E$16))) -> 11.366245
B11: Cash sweep to TLB | D11: =MIN(MAX(0,D17-D19),MAX(0,D9+D10-Assumptions!$E$16)*Assumptions!$E$25) -> 0 | E11: =MIN(MAX(0,E17-E19),MAX(0,E9+E10-Assumptions!$E$16)*Assumptions!$E$25) -> 0 | F11: =MIN(MAX(0,F17-F19),MAX(0,F9+F10-Assumptions!$E$16)*Assumptions!$E$25) -> 0 | G11: =MIN(MAX(0,G17-G19),MAX(0,G9+G10-Assumptions!$E$16)*Assumptions!$E$25) -> 0 | H11: =MIN(MAX(0,H17-H19),MAX(0,H9+H10-Assumptions!$E$16)*Assumptions!$E$25) -> 0 | I11: =MIN(MAX(0,I17-I19),MAX(0,I9+I10-Assumptions!$E$16)*Assumptions!$E$25) -> 0 | J11: =MIN(MAX(0,J17-J19),MAX(0,J9+J10-Assumptions!$E$16)*Assumptions!$E$25) -> 0
B12: Cash sweep to second lien | D12: =MIN(MAX(0,D22+D24),MAX(0,D9+D10-D11-Assumptions!$E$16)*Assumptions!$E$25) -> 0 | E12: =MIN(MAX(0,E22+E24),MAX(0,E9+E10-E11-Assumptions!$E$16)*Assumptions!$E$25) -> 0 | F12: =MIN(MAX(0,F22+F24),MAX(0,F9+F10-F11-Assumptions!$E$16)*Assumptions!$E$25) -> 0 | G12: =MIN(MAX(0,G22+G24),MAX(0,G9+G10-G11-Assumptions!$E$16)*Assumptions!$E$25) -> 0 | H12: =MIN(MAX(0,H22+H24),MAX(0,H9+H10-H11-Assumptions!$E$16)*Assumptions!$E$25) -> 0 | I12: =MIN(MAX(0,I22+I24),MAX(0,I9+I10-I11-Assumptions!$E$16)*Assumptions!$E$25) -> 0 | J12: =MIN(MAX(0,J22+J24),MAX(0,J9+J10-J11-Assumptions!$E$16)*Assumptions!$E$25) -> 0
B13: Ending cash | C13: =C5 -> 25 | D13: =D9+D10-D11-D12 -> 25 | E13: =E9+E10-E11-E12 -> 25 | F13: =F9+F10-F11-F12 -> 25 | G13: =G9+G10-G11-G12 -> 25 | H13: =H9+H10-H11-H12 -> 25 | I13: =I9+I10-I11-I12 -> 25 | J13: =J9+J10-J11-J12 -> 25
B14: Beginning revolver | C14: ='Sources & Uses'!F5 -> 0 | D14: =C16 -> 0 | E14: =D16 -> 1.2162 | F14: =E16 -> 5.1196086 | G14: =F16 -> 11.013232 | H14: =G16 -> 18.490202 | I14: =H16 -> 27.33672 | J14: =I16 -> 37.468352
B15: Revolver interest | D15: =D14*Assumptions!$E$18 -> 0 | E15: =E14*Assumptions!$E$18 -> 0.139863 | F15: =F14*Assumptions!$E$18 -> 0.58875499 | G15: =G14*Assumptions!$E$18 -> 1.2665217 | H15: =H14*Assumptions!$E$18 -> 2.1263732 | I15: =I14*Assumptions!$E$18 -> 3.1437229 | J15: =J14*Assumptions!$E$18 -> 4.3088605
B16: Ending revolver | C16: =C14 -> 0 | D16: =MAX(0,D14+D10) -> 1.2162 | E16: =MAX(0,E14+E10) -> 5.1196086 | F16: =MAX(0,F14+F10) -> 11.013232 | G16: =MAX(0,G14+G10) -> 18.490202 | H16: =MAX(0,H14+H10) -> 27.33672 | I16: =MAX(0,I14+I10) -> 37.468352 | J16: =MAX(0,J14+J10) -> 48.834598
B17: Beginning TLB | C17: ='Sources & Uses'!F6 -> 42 | D17: =C21 -> 42 | E17: =D21 -> 41.58 | F17: =E21 -> 41.16 | G17: =F21 -> 40.74 | H17: =G21 -> 40.32 | I17: =H21 -> 39.9 | J17: =I21 -> 39.48
B18: TLB interest | D18: =D17*Assumptions!$E$20 -> 4.41 | E18: =E17*Assumptions!$E$20 -> 4.3659 | F18: =F17*Assumptions!$E$20 -> 4.3218 | G18: =G17*Assumptions!$E$20 -> 4.2777 | H18: =H17*Assumptions!$E$20 -> 4.2336 | I18: =I17*Assumptions!$E$20 -> 4.1895 | J18: =J17*Assumptions!$E$20 -> 4.1454
B19: TLB amortization | D19: =MIN(D17,'Sources & Uses'!$F$6*Assumptions!$E$21) -> 0.42 | E19: =MIN(E17,'Sources & Uses'!$F$6*Assumptions!$E$21) -> 0.42 | F19: =MIN(F17,'Sources & Uses'!$F$6*Assumptions!$E$21) -> 0.42 | G19: =MIN(G17,'Sources & Uses'!$F$6*Assumptions!$E$21) -> 0.42 | H19: =MIN(H17,'Sources & Uses'!$F$6*Assumptions!$E$21) -> 0.42 | I19: =MIN(I17,'Sources & Uses'!$F$6*Assumptions!$E$21) -> 0.42 | J19: =MIN(J17,'Sources & Uses'!$F$6*Assumptions!$E$21) -> 0.42
B20: TLB cash sweep | C20: ='Sources & Uses'!F7 -> 12 | D20: =D11 -> 0 | E20: =E11 -> 0 | F20: =F11 -> 0 | G20: =G11 -> 0 | H20: =H11 -> 0 | I20: =I11 -> 0 | J20: =J11 -> 0
B21: Ending TLB | C21: =C17 -> 42 | D21: =MAX(0,D17-D19-D20) -> 41.58 | E21: =MAX(0,E17-E19-E20) -> 41.16 | F21: =MAX(0,F17-F19-F20) -> 40.74 | G21: =MAX(0,G17-G19-G20) -> 40.32 | H21: =MAX(0,H17-H19-H20) -> 39.9 | I21: =MAX(0,I17-I19-I20) -> 39.48 | J21: =MAX(0,J17-J19-J20) -> 39.06
B22: Beginning second lien | C22: ='Sources & Uses'!F7 -> 12 | D22: =C26 -> 12 | E22: =D26 -> 12.6 | F22: =E26 -> 13.23 | G22: =F26 -> 13.8915 | H22: =G26 -> 14.586075 | I22: =H26 -> 15.315379 | J22: =I26 -> 16.081148
B23: Second-lien cash interest | D23: =D22*Assumptions!$E$23 -> 1.56 | E23: =E22*Assumptions!$E$23 -> 1.638 | F23: =F22*Assumptions!$E$23 -> 1.7199 | G23: =G22*Assumptions!$E$23 -> 1.805895 | H23: =H22*Assumptions!$E$23 -> 1.8961898 | I23: =I22*Assumptions!$E$23 -> 1.9909992 | J23: =J22*Assumptions!$E$23 -> 2.0905492
B24: Second-lien PIK | D24: =D22*Assumptions!$E$24 -> 0.6 | E24: =E22*Assumptions!$E$24 -> 0.63 | F24: =F22*Assumptions!$E$24 -> 0.6615 | G24: =G22*Assumptions!$E$24 -> 0.694575 | H24: =H22*Assumptions!$E$24 -> 0.72930375 | I24: =I22*Assumptions!$E$24 -> 0.76576894 | J24: =J22*Assumptions!$E$24 -> 0.80405738
B25: Second-lien cash sweep | C25: =SUM(C16,C20,C13) -> 37 | D25: =D12 -> 0 | E25: =E12 -> 0 | F25: =F12 -> 0 | G25: =G12 -> 0 | H25: =H12 -> 0 | I25: =I12 -> 0 | J25: =J12 -> 0
B26: Ending second lien | C26: =C22 -> 12 | D26: =MAX(0,D22+D24-D25) -> 12.6 | E26: =MAX(0,E22+E24-E25) -> 13.23 | F26: =MAX(0,F22+F24-F25) -> 13.8915 | G26: =MAX(0,G22+G24-G25) -> 14.586075 | H26: =MAX(0,H22+H24-H25) -> 15.315379 | I26: =MAX(0,I22+I24-I25) -> 16.081148 | J26: =MAX(0,J22+J24-J25) -> 16.885205
B27: Total debt | C27: =SUM(C16,C21,C26) -> 54 | D27: =SUM(D16,D21,D26) -> 55.3962 | E27: =SUM(E16,E21,E26) -> 59.509609 | F27: =SUM(F16,F21,F26) -> 65.644732 | G27: =SUM(G16,G21,G26) -> 73.396277 | H27: =SUM(H16,H21,H26) -> 82.552099 | I27: =SUM(I16,I21,I26) -> 93.0295 | J27: =SUM(J16,J21,J26) -> 104.7798
B28: Net debt | C28: =C27-C13 -> 29 | D28: =D27-D13 -> 30.3962 | E28: =E27-E13 -> 34.509609 | F28: =F27-F13 -> 40.644732 | G28: =G27-G13 -> 48.396277 | H28: =H27-H13 -> 57.552099 | I28: =I27-I13 -> 68.0295 | J28: =J27-J13 -> 79.779803
B29: Revolver commitment fee (undrawn balance) | D29: =MAX(0,Assumptions!$E$17-D14)*Assumptions!$E$33 -> 0.375 | E29: =MAX(0,Assumptions!$E$17-E14)*Assumptions!$E$33 -> 0.368919 | F29: =MAX(0,Assumptions!$E$17-F14)*Assumptions!$E$33 -> 0.34940196 | G29: =MAX(0,Assumptions!$E$17-G14)*Assumptions!$E$33 -> 0.31993384 | H29: =MAX(0,Assumptions!$E$17-H14)*Assumptions!$E$33 -> 0.28254899 | I29: =MAX(0,Assumptions!$E$17-I14)*Assumptions!$E$33 -> 0.2383164 | J29: =MAX(0,Assumptions!$E$17-J14)*Assumptions!$E$33 -> 0.18765824

Sheet Covenants
B2: Lender Covenant and Liquidity Dashboard
B4: Metric | C4: Year 1 | D4: Year 2 | E4: Year 3 | F4: Year 4 | G4: Year 5 | H4: Year 6 | I4: Year 7
B5: Gross leverage | C5: =IFERROR('Debt Schedule'!D25/'Operating Model'!D8,0) -> 0 | D5: =IFERROR('Debt Schedule'!E25/'Operating Model'!E8,0) -> 0 | E5: =IFERROR('Debt Schedule'!F25/'Operating Model'!F8,0) -> 0 | F5: =IFERROR('Debt Schedule'!G25/'Operating Model'!G8,0) -> 0 | G5: =IFERROR('Debt Schedule'!H25/'Operating Model'!H8,0) -> 0 | H5: =IFERROR('Debt Schedule'!I25/'Operating Model'!I8,0) -> 0 | I5: =IFERROR('Debt Schedule'!J25/'Operating Model'!J8,0) -> 0
B6: Maximum leverage | C6: =Assumptions!$E$26 -> 6.5 | D6: =Assumptions!$E$26 -> 6.5 | E6: =Assumptions!$E$26 -> 6.5 | F6: =Assumptions!$E$26 -> 6.5 | G6: =Assumptions!$E$26 -> 6.5 | H6: =Assumptions!$E$26 -> 6.5 | I6: =Assumptions!$E$26 -> 6.5
B7: Leverage headroom | C7: =C6-C5 -> 6.5 | D7: =D6-D5 -> 6.5 | E7: =E6-E5 -> 6.5 | F7: =F6-F5 -> 6.5 | G7: =G6-G5 -> 6.5 | H7: =H6-H5 -> 6.5 | I7: =I6-I5 -> 6.5
B8: Interest coverage | C8: =IFERROR('Operating Model'!D8/'Debt Schedule'!D7,0) -> 1.1397636 | D8: =IFERROR('Operating Model'!E8/'Debt Schedule'!E7,0) -> 0.64835354 | E8: =IFERROR('Operating Model'!F8/'Debt Schedule'!F7,0) -> 0.33700483 | F8: =IFERROR('Operating Model'!G8/'Debt Schedule'!G7,0) -> 0.15813498 | G8: =IFERROR('Operating Model'!H8/'Debt Schedule'!H7,0) -> 0.06294483 | H8: =IFERROR('Operating Model'!I8/'Debt Schedule'!I7,0) -> 0.015939895 | I8: =IFERROR('Operating Model'!J8/'Debt Schedule'!J7,0) -> 0
B9: Minimum coverage | C9: =Assumptions!$E$27 -> 1.5 | D9: =Assumptions!$E$27 -> 1.5 | E9: =Assumptions!$E$27 -> 1.5 | F9: =Assumptions!$E$27 -> 1.5 | G9: =Assumptions!$E$27 -> 1.5 | H9: =Assumptions!$E$27 -> 1.5 | I9: =Assumptions!$E$27 -> 1.5
B10: Coverage headroom | C10: =C8-C9 -> -0.36023641 | D10: =D8-D9 -> -0.85164646 | E10: =E8-E9 -> -1.1629952 | F10: =F8-F9 -> -1.341865 | G10: =G8-G9 -> -1.4370552 | H10: =H8-H9 -> -1.4840601 | I10: =I8-I9 -> -1.5
B11: Minimum cash | C11: =Assumptions!$E$16 -> 25 | D11: =Assumptions!$E$16 -> 25 | E11: =Assumptions!$E$16 -> 25 | F11: =Assumptions!$E$16 -> 25 | G11: =Assumptions!$E$16 -> 25 | H11: =Assumptions!$E$16 -> 25 | I11: =Assumptions!$E$16 -> 25
B12: Cash headroom | C12: ='Debt Schedule'!D13-C11 -> 0 | D12: ='Debt Schedule'!E13-D11 -> 0 | E12: ='Debt Schedule'!F13-E11 -> 0 | F12: ='Debt Schedule'!G13-F11 -> 0 | G12: ='Debt Schedule'!H13-G11 -> 0 | H12: ='Debt Schedule'!I13-H11 -> 0 | I12: ='Debt Schedule'!J13-I11 -> 0
B13: Status | C13: =IF(AND(C7>=0,C10>=0,C12>=0),"PASS","BREACH") -> BREACH | D13: =IF(AND(D7>=0,D10>=0,D12>=0),"PASS","BREACH") -> BREACH | E13: =IF(AND(E7>=0,E10>=0,E12>=0),"PASS","BREACH") -> BREACH | F13: =IF(AND(F7>=0,F10>=0,F12>=0),"PASS","BREACH") -> BREACH | G13: =IF(AND(G7>=0,G10>=0,G12>=0),"PASS","BREACH") -> BREACH | H13: =IF(AND(H7>=0,H10>=0,H12>=0),"PASS","BREACH") -> BREACH | I13: =IF(AND(I7>=0,I10>=0,I12>=0),"PASS","BREACH") -> BREACH

Sheet Management Equity
B2: Management Equity and Incentive Pool
B4: Metric | C4: Value | D4: Units | E4: Notes
B5: Management fully diluted pool | C5: =Assumptions!E30 -> 0.1 | D5: % | E5: granted / reserved pool
B6: Sponsor ownership before pool | C6: =1-C5 -> 0.9 | D6: % | E6: fully diluted
B7: Sponsor invested equity | C7: ='Sources & Uses'!F8 -> 181.7 | D7: $mm | E7: entry equity
B8: Preferred return at exit | C8: =C7*(1+Assumptions!E31)^Assumptions!E29 -> 266.97691 | D8: $mm | E8: sponsor hurdle
B9: Management catch-up rate | C9: =Assumptions!E32 -> 0.2 | D9: % incremental | E9: above preferred return

Sheet Returns Waterfall
B2: Exit Equity and Sponsor / Management Waterfall
B4: Metric | C4: Year 1 | D4: Year 2 | E4: Year 3 | F4: Year 4 | G4: Year 5 | H4: Year 6 | I4: Year 7 | J4: Selected exit
B5: Exit EBITDA | C5: ='Operating Model'!D8 -> 7.2318 | D5: ='Operating Model'!E8 -> 4.2225204 | E5: ='Operating Model'!F8 -> 2.3522455 | F5: ='Operating Model'!G8 -> 1.2129033 | G5: ='Operating Model'!H8 -> 0.53746778 | H5: ='Operating Model'!I8 -> 0.15242586 | I5: ='Operating Model'!J8 -> 0 | J5: =INDEX(C5:I5,1,Assumptions!E29) -> 0.53746778
B6: Exit multiple | C6: =Assumptions!$E$28 -> 8 | D6: =Assumptions!$E$28 -> 8 | E6: =Assumptions!$E$28 -> 8 | F6: =Assumptions!$E$28 -> 8 | G6: =Assumptions!$E$28 -> 8 | H6: =Assumptions!$E$28 -> 8 | I6: =Assumptions!$E$28 -> 8 | J6: =INDEX(C6:I6,1,Assumptions!E29) -> 8
B7: Exit enterprise value | C7: =C5*C6 -> 57.8544 | D7: =D5*D6 -> 33.780163 | E7: =E5*E6 -> 18.817964 | F7: =F5*F6 -> 9.7032264 | G7: =G5*G6 -> 4.2997422 | H7: =H5*H6 -> 1.2194069 | I7: =I5*I6 -> 0 | J7: =INDEX(C7:I7,1,Assumptions!E29) -> 4.2997422
B8: Net debt | C8: ='Debt Schedule'!D28 -> 30.3962 | D8: ='Debt Schedule'!E28 -> 34.509609 | E8: ='Debt Schedule'!F28 -> 40.644732 | F8: ='Debt Schedule'!G28 -> 48.396277 | G8: ='Debt Schedule'!H28 -> 57.552099 | H8: ='Debt Schedule'!I28 -> 68.0295 | I8: ='Debt Schedule'!J28 -> 79.779803 | J8: =INDEX(C8:I8,1,Assumptions!E29) -> 57.552099
B9: Gross equity value | C9: =MAX(0,C7-C8) -> 27.4582 | D9: =MAX(0,D7-D8) -> 0 | E9: =MAX(0,E7-E8) -> 0 | F9: =MAX(0,F7-F8) -> 0 | G9: =MAX(0,G7-G8) -> 0 | H9: =MAX(0,H7-H8) -> 0 | I9: =MAX(0,I7-I8) -> 0 | J9: =INDEX(C9:I9,1,Assumptions!E29) -> 0
B10: Sponsor preferred return | C10: ='Management Equity'!$C$7*(1+Assumptions!$E$31)^1 -> 196.236 | D10: ='Management Equity'!$C$7*(1+Assumptions!$E$31)^2 -> 211.93488 | E10: ='Management Equity'!$C$7*(1+Assumptions!$E$31)^3 -> 228.88967 | F10: ='Management Equity'!$C$7*(1+Assumptions!$E$31)^4 -> 247.20084 | G10: ='Management Equity'!$C$7*(1+Assumptions!$E$31)^5 -> 266.97691 | H10: ='Management Equity'!$C$7*(1+Assumptions!$E$31)^6 -> 288.33506 | I10: ='Management Equity'!$C$7*(1+Assumptions!$E$31)^7 -> 311.40187 | J10: =INDEX(C10:I10,1,Assumptions!E29) -> 266.97691
B11: Equity above preferred | C11: =MAX(0,C9-C10) -> 0 | D11: =MAX(0,D9-D10) -> 0 | E11: =MAX(0,E9-E10) -> 0 | F11: =MAX(0,F9-F10) -> 0 | G11: =MAX(0,G9-G10) -> 0 | H11: =MAX(0,H9-H10) -> 0 | I11: =MAX(0,I9-I10) -> 0 | J11: =INDEX(C11:I11,1,Assumptions!E29) -> 0
B12: Management proceeds | C12: =MIN(C9,C9*Assumptions!$E$30+C11*Assumptions!$E$32) -> 2.74582 | D12: =MIN(D9,D9*Assumptions!$E$30+D11*Assumptions!$E$32) -> 0 | E12: =MIN(E9,E9*Assumptions!$E$30+E11*Assumptions!$E$32) -> 0 | F12: =MIN(F9,F9*Assumptions!$E$30+F11*Assumptions!$E$32) -> 0 | G12: =MIN(G9,G9*Assumptions!$E$30+G11*Assumptions!$E$32) -> 0 | H12: =MIN(H9,H9*Assumptions!$E$30+H11*Assumptions!$E$32) -> 0 | I12: =MIN(I9,I9*Assumptions!$E$30+I11*Assumptions!$E$32) -> 0 | J12: =INDEX(C12:I12,1,Assumptions!E29) -> 0
B13: Sponsor proceeds | C13: =MAX(0,C9-C12) -> 24.71238 | D13: =MAX(0,D9-D12) -> 0 | E13: =MAX(0,E9-E12) -> 0 | F13: =MAX(0,F9-F12) -> 0 | G13: =MAX(0,G9-G12) -> 0 | H13: =MAX(0,H9-H12) -> 0 | I13: =MAX(0,I9-I12) -> 0 | J13: =INDEX(C13:I13,1,Assumptions!E29) -> 0
B14: Sponsor MOIC | C14: =IFERROR(C13/'Sources & Uses'!$F$8,0) -> 0.13600649 | D14: =IFERROR(D13/'Sources & Uses'!$F$8,0) -> 0 | E14: =IFERROR(E13/'Sources & Uses'!$F$8,0) -> 0 | F14: =IFERROR(F13/'Sources & Uses'!$F$8,0) -> 0 | G14: =IFERROR(G13/'Sources & Uses'!$F$8,0) -> 0 | H14: =IFERROR(H13/'Sources & Uses'!$F$8,0) -> 0 | I14: =IFERROR(I13/'Sources & Uses'!$F$8,0) -> 0 | J14: =INDEX(C14:I14,1,Assumptions!E29) -> 0
B15: Sponsor IRR | C15: =IFERROR((C13/'Sources & Uses'!$F$8)^(1/1)-1,0) -> -0.86399351 | D15: =IFERROR((D13/'Sources & Uses'!$F$8)^(1/2)-1,0) -> -1 | E15: =IFERROR((E13/'Sources & Uses'!$F$8)^(1/3)-1,0) -> -1 | F15: =IFERROR((F13/'Sources & Uses'!$F$8)^(1/4)-1,0) -> -1 | G15: =IFERROR((G13/'Sources & Uses'!$F$8)^(1/5)-1,0) -> -1 | H15: =IFERROR((H13/'Sources & Uses'!$F$8)^(1/6)-1,0) -> -1 | I15: =IFERROR((I13/'Sources & Uses'!$F$8)^(1/7)-1,0) -> -1 | J15: =INDEX(C15:I15,1,Assumptions!E29) -> -1

Sheet Sensitivity
B2: Sponsor IRR Sensitivity
B4: Entry / Exit multiple | C4: 7 | D4: 8 | E4: 9 | F4: 10 | G4: 11
B5: 8 | C5: =IFERROR(((('Operating Model'!H8*C$4-'Debt Schedule'!G28)*(1-Assumptions!$E$30))/MAX(0.01,('Operating Model'!C8*$B5+Assumptions!$E$15+'Sources & Uses'!C7+Assumptions!$E$16-'Sources & Uses'!F6-'Sources & Uses'!F7)))^(1/5)-1,0) -> -1.7496271 | D5: =IFERROR(((('Operating Model'!H8*D$4-'Debt Schedule'!G28)*(1-Assumptions!$E$30))/MAX(0.01,('Operating Model'!C8*$B5+Assumptions!$E$15+'Sources & Uses'!C7+Assumptions!$E$16-'Sources & Uses'!F6-'Sources & Uses'!F7)))^(1/5)-1,0) -> -1.747813 | E5: =IFERROR(((('Operating Model'!H8*E$4-'Debt Schedule'!G28)*(1-Assumptions!$E$30))/MAX(0.01,('Operating Model'!C8*$B5+Assumptions!$E$15+'Sources & Uses'!C7+Assumptions!$E$16-'Sources & Uses'!F6-'Sources & Uses'!F7)))^(1/5)-1,0) -> -1.7459811 | F5: =IFERROR(((('Operating Model'!H8*F$4-'Debt Schedule'!G28)*(1-Assumptions!$E$30))/MAX(0.01,('Operating Model'!C8*$B5+Assumptions!$E$15+'Sources & Uses'!C7+Assumptions!$E$16-'Sources & Uses'!F6-'Sources & Uses'!F7)))^(1/5)-1,0) -> -1.7441311 | G5: =IFERROR(((('Operating Model'!H8*G$4-'Debt Schedule'!G28)*(1-Assumptions!$E$30))/MAX(0.01,('Operating Model'!C8*$B5+Assumptions!$E$15+'Sources & Uses'!C7+Assumptions!$E$16-'Sources & Uses'!F6-'Sources & Uses'!F7)))^(1/5)-1,0) -> -1.7422624
B6: 9 | C6: =IFERROR(((('Operating Model'!H8*C$4-'Debt Schedule'!G28)*(1-Assumptions!$E$30))/MAX(0.01,('Operating Model'!C8*$B6+Assumptions!$E$15+'Sources & Uses'!C7+Assumptions!$E$16-'Sources & Uses'!F6-'Sources & Uses'!F7)))^(1/5)-1,0) -> -1.7394532 | D6: =IFERROR(((('Operating Model'!H8*D$4-'Debt Schedule'!G28)*(1-Assumptions!$E$30))/MAX(0.01,('Operating Model'!C8*$B6+Assumptions!$E$15+'Sources & Uses'!C7+Assumptions!$E$16-'Sources & Uses'!F6-'Sources & Uses'!F7)))^(1/5)-1,0) -> -1.7376637 | E6: =IFERROR(((('Operating Model'!H8*E$4-'Debt Schedule'!G28)*(1-Assumptions!$E$30))/MAX(0.01,('Operating Model'!C8*$B6+Assumptions!$E$15+'Sources & Uses'!C7+Assumptions!$E$16-'Sources & Uses'!F6-'Sources & Uses'!F7)))^(1/5)-1,0) -> -1.7358567 | F6: =IFERROR(((('Operating Model'!H8*F$4-'Debt Schedule'!G28)*(1-Assumptions!$E$30))/MAX(0.01,('Operating Model'!C8*$B6+Assumptions!$E$15+'Sources & Uses'!C7+Assumptions!$E$16-'Sources & Uses'!F6-'Sources & Uses'!F7)))^(1/5)-1,0) -> -1.7340317 | G6: =IFERROR(((('Operating Model'!H8*G$4-'Debt Schedule'!G28)*(1-Assumptions!$E$30))/MAX(0.01,('Operating Model'!C8*$B6+Assumptions!$E$15+'Sources & Uses'!C7+Assumptions!$E$16-'Sources & Uses'!F6-'Sources & Uses'!F7)))^(1/5)-1,0) -> -1.7321884
B7: 10 | C7: =IFERROR(((('Operating Model'!H8*C$4-'Debt Schedule'!G28)*(1-Assumptions!$E$30))/MAX(0.01,('Operating Model'!C8*$B7+Assumptions!$E$15+'Sources & Uses'!C7+Assumptions!$E$16-'Sources & Uses'!F6-'Sources & Uses'!F7)))^(1/5)-1,0) -> -1.7300553 | D7: =IFERROR(((('Operating Model'!H8*D$4-'Debt Schedule'!G28)*(1-Assumptions!$E$30))/MAX(0.01,('Operating Model'!C8*$B7+Assumptions!$E$15+'Sources & Uses'!C7+Assumptions!$E$16-'Sources & Uses'!F6-'Sources & Uses'!F7)))^(1/5)-1,0) -> -1.7282885 | E7: =IFERROR(((('Operating Model'!H8*E$4-'Debt Schedule'!G28)*(1-Assumptions!$E$30))/MAX(0.01,('Operating Model'!C8*$B7+Assumptions!$E$15+'Sources & Uses'!C7+Assumptions!$E$16-'Sources & Uses'!F6-'Sources & Uses'!F7)))^(1/5)-1,0) -> -1.7265045 | F7: =IFERROR(((('Operating Model'!H8*F$4-'Debt Schedule'!G28)*(1-Assumptions!$E$30))/MAX(0.01,('Operating Model'!C8*$B7+Assumptions!$E$15+'Sources & Uses'!C7+Assumptions!$E$16-'Sources & Uses'!F6-'Sources & Uses'!F7)))^(1/5)-1,0) -> -1.7247027 | G7: =IFERROR(((('Operating Model'!H8*G$4-'Debt Schedule'!G28)*(1-Assumptions!$E$30))/MAX(0.01,('Operating Model'!C8*$B7+Assumptions!$E$15+'Sources & Uses'!C7+Assumptions!$E$16-'Sources & Uses'!F6-'Sources & Uses'!F7)))^(1/5)-1,0) -> -1.7228829
B8: 11 | C8: =IFERROR(((('Operating Model'!H8*C$4-'Debt Schedule'!G28)*(1-Assumptions!$E$30))/MAX(0.01,('Operating Model'!C8*$B8+Assumptions!$E$15+'Sources & Uses'!C7+Assumptions!$E$16-'Sources & Uses'!F6-'Sources & Uses'!F7)))^(1/5)-1,0) -> -1.7213314 | D8: =IFERROR(((('Operating Model'!H8*D$4-'Debt Schedule'!G28)*(1-Assumptions!$E$30))/MAX(0.01,('Operating Model'!C8*$B8+Assumptions!$E$15+'Sources & Uses'!C7+Assumptions!$E$16-'Sources & Uses'!F6-'Sources & Uses'!F7)))^(1/5)-1,0) -> -1.7195857 | E8: =IFERROR(((('Operating Model'!H8*E$4-'Debt Schedule'!G28)*(1-Assumptions!$E$30))/MAX(0.01,('Operating Model'!C8*$B8+Assumptions!$E$15+'Sources & Uses'!C7+Assumptions!$E$16-'Sources & Uses'!F6-'Sources & Uses'!F7)))^(1/5)-1,0) -> -1.717823 | F8: =IFERROR(((('Operating Model'!H8*F$4-'Debt Schedule'!G28)*(1-Assumptions!$E$30))/MAX(0.01,('Operating Model'!C8*$B8+Assumptions!$E$15+'Sources & Uses'!C7+Assumptions!$E$16-'Sources & Uses'!F6-'Sources & Uses'!F7)))^(1/5)-1,0) -> -1.7160428 | G8: =IFERROR(((('Operating Model'!H8*G$4-'Debt Schedule'!G28)*(1-Assumptions!$E$30))/MAX(0.01,('Operating Model'!C8*$B8+Assumptions!$E$15+'Sources & Uses'!C7+Assumptions!$E$16-'Sources & Uses'!F6-'Sources & Uses'!F7)))^(1/5)-1,0) -> -1.7142446
B9: 12 | C9: =IFERROR(((('Operating Model'!H8*C$4-'Debt Schedule'!G28)*(1-Assumptions!$E$30))/MAX(0.01,('Operating Model'!C8*$B9+Assumptions!$E$15+'Sources & Uses'!C7+Assumptions!$E$16-'Sources & Uses'!F6-'Sources & Uses'!F7)))^(1/5)-1,0) -> -1.7131978 | D9: =IFERROR(((('Operating Model'!H8*D$4-'Debt Schedule'!G28)*(1-Assumptions!$E$30))/MAX(0.01,('Operating Model'!C8*$B9+Assumptions!$E$15+'Sources & Uses'!C7+Assumptions!$E$16-'Sources & Uses'!F6-'Sources & Uses'!F7)))^(1/5)-1,0) -> -1.7114718 | E9: =IFERROR(((('Operating Model'!H8*E$4-'Debt Schedule'!G28)*(1-Assumptions!$E$30))/MAX(0.01,('Operating Model'!C8*$B9+Assumptions!$E$15+'Sources & Uses'!C7+Assumptions!$E$16-'Sources & Uses'!F6-'Sources & Uses'!F7)))^(1/5)-1,0) -> -1.709729 | F9: =IFERROR(((('Operating Model'!H8*F$4-'Debt Schedule'!G28)*(1-Assumptions!$E$30))/MAX(0.01,('Operating Model'!C8*$B9+Assumptions!$E$15+'Sources & Uses'!C7+Assumptions!$E$16-'Sources & Uses'!F6-'Sources & Uses'!F7)))^(1/5)-1,0) -> -1.7079688 | G9: =IFERROR(((('Operating Model'!H8*G$4-'Debt Schedule'!G28)*(1-Assumptions!$E$30))/MAX(0.01,('Operating Model'!C8*$B9+Assumptions!$E$15+'Sources & Uses'!C7+Assumptions!$E$16-'Sources & Uses'!F6-'Sources & Uses'!F7)))^(1/5)-1,0) -> -1.706191

Sheet Checks
B2: LBO Model Checks
B4: Check | C4: Status
B5: Sources equal uses | C5: =IF(ABS('Sources & Uses'!F10)<0.000001,"PASS","FAIL") -> PASS
B6: Sponsor equity positive | C6: =IF('Sources & Uses'!F8>0,"PASS","FAIL") -> PASS
B7: Debt balances nonnegative | C7: =IF(MIN('Debt Schedule'!D15:J25)>=0,"PASS","FAIL") -> PASS
B8: Cash at or above minimum | C8: =IF(MIN('Debt Schedule'!D13:J13)>=Assumptions!E16,"PASS","REVIEW") -> PASS
B9: No covenant breaches | C9: =IF(COUNTIF(Covenants!C13:I13,"BREACH")=0,"PASS","REVIEW") -> REVIEW
B10: Exit equity nonnegative | C10: =IF(MIN('Returns Waterfall'!C9:I9)>=0,"PASS","FAIL") -> PASS
B11: Waterfall conserves equity | C11: =IF(MAX(ABS('Returns Waterfall'!C9:I9-'Returns Waterfall'!C12:I12-'Returns Waterfall'!C13:I13))<0.000001,"PASS","FAIL") -> PASS
B12: Selected exit year valid | C12: =IF(AND(Assumptions!E29>=1,Assumptions!E29<=7),"PASS","FAIL") -> PASS
B13: Overall | C13: =IF(COUNTIF(C5:C12,"FAIL")=0,"PASS","FAIL") -> PASS

Sheet Sources
B2: Source Register
B4: Input / dataset | C4: Source URL or document | D4: As-of | E4: Notes / transformation
B5: Historical financial statements | C5: [filing / data room URL] | D5: [period] | E5: Revenue, margins, capex, working capital, taxes
B6: Quality of earnings and diligence | C6: [advisor report URL] | D6: [date] | E6: EBITDA adjustments, one-time items, risks
B7: Debt term sheets and documentation | C7: [data room URL] | D7: [date] | E7: Rates, PIK, amortization, sweeps, covenants, baskets
B8: Transaction terms | C8: [purchase agreement / process letter] | D8: [date] | E8: Price, fees, minimum cash, rollover, management pool
B9: Market valuation references | C9: [public market / transaction source] | D9: [date] | E9: Entry and exit multiple support
B10: Macy's 2020 Form 10-K | C10: https://www.sec.gov/Archives/edgar/data/794367/000079436721000038/m-20210130.htm | D10: 2021-03-30 | E10: U.S. SEC; frozen curated observation as of case date
B11: Frozen source snapshot | C11: repo://03_Private_Equity/sources/snapshots/pe-public-macys-2020.json | D11: 2021-03-30 | E11: Immutable curated observation package with SHA-256 digest

Sheet RefreshLog
B2: Refresh Log
B4: Date | C4: Trigger | D4: Source snapshot | E4: What changed | F4: Reviewer / challenge | G4: Next check
B5: 2026-08-04 | C5: External historical evidence materialization | D5: repo://03_Private_Equity/sources/snapshots/pe-public-macys-2020.json | E5: Generated public case pe-public-macys-2020 from canonical release template | F5: External historical case; human stakeholder approval remains pending | G5: On source revision, builder change, monitoring breach, or annual review
