Workbook

Sheet Cover
B2: [COMPANY] — Venture Capital Model
B4: Sector: | C4: [fill in]
B5: Current stage: | C5: Seed / A / B / C / Growth
B6: Last refreshed: | C6: 2026-08-04
B7: Next round expected: | C7: [date]
B8: Refresh cadence: | C8: Weekly

Sheet Institutional Surface
B2: Venture Capital — Institutional Decision Surface
B4: Model ID | C4: 13
B5: Domain | C5: Venture Capital
B6: Declared maturity | C6: M2
B7: Canonical builder | C7: tools/builders/build_venture_capital_release.py
B8: Decision arena | C8: investment team, partnership IC, board and portfolio finance
B9: Committee artifact | C9: investment and reserve-allocation memo
B10: Operating cadence | C10: monthly portfolio; event-driven financings; quarterly IC
B12: Key decision outputs
B13: # | C13: Requirement | D13: Owner | E13: Evidence / location | F13: Status
B14: 1 | C14: post-money ownership | F14: OPEN
B15: 2 | C15: SAFE / note conversion | F15: OPEN
B16: 3 | C16: preference and participation waterfall | F16: OPEN
B17: 4 | C17: base, downside and break-even outputs | F17: OPEN
B18: 5 | C18: liquidity / funding requirement and binding constraint | F18: OPEN
B20: Insider questions
B21: # | C21: Requirement | D21: Owner | E21: Evidence / location | F21: Status
B22: 1 | C22: Which security is actually senior? | F22: OPEN
B23: 2 | C23: Who can block the next financing? | F23: OPEN
B24: 3 | C24: What converts before the option-pool top-up? | F24: OPEN
B25: 4 | C25: Which assumption is owner-approved versus modeler judgement? | F25: OPEN
B26: 5 | C26: What fails first and who must act? | F26: OPEN
B28: Scenario families
B29: # | C29: Requirement | D29: Owner | E29: Evidence / location | F29: Status
B30: 1 | C30: down round | F30: OPEN
B31: 2 | C31: bridge with seniority | F31: OPEN
B32: 3 | C32: flat exit preference stack | F32: OPEN
B33: 4 | C33: data freshness / source failure | F33: OPEN
B34: 5 | C34: combined severe-but-plausible downside | F34: OPEN
B36: Primary diligence documents
B37: # | C37: Requirement | D37: Owner | E37: Evidence / location | F37: Status
B38: 1 | C38: charter and cap table | F38: OPEN
B39: 2 | C39: SAFE / note instruments | F39: OPEN
B40: 3 | C40: stock purchase agreement | F40: OPEN
B41: 4 | C41: approved model card and assumption register | F41: OPEN
B42: 5 | C42: independent validation and challenge record | F42: OPEN
B44: Challenge tests
B45: # | C45: Requirement | D45: Owner | E45: Evidence / location | F45: Status
B46: 1 | C46: waterfall conserves proceeds | F46: OPEN
B47: 2 | C47: share count reconciles | F47: OPEN
...

Sheet Challenge Log
B2: Independent Challenge, Override and Closure Log
B4: Date | C4: Reviewer | D4: Challenge | E4: Owner response | F4: Evidence | G4: Impact | H4: Status | I4: Closure
D5: waterfall conserves proceeds | H5: OPEN
D6: share count reconciles | H6: OPEN
D7: SAFE conversion follows instrument terms | H7: OPEN
D8: source-to-model lineage is reproducible | H8: OPEN
D9: units, signs, dates and legal definitions reconcile | H9: OPEN

Sheet Lineage Map
B2: Source, Transformation, Ownership and Refresh Map
B4: Source class | C4: Cadence | D4: Control | E4: System / provider | F4: As-of | G4: Owner | H4: Transform | I4: Downstream | J4: Status
B5: cap table | C5: event-driven | D5: fully diluted share reconciliation | J5: TO MAP
B6: financing instruments | C6: event-driven | D6: conversion and seniority map | J6: TO MAP
B7: model governance evidence | C7: per release | D7: version, reviewer, sign-off and change log | J7: TO MAP
B8: decision-use snapshot | C8: per decision | D8: immutable as-of date and source receipt | J8: TO MAP

Sheet Cap Table
B2: Capitalization Table
B4: Holder / Class | C4: Shares | D4: % Fully Diluted | E4: Price paid/sh | F4: Invested $ | G4: Class
B5: Founders (common) | C5: 0 | D5: =IFERROR(C5/$C$11,"-") -> - | E5: 0 | F5: =C5*E5 -> 0 | G5: Common/Pref
B6: Employee option pool | C6: 0 | D6: =IFERROR(C6/$C$11,"-") -> - | E6: 0 | F6: =C6*E6 -> 0 | G6: Common/Pref
B7: SAFE holders (pre-conversion) | C7: 0 | D7: =IFERROR(C7/$C$11,"-") -> - | E7: 0 | F7: =C7*E7 -> 0 | G7: Common/Pref
B8: Seed preferred | C8: 0 | D8: =IFERROR(C8/$C$11,"-") -> - | E8: 0 | F8: =C8*E8 -> 0 | G8: Common/Pref
B9: Series A preferred | C9: 0 | D9: =IFERROR(C9/$C$11,"-") -> - | E9: 0 | F9: =C9*E9 -> 0 | G9: Common/Pref
B10: Series B preferred | C10: 0 | D10: =IFERROR(C10/$C$11,"-") -> - | E10: 0 | F10: =C10*E10 -> 0 | G10: Common/Pref
B11: Total | C11: =SUM(C5:C10) -> 0 | F11: =SUM(F5:F10) -> 0

Sheet Round Modeling
B2: New Round Modeling
B4: Inputs | E4: Outputs
B5: Pre-money valuation | C5: 0 | E5: Post-money valuation | F5: =C5+C6 -> 0
B6: New money raised | C6: 0 | E6: Price per share | F6: =IFERROR(C5/C8,"-") -> -
B7: New option pool top-up % | C7: 0 | E7: New shares issued (investor) | F7: =IFERROR(C6/F6,"-") -> -
B8: Existing fully diluted shares | C8: 0 | E8: New pool shares (top-up) | F8: =IFERROR(C7*(C8+F7),"-") -> -
E9: Total post-round shares | F9: =IFERROR(C8+F7+F8,"-") -> -
E10: New investor ownership % | F10: =IFERROR(F7/F9,"-") -> -
E11: Existing holder dilution % | F11: =IFERROR(1-C8/F9,"-") -> -

Sheet SAFE Conversion
B2: SAFE / Convertible Note Conversion
B4: SAFE Terms | E4: At Priced Round
B5: SAFE investment amount | C5: 0 | E5: Priced round price/share | F5: ='Round Modeling'!F6 -> -
B6: Valuation cap | C6: 0 | E6: Cap price/share (cap / pre-round FD shares) | F6: =IFERROR(C6/'Round Modeling'!C8,"-") -> -
B7: Discount % | C7: 0 | E7: Discount price/share | F7: =IFERROR(F5*(1-C7),"-") -> -
E8: SAFE conversion price (lower of cap/discount/round) | F8: =IFERROR(MIN(IF(ISNUMBER(F5),F5,9E+099),IF(ISNUMBER(F6),F6,9E+099),IF(ISNUMBER(F7),F7,9E+099)),"-") -> 9e+99
E9: SAFE shares issued | F9: =IFERROR(C5/F8,"-") -> 0

Sheet Comparable Financings
B2: Comparable Financings
B4: Company | C4: Round | D4: Date | E4: Pre-money | F4: Amount raised | G4: Lead investor
B5: [fill in] | C5: [fill in] | D5: [fill in] | E5: 0 | F5: 0 | G5: [fill in]
B6: [fill in] | C6: [fill in] | D6: [fill in] | E6: 0 | F6: 0 | G6: [fill in]
B7: [fill in] | C7: [fill in] | D7: [fill in] | E7: 0 | F7: 0 | G7: [fill in]
B8: [fill in] | C8: [fill in] | D8: [fill in] | E8: 0 | F8: 0 | G8: [fill in]
B9: [fill in] | C9: [fill in] | D9: [fill in] | E9: 0 | F9: 0 | G9: [fill in]
B10: [fill in] | C10: [fill in] | D10: [fill in] | E10: 0 | F10: 0 | G10: [fill in]
B11: [fill in] | C11: [fill in] | D11: [fill in] | E11: 0 | F11: 0 | G11: [fill in]
B12: [fill in] | C12: [fill in] | D12: [fill in] | E12: 0 | F12: 0 | G12: [fill in]

Sheet RefreshLog
B2: Refresh Log
B4: Date | C4: Trigger | D4: What changed | E4: Reviewer notes | F4: Next check
B5: 2026-08-04 | C5: Six-engine frontier release | D5: Applied conventional fixture vc-reference-up-round | E5: Synthetic engineering benchmark; not M4 evidence | F5: On builder, source, contract, or threshold change

Sheet Ownership & Dilution
B2: Post-Money Ownership, Option Pool, and Round Pricing
B4: Metric | C4: Base | D4: Adversarial | E4: Units / control
B5: Pre-money value | C5: 80 | D5: 80
B6: Investment | C6: 20 | D6: 20
B7: Existing shares | C7: 8 | D7: 8
B8: New investor shares | C8: 2 | D8: 2
B9: Option-pool expansion | C9: 0 | D9: 0
B10: Maximum investor ownership | C10: 0.4 | D10: 0.4
B11: Maximum option-pool dilution | C11: 0.2 | D11: 0.2
B15: Post-money value | C15: =C5+C6 -> 100 | D15: =D5+D6 -> 100
B16: Total post-money shares | C16: =C7+C8+C9 -> 10 | D16: =D7+D8+D9 -> 10
B17: Investor ownership | C17: =IFERROR(C8/C16,0) -> 0.2 | D17: =IFERROR(D8/D16,0) -> 0.2
B18: Founder ownership | C18: =IFERROR(C7/C16,0) -> 0.8 | D18: =IFERROR(D7/D16,0) -> 0.8
B19: Option-pool ownership | C19: =IFERROR(C9/C16,0) -> 0 | D19: =IFERROR(D9/D16,0) -> 0
B20: Round price / share | C20: =IFERROR(C6/C8,0) -> 10 | D20: =IFERROR(D6/D8,0) -> 10
B21: Pre-money implied price / share | C21: =IFERROR(C5/C7,0) -> 10 | D21: =IFERROR(D5/D7,0) -> 10

Sheet Reserves & Follow-ons
B2: Follow-On Requirements, Reserves, and Ownership Defense
B4: Metric | C4: Base | D4: Adversarial | E4: Units / control
B5: Follow-on required | C5: 10 | D5: 10
B6: Available reserves | C6: 15 | D6: 15
B7: Pro rata ownership target | C7: 0.2 | D7: 0.2
B8: Next-round size | C8: 40 | D8: 60
B11: Reserve gap | C11: =MAX(0,C5-C6) -> 0 | D11: =MAX(0,D5-D6) -> 0
B12: Pro rata capital required | C12: =C7*C8 -> 8 | D12: =D7*D8 -> 12
B13: Ownership-defense shortfall | C13: =MAX(0,C12-C6) -> 0 | D13: =MAX(0,D12-D6) -> 0

Sheet Exit Waterfall
B2: Exit Proceeds, Investor MOIC, and Return Thresholds
B4: Metric | C4: Base | D4: Adversarial | E4: Units / control
B5: Exit equity value | C5: 500 | D5: 500
B6: Investment cost | C6: 20 | D6: 20
B7: Minimum gross MOIC | C7: 3 | D7: 3
B11: Investor ownership | C11: ='Ownership & Dilution'!C17 -> 0.2 | D11: ='Ownership & Dilution'!D17 -> 0.2
B12: Investor exit proceeds | C12: =C5*C11 -> 100 | D12: =D5*D11 -> 100
B13: Gross MOIC | C13: =IFERROR(C12/C6,0) -> 5 | D13: =IFERROR(D12/D6,0) -> 5

Sheet Decision & Checks
B2: Venture Capital Decision Dashboard and Independent Checks
B4: Check / decision | C4: Metric | D4: Status | E4: Interpretation / action
B5: Post-money identity residual | C5: ='Ownership & Dilution'!D15-'Ownership & Dilution'!D5-'Ownership & Dilution'!D6 -> 0 | D5: =IF(ABS(C5)<0.01,"PASS","FAIL") -> PASS | E5: Post-money value must equal pre-money value plus new investment.
B6: Ownership conservation residual | C6: ='Ownership & Dilution'!D17+'Ownership & Dilution'!D18+'Ownership & Dilution'!D19-1 -> 0 | D6: =IF(ABS(C6)<0.000001,"PASS","FAIL") -> PASS | E6: Investor, founder, and option-pool ownership must sum to one.
B7: Follow-on reserve gap | C7: ='Reserves & Follow-ons'!D11 -> 0 | D7: =IF(C7=0,"PASS","BREACH") -> PASS | E7: Reserves must cover approved follow-on requirements.
B8: Investor ownership | C8: ='Ownership & Dilution'!D17 -> 0.2 | D8: =IF(C8<='Ownership & Dilution'!D10,"PASS","BREACH") -> PASS | E8: Escalate ownership concentration and governance terms.
B9: Option-pool dilution | C9: ='Ownership & Dilution'!D19 -> 0 | D9: =IF(C9<='Ownership & Dilution'!D11,"PASS","BREACH") -> PASS | E9: Pool expansion must remain within the approved dilution boundary.
B10: Round pricing | C10: ='Ownership & Dilution'!D20-'Ownership & Dilution'!D21 -> 0 | D10: =IF(C10>=0,"PASS","BREACH") -> PASS | E10: A negative price delta indicates a down round.
B11: Gross MOIC | C11: ='Exit Waterfall'!D13 -> 5 | D11: =IF(C11>='Exit Waterfall'!D7,"PASS","BREACH") -> PASS | E11: Exit proceeds must clear the approved return threshold.
B13: Overall model status | C13: =IF(COUNTIF(D5:D11,"FAIL")+COUNTIF(D5:D11,"BREACH")>0,"BREACH",IF(COUNTIF(D5:D11,"REVIEW")>0,"REVIEW","PASS")) -> PASS
