Workbook
Name FS_MODEL_ID: 'Institutional Surface'!$C$4
Name FS_DOMAIN: 'Institutional Surface'!$C$5
Name FS_MATURITY: 'Institutional Surface'!$C$6

Sheet Cover
B2: [ISSUER] — Equity Finance, Dilution, and Capital Structure
B4: Issuer / security: | C4: Tesla February 2020 underwritten primary offering
B5: Coverage started: | C5: [date]
B6: Last refreshed: | C6: 2020-02-14
B7: Next financing / shareholder date: | C7: [date]
B8: Refresh cadence: | C8: Weekly
B10: Thesis (2-3 sentences):
B11: [fill in]
B16: COLOR LEGEND
B17: Blue text | C17: Hardcoded input / scenario lever — edit freely
B18: Black text | C18: Formula — do not overwrite
B19: Green text | C19: Link to another sheet in this workbook
B20: Yellow fill | C20: Key assumption — review every refresh

Sheet Institutional Surface
B2: Equity Finance — Institutional Decision Surface
B4: Model ID | C4: 12
B5: Domain | C5: Equity Finance
B6: Declared maturity | C6: M2
B7: Canonical builder | C7: tools/builders/build_equity_finance_release.py
B8: Decision arena | C8: issuer board, ECM, shareholders, counsel and exchange
B9: Committee artifact | C9: capital raise and dilution memo
B10: Operating cadence | C10: daily during offering; quarterly cap table
B12: Key decision outputs
B13: # | C13: Requirement | D13: Owner | E13: Evidence / location | F13: Status
B14: 1 | C14: gross and net proceeds | F14: OPEN
B15: 2 | C15: pro forma ownership and dilution | F15: OPEN
B16: 3 | C16: rights take-up / backstop need | F16: OPEN
B17: 4 | C17: base, downside and break-even outputs | F17: OPEN
B18: 5 | C18: liquidity / funding requirement and binding constraint | F18: OPEN
B20: Insider questions
B21: # | C21: Requirement | D21: Owner | E21: Evidence / location | F21: Status
B22: 1 | C22: What is the real free float after locks? | F22: OPEN
B23: 2 | C23: Who is economically short through hedges? | F23: OPEN
B24: 3 | C24: What is the break price after fees? | F24: OPEN
B25: 4 | C25: Which assumption is owner-approved versus modeler judgement? | F25: OPEN
B26: 5 | C26: What fails first and who must act? | F26: OPEN
B28: Scenario families
B29: # | C29: Requirement | D29: Owner | E29: Evidence / location | F29: Status
B30: 1 | C30: discount and market break | F30: OPEN
B31: 2 | C31: rights under-subscription | F31: OPEN
B32: 3 | C32: convertible dilution | F32: OPEN
B33: 4 | C33: data freshness / source failure | F33: OPEN
B34: 5 | C34: combined severe-but-plausible downside | F34: OPEN
B36: Primary diligence documents
B37: # | C37: Requirement | D37: Owner | E37: Evidence / location | F37: Status
B38: 1 | C38: registration statement / prospectus | F38: OPEN
B39: 2 | C39: underwriting agreement | F39: OPEN
B40: 3 | C40: shareholder register | F40: OPEN
B41: 4 | C41: approved model card and assumption register | F41: OPEN
B42: 5 | C42: independent validation and challenge record | F42: OPEN
B44: Challenge tests
B45: # | C45: Requirement | D45: Owner | E45: Evidence / location | F45: Status
B46: 1 | C46: proceeds reconcile | F46: OPEN
B47: 2 | C47: ownership sums to 100% | F47: OPEN
...

Sheet Challenge Log
B2: Independent Challenge, Override and Closure Log
B4: Date | C4: Reviewer | D4: Challenge | E4: Owner response | F4: Evidence | G4: Impact | H4: Status | I4: Closure
D5: proceeds reconcile | H5: OPEN
D6: ownership sums to 100% | H6: OPEN
D7: dilution includes options and convertibles | H7: OPEN
D8: source-to-model lineage is reproducible | H8: OPEN
D9: units, signs, dates and legal definitions reconcile | H9: OPEN

Sheet Lineage Map
B2: Source, Transformation, Ownership and Refresh Map
B4: Source class | C4: Cadence | D4: Control | E4: System / provider | F4: As-of | G4: Owner | H4: Transform | I4: Downstream | J4: Status
B5: share count | C5: event-driven | D5: basic, diluted and treasury-stock reconciliation | J5: TO MAP
B6: market price and volume | C6: daily | D6: unaffected and VWAP windows | J6: TO MAP
B7: model governance evidence | C7: per release | D7: version, reviewer, sign-off and change log | J7: TO MAP
B8: decision-use snapshot | C8: per decision | D8: immutable as-of date and source receipt | J8: TO MAP

Sheet Assumptions
B2: Assumptions
B4: Driver | C4: FY1 | D4: FY2 | E4: FY3 | F4: FY4 | G4: FY5 | H4: Source / notes
B5: Revenue growth % | C5: 0.445733 | D5: 0.37061 | E5: 0.295487 | F5: 0.220363 | G5: 0.14524 | H5: Source: [10-K/10-Q cite or user estimate]
B6: Gross margin % | C6: 0.165555 | D6: 0.165555 | E6: 0.165555 | F6: 0.165555 | G6: 0.165555 | H6: Source: [10-K/10-Q cite or user estimate]
B7: Opex % of revenue | C7: 0.080723 | D7: 0.080723 | E7: 0.080723 | F7: 0.080723 | G7: 0.080723 | H7: Source: [10-K/10-Q cite or user estimate]
B8: Tax rate % | C8: 0.21 | D8: 0.21 | E8: 0.21 | F8: 0.21 | G8: 0.21 | H8: Source: [10-K/10-Q cite or user estimate]
B9: D&A % of capex | C9: 1.498956 | D9: 1.498956 | E9: 1.498956 | F9: 1.498956 | G9: 1.498956 | H9: Source: [10-K/10-Q cite or user estimate]
B10: Capex % of revenue | C10: 0.058467 | D10: 0.058467 | E10: 0.058467 | F10: 0.058467 | G10: 0.058467 | H10: Source: [10-K/10-Q cite or user estimate]
B11: NWC % of revenue chg | C11: 0.470816 | D11: 0.470816 | E11: 0.470816 | F11: 0.470816 | G11: 0.470816 | H11: Source: [10-K/10-Q cite or user estimate]
B12: Shares outstanding (mm) | C12: ='Cap Table & Dilution'!E19 | D12: ='Cap Table & Dilution'!E19 | E12: ='Cap Table & Dilution'!E19 | F12: ='Cap Table & Dilution'!E19 | G12: ='Cap Table & Dilution'!E19 | H12: Source: [10-K/10-Q cite or user estimate]
B13: WACC % | C13: 0.095 | D13: 0.095 | E13: 0.095 | F13: 0.095 | G13: 0.095 | H13: Source: [10-K/10-Q cite or user estimate]
B14: Terminal growth % | C14: 0.025 | D14: 0.025 | E14: 0.025 | F14: 0.025 | G14: 0.025 | H14: Source: [10-K/10-Q cite or user estimate]

Sheet Cap Table & Dilution
B2: Fully Diluted Cap Table and Ownership Attribution
B3: Active scenario | C3: Base
B4: Metric | C4: Base | D4: Adversarial | E4: Active | F4: Owner / interpretation
B5: Existing common shares | C5: 179.7 | D5: 100 | E5: =IF($C$3="Adversarial",D5,C5) | F5: pre-transaction issued common
B6: In-the-money options / RSUs | C6: 5 | D6: 20 | E6: =IF($C$3="Adversarial",D6,C6) | F6: treasury-stock or approved dilution method
B7: Primary shares issued | C7: 2.65 | D7: 150 | E7: =IF($C$3="Adversarial",D7,C7) | F7: new-money common issuance
B8: Rights shares issued | C8: 0 | D8: 100 | E8: =IF($C$3="Adversarial",D8,C8) | F8: shares issued under rights offering
B9: Convertible principal | C9: 100 | D9: 500 | E9: =IF($C$3="Adversarial",D9,C9) | F9: principal subject to conversion
B10: Conversion price | C10: 10 | D10: 5 | E10: =IF($C$3="Adversarial",D10,C10) | F10: contractual or adjusted conversion price
B11: Primary issue price | C11: 767 | D11: 4 | E11: =IF($C$3="Adversarial",D11,C11) | F11: gross primary price per share
B12: Transaction fees | C12: 40.6 | D12: 20 | E12: =IF($C$3="Adversarial",D12,C12) | F12: underwriting, legal, exchange, and other costs
B13: Maximum existing-holder dilution | C13: 0.35 | D13: 0.35 | E13: =IF($C$3="Adversarial",D13,C13) | F13: approved decision threshold
B14: Maximum option / RSU overhang | C14: 0.1 | D14: 0.1 | E14: =IF($C$3="Adversarial",D14,C14) | F14: options and RSUs / fully diluted shares
B17: Derived outputs
B18: Converted shares | C18: =IFERROR(C9/C10,0) | D18: =IFERROR(D9/D10,0) | E18: =IFERROR(E9/E10,0)
B19: Fully diluted post-money shares | C19: =SUM(C5:C8)+C18 | D19: =SUM(D5:D8)+D18 | E19: =SUM(E5:E8)+E18
B20: Existing common ownership | C20: =IFERROR(C5/C19,0) | D20: =IFERROR(D5/D19,0) | E20: =IFERROR(E5/E19,0)
B21: Existing-holder dilution | C21: =1-C20 | D21: =1-D20 | E21: =1-E20
B22: Option / RSU overhang | C22: =IFERROR(C6/C19,0) | D22: =IFERROR(D6/D19,0) | E22: =IFERROR(E6/E19,0)
B23: Gross primary proceeds | C23: =C7*C11 | D23: =D7*D11 | E23: =E7*E11
B24: Net primary proceeds | C24: =C23-C12 | D24: =D23-D12 | E24: =E23-E12
B25: Share-conservation residual | C25: =C19-C5-C6-C7-C8-C18 | D25: =D19-D5-D6-D7-D8-D18 | E25: =E19-E5-E6-E7-E8-E18
B27: The fully diluted denominator must use the security-specific treasury-stock, if-converted, contingently issuable, and anti-dilution conventions approved for the analysis.

Sheet Rights Offering
B2: Rights Offering Economics and Holder Choices
B4: Metric | C4: Base | D4: Adversarial | E4: Interpretation
B5: Existing shares entitled | C5: ='Cap Table & Dilution'!C5 | D5: ='Cap Table & Dilution'!D5 | E5: record-date eligible shares
B6: Rights shares offered | C6: ='Cap Table & Dilution'!C8 | D6: ='Cap Table & Dilution'!D8 | E6: new shares available through rights
B7: Cum-rights market price | C7: 767 | D7: 10 | E7: unaffected reference price
B8: Subscription price | C8: 767 | D8: 3 | E8: cash exercise price
B9: Expected participation | C9: 1 | D9: 1 | E9: take-up before standby / rump placement
B10: Standby / backstop fee | C10: 0.01176 | D10: 0.08 | E10: % of underwritten proceeds
B13: Theoretical ex-rights price | C13: =IFERROR((C5*C7+C6*C8)/(C5+C6),0) | D13: =IFERROR((D5*D7+D6*D8)/(D5+D6),0)
B14: Theoretical value per right / existing share | C14: =C7-C13 | D14: =D7-D13
B15: Subscription discount | C15: =IFERROR(1-C8/C7,0) | D15: =IFERROR(1-D8/D7,0)
B16: Expected subscribed shares | C16: =C6*C9 | D16: =D6*D9
B17: Expected gross proceeds | C17: =C16*C8 | D17: =D16*D8
B18: Expected standby fee | C18: =(C6-C16)*C8*C10 | D18: =(D6-D16)*D8*D10
B19: Expected net rights proceeds | C19: =C17-C18 | D19: =D17-D18
B21: TERP is a frictionless reference. Actual value depends on trading, eligibility, taxes, participation, backstop terms, execution leakage, and the use of proceeds.

Sheet Convertible Securities
B2: Convertible Security Economics and If-Converted Dilution
B4: Metric | C4: Base | D4: Adversarial | E4: Interpretation
B5: Principal | C5: ='Cap Table & Dilution'!C9 | D5: ='Cap Table & Dilution'!D9 | E5: outstanding principal
B6: Conversion price | C6: ='Cap Table & Dilution'!C10 | D6: ='Cap Table & Dilution'!D10 | E6: post-adjustment conversion price
B7: Current share price | C7: 12 | D7: 4 | E7: market reference
B8: Cash coupon | C8: 0.04 | D8: 0.08 | E8: annual cash interest
B9: Remaining tenor | C9: 3 | D9: 1 | E9: years
B10: Redemption premium | C10: 0.05 | D10: 0.15 | E10: premium to principal at maturity / redemption
B11: Anti-dilution adjusted price | C11: 9.5 | D11: 3.5 | E11: approved modeled adjustment
B14: Contractual converted shares | C14: =IFERROR(C5/C6,0) | D14: =IFERROR(D5/D6,0)
B15: Anti-dilution adjusted shares | C15: =IFERROR(C5/C11,0) | D15: =IFERROR(D5/D11,0)
B16: Conversion value | C16: =C14*C7 | D16: =D14*D7
B17: Redemption value | C17: =C5*(1+C10) | D17: =D5*(1+D10)
B18: Conversion parity | C18: =IFERROR(C16/C5,0) | D18: =IFERROR(D16/D5,0)
B19: Incremental anti-dilution shares | C19: =C15-C14 | D19: =D15-D14
B20: Annual cash coupon | C20: =C5*C8 | D20: =D5*D8
B22: This sheet models if-converted economics, not the full value of optionality. Call features, soft calls, resets, make-wholes, caps, floors, and settlement elections require explicit terms.

Sheet Decision & Checks
B2: Equity Finance Decision Dashboard and Independent Checks
B4: Check / decision | C4: Metric | D4: Status | E4: Interpretation / action
B5: Share-conservation residual | C5: ='Cap Table & Dilution'!E25 | D5: =IF(ABS(C5)<0.000001,"PASS","FAIL") | E5: Fully diluted shares must reconcile to every issued and contingently issuable security.
B6: Ownership / dilution identity | C6: ='Cap Table & Dilution'!E20+'Cap Table & Dilution'!E21-1 | D6: =IF(ABS(C6)<0.000001,"PASS","FAIL") | E6: Existing ownership plus dilution must equal one.
B7: Existing-holder dilution | C7: ='Cap Table & Dilution'!E21 | D7: =IF(C7<='Cap Table & Dilution'!E13,"PASS","BREACH") | E7: A financing that exceeds approved dilution requires explicit board and shareholder analysis.
B8: Option / RSU overhang | C8: ='Cap Table & Dilution'!E22 | D8: =IF(C8<='Cap Table & Dilution'!E14,"PASS","REVIEW") | E8: Track employee, acquisition, and contingent-equity dilution separately.
B9: Net primary proceeds | C9: ='Cap Table & Dilution'!E24 | D9: =IF(C9>=0,"PASS","BREACH") | E9: Fees and discounts may not exceed gross proceeds.
B10: Rights TERP residual | C10: ='Rights Offering'!C13-(('Rights Offering'!C5*'Rights Offering'!C7+'Rights Offering'!C6*'Rights Offering'!C8)/('Rights Offering'!C5+'Rights Offering'!C6)) | D10: =IF(ABS(C10)<0.000001,"PASS","FAIL") | E10: TERP must reconcile from old and new shares and their respective prices.
B11: Rights value | C11: ='Rights Offering'!C14 | D11: =IF(C11>=0,"PASS","REVIEW") | E11: Negative theoretical right value indicates inconsistent market or subscription inputs.
B12: Adversarial rights participation | C12: ='Rights Offering'!D9 | D12: =IF(C12>=0.75,"PASS",IF(C12>=0.50,"REVIEW","BREACH")) | E12: Low participation creates rump-placement, backstop, execution, and control risk.
B13: Converted-share reconciliation | C13: ='Convertible Securities'!C14-'Cap Table & Dilution'!C18 | D13: =IF(ABS(C13)<0.000001,"PASS","FAIL") | E13: Cap table and convertible schedule must use the same principal and conversion price.
B14: Incremental anti-dilution shares | C14: ='Convertible Securities'!D19 | D14: =IF(C14<=0,"PASS","REVIEW") | E14: Reset and anti-dilution provisions can materially expand fully diluted shares in downside cases.
B16: Overall model status | C16: =IF(COUNTIF(D5:D14,"FAIL")+COUNTIF(D5:D14,"BREACH")>0,"BREACH",IF(COUNTIF(D5:D14,"REVIEW")>0,"REVIEW","PASS"))
B18: Primary decision outputs
B19: Fully diluted shares | C19: ='Cap Table & Dilution'!E19
B20: Existing-holder dilution | C20: ='Cap Table & Dilution'!E21
B21: Net primary proceeds | C21: ='Cap Table & Dilution'!E24
B22: Base TERP | C22: ='Rights Offering'!C13
B23: Expected net rights proceeds | C23: ='Rights Offering'!C19
B24: Contractual converted shares | C24: ='Convertible Securities'!C14
B25: Adversarial anti-dilution shares | C25: ='Convertible Securities'!D15
B26: Adversarial redemption value | C26: ='Convertible Securities'!D17

Sheet IS
B2: Income Statement ($mm)
B4: Line item | C4: FY-2A | D4: FY-1A | E4: FY0A | F4: FY1E | G4: FY2E | H4: FY3E | I4: FY4E
B5: Revenue | C5: 11759 | D5: 21461 | E5: 24578 | F5: =E5*(1+Assumptions!C5) | G5: =F5*(1+Assumptions!D5) | H5: =G5*(1+Assumptions!E5) | I5: =H5*(1+Assumptions!F5)
B6: Revenue growth % | D6: =IFERROR(D5/C5-1,"-") | E6: =IFERROR(E5/D5-1,"-") | F6: =IFERROR(F5/E5-1,"-") | G6: =IFERROR(G5/F5-1,"-") | H6: =IFERROR(H5/G5-1,"-") | I6: =IFERROR(I5/H5-1,"-")
B7: COGS | C7: 9536 | D7: 17419 | E7: 20509 | F7: =F5*(1-Assumptions!C6) | G7: =G5*(1-Assumptions!D6) | H7: =H5*(1-Assumptions!E6) | I7: =I5*(1-Assumptions!F6)
B8: Gross profit | C8: =C5-C7 | D8: =D5-D7 | E8: =E5-E7 | F8: =F5-F7 | G8: =G5-G7 | H8: =H5-H7 | I8: =I5-I7
B9: Gross margin % | C9: =IFERROR(C8/C5,"-") | D9: =IFERROR(D8/D5,"-") | E9: =IFERROR(E8/E5,"-") | F9: =IFERROR(F8/F5,"-") | G9: =IFERROR(G8/G5,"-") | H9: =IFERROR(H8/H5,"-") | I9: =IFERROR(I8/I5,"-")
B10: Opex | C10: 2219 | D10: 2529 | E10: 1984 | F10: =F5*Assumptions!C7 | G10: =G5*Assumptions!D7 | H10: =H5*Assumptions!E7 | I10: =I5*Assumptions!F7
B11: EBITDA | C11: =C8-C10 | D11: =D8-D10 | E11: =E8-E10 | F11: =F8-F10 | G11: =G8-G10 | H11: =H8-H10 | I11: =I8-I10
B12: EBITDA margin % | C12: =IFERROR(C11/C5,"-") | D12: =IFERROR(D11/D5,"-") | E12: =IFERROR(E11/E5,"-") | F12: =IFERROR(F11/F5,"-") | G12: =IFERROR(G11/G5,"-") | H12: =IFERROR(H11/H5,"-") | I12: =IFERROR(I11/I5,"-")
B13: D&A | C13: 1636 | D13: 1901 | E13: 2154 | F13: =F5*Assumptions!C10*Assumptions!C9 | G13: =G5*Assumptions!D10*Assumptions!D9 | H13: =H5*Assumptions!E10*Assumptions!E9 | I13: =I5*Assumptions!F10*Assumptions!F9
B14: EBIT | C14: =C11-C13 | D14: =D11-D13 | E14: =E11-E13 | F14: =F11-F13 | G14: =G11-G13 | H14: =H11-H13 | I14: =I11-I13
B15: Interest expense | C15: 471 | D15: 663 | E15: 685 | F15: =$E$15 | G15: =$E$15 | H15: =$E$15 | I15: =$E$15
B16: Pre-tax income | C16: =C14-C15 | D16: =D14-D15 | E16: =E14-E15 | F16: =F14-F15 | G16: =G14-G15 | H16: =H14-H15 | I16: =I14-I15
B17: Tax | C17: 32 | D17: 58 | E17: 110 | F17: =F16*Assumptions!C8 | G17: =G16*Assumptions!D8 | H17: =H16*Assumptions!E8 | I17: =I16*Assumptions!F8
B18: Net income | C18: =C16-C17 | D18: =D16-D17 | E18: =E16-E17 | F18: =F16-F17 | G18: =G16-G17 | H18: =H16-H17 | I18: =I16-I17
B19: Diluted shares | C19: 168.8 | D19: 173 | E19: 179.7 | F19: =Assumptions!C12 | G19: =Assumptions!D12 | H19: =Assumptions!E12 | I19: =Assumptions!F12
B20: Diluted EPS | C20: =IFERROR(C18/C19,"-") | D20: =IFERROR(D18/D19,"-") | E20: =IFERROR(E18/E19,"-") | F20: =IFERROR(F18/F19,"-") | G20: =IFERROR(G18/G19,"-") | H20: =IFERROR(H18/H19,"-") | I20: =IFERROR(I18/I19,"-")

Sheet BS
B2: Balance Sheet ($mm)
B4: Line item | C4: FY-1A | D4: FY0A | E4: FY1E | F4: FY2E | G4: FY3E
B5: Cash & equivalents
B6: Accounts receivable
B7: Inventory
B8: Total current assets | C8: =C5+C6+C7 | D8: =D5+D6+D7 | E8: =E5+E6+E7 | F8: =F5+F6+F7 | G8: =G5+G6+G7
B9: PP&E net
B10: Goodwill & intangibles
B11: Total assets | C11: =C8+C9+C10 | D11: =D8+D9+D10 | E11: =E8+E9+E10 | F11: =F8+F9+F10 | G11: =G8+G9+G10
B12: Accounts payable
B13: Debt (current)
B14: Total current liabilities | C14: =C12+C13 | D14: =D12+D13 | E14: =E12+E13 | F14: =F12+F13 | G14: =G12+G13
B15: Long-term debt
B16: Total liabilities | C16: =C14+C15 | D16: =D14+D15 | E16: =E14+E15 | F16: =F14+F15 | G16: =G14+G15
B17: Total equity
B19: Balance check (Total assets - Total liabilities - Total equity, should = 0) | C19: =C11-C16-C17 | D19: =D11-D16-D17 | E19: =E11-E16-E17 | F19: =F11-F16-F17 | G19: =G11-G16-G17

Sheet CF
B2: Cash Flow ($mm)
B4: Line item | C4: FY-1A | D4: FY0A | E4: FY1E | F4: FY2E | G4: FY3E
B5: Net income | E5: =IS!F18 | F5: =IS!G18 | G5: =IS!H18
B6: + D&A | E6: =IS!F13 | F6: =IS!G13 | G6: =IS!H13
B7: +/- Change in NWC
B8: Cash flow from operations | C8: =C5+C6+C7 | D8: =D5+D6+D7 | E8: =E5+E6+E7 | F8: =F5+F6+F7 | G8: =G5+G6+G7
B9: Capex
B10: Free cash flow | C10: =C8+C9 | D10: =D8+D9 | E10: =E8+E9 | F10: =F8+F9 | G10: =G8+G9
B11: Debt issuance/(repayment)
B12: Dividends/buybacks
B13: Net change in cash | C13: =C10+C11+C12 | D13: =D10+D11+D12 | E13: =E10+E11+E12 | F13: =F10+F11+F12 | G13: =G10+G11+G12

Sheet DCF
B2: DCF Valuation
C4: FY1E | D4: FY2E | E4: FY3E | F4: FY4E | G4: FY5E | H4: Key outputs
B5: Unlevered FCF | C5: =IS!F14*(1-Assumptions!C8)+IS!F13-IS!F5*Assumptions!C10 | D5: =IS!G14*(1-Assumptions!D8)+IS!G13-IS!G5*Assumptions!D10 | E5: =IS!H14*(1-Assumptions!E8)+IS!H13-IS!H5*Assumptions!E10 | F5: =IS!I14*(1-Assumptions!F8)+IS!I13-IS!I5*Assumptions!F10 | G5: =F5*(1+Assumptions!G5) | H5: WACC | I5: 0.095
B6: Discount factor | C6: =1/(1+$I$5)^(1) | D6: =1/(1+$I$5)^(2) | E6: =1/(1+$I$5)^(3) | F6: =1/(1+$I$5)^(4) | G6: =1/(1+$I$5)^(5) | H6: Terminal growth | I6: 0.025
B7: PV of FCF | C7: =C5*C6 | D7: =D5*D6 | E7: =E5*E6 | F7: =F5*F6 | G7: =G5*G6 | H7: Terminal value | I7: =G5*(1+I6)/(I5-I6)
H8: PV of terminal value | I8: =I7*G6
H9: Sum PV of FCF | I9: =SUM(C7:G7)
H10: Enterprise value | I10: =I8+I9
H11: Less: net debt | I11: -6105
H12: Equity value | I12: =I10-I11
H13: Diluted shares (mm) | I13: 179.7
H14: Implied value/share | I14: =I12/I13

Sheet Comps
B2: Comparable Companies
B4: Ticker | C4: Price | D4: Mkt Cap | E4: EV | F4: EV/Rev | G4: EV/EBITDA | H4: P/E
B5: [TICKER] | C5: 0 | D5: 0 | E5: 0 | F5: 0 | G5: 0 | H5: 0
B6: [TICKER] | C6: 0 | D6: 0 | E6: 0 | F6: 0 | G6: 0 | H6: 0
B7: [TICKER] | C7: 0 | D7: 0 | E7: 0 | F7: 0 | G7: 0 | H7: 0
B8: [TICKER] | C8: 0 | D8: 0 | E8: 0 | F8: 0 | G8: 0 | H8: 0
B9: [TICKER] | C9: 0 | D9: 0 | E9: 0 | F9: 0 | G9: 0 | H9: 0
B10: [TICKER] | C10: 0 | D10: 0 | E10: 0 | F10: 0 | G10: 0 | H10: 0
B11: [TICKER] | C11: 0 | D11: 0 | E11: 0 | F11: 0 | G11: 0 | H11: 0
B13: Median | C13: =MEDIAN(C5:C12) | D13: =MEDIAN(D5:D12) | E13: =MEDIAN(E5:E12) | F13: =MEDIAN(F5:F12) | G13: =MEDIAN(G5:G12) | H13: =MEDIAN(H5:H12)

Sheet Sensitivity
B2: Sensitivity — Implied Value/Share
B4: WACC \ Term. growth | C4: 0.015 | D4: 0.02 | E4: 0.025 | F4: 0.03 | G4: 0.035
B5: 0.08 | C5: [data table — Excel What-If Analysis] | D5: [data table — Excel What-If Analysis] | E5: [data table — Excel What-If Analysis] | F5: [data table — Excel What-If Analysis] | G5: [data table — Excel What-If Analysis]
B6: 0.09 | C6: [data table — Excel What-If Analysis] | D6: [data table — Excel What-If Analysis] | E6: [data table — Excel What-If Analysis] | F6: [data table — Excel What-If Analysis] | G6: [data table — Excel What-If Analysis]
B7: 0.1 | C7: [data table — Excel What-If Analysis] | D7: [data table — Excel What-If Analysis] | E7: [data table — Excel What-If Analysis] | F7: [data table — Excel What-If Analysis] | G7: [data table — Excel What-If Analysis]
B8: 0.11 | C8: [data table — Excel What-If Analysis] | D8: [data table — Excel What-If Analysis] | E8: [data table — Excel What-If Analysis] | F8: [data table — Excel What-If Analysis] | G8: [data table — Excel What-If Analysis]
B9: 0.12 | C9: [data table — Excel What-If Analysis] | D9: [data table — Excel What-If Analysis] | E9: [data table — Excel What-If Analysis] | F9: [data table — Excel What-If Analysis] | G9: [data table — Excel What-If Analysis]

Sheet RefreshLog
B2: Refresh Log
B4: Date | C4: Trigger | D4: What changed | E4: Reviewer notes | F4: Next check
B5: 2026-10-01 | C5: Historical actuals block filled after the BASE template fix | D5: The BASE template's income-statement historical block carried no input marker and no derived formulas, so the income statement, the DCF, and diluted EPS all evaluated to zero. With the template fixed, this fills FY2017-FY2019 revenue, cost of revenue, operating expense, depreciation and amortisation, interest, tax, and share count. Depreciation comes from the cash flow statement rather than EDGAR, because Tesla tagged EDGAR's D&A concept in one filing only and with a narrower figure. With D&A real and taken out of the operating expense row, the EBITDA line is a real EBITDA and EBIT ties exactly to the disclosed operating income in all three years. | E5: External historical case; human stakeholder approval remains pending. Read three things before using any number here. First, the share counts are period-end outstanding rather than weighted diluted, which understates earnings per share. Second, the forward D&A driver is the product of a capex ratio and a D&A-to-capex ratio, and the second of those is unstable across the window; the pair is set so the product ties to D&A as a share of revenue, which is stable, and the two rows must be read together. Third, the discounted cash flow values the equity at roughly a quarter of the price the February 2020 offering actually cleared at. That is not a defect in the arithmetic. It is what a cash flow model built on Tesla's FY2019 operating margins produces, and the gap between the two was the whole argument about Tesla at the time. The case exists to show the offering mechanics, not to settle that argument. | F5: On builder change or annual review
