Workbook

Sheet Cover
B2: [TARGET] — LBO Underwriting Model
B4: Target / transaction: | C4: WeWork Inc. -- pre-bankruptcy holdco stress (adversarial case)
B5: Sponsor / principal: | C5: [Fund / merchant bank]
B6: Entry / close date: | C6: [date]
B7: Last refreshed: | C7: 2023-03-29
B8: Next IC / financing event: | C8: [date]
B9: Active scenario: | C9: Downside
B10: Units: | C10: $ in millions unless noted
B13: Modeling conventions
B14: Blue text / yellow fill | C14: Hardcoded input or selected scenario
B15: Black text | C15: Formula / same-sheet calculation
B16: Green text | C16: Cross-sheet formula / link
B17: Checks | C17: PASS / REVIEW / FAIL must remain visible

Sheet Institutional Surface
B2: Merchant Banking — Institutional Decision Surface
B4: Model ID | C4: 04
B5: Domain | C5: Merchant Banking
B6: Declared maturity | C6: M2
B7: Canonical builder | C7: tools/builders/build_lbo_release.py
B8: Decision arena | C8: principal investing committee, client coverage, financing partners and risk committee
B9: Committee artifact | C9: principal-and-advisory conflicts pack
B10: Operating cadence | C10: daily live transactions; weekly risk; monthly portfolio
B12: Key decision outputs
B13: # | C13: Requirement | D13: Owner | E13: Evidence / location | F13: Status
B14: 1 | C14: risk-adjusted principal return | F14: OPEN
B15: 2 | C15: client economics and fee offsets | F15: OPEN
B16: 3 | C16: holdco / opco value and leakage | F16: OPEN
B17: 4 | C17: base, downside and break-even outputs | F17: OPEN
B18: 5 | C18: liquidity / funding requirement and binding constraint | F18: OPEN
B20: Insider questions
B21: # | C21: Requirement | D21: Owner | E21: Evidence / location | F21: Status
B22: 1 | C22: Who owns the paper if distribution fails? | F22: OPEN
B23: 2 | C23: Which economics are contractual versus relationship assumptions? | F23: OPEN
B24: 3 | C24: Where can holdco cash be trapped? | F24: OPEN
B25: 4 | C25: Which assumption is owner-approved versus modeler judgement? | F25: OPEN
B26: 5 | C26: What fails first and who must act? | F26: OPEN
B28: Scenario families
B29: # | C29: Requirement | D29: Owner | E29: Evidence / location | F29: Status
B30: 1 | C30: client loss / failed process | F30: OPEN
B31: 2 | C31: underwriting take-down | F31: OPEN
B32: 3 | C32: holdco leakage | F32: OPEN
B33: 4 | C33: data freshness / source failure | F33: OPEN
B34: 5 | C34: combined severe-but-plausible downside | F34: OPEN
B36: Primary diligence documents
B37: # | C37: Requirement | D37: Owner | E37: Evidence / location | F37: Status
B38: 1 | C38: engagement letters | F38: OPEN
B39: 2 | C39: conflicts memorandum | F39: OPEN
B40: 3 | C40: financing and syndication papers | F40: OPEN
B41: 4 | C41: approved model card and assumption register | F41: OPEN
B42: 5 | C42: independent validation and challenge record | F42: OPEN
B44: Challenge tests
B45: # | C45: Requirement | D45: Owner | E45: Evidence / location | F45: Status
B46: 1 | C46: principal and advisory cash flows separated | F46: OPEN
B47: 2 | C47: fees not double-counted in returns | F47: OPEN
...

Sheet Challenge Log
B2: Independent Challenge, Override and Closure Log
B4: Date | C4: Reviewer | D4: Challenge | E4: Owner response | F4: Evidence | G4: Impact | H4: Status | I4: Closure
D5: principal and advisory cash flows separated | H5: OPEN
D6: fees not double-counted in returns | H6: OPEN
D7: legal-entity exposure reconciles | H7: OPEN
D8: source-to-model lineage is reproducible | H8: OPEN
D9: units, signs, dates and legal definitions reconcile | H9: OPEN

Sheet Lineage Map
B2: Source, Transformation, Ownership and Refresh Map
B4: Source class | C4: Cadence | D4: Control | E4: System / provider | F4: As-of | G4: Owner | H4: Transform | I4: Downstream | J4: Status
B5: client pipeline | C5: weekly | D5: engagement status and probability | J5: TO MAP
B6: principal exposure | C6: daily/weekly | D6: legal-entity and concentration mapping | J6: TO MAP
B7: model governance evidence | C7: per release | D7: version, reviewer, sign-off and change log | J7: TO MAP
B8: decision-use snapshot | C8: per decision | D8: immutable as-of date and source receipt | J8: TO MAP

Sheet Assumptions
B2: Transaction, Operating, and Financing Assumptions
B4: Assumption | C4: Base | D4: Downside | E4: Active | F4: Units / note
B5: LTM revenue | C5: 600 | D5: 600 | E5: =IF(Cover!$C$9="Downside",D5,C5) -> 600 | F5: $mm
B6: LTM EBITDA margin | C6: 0.2 | D6: 0.17 | E6: =IF(Cover!$C$9="Downside",D6,C6) -> 0.17 | F6: %
B7: Annual revenue growth | C7: 0.06 | D7: -0.25 | E7: =IF(Cover!$C$9="Downside",D7,C7) -> -0.25 | F7: %
B8: Annual EBITDA margin expansion | C8: 0.005 | D8: -0.003 | E8: =IF(Cover!$C$9="Downside",D8,C8) -> -0.003 | F8: % points
B9: D&A / revenue | C9: 0.025 | D9: 0.025 | E9: =IF(Cover!$C$9="Downside",D9,C9) -> 0.025 | F9: %
B10: Capex / revenue | C10: 0.035 | D10: 0.045 | E10: =IF(Cover!$C$9="Downside",D10,C10) -> 0.045 | F10: %
B11: NWC / revenue | C11: 0.08 | D11: 0.1 | E11: =IF(Cover!$C$9="Downside",D11,C11) -> 0.1 | F11: %
B12: Cash tax rate | C12: 0.25 | D12: 0.2 | E12: =IF(Cover!$C$9="Downside",D12,C12) -> 0.2 | F12: %
B13: Entry EBITDA multiple | C13: 10 | D13: 9 | E13: =IF(Cover!$C$9="Downside",D13,C13) -> 9 | F13: x
B14: Transaction fees / enterprise value | C14: 0.02 | D14: 0.025 | E14: =IF(Cover!$C$9="Downside",D14,C14) -> 0.025 | F14: %
B15: Existing net debt refinanced | C15: 100 | D15: 100 | E15: =IF(Cover!$C$9="Downside",D15,C15) -> 100 | F15: $mm
B16: Minimum cash | C16: 20 | D16: 25 | E16: =IF(Cover!$C$9="Downside",D16,C16) -> 25 | F16: $mm
... B32: Management catch-up above hurdle | C32: 0.2 | D32: 0.2 | E32: =IF(Cover!$C$9="Downside",D32,C32) -> 0.2 | F32: % incremental

Sheet Sources & Uses
B2: Transaction Sources & Uses
B4: Uses | C4: Amount | E4: Sources | F4: Amount
B5: Purchase enterprise value | C5: =Assumptions!E5*Assumptions!E6*Assumptions!E13 -> 918 | E5: Revolver at close | F5: 0
B6: Refinance existing net debt | C6: =Assumptions!E15 -> 100 | E6: Term loan B | F6: =Assumptions!E5*Assumptions!E6*Assumptions!E19 -> 357
B7: Transaction fees | C7: =C5*Assumptions!E14 -> 22.95 | E7: Second-lien / holdco debt | F7: =Assumptions!E5*Assumptions!E6*Assumptions!E22 -> 102
B8: Minimum cash funded | C8: =Assumptions!E16 -> 25 | E8: Sponsor equity | F8: =C9-SUM(F5:F7) -> 606.95
B9: Total uses | C9: =SUM(C5:C8) -> 1065.95 | E9: Total sources | F9: =SUM(F5:F8) -> 1065.95
E10: Sources less uses | F10: =F9-C9 -> 0

Sheet Operating Model
B2: Seven-Year Operating, Tax, and Cash Flow Model
B4: $mm / % | C4: LTM | D4: Year 1 | E4: Year 2 | F4: Year 3 | G4: Year 4 | H4: Year 5 | I4: Year 6 | J4: Year 7
B5: Revenue | C5: =Assumptions!E5 -> 600 | D5: =C5*(1+Assumptions!$E$7) -> 450 | E5: =D5*(1+Assumptions!$E$7) -> 337.5 | F5: =E5*(1+Assumptions!$E$7) -> 253.125 | G5: =F5*(1+Assumptions!$E$7) -> 189.84375 | H5: =G5*(1+Assumptions!$E$7) -> 142.38281 | I5: =H5*(1+Assumptions!$E$7) -> 106.78711 | J5: =I5*(1+Assumptions!$E$7) -> 80.090332
B6: Revenue growth | D6: =IFERROR(D5/C5-1,0) -> -0.25 | E6: =IFERROR(E5/D5-1,0) -> -0.25 | F6: =IFERROR(F5/E5-1,0) -> -0.25 | G6: =IFERROR(G5/F5-1,0) -> -0.25 | H6: =IFERROR(H5/G5-1,0) -> -0.25 | I6: =IFERROR(I5/H5-1,0) -> -0.25 | J6: =IFERROR(J5/I5-1,0) -> -0.25
B7: EBITDA margin | C7: =Assumptions!E6 -> 0.17 | D7: =MAX(0,MIN(0.6,C7+Assumptions!$E$8)) -> 0.167 | E7: =MAX(0,MIN(0.6,D7+Assumptions!$E$8)) -> 0.164 | F7: =MAX(0,MIN(0.6,E7+Assumptions!$E$8)) -> 0.161 | G7: =MAX(0,MIN(0.6,F7+Assumptions!$E$8)) -> 0.158 | H7: =MAX(0,MIN(0.6,G7+Assumptions!$E$8)) -> 0.155 | I7: =MAX(0,MIN(0.6,H7+Assumptions!$E$8)) -> 0.152 | J7: =MAX(0,MIN(0.6,I7+Assumptions!$E$8)) -> 0.149
B8: EBITDA | C8: =C5*C7 -> 102 | D8: =D5*D7 -> 75.15 | E8: =E5*E7 -> 55.35 | F8: =F5*F7 -> 40.753125 | G8: =G5*G7 -> 29.995313 | H8: =H5*H7 -> 22.069336 | I8: =I5*I7 -> 16.231641 | J8: =J5*J7 -> 11.933459
B9: D&A | C9: =C5*Assumptions!E9 -> 15 | D9: =D5*Assumptions!$E$9 -> 11.25 | E9: =E5*Assumptions!$E$9 -> 8.4375 | F9: =F5*Assumptions!$E$9 -> 6.328125 | G9: =G5*Assumptions!$E$9 -> 4.7460938 | H9: =H5*Assumptions!$E$9 -> 3.5595703 | I9: =I5*Assumptions!$E$9 -> 2.6696777 | J9: =J5*Assumptions!$E$9 -> 2.0022583
B10: EBIT | C10: =C8-C9 -> 87 | D10: =D8-D9 -> 63.9 | E10: =E8-E9 -> 46.9125 | F10: =F8-F9 -> 34.425 | G10: =G8-G9 -> 25.249219 | H10: =H8-H9 -> 18.509766 | I10: =I8-I9 -> 13.561963 | J10: =J8-J9 -> 9.9312012
B11: Cash interest | D11: ='Debt Schedule'!D7 -> 65.025 | E11: ='Debt Schedule'!E7 -> 65.033325 | F11: ='Debt Schedule'!F7 -> 67.14913 | G11: ='Debt Schedule'!G7 -> 71.145911 | H11: ='Debt Schedule'!H7 -> 74.293303 | I11: ='Debt Schedule'!I7 -> 74.579078 | J11: ='Debt Schedule'!J7 -> 74.905025
B12: EBT | D12: =D10-D11 -> -1.125 | E12: =E10-E11 -> -18.120825 | F12: =F10-F11 -> -32.724131 | G12: =G10-G11 -> -45.896693 | H12: =H10-H11 -> -55.783537 | I12: =I10-I11 -> -61.017115 | J12: =J10-J11 -> -64.973824
B13: Cash taxes | D13: =MAX(0,D12*Assumptions!$E$12) -> 0 | E13: =MAX(0,E12*Assumptions!$E$12) -> 0 | F13: =MAX(0,F12*Assumptions!$E$12) -> 0 | G13: =MAX(0,G12*Assumptions!$E$12) -> 0 | H13: =MAX(0,H12*Assumptions!$E$12) -> 0 | I13: =MAX(0,I12*Assumptions!$E$12) -> 0 | J13: =MAX(0,J12*Assumptions!$E$12) -> 0
B14: Net income | D14: =D12-D13 -> -1.125 | E14: =E12-E13 -> -18.120825 | F14: =F12-F13 -> -32.724131 | G14: =G12-G13 -> -45.896693 | H14: =H12-H13 -> -55.783537 | I14: =I12-I13 -> -61.017115 | J14: =J12-J13 -> -64.973824
B15: Capex | D15: =D5*Assumptions!$E$10 -> 20.25 | E15: =E5*Assumptions!$E$10 -> 15.1875 | F15: =F5*Assumptions!$E$10 -> 11.390625 | G15: =G5*Assumptions!$E$10 -> 8.5429688 | H15: =H5*Assumptions!$E$10 -> 6.4072266 | I15: =I5*Assumptions!$E$10 -> 4.8054199 | J15: =J5*Assumptions!$E$10 -> 3.6040649
B16: NWC | C16: =C5*Assumptions!E11 -> 60 | D16: =D5*Assumptions!$E$11 -> 45 | E16: =E5*Assumptions!$E$11 -> 33.75 | F16: =F5*Assumptions!$E$11 -> 25.3125 | G16: =G5*Assumptions!$E$11 -> 18.984375 | H16: =H5*Assumptions!$E$11 -> 14.238281 | I16: =I5*Assumptions!$E$11 -> 10.678711 | J16: =J5*Assumptions!$E$11 -> 8.0090332
B17: Change in NWC | D17: =D16-C16 -> -15 | E17: =E16-D16 -> -11.25 | F17: =F16-E16 -> -8.4375 | G17: =G16-F16 -> -6.328125 | H17: =H16-G16 -> -4.7460938 | I17: =I16-H16 -> -3.5595703 | J17: =J16-I16 -> -2.6696777
B18: FCF before financing | D18: =D14+D9-D15-D17 -> 4.875 | E18: =E14+E9-E15-E17 -> -13.620825 | F18: =F14+F9-F15-F17 -> -29.349131 | G18: =G14+G9-G15-G17 -> -43.365443 | H18: =H14+H9-H15-H17 -> -53.885099 | I18: =I14+I9-I15-I17 -> -59.593287 | J18: =J14+J9-J15-J17 -> -63.905953
B19: FCF before interest | D19: =D8-D13-D15-D17 -> 69.9 | E19: =E8-E13-E15-E17 -> 51.4125 | F19: =F8-F13-F15-F17 -> 37.8 | G19: =G8-G13-G15-G17 -> 27.780469 | H19: =H8-H13-H15-H17 -> 20.408203 | I19: =I8-I13-I15-I17 -> 14.985791 | J19: =J8-J13-J15-J17 -> 10.999072

Sheet Debt Schedule
B2: Multi-Tranche Debt and Cash Sweep
B4: $mm / % | C4: Close | D4: Year 1 | E4: Year 2 | F4: Year 3 | G4: Year 4 | H4: Year 5 | I4: Year 6 | J4: Year 7
B5: Beginning cash | C5: =Assumptions!E16 -> 25 | D5: =C13 -> 25 | E5: =D13 -> 25.32625 | F5: =E13 -> 25 | G5: =F13 -> 25 | H5: =G13 -> 3.2808519 | I5: =H13 -> -54.174248 | J5: =I13 -> -117.33753
B6: FCF before interest | D6: ='Operating Model'!D19 -> 69.9 | E6: ='Operating Model'!E19 -> 51.4125 | F6: ='Operating Model'!F19 -> 37.8 | G6: ='Operating Model'!G19 -> 27.780469 | H6: ='Operating Model'!H19 -> 20.408203 | I6: ='Operating Model'!I19 -> 14.985791 | J6: ='Operating Model'!J19 -> 10.999072
B7: Cash interest | D7: =SUM(D15,D18,D23) -> 65.025 | E7: =SUM(E15,E18,E23) -> 65.033325 | F7: =SUM(F15,F18,F23) -> 67.14913 | G7: =SUM(G15,G18,G23) -> 71.145911 | H7: =SUM(H15,H18,H23) -> 74.293303 | I7: =SUM(I15,I18,I23) -> 74.579078 | J7: =SUM(J15,J18,J23) -> 74.905025
B8: Mandatory TLB amortization | D8: =D19 -> 3.57 | E8: =E19 -> 3.57 | F8: =F19 -> 3.57 | G8: =G19 -> 3.57 | H8: =H19 -> 3.57 | I8: =I19 -> 3.57 | J8: =J19 -> 3.57
B9: Cash before revolver / sweep | D9: =D5+D6-D7-D8 -> 26.305 | E9: =E5+E6-E7-E8 -> 8.135425 | F9: =F5+F6-F7-F8 -> -7.9191305 | G9: =G5+G6-G7-G8 -> -21.935443 | H9: =H5+H6-H7-H8 -> -54.174248 | I9: =I5+I6-I7-I8 -> -117.33753 | J9: =J5+J6-J7-J8 -> -184.81349
B10: Revolver draw / (repayment) | D10: =IF(D9<Assumptions!$E$16,MIN(Assumptions!$E$17-D14,Assumptions!$E$16-D9),-MIN(D14,MAX(0,D9-Assumptions!$E$16))) -> 0 | E10: =IF(E9<Assumptions!$E$16,MIN(Assumptions!$E$17-E14,Assumptions!$E$16-E9),-MIN(E14,MAX(0,E9-Assumptions!$E$16))) -> 16.864575 | F10: =IF(F9<Assumptions!$E$16,MIN(Assumptions!$E$17-F14,Assumptions!$E$16-F9),-MIN(F14,MAX(0,F9-Assumptions!$E$16))) -> 32.919131 | G10: =IF(G9<Assumptions!$E$16,MIN(Assumptions!$E$17-G14,Assumptions!$E$16-G9),-MIN(G14,MAX(0,G9-Assumptions!$E$16))) -> 25.216295 | H10: =IF(H9<Assumptions!$E$16,MIN(Assumptions!$E$17-H14,Assumptions!$E$16-H9),-MIN(H14,MAX(0,H9-Assumptions!$E$16))) -> 0 | I10: =IF(I9<Assumptions!$E$16,MIN(Assumptions!$E$17-I14,Assumptions!$E$16-I9),-MIN(I14,MAX(0,I9-Assumptions!$E$16))) -> 0 | J10: =IF(J9<Assumptions!$E$16,MIN(Assumptions!$E$17-J14,Assumptions!$E$16-J9),-MIN(J14,MAX(0,J9-Assumptions!$E$16))) -> 0
B11: Cash sweep to TLB | D11: =MIN(MAX(0,D17-D19),MAX(0,D9+D10-Assumptions!$E$16)*Assumptions!$E$25) -> 0.6525 | E11: =MIN(MAX(0,E17-E19),MAX(0,E9+E10-Assumptions!$E$16)*Assumptions!$E$25) -> 0 | F11: =MIN(MAX(0,F17-F19),MAX(0,F9+F10-Assumptions!$E$16)*Assumptions!$E$25) -> 0 | G11: =MIN(MAX(0,G17-G19),MAX(0,G9+G10-Assumptions!$E$16)*Assumptions!$E$25) -> 0 | H11: =MIN(MAX(0,H17-H19),MAX(0,H9+H10-Assumptions!$E$16)*Assumptions!$E$25) -> 0 | I11: =MIN(MAX(0,I17-I19),MAX(0,I9+I10-Assumptions!$E$16)*Assumptions!$E$25) -> 0 | J11: =MIN(MAX(0,J17-J19),MAX(0,J9+J10-Assumptions!$E$16)*Assumptions!$E$25) -> 0
B12: Cash sweep to second lien | D12: =MIN(MAX(0,D22+D24),MAX(0,D9+D10-D11-Assumptions!$E$16)*Assumptions!$E$25) -> 0.32625 | E12: =MIN(MAX(0,E22+E24),MAX(0,E9+E10-E11-Assumptions!$E$16)*Assumptions!$E$25) -> 0 | F12: =MIN(MAX(0,F22+F24),MAX(0,F9+F10-F11-Assumptions!$E$16)*Assumptions!$E$25) -> 0 | G12: =MIN(MAX(0,G22+G24),MAX(0,G9+G10-G11-Assumptions!$E$16)*Assumptions!$E$25) -> 0 | H12: =MIN(MAX(0,H22+H24),MAX(0,H9+H10-H11-Assumptions!$E$16)*Assumptions!$E$25) -> 0 | I12: =MIN(MAX(0,I22+I24),MAX(0,I9+I10-I11-Assumptions!$E$16)*Assumptions!$E$25) -> 0 | J12: =MIN(MAX(0,J22+J24),MAX(0,J9+J10-J11-Assumptions!$E$16)*Assumptions!$E$25) -> 0
B13: Ending cash | C13: =C5 -> 25 | D13: =D9+D10-D11-D12 -> 25.32625 | E13: =E9+E10-E11-E12 -> 25 | F13: =F9+F10-F11-F12 -> 25 | G13: =G9+G10-G11-G12 -> 3.2808519 | H13: =H9+H10-H11-H12 -> -54.174248 | I13: =I9+I10-I11-I12 -> -117.33753 | J13: =J9+J10-J11-J12 -> -184.81349
B14: Beginning revolver | C14: ='Sources & Uses'!F5 -> 0 | D14: =C16 -> 0 | E14: =D16 -> 0 | F14: =E16 -> 16.864575 | G14: =F16 -> 49.783706 | H14: =G16 -> 75 | I14: =H16 -> 75 | J14: =I16 -> 75
B15: Revolver interest | D15: =D14*Assumptions!$E$18 -> 0 | E15: =E14*Assumptions!$E$18 -> 0 | F15: =F14*Assumptions!$E$18 -> 1.9394261 | G15: =G14*Assumptions!$E$18 -> 5.7251261 | H15: =H14*Assumptions!$E$18 -> 8.625 | I15: =I14*Assumptions!$E$18 -> 8.625 | J15: =J14*Assumptions!$E$18 -> 8.625
B16: Ending revolver | C16: =C14 -> 0 | D16: =MAX(0,D14+D10) -> 0 | E16: =MAX(0,E14+E10) -> 16.864575 | F16: =MAX(0,F14+F10) -> 49.783706 | G16: =MAX(0,G14+G10) -> 75 | H16: =MAX(0,H14+H10) -> 75 | I16: =MAX(0,I14+I10) -> 75 | J16: =MAX(0,J14+J10) -> 75
B17: Beginning TLB | C17: ='Sources & Uses'!F6 -> 357 | D17: =C21 -> 357 | E17: =D21 -> 352.7775 | F17: =E21 -> 349.2075 | G17: =F21 -> 345.6375 | H17: =G21 -> 342.0675 | I17: =H21 -> 338.4975 | J17: =I21 -> 334.9275
B18: TLB interest | D18: =D17*Assumptions!$E$20 -> 51.765 | E18: =E17*Assumptions!$E$20 -> 51.152738 | F18: =F17*Assumptions!$E$20 -> 50.635087 | G18: =G17*Assumptions!$E$20 -> 50.117438 | H18: =H17*Assumptions!$E$20 -> 49.599787 | I18: =I17*Assumptions!$E$20 -> 49.082138 | J18: =J17*Assumptions!$E$20 -> 48.564487
B19: TLB amortization | D19: =MIN(D17,'Sources & Uses'!$F$6*Assumptions!$E$21) -> 3.57 | E19: =MIN(E17,'Sources & Uses'!$F$6*Assumptions!$E$21) -> 3.57 | F19: =MIN(F17,'Sources & Uses'!$F$6*Assumptions!$E$21) -> 3.57 | G19: =MIN(G17,'Sources & Uses'!$F$6*Assumptions!$E$21) -> 3.57 | H19: =MIN(H17,'Sources & Uses'!$F$6*Assumptions!$E$21) -> 3.57 | I19: =MIN(I17,'Sources & Uses'!$F$6*Assumptions!$E$21) -> 3.57 | J19: =MIN(J17,'Sources & Uses'!$F$6*Assumptions!$E$21) -> 3.57
B20: TLB cash sweep | C20: ='Sources & Uses'!F7 -> 102 | D20: =D11 -> 0.6525 | E20: =E11 -> 0 | F20: =F11 -> 0 | G20: =G11 -> 0 | H20: =H11 -> 0 | I20: =I11 -> 0 | J20: =J11 -> 0
B21: Ending TLB | C21: =C17 -> 357 | D21: =MAX(0,D17-D19-D20) -> 352.7775 | E21: =MAX(0,E17-E19-E20) -> 349.2075 | F21: =MAX(0,F17-F19-F20) -> 345.6375 | G21: =MAX(0,G17-G19-G20) -> 342.0675 | H21: =MAX(0,H17-H19-H20) -> 338.4975 | I21: =MAX(0,I17-I19-I20) -> 334.9275 | J21: =MAX(0,J17-J19-J20) -> 331.3575
B22: Beginning second lien | C22: ='Sources & Uses'!F7 -> 102 | D22: =C26 -> 102 | E22: =D26 -> 106.77375 | F22: =E26 -> 112.11244 | G22: =F26 -> 117.71806 | H22: =G26 -> 123.60396 | I22: =H26 -> 129.78416 | J22: =I26 -> 136.27337
B23: Second-lien cash interest | D23: =D22*Assumptions!$E$23 -> 13.26 | E23: =E22*Assumptions!$E$23 -> 13.880588 | F23: =F22*Assumptions!$E$23 -> 14.574617 | G23: =G22*Assumptions!$E$23 -> 15.303348 | H23: =H22*Assumptions!$E$23 -> 16.068515 | I23: =I22*Assumptions!$E$23 -> 16.871941 | J23: =J22*Assumptions!$E$23 -> 17.715538
B24: Second-lien PIK | D24: =D22*Assumptions!$E$24 -> 5.1 | E24: =E22*Assumptions!$E$24 -> 5.3386875 | F24: =F22*Assumptions!$E$24 -> 5.6056219 | G24: =G22*Assumptions!$E$24 -> 5.885903 | H24: =H22*Assumptions!$E$24 -> 6.1801981 | I24: =I22*Assumptions!$E$24 -> 6.489208 | J24: =J22*Assumptions!$E$24 -> 6.8136684
B25: Second-lien cash sweep | C25: =SUM(C16,C20,C13) -> 127 | D25: =D12 -> 0.32625 | E25: =E12 -> 0 | F25: =F12 -> 0 | G25: =G12 -> 0 | H25: =H12 -> 0 | I25: =I12 -> 0 | J25: =J12 -> 0
B26: Ending second lien | C26: =C22 -> 102 | D26: =MAX(0,D22+D24-D25) -> 106.77375 | E26: =MAX(0,E22+E24-E25) -> 112.11244 | F26: =MAX(0,F22+F24-F25) -> 117.71806 | G26: =MAX(0,G22+G24-G25) -> 123.60396 | H26: =MAX(0,H22+H24-H25) -> 129.78416 | I26: =MAX(0,I22+I24-I25) -> 136.27337 | J26: =MAX(0,J22+J24-J25) -> 143.08704
B27: Total debt | C27: =SUM(C16,C21,C26) -> 459 | D27: =SUM(D16,D21,D26) -> 459.55125 | E27: =SUM(E16,E21,E26) -> 478.18451 | F27: =SUM(F16,F21,F26) -> 513.13926 | G27: =SUM(G16,G21,G26) -> 540.67146 | H27: =SUM(H16,H21,H26) -> 543.28166 | I27: =SUM(I16,I21,I26) -> 546.20087 | J27: =SUM(J16,J21,J26) -> 549.44454
B28: Net debt | C28: =C27-C13 -> 434 | D28: =D27-D13 -> 434.225 | E28: =E27-E13 -> 453.18451 | F28: =F27-F13 -> 488.13926 | G28: =G27-G13 -> 537.39061 | H28: =H27-H13 -> 597.45591 | I28: =I27-I13 -> 663.5384 | J28: =J27-J13 -> 734.25802

Sheet Covenants
B2: Lender Covenant and Liquidity Dashboard
B4: Metric | C4: Year 1 | D4: Year 2 | E4: Year 3 | F4: Year 4 | G4: Year 5 | H4: Year 6 | I4: Year 7
B5: Gross leverage | C5: =IFERROR('Debt Schedule'!D25/'Operating Model'!D8,0) -> 0.0043413174 | D5: =IFERROR('Debt Schedule'!E25/'Operating Model'!E8,0) -> 0 | E5: =IFERROR('Debt Schedule'!F25/'Operating Model'!F8,0) -> 0 | F5: =IFERROR('Debt Schedule'!G25/'Operating Model'!G8,0) -> 0 | G5: =IFERROR('Debt Schedule'!H25/'Operating Model'!H8,0) -> 0 | H5: =IFERROR('Debt Schedule'!I25/'Operating Model'!I8,0) -> 0 | I5: =IFERROR('Debt Schedule'!J25/'Operating Model'!J8,0) -> 0
B6: Maximum leverage | C6: =Assumptions!$E$26 -> 6.5 | D6: =Assumptions!$E$26 -> 6.5 | E6: =Assumptions!$E$26 -> 6.5 | F6: =Assumptions!$E$26 -> 6.5 | G6: =Assumptions!$E$26 -> 6.5 | H6: =Assumptions!$E$26 -> 6.5 | I6: =Assumptions!$E$26 -> 6.5
B7: Leverage headroom | C7: =C6-C5 -> 6.4956587 | D7: =D6-D5 -> 6.5 | E7: =E6-E5 -> 6.5 | F7: =F6-F5 -> 6.5 | G7: =G6-G5 -> 6.5 | H7: =H6-H5 -> 6.5 | I7: =I6-I5 -> 6.5
B8: Interest coverage | C8: =IFERROR('Operating Model'!D8/'Debt Schedule'!D7,0) -> 1.1557093 | D8: =IFERROR('Operating Model'!E8/'Debt Schedule'!E7,0) -> 0.85110211 | E8: =IFERROR('Operating Model'!F8/'Debt Schedule'!F7,0) -> 0.60690473 | F8: =IFERROR('Operating Model'!G8/'Debt Schedule'!G7,0) -> 0.42160276 | G8: =IFERROR('Operating Model'!H8/'Debt Schedule'!H7,0) -> 0.29705687 | H8: =IFERROR('Operating Model'!I8/'Debt Schedule'!I7,0) -> 0.21764335 | I8: =IFERROR('Operating Model'!J8/'Debt Schedule'!J7,0) -> 0.15931454
B9: Minimum coverage | C9: =Assumptions!$E$27 -> 1.5 | D9: =Assumptions!$E$27 -> 1.5 | E9: =Assumptions!$E$27 -> 1.5 | F9: =Assumptions!$E$27 -> 1.5 | G9: =Assumptions!$E$27 -> 1.5 | H9: =Assumptions!$E$27 -> 1.5 | I9: =Assumptions!$E$27 -> 1.5
B10: Coverage headroom | C10: =C8-C9 -> -0.34429066 | D10: =D8-D9 -> -0.64889789 | E10: =E8-E9 -> -0.89309527 | F10: =F8-F9 -> -1.0783972 | G10: =G8-G9 -> -1.2029431 | H10: =H8-H9 -> -1.2823566 | I10: =I8-I9 -> -1.3406855
B11: Minimum cash | C11: =Assumptions!$E$16 -> 25 | D11: =Assumptions!$E$16 -> 25 | E11: =Assumptions!$E$16 -> 25 | F11: =Assumptions!$E$16 -> 25 | G11: =Assumptions!$E$16 -> 25 | H11: =Assumptions!$E$16 -> 25 | I11: =Assumptions!$E$16 -> 25
B12: Cash headroom | C12: ='Debt Schedule'!D13-C11 -> 0.32625 | D12: ='Debt Schedule'!E13-D11 -> 0 | E12: ='Debt Schedule'!F13-E11 -> 0 | F12: ='Debt Schedule'!G13-F11 -> -21.719148 | G12: ='Debt Schedule'!H13-G11 -> -79.174248 | H12: ='Debt Schedule'!I13-H11 -> -142.33753 | I12: ='Debt Schedule'!J13-I11 -> -209.81349
B13: Status | C13: =IF(AND(C7>=0,C10>=0,C12>=0),"PASS","BREACH") -> BREACH | D13: =IF(AND(D7>=0,D10>=0,D12>=0),"PASS","BREACH") -> BREACH | E13: =IF(AND(E7>=0,E10>=0,E12>=0),"PASS","BREACH") -> BREACH | F13: =IF(AND(F7>=0,F10>=0,F12>=0),"PASS","BREACH") -> BREACH | G13: =IF(AND(G7>=0,G10>=0,G12>=0),"PASS","BREACH") -> BREACH | H13: =IF(AND(H7>=0,H10>=0,H12>=0),"PASS","BREACH") -> BREACH | I13: =IF(AND(I7>=0,I10>=0,I12>=0),"PASS","BREACH") -> BREACH

Sheet Management Equity
B2: Management Equity and Incentive Pool
B4: Metric | C4: Value | D4: Units | E4: Notes
B5: Management fully diluted pool | C5: =Assumptions!E30 -> 0.1 | D5: % | E5: granted / reserved pool
B6: Sponsor ownership before pool | C6: =1-C5 -> 0.9 | D6: % | E6: fully diluted
B7: Sponsor invested equity | C7: ='Sources & Uses'!F8 -> 606.95 | D7: $mm | E7: entry equity
B8: Preferred return at exit | C8: =C7*(1+Assumptions!E31)^Assumptions!E29 -> 891.80868 | D8: $mm | E8: sponsor hurdle
B9: Management catch-up rate | C9: =Assumptions!E32 -> 0.2 | D9: % incremental | E9: above preferred return

Sheet Returns Waterfall
B2: Exit Equity and Sponsor / Management Waterfall
B4: Metric | C4: Year 1 | D4: Year 2 | E4: Year 3 | F4: Year 4 | G4: Year 5 | H4: Year 6 | I4: Year 7 | J4: Selected exit
B5: Exit EBITDA | C5: ='Operating Model'!D8 -> 75.15 | D5: ='Operating Model'!E8 -> 55.35 | E5: ='Operating Model'!F8 -> 40.753125 | F5: ='Operating Model'!G8 -> 29.995313 | G5: ='Operating Model'!H8 -> 22.069336 | H5: ='Operating Model'!I8 -> 16.231641 | I5: ='Operating Model'!J8 -> 11.933459 | J5: =INDEX(C5:I5,1,Assumptions!E29) -> 22.069336
B6: Exit multiple | C6: =Assumptions!$E$28 -> 8 | D6: =Assumptions!$E$28 -> 8 | E6: =Assumptions!$E$28 -> 8 | F6: =Assumptions!$E$28 -> 8 | G6: =Assumptions!$E$28 -> 8 | H6: =Assumptions!$E$28 -> 8 | I6: =Assumptions!$E$28 -> 8 | J6: =INDEX(C6:I6,1,Assumptions!E29) -> 8
B7: Exit enterprise value | C7: =C5*C6 -> 601.2 | D7: =D5*D6 -> 442.8 | E7: =E5*E6 -> 326.025 | F7: =F5*F6 -> 239.9625 | G7: =G5*G6 -> 176.55469 | H7: =H5*H6 -> 129.85313 | I7: =I5*I6 -> 95.467676 | J7: =INDEX(C7:I7,1,Assumptions!E29) -> 176.55469
B8: Net debt | C8: ='Debt Schedule'!D28 -> 434.225 | D8: ='Debt Schedule'!E28 -> 453.18451 | E8: ='Debt Schedule'!F28 -> 488.13926 | F8: ='Debt Schedule'!G28 -> 537.39061 | G8: ='Debt Schedule'!H28 -> 597.45591 | H8: ='Debt Schedule'!I28 -> 663.5384 | I8: ='Debt Schedule'!J28 -> 734.25802 | J8: =INDEX(C8:I8,1,Assumptions!E29) -> 597.45591
B9: Gross equity value | C9: =MAX(0,C7-C8) -> 166.975 | D9: =MAX(0,D7-D8) -> 0 | E9: =MAX(0,E7-E8) -> 0 | F9: =MAX(0,F7-F8) -> 0 | G9: =MAX(0,G7-G8) -> 0 | H9: =MAX(0,H7-H8) -> 0 | I9: =MAX(0,I7-I8) -> 0 | J9: =INDEX(C9:I9,1,Assumptions!E29) -> 0
B10: Sponsor preferred return | C10: ='Management Equity'!$C$7*(1+Assumptions!$E$31)^1 -> 655.506 | D10: ='Management Equity'!$C$7*(1+Assumptions!$E$31)^2 -> 707.94648 | E10: ='Management Equity'!$C$7*(1+Assumptions!$E$31)^3 -> 764.5822 | F10: ='Management Equity'!$C$7*(1+Assumptions!$E$31)^4 -> 825.74877 | G10: ='Management Equity'!$C$7*(1+Assumptions!$E$31)^5 -> 891.80868 | H10: ='Management Equity'!$C$7*(1+Assumptions!$E$31)^6 -> 963.15337 | I10: ='Management Equity'!$C$7*(1+Assumptions!$E$31)^7 -> 1040.2056 | J10: =INDEX(C10:I10,1,Assumptions!E29) -> 891.80868
B11: Equity above preferred | C11: =MAX(0,C9-C10) -> 0 | D11: =MAX(0,D9-D10) -> 0 | E11: =MAX(0,E9-E10) -> 0 | F11: =MAX(0,F9-F10) -> 0 | G11: =MAX(0,G9-G10) -> 0 | H11: =MAX(0,H9-H10) -> 0 | I11: =MAX(0,I9-I10) -> 0 | J11: =INDEX(C11:I11,1,Assumptions!E29) -> 0
B12: Management proceeds | C12: =MIN(C9,C9*Assumptions!$E$30+C11*Assumptions!$E$32) -> 16.6975 | D12: =MIN(D9,D9*Assumptions!$E$30+D11*Assumptions!$E$32) -> 0 | E12: =MIN(E9,E9*Assumptions!$E$30+E11*Assumptions!$E$32) -> 0 | F12: =MIN(F9,F9*Assumptions!$E$30+F11*Assumptions!$E$32) -> 0 | G12: =MIN(G9,G9*Assumptions!$E$30+G11*Assumptions!$E$32) -> 0 | H12: =MIN(H9,H9*Assumptions!$E$30+H11*Assumptions!$E$32) -> 0 | I12: =MIN(I9,I9*Assumptions!$E$30+I11*Assumptions!$E$32) -> 0 | J12: =INDEX(C12:I12,1,Assumptions!E29) -> 0
B13: Sponsor proceeds | C13: =MAX(0,C9-C12) -> 150.2775 | D13: =MAX(0,D9-D12) -> 0 | E13: =MAX(0,E9-E12) -> 0 | F13: =MAX(0,F9-F12) -> 0 | G13: =MAX(0,G9-G12) -> 0 | H13: =MAX(0,H9-H12) -> 0 | I13: =MAX(0,I9-I12) -> 0 | J13: =INDEX(C13:I13,1,Assumptions!E29) -> 0
B14: Sponsor MOIC | C14: =IFERROR(C13/'Sources & Uses'!$F$8,0) -> 0.24759453 | D14: =IFERROR(D13/'Sources & Uses'!$F$8,0) -> 0 | E14: =IFERROR(E13/'Sources & Uses'!$F$8,0) -> 0 | F14: =IFERROR(F13/'Sources & Uses'!$F$8,0) -> 0 | G14: =IFERROR(G13/'Sources & Uses'!$F$8,0) -> 0 | H14: =IFERROR(H13/'Sources & Uses'!$F$8,0) -> 0 | I14: =IFERROR(I13/'Sources & Uses'!$F$8,0) -> 0 | J14: =INDEX(C14:I14,1,Assumptions!E29) -> 0
B15: Sponsor IRR | C15: =IFERROR((C13/'Sources & Uses'!$F$8)^(1/1)-1,0) -> -0.75240547 | D15: =IFERROR((D13/'Sources & Uses'!$F$8)^(1/2)-1,0) -> -1 | E15: =IFERROR((E13/'Sources & Uses'!$F$8)^(1/3)-1,0) -> -1 | F15: =IFERROR((F13/'Sources & Uses'!$F$8)^(1/4)-1,0) -> -1 | G15: =IFERROR((G13/'Sources & Uses'!$F$8)^(1/5)-1,0) -> -1 | H15: =IFERROR((H13/'Sources & Uses'!$F$8)^(1/6)-1,0) -> -1 | I15: =IFERROR((I13/'Sources & Uses'!$F$8)^(1/7)-1,0) -> -1 | J15: =INDEX(C15:I15,1,Assumptions!E29) -> -1

Sheet Sensitivity
B2: Sponsor IRR Sensitivity
B4: Entry / Exit multiple | C4: 7 | D4: 8 | E4: 9 | F4: 10 | G4: 11
B5: 8 | C5: =IFERROR(((('Operating Model'!H8*C$4-'Debt Schedule'!G28)*(1-Assumptions!$E$30))/MAX(0.01,('Operating Model'!C8*$B5+Assumptions!$E$15+'Sources & Uses'!C7+Assumptions!$E$16-'Sources & Uses'!F6-'Sources & Uses'!F7)))^(1/5)-1,0) -> -1.9264396 | D5: =IFERROR(((('Operating Model'!H8*D$4-'Debt Schedule'!G28)*(1-Assumptions!$E$30))/MAX(0.01,('Operating Model'!C8*$B5+Assumptions!$E$15+'Sources & Uses'!C7+Assumptions!$E$16-'Sources & Uses'!F6-'Sources & Uses'!F7)))^(1/5)-1,0) -> -1.9155051 | E5: =IFERROR(((('Operating Model'!H8*E$4-'Debt Schedule'!G28)*(1-Assumptions!$E$30))/MAX(0.01,('Operating Model'!C8*$B5+Assumptions!$E$15+'Sources & Uses'!C7+Assumptions!$E$16-'Sources & Uses'!F6-'Sources & Uses'!F7)))^(1/5)-1,0) -> -1.9040219 | F5: =IFERROR(((('Operating Model'!H8*F$4-'Debt Schedule'!G28)*(1-Assumptions!$E$30))/MAX(0.01,('Operating Model'!C8*$B5+Assumptions!$E$15+'Sources & Uses'!C7+Assumptions!$E$16-'Sources & Uses'!F6-'Sources & Uses'!F7)))^(1/5)-1,0) -> -1.8919237 | G5: =IFERROR(((('Operating Model'!H8*G$4-'Debt Schedule'!G28)*(1-Assumptions!$E$30))/MAX(0.01,('Operating Model'!C8*$B5+Assumptions!$E$15+'Sources & Uses'!C7+Assumptions!$E$16-'Sources & Uses'!F6-'Sources & Uses'!F7)))^(1/5)-1,0) -> -1.879131
B6: 9 | C6: =IFERROR(((('Operating Model'!H8*C$4-'Debt Schedule'!G28)*(1-Assumptions!$E$30))/MAX(0.01,('Operating Model'!C8*$B6+Assumptions!$E$15+'Sources & Uses'!C7+Assumptions!$E$16-'Sources & Uses'!F6-'Sources & Uses'!F7)))^(1/5)-1,0) -> -1.8929686 | D6: =IFERROR(((('Operating Model'!H8*D$4-'Debt Schedule'!G28)*(1-Assumptions!$E$30))/MAX(0.01,('Operating Model'!C8*$B6+Assumptions!$E$15+'Sources & Uses'!C7+Assumptions!$E$16-'Sources & Uses'!F6-'Sources & Uses'!F7)))^(1/5)-1,0) -> -1.8824292 | E6: =IFERROR(((('Operating Model'!H8*E$4-'Debt Schedule'!G28)*(1-Assumptions!$E$30))/MAX(0.01,('Operating Model'!C8*$B6+Assumptions!$E$15+'Sources & Uses'!C7+Assumptions!$E$16-'Sources & Uses'!F6-'Sources & Uses'!F7)))^(1/5)-1,0) -> -1.8713608 | F6: =IFERROR(((('Operating Model'!H8*F$4-'Debt Schedule'!G28)*(1-Assumptions!$E$30))/MAX(0.01,('Operating Model'!C8*$B6+Assumptions!$E$15+'Sources & Uses'!C7+Assumptions!$E$16-'Sources & Uses'!F6-'Sources & Uses'!F7)))^(1/5)-1,0) -> -1.8596997 | G6: =IFERROR(((('Operating Model'!H8*G$4-'Debt Schedule'!G28)*(1-Assumptions!$E$30))/MAX(0.01,('Operating Model'!C8*$B6+Assumptions!$E$15+'Sources & Uses'!C7+Assumptions!$E$16-'Sources & Uses'!F6-'Sources & Uses'!F7)))^(1/5)-1,0) -> -1.8473692
B7: 10 | C7: =IFERROR(((('Operating Model'!H8*C$4-'Debt Schedule'!G28)*(1-Assumptions!$E$30))/MAX(0.01,('Operating Model'!C8*$B7+Assumptions!$E$15+'Sources & Uses'!C7+Assumptions!$E$16-'Sources & Uses'!F6-'Sources & Uses'!F7)))^(1/5)-1,0) -> -1.8656526 | D7: =IFERROR(((('Operating Model'!H8*D$4-'Debt Schedule'!G28)*(1-Assumptions!$E$30))/MAX(0.01,('Operating Model'!C8*$B7+Assumptions!$E$15+'Sources & Uses'!C7+Assumptions!$E$16-'Sources & Uses'!F6-'Sources & Uses'!F7)))^(1/5)-1,0) -> -1.8554356 | E7: =IFERROR(((('Operating Model'!H8*E$4-'Debt Schedule'!G28)*(1-Assumptions!$E$30))/MAX(0.01,('Operating Model'!C8*$B7+Assumptions!$E$15+'Sources & Uses'!C7+Assumptions!$E$16-'Sources & Uses'!F6-'Sources & Uses'!F7)))^(1/5)-1,0) -> -1.8447058 | F7: =IFERROR(((('Operating Model'!H8*F$4-'Debt Schedule'!G28)*(1-Assumptions!$E$30))/MAX(0.01,('Operating Model'!C8*$B7+Assumptions!$E$15+'Sources & Uses'!C7+Assumptions!$E$16-'Sources & Uses'!F6-'Sources & Uses'!F7)))^(1/5)-1,0) -> -1.8334014 | G7: =IFERROR(((('Operating Model'!H8*G$4-'Debt Schedule'!G28)*(1-Assumptions!$E$30))/MAX(0.01,('Operating Model'!C8*$B7+Assumptions!$E$15+'Sources & Uses'!C7+Assumptions!$E$16-'Sources & Uses'!F6-'Sources & Uses'!F7)))^(1/5)-1,0) -> -1.8214482
B8: 11 | C8: =IFERROR(((('Operating Model'!H8*C$4-'Debt Schedule'!G28)*(1-Assumptions!$E$30))/MAX(0.01,('Operating Model'!C8*$B8+Assumptions!$E$15+'Sources & Uses'!C7+Assumptions!$E$16-'Sources & Uses'!F6-'Sources & Uses'!F7)))^(1/5)-1,0) -> -1.8426902 | D8: =IFERROR(((('Operating Model'!H8*D$4-'Debt Schedule'!G28)*(1-Assumptions!$E$30))/MAX(0.01,('Operating Model'!C8*$B8+Assumptions!$E$15+'Sources & Uses'!C7+Assumptions!$E$16-'Sources & Uses'!F6-'Sources & Uses'!F7)))^(1/5)-1,0) -> -1.8327442 | E8: =IFERROR(((('Operating Model'!H8*E$4-'Debt Schedule'!G28)*(1-Assumptions!$E$30))/MAX(0.01,('Operating Model'!C8*$B8+Assumptions!$E$15+'Sources & Uses'!C7+Assumptions!$E$16-'Sources & Uses'!F6-'Sources & Uses'!F7)))^(1/5)-1,0) -> -1.8222991 | F8: =IFERROR(((('Operating Model'!H8*F$4-'Debt Schedule'!G28)*(1-Assumptions!$E$30))/MAX(0.01,('Operating Model'!C8*$B8+Assumptions!$E$15+'Sources & Uses'!C7+Assumptions!$E$16-'Sources & Uses'!F6-'Sources & Uses'!F7)))^(1/5)-1,0) -> -1.8112945 | G8: =IFERROR(((('Operating Model'!H8*G$4-'Debt Schedule'!G28)*(1-Assumptions!$E$30))/MAX(0.01,('Operating Model'!C8*$B8+Assumptions!$E$15+'Sources & Uses'!C7+Assumptions!$E$16-'Sources & Uses'!F6-'Sources & Uses'!F7)))^(1/5)-1,0) -> -1.7996583
B9: 12 | C9: =IFERROR(((('Operating Model'!H8*C$4-'Debt Schedule'!G28)*(1-Assumptions!$E$30))/MAX(0.01,('Operating Model'!C8*$B9+Assumptions!$E$15+'Sources & Uses'!C7+Assumptions!$E$16-'Sources & Uses'!F6-'Sources & Uses'!F7)))^(1/5)-1,0) -> -1.8229574 | D9: =IFERROR(((('Operating Model'!H8*D$4-'Debt Schedule'!G28)*(1-Assumptions!$E$30))/MAX(0.01,('Operating Model'!C8*$B9+Assumptions!$E$15+'Sources & Uses'!C7+Assumptions!$E$16-'Sources & Uses'!F6-'Sources & Uses'!F7)))^(1/5)-1,0) -> -1.8132444 | E9: =IFERROR(((('Operating Model'!H8*E$4-'Debt Schedule'!G28)*(1-Assumptions!$E$30))/MAX(0.01,('Operating Model'!C8*$B9+Assumptions!$E$15+'Sources & Uses'!C7+Assumptions!$E$16-'Sources & Uses'!F6-'Sources & Uses'!F7)))^(1/5)-1,0) -> -1.8030438 | F9: =IFERROR(((('Operating Model'!H8*F$4-'Debt Schedule'!G28)*(1-Assumptions!$E$30))/MAX(0.01,('Operating Model'!C8*$B9+Assumptions!$E$15+'Sources & Uses'!C7+Assumptions!$E$16-'Sources & Uses'!F6-'Sources & Uses'!F7)))^(1/5)-1,0) -> -1.7922969 | G9: =IFERROR(((('Operating Model'!H8*G$4-'Debt Schedule'!G28)*(1-Assumptions!$E$30))/MAX(0.01,('Operating Model'!C8*$B9+Assumptions!$E$15+'Sources & Uses'!C7+Assumptions!$E$16-'Sources & Uses'!F6-'Sources & Uses'!F7)))^(1/5)-1,0) -> -1.7809332

Sheet Checks
B2: LBO Model Checks
B4: Check | C4: Status
B5: Sources equal uses | C5: =IF(ABS('Sources & Uses'!F10)<0.000001,"PASS","FAIL") -> PASS
B6: Sponsor equity positive | C6: =IF('Sources & Uses'!F8>0,"PASS","FAIL") -> PASS
B7: Debt balances nonnegative | C7: =IF(MIN('Debt Schedule'!D15:J25)>=0,"PASS","FAIL") -> PASS
B8: Cash at or above minimum | C8: =IF(MIN('Debt Schedule'!D13:J13)>=Assumptions!E16,"PASS","REVIEW") -> REVIEW
B9: No covenant breaches | C9: =IF(COUNTIF(Covenants!C13:I13,"BREACH")=0,"PASS","REVIEW") -> REVIEW
B10: Exit equity nonnegative | C10: =IF(MIN('Returns Waterfall'!C9:I9)>=0,"PASS","FAIL") -> PASS
B11: Waterfall conserves equity | C11: =IF(MAX(ABS('Returns Waterfall'!C9:I9-'Returns Waterfall'!C12:I12-'Returns Waterfall'!C13:I13))<0.000001,"PASS","FAIL") -> PASS
B12: Selected exit year valid | C12: =IF(AND(Assumptions!E29>=1,Assumptions!E29<=7),"PASS","FAIL") -> PASS
B13: Overall | C13: =IF(COUNTIF(C5:C12,"FAIL")=0,"PASS","FAIL") -> PASS

Sheet Sources
B2: Source Register
B4: Input / dataset | C4: Source URL or document | D4: As-of | E4: Notes / transformation
B5: Historical financial statements | C5: [filing / data room URL] | D5: [period] | E5: Revenue, margins, capex, working capital, taxes
B6: Quality of earnings and diligence | C6: [advisor report URL] | D6: [date] | E6: EBITDA adjustments, one-time items, risks
B7: Debt term sheets and documentation | C7: [data room URL] | D7: [date] | E7: Rates, PIK, amortization, sweeps, covenants, baskets
B8: Transaction terms | C8: [purchase agreement / process letter] | D8: [date] | E8: Price, fees, minimum cash, rollover, management pool
B9: Market valuation references | C9: [public market / transaction source] | D9: [date] | E9: Entry and exit multiple support
B10: WeWork 2022 Form 10-K | C10: https://www.sec.gov/Archives/edgar/data/1813756/000181375623000019/we-20221231.htm | D10: 2023-03-29 | E10: U.S. SEC; frozen curated observation as of case date
B11: Frozen source snapshot | C11: repo://04_Merchant_Banking/sources/snapshots/merchant-wework-2022.json | D11: 2023-03-29 | E11: Immutable curated observation package with SHA-256 digest
B12: WeWork 2022 downside calibrated to public filing | C12: repo://04_Merchant_Banking/sources/snapshots/merchant-wework-2022.json | D12: 2023-03-29 | E12: Modeler-owned assumption documented in frozen snapshot
B13: Distressed holdco financing assumption | C13: repo://04_Merchant_Banking/sources/snapshots/merchant-wework-2022.json | D13: 2023-03-29 | E13: Modeler-owned assumption documented in frozen snapshot

Sheet RefreshLog
B2: Refresh Log
B4: Date | C4: Trigger | D4: Source snapshot | E4: What changed | F4: Reviewer / challenge | G4: Next check
B5: 2026-08-04 | C5: External historical evidence materialization | D5: repo://04_Merchant_Banking/sources/snapshots/merchant-wework-2022.json | E5: Generated public case merchant-wework-2022 from canonical release template | F5: External historical case; human stakeholder approval remains pending | G5: On source revision, builder change, monitoring breach, or annual review
