Workbook

Sheet Cover
B2: [ETF] — Construction, Creation/Redemption, and Tracking-Cost Model
B4: ETF / share class: | C4: KraneShares CSI China Internet ETF (NYSE Arca: KWEB)
B5: Benchmark index: | C5: CSI Overseas China Internet Index
B6: As of date: | C6: [date]
B7: Last refreshed: | C7: 2026-08-17
B8: Next NAV / holdings refresh: | C8: [date]
B9: Active scenario: | C9: Downside
B10: Units: | C10: $ in millions unless noted
B13: Modeling conventions
B14: Blue text / yellow fill | C14: Hardcoded input or selected scenario
B15: Black text | C15: Formula / same-sheet calculation
B16: Green text | C16: Cross-sheet formula / link
B17: Checks | C17: PASS / REVIEW / FAIL must remain visible

Sheet Institutional Surface
B2: ETF Construction & Management — Institutional Decision Surface
B4: Model ID | C4: 30
B5: Domain | C5: ETF Construction & Management
B6: Declared maturity | C6: M2
B7: Canonical builder | C7: tools/builders/build_etf_construction_institutional.py
B8: Decision arena | C8: fund board, authorized participant desk, capital markets/index committee
B9: Committee artifact | C9: quarterly holdings and tracking-difference report
B10: Operating cadence | C10: daily NAV and holdings disclosure; quarterly tracking-difference report; annual prospectus update
B12: Key decision outputs
B13: # | C13: Requirement | D13: Owner | E13: Evidence / location | F13: Status
B14: 1 | C14: net tracking difference (fund return vs. benchmark return) | F14: OPEN
B15: 2 | C15: creation unit basket value and AP arbitrage economics | F15: OPEN
B16: 3 | C16: premium/discount to NAV and portfolio sector/holdings weights | F16: OPEN
B17: 4 | C17: base, downside and break-even outputs | F17: OPEN
B18: 5 | C18: liquidity / funding requirement and binding constraint | F18: OPEN
B20: Insider questions
B21: # | C21: Requirement | D21: Owner | E21: Evidence / location | F21: Status
B22: 1 | C22: What is the funds realized tracking difference versus its benchmark over the last year? | F22: OPEN
B23: 2 | C23: How concentrated is the portfolio in its largest holdings and sectors? | F23: OPEN
B24: 3 | C24: What premium or discount to NAV is the fund currently trading at, and is AP arbitrage keeping it in bounds? | F24: OPEN
B25: 4 | C25: Which assumption is owner-approved versus modeler judgement? | F25: OPEN
B26: 5 | C26: What fails first and who must act? | F26: OPEN
B28: Scenario families
B29: # | C29: Requirement | D29: Owner | E29: Evidence / location | F29: Status
B30: 1 | C30: authorized participant withdrawal or reduced creation/redemption activity | F30: OPEN
B31: 2 | C31: index reconstitution and rebalance turnover | F31: OPEN
B32: 3 | C32: securities-lending market disruption | F32: OPEN
B33: 4 | C33: data freshness / source failure | F33: OPEN
B34: 5 | C34: combined severe-but-plausible downside | F34: OPEN
B36: Primary diligence documents
B37: # | C37: Requirement | D37: Owner | E37: Evidence / location | F37: Status
B38: 1 | C38: fund prospectus and Statement of Additional Information | F38: OPEN
B39: 2 | C39: daily holdings and NAV disclosure | F39: OPEN
B40: 3 | C40: authorized participant agreement | F40: OPEN
B41: 4 | C41: approved model card and assumption register | F41: OPEN
B42: 5 | C42: independent validation and challenge record | F42: OPEN
B44: Challenge tests
B45: # | C45: Requirement | D45: Owner | E45: Evidence / location | F45: Status
B46: 1 | C46: holdings and sector weights reconcile to disclosed totals | F46: OPEN
B47: 2 | C47: creation unit basket value ties to NAV and market price | F47: OPEN
...

Sheet Challenge Log
B2: Independent Challenge, Override and Closure Log
B4: Date | C4: Reviewer | D4: Challenge | E4: Owner response | F4: Evidence | G4: Impact | H4: Status | I4: Closure
D5: holdings and sector weights reconcile to disclosed totals | H5: OPEN
D6: creation unit basket value ties to NAV and market price | H6: OPEN
D7: tracking-difference bridge components are individually plausible | H7: OPEN
D8: source-to-model lineage is reproducible | H8: OPEN
D9: units, signs, dates and legal definitions reconcile | H9: OPEN

Sheet Lineage Map
B2: Source, Transformation, Ownership and Refresh Map
B4: Source class | C4: Cadence | D4: Control | E4: System / provider | F4: As-of | G4: Owner | H4: Transform | I4: Downstream | J4: Status
B5: fund issuer holdings/profile disclosure | C5: daily | D5: fund-administrator-verified holdings and NAV | J5: TO MAP
B6: market price and quote data | C6: real-time/daily | D6: exchange-reported last trade | J6: TO MAP
B7: model governance evidence | C7: per release | D7: version, reviewer, sign-off and change log | J7: TO MAP
B8: decision-use snapshot | C8: per decision | D8: immutable as-of date and source receipt | J8: TO MAP

Sheet Assumptions
B2: Fund, Replication, and Creation-Unit Assumptions
B4: Assumption | C4: Base | D4: Downside | E4: Active | F4: Units / note
B5: Fund net assets (AUM) | C5: 10000 | D5: 6033.6 | E5: =IF(Cover!$C$9="Downside",D5,C5) -> 6033.6 | F5: $mm
B6: Net expense ratio | C6: 0.005 | D6: 0.0069 | E6: =IF(Cover!$C$9="Downside",D6,C6) -> 0.0069 | F6: % p.a.
B7: Trailing 12-month dividend yield | C7: 0.015 | D7: 0.0743 | E7: =IF(Cover!$C$9="Downside",D7,C7) -> 0.0743 | F7: % p.a.
B8: Market price (last close) | C8: 100 | D8: 27.01 | E8: =IF(Cover!$C$9="Downside",D8,C8) -> 27.01 | F8: $/share
B9: Standard creation unit size | C9: 50000 | D9: 50000 | E9: =IF(Cover!$C$9="Downside",D9,C9) -> 50000 | F9: shares
B10: Current premium / (discount) to NAV | C10: 0 | D10: -0.0025 | E10: =IF(Cover!$C$9="Downside",D10,C10) -> -0.0025 | F10: %
B11: Estimated securities-lending revenue offset | C11: 0.0002 | D11: 0.0001 | E11: =IF(Cover!$C$9="Downside",D11,C11) -> 0.0001 | F11: % of NAV p.a.
B12: Estimated cash-drag cost | C12: 0.0002 | D12: 0.0008 | E12: =IF(Cover!$C$9="Downside",D12,C12) -> 0.0008 | F12: % of NAV p.a.
B13: Estimated sampling / optimization tracking error | C13: 0.001 | D13: 0.005 | E13: =IF(Cover!$C$9="Downside",D13,C13) -> 0.005 | F13: % of NAV p.a.
B14: AP arbitrage action threshold | C14: 0.001 | D14: 0.0025 | E14: =IF(Cover!$C$9="Downside",D14,C14) -> 0.0025 | F14: % premium/discount
B16: Implied shares outstanding | C16: =E5/E8 -> 223.38393 | D16: mm shares -- derived: AUM / market price

Sheet Portfolio Construction
B2: Constituent Holdings (Look-Through)
B4: Symbol | C4: Issuer / description | D4: Weight
B5: n/a | C5: TENCENT HOLDINGS LTD | D5: 0.1009
B6: n/a | C6: ALIBABA GROUP HOLDING LTD ORDINARY SHARES | D6: 0.0879
B7: PDD | C7: PDD HOLDINGS INC ADR | D7: 0.08
B8: n/a | C8: MEITUAN CLASS B | D8: 0.0789
B9: n/a | C9: NETEASE INC ORDINARY SHARES | D9: 0.0606
B10: n/a | C10: JD.COM INC ORDINARY SHARES CLASS A | D10: 0.0427
B11: YMM | C11: FULL TRUCK ALLIANCE CO LTD ADR | D11: 0.0421
B12: n/a | C12: KE HOLDINGS INC CLASS A | D12: 0.0391
B13: n/a | C13: KUAISHOU TECHNOLOGY ORDINARY SHARES CLASS B | D13: 0.0374
B14: n/a | C14: TRIP.COM GROUP LTD | D14: 0.0365
B15: n/a | C15: JD HEALTH INTERNATIONAL INC | D15: 0.0359
B16: n/a | C16: BAIDU INC | D16: 0.0356
... B34: QFIN | C34: QFIN HOLDINGS INC ADR | D34: 0.0072
B35: All other constituents | C35: [remaining positions] | D35: =MAX(0,1-SUM(D5:D34)) -> 0.0161
D36: =SUM(D5:D35) -> 1
B38: Sector Allocation (as disclosed)
B39: Sector | C39: Weight
B40: CONSUMER DISCRETIONARY | C40: 0.414
B41: COMMUNICATION SERVICES | C41: 0.373
B42: CONSUMER STAPLES | C42: 0.083
B43: INDUSTRIALS | C43: 0.065
B44: REAL ESTATE | C44: 0.043
B45: SHORT-TERM INVESTMENT | C45: 0.027
B46: FINANCIALS | C46: 0.021
B47: OTHER ASSETS LESS LIABILITIES | C47: -0.026
B48: [Sector 9] | C48: 0
B49: [Sector 10] | C49: 0
B50: [Sector 11] | C50: 0
B51: Total disclosed sector weight | C51: =SUM(C40:C50) -> 1

Sheet Creation & Redemption
B2: Creation Unit Economics and Authorized-Participant Arbitrage
B4: Metric | C4: Value
B5: NAV per share (proxy: market price / (1+premium)) | C5: =Assumptions!$E$8/(1+Assumptions!$E$10) -> 27.077694
B6: Creation unit basket value (NAV basis) | C6: =C5*Assumptions!$E$9 -> 1353884.7
B7: Creation unit basket value (market-price basis) | C7: =Assumptions!$E$8*Assumptions!$E$9 -> 1350500
B8: Creation unit implied share of total AUM | C8: =C6/(Assumptions!$E$5*1000000) -> 0.00022439086
B9: Premium / (discount) at market price vs. NAV | C9: =Assumptions!$E$10 -> -0.0025
B10: AP arbitrage profit per creation unit at current premium/discount | C10: =C9*C7 -> -3376.25
B11: AP action threshold breached? | C11: =IF(ABS(C9)>Assumptions!$E$14,"YES -- AP arbitrage expected to compress premium/discount","NO -- within normal trading band") -> NO -- within normal trading band

Sheet Tracking Error & Costs
B2: Fund Return vs. Benchmark: Tracking-Difference Bridge
B4: Component | C4: Annualized impact
B5: Expense ratio drag | C5: =-Assumptions!$E$6 -> -0.0069
B6: Securities-lending revenue offset | C6: =Assumptions!$E$11 -> 0.0001
B7: Cash-drag cost | C7: =-Assumptions!$E$12 -> -0.0008
B8: Sampling / optimization tracking error (+/-) | C8: =-Assumptions!$E$13 -> -0.005
B9: Estimated net tracking difference (fund return - benchmark return) | C9: =SUM(C5:C8) -> -0.0126
B11: Reference: trailing dividend yield (informational, not part of tracking bridge) | C11: =Assumptions!$E$7 -> 0.0743

Sheet Checks
B2: ETF Model Checks
B4: Check | C4: Status
B5: Holdings weights (shown + other) sum to ~100% | C5: =IF(ABS('Portfolio Construction'!D36-1)<0.02,"PASS","REVIEW") -> PASS
B6: Disclosed sector weights sum within a plausible band (90%-101%) | C6: =IF(AND('Portfolio Construction'!C51>=0.9,'Portfolio Construction'!C51<=1.01),"PASS","REVIEW") -> PASS
B7: Implied shares outstanding is positive | C7: =IF(Assumptions!C16>0,"PASS","FAIL") -> PASS
B8: Creation unit basket value is positive | C8: =IF('Creation & Redemption'!C6>0,"PASS","FAIL") -> PASS
B9: Net expense ratio is nonnegative and below 3% | C9: =IF(AND(Assumptions!E6>=0,Assumptions!E6<0.03),"PASS","REVIEW") -> PASS
B10: Estimated net tracking difference within a plausible band (-2% to +0.5%) | C10: =IF(AND('Tracking Error & Costs'!C9>=-0.02,'Tracking Error & Costs'!C9<=0.005),"PASS","REVIEW") -> PASS
B11: Overall | C11: =IF(COUNTIF(C5:C10,"FAIL")>0,"FAIL",IF(COUNTIF(C5:C10,"REVIEW")>0,"REVIEW","PASS")) -> PASS

Sheet Sources
B2: Source Register
B4: Input / dataset | C4: Source URL or document | D4: As-of | E4: Notes / transformation
B5: ETF issuer fund profile / holdings disclosure | C5: [issuer fact sheet or N-CSR/N-PORT filing] | D5: [date] | E5: AUM, expense ratio, dividend yield, holdings, sector weights
B6: Market data (last price, volume) | C6: [exchange / market data vendor] | D6: [date] | E6: Market price used as a NAV proxy
B7: Prospectus / Statement of Additional Information | C7: [SEC-filed prospectus / SAI] | D7: [date] | E7: Creation unit size, in-kind/cash creation mix, authorized participant list
B8: KraneShares CSI China Internet ETF Profile (Alpha Vantage, fund-disclosed holdings/AUM/expense ratio) | C8: https://www.alphavantage.co/documentation/#etf-profile | D8: 2026-08-17 | E8: Fund net assets, net expense ratio, and trailing dividend yield, retrieved via Alpha Vantage ETF_PROFILE (symbol=KWEB). Sourced from the fund's own disclosed holdings/profile data. This endpoint returned no sector breakdown for this fund (unlike QQQ) -- sector weights below are sourced from the fund's SEC N-CSR instead.
B9: KWEB market close price (Alpha Vantage GLOBAL_QUOTE, 2026-08-14) | C9: https://www.alphavantage.co/documentation/#quote-endpoint | D9: 2026-08-14 | E9: Last daily close $27.01, retrieved via Alpha Vantage GLOBAL_QUOTE (symbol=KWEB).
B10: KraneShares CSI China Internet ETF Annual Shareholder Report (SEC Form N-CSR) | C10: https://www.sec.gov/Archives/edgar/data/1547576/000182912626006162/kraneshares_ncsr.htm | D10: 2026-03-31 | E10: Filed 2026-06-08, accession 0001829126-26-006162, CIK 0001547576. Source of sector weightings, total net assets, holdings count, and the realized 5-year average annual total return used as this case's adversarial outcome.
B11: Case design decision | C11: repo://tools/build_etf_kweb_case.py | D11: 2026-08-17 | E11: This case is the adversarial half of the pair; only the Downside column is populated with real data.

Sheet RefreshLog
B2: Refresh Log
B4: Date | C4: Trigger | D4: Source snapshot | E4: What changed | F4: Reviewer / challenge | G4: Next check
B5: 2026-08-17 | C5: Adversarial-pair sourcing for the ETF Construction & Management domain (model_card.md thin-coverage gap) | D5: repo://30_ETF_Construction_Management/sources/snapshots/etf-public-kweb-2026-stress.json | E5: Generated public case etf-public-kweb-2026-stress from canonical release template | F5: External historical case; human stakeholder approval remains pending | G5: On source revision, builder change, monitoring breach, or quarterly review
