Workbook

Sheet Cover
B2: Adobe Inc. -- FY2025 software operating, RPO, and unit-economics case
B4: Company / ticker: | C4: Adobe Inc. (NASDAQ: ADBE), CIK 0000796343
B5: Subsector: | C5: application software -- SEC SIC 7372 (Services-Prepackaged Software), as filed by the registrant
B6: Fiscal year end: | C6: 2025-11-28 (FY2025; 52/53-week year ending the Friday nearest November 30)
B7: Last refreshed: | C7: 2026-01-15
B8: Next filing / refresh: | C8: 2027-01 expected (FY2026 Form 10-K); every Adobe 10-K in this fact set was filed in January (17 filings, 2010-01 through 2026-01)
B9: Active scenario: | C9: Base
B10: Units: | C10: $ in millions unless noted
B13: Modeling conventions
B14: Blue text / yellow fill | C14: Hardcoded input or selected scenario
B15: Black text | C15: Formula / same-sheet calculation
B16: Green text | C16: Cross-sheet formula / link
B17: Checks | C17: PASS / REVIEW / FAIL must remain visible

Sheet Institutional Surface
B2: Software & SaaS — Institutional Decision Surface
B4: Model ID | C4: 31
B5: Domain | C5: Software & SaaS
B6: Declared maturity | C6: M1
B7: Canonical builder | C7: tools/builders/build_software_saas_institutional.py
B8: Decision arena | C8: management team, board, public-market investors and growth-equity investment committee
B9: Committee artifact | C9: quarterly ARR and retention review pack
B10: Operating cadence | C10: quarterly earnings and ARR reporting; annual plan and long-range model refresh
B12: Key decision outputs
B13: # | C13: Requirement | D13: Owner | E13: Evidence / location | F13: Status
B14: 1 | C14: ARR roll-forward with net and gross revenue retention | F14: OPEN
B15: 2 | C15: customer-acquisition payback and magic number | F15: OPEN
B16: 3 | C16: Rule of 40 growth-versus-profitability trade-off | F16: OPEN
B17: 4 | C17: base, downside and break-even outputs | F17: OPEN
B18: 5 | C18: liquidity / funding requirement and binding constraint | F18: OPEN
B20: Insider questions
B21: # | C21: Requirement | D21: Owner | E21: Evidence / location | F21: Status
B22: 1 | C22: What is net revenue retention excluding new customers, and how does it compare to gross retention? | F22: OPEN
B23: 2 | C23: How many months of gross profit does it take to repay customer-acquisition cost? | F23: OPEN
B24: 3 | C24: Does the company clear Rule of 40 on free cash flow, not just on operating margin? | F24: OPEN
B25: 4 | C25: Which assumption is owner-approved versus modeler judgement? | F25: OPEN
B26: 5 | C26: What fails first and who must act? | F26: OPEN
B28: Scenario families
B29: # | C29: Requirement | D29: Owner | E29: Evidence / location | F29: Status
B30: 1 | C30: gross churn acceleration | F30: OPEN
B31: 2 | C31: expansion contraction as customers optimise seats | F31: OPEN
B32: 3 | C32: sales-efficiency deterioration raising payback | F32: OPEN
B33: 4 | C33: data freshness / source failure | F33: OPEN
B34: 5 | C34: combined severe-but-plausible downside | F34: OPEN
B36: Primary diligence documents
B37: # | C37: Requirement | D37: Owner | E37: Evidence / location | F37: Status
B38: 1 | C38: annual report and quarterly filings | F38: OPEN
B39: 2 | C39: revenue disaggregation and equity compensation notes | F39: OPEN
B40: 3 | C40: shareholder letters and investor-day disclosure | F40: OPEN
B41: 4 | C41: approved model card and assumption register | F41: OPEN
B42: 5 | C42: independent validation and challenge record | F42: OPEN
B44: Challenge tests
B45: # | C45: Requirement | D45: Owner | E45: Evidence / location | F45: Status
B46: 1 | C46: ARR roll-forward reconciles beginning to ending balance | F46: OPEN
B47: 2 | C47: net revenue retention exceeds gross revenue retention | F47: OPEN
...

Sheet Challenge Log
B2: Independent Challenge, Override and Closure Log
B4: Date | C4: Reviewer | D4: Challenge | E4: Owner response | F4: Evidence | G4: Impact | H4: Status | I4: Closure
D5: ARR roll-forward reconciles beginning to ending balance | H5: OPEN
D6: net revenue retention exceeds gross revenue retention | H6: OPEN
D7: blended gross margin sits between its subscription and services components | H7: OPEN
D8: source-to-model lineage is reproducible | H8: OPEN
D9: units, signs, dates and legal definitions reconcile | H9: OPEN

Sheet Lineage Map
B2: Source, Transformation, Ownership and Refresh Map
B4: Source class | C4: Cadence | D4: Control | E4: System / provider | F4: As-of | G4: Owner | H4: Transform | I4: Downstream | J4: Status
B5: annual and quarterly filings | C5: quarterly | D5: audited financial statements and revenue disaggregation | J5: TO MAP
B6: industry cost of capital and multiple datasets | C6: annual | D6: published industry statistics used to ground driver ranges | J6: TO MAP
B7: model governance evidence | C7: per release | D7: version, reviewer, sign-off and change log | J7: TO MAP
B8: decision-use snapshot | C8: per decision | D8: immutable as-of date and source receipt | J8: TO MAP

Sheet Assumptions
B2: Software Operating Drivers
B4: Driver | C4: Base | D4: Downside | E4: Active | F4: Units / note
B5: Beginning ARR | C5: 20878.6 | D5: 20878.6 | E5: =IF(Cover!$C$9="Downside",D5,C5) -> 20878.6 | F5: $mm
B6: New ARR added (% of beginning ARR) | C6: 0.1 | D6: 0.1 | E6: =IF(Cover!$C$9="Downside",D6,C6) -> 0.1 | F6: %
B7: Expansion ARR (% of beginning ARR) | C7: 0.09 | D7: 0.09 | E7: =IF(Cover!$C$9="Downside",D7,C7) -> 0.09 | F7: %
B8: Contraction ARR (% of beginning ARR) | C8: 0.03 | D8: 0.03 | E8: =IF(Cover!$C$9="Downside",D8,C8) -> 0.03 | F8: %
B9: Gross churn (% of beginning ARR) | C9: 0.054722 | D9: 0.057592 | E9: =IF(Cover!$C$9="Downside",D9,C9) -> 0.054722 | F9: %
B10: Services revenue (% of subscription revenue) | C10: 0.03 | D10: 0.03 | E10: =IF(Cover!$C$9="Downside",D10,C10) -> 0.03 | F10: %
B11: Subscription gross margin | C11: 0.908956 | D11: 0.894578 | E11: =IF(Cover!$C$9="Downside",D11,C11) -> 0.908956 | F11: %
B12: Services gross margin | C12: 0.35 | D12: 0.35 | E12: =IF(Cover!$C$9="Downside",D12,C12) -> 0.35 | F12: %
B13: Sales & marketing (% of revenue) | C13: 0.272961 | D13: 0.275697 | E13: =IF(Cover!$C$9="Downside",D13,C13) -> 0.272961 | F13: %
B14: Research & development (% of revenue) | C14: 0.187261 | D14: 0.237759 | E14: =IF(Cover!$C$9="Downside",D14,C14) -> 0.187261 | F14: %
B15: General & administrative (% of revenue) | C15: 0.066179 | D15: 0.072801 | E15: =IF(Cover!$C$9="Downside",D15,C15) -> 0.066179 | F15: %
B16: Stock-based compensation (% of revenue) | C16: 0.081703 | D16: 0.088516 | E16: =IF(Cover!$C$9="Downside",D16,C16) -> 0.081703 | F16: %
... B23: Contract liability / deferred revenue (% of revenue) | C23: 0.295763 | D23: 0.306559 | E23: =IF(Cover!$C$9="Downside",D23,C23) -> 0.295763 | F23: %

Sheet ARR Rollforward
B2: Annual Recurring Revenue Roll-Forward
B4: $mm | C4: Year 1 | D4: Year 2 | E4: Year 3 | F4: Year 4 | G4: Year 5
B5: Beginning ARR | C5: =Assumptions!$E$5 -> 20878.6 | D5: =C10 -> 23076.657 | E5: =D10 -> 25506.122 | F5: =E10 -> 28191.355 | G5: =F10 -> 31159.285
B6: + New ARR | C6: =C5*Assumptions!$E$6 -> 2087.86 | D6: =D5*Assumptions!$E$6 -> 2307.6657 | E6: =E5*Assumptions!$E$6 -> 2550.6122 | F6: =F5*Assumptions!$E$6 -> 2819.1355 | G6: =G5*Assumptions!$E$6 -> 3115.9285
B7: + Expansion ARR | C7: =C5*Assumptions!$E$7 -> 1879.074 | D7: =D5*Assumptions!$E$7 -> 2076.8992 | E7: =E5*Assumptions!$E$7 -> 2295.5509 | F7: =F5*Assumptions!$E$7 -> 2537.222 | G7: =G5*Assumptions!$E$7 -> 2804.3356
B8: - Contraction ARR | C8: =C5*Assumptions!$E$8 -> 626.358 | D8: =D5*Assumptions!$E$8 -> 692.29972 | E8: =E5*Assumptions!$E$8 -> 765.18365 | F8: =F5*Assumptions!$E$8 -> 845.74065 | G8: =G5*Assumptions!$E$8 -> 934.77854
B9: - Gross churn | C9: =C5*Assumptions!$E$9 -> 1142.5187 | D9: =D5*Assumptions!$E$9 -> 1262.8008 | E9: =E5*Assumptions!$E$9 -> 1395.746 | F9: =F5*Assumptions!$E$9 -> 1542.6873 | G9: =G5*Assumptions!$E$9 -> 1705.0984
B10: Ending ARR | C10: =C5+C6+C7-C8-C9 -> 23076.657 | D10: =D5+D6+D7-D8-D9 -> 25506.122 | E10: =E5+E6+E7-E8-E9 -> 28191.355 | F10: =F5+F6+F7-F8-F9 -> 31159.285 | G10: =G5+G6+G7-G8-G9 -> 34439.672
B11: Net new ARR | C11: =C10-C5 -> 2198.0573 | D11: =D10-D5 -> 2429.4643 | E11: =E10-E5 -> 2685.2335 | F11: =F10-F5 -> 2967.9295 | G11: =G10-G5 -> 3280.3872
B12: Net revenue retention | C12: =IFERROR((C5+C7-C8-C9)/C5,0) -> 1.005278 | D12: =IFERROR((D5+D7-D8-D9)/D5,0) -> 1.005278 | E12: =IFERROR((E5+E7-E8-E9)/E5,0) -> 1.005278 | F12: =IFERROR((F5+F7-F8-F9)/F5,0) -> 1.005278 | G12: =IFERROR((G5+G7-G8-G9)/G5,0) -> 1.005278
B13: Gross revenue retention | C13: =IFERROR((C5-C9)/C5,0) -> 0.945278 | D13: =IFERROR((D5-D9)/D5,0) -> 0.945278 | E13: =IFERROR((E5-E9)/E5,0) -> 0.945278 | F13: =IFERROR((F5-F9)/F5,0) -> 0.945278 | G13: =IFERROR((G5-G9)/G5,0) -> 0.945278
B14: ARR growth | C14: =IFERROR(C10/C5-1,0) -> 0.105278 | D14: =IFERROR(D10/D5-1,0) -> 0.105278 | E14: =IFERROR(E10/E5-1,0) -> 0.105278 | F14: =IFERROR(F10/F5-1,0) -> 0.105278 | G14: =IFERROR(G10/G5-1,0) -> 0.105278

Sheet Operating Model
B2: Revenue, Margin, and Cash Flow
B4: $mm | C4: Year 1 | D4: Year 2 | E4: Year 3 | F4: Year 4 | G4: Year 5
B5: Subscription revenue | C5: =AVERAGE('ARR Rollforward'!C5,'ARR Rollforward'!C10) -> 21977.629 | D5: =AVERAGE('ARR Rollforward'!D5,'ARR Rollforward'!D10) -> 24291.389 | E5: =AVERAGE('ARR Rollforward'!E5,'ARR Rollforward'!E10) -> 26848.738 | F5: =AVERAGE('ARR Rollforward'!F5,'ARR Rollforward'!F10) -> 29675.32 | G5: =AVERAGE('ARR Rollforward'!G5,'ARR Rollforward'!G10) -> 32799.478
B6: Services revenue | C6: =C5*Assumptions!$E$10 -> 659.32886 | D6: =D5*Assumptions!$E$10 -> 728.74168 | E6: =E5*Assumptions!$E$10 -> 805.46215 | F6: =F5*Assumptions!$E$10 -> 890.25959 | G6: =G5*Assumptions!$E$10 -> 983.98434
B7: Total revenue | C7: =C5+C6 -> 22636.957 | D7: =D5+D6 -> 25020.131 | E7: =E5+E6 -> 27654.2 | F7: =F5+F6 -> 30565.579 | G7: =G5+G6 -> 33783.462
B8: Subscription gross profit | C8: =C5*Assumptions!$E$11 -> 19976.697 | D8: =D5*Assumptions!$E$11 -> 22079.804 | E8: =E5*Assumptions!$E$11 -> 24404.322 | F8: =F5*Assumptions!$E$11 -> 26973.56 | G8: =G5*Assumptions!$E$11 -> 29813.282
B9: Services gross profit | C9: =C6*Assumptions!$E$12 -> 230.7651 | D9: =D6*Assumptions!$E$12 -> 255.05959 | E9: =E6*Assumptions!$E$12 -> 281.91175 | F9: =F6*Assumptions!$E$12 -> 311.59086 | G9: =G6*Assumptions!$E$12 -> 344.39452
B10: Total gross profit | C10: =C8+C9 -> 20207.463 | D10: =D8+D9 -> 22334.864 | E10: =E8+E9 -> 24686.234 | F10: =F8+F9 -> 27285.151 | G10: =G8+G9 -> 30157.677
B11: Blended gross margin | C11: =IFERROR(C10/C7,0) -> 0.89267573 | D11: =IFERROR(D10/D7,0) -> 0.89267573 | E11: =IFERROR(E10/E7,0) -> 0.89267573 | F11: =IFERROR(F10/F7,0) -> 0.89267573 | G11: =IFERROR(G10/G7,0) -> 0.89267573
B12: Sales & marketing | C12: =C7*Assumptions!$E$13 -> 6179.0066 | D12: =D7*Assumptions!$E$13 -> 6829.52 | E12: =E7*Assumptions!$E$13 -> 7548.5182 | F12: =F7*Assumptions!$E$13 -> 8343.2111 | G12: =G7*Assumptions!$E$13 -> 9221.5677
B13: Research & development | C13: =C7*Assumptions!$E$14 -> 4239.0193 | D13: =D7*Assumptions!$E$14 -> 4685.2948 | E13: =E7*Assumptions!$E$14 -> 5178.5532 | F13: =F7*Assumptions!$E$14 -> 5723.741 | G13: =G7*Assumptions!$E$14 -> 6326.325
B14: General & administrative | C14: =C7*Assumptions!$E$15 -> 1498.0912 | D14: =D7*Assumptions!$E$15 -> 1655.8073 | E14: =E7*Assumptions!$E$15 -> 1830.1273 | F14: =F7*Assumptions!$E$15 -> 2022.7995 | G14: =G7*Assumptions!$E$15 -> 2235.7558
B15: Total operating expense | C15: =C12+C13+C14 -> 11916.117 | D15: =D12+D13+D14 -> 13170.622 | E15: =E12+E13+E14 -> 14557.199 | F15: =F12+F13+F14 -> 16089.752 | G15: =G12+G13+G14 -> 17783.648
B16: GAAP operating income | C16: =C10-C15 -> 8291.3454 | D16: =D10-D15 -> 9164.2417 | E16: =E10-E15 -> 10129.035 | F16: =F10-F15 -> 11195.399 | G16: =G10-G15 -> 12374.029
B17: GAAP operating margin | C17: =IFERROR(C16/C7,0) -> 0.36627473 | D17: =IFERROR(D16/D7,0) -> 0.36627473 | E17: =IFERROR(E16/E7,0) -> 0.36627473 | F17: =IFERROR(F16/F7,0) -> 0.36627473 | G17: =IFERROR(G16/G7,0) -> 0.36627473
B18: Stock-based compensation | C18: =C7*Assumptions!$E$16 -> 1849.5073 | D18: =D7*Assumptions!$E$16 -> 2044.2198 | E18: =E7*Assumptions!$E$16 -> 2259.4311 | F18: =F7*Assumptions!$E$16 -> 2497.2995 | G18: =G7*Assumptions!$E$16 -> 2760.2102
B19: Non-GAAP operating income (ex-SBC) | C19: =C16+C18 -> 10140.853 | D19: =D16+D18 -> 11208.461 | E19: =E16+E18 -> 12388.466 | F19: =F16+F18 -> 13692.699 | G19: =G16+G18 -> 15134.239
B20: Non-GAAP operating margin | C20: =IFERROR(C19/C7,0) -> 0.44797773 | D20: =IFERROR(D19/D7,0) -> 0.44797773 | E20: =IFERROR(E19/E7,0) -> 0.44797773 | F20: =IFERROR(F19/F7,0) -> 0.44797773 | G20: =IFERROR(G19/G7,0) -> 0.44797773
B21: Cash taxes | C21: =MAX(0,C16)*Assumptions!$E$18 -> 1522.7056 | D21: =MAX(0,D16)*Assumptions!$E$18 -> 1683.013 | E21: =MAX(0,E16)*Assumptions!$E$18 -> 1860.1972 | F21: =MAX(0,F16)*Assumptions!$E$18 -> 2056.0351 | G21: =MAX(0,G16)*Assumptions!$E$18 -> 2272.4903
B22: Capex | C22: =C7*Assumptions!$E$17 -> 170.47893 | D22: =D7*Assumptions!$E$17 -> 188.42661 | E22: =E7*Assumptions!$E$17 -> 208.26378 | F22: =F7*Assumptions!$E$17 -> 230.18938 | G22: =G7*Assumptions!$E$17 -> 254.42326
B23: Free cash flow | C23: =C16+C18-C21-C22 -> 8447.6683 | D23: =D16+D18-D21-D22 -> 9337.0219 | E23: =E16+E18-E21-E22 -> 10320.005 | F23: =F16+F18-F21-F22 -> 11406.474 | G23: =G16+G18-G21-G22 -> 12607.325
B24: FCF margin | C24: =IFERROR(C23/C7,0) -> 0.37318037 | D24: =IFERROR(D23/D7,0) -> 0.37318037 | E24: =IFERROR(E23/E7,0) -> 0.37318037 | F24: =IFERROR(F23/F7,0) -> 0.37318037 | G24: =IFERROR(G23/G7,0) -> 0.37318037

Sheet RPO & Bookings
B2: Remaining Performance Obligations and Implied Bookings
B4: $mm | C4: Year 1 | D4: Year 2 | E4: Year 3 | F4: Year 4 | G4: Year 5
B5: Revenue recognised | C5: ='Operating Model'!C7 -> 22636.957 | D5: ='Operating Model'!D7 -> 25020.131 | E5: ='Operating Model'!E7 -> 27654.2 | F5: ='Operating Model'!F7 -> 30565.579 | G5: ='Operating Model'!G7 -> 33783.462
B6: Beginning RPO | C6: =Assumptions!$E$20 -> 19960 | D6: =C7 -> 21447.453 | E6: =D7 -> 23705.398 | F6: =E7 -> 26201.055 | G6: =F7 -> 28959.45
B7: Ending RPO | C7: =C5*Assumptions!$E$21 -> 21447.453 | D7: =D5*Assumptions!$E$21 -> 23705.398 | E7: =E5*Assumptions!$E$21 -> 26201.055 | F7: =F5*Assumptions!$E$21 -> 28959.45 | G7: =G5*Assumptions!$E$21 -> 32008.243
B8: Implied gross bookings (residual) | C8: =C7-C6+C5 -> 24124.411 | D8: =D7-D6+D5 -> 27278.076 | E8: =E7-E6+E5 -> 30149.857 | F8: =F7-F6+F5 -> 33323.974 | G8: =G7-G6+G5 -> 36832.255
B9: Book-to-bill | C9: =IFERROR(C8/C5,0) -> 1.0657091 | D9: =IFERROR(D8/D5,0) -> 1.0902451 | E9: =IFERROR(E8/E5,0) -> 1.0902451 | F9: =IFERROR(F8/F5,0) -> 1.0902451 | G9: =IFERROR(G8/G5,0) -> 1.0902451
B10: RPO growth | C10: =IFERROR(C7/C6-1,0) -> 0.074521707 | D10: =IFERROR(D7/D6-1,0) -> 0.105278 | E10: =IFERROR(E7/E6-1,0) -> 0.105278 | F10: =IFERROR(F7/F6-1,0) -> 0.105278 | G10: =IFERROR(G7/G6-1,0) -> 0.105278
B11: Current RPO (recognised within 12 months) | C11: =C7*Assumptions!$E$22 -> 13726.37 | D11: =D7*Assumptions!$E$22 -> 15171.455 | E11: =E7*Assumptions!$E$22 -> 16768.675 | F11: =F7*Assumptions!$E$22 -> 18534.048 | G11: =G7*Assumptions!$E$22 -> 20485.275
B12: Non-current RPO | C12: =C7-C11 -> 7721.0832 | D12: =D7-D11 -> 8533.9434 | E12: =E7-E11 -> 9432.3799 | F12: =F7-F11 -> 10425.402 | G12: =G7-G11 -> 11522.967
B13: Contract liability (deferred revenue) | C13: =C5*Assumptions!$E$23 -> 6695.1745 | D13: =D5*Assumptions!$E$23 -> 7400.029 | E13: =E5*Assumptions!$E$23 -> 8179.0893 | F13: =F5*Assumptions!$E$23 -> 9040.1675 | G13: =G5*Assumptions!$E$23 -> 9991.8982
B14: Unbilled RPO | C14: =C7-C13 -> 14752.279 | D14: =D7-D13 -> 16305.369 | E14: =E7-E13 -> 18021.966 | F14: =F7-F13 -> 19919.282 | G14: =G7-G13 -> 22016.345
B15: Unbilled share of RPO | C15: =IFERROR(C14/C7,0) -> 0.68783359 | D15: =IFERROR(D14/D7,0) -> 0.68783359 | E15: =IFERROR(E14/E7,0) -> 0.68783359 | F15: =IFERROR(F14/F7,0) -> 0.68783359 | G15: =IFERROR(G14/G7,0) -> 0.68783359
B16: Current RPO / following-year revenue | C16: =IFERROR(C11/'Operating Model'!D7,0) -> 0.54861304 | D16: =IFERROR(D11/'Operating Model'!E7,0) -> 0.54861304 | E16: =IFERROR(E11/'Operating Model'!F7,0) -> 0.54861304 | F16: =IFERROR(F11/'Operating Model'!G7,0) -> 0.54861304 | G16: n/a
B17: Ending RPO / ending ARR | C17: =IFERROR(C7/'ARR Rollforward'!C10,0) -> 0.92940035 | D17: =IFERROR(D7/'ARR Rollforward'!D10,0) -> 0.92940035 | E17: =IFERROR(E7/'ARR Rollforward'!E10,0) -> 0.92940035 | F17: =IFERROR(F7/'ARR Rollforward'!F10,0) -> 0.92940035 | G17: =IFERROR(G7/'ARR Rollforward'!G10,0) -> 0.92940035

Sheet Unit Economics
B2: Customer Acquisition Efficiency
B4: Metric | C4: Year 1 | D4: Year 2 | E4: Year 3 | F4: Year 4 | G4: Year 5
B5: S&M spend | C5: ='Operating Model'!C12 -> 6179.0066 | D5: ='Operating Model'!D12 -> 6829.52 | E5: ='Operating Model'!E12 -> 7548.5182 | F5: ='Operating Model'!F12 -> 8343.2111 | G5: ='Operating Model'!G12 -> 9221.5677
B6: New + expansion ARR | C6: ='ARR Rollforward'!C6+'ARR Rollforward'!C7 -> 3966.934 | D6: ='ARR Rollforward'!D6+'ARR Rollforward'!D7 -> 4384.5649 | E6: ='ARR Rollforward'!E6+'ARR Rollforward'!E7 -> 4846.1631 | F6: ='ARR Rollforward'!F6+'ARR Rollforward'!F7 -> 5356.3575 | G6: ='ARR Rollforward'!G6+'ARR Rollforward'!G7 -> 5920.2641
B7: Magic number | C7: =IFERROR(C6/C5,0) -> 0.64200191 | D7: =IFERROR(D6/D5,0) -> 0.64200191 | E7: =IFERROR(E6/E5,0) -> 0.64200191 | F7: =IFERROR(F6/F5,0) -> 0.64200191 | G7: =IFERROR(G6/G5,0) -> 0.64200191
B8: CAC payback (months) | C8: =IFERROR(C5/C6*12,0) -> 18.691533 | D8: =IFERROR(D5/D6*12,0) -> 18.691533 | E8: =IFERROR(E5/E6*12,0) -> 18.691533 | F8: =IFERROR(F5/F6*12,0) -> 18.691533 | G8: =IFERROR(G5/G6*12,0) -> 18.691533
B9: Gross-profit-weighted CAC payback (months) | C9: =IFERROR(C5/(C6*Assumptions!$E$19)*12,0) -> 21.001723 | D9: =IFERROR(D5/(D6*Assumptions!$E$19)*12,0) -> 21.001723 | E9: =IFERROR(E5/(E6*Assumptions!$E$19)*12,0) -> 21.001723 | F9: =IFERROR(F5/(F6*Assumptions!$E$19)*12,0) -> 21.001723 | G9: =IFERROR(G5/(G6*Assumptions!$E$19)*12,0) -> 21.001723
B10: S&M as % of new ARR | C10: =IFERROR(C5/C6,0) -> 1.5576278 | D10: =IFERROR(D5/D6,0) -> 1.5576278 | E10: =IFERROR(E5/E6,0) -> 1.5576278 | F10: =IFERROR(F5/F6,0) -> 1.5576278 | G10: =IFERROR(G5/G6,0) -> 1.5576278

Sheet Rule of 40
B2: Growth versus Profitability Trade-off
B4: Metric | C4: Year 1 | D4: Year 2 | E4: Year 3 | F4: Year 4 | G4: Year 5
B5: Revenue growth | C5: ='ARR Rollforward'!C14 -> 0.105278 | D5: =IFERROR('Operating Model'!D7/'Operating Model'!C7-1,0) -> 0.105278 | E5: =IFERROR('Operating Model'!E7/'Operating Model'!D7-1,0) -> 0.105278 | F5: =IFERROR('Operating Model'!F7/'Operating Model'!E7-1,0) -> 0.105278 | G5: =IFERROR('Operating Model'!G7/'Operating Model'!F7-1,0) -> 0.105278
B6: FCF margin | C6: ='Operating Model'!C24 -> 0.37318037 | D6: ='Operating Model'!D24 -> 0.37318037 | E6: ='Operating Model'!E24 -> 0.37318037 | F6: ='Operating Model'!F24 -> 0.37318037 | G6: ='Operating Model'!G24 -> 0.37318037
B7: Rule of 40 (growth + FCF margin) | C7: =C5+C6 -> 0.47845837 | D7: =D5+D6 -> 0.47845837 | E7: =E5+E6 -> 0.47845837 | F7: =F5+F6 -> 0.47845837 | G7: =G5+G6 -> 0.47845837
B8: Non-GAAP operating margin | C8: ='Operating Model'!C20 -> 0.44797773 | D8: ='Operating Model'!D20 -> 0.44797773 | E8: ='Operating Model'!E20 -> 0.44797773 | F8: ='Operating Model'!F20 -> 0.44797773 | G8: ='Operating Model'!G20 -> 0.44797773
B9: Rule of 40 (growth + operating margin) | C9: =C5+C8 -> 0.55325573 | D9: =D5+D8 -> 0.55325573 | E9: =E5+E8 -> 0.55325573 | F9: =F5+F8 -> 0.55325573 | G9: =G5+G8 -> 0.55325573
B10: Status | C10: =IF(C7>=0.4,"PASS",IF(C7>=0.3,"REVIEW","BELOW")) -> PASS | D10: =IF(D7>=0.4,"PASS",IF(D7>=0.3,"REVIEW","BELOW")) -> PASS | E10: =IF(E7>=0.4,"PASS",IF(E7>=0.3,"REVIEW","BELOW")) -> PASS | F10: =IF(F7>=0.4,"PASS",IF(F7>=0.3,"REVIEW","BELOW")) -> PASS | G10: =IF(G7>=0.4,"PASS",IF(G7>=0.3,"REVIEW","BELOW")) -> PASS

Sheet Checks
B2: Software Model Checks
B4: Check | C4: Status
B5: ARR roll-forward reconciles (ending = beginning + new + expansion - contraction - churn) | C5: =IF(MAX(ABS('ARR Rollforward'!C10-('ARR Rollforward'!C5+'ARR Rollforward'!C6+'ARR Rollforward'!C7-'ARR Rollforward'!C8-'ARR Rollforward'!C9)))<0.000001,"PASS","FAIL") -> PASS
B6: ARR balances never negative | C6: =IF(MIN('ARR Rollforward'!C10:G10)>=0,"PASS","FAIL") -> PASS
B7: Gross revenue retention does not exceed 100% | C7: =IF(MAX('ARR Rollforward'!C13:G13)<=1.000001,"PASS","FAIL") -> PASS
B8: Net revenue retention exceeds gross revenue retention | C8: =IF(MIN('ARR Rollforward'!C12:G12-'ARR Rollforward'!C13:G13)>=-0.000001,"PASS","FAIL") -> PASS
B9: Total revenue equals subscription plus services | C9: =IF(MAX(ABS('Operating Model'!C7:G7-'Operating Model'!C5:G5-'Operating Model'!C6:G6))<0.000001,"PASS","FAIL") -> PASS
B10: Blended gross margin sits between services and subscription margin | C10: =IF(AND(MIN('Operating Model'!C11:G11)>=Assumptions!E12,MAX('Operating Model'!C11:G11)<=Assumptions!E11),"PASS","REVIEW") -> PASS
B11: Non-GAAP operating income exceeds GAAP (SBC added back) | C11: =IF(MIN('Operating Model'!C19:G19-'Operating Model'!C16:G16)>=0,"PASS","FAIL") -> PASS
B12: Magic number positive | C12: =IF(MIN('Unit Economics'!C7:G7)>0,"PASS","REVIEW") -> PASS
B13: Gross-profit CAC payback within 36 months | C13: =IF(MAX('Unit Economics'!C9:G9)<=36,"PASS","REVIEW") -> PASS
B14: RPO roll-forward reconciles (ending = beginning + bookings - revenue) | C14: =IF(MAX(ABS('RPO & Bookings'!C7:G7-('RPO & Bookings'!C6:G6+'RPO & Bookings'!C8:G8-'RPO & Bookings'!C5:G5)))<0.000001,"PASS","FAIL") -> PASS
B15: Current RPO does not exceed total RPO | C15: =IF(MIN('RPO & Bookings'!C12:G12)>=-0.000001,"PASS","FAIL") -> PASS
B16: Contract liability does not exceed total RPO (unbilled RPO non-negative) | C16: =IF(MIN('RPO & Bookings'!C14:G14)>=-0.000001,"PASS","REVIEW") -> PASS
B17: Implied gross bookings positive (no negative-bookings year) | C17: =IF(MIN('RPO & Bookings'!C8:G8)>0,"PASS","REVIEW") -> PASS
B18: Overall | C18: =IF(COUNTIF(C5:C17,"FAIL")>0,"FAIL",IF(COUNTIF(C5:C17,"REVIEW")>0,"REVIEW","PASS")) -> PASS

Sheet Sources
B2: Source Register
B4: Input / dataset | C4: Source URL or document | D4: As-of | E4: Notes / transformation
B5: ARR and retention disclosures | C5: [10-K / 10-Q / shareholder letter] | D5: [period] | E5: Beginning/ending ARR, NRR, customer counts
B6: Revenue disaggregation | C6: [10-K revenue note] | D6: [period] | E6: Subscription versus services split and gross margin by type
B7: Stock-based compensation | C7: [10-K equity note] | D7: [period] | E7: SBC by expense line
B8: Remaining performance obligations | C8: [10-K revenue note / XBRL RevenueRemainingPerformanceObligation] | D8: [period] | E8: Total RPO and the portion expected to be recognised within twelve months
B9: Contract liabilities | C9: [10-K balance sheet / XBRL ContractWithCustomerLiability] | D9: [period] | E9: Deferred revenue, used to split billed from unbilled RPO
B10: Industry cost of capital and multiples | C10: https://pages.stern.nyu.edu/~adamodar/New_Home_Page/data.html | D10: [annual] | E10: Software industry margins, betas, and multiple ranges for driver grounding
B11: Adobe Inc. FY2025 Form 10-K (XBRL company facts, CIK 0000796343) | C11: https://www.sec.gov/cgi-bin/browse-edgar?action=getcompany&CIK=0000796343&type=10-K | D11: 2026-01-15 | E11: SEC XBRL company facts for CIK 0000796343, recorded at tools/data_fabric/out/ADBE_facts_annual_series.json. Three most recent disclosed fiscal years: 2025-11-28, 2024-11-29, 2023-12-01.
B12: Frozen source snapshot | C12: repo://31_Software_SaaS/sources/snapshots/software-public-adobe-fy2025.json | D12: 2026-01-15 | E12: Immutable curated observation package with SHA-256 digest
B13: Case driver (no disclosure exists) | C13: repo://31_Software_SaaS/sources/snapshots/software-public-adobe-fy2025.json | D13: 2026-01-15 | E13: New, expansion, and contraction ARR rates are not disclosed by Adobe or by any other issuer. They are drivers. Their decomposition is chosen; their net effect is not -- see the gross-churn residual, which pins the sum to disclosed growth.

Sheet RefreshLog
B2: Refresh Log
B4: Date | C4: Trigger | D4: Source snapshot | E4: What changed | F4: Reviewer / challenge | G4: Next check
B5: 2026-08-06 | C5: Initial materialization from SEC XBRL company facts | D5: repo://31_Software_SaaS/sources/snapshots/software-public-adobe-fy2025.json | E5: Built the software domain's first company case. Sourced the entire GAAP cost and RPO layer from Adobe's disclosed FY2025 facts; pinned blended gross margin and net ARR growth to disclosure while leaving their undisclosed components as declared drivers; set the Downside column from the worst of three disclosed fiscal years rather than an invented stress. The ARR cohort layer remains ungrounded because no issuer discloses it. | F5: External historical case; human stakeholder approval remains pending. Absolute ARR and RPO dollar levels inherit the revenue-as-ARR-scale proxy and should be read as approximate; ratios are sourced. | G5: On Adobe's next 10-K, builder change, or annual review
