Workbook

Sheet Cover
B2: [TRANSACTION] — Structured Credit Model
B4: Transaction / collateral: | C4: Reference Amortizing Consumer Pool
B5: Cut-off / payment date: | C5: [dates]
B6: Last refreshed: | C6: 2026-08-03
B7: Next distribution / trigger date: | C7: [date]
B8: Refresh cadence: | C8: Monthly and on servicer reports
B9: Active scenario: | C9: Base
B10: Units: | C10: $ in millions unless noted
B13: Modeling conventions
B14: Blue text / yellow fill | C14: Hardcoded input or selected scenario
B15: Black text | C15: Formula / same-sheet calculation
B16: Green text | C16: Cross-sheet formula / link
B17: Checks | C17: PASS / REVIEW / FAIL must remain visible

Sheet Institutional Surface
B2: Structured Finance & Securitization — Institutional Decision Surface
B4: Model ID | C4: 19
B5: Domain | C5: Structured Finance & Securitization
B6: Declared maturity | C6: M2
B7: Canonical builder | C7: tools/builders/build_securitization_institutional.py
B8: Decision arena | C8: structuring, collateral, servicing, trustee, rating agency and investor
B9: Committee artifact | C9: cash-flow, trigger and tranche-loss pack
B10: Operating cadence | C10: monthly surveillance; event-driven trigger review
B12: Key decision outputs
B13: # | C13: Requirement | D13: Owner | E13: Evidence / location | F13: Status
B14: 1 | C14: collateral cash flow and losses | F14: OPEN
B15: 2 | C15: tranche interest/principal waterfall | F15: OPEN
B16: 3 | C16: OC/IC and performance triggers | F16: OPEN
B17: 4 | C17: base, downside and break-even outputs | F17: OPEN
B18: 5 | C18: liquidity / funding requirement and binding constraint | F18: OPEN
B20: Insider questions
B21: # | C21: Requirement | D21: Owner | E21: Evidence / location | F21: Status
B22: 1 | C22: What changes when the trigger fails? | F22: OPEN
B23: 2 | C23: Who advances delinquent interest and for how long? | F23: OPEN
B24: 3 | C24: Which tape fields are servicer-created? | F24: OPEN
B25: 4 | C25: Which assumption is owner-approved versus modeler judgement? | F25: OPEN
B26: 5 | C26: What fails first and who must act? | F26: OPEN
B28: Scenario families
B29: # | C29: Requirement | D29: Owner | E29: Evidence / location | F29: Status
B30: 1 | C30: default and severity | F30: OPEN
B31: 2 | C31: prepayment | F31: OPEN
B32: 3 | C32: recovery timing | F32: OPEN
B33: 4 | C33: data freshness / source failure | F33: OPEN
B34: 5 | C34: combined severe-but-plausible downside | F34: OPEN
B36: Primary diligence documents
B37: # | C37: Requirement | D37: Owner | E37: Evidence / location | F37: Status
B38: 1 | C38: offering memorandum | F38: OPEN
B39: 2 | C39: pool tape and data dictionary | F39: OPEN
B40: 3 | C40: servicing agreement | F40: OPEN
B41: 4 | C41: approved model card and assumption register | F41: OPEN
B42: 5 | C42: independent validation and challenge record | F42: OPEN
B44: Challenge tests
B45: # | C45: Requirement | D45: Owner | E45: Evidence / location | F45: Status
B46: 1 | C46: collateral roll-forward conserves | F46: OPEN
B47: 2 | C47: waterfall distributes available funds only | F47: OPEN
...

Sheet Challenge Log
B2: Independent Challenge, Override and Closure Log
B4: Date | C4: Reviewer | D4: Challenge | E4: Owner response | F4: Evidence | G4: Impact | H4: Status | I4: Closure
D5: collateral roll-forward conserves | H5: OPEN
D6: waterfall distributes available funds only | H6: OPEN
D7: tranche balances nonnegative | H7: OPEN
D8: source-to-model lineage is reproducible | H8: OPEN
D9: units, signs, dates and legal definitions reconcile | H9: OPEN

Sheet Lineage Map
B2: Source, Transformation, Ownership and Refresh Map
B4: Source class | C4: Cadence | D4: Control | E4: System / provider | F4: As-of | G4: Owner | H4: Transform | I4: Downstream | J4: Status
B5: loan-level tape | C5: monthly | D5: field and cut-off reconciliation | J5: TO MAP
B6: servicer report | C6: monthly | D6: cash and status tie-out | J6: TO MAP
B7: model governance evidence | C7: per release | D7: version, reviewer, sign-off and change log | J7: TO MAP
B8: decision-use snapshot | C8: per decision | D8: immutable as-of date and source receipt | J8: TO MAP

Sheet Assumptions
B2: Collateral and Capital Structure Assumptions
B4: Assumption | C4: Base | D4: Downside | E4: Active | F4: Units / note
B5: Opening collateral balance | C5: 1200 | D5: 1000 | E5: =IF(Cover!$C$9="Downside",D5,C5) -> 1200 | F5: $mm
B6: Collateral gross coupon | C6: 0.08 | D6: 0.075 | E6: =IF(Cover!$C$9="Downside",D6,C6) -> 0.08 | F6: %
B7: Annual CPR | C7: 0.14 | D7: 0.06 | E7: =IF(Cover!$C$9="Downside",D7,C7) -> 0.14 | F7: %
B8: Annual CDR | C8: 0.025 | D8: 0.08 | E8: =IF(Cover!$C$9="Downside",D8,C8) -> 0.025 | F8: %
B9: Recovery rate | C9: 0.5 | D9: 0.25 | E9: =IF(Cover!$C$9="Downside",D9,C9) -> 0.5 | F9: %
B10: Recovery lag | C10: 3 | D10: 6 | E10: =IF(Cover!$C$9="Downside",D10,C10) -> 3 | F10: months
B11: Servicing and senior fees | C11: 0.01 | D11: 0.012 | E11: =IF(Cover!$C$9="Downside",D11,C11) -> 0.01 | F11: % annual
B12: Senior tranche opening balance | C12: 650 | D12: 650 | E12: =IF(Cover!$C$9="Downside",D12,C12) -> 650 | F12: $mm
B13: Senior tranche coupon | C13: 0.05 | D13: 0.06 | E13: =IF(Cover!$C$9="Downside",D13,C13) -> 0.05 | F13: %
B14: Mezz tranche opening balance | C14: 220 | D14: 220 | E14: =IF(Cover!$C$9="Downside",D14,C14) -> 220 | F14: $mm
B15: Mezz tranche coupon | C15: 0.08 | D15: 0.1 | E15: =IF(Cover!$C$9="Downside",D15,C15) -> 0.08 | F15: %
B16: Reserve account | C16: 20 | D16: 20 | E16: =IF(Cover!$C$9="Downside",D16,C16) -> 20 | F16: $mm
... B21: Model horizon | C21: 24 | D21: 24 | E21: =IF(Cover!$C$9="Downside",D21,C21) -> 24 | F21: months

Sheet Collateral
B2: Monthly Collateral Cash Flows
B4: $mm | C4: M1 | D4: M2 | E4: M3 | F4: M4 | G4: M5 | H4: M6 | I4: M7 | J4: M8 | K4: M9 | L4: M10 | M4: M11 | N4: M12 | O4: M13 | P4: M14 | Q4: M15 | R4: M16 | S4: M17 | T4: M18 | U4: M19 | V4: M20 | W4: M21 | X4: M22 | Y4: M23 | Z4: M24
B5: Beginning collateral | C5: =Assumptions!E5 -> 1200 | D5: =C14 -> 1133.2431 | E5: =D14 -> 1068.1769 | F5: =E14 -> 1004.7663 | G5: =F14 -> 942.97683 | H5: =G14 -> 882.77471 | I5: =H14 -> 824.12681 | J5: =I14 -> 767.00062 | K5: =J14 -> 711.36424 | ... Z5: =Y14 -> 35.673924
B6: Scheduled principal | C6: =MIN(C5,C5/24) -> 50 | D6: =MIN(D5,D5/23) -> 49.271441 | E6: =MIN(E5,E5/22) -> 48.553497 | F6: =MIN(F5,F5/21) -> 47.846015 | G6: =MIN(G5,G5/20) -> 47.148842 | H6: =MIN(H5,H5/19) -> 46.461827 | I6: =MIN(I5,I5/18) -> 45.784823 | J6: =MIN(J5,J5/17) -> 45.117684 | K6: =MIN(K5,K5/16) -> 44.460265 | L6: =MIN(L5,L5/15) -> 43.812426 | M6: =MIN(M5,M5/14) -> 43.174027 | N6: =MIN(N5,N5/13) -> 42.54493 | O6: =MIN(O5,O5/12) -> 41.925 | P6: =MIN(P5,P5/11) -> 41.314103 | Q6: =MIN(Q5,Q5/10) -> 40.712107 | R6: =MIN(R5,R5/9) -> 40.118883 | S6: =MIN(S5,S5/8) -> 39.534304 | T6: =MIN(T5,T5/7) -> 38.958242 | U6: =MIN(U5,U5/6) -> 38.390574 | V6: =MIN(V5,V5/5) -> 37.831178 | W6: =MIN(W5,W5/4) -> 37.279932 | X6: =MIN(X5,X5/3) -> 36.736719 | Y6: =MIN(Y5,Y5/2) -> 36.201422 | Z6: =MIN(Z5,Z5/1) -> 35.673924
B7: Defaults | C7: =MAX(0,C5-C6)*'Loss Curves'!C6 -> 2.4237322 | D7: =MAX(0,D5-D6)*'Loss Curves'!D6 -> 2.2845714 | E7: =MAX(0,E5-E6)*'Loss Curves'!E6 -> 2.1489515 | F7: =MAX(0,F5-F6)*'Loss Curves'!F6 -> 2.0167987 | G7: =MAX(0,G5-G6)*'Loss Curves'!G6 -> 1.888041 | H7: =MAX(0,H5-H6)*'Loss Curves'!H6 -> 1.7626074 | I7: =MAX(0,I5-I6)*'Loss Curves'!I6 -> 1.6404283 | J7: =MAX(0,J5-J6)*'Loss Curves'!J6 -> 1.5214356 | ... Z7: =MAX(0,Z5-Z6)*'Loss Curves'!Z6 -> 0
B8: Recoveries | C8: 0 | D8: 0 | E8: 0 | F8: =C7*Assumptions!$E$9 -> 1.2118661 | G8: =D7*Assumptions!$E$9 -> 1.1422857 | H8: =E7*Assumptions!$E$9 -> 1.0744757 | I8: =F7*Assumptions!$E$9 -> 1.0083994 | J8: =G7*Assumptions!$E$9 -> 0.9440205 | K8: =H7*Assumptions!$E$9 -> 0.88130369 | L8: =I7*Assumptions!$E$9 -> 0.82021415 | M8: =J7*Assumptions!$E$9 -> 0.7607178 | ... Z8: =W7*Assumptions!$E$9 -> 0.1178564
B9: Prepayments | C9: =MAX(0,C5-C6-C7)*'Loss Curves'!C5 -> 14.333135 | D9: =MAX(0,D5-D6-D7)*'Loss Curves'!D5 -> 13.510185 | E9: =MAX(0,E5-E6-E7)*'Loss Curves'!E5 -> 12.708174 | F9: =MAX(0,F5-F6-F7)*'Loss Curves'!F5 -> 11.926668 | G9: =MAX(0,G5-G6-G7)*'Loss Curves'!G5 -> 11.165238 | H9: =MAX(0,H5-H6-H7)*'Loss Curves'!H5 -> 10.423466 | I9: =MAX(0,I5-I6-I7)*'Loss Curves'!I5 -> 9.7009399 | J9: =MAX(0,J5-J6-J7)*'Loss Curves'!J5 -> 8.9972571 | ... Z9: =MAX(0,Z5-Z6-Z7)*'Loss Curves'!Z5 -> 0
B10: Interest collections | C10: =C5*Assumptions!$E$6/Assumptions!$E$20 -> 8 | D10: =D5*Assumptions!$E$6/Assumptions!$E$20 -> 7.5549542 | E10: =E5*Assumptions!$E$6/Assumptions!$E$20 -> 7.1211796 | F10: =F5*Assumptions!$E$6/Assumptions!$E$20 -> 6.6984421 | G10: =G5*Assumptions!$E$6/Assumptions!$E$20 -> 6.2865122 | H10: =H5*Assumptions!$E$6/Assumptions!$E$20 -> 5.8851647 | I10: =I5*Assumptions!$E$6/Assumptions!$E$20 -> 5.4941787 | J10: =J5*Assumptions!$E$6/Assumptions!$E$20 -> 5.1133375 | ... Z10: =Z5*Assumptions!$E$6/Assumptions!$E$20 -> 0.23782616
B11: Servicing / senior fees | C11: =C5*Assumptions!$E$11/Assumptions!$E$20 -> 1 | D11: =D5*Assumptions!$E$11/Assumptions!$E$20 -> 0.94436928 | E11: =E5*Assumptions!$E$11/Assumptions!$E$20 -> 0.89014745 | F11: =F5*Assumptions!$E$11/Assumptions!$E$20 -> 0.83730526 | G11: =G5*Assumptions!$E$11/Assumptions!$E$20 -> 0.78581403 | H11: =H5*Assumptions!$E$11/Assumptions!$E$20 -> 0.73564559 | I11: =I5*Assumptions!$E$11/Assumptions!$E$20 -> 0.68677234 | J11: =J5*Assumptions!$E$11/Assumptions!$E$20 -> 0.63916718 | ... Z11: =Z5*Assumptions!$E$11/Assumptions!$E$20 -> 0.02972827
B12: Net interest collections | C12: =MAX(0,C10-C11) -> 7 | D12: =MAX(0,D10-D11) -> 6.6105849 | E12: =MAX(0,E10-E11) -> 6.2310321 | F12: =MAX(0,F10-F11) -> 5.8611368 | G12: =MAX(0,G10-G11) -> 5.5006982 | H12: =MAX(0,H10-H11) -> 5.1495191 | I12: =MAX(0,I10-I11) -> 4.8074064 | J12: =MAX(0,J10-J11) -> 4.4741703 | ... Z12: =MAX(0,Z10-Z11) -> 0.20809789
B13: Principal collections | C13: =C6+C8+C9 -> 64.333135 | D13: =D6+D8+D9 -> 62.781626 | E13: =E6+E8+E9 -> 61.261671 | F13: =F6+F8+F9 -> 60.984549 | G13: =G6+G8+G9 -> 59.456365 | H13: =H6+H8+H9 -> 57.959768 | I13: =I6+I8+I9 -> 56.494162 | J13: =J6+J8+J9 -> 55.058961 | ... Z13: =Z6+Z8+Z9 -> 35.79178
B14: Ending collateral | C14: =MAX(0,C5-C6-C7-C9) -> 1133.2431 | D14: =MAX(0,D5-D6-D7-D9) -> 1068.1769 | E14: =MAX(0,E5-E6-E7-E9) -> 1004.7663 | F14: =MAX(0,F5-F6-F7-F9) -> 942.97683 | G14: =MAX(0,G5-G6-G7-G9) -> 882.77471 | H14: =MAX(0,H5-H6-H7-H9) -> 824.12681 | I14: =MAX(0,I5-I6-I7-I9) -> 767.00062 | J14: =MAX(0,J5-J6-J7-J9) -> 711.36424 | ... Z14: =MAX(0,Z5-Z6-Z7-Z9) -> 0

Sheet Loss Curves
B2: Monthly Prepayment, Default, and Recovery Curves
B4: Rate | C4: M1 | D4: M2 | E4: M3 | F4: M4 | G4: M5 | H4: M6 | I4: M7 | J4: M8 | K4: M9 | L4: M10 | M4: M11 | N4: M12 | O4: M13 | P4: M14 | Q4: M15 | R4: M16 | S4: M17 | T4: M18 | U4: M19 | V4: M20 | W4: M21 | X4: M22 | Y4: M23 | Z4: M24
B5: SMM | C5: =1-(1-Assumptions!$E$7)^(1/Assumptions!$E$20) -> 0.012489919 | D5: =1-(1-Assumptions!$E$7)^(1/Assumptions!$E$20) -> 0.012489919 | E5: =1-(1-Assumptions!$E$7)^(1/Assumptions!$E$20) -> 0.012489919 | F5: =1-(1-Assumptions!$E$7)^(1/Assumptions!$E$20) -> 0.012489919 | G5: =1-(1-Assumptions!$E$7)^(1/Assumptions!$E$20) -> 0.012489919 | H5: =1-(1-Assumptions!$E$7)^(1/Assumptions!$E$20) -> 0.012489919 | I5: =1-(1-Assumptions!$E$7)^(1/Assumptions!$E$20) -> 0.012489919 | J5: =1-(1-Assumptions!$E$7)^(1/Assumptions!$E$20) -> 0.012489919 | ... Z5: =1-(1-Assumptions!$E$7)^(1/Assumptions!$E$20) -> 0.012489919
B6: MDR | C6: =1-(1-Assumptions!$E$8)^(1/Assumptions!$E$20) -> 0.0021075932 | D6: =1-(1-Assumptions!$E$8)^(1/Assumptions!$E$20) -> 0.0021075932 | E6: =1-(1-Assumptions!$E$8)^(1/Assumptions!$E$20) -> 0.0021075932 | F6: =1-(1-Assumptions!$E$8)^(1/Assumptions!$E$20) -> 0.0021075932 | G6: =1-(1-Assumptions!$E$8)^(1/Assumptions!$E$20) -> 0.0021075932 | H6: =1-(1-Assumptions!$E$8)^(1/Assumptions!$E$20) -> 0.0021075932 | I6: =1-(1-Assumptions!$E$8)^(1/Assumptions!$E$20) -> 0.0021075932 | J6: =1-(1-Assumptions!$E$8)^(1/Assumptions!$E$20) -> 0.0021075932 | ... Z6: =1-(1-Assumptions!$E$8)^(1/Assumptions!$E$20) -> 0.0021075932
B7: Recovery rate | C7: =Assumptions!$E$9 -> 0.5 | D7: =Assumptions!$E$9 -> 0.5 | E7: =Assumptions!$E$9 -> 0.5 | F7: =Assumptions!$E$9 -> 0.5 | G7: =Assumptions!$E$9 -> 0.5 | H7: =Assumptions!$E$9 -> 0.5 | I7: =Assumptions!$E$9 -> 0.5 | J7: =Assumptions!$E$9 -> 0.5 | ... Z7: =Assumptions!$E$9 -> 0.5
B8: Cumulative default rate | C8: =Collateral!C9/Assumptions!$E$5 -> 0.011944279 | D8: =C8+Collateral!D9/Assumptions!$E$5 -> 0.023202767 | E8: =D8+Collateral!E9/Assumptions!$E$5 -> 0.033792912 | F8: =E8+Collateral!F9/Assumptions!$E$5 -> 0.043731802 | G8: =F8+Collateral!G9/Assumptions!$E$5 -> 0.053036167 | H8: =G8+Collateral!H9/Assumptions!$E$5 -> 0.061722389 | I8: =H8+Collateral!I9/Assumptions!$E$5 -> 0.069806505 | J8: =I8+Collateral!J9/Assumptions!$E$5 -> 0.077304219 | K8: =J8+Collateral!K9/Assumptions!$E$5 -> 0.084230904 | ... Z8: =Y8+Collateral!Z9/Assumptions!$E$5 -> 0.12912201
B9: Cumulative loss rate | C9: =Collateral!C9*(1-C7)/Assumptions!$E$5 -> 0.0059721397 | D9: =C9+Collateral!D9*(1-D7)/Assumptions!$E$5 -> 0.011601383 | E9: =D9+Collateral!E9*(1-E7)/Assumptions!$E$5 -> 0.016896456 | F9: =E9+Collateral!F9*(1-F7)/Assumptions!$E$5 -> 0.021865901 | G9: =F9+Collateral!G9*(1-G7)/Assumptions!$E$5 -> 0.026518084 | H9: =G9+Collateral!H9*(1-H7)/Assumptions!$E$5 -> 0.030861194 | I9: =H9+Collateral!I9*(1-I7)/Assumptions!$E$5 -> 0.034903253 | J9: =I9+Collateral!J9*(1-J7)/Assumptions!$E$5 -> 0.03865211 | K9: =J9+Collateral!K9*(1-K7)/Assumptions!$E$5 -> 0.042115452 | ... Z9: =Y9+Collateral!Z9*(1-Z7)/Assumptions!$E$5 -> 0.064561003

Sheet Waterfall
B2: Monthly Priority of Payments
B4: $mm | C4: M1 | D4: M2 | E4: M3 | F4: M4 | G4: M5 | H4: M6 | I4: M7 | J4: M8 | K4: M9 | L4: M10 | M4: M11 | N4: M12 | O4: M13 | P4: M14 | Q4: M15 | R4: M16 | S4: M17 | T4: M18 | U4: M19 | V4: M20 | W4: M21 | X4: M22 | Y4: M23 | Z4: M24
B5: Available interest | C5: =Collateral!C12+Collateral!C8 -> 7 | D5: =Collateral!D12+Collateral!D8 -> 6.6105849 | E5: =Collateral!E12+Collateral!E8 -> 6.2310321 | F5: =Collateral!F12+Collateral!F8 -> 7.0730029 | G5: =Collateral!G12+Collateral!G8 -> 6.6429839 | H5: =Collateral!H12+Collateral!H8 -> 6.2239949 | I5: =Collateral!I12+Collateral!I8 -> 5.8158058 | J5: =Collateral!J12+Collateral!J8 -> 5.4181908 | ... Z5: =Collateral!Z12+Collateral!Z8 -> 0.32595429
B6: Available principal | C6: =Collateral!C13 -> 64.333135 | D6: =Collateral!D13 -> 62.781626 | E6: =Collateral!E13 -> 61.261671 | F6: =Collateral!F13 -> 60.984549 | G6: =Collateral!G13 -> 59.456365 | H6: =Collateral!H13 -> 57.959768 | I6: =Collateral!I13 -> 56.494162 | J6: =Collateral!J13 -> 55.058961 | ... Z6: =Collateral!Z13 -> 35.79178
B7: Senior beginning balance | C7: =Assumptions!E12 -> 650 | D7: =C12 -> 585.66686 | E7: =D12 -> 522.88524 | F7: =E12 -> 461.62357 | G7: =F12 -> 400.63902 | H7: =G12 -> 341.18265 | I7: =H12 -> 283.22289 | J7: =I12 -> 226.72872 | K7: =J12 -> 171.66976 | ... Z7: =Y12 -> 0
B8: Senior interest due | C8: =C7*Assumptions!$E$13/Assumptions!$E$20+0 -> 2.7083333 | D8: =D7*Assumptions!$E$13/Assumptions!$E$20+C10 -> 2.4402786 | E8: =E7*Assumptions!$E$13/Assumptions!$E$20+D10 -> 2.1786885 | F8: =F7*Assumptions!$E$13/Assumptions!$E$20+E10 -> 1.9234315 | G8: =G7*Assumptions!$E$13/Assumptions!$E$20+F10 -> 1.6693292 | H8: =H7*Assumptions!$E$13/Assumptions!$E$20+G10 -> 1.4215944 | I8: =I7*Assumptions!$E$13/Assumptions!$E$20+H10 -> 1.1800954 | J8: =J7*Assumptions!$E$13/Assumptions!$E$20+I10 -> 0.94470301 | K8: =K7*Assumptions!$E$13/Assumptions!$E$20+J10 -> 0.71529068 | ... Z8: =Z7*Assumptions!$E$13/Assumptions!$E$20+Y10 -> 0
B9: Senior interest paid | C9: =MIN(C5,C8) -> 2.7083333 | D9: =MIN(D5,D8) -> 2.4402786 | E9: =MIN(E5,E8) -> 2.1786885 | F9: =MIN(F5,F8) -> 1.9234315 | G9: =MIN(G5,G8) -> 1.6693292 | H9: =MIN(H5,H8) -> 1.4215944 | I9: =MIN(I5,I8) -> 1.1800954 | J9: =MIN(J5,J8) -> 0.94470301 | ... Z9: =MIN(Z5,Z8) -> 0
B10: Senior interest shortfall | C10: =C8-C9 -> 0 | D10: =D8-D9 -> 0 | E10: =E8-E9 -> 0 | F10: =F8-F9 -> 0 | G10: =G8-G9 -> 0 | H10: =H8-H9 -> 0 | I10: =I8-I9 -> 0 | J10: =J8-J9 -> 0 | ... Z10: =Z8-Z9 -> 0
B11: Senior principal paid | C11: =MIN(C7,C6) -> 64.333135 | D11: =MIN(D7,D6) -> 62.781626 | E11: =MIN(E7,E6) -> 61.261671 | F11: =MIN(F7,F6) -> 60.984549 | G11: =MIN(G7,G6) -> 59.456365 | H11: =MIN(H7,H6) -> 57.959768 | I11: =MIN(I7,I6) -> 56.494162 | J11: =MIN(J7,J6) -> 55.058961 | ... Z11: =MIN(Z7,Z6) -> 0
B12: Senior ending balance | C12: =MAX(0,C7-C11) -> 585.66686 | D12: =MAX(0,D7-D11) -> 522.88524 | E12: =MAX(0,E7-E11) -> 461.62357 | F12: =MAX(0,F7-F11) -> 400.63902 | G12: =MAX(0,G7-G11) -> 341.18265 | H12: =MAX(0,H7-H11) -> 283.22289 | I12: =MAX(0,I7-I11) -> 226.72872 | J12: =MAX(0,J7-J11) -> 171.66976 | ... Z12: =MAX(0,Z7-Z11) -> 0
B13: Mezz beginning balance | C13: =Assumptions!E14 -> 220 | D13: =C18 -> 220 | E13: =D18 -> 220 | F13: =E18 -> 220 | G13: =F18 -> 220 | H13: =G18 -> 220 | I13: =H18 -> 220 | J13: =I18 -> 220 | K13: =J18 -> 220 | ... Z13: =Y18 -> 0
B14: Mezz interest due | C14: =C13*Assumptions!$E$15/Assumptions!$E$20+0 -> 1.4666667 | D14: =D13*Assumptions!$E$15/Assumptions!$E$20+C16 -> 1.4666667 | E14: =E13*Assumptions!$E$15/Assumptions!$E$20+D16 -> 1.4666667 | F14: =F13*Assumptions!$E$15/Assumptions!$E$20+E16 -> 1.4666667 | G14: =G13*Assumptions!$E$15/Assumptions!$E$20+F16 -> 1.4666667 | H14: =H13*Assumptions!$E$15/Assumptions!$E$20+G16 -> 1.4666667 | I14: =I13*Assumptions!$E$15/Assumptions!$E$20+H16 -> 1.4666667 | J14: =J13*Assumptions!$E$15/Assumptions!$E$20+I16 -> 1.4666667 | K14: =K13*Assumptions!$E$15/Assumptions!$E$20+J16 -> 1.4666667 | ... Z14: =Z13*Assumptions!$E$15/Assumptions!$E$20+Y16 -> 0
B15: Mezz interest paid | C15: =MIN(MAX(0,C5-C9),C14) -> 1.4666667 | D15: =MIN(MAX(0,D5-D9),D14) -> 1.4666667 | E15: =MIN(MAX(0,E5-E9),E14) -> 1.4666667 | F15: =MIN(MAX(0,F5-F9),F14) -> 1.4666667 | G15: =MIN(MAX(0,G5-G9),G14) -> 1.4666667 | H15: =MIN(MAX(0,H5-H9),H14) -> 1.4666667 | I15: =MIN(MAX(0,I5-I9),I14) -> 1.4666667 | J15: =MIN(MAX(0,J5-J9),J14) -> 1.4666667 | ... Z15: =MIN(MAX(0,Z5-Z9),Z14) -> 0
B16: Mezz interest shortfall | C16: =C14-C15 -> 0 | D16: =D14-D15 -> 0 | E16: =E14-E15 -> 0 | F16: =F14-F15 -> 0 | G16: =G14-G15 -> 0 | H16: =H14-H15 -> 0 | I16: =I14-I15 -> 0 | J16: =J14-J15 -> 0 | ... Z16: =Z14-Z15 -> 0
B17: Mezz principal paid | C17: =MIN(C13,MAX(0,C6-C11)) -> 0 | D17: =MIN(D13,MAX(0,D6-D11)) -> 0 | E17: =MIN(E13,MAX(0,E6-E11)) -> 0 | F17: =MIN(F13,MAX(0,F6-F11)) -> 0 | G17: =MIN(G13,MAX(0,G6-G11)) -> 0 | H17: =MIN(H13,MAX(0,H6-H11)) -> 0 | I17: =MIN(I13,MAX(0,I6-I11)) -> 0 | J17: =MIN(J13,MAX(0,J6-J11)) -> 0 | ... Z17: =MIN(Z13,MAX(0,Z6-Z11)) -> 0
B18: Mezz ending balance | C18: =MAX(0,C13-C17) -> 220 | D18: =MAX(0,D13-D17) -> 220 | E18: =MAX(0,E13-E17) -> 220 | F18: =MAX(0,F13-F17) -> 220 | G18: =MAX(0,G13-G17) -> 220 | H18: =MAX(0,H13-H17) -> 220 | I18: =MAX(0,I13-I17) -> 220 | J18: =MAX(0,J13-J17) -> 220 | ... Z18: =MAX(0,Z13-Z17) -> 0
B19: Residual cash | C19: =MAX(0,C5-C9-C15)+MAX(0,C6-C11-C17) -> 2.825 | D19: =MAX(0,D5-D9-D15)+MAX(0,D6-D11-D17) -> 2.7036397 | E19: =MAX(0,E5-E9-E15)+MAX(0,E6-E11-E17) -> 2.585677 | F19: =MAX(0,F5-F9-F15)+MAX(0,F6-F11-F17) -> 3.6829047 | G19: =MAX(0,G5-G9-G15)+MAX(0,G6-G11-G17) -> 3.506988 | H19: =MAX(0,H5-H9-H15)+MAX(0,H6-H11-H17) -> 3.3357338 | I19: =MAX(0,I5-I9-I15)+MAX(0,I6-I11-I17) -> 3.1690437 | J19: =MAX(0,J5-J9-J15)+MAX(0,J6-J11-J17) -> 3.0068211 | ... Z19: =MAX(0,Z5-Z9-Z15)+MAX(0,Z6-Z11-Z17) -> 36.117735

Sheet Triggers
B2: OC / IC Triggers and Cash Diversion
B4: Metric | C4: M1 | D4: M2 | E4: M3 | F4: M4 | G4: M5 | H4: M6 | I4: M7 | J4: M8 | K4: M9 | L4: M10 | M4: M11 | N4: M12 | O4: M13 | P4: M14 | Q4: M15 | R4: M16 | S4: M17 | T4: M18 | U4: M19 | V4: M20 | W4: M21 | X4: M22 | Y4: M23 | Z4: M24
B5: OC ratio | C5: =IFERROR(Collateral!C14/(Waterfall!C12+Waterfall!C18),0) -> 1.4065902 | D5: =IFERROR(Collateral!D14/(Waterfall!D12+Waterfall!D18),0) -> 1.4378761 | E5: =IFERROR(Collateral!E14/(Waterfall!E12+Waterfall!E18),0) -> 1.474078 | F5: =IFERROR(Collateral!F14/(Waterfall!F12+Waterfall!F18),0) -> 1.5193644 | G5: =IFERROR(Collateral!G14/(Waterfall!G12+Waterfall!G18),0) -> 1.5730613 | H5: =IFERROR(Collateral!H14/(Waterfall!H12+Waterfall!H18),0) -> 1.6376974 | I5: =IFERROR(Collateral!I14/(Waterfall!I12+Waterfall!I18),0) -> 1.716927 | J5: =IFERROR(Collateral!J14/(Waterfall!J12+Waterfall!J18),0) -> 1.8162348 | ... Z5: =IFERROR(Collateral!Z14/(Waterfall!Z12+Waterfall!Z18),0) -> 0
B6: Minimum OC ratio | C6: =Assumptions!$E$17 -> 1.08 | D6: =Assumptions!$E$17 -> 1.08 | E6: =Assumptions!$E$17 -> 1.08 | F6: =Assumptions!$E$17 -> 1.08 | G6: =Assumptions!$E$17 -> 1.08 | H6: =Assumptions!$E$17 -> 1.08 | I6: =Assumptions!$E$17 -> 1.08 | J6: =Assumptions!$E$17 -> 1.08 | ... Z6: =Assumptions!$E$17 -> 1.08
B7: Senior interest coverage | C7: =IFERROR(Collateral!C12/Waterfall!C8,0) -> 2.5846154 | D7: =IFERROR(Collateral!D12/Waterfall!D8,0) -> 2.7089468 | E7: =IFERROR(Collateral!E12/Waterfall!E8,0) -> 2.8599922 | F7: =IFERROR(Collateral!F12/Waterfall!F8,0) -> 3.0472292 | G7: =IFERROR(Collateral!G12/Waterfall!G8,0) -> 3.2951547 | H7: =IFERROR(Collateral!H12/Waterfall!H8,0) -> 3.6223547 | I7: =IFERROR(Collateral!I12/Waterfall!I8,0) -> 4.073744 | J7: =IFERROR(Collateral!J12/Waterfall!J8,0) -> 4.7360601 | ... Z7: =IFERROR(Collateral!Z12/Waterfall!Z8,0) -> 0
B8: Minimum senior IC | C8: =Assumptions!$E$18 -> 1.5 | D8: =Assumptions!$E$18 -> 1.5 | E8: =Assumptions!$E$18 -> 1.5 | F8: =Assumptions!$E$18 -> 1.5 | G8: =Assumptions!$E$18 -> 1.5 | H8: =Assumptions!$E$18 -> 1.5 | I8: =Assumptions!$E$18 -> 1.5 | J8: =Assumptions!$E$18 -> 1.5 | ... Z8: =Assumptions!$E$18 -> 1.5
B9: Mezz interest coverage | C9: =IFERROR(MAX(0,Collateral!C12-Waterfall!C8)/Waterfall!C14,0) -> 2.9261364 | D9: =IFERROR(MAX(0,Collateral!D12-Waterfall!D8)/Waterfall!D14,0) -> 2.8433907 | E9: =IFERROR(MAX(0,Collateral!E12-Waterfall!E8)/Waterfall!E14,0) -> 2.7629616 | F9: =IFERROR(MAX(0,Collateral!F12-Waterfall!F8)/Waterfall!F14,0) -> 2.6847991 | G9: =IFERROR(MAX(0,Collateral!G12-Waterfall!G8)/Waterfall!G14,0) -> 2.612297 | H9: =IFERROR(MAX(0,Collateral!H12-Waterfall!H8)/Waterfall!H14,0) -> 2.5417669 | I9: =IFERROR(MAX(0,Collateral!I12-Waterfall!I8)/Waterfall!I14,0) -> 2.4731666 | J9: =IFERROR(MAX(0,Collateral!J12-Waterfall!J8)/Waterfall!J14,0) -> 2.406455 | ... Z9: =IFERROR(MAX(0,Collateral!Z12-Waterfall!Z8)/Waterfall!Z14,0) -> 0
B10: Minimum mezz IC | C10: =Assumptions!$E$19 -> 1.15 | D10: =Assumptions!$E$19 -> 1.15 | E10: =Assumptions!$E$19 -> 1.15 | F10: =Assumptions!$E$19 -> 1.15 | G10: =Assumptions!$E$19 -> 1.15 | H10: =Assumptions!$E$19 -> 1.15 | I10: =Assumptions!$E$19 -> 1.15 | J10: =Assumptions!$E$19 -> 1.15 | ... Z10: =Assumptions!$E$19 -> 1.15
B11: Trigger status | C11: =IF(AND(C5>=C6,C7>=C8,C9>=C10),"PASS","TRIGGER") -> PASS | D11: =IF(AND(D5>=D6,D7>=D8,D9>=D10),"PASS","TRIGGER") -> PASS | E11: =IF(AND(E5>=E6,E7>=E8,E9>=E10),"PASS","TRIGGER") -> PASS | F11: =IF(AND(F5>=F6,F7>=F8,F9>=F10),"PASS","TRIGGER") -> PASS | G11: =IF(AND(G5>=G6,G7>=G8,G9>=G10),"PASS","TRIGGER") -> PASS | H11: =IF(AND(H5>=H6,H7>=H8,H9>=H10),"PASS","TRIGGER") -> PASS | I11: =IF(AND(I5>=I6,I7>=I8,I9>=I10),"PASS","TRIGGER") -> PASS | J11: =IF(AND(J5>=J6,J7>=J8,J9>=J10),"PASS","TRIGGER") -> PASS | ... Z11: =IF(AND(Z5>=Z6,Z7>=Z8,Z9>=Z10),"PASS","TRIGGER") -> TRIGGER

Sheet Tranche Analytics
B2: Tranche Yield, WAL, and Loss Analytics
B4: Metric | C4: Senior | D4: Mezz | E4: Residual | F4: Notes
B5: Opening balance | C5: =Assumptions!E12 -> 650 | D5: =Assumptions!E14 -> 220 | E5: =Assumptions!E5-Assumptions!E12-Assumptions!E14 -> 330 | F5: capital structure
B6: Ending balance | C6: =Waterfall!Z12 -> 0 | D6: =Waterfall!Z18 -> 0 | E6: =0 -> 0 | F6: modeled horizon
B7: Principal paid | C7: =SUM(Waterfall!C11:Z11) -> 650 | D7: =SUM(Waterfall!C17:Z17) -> 220 | E7: =0 -> 0 | F7: cash principal
B8: Interest paid | C8: =SUM(Waterfall!C9:Z9) -> 16.009092 | D8: =SUM(Waterfall!C15:Z15) -> 20.639378 | E8: =SUM(Waterfall!C19:Z19) -> 371.58321 | F8: cash interest / residual
B9: WAL | C9: =SUMPRODUCT(COLUMN(Waterfall!C11:Z11)-COLUMN(Waterfall!B11),Waterfall!C11:Z11)/Assumptions!E20/SUM(Waterfall!C11:Z11) -> 0.49258746 | D9: =SUMPRODUCT(COLUMN(Waterfall!C17:Z17)-COLUMN(Waterfall!B17),Waterfall!C17:Z17)/Assumptions!E20/SUM(Waterfall!C17:Z17) -> 1.1726919 | E9: =0 -> 0 | F9: years
B10: Interest shortfall | C10: =SUM(Waterfall!C10:Z10) -> 0 | D10: =SUM(Waterfall!C16:Z16) -> 0 | E10: =0 -> 0 | F10: cumulative
B11: Principal loss / unpaid balance | C11: =Waterfall!Z12 -> 0 | D11: =Waterfall!Z18 -> 0 | E11: =MAX(0,Collateral!Z14-Waterfall!Z12-Waterfall!Z18) -> 0 | F11: end-horizon exposure

Sheet Sensitivity
B2: Senior Ending Balance Sensitivity
B4: CDR / CPR | C4: 0 | D4: 0.06 | E4: 0.12 | F4: 0.18 | G4: 0.24
B5: 0 | C5: =MAX(0,Assumptions!$E$12-Assumptions!$E$5*(1-(1-$B5)^(2))*(1-Assumptions!$E$9)-Assumptions!$E$5*(1-(1-C$4)^2)) -> 650 | D5: =MAX(0,Assumptions!$E$12-Assumptions!$E$5*(1-(1-$B5)^(2))*(1-Assumptions!$E$9)-Assumptions!$E$5*(1-(1-D$4)^2)) -> 510.32 | E5: =MAX(0,Assumptions!$E$12-Assumptions!$E$5*(1-(1-$B5)^(2))*(1-Assumptions!$E$9)-Assumptions!$E$5*(1-(1-E$4)^2)) -> 379.28 | F5: =MAX(0,Assumptions!$E$12-Assumptions!$E$5*(1-(1-$B5)^(2))*(1-Assumptions!$E$9)-Assumptions!$E$5*(1-(1-F$4)^2)) -> 256.88 | G5: =MAX(0,Assumptions!$E$12-Assumptions!$E$5*(1-(1-$B5)^(2))*(1-Assumptions!$E$9)-Assumptions!$E$5*(1-(1-G$4)^2)) -> 143.12
B6: 0.03 | C6: =MAX(0,Assumptions!$E$12-Assumptions!$E$5*(1-(1-$B6)^(2))*(1-Assumptions!$E$9)-Assumptions!$E$5*(1-(1-C$4)^2)) -> 614.54 | D6: =MAX(0,Assumptions!$E$12-Assumptions!$E$5*(1-(1-$B6)^(2))*(1-Assumptions!$E$9)-Assumptions!$E$5*(1-(1-D$4)^2)) -> 474.86 | E6: =MAX(0,Assumptions!$E$12-Assumptions!$E$5*(1-(1-$B6)^(2))*(1-Assumptions!$E$9)-Assumptions!$E$5*(1-(1-E$4)^2)) -> 343.82 | F6: =MAX(0,Assumptions!$E$12-Assumptions!$E$5*(1-(1-$B6)^(2))*(1-Assumptions!$E$9)-Assumptions!$E$5*(1-(1-F$4)^2)) -> 221.42 | G6: =MAX(0,Assumptions!$E$12-Assumptions!$E$5*(1-(1-$B6)^(2))*(1-Assumptions!$E$9)-Assumptions!$E$5*(1-(1-G$4)^2)) -> 107.66
B7: 0.06 | C7: =MAX(0,Assumptions!$E$12-Assumptions!$E$5*(1-(1-$B7)^(2))*(1-Assumptions!$E$9)-Assumptions!$E$5*(1-(1-C$4)^2)) -> 580.16 | D7: =MAX(0,Assumptions!$E$12-Assumptions!$E$5*(1-(1-$B7)^(2))*(1-Assumptions!$E$9)-Assumptions!$E$5*(1-(1-D$4)^2)) -> 440.48 | E7: =MAX(0,Assumptions!$E$12-Assumptions!$E$5*(1-(1-$B7)^(2))*(1-Assumptions!$E$9)-Assumptions!$E$5*(1-(1-E$4)^2)) -> 309.44 | F7: =MAX(0,Assumptions!$E$12-Assumptions!$E$5*(1-(1-$B7)^(2))*(1-Assumptions!$E$9)-Assumptions!$E$5*(1-(1-F$4)^2)) -> 187.04 | G7: =MAX(0,Assumptions!$E$12-Assumptions!$E$5*(1-(1-$B7)^(2))*(1-Assumptions!$E$9)-Assumptions!$E$5*(1-(1-G$4)^2)) -> 73.28
B8: 0.09 | C8: =MAX(0,Assumptions!$E$12-Assumptions!$E$5*(1-(1-$B8)^(2))*(1-Assumptions!$E$9)-Assumptions!$E$5*(1-(1-C$4)^2)) -> 546.86 | D8: =MAX(0,Assumptions!$E$12-Assumptions!$E$5*(1-(1-$B8)^(2))*(1-Assumptions!$E$9)-Assumptions!$E$5*(1-(1-D$4)^2)) -> 407.18 | E8: =MAX(0,Assumptions!$E$12-Assumptions!$E$5*(1-(1-$B8)^(2))*(1-Assumptions!$E$9)-Assumptions!$E$5*(1-(1-E$4)^2)) -> 276.14 | F8: =MAX(0,Assumptions!$E$12-Assumptions!$E$5*(1-(1-$B8)^(2))*(1-Assumptions!$E$9)-Assumptions!$E$5*(1-(1-F$4)^2)) -> 153.74 | G8: =MAX(0,Assumptions!$E$12-Assumptions!$E$5*(1-(1-$B8)^(2))*(1-Assumptions!$E$9)-Assumptions!$E$5*(1-(1-G$4)^2)) -> 39.98
B9: 0.12 | C9: =MAX(0,Assumptions!$E$12-Assumptions!$E$5*(1-(1-$B9)^(2))*(1-Assumptions!$E$9)-Assumptions!$E$5*(1-(1-C$4)^2)) -> 514.64 | D9: =MAX(0,Assumptions!$E$12-Assumptions!$E$5*(1-(1-$B9)^(2))*(1-Assumptions!$E$9)-Assumptions!$E$5*(1-(1-D$4)^2)) -> 374.96 | E9: =MAX(0,Assumptions!$E$12-Assumptions!$E$5*(1-(1-$B9)^(2))*(1-Assumptions!$E$9)-Assumptions!$E$5*(1-(1-E$4)^2)) -> 243.92 | F9: =MAX(0,Assumptions!$E$12-Assumptions!$E$5*(1-(1-$B9)^(2))*(1-Assumptions!$E$9)-Assumptions!$E$5*(1-(1-F$4)^2)) -> 121.52 | G9: =MAX(0,Assumptions!$E$12-Assumptions!$E$5*(1-(1-$B9)^(2))*(1-Assumptions!$E$9)-Assumptions!$E$5*(1-(1-G$4)^2)) -> 7.76

Sheet Checks
B2: Model Checks
B4: Check | C4: Status
B5: Collateral balance nonnegative | C5: =IF(MIN(Collateral!C14:Z14)>=0,"PASS","FAIL") -> PASS
B6: Senior balance nonnegative | C6: =IF(MIN(Waterfall!C12:Z12)>=0,"PASS","FAIL") -> PASS
B7: Mezz balance nonnegative | C7: =IF(MIN(Waterfall!C18:Z18)>=0,"PASS","FAIL") -> PASS
B8: Collateral roll-forward | C8: =IF(MAX(ABS(Collateral!C5:Z5-Collateral!C6:Z6-Collateral!C7:Z7-Collateral!C9:Z9-Collateral!C14:Z14))<0.000001,"PASS","FAIL") -> PASS
B9: Interest waterfall conserved | C9: =IF(MAX(ABS(Collateral!C12:Z12+Collateral!C8:Z8-Waterfall!C9:Z9-Waterfall!C15:Z15-(Waterfall!C19:Z19-MAX(0,Waterfall!C6:Z6-Waterfall!C11:Z11-Waterfall!C17:Z17))))<0.000001,"PASS","REVIEW") -> PASS
B10: No trigger breach | C10: =IF(COUNTIF(Triggers!C11:Z11,"TRIGGER")=0,"PASS","REVIEW") -> REVIEW
B11: Recovery and loss rates bounded | C11: =IF(AND(MIN('Loss Curves'!C7:Z9)>=0,MAX('Loss Curves'!C7:Z9)<=1),"PASS","FAIL") -> PASS
B12: Overall | C12: =IF(COUNTIF(C5:C11,"FAIL")=0,"PASS","FAIL") -> PASS

Sheet Sources
B2: Source Register
B4: Input / dataset | C4: Source URL or document | D4: As-of | E4: Notes / transformation
B5: Offering memorandum / indenture | C5: [public filing / data room URL] | D5: [date] | E5: Capital structure, priority of payments, triggers
B6: Servicer report | C6: [trustee / servicer URL] | D6: [payment date] | E6: Pool balance, delinquencies, defaults, recoveries
B7: Collateral data tape | C7: [restricted source] | D7: [cut-off date] | E7: Loan-level fields and transformations
B8: Rating methodology | C8: [agency methodology URL] | D8: [date] | E8: Stress assumptions and legal criteria
B9: Market benchmarks | C9: [market data URL] | D9: [date] | E9: Spreads, CPR/CDR expectations, relative value
B10: Finance-Segway benchmark fixture securitization-reference-pool | C10: repo://standards/benchmark_cases/securitization-reference-pool.json | D10: 2026-08-03 | E10: Synthetic engineering fixture; not investment evidence

Sheet RefreshLog
B2: Refresh Log
B4: Date | C4: Trigger | D4: Source snapshot | E4: What changed | F4: Reviewer / challenge | G4: Next check
B5: 2026-08-03 | C5: Synthetic benchmark generation | D5: repo://standards/benchmark_cases/securitization-reference-pool.json | E5: Generated securitization-reference-pool from canonical release template | F5: Engineering fixture only; not public underwriting or M4 evidence | G5: On builder, formula, or contract change
