Workbook

Sheet Cover
B2: [COMPANY] — Distressed / Restructuring Model
B4: Situation type: | C4: Chapter 11 / Out-of-court / Chapter 7
B5: Petition/filing date: | C5: [date]
B6: Last refreshed: | C6: 2026-08-04
B7: Refresh cadence: | C7: Weekly (daily near key dates)

Sheet Institutional Surface
B2: Distressed & Restructuring — Institutional Decision Surface
B4: Model ID | C4: 24
B5: Domain | C5: Distressed & Restructuring
B6: Declared maturity | C6: M2
B7: Canonical builder | C7: tools/builders/build_restructuring_release.py
B8: Decision arena | C8: debtor, creditor groups, advisors, court and new-money providers
B9: Committee artifact | C9: 13-week liquidity, recovery and plan-value pack
B10: Operating cadence | C10: daily liquidity; weekly stakeholder; court-event driven
B12: Key decision outputs
B13: # | C13: Requirement | D13: Owner | E13: Evidence / location | F13: Status
B14: 1 | C14: 13-week liquidity and DIP need | F14: OPEN
B15: 2 | C15: enterprise / reorganization value | F15: OPEN
B16: 3 | C16: recovery by class | F16: OPEN
B17: 4 | C17: base, downside and break-even outputs | F17: OPEN
B18: 5 | C18: liquidity / funding requirement and binding constraint | F18: OPEN
B20: Insider questions
B21: # | C21: Requirement | D21: Owner | E21: Evidence / location | F21: Status
B22: 1 | C22: What is the first day cash goes negative? | F22: OPEN
B23: 2 | C23: Which creditor is the fulcrum under each value case? | F23: OPEN
B24: 3 | C24: What collateral and priority actually support each claim? | F24: OPEN
B25: 4 | C25: Which assumption is owner-approved versus modeler judgement? | F25: OPEN
B26: 5 | C26: What fails first and who must act? | F26: OPEN
B28: Scenario families
B29: # | C29: Requirement | D29: Owner | E29: Evidence / location | F29: Status
B30: 1 | C30: liquidity miss | F30: OPEN
B31: 2 | C31: vendor tightening | F31: OPEN
B32: 3 | C32: priming and adequate protection | F32: OPEN
B33: 4 | C33: data freshness / source failure | F33: OPEN
B34: 5 | C34: combined severe-but-plausible downside | F34: OPEN
B36: Primary diligence documents
B37: # | C37: Requirement | D37: Owner | E37: Evidence / location | F37: Status
B38: 1 | C38: 13-week cash flow and variance report | F38: OPEN
B39: 2 | C39: credit agreements and intercreditor documents | F39: OPEN
B40: 3 | C40: claims register | F40: OPEN
B41: 4 | C41: approved model card and assumption register | F41: OPEN
B42: 5 | C42: independent validation and challenge record | F42: OPEN
B44: Challenge tests
B45: # | C45: Requirement | D45: Owner | E45: Evidence / location | F45: Status
B46: 1 | C46: weekly cash roll-forward balances | F46: OPEN
B47: 2 | C47: claims map equals capital structure | F47: OPEN
...

Sheet Challenge Log
B2: Independent Challenge, Override and Closure Log
B4: Date | C4: Reviewer | D4: Challenge | E4: Owner response | F4: Evidence | G4: Impact | H4: Status | I4: Closure
D5: weekly cash roll-forward balances | H5: OPEN
D6: claims map equals capital structure | H6: OPEN
D7: recoveries conserve distributable value | H7: OPEN
D8: source-to-model lineage is reproducible | H8: OPEN
D9: units, signs, dates and legal definitions reconcile | H9: OPEN

Sheet Lineage Map
B2: Source, Transformation, Ownership and Refresh Map
B4: Source class | C4: Cadence | D4: Control | E4: System / provider | F4: As-of | G4: Owner | H4: Transform | I4: Downstream | J4: Status
B5: cash receipts/disbursements | C5: daily/weekly | D5: bank and AP/AR reconciliation | J5: TO MAP
B6: claims and debt | C6: event-driven | D6: legal status and class mapping | J6: TO MAP
B7: model governance evidence | C7: per release | D7: version, reviewer, sign-off and change log | J7: TO MAP
B8: decision-use snapshot | C8: per decision | D8: immutable as-of date and source receipt | J8: TO MAP

Sheet Recovery Waterfall
B2: Capital Structure & Recovery Waterfall
B4: Tranche | C4: Face claim ($) | D4: Seniority rank | E4: Recovery ($) | F4: Recovery % | G4: Fulcrum?
B5: DIP / super-priority | C5: 15 | D5: 1 | E5: =MIN(C12,C5) -> 15 | F5: =IFERROR(E5/C5,"-") -> 1 | G5: =IF(AND(ISNUMBER(F5),F5<1),"FULCRUM","")
B6: First lien secured | C6: 80 | D6: 2 | E6: =MIN(MAX(C12-SUM(E5:E5),0),C6) -> 80 | F6: =IFERROR(E6/C6,"-") -> 1 | G6: =IF(AND(ISNUMBER(F6),F6<1,ISNUMBER(F5),F5>=1),"FULCRUM","")
B7: Second lien secured | C7: 20 | D7: 3 | E7: =MIN(MAX(C12-SUM(E5:E6),0),C7) -> 5 | F7: =IFERROR(E7/C7,"-") -> 0.25 | G7: =IF(AND(ISNUMBER(F7),F7<1,ISNUMBER(F6),F6>=1),"FULCRUM","") -> FULCRUM
B8: Senior unsecured notes | C8: 50 | D8: 4 | E8: =MIN(MAX(C12-SUM(E5:E7),0),C8) -> 0 | F8: =IFERROR(E8/C8,"-") -> 0 | G8: =IF(AND(ISNUMBER(F8),F8<1,ISNUMBER(F7),F7>=1),"FULCRUM","")
B9: Subordinated debt | C9: 20 | D9: 5 | E9: =MIN(MAX(C12-SUM(E5:E8),0),C9) -> 0 | F9: =IFERROR(E9/C9,"-") -> 0 | G9: =IF(AND(ISNUMBER(F9),F9<1,ISNUMBER(F8),F8>=1),"FULCRUM","")
B10: Equity | C10: 0 | D10: 6 | E10: =MIN(MAX(C12-SUM(E5:E9),0),C10) -> 0 | F10: =IFERROR(E10/C10,"-") -> - | G10: =IF(AND(ISNUMBER(F10),F10<1,ISNUMBER(F9),F9>=1),"FULCRUM","")
B12: Total enterprise value available for distribution ($) | C12: 100
B14: Waterfall (senior to junior, absolute priority)
B20: Fulcrum security = the tranche where recovery % first drops below 100% — that class controls the reorg (converts to new equity)
B21: Fulcrum security | C21: =IFERROR(INDEX(B5:B10,MATCH("FULCRUM",G5:G10,0)),"-") -> Second lien secured

Sheet 13-Week Liquidity
B2: 13-Week Cash Flow, Minimum Liquidity, and Funding Need
B3: Initial unrestricted liquidity | C3: 5
B4: Minimum operating liquidity | C4: 5
B6: Week | C6: Beginning cash | D6: Receipts | E6: Operating disbursements | F6: Interest | G6: Professional fees | H6: New money | I6: Ending cash | J6: Headroom | K6: Status
B7: 1 | C7: =$C$3 -> 5 | D7: 4 | E7: 5 | F7: 0.75 | G7: 0.75 | H7: 0 | I7: =C7+D7+H7-E7-F7-G7 -> 2.5 | J7: =I7-$C$4 -> -2.5 | K7: =IF(J7>=0,"PASS","BREACH") -> BREACH
B8: 2 | C8: =I7 -> 2.5 | D8: 4 | E8: 5 | F8: 0.75 | G8: 0.75 | H8: 0 | I8: =C8+D8+H8-E8-F8-G8 -> 0 | J8: =I8-$C$4 -> -5 | K8: =IF(J8>=0,"PASS","BREACH") -> BREACH
B9: 3 | C9: =I8 -> 0 | D9: 4 | E9: 5 | F9: 0.75 | G9: 0.75 | H9: 0 | I9: =C9+D9+H9-E9-F9-G9 -> -2.5 | J9: =I9-$C$4 -> -7.5 | K9: =IF(J9>=0,"PASS","BREACH") -> BREACH
B10: 4 | C10: =I9 -> -2.5 | D10: 4 | E10: 5 | F10: 0.75 | G10: 0.75 | H10: 0 | I10: =C10+D10+H10-E10-F10-G10 -> -5 | J10: =I10-$C$4 -> -10 | K10: =IF(J10>=0,"PASS","BREACH") -> BREACH
B11: 5 | C11: =I10 -> -5 | D11: 4 | E11: 5 | F11: 0.75 | G11: 0.75 | H11: 0 | I11: =C11+D11+H11-E11-F11-G11 -> -7.5 | J11: =I11-$C$4 -> -12.5 | K11: =IF(J11>=0,"PASS","BREACH") -> BREACH
B12: 6 | C12: =I11 -> -7.5 | D12: 4 | E12: 5 | F12: 0.75 | G12: 0.75 | H12: 0 | I12: =C12+D12+H12-E12-F12-G12 -> -10 | J12: =I12-$C$4 -> -15 | K12: =IF(J12>=0,"PASS","BREACH") -> BREACH
B13: 7 | C13: =I12 -> -10 | D13: 4 | E13: 5 | F13: 0.75 | G13: 0.75 | H13: 0 | I13: =C13+D13+H13-E13-F13-G13 -> -12.5 | J13: =I13-$C$4 -> -17.5 | K13: =IF(J13>=0,"PASS","BREACH") -> BREACH
B14: 8 | C14: =I13 -> -12.5 | D14: 4 | E14: 5 | F14: 0.75 | G14: 0.75 | H14: 0 | I14: =C14+D14+H14-E14-F14-G14 -> -15 | J14: =I14-$C$4 -> -20 | K14: =IF(J14>=0,"PASS","BREACH") -> BREACH
B15: 9 | C15: =I14 -> -15 | D15: 4 | E15: 5 | F15: 0.75 | G15: 0.75 | H15: 0 | I15: =C15+D15+H15-E15-F15-G15 -> -17.5 | J15: =I15-$C$4 -> -22.5 | K15: =IF(J15>=0,"PASS","BREACH") -> BREACH
B16: 10 | C16: =I15 -> -17.5 | D16: 4 | E16: 5 | F16: 0.75 | G16: 0.75 | H16: 0 | I16: =C16+D16+H16-E16-F16-G16 -> -20 | J16: =I16-$C$4 -> -25 | K16: =IF(J16>=0,"PASS","BREACH") -> BREACH
B17: 11 | C17: =I16 -> -20 | D17: 4 | E17: 5 | F17: 0.75 | G17: 0.75 | H17: 0 | I17: =C17+D17+H17-E17-F17-G17 -> -22.5 | J17: =I17-$C$4 -> -27.5 | K17: =IF(J17>=0,"PASS","BREACH") -> BREACH
B18: 12 | C18: =I17 -> -22.5 | D18: 4 | E18: 5 | F18: 0.75 | G18: 0.75 | H18: 0 | I18: =C18+D18+H18-E18-F18-G18 -> -25 | J18: =I18-$C$4 -> -30 | K18: =IF(J18>=0,"PASS","BREACH") -> BREACH
B19: 13 | C19: =I18 -> -25 | D19: 4 | E19: 5 | F19: 0.75 | G19: 0.75 | H19: 0 | I19: =C19+D19+H19-E19-F19-G19 -> -27.5 | J19: =I19-$C$4 -> -32.5 | K19: =IF(J19>=0,"PASS","BREACH") -> BREACH
B22: Minimum ending cash | C22: =MIN(I7:I19) -> -27.5
B23: Peak funding need | C23: =MAX(0,-MIN(J7:J19)) -> 32.5
B24: First breach week | C24: =IFERROR(MATCH("BREACH",K7:K19,0),"-") -> 1
B26: A 13-week schedule is an operating control: replace the illustrative weekly flows with treasury-owned receipts, disbursements, financing availability, and variance explanations.

Sheet New Money
B2: DIP / Rescue Financing Economics and Priority
B5: New-money commitment | C5: 5 | D5: committed financing
B6: Expected draw | C6: ='13-Week Liquidity'!C23 -> 32.5 | D6: peak funding need
B7: Upfront fee | C7: 0.05 | D7: % of drawn amount
B8: Annual cash interest rate | C8: 0.18 | D8: contractual cash coupon
B9: Tenor | C9: 1 | D9: years
B10: Exit fee | C10: 0.1 | D10: % of drawn amount
B11: Super-priority / administrative claim | C11: 1 | D11: 1.0x if fully senior to prepetition claims
B14: Undrawn commitment | C14: =MAX(0,C5-C6) -> 0
B15: Upfront fee amount | C15: =C6*C7 -> 1.625
B16: Cash interest | C16: =C6*C8*C9 -> 5.85
B17: Exit fee amount | C17: =C6*C10 -> 3.25
B18: Total new-money claim at exit | C18: =C6+C15+C16+C17 -> 43.225
B19: Commitment sufficiency | C19: =IF(C5>=C6,"PASS","BREACH") -> BREACH
B21: Priority, roll-up, milestones, collateral, avoidance risk, and adequate-protection terms require legal review and cannot be inferred from economic seniority alone.

Sheet Liquidation vs Reorg
B2: Liquidation (Ch. 7) vs. Reorganization (Ch. 11) NPV
C4: Liquidation | D4: Reorg | E4: Notes
B5: Gross asset value / going-concern EV | C5: 140 | D5: 110
B6: Less: liquidation discount / distress costs | C6: 20
B7: Less: administrative/professional fees | C7: 10 | D7: 10
B8: Time to distribution (months) | C8: 6 | D8: 24
B9: Discount rate (annual, for NPV of delayed recovery) | C9: 0.2
B11: Net proceeds | C11: =C5-C6-C7 -> 110 | D11: =D5-D7 -> 100
B12: NPV of proceeds (discounted for time to distribution) | C12: =C11/(1+$C$9)^(C8/12) -> 100.4158 | D12: =D11/(1+$C$9)^(D8/12) -> 69.444444 | E12: Compare NPVs — higher wins for creditors as a class, though individual tranche outcomes differ

Sheet Decision & Checks
B2: Distressed / Restructuring Decision Dashboard and Independent Checks
B4: Check / decision | C4: Metric | D4: Status | E4: Interpretation / action
B5: Waterfall conservation residual | C5: ='Recovery Waterfall'!C12-SUM('Recovery Waterfall'!E5:E10) -> 0 | D5: =IF(ABS(C5)<0.01,"PASS","FAIL") -> PASS | E5: Distributed value must equal enterprise value available under the modeled waterfall.
B6: Priority ordering | C6: =MIN(IF(AND(ISNUMBER('Recovery Waterfall'!F5),ISNUMBER('Recovery Waterfall'!F6)),'Recovery Waterfall'!F5-'Recovery Waterfall'!F6,0),IF(AND(ISNUMBER('Recovery Waterfall'!F6),ISNUMBER('Recovery Waterfall'!F7)),'Recovery Waterfall'!F6-'Recovery Waterfall'!F7,0),IF(AND(ISNUMBER('Recovery Waterfall'!F7),ISNUMBER('Recovery Waterfall'!F8)),'Recovery Waterfall'!F7-'Recovery Waterfall'!F8,0),IF(AND(ISNUMBER('Recovery Waterfall'!F8),ISNUMBER('Recovery Waterfall'!F9)),'Recovery Waterfall'!F8-'Recovery Waterfall'!F9,0)) -> 0 | D6: =IF(C6>=-0.000001,"PASS","FAIL") -> PASS | E6: Junior recoveries may not exceed an impaired senior class under the absolute-priority model.
B7: Fulcrum security | C7: ='Recovery Waterfall'!C21 -> Second lien secured | D7: =IF(C7="-","REVIEW","PASS") -> PASS | E7: The impaired class immediately below fully paid senior claims is the modeled fulcrum.
B8: Minimum 13-week liquidity | C8: ='13-Week Liquidity'!C22 -> -27.5 | D8: =IF(C8>='13-Week Liquidity'!C4,"PASS","BREACH") -> BREACH | E8: Escalate a minimum-liquidity breach before the modeled cash-out date.
B9: Peak funding need | C9: ='13-Week Liquidity'!C23 -> 32.5 | D9: =IF(C9<='New Money'!C5,"PASS","BREACH") -> BREACH | E9: New-money commitment must cover peak need plus execution contingency.
B10: Reorganization NPV uplift | C10: ='Liquidation vs Reorg'!D12-'Liquidation vs Reorg'!C12 -> -30.971358 | D10: =IF(C10>=0,"PASS","REVIEW") -> REVIEW | E10: Reorganization should not be preferred without a supportable value advantage and feasible plan.
B11: New-money commitment status | C11: ='New Money'!C19 -> BREACH | D11: =IF(C11="PASS","PASS","BREACH") -> BREACH | E11: Insufficient rescue financing requires a revised operating plan, asset sale, or liquidation path.
B12: Equity recovery | C12: ='Recovery Waterfall'!E10 -> 0 | D12: =IF(C12>0,"REVIEW","PASS") -> PASS | E12: Equity value while a creditor class is impaired requires explicit exception analysis.
B14: Overall model status | C14: =IF(COUNTIF(D5:D12,"FAIL")+COUNTIF(D5:D12,"BREACH")>0,"BREACH",IF(COUNTIF(D5:D12,"REVIEW")>0,"REVIEW","PASS")) -> BREACH
B16: Primary decision outputs
B17: Enterprise value available | C17: ='Recovery Waterfall'!C12 -> 100
B18: Fulcrum security | C18: ='Recovery Waterfall'!C21 -> Second lien secured
B19: Liquidation NPV | C19: ='Liquidation vs Reorg'!C12 -> 100.4158
B20: Reorganization NPV | C20: ='Liquidation vs Reorg'!D12 -> 69.444444
B21: Peak funding need | C21: ='13-Week Liquidity'!C23 -> 32.5
B22: Total new-money claim | C22: ='New Money'!C18 -> 43.225
B23: First liquidity breach week | C23: ='13-Week Liquidity'!C24 -> 1

Sheet RefreshLog
B2: Refresh Log
B4: Date | C4: Trigger | D4: What changed | E4: Reviewer notes | F4: Next check
B5: 2026-08-04 | C5: M1-to-M2 domain hardening benchmark | D5: Generated adversarial benchmark distressed-adversarial-cramdown from the canonical hardened release template | E5: Synthetic engineering fixture only; does not count toward M4 or live approval | F5: On builder, reference-check, formula, or contract change
