Workbook

Sheet Cover
B2: [ISSUER] — Public Finance Credit Model
B4: Issuer: | C4: [Sovereign / state / municipality / authority]
B5: Instrument: | C5: GO / revenue bond / sovereign note
B6: Last refreshed: | C6: 2026-08-04
B7: Next payment / issuance: | C7: [date]
B8: Refresh cadence: | C8: Weekly
B9: Active scenario: | C9: Base
B10: Units: | C10: $ in millions unless noted
B13: Modeling conventions
B14: Blue text / yellow fill | C14: Hardcoded input or selected scenario
B15: Black text | C15: Formula / same-sheet calculation
B16: Green text | C16: Cross-sheet formula / link
B17: Checks | C17: PASS / REVIEW / FAIL must remain visible

Sheet Institutional Surface
B2: Public Finance — Institutional Decision Surface
B4: Model ID | C4: 07
B5: Domain | C5: Public Finance
B6: Declared maturity | C6: M2
B7: Canonical builder | C7: tools/builders/build_public_finance_release.py
B8: Decision arena | C8: debt management office, budget office, governing body, investors and rating agencies
B9: Committee artifact | C9: debt-affordability and authorization package
B10: Operating cadence | C10: monthly budget; quarterly debt; annual DSA
B12: Key decision outputs
B13: # | C13: Requirement | D13: Owner | E13: Evidence / location | F13: Status
B14: 1 | C14: debt-to-revenue / GDP path | F14: OPEN
B15: 2 | C15: primary balance and debt-stabilizing balance | F15: OPEN
B16: 3 | C16: debt service coverage and reserves | F16: OPEN
B17: 4 | C17: base, downside and break-even outputs | F17: OPEN
B18: 5 | C18: liquidity / funding requirement and binding constraint | F18: OPEN
B20: Insider questions
B21: # | C21: Requirement | D21: Owner | E21: Evidence / location | F21: Status
B22: 1 | C22: What revenues are legally pledged? | F22: OPEN
B23: 2 | C23: Which reserves are actually spendable? | F23: OPEN
B24: 3 | C24: What is the refinancing share over the next three years? | F24: OPEN
B25: 4 | C25: Which assumption is owner-approved versus modeler judgement? | F25: OPEN
B26: 5 | C26: What fails first and who must act? | F26: OPEN
B28: Scenario families
B29: # | C29: Requirement | D29: Owner | E29: Evidence / location | F29: Status
B30: 1 | C30: growth and revenue shock | F30: OPEN
B31: 2 | C31: rate / FX shock | F31: OPEN
B32: 3 | C32: primary-balance slippage | F32: OPEN
B33: 4 | C33: data freshness / source failure | F33: OPEN
B34: 5 | C34: combined severe-but-plausible downside | F34: OPEN
B36: Primary diligence documents
B37: # | C37: Requirement | D37: Owner | E37: Evidence / location | F37: Status
B38: 1 | C38: official budget and CAFR/ACFR | F38: OPEN
B39: 2 | C39: debt policy and authorization | F39: OPEN
B40: 3 | C40: official statement | F40: OPEN
B41: 4 | C41: approved model card and assumption register | F41: OPEN
B42: 5 | C42: independent validation and challenge record | F42: OPEN
B44: Challenge tests
B45: # | C45: Requirement | D45: Owner | E45: Evidence / location | F45: Status
B46: 1 | C46: debt dynamics identity | F46: OPEN
B47: 2 | C47: coverage definition matches pledge | F47: OPEN
...

Sheet Challenge Log
B2: Independent Challenge, Override and Closure Log
B4: Date | C4: Reviewer | D4: Challenge | E4: Owner response | F4: Evidence | G4: Impact | H4: Status | I4: Closure
D5: debt dynamics identity | H5: OPEN
D6: coverage definition matches pledge | H6: OPEN
D7: reserves exclude restricted funds | H7: OPEN
D8: source-to-model lineage is reproducible | H8: OPEN
D9: units, signs, dates and legal definitions reconcile | H9: OPEN

Sheet Lineage Map
B2: Source, Transformation, Ownership and Refresh Map
B4: Source class | C4: Cadence | D4: Control | E4: System / provider | F4: As-of | G4: Owner | H4: Transform | I4: Downstream | J4: Status
B5: budget actuals | C5: monthly/annual | D5: fund and government-wide mapping | J5: TO MAP
B6: debt service | C6: monthly/annual | D6: CUSIP and legal-security tie | J6: TO MAP
B7: model governance evidence | C7: per release | D7: version, reviewer, sign-off and change log | J7: TO MAP
B8: decision-use snapshot | C8: per decision | D8: immutable as-of date and source receipt | J8: TO MAP

Sheet Assumptions
B2: Public Finance Assumptions
B4: Assumption | C4: Base | D4: Downside | E4: Active | F4: Units / note
B5: Population / service base | C5: 1000000 | D5: 950000 | E5: =IF(Cover!$C$9="Downside",D5,C5) -> 1000000
B6: Recurring revenue | C6: 1200 | D6: 1080 | E6: =IF(Cover!$C$9="Downside",D6,C6) -> 1200
B7: Recurring expenditure | C7: 1050 | D7: 1090 | E7: =IF(Cover!$C$9="Downside",D7,C7) -> 1050
B8: Capital expenditure | C8: 180 | D8: 220 | E8: =IF(Cover!$C$9="Downside",D8,C8) -> 180
B9: Cash & unrestricted reserves | C9: 300 | D9: 220 | E9: =IF(Cover!$C$9="Downside",D9,C9) -> 300
B10: Gross debt | C10: 2500 | D10: 2500 | E10: =IF(Cover!$C$9="Downside",D10,C10) -> 2500
B11: Annual scheduled principal | C11: 125 | D11: 125 | E11: =IF(Cover!$C$9="Downside",D11,C11) -> 125
B12: Pledged revenue | C12: 420 | D12: 360 | E12: =IF(Cover!$C$9="Downside",D12,C12) -> 420
B13: Intergovernmental transfers | C13: 150 | D13: 120 | E13: =IF(Cover!$C$9="Downside",D13,C13) -> 150
B14: Revenue growth | C14: 0.03 | D14: -0.02 | E14: =IF(Cover!$C$9="Downside",D14,C14) -> 0.03
B15: Expenditure growth | C15: 0.035 | D15: 0.05 | E15: =IF(Cover!$C$9="Downside",D15,C15) -> 0.035
B16: Effective interest rate (r) | C16: 0.045 | D16: 0.06 | E16: =IF(Cover!$C$9="Downside",D16,C16) -> 0.045
... B23: Debt-service reserve fund | C23: 50 | D23: 40 | E23: =IF(Cover!$C$9="Downside",D23,C23) -> 50

Sheet Debt Sustainability
B2: Debt Sustainability Analysis
B4: Metric | C4: Active | D4: Downside | E4: Units | F4: Interpretation
B5: Debt ratio | C5: =IFERROR(Assumptions!E10/Assumptions!E6,0) -> 2.0833333 | D5: =IFERROR(Assumptions!D10/Assumptions!D6,0) -> 2.3148148 | E5: 0.0x;[Red](0.0x);- | F5: Debt / recurring revenue or GDP proxy
B6: Effective rate (r) | C6: =Assumptions!E16 -> 0.045 | D6: =Assumptions!D16 -> 0.06 | E6: 0.0%;[Red](0.0%);- | F6: Weighted effective debt cost
B7: Nominal growth (g) | C7: =Assumptions!E21 -> 0.03 | D7: =Assumptions!D21 -> 0 | E7: 0.0%;[Red](0.0%);- | F7: Nominal revenue-base growth
B8: r - g | C8: =C6-C7 -> 0.015 | D8: =D6-D7 -> 0.06 | E8: 0.0%;[Red](0.0%);- | F8: Positive differential raises stabilization burden
B9: Current primary balance | C9: =Assumptions!E22 -> 0.01 | D9: =Assumptions!D22 -> -0.03 | E9: 0.0%;[Red](0.0%);- | F9: Surplus positive
B10: Debt-stabilizing primary balance | C10: =IFERROR((C6-C7)/(1+C7)*C5,0) -> 0.030339806 | D10: =IFERROR((D6-D7)/(1+D7)*D5,0) -> 0.13888889 | E10: 0.0%;[Red](0.0%);- | F10: Required balance to stabilize debt ratio
B11: Primary-balance gap | C11: =C9-C10 -> -0.020339806 | D11: =D9-D10 -> -0.16888889 | E11: 0.0%;[Red](0.0%);- | F11: Positive is stronger than stabilizing
B12: One-year projected debt ratio | C12: =IFERROR((1+C6)/(1+C7)*C5-C9,0) -> 2.1036731 | D12: =IFERROR((1+D6)/(1+D7)*D5-D9,0) -> 2.4837037 | E12: 0.0x;[Red](0.0x);- | F12: Standard debt-dynamics identity
B13: Trajectory | C13: =IF(C12<=C5,"STABILIZING / FALLING","RISING") -> RISING | D13: =IF(D12<=D5,"STABILIZING / FALLING","RISING") -> RISING | E13: status | F13: Screen excludes stock-flow adjustments

Sheet Revenue & Expenditure
B2: Operating Forecast
B4: $mm | C4: Current | D4: Year 1 | E4: Year 2 | F4: Year 3 | G4: Year 4 | H4: Year 5
B5: Recurring revenue | C5: =Assumptions!E6 -> 1200 | D5: =C5*(1+Assumptions!$E$14) -> 1236 | E5: =D5*(1+Assumptions!$E$14) -> 1273.08 | F5: =E5*(1+Assumptions!$E$14) -> 1311.2724 | G5: =F5*(1+Assumptions!$E$14) -> 1350.6106 | H5: =G5*(1+Assumptions!$E$14) -> 1391.1289
B6: Revenue growth | D6: =IFERROR(D5/C5-1,0) -> 0.03 | E6: =IFERROR(E5/D5-1,0) -> 0.03 | F6: =IFERROR(F5/E5-1,0) -> 0.03 | G6: =IFERROR(G5/F5-1,0) -> 0.03 | H6: =IFERROR(H5/G5-1,0) -> 0.03
B7: Recurring expenditure | C7: =Assumptions!E7 -> 1050 | D7: =C7*(1+Assumptions!$E$15) -> 1086.75 | E7: =D7*(1+Assumptions!$E$15) -> 1124.7863 | F7: =E7*(1+Assumptions!$E$15) -> 1164.1538 | G7: =F7*(1+Assumptions!$E$15) -> 1204.8992 | H7: =G7*(1+Assumptions!$E$15) -> 1247.0706
B8: Expenditure growth | D8: =IFERROR(D7/C7-1,0) -> 0.035 | E8: =IFERROR(E7/D7-1,0) -> 0.035 | F8: =IFERROR(F7/E7-1,0) -> 0.035 | G8: =IFERROR(G7/F7-1,0) -> 0.035 | H8: =IFERROR(H7/G7-1,0) -> 0.035
B9: Operating surplus | C9: =C5-C7 -> 150 | D9: =D5-D7 -> 149.25 | E9: =E5-E7 -> 148.29375 | F9: =F5-F7 -> 147.11863 | G9: =G5-G7 -> 145.71142 | H9: =H5-H7 -> 144.05827
B10: Operating margin | C10: =IFERROR(C9/C5,0) -> 0.125 | D10: =IFERROR(D9/D5,0) -> 0.12075243 | E10: =IFERROR(E9/E5,0) -> 0.11648424 | F10: =IFERROR(F9/F5,0) -> 0.11219532 | G10: =IFERROR(G9/G5,0) -> 0.10788559 | H10: =IFERROR(H9/H5,0) -> 0.10355494
B11: Pension / OPEB contribution | C11: =Assumptions!E20 -> 90 | D11: =Assumptions!$E$20 -> 90 | E11: =Assumptions!$E$20 -> 90 | F11: =Assumptions!$E$20 -> 90 | G11: =Assumptions!$E$20 -> 90 | H11: =Assumptions!$E$20 -> 90
B12: Net operating result | C12: =C9-C11 -> 60 | D12: =D9-D11 -> 59.25 | E12: =E9-E11 -> 58.29375 | F12: =F9-F11 -> 57.118631 | G12: =G9-G11 -> 55.711421 | H12: =H9-H11 -> 54.058268
B13: Capital expenditure | C13: =Assumptions!E8 -> 180 | D13: =Assumptions!$E$8 -> 180 | E13: =Assumptions!$E$8 -> 180 | F13: =Assumptions!$E$8 -> 180 | G13: =Assumptions!$E$8 -> 180 | H13: =Assumptions!$E$8 -> 180
B14: FCF before debt service | C14: =C12-C13 -> -120 | D14: =D12-D13 -> -120.75 | E14: =E12-E13 -> -121.70625 | F14: =F12-F13 -> -122.88137 | G14: =G12-G13 -> -124.28858 | H14: =H12-H13 -> -125.94173

Sheet Debt Service
B2: Debt Service, Borrowing & Reserves
B4: $mm | C4: Year 1 | D4: Year 2 | E4: Year 3 | F4: Year 4 | G4: Year 5
B5: Beginning debt | C5: =Assumptions!E10 -> 2500 | D5: =C11 -> 2733.25 | E5: =D11 -> 2977.9525 | F5: =E11 -> 3234.8417 | G5: =F11 -> 3504.6982
B6: Scheduled principal | C6: =MIN(C5,Assumptions!$E$11) -> 125 | D6: =MIN(D5,Assumptions!$E$11) -> 125 | E6: =MIN(E5,Assumptions!$E$11) -> 125 | F6: =MIN(F5,Assumptions!$E$11) -> 125 | G6: =MIN(G5,Assumptions!$E$11) -> 125
B7: Cash interest | C7: =C5*Assumptions!$E$16 -> 112.5 | D7: =D5*Assumptions!$E$16 -> 122.99625 | E7: =E5*Assumptions!$E$16 -> 134.00786 | F7: =F5*Assumptions!$E$16 -> 145.56788 | G7: =G5*Assumptions!$E$16 -> 157.71142
B8: Total debt service | C8: =C6+C7 -> 237.5 | D8: =D6+D7 -> 247.99625 | E8: =E6+E7 -> 259.00786 | F8: =F6+F7 -> 270.56788 | G8: =G6+G7 -> 282.71142
B9: FCF before debt service | C9: ='Revenue & Expenditure'!D14 -> -120.75 | D9: ='Revenue & Expenditure'!E14 -> -121.70625 | E9: ='Revenue & Expenditure'!F14 -> -122.88137 | F9: ='Revenue & Expenditure'!G14 -> -124.28858 | G9: ='Revenue & Expenditure'!H14 -> -125.94173
B10: New borrowing / funding gap | C10: =MAX(0,C8-C9) -> 358.25 | D10: =MAX(0,D8-D9) -> 369.7025 | E10: =MAX(0,E8-E9) -> 381.88923 | F10: =MAX(0,F8-F9) -> 394.85646 | G10: =MAX(0,G8-G9) -> 408.65315
B11: Ending debt | C11: =C5-C6+C10 -> 2733.25 | D11: =D5-D6+D10 -> 2977.9525 | E11: =E5-E6+E10 -> 3234.8417 | F11: =F5-F6+F10 -> 3504.6982 | G11: =G5-G6+G10 -> 3788.3513
B12: Beginning reserves | C12: =Assumptions!E9 -> 300 | D12: =C13 -> 300 | E12: =D13 -> 300 | F12: =E13 -> 300 | G12: =F13 -> 300
B13: Ending reserves | C13: =MAX(0,C12+C9-C8+C10) -> 300 | D13: =MAX(0,D12+D9-D8+D10) -> 300 | E13: =MAX(0,E12+E9-E8+E10) -> 300 | F13: =MAX(0,F12+F9-F8+F10) -> 300 | G13: =MAX(0,G12+G9-G8+G10) -> 300
B14: Pledged revenue | C14: =Assumptions!$E$12*(1+Assumptions!$E$14)^1 -> 432.6 | D14: =Assumptions!$E$12*(1+Assumptions!$E$14)^2 -> 445.578 | E14: =Assumptions!$E$12*(1+Assumptions!$E$14)^3 -> 458.94534 | F14: =Assumptions!$E$12*(1+Assumptions!$E$14)^4 -> 472.7137 | G14: =Assumptions!$E$12*(1+Assumptions!$E$14)^5 -> 486.89511
B15: Revenue-bond DSCR | C15: =IFERROR(C14/C8,0) -> 1.8214737 | D15: =IFERROR(D14/D8,0) -> 1.7967127 | E15: =IFERROR(E14/E8,0) -> 1.7719359 | F15: =IFERROR(F14/F8,0) -> 1.7471169 | G15: =IFERROR(G14/G8,0) -> 1.7222336

Sheet Coverage
B2: Coverage, Liquidity & Debt Burden
B4: Metric | C4: Year 1 | D4: Year 2 | E4: Year 3 | F4: Year 4 | G4: Year 5
B5: Debt / recurring revenue | C5: =IFERROR('Debt Service'!C11/'Revenue & Expenditure'!D5,0) -> 2.2113673 | D5: =IFERROR('Debt Service'!D11/'Revenue & Expenditure'!E5,0) -> 2.3391715 | E5: =IFERROR('Debt Service'!E11/'Revenue & Expenditure'!F5,0) -> 2.4669487 | F5: =IFERROR('Debt Service'!F11/'Revenue & Expenditure'!G5,0) -> 2.5948991 | G5: =IFERROR('Debt Service'!G11/'Revenue & Expenditure'!H5,0) -> 2.723221
B6: Maximum debt / revenue | C6: =Assumptions!E17 -> 2.5 | D6: =Assumptions!E17 -> 2.5 | E6: =Assumptions!E17 -> 2.5 | F6: =Assumptions!E17 -> 2.5 | G6: =Assumptions!E17 -> 2.5
B7: Debt burden headroom | C7: =C6-C5 -> 0.28863269 | D7: =D6-D5 -> 0.16082846 | E7: =E6-E5 -> 0.033051309 | F7: =F6-F5 -> -0.094899122 | G7: =G6-G5 -> -0.22322095
B8: Revenue-bond DSCR | C8: ='Debt Service'!C15 -> 1.8214737 | D8: ='Debt Service'!D15 -> 1.7967127 | E8: ='Debt Service'!E15 -> 1.7719359 | F8: ='Debt Service'!F15 -> 1.7471169 | G8: ='Debt Service'!G15 -> 1.7222336
B9: Minimum DSCR | C9: =Assumptions!E18 -> 1.5 | D9: =Assumptions!E18 -> 1.5 | E9: =Assumptions!E18 -> 1.5 | F9: =Assumptions!E18 -> 1.5 | G9: =Assumptions!E18 -> 1.5
B10: DSCR headroom | C10: =C8-C9 -> 0.32147368 | D10: =D8-D9 -> 0.29671265 | E10: =E8-E9 -> 0.27193594 | F10: =F8-F9 -> 0.24711686 | G10: =G8-G9 -> 0.22223363
B11: Days cash on hand | C11: =IFERROR('Debt Service'!C13/('Revenue & Expenditure'!D7/365),0) -> 100.75914 | D11: =IFERROR('Debt Service'!D13/('Revenue & Expenditure'!E7/365),0) -> 97.35183 | E11: =IFERROR('Debt Service'!E13/('Revenue & Expenditure'!F7/365),0) -> 94.059739 | F11: =IFERROR('Debt Service'!F13/('Revenue & Expenditure'!G7/365),0) -> 90.878975 | G11: =IFERROR('Debt Service'!G13/('Revenue & Expenditure'!H7/365),0) -> 87.805773
B12: Minimum days cash | C12: =Assumptions!E19 -> 90 | D12: =Assumptions!E19 -> 90 | E12: =Assumptions!E19 -> 90 | F12: =Assumptions!E19 -> 90 | G12: =Assumptions!E19 -> 90
B13: Liquidity headroom | C13: =C11-C12 -> 10.759144 | D13: =D11-D12 -> 7.3518302 | E13: =E11-E12 -> 4.0597393 | F13: =F11-F12 -> 0.87897517 | G13: =G11-G12 -> -2.1942269
B14: Pension burden / revenue | C14: =IFERROR('Revenue & Expenditure'!D11/'Revenue & Expenditure'!D5,0) -> 0.072815534 | D14: =IFERROR('Revenue & Expenditure'!E11/'Revenue & Expenditure'!E5,0) -> 0.070694693 | E14: =IFERROR('Revenue & Expenditure'!F11/'Revenue & Expenditure'!F5,0) -> 0.068635624 | F14: =IFERROR('Revenue & Expenditure'!G11/'Revenue & Expenditure'!G5,0) -> 0.066636529 | G14: =IFERROR('Revenue & Expenditure'!H11/'Revenue & Expenditure'!H5,0) -> 0.064695659
B15: Status | C15: =IF(AND(C7>=0,C10>=0,C13>=0),"PASS","BREACH") -> PASS | D15: =IF(AND(D7>=0,D10>=0,D13>=0),"PASS","BREACH") -> PASS | E15: =IF(AND(E7>=0,E10>=0,E13>=0),"PASS","BREACH") -> PASS | F15: =IF(AND(F7>=0,F10>=0,F13>=0),"PASS","BREACH") -> BREACH | G15: =IF(AND(G7>=0,G10>=0,G13>=0),"PASS","BREACH") -> BREACH

Sheet Scenarios
B2: Scenario Summary
B4: Metric | C4: Base | D4: Downside | E4: Threshold / interpretation
B5: Operating surplus | C5: =Assumptions!C6-Assumptions!C7-Assumptions!C20 -> 60 | D5: =Assumptions!D6-Assumptions!D7-Assumptions!D20 -> -120 | E5: Decision screen
B6: Debt / revenue | C6: =IFERROR(Assumptions!C10/Assumptions!C6,0) -> 2.0833333 | D6: =IFERROR(Assumptions!D10/Assumptions!D6,0) -> 2.3148148 | E6: Decision screen
B7: Revenue-bond DSCR | C7: =IFERROR(Assumptions!C12/(Assumptions!C11+Assumptions!C10*Assumptions!C16),0) -> 1.7684211 | D7: =IFERROR(Assumptions!D12/(Assumptions!D11+Assumptions!D10*Assumptions!D16),0) -> 1.3090909 | E7: Decision screen
B8: Days cash | C8: =IFERROR(Assumptions!C9/(Assumptions!C7/365),0) -> 104.28571 | D8: =IFERROR(Assumptions!D9/(Assumptions!D7/365),0) -> 73.669725 | E8: Decision screen
B9: Debt-stabilizing primary balance | C9: =IFERROR((Assumptions!C16-Assumptions!C21)/(1+Assumptions!C21)*(Assumptions!C10/Assumptions!C6),0) -> 0.030339806 | D9: =IFERROR((Assumptions!D16-Assumptions!D21)/(1+Assumptions!D21)*(Assumptions!D10/Assumptions!D6),0) -> 0.13888889 | E9: Decision screen
B10: Overall | C10: =IF(AND(C5>0,C6<=Assumptions!C17,C7>=Assumptions!C18,C8>=Assumptions!C19),"PASS","REVIEW") -> PASS | D10: =IF(AND(D5>0,D6<=Assumptions!D17,D7>=Assumptions!D18,D8>=Assumptions!D19),"PASS","REVIEW") -> REVIEW | E10: Decision screen

Sheet Sensitivity
B2: Debt Ratio Sensitivity — One Year
B4: Primary balance / r-g | C4: -0.02 | D4: 0 | E4: 0.02 | F4: 0.04 | G4: 0.06
B5: -0.05 | C5: ='Debt Sustainability'!$C$5*(1+C$4)-$B5 -> 2.0916667 | D5: ='Debt Sustainability'!$C$5*(1+D$4)-$B5 -> 2.1333333 | E5: ='Debt Sustainability'!$C$5*(1+E$4)-$B5 -> 2.175 | F5: ='Debt Sustainability'!$C$5*(1+F$4)-$B5 -> 2.2166667 | G5: ='Debt Sustainability'!$C$5*(1+G$4)-$B5 -> 2.2583333
B6: -0.025 | C6: ='Debt Sustainability'!$C$5*(1+C$4)-$B6 -> 2.0666667 | D6: ='Debt Sustainability'!$C$5*(1+D$4)-$B6 -> 2.1083333 | E6: ='Debt Sustainability'!$C$5*(1+E$4)-$B6 -> 2.15 | F6: ='Debt Sustainability'!$C$5*(1+F$4)-$B6 -> 2.1916667 | G6: ='Debt Sustainability'!$C$5*(1+G$4)-$B6 -> 2.2333333
B7: 0 | C7: ='Debt Sustainability'!$C$5*(1+C$4)-$B7 -> 2.0416667 | D7: ='Debt Sustainability'!$C$5*(1+D$4)-$B7 -> 2.0833333 | E7: ='Debt Sustainability'!$C$5*(1+E$4)-$B7 -> 2.125 | F7: ='Debt Sustainability'!$C$5*(1+F$4)-$B7 -> 2.1666667 | G7: ='Debt Sustainability'!$C$5*(1+G$4)-$B7 -> 2.2083333
B8: 0.025 | C8: ='Debt Sustainability'!$C$5*(1+C$4)-$B8 -> 2.0166667 | D8: ='Debt Sustainability'!$C$5*(1+D$4)-$B8 -> 2.0583333 | E8: ='Debt Sustainability'!$C$5*(1+E$4)-$B8 -> 2.1 | F8: ='Debt Sustainability'!$C$5*(1+F$4)-$B8 -> 2.1416667 | G8: ='Debt Sustainability'!$C$5*(1+G$4)-$B8 -> 2.1833333
B9: 0.05 | C9: ='Debt Sustainability'!$C$5*(1+C$4)-$B9 -> 1.9916667 | D9: ='Debt Sustainability'!$C$5*(1+D$4)-$B9 -> 2.0333333 | E9: ='Debt Sustainability'!$C$5*(1+E$4)-$B9 -> 2.075 | F9: ='Debt Sustainability'!$C$5*(1+F$4)-$B9 -> 2.1166667 | G9: ='Debt Sustainability'!$C$5*(1+G$4)-$B9 -> 2.1583333

Sheet Checks
B2: Model Checks
B4: Check | C4: Status
B5: Debt nonnegative | C5: =IF(MIN('Debt Service'!C11:G11)>=0,"PASS","FAIL") -> PASS
B6: Reserves nonnegative | C6: =IF(MIN('Debt Service'!C13:G13)>=0,"PASS","FAIL") -> PASS
B7: Coverage finite | C7: =IF(AND(MAX(Coverage!C5:G14)<1000,MIN(Coverage!C5:G14)>-1000),"PASS","FAIL") -> PASS
B8: No coverage breach | C8: =IF(COUNTIF(Coverage!C15:G15,"BREACH")=0,"PASS","REVIEW") -> REVIEW
B9: Debt dynamics bounded | C9: =IF(AND('Debt Sustainability'!C12>=0,'Debt Sustainability'!C12<10),"PASS","REVIEW") -> PASS
B10: Overall | C10: =IF(COUNTIF(C5:C9,"FAIL")+COUNTIF(C5:C9,"REVIEW")=0,"PASS","REVIEW") -> REVIEW

Sheet Sources
B2: Source Register
B4: Input / dataset | C4: Source URL or document | D4: As-of | E4: Notes / transformation
B5: Official statements / disclosures | C5: EMMA, finance ministry, issuer or audited report | D5: [period] | E5: Revenue, expenditure, debt and reserves
B6: Accounting standards | C6: GASB, IPSAS, or applicable national standards | D6: [date] | E6: Map reporting consistently
B7: Economic and demographic data | C7: Official statistics, FRED, or multilateral dataset | D7: [period] | E7: Freeze series and release vintage
B8: Benchmark rates | C8: Treasury or sovereign curve | D8: [date] | E8: Refinancing and relative-value assumptions
B9: Debt sustainability method | C9: IMF / World Bank public methodology | D9: [date] | E9: Document debt-dynamics and stress choices
B10: Finance-Segway six-engine fixture public-reference-stable | C10: repo://standards/frontier/legacy_engine_registry.json | D10: 2026-08-04 | E10: Synthetic engineering fixture derived from the independent legacy-engine oracle registry; not investment evidence and not M4 evidence

Sheet RefreshLog
B2: Refresh Log
B4: Date | C4: Trigger | D4: Source snapshot | E4: What changed | F4: Reviewer / challenge | G4: Next check
B5: 2026-08-04 | C5: Six-engine frontier release | D5: repo://standards/frontier/legacy_engine_registry.json | E5: Applied conventional fixture public-reference-stable | F5: Synthetic engineering benchmark; not M4 evidence | G5: On builder, source, contract, or threshold change

Sheet Revenue Stress
B2: Debt Dynamics, Revenue Coverage, Reserves, and Fiscal Stress
B4: Metric | C4: Base | D4: Adversarial | E4: Units / control
B5: Opening debt ratio | C5: 0.6 | D5: 0.6
B6: Nominal interest rate | C6: 0.05 | D6: 0.05
B7: Nominal growth rate | C7: 0.04 | D7: 0.04
B8: Primary balance ratio | C8: 0.015 | D8: 0.015
B9: Pledged revenue | C9: 120 | D9: 120
B10: Debt service | C10: 80 | D10: 80
B11: Unrestricted reserves | C11: 20 | D11: 20
B12: Operating expenditure | C12: 100 | D12: 100
B13: Maximum debt ratio | C13: 1 | D13: 1
B14: Minimum DSCR | C14: 1.2 | D14: 1.2
B15: Minimum reserve coverage | C15: 0.1 | D15: 0.1
B19: Projected debt ratio | C19: =((1+C6)/(1+C7))*C5-C8 -> 0.59076923 | D19: =((1+D6)/(1+D7))*D5-D8 -> 0.59076923
B20: Debt-stabilizing primary balance | C20: =((C6-C7)/(1+C7))*C5 -> 0.0057692308 | D20: =((D6-D7)/(1+D7))*D5 -> 0.0057692308
B21: Primary-balance gap | C21: =C8-C20 -> 0.0092307692 | D21: =D8-D20 -> 0.0092307692
B22: DSCR | C22: =IFERROR(C9/C10,0) -> 1.5 | D22: =IFERROR(D9/D10,0) -> 1.5
B23: Reserve coverage | C23: =IFERROR(C11/C12,0) -> 0.2 | D23: =IFERROR(D11/D12,0) -> 0.2

Sheet Decision & Checks
B2: Public Finance Decision Dashboard and Independent Checks
B4: Check / decision | C4: Metric | D4: Status | E4: Interpretation / action
B5: Debt-ratio identity residual | C5: ='Revenue Stress'!D19-(((1+'Revenue Stress'!D6)/(1+'Revenue Stress'!D7))*'Revenue Stress'!D5-'Revenue Stress'!D8) -> 0 | D5: =IF(ABS(C5)<0.000001,"PASS","FAIL") -> PASS | E5: Projected debt must follow the debt-dynamics identity.
B6: Stabilizing-balance residual | C6: ='Revenue Stress'!D20-((('Revenue Stress'!D6-'Revenue Stress'!D7)/(1+'Revenue Stress'!D7))*'Revenue Stress'!D5) -> 0 | D6: =IF(ABS(C6)<0.000001,"PASS","FAIL") -> PASS | E6: Required primary balance must reconcile to r-g and opening debt.
B7: Projected debt ratio | C7: ='Revenue Stress'!D19 -> 0.59076923 | D7: =IF(C7<='Revenue Stress'!D13,"PASS","BREACH") -> PASS | E7: Escalate debt trajectories above the approved ceiling.
B8: Primary-balance gap | C8: ='Revenue Stress'!D21 -> 0.0092307692 | D8: =IF(C8>=0,"PASS","BREACH") -> PASS | E8: A negative gap implies a destabilizing fiscal stance.
B9: Debt-service coverage | C9: ='Revenue Stress'!D22 -> 1.5 | D9: =IF(C9>='Revenue Stress'!D14,"PASS","BREACH") -> PASS | E9: Pledged revenue must cover scheduled debt service.
B10: Reserve coverage | C10: ='Revenue Stress'!D23 -> 0.2 | D10: =IF(C10>='Revenue Stress'!D15,"PASS","BREACH") -> PASS | E10: Unrestricted reserves must cover the approved expenditure buffer.
B12: Overall model status | C12: =IF(COUNTIF(D5:D10,"FAIL")+COUNTIF(D5:D10,"BREACH")>0,"BREACH",IF(COUNTIF(D5:D10,"REVIEW")>0,"REVIEW","PASS")) -> PASS
