Workbook
Name FS_MODEL_ID: 'Institutional Surface'!$C$4
Name FS_DOMAIN: 'Institutional Surface'!$C$5
Name FS_MATURITY: 'Institutional Surface'!$C$6

Sheet Cover
B2: [FUND OF FUNDS] — Look-Through and Fee-Layering Model
B4: FoF vehicle / vintage: | C4: [Name / vintage]
B5: Reporting date: | C5: [date]
B6: Last refreshed: | C6: [date]
B7: Next LP report / valuation: | C7: [date]
B8: Refresh cadence: | C8: Quarterly, aligned to underlying-fund GP reporting
B9: Active scenario: | C9: Base
B10: Units: | C10: $ in millions unless noted
B13: Modeling conventions
B14: Blue text / yellow fill | C14: Hardcoded input or selected scenario
B15: Black text | C15: Formula / same-sheet calculation
B16: Green text | C16: Cross-sheet formula / link
B17: Checks | C17: PASS / REVIEW / FAIL must remain visible

Sheet Institutional Surface
B2: Fund of Funds — Institutional Decision Surface
B4: Model ID | C4: 29
B5: Domain | C5: Fund of Funds
B6: Declared maturity | C6: M1
B7: Canonical builder | C7: tools/builders/build_fund_of_funds_institutional.py
B8: Decision arena | C8: fund board, LP advisory committee, investment committee and portfolio management
B9: Committee artifact | C9: quarterly LP reporting and portfolio review pack
B10: Operating cadence | C10: quarterly LP reporting; semi-annual portfolio review; annual valuation
B12: Key decision outputs
B13: # | C13: Requirement | D13: Owner | E13: Evidence / location | F13: Status
B14: 1 | C14: net asset value and TVPI/DPI/RVPI bridge | F14: OPEN
B15: 2 | C15: look-through fee drag between FoF and underlying-fund layers | F15: OPEN
B16: 3 | C16: vintage-year and manager concentration | F16: OPEN
B17: 4 | C17: base, downside and break-even outputs | F17: OPEN
B18: 5 | C18: liquidity / funding requirement and binding constraint | F18: OPEN
B20: Insider questions
B21: # | C21: Requirement | D21: Owner | E21: Evidence / location | F21: Status
B22: 1 | C22: What is the FoF net TVPI to its LPs versus the underlying funds gross TVPI? | F22: OPEN
B23: 2 | C23: How much NAV sits in the single largest underlying-fund position? | F23: OPEN
B24: 3 | C24: What uncalled capital remains and when is it likely to be drawn? | F24: OPEN
B25: 4 | C25: Which assumption is owner-approved versus modeler judgement? | F25: OPEN
B26: 5 | C26: What fails first and who must act? | F26: OPEN
B28: Scenario families
B29: # | C29: Requirement | D29: Owner | E29: Evidence / location | F29: Status
B30: 1 | C30: underlying-fund NAV markdown | F30: OPEN
B31: 2 | C31: capital call acceleration | F31: OPEN
B32: 3 | C32: distribution slowdown and extended hold periods | F32: OPEN
B33: 4 | C33: data freshness / source failure | F33: OPEN
B34: 5 | C34: combined severe-but-plausible downside | F34: OPEN
B36: Primary diligence documents
B37: # | C37: Requirement | D37: Owner | E37: Evidence / location | F37: Status
B38: 1 | C38: limited partnership agreement and fee letter | F38: OPEN
B39: 2 | C39: underlying fund capital account statements | F39: OPEN
B40: 3 | C40: underlying fund quarterly and annual reports | F40: OPEN
B41: 4 | C41: approved model card and assumption register | F41: OPEN
B42: 5 | C42: independent validation and challenge record | F42: OPEN
B44: Challenge tests
B45: # | C45: Requirement | D45: Owner | E45: Evidence / location | F45: Status
B46: 1 | C46: NAV roll-forward reconciles to capital called, distributed and fees | F46: OPEN
B47: 2 | C47: TVPI equals DPI plus RVPI at both FoF and look-through level | F47: OPEN
...

Sheet Challenge Log
B2: Independent Challenge, Override and Closure Log
B4: Date | C4: Reviewer | D4: Challenge | E4: Owner response | F4: Evidence | G4: Impact | H4: Status | I4: Closure
D5: NAV roll-forward reconciles to capital called, distributed and fees | H5: OPEN
D6: TVPI equals DPI plus RVPI at both FoF and look-through level | H6: OPEN
D7: no single underlying fund exceeds the concentration limit | H7: OPEN
D8: source-to-model lineage is reproducible | H8: OPEN
D9: units, signs, dates and legal definitions reconcile | H9: OPEN

Sheet Lineage Map
B2: Source, Transformation, Ownership and Refresh Map
B4: Source class | C4: Cadence | D4: Control | E4: System / provider | F4: As-of | G4: Owner | H4: Transform | I4: Downstream | J4: Status
B5: underlying fund capital account statements | C5: quarterly | D5: general partner-reported NAV and cash flow reconciliation | J5: TO MAP
B6: FoF administrator NAV package | C6: quarterly | D6: independent administrator verification | J6: TO MAP
B7: model governance evidence | C7: per release | D7: version, reviewer, sign-off and change log | J7: TO MAP
B8: decision-use snapshot | C8: per decision | D8: immutable as-of date and source receipt | J8: TO MAP

Sheet Assumptions
B2: Fund-of-Funds Terms and Portfolio Assumptions
B4: Assumption | C4: Base | D4: Downside | E4: Active | F4: Units / note
B5: Total LP commitments to FoF | C5: 500 | D5: 500 | E5: =IF(Cover!$C$9="Downside",D5,C5) | F5: $mm
B6: FoF management fee (% of commitments, p.a.) | C6: 0.0075 | D6: 0.0075 | E6: =IF(Cover!$C$9="Downside",D6,C6) | F6: %
B7: FoF carried interest (% of profit above hurdle) | C7: 0.05 | D7: 0.05 | E7: =IF(Cover!$C$9="Downside",D7,C7) | F7: %
B8: FoF preferred return / hurdle | C8: 0.08 | D8: 0.08 | E8: =IF(Cover!$C$9="Downside",D8,C8) | F8: %
B9: Number of underlying funds | C9: 8 | D9: 8 | E9: =IF(Cover!$C$9="Downside",D9,C9) | F9: count
B10: Underlying-fund NAV markdown (stress) | C10: 0 | D10: 0.25 | E10: =IF(Cover!$C$9="Downside",D10,C10) | F10: %
B11: Maximum single-fund concentration limit | C11: 0.2 | D11: 0.2 | E11: =IF(Cover!$C$9="Downside",D11,C11) | F11: % of NAV

Sheet Underlying Fund Portfolio
B2: Underlying Fund Portfolio (Look-Through)
B4: Underlying fund / GP | C4: Vintage year | D4: Strategy | E4: Commitment | F4: Called | G4: Distributed | H4: Reported NAV (Base) | I4: Active NAV | J4: Gross TVPI (look-through)
B5: [Fund A] | C5: 2016 | D5: Buyout | E5: 60 | F5: 58 | G5: 71 | H5: 42 | I5: =H5*(1-Assumptions!$E$10) | J5: =IFERROR((G5+I5)/F5,0)
B6: [Fund B] | C6: 2017 | D6: Buyout | E6: 55 | F6: 52 | G6: 48 | H6: 55 | I6: =H6*(1-Assumptions!$E$10) | J6: =IFERROR((G6+I6)/F6,0)
B7: [Fund C] | C7: 2018 | D7: Growth equity | E7: 65 | F7: 58 | G7: 30 | H7: 78 | I7: =H7*(1-Assumptions!$E$10) | J7: =IFERROR((G7+I7)/F7,0)
B8: [Fund D] | C8: 2019 | D8: Venture | E8: 45 | F8: 38 | G8: 12 | H8: 58 | I8: =H8*(1-Assumptions!$E$10) | J8: =IFERROR((G8+I8)/F8,0)
B9: [Fund E] | C9: 2019 | D9: Buyout | E9: 70 | F9: 63 | G9: 25 | H9: 82 | I9: =H9*(1-Assumptions!$E$10) | J9: =IFERROR((G9+I9)/F9,0)
B10: [Fund F] | C10: 2020 | D10: Secondaries | E10: 50 | F10: 44 | G10: 18 | H10: 56 | I10: =H10*(1-Assumptions!$E$10) | J10: =IFERROR((G10+I10)/F10,0)
B11: [Fund G] | C11: 2021 | D11: Growth equity | E11: 60 | F11: 41 | G11: 4 | H11: 51 | I11: =H11*(1-Assumptions!$E$10) | J11: =IFERROR((G11+I11)/F11,0)
B12: [Fund H] | C12: 2022 | D12: Buyout | E12: 65 | F12: 32 | G12: 0.5 | H12: 36 | I12: =H12*(1-Assumptions!$E$10) | J12: =IFERROR((G12+I12)/F12,0)
B13: Total / look-through weighted | E13: =SUM(E5:E12) | F13: =SUM(F5:F12) | G13: =SUM(G5:G12) | H13: =SUM(H5:H12) | I13: =SUM(I5:I12) | J13: =IFERROR((G13+I13)/F13,0)
B15: Largest single-fund Active NAV | C15: =MAX(I5:I12)
B16: Largest single-fund concentration | C16: =IFERROR(C15/I13,0)

Sheet NAV Rollforward & Fee Layering
B2: FoF-Level NAV Roll-Forward and Fee Layering
B4: Line item | C4: Value
B5: Beginning-of-period FoF NAV | C5: 380
B6: + Capital called from LPs this period | C6: 45
B7: - Distributions to LPs this period | C7: 38
B8: - FoF management fee this period | C8: =Assumptions!$C$5*Assumptions!$C$6
B9: - FoF carried interest this period | C9: =MAX(0,C7-C5*Assumptions!$C$8)*Assumptions!$C$7
B10: +/- Net realized/unrealized gain (underlying funds) | C10: 28.13
B11: Computed ending-of-period FoF NAV | C11: =C5+C6-C7-C8-C9+C10
B12: Reported ending-of-period FoF NAV | C12: 411
B13: Reconciliation residual (computed vs. reported ending NAV) | C13: =C11-C12
B15: Total LP capital called to date | C15: 400
B16: Total LP distributions to date | C16: 165

Sheet Performance & Multiples
B2: FoF Net Multiples, Look-Through Gross Multiples, and Fee Drag
B4: Metric | C4: Value
B5: FoF net DPI (distributions / paid-in, to LP) | C5: =IFERROR('NAV Rollforward & Fee Layering'!C16/'NAV Rollforward & Fee Layering'!C15,0)
B6: FoF net RVPI (residual value / paid-in, to LP) | C6: =IFERROR('NAV Rollforward & Fee Layering'!C12/'NAV Rollforward & Fee Layering'!C15,0)
B7: FoF net TVPI (to LP) | C7: =C5+C6
B8: Look-through gross TVPI (weighted, underlying funds) | C8: ='Underlying Fund Portfolio'!J13
B9: Fee-layering drag (gross TVPI - FoF net TVPI) | C9: =C8-C7
B10: Fee-layering drag, $ of paid-in capital | C10: =C9*'NAV Rollforward & Fee Layering'!C15

Sheet Checks
B2: Fund-of-Funds Model Checks
B4: Check | C4: Status
B5: NAV roll-forward reconciles | C5: =IF(ABS('NAV Rollforward & Fee Layering'!C13)<0.01,"PASS","FAIL")
B6: TVPI equals DPI plus RVPI | C6: =IF(ABS('Performance & Multiples'!C7-('Performance & Multiples'!C5+'Performance & Multiples'!C6))<0.0001,"PASS","FAIL")
B7: Fee-layering drag is nonnegative | C7: =IF('Performance & Multiples'!C9>=-0.0001,"PASS","FAIL")
B8: Single-fund concentration within limit | C8: =IF('Underlying Fund Portfolio'!C16<=Assumptions!$E$11,"PASS","BREACH")
B9: Portfolio called capital does not exceed commitments | C9: =IF('Underlying Fund Portfolio'!F13<='Underlying Fund Portfolio'!E13,"PASS","FAIL")
B10: FoF-level called capital does not exceed total commitments | C10: =IF('NAV Rollforward & Fee Layering'!C15<=Assumptions!$C$5,"PASS","FAIL")
B11: Overall | C11: =IF(COUNTIF(C5:C10,"FAIL")+COUNTIF(C5:C10,"BREACH")>0,"BREACH",IF(COUNTIF(C5:C10,"REVIEW")>0,"REVIEW","PASS"))

Sheet Sources
B2: Source Register
B4: Input / dataset | C4: Source URL or document | D4: As-of | E4: Notes / transformation
B5: Underlying fund capital account statements | C5: [GP quarterly/annual capital account statement] | D5: [period end] | E5: Commitment, called, distributed, reported NAV per underlying fund
B6: FoF administrator NAV package | C6: [fund administrator report] | D6: [period end] | E6: FoF-level beginning/ending NAV, capital called and distributed to LPs
B7: Fee letter / limited partnership agreement | C7: [LPA / side letter] | D7: [effective date] | E7: FoF management fee rate, carried interest rate, hurdle

Sheet RefreshLog
B2: Refresh Log
B4: Date | C4: Trigger | D4: Source snapshot | E4: What changed | F4: Reviewer / challenge | G4: Next check
