Workbook
Name FS_MODEL_ID: 'Institutional Surface'!$C$4
Name FS_DOMAIN: 'Institutional Surface'!$C$5
Name FS_MATURITY: 'Institutional Surface'!$C$6

Sheet Cover
B2: [COMMODITY] — Commodities Model
B4: Commodity: | C4: [e.g. WTI Crude, Corn, Copper]
B5: Exchange: | C5: [NYMEX / CME / ICE]
B6: Last refreshed: | C6: [date]
B7: Next roll date: | C7: [date]
B8: Refresh cadence: | C8: Weekly (daily near roll/expiry)

Sheet Institutional Surface
B2: Commodities — Institutional Decision Surface
B4: Model ID | C4: 15
B5: Domain | C5: Commodities
B6: Declared maturity | C6: M2
B7: Canonical builder | C7: tools/builders/build_commodities_release.py
B8: Decision arena | C8: physical trading, scheduling, storage, credit and market risk
B9: Committee artifact | C9: physical-plus-paper position and optionality pack
B10: Operating cadence | C10: intraday risk; daily scheduling; weekly S&OP
B12: Key decision outputs
B13: # | C13: Requirement | D13: Owner | E13: Evidence / location | F13: Status
B14: 1 | C14: flat price, basis and location exposure | F14: OPEN
B15: 2 | C15: inventory and storage economics | F15: OPEN
B16: 3 | C16: transport and quality differentials | F16: OPEN
B17: 4 | C17: base, downside and break-even outputs | F17: OPEN
B18: 5 | C18: liquidity / funding requirement and binding constraint | F18: OPEN
B20: Insider questions
B21: # | C21: Requirement | D21: Owner | E21: Evidence / location | F21: Status
B22: 1 | C22: Where is title and can the product move? | F22: OPEN
B23: 2 | C23: Which basis is unhedgeable? | F23: OPEN
B24: 3 | C24: What is the value of storage optionality? | F24: OPEN
B25: 4 | C25: Which assumption is owner-approved versus modeler judgement? | F25: OPEN
B26: 5 | C26: What fails first and who must act? | F26: OPEN
B28: Scenario families
B29: # | C29: Requirement | D29: Owner | E29: Evidence / location | F29: Status
B30: 1 | C30: flat-price shock | F30: OPEN
B31: 2 | C31: basis blowout | F31: OPEN
B32: 3 | C32: curve shape / roll | F32: OPEN
B33: 4 | C33: data freshness / source failure | F33: OPEN
B34: 5 | C34: combined severe-but-plausible downside | F34: OPEN
B36: Primary diligence documents
B37: # | C37: Requirement | D37: Owner | E37: Evidence / location | F37: Status
B38: 1 | C38: purchase / sale contracts | F38: OPEN
B39: 2 | C39: storage and transport agreements | F39: OPEN
B40: 3 | C40: quality certificates | F40: OPEN
B41: 4 | C41: approved model card and assumption register | F41: OPEN
B42: 5 | C42: independent validation and challenge record | F42: OPEN
B44: Challenge tests
B45: # | C45: Requirement | D45: Owner | E45: Evidence / location | F45: Status
B46: 1 | C46: physical and paper positions reconcile by unit | F46: OPEN
B47: 2 | C47: storage carry identity | F47: OPEN
...

Sheet Challenge Log
B2: Independent Challenge, Override and Closure Log
B4: Date | C4: Reviewer | D4: Challenge | E4: Owner response | F4: Evidence | G4: Impact | H4: Status | I4: Closure
D5: physical and paper positions reconcile by unit | H5: OPEN
D6: storage carry identity | H6: OPEN
D7: hedge ratio uses matched grade/location/tenor | H7: OPEN
D8: source-to-model lineage is reproducible | H8: OPEN
D9: units, signs, dates and legal definitions reconcile | H9: OPEN

Sheet Lineage Map
B2: Source, Transformation, Ownership and Refresh Map
B4: Source class | C4: Cadence | D4: Control | E4: System / provider | F4: As-of | G4: Owner | H4: Transform | I4: Downstream | J4: Status
B5: physical inventory | C5: daily | D5: title, location and quality reconciliation | J5: TO MAP
B6: futures / swaps | C6: intraday/daily | D6: trade and clearing reconciliation | J6: TO MAP
B7: model governance evidence | C7: per release | D7: version, reviewer, sign-off and change log | J7: TO MAP
B8: decision-use snapshot | C8: per decision | D8: immutable as-of date and source receipt | J8: TO MAP

Sheet Futures Curve
B2: Futures Curve — Contango / Backwardation
B4: Contract month | C4: Price | D4: Days to expiry | E4: Annualized basis % | F4: vs. front month | G4: Curve shape
B5: M1 (front) | C5: 0 | D5: 0 | E5: =IFERROR((C5/$C$5-1)*(365/(D5-$D$5)),"-") | F5: =IFERROR(C5/$C$5-1,"-") | G5: =IF(C5>$C$5,"Contango",IF(C5<$C$5,"Backwardation","Flat"))
B6: M2 | C6: 0 | D6: 0 | E6: =IFERROR((C6/$C$5-1)*(365/(D6-$D$5)),"-") | F6: =IFERROR(C6/$C$5-1,"-") | G6: =IF(C6>$C$5,"Contango",IF(C6<$C$5,"Backwardation","Flat"))
B7: M3 | C7: 0 | D7: 0 | E7: =IFERROR((C7/$C$5-1)*(365/(D7-$D$5)),"-") | F7: =IFERROR(C7/$C$5-1,"-") | G7: =IF(C7>$C$5,"Contango",IF(C7<$C$5,"Backwardation","Flat"))
B8: M6 | C8: 0 | D8: 0 | E8: =IFERROR((C8/$C$5-1)*(365/(D8-$D$5)),"-") | F8: =IFERROR(C8/$C$5-1,"-") | G8: =IF(C8>$C$5,"Contango",IF(C8<$C$5,"Backwardation","Flat"))
B9: M12 | C9: 0 | D9: 0 | E9: =IFERROR((C9/$C$5-1)*(365/(D9-$D$5)),"-") | F9: =IFERROR(C9/$C$5-1,"-") | G9: =IF(C9>$C$5,"Contango",IF(C9<$C$5,"Backwardation","Flat"))

Sheet Roll Yield
B2: Roll Yield
B4: Expiring contract price | C4: ='Futures Curve'!C5
B5: Next contract price | C5: ='Futures Curve'!C6
B6: Roll yield (%) | C6: =IFERROR(C4/C5-1,"-") | D6: Positive = backwardation roll gain (long-only benefits). Negative = contango roll cost.
B8: Annual roll cost/gain estimate (12 rolls, illustrative) | C8: =IFERROR(C6*12,"-")

Sheet Hedging
B2: Producer / Consumer Hedge Model
B4: Inputs
B5: Physical exposure (units) | C5: 0
B6: Futures contract size (units) | C6: 1000
B7: Spot price | C7: 0
B8: Futures price (hedge contract) | C8: 0
B9: Hedge ratio (beta-adjusted) | C9: 1
B11: Outputs
B12: Contracts needed | C12: =IFERROR(ROUND(C5*C9/C6,0),"-")
B13: Notional hedged | C13: =C12*C6*C8
B14: Unhedged basis exposure | C14: =C5*C7-C13

Sheet Physical Balance & Carry
B2: Physical Balance, Cost of Carry, and Basis
B4: Metric | C4: Base | D4: Downside | E4: Active | F4: Units / source
B5: Spot price | C5: ='Hedging'!C7 | D5: ='Hedging'!C7*0.70 | E5: =IF(Cover!$C$9="Downside",D5,C5) | F5: linked to hedge spot
B6: Observed futures price | C6: ='Hedging'!C8 | D6: ='Hedging'!C8*1.10 | E6: =IF(Cover!$C$9="Downside",D6,C6) | F6: linked to hedge contract
B7: Risk-free rate | C7: 0.04 | D7: 0.07 | E7: =IF(Cover!$C$9="Downside",D7,C7) | F7: annual continuously compounded
B8: Storage and financing rate | C8: 0.02 | D8: 0.2 | E8: =IF(Cover!$C$9="Downside",D8,C8) | F8: annual cost of carry
B9: Convenience yield | C9: 0.03 | D9: 0 | E9: =IF(Cover!$C$9="Downside",D9,C9) | F9: annual non-cash benefit
B10: Time to delivery | C10: 0.5 | D10: 0.25 | E10: =IF(Cover!$C$9="Downside",D10,C10) | F10: years
B11: Beginning inventory | C11: 100 | D11: 20 | E11: =IF(Cover!$C$9="Downside",D11,C11) | F11: physical units
B12: Production | C12: 50 | D12: 0 | E12: =IF(Cover!$C$9="Downside",D12,C12) | F12: physical units
B13: Purchases | C13: 20 | D13: 10 | E13: =IF(Cover!$C$9="Downside",D13,C13) | F13: physical units
B14: Sales | C14: 80 | D14: 25 | E14: =IF(Cover!$C$9="Downside",D14,C14) | F14: physical units
B15: Internal consumption / shrink | C15: 30 | D15: 5 | E15: =IF(Cover!$C$9="Downside",D15,C15) | F15: physical units
B16: Reported ending inventory | C16: 60 | D16: 0 | E16: =IF(Cover!$C$9="Downside",D16,C16) | F16: physical units
B17: Basis warning threshold | C17: 10 | D17: 5 | E17: =IF(Cover!$C$9="Downside",D17,C17) | F17: absolute spot-futures difference
B18: Maximum hedge ratio | C18: 1.25 | D18: 1.1 | E18: =IF(Cover!$C$9="Downside",D18,C18) | F18: absolute futures units / physical units
B21: Derived outputs
B22: Net carry rate | E22: =E7+E8-E9
B23: Cost-of-carry fair forward | E23: =E5*EXP(E22*E10)
B24: Observed less fair forward | E24: =E6-E23
B25: Spot-futures basis | E25: =E5-E6
B26: Front-to-next roll yield | E26: ='Roll Yield'!C6
B27: Calculated ending inventory | E27: =E11+E12+E13-E14-E15
B28: Physical balance residual | E28: =E27-E16
B29: Absolute hedge ratio | E29: =IFERROR(ABS('Hedging'!C12*'Hedging'!C6/'Hedging'!C5),0)
B30: Unhedged basis exposure | E30: ='Hedging'!C14
B32: The cost-of-carry result is a reference relationship, not a claim that convenience yield or storage is directly observable.

Sheet Decision & Checks
B2: Commodities Decision Dashboard and Independent Checks
B4: Check / decision | C4: Metric | D4: Status | E4: Interpretation / action
B5: Cost-of-carry residual | C5: ='Physical Balance & Carry'!E24 | D5: =IF(ABS(C5)<=MAX(0.01,ABS('Physical Balance & Carry'!E23)*0.05),"PASS","REVIEW") | E5: Review storage, funding, convenience yield, delivery option, and contract alignment.
B6: Physical balance residual | C6: ='Physical Balance & Carry'!E28 | D6: =IF(ABS(C6)<0.000001,"PASS","FAIL") | E6: Inventory must conserve across beginning stock, flows, shrink, and reported ending stock.
B7: Absolute basis | C7: =ABS('Physical Balance & Carry'!E25) | D7: =IF(C7<='Physical Balance & Carry'!E17,"PASS","BREACH") | E7: Escalate material location, grade, quality, or timing basis risk.
B8: Hedge ratio | C8: ='Physical Balance & Carry'!E29 | D8: =IF(C8<='Physical Balance & Carry'!E18,"PASS","BREACH") | E8: Review over-hedging, contract multiplier, and beta-adjustment assumptions.
B9: Roll yield | C9: ='Physical Balance & Carry'!E26 | D9: =IF(ISNUMBER(C9),IF(C9<0,"REVIEW","PASS"),"REVIEW") | E9: Negative roll yield is expected in contango but must be included in return and hedge economics.
B10: Ending inventory | C10: ='Physical Balance & Carry'!E27 | D10: =IF(C10>=0,"PASS","BREACH") | E10: Negative physical inventory indicates an impossible operating plan or missing purchase.
B12: Overall model status | C12: =IF(COUNTIF(D5:D10,"FAIL")+COUNTIF(D5:D10,"BREACH")>0,"BREACH",IF(COUNTIF(D5:D10,"REVIEW")>0,"REVIEW","PASS"))
B14: Primary decision outputs
B15: Fair forward | C15: ='Physical Balance & Carry'!E23
B16: Observed futures | C16: ='Physical Balance & Carry'!E6
B17: Basis | C17: ='Physical Balance & Carry'!E25
B18: Contracts needed | C18: ='Hedging'!C12
B19: Unhedged exposure | C19: ='Hedging'!C14

Sheet Sensitivity
B2: Sensitivity — P&L by Spot Move
B4: Spot move % | C4: -0.2 | D4: -0.1 | E4: 0 | F4: 0.1 | G4: 0.2
B5: Unhedged P&L | C5: ='Hedging'!$C$5*'Hedging'!$C$7*C4 | D5: ='Hedging'!$C$5*'Hedging'!$C$7*D4 | E5: ='Hedging'!$C$5*'Hedging'!$C$7*E4 | F5: ='Hedging'!$C$5*'Hedging'!$C$7*F4 | G5: ='Hedging'!$C$5*'Hedging'!$C$7*G4
B6: Hedged P&L | C6: =(C4*'Hedging'!$C$5*'Hedging'!$C$7)-(C4*'Hedging'!$C$13) | D6: =(D4*'Hedging'!$C$5*'Hedging'!$C$7)-(D4*'Hedging'!$C$13) | E6: =(E4*'Hedging'!$C$5*'Hedging'!$C$7)-(E4*'Hedging'!$C$13) | F6: =(F4*'Hedging'!$C$5*'Hedging'!$C$7)-(F4*'Hedging'!$C$13) | G6: =(G4*'Hedging'!$C$5*'Hedging'!$C$7)-(G4*'Hedging'!$C$13)

Sheet RefreshLog
B2: Refresh Log
B4: Date | C4: Trigger | D4: What changed | E4: Reviewer notes | F4: Next check
