Workbook
Name FS_MODEL_ID: 'Institutional Surface'!$C$4
Name FS_DOMAIN: 'Institutional Surface'!$C$5
Name FS_MATURITY: 'Institutional Surface'!$C$6

Sheet Cover
B2: [TICKER] — Company Name
B4: Sector: | C4: [fill in]
B5: Coverage started: | C5: [date]
B6: Last refreshed: | C6: [date]
B7: Next earnings date: | C7: [date]
B8: Refresh cadence: | C8: Weekly
B10: Thesis (2-3 sentences):
B11: [fill in]
B16: COLOR LEGEND
B17: Blue text | C17: Hardcoded input / scenario lever — edit freely
B18: Black text | C18: Formula — do not overwrite
B19: Green text | C19: Link to another sheet in this workbook
B20: Yellow fill | C20: Key assumption — review every refresh

Sheet Institutional Surface
B2: Corporate Finance — Institutional Decision Surface
B4: Model ID | C4: 02
B5: Domain | C5: Corporate Finance
B6: Declared maturity | C6: M2
B7: Canonical builder | C7: tools/builders/build_corporate_finance_release.py
B8: Decision arena | C8: treasury, CFO staff, ALCO and board finance committee
B9: Committee artifact | C9: liquidity and capital-allocation pack
B10: Operating cadence | C10: weekly treasury; monthly ALCO; quarterly board
B12: Key decision outputs
B13: # | C13: Requirement | D13: Owner | E13: Evidence / location | F13: Status
B14: 1 | C14: cash runway and minimum liquidity | F14: OPEN
B15: 2 | C15: debt maturity wall and refinancing need | F15: OPEN
B16: 3 | C16: WACC and hurdle rates | F16: OPEN
B17: 4 | C17: base, downside and break-even outputs | F17: OPEN
B18: 5 | C18: liquidity / funding requirement and binding constraint | F18: OPEN
B20: Insider questions
B21: # | C21: Requirement | D21: Owner | E21: Evidence / location | F21: Status
B22: 1 | C22: What cash is actually fungible? | F22: OPEN
B23: 2 | C23: Which covenant becomes binding before headline leverage? | F23: OPEN
B24: 3 | C24: How much capacity survives a closed market? | F24: OPEN
B25: 4 | C25: Which assumption is owner-approved versus modeler judgement? | F25: OPEN
B26: 5 | C26: What fails first and who must act? | F26: OPEN
B28: Scenario families
B29: # | C29: Requirement | D29: Owner | E29: Evidence / location | F29: Status
B30: 1 | C30: rate shocks and basis | F30: OPEN
B31: 2 | C31: revenue/margin downturn | F31: OPEN
B32: 3 | C32: working-capital draw | F32: OPEN
B33: 4 | C33: data freshness / source failure | F33: OPEN
B34: 5 | C34: combined severe-but-plausible downside | F34: OPEN
B36: Primary diligence documents
B37: # | C37: Requirement | D37: Owner | E37: Evidence / location | F37: Status
B38: 1 | C38: treasury policy | F38: OPEN
B39: 2 | C39: credit agreements and indentures | F39: OPEN
B40: 3 | C40: rating-agency reports | F40: OPEN
B41: 4 | C41: approved model card and assumption register | F41: OPEN
B42: 5 | C42: independent validation and challenge record | F42: OPEN
B44: Challenge tests
B45: # | C45: Requirement | D45: Owner | E45: Evidence / location | F45: Status
B46: 1 | C46: cash roll-forward balances | F46: OPEN
B47: 2 | C47: maturity ladder equals debt ledger | F47: OPEN
...

Sheet Challenge Log
B2: Independent Challenge, Override and Closure Log
B4: Date | C4: Reviewer | D4: Challenge | E4: Owner response | F4: Evidence | G4: Impact | H4: Status | I4: Closure
D5: cash roll-forward balances | H5: OPEN
D6: maturity ladder equals debt ledger | H6: OPEN
D7: interest expense ties to debt schedule | H7: OPEN
D8: source-to-model lineage is reproducible | H8: OPEN
D9: units, signs, dates and legal definitions reconcile | H9: OPEN

Sheet Lineage Map
B2: Source, Transformation, Ownership and Refresh Map
B4: Source class | C4: Cadence | D4: Control | E4: System / provider | F4: As-of | G4: Owner | H4: Transform | I4: Downstream | J4: Status
B5: cash and debt positions | C5: daily/weekly | D5: bank and trustee reconciliation | J5: TO MAP
B6: forecast | C6: monthly | D6: actual-to-forecast bridge | J6: TO MAP
B7: model governance evidence | C7: per release | D7: version, reviewer, sign-off and change log | J7: TO MAP
B8: decision-use snapshot | C8: per decision | D8: immutable as-of date and source receipt | J8: TO MAP

Sheet Assumptions
B2: Assumptions
B4: Driver | C4: FY1 | D4: FY2 | E4: FY3 | F4: FY4 | G4: FY5 | H4: Source / notes
B5: Revenue growth % | C5: 0 | D5: 0 | E5: 0 | F5: 0 | G5: 0 | H5: Source: [10-K/10-Q cite or user estimate]
B6: Gross margin % | C6: 0 | D6: 0 | E6: 0 | F6: 0 | G6: 0 | H6: Source: [10-K/10-Q cite or user estimate]
B7: Opex % of revenue | C7: 0 | D7: 0 | E7: 0 | F7: 0 | G7: 0 | H7: Source: [10-K/10-Q cite or user estimate]
B8: Tax rate % | C8: 0 | D8: 0 | E8: 0 | F8: 0 | G8: 0 | H8: Source: [10-K/10-Q cite or user estimate]
B9: D&A % of capex | C9: 0 | D9: 0 | E9: 0 | F9: 0 | G9: 0 | H9: Source: [10-K/10-Q cite or user estimate]
B10: Capex % of revenue | C10: 0 | D10: 0 | E10: 0 | F10: 0 | G10: 0 | H10: Source: [10-K/10-Q cite or user estimate]
B11: NWC % of revenue chg | C11: 0 | D11: 0 | E11: 0 | F11: 0 | G11: 0 | H11: Source: [10-K/10-Q cite or user estimate]
B12: Shares outstanding (mm) | C12: 0 | D12: 0 | E12: 0 | F12: 0 | G12: 0 | H12: Source: [10-K/10-Q cite or user estimate]
B13: WACC % | C13: 0 | D13: 0 | E13: 0 | F13: 0 | G13: 0 | H13: Source: [10-K/10-Q cite or user estimate]
B14: Terminal growth % | C14: 0 | D14: 0 | E14: 0 | F14: 0 | G14: 0 | H14: Source: [10-K/10-Q cite or user estimate]

Sheet IS
B2: Income Statement ($mm)
B4: Line item | C4: FY-2A | D4: FY-1A | E4: FY0A | F4: FY1E | G4: FY2E | H4: FY3E | I4: FY4E
B5: Revenue | F5: =E5*(1+Assumptions!C5) | G5: =F5*(1+Assumptions!D5) | H5: =G5*(1+Assumptions!E5) | I5: =H5*(1+Assumptions!F5)
B6: Revenue growth % | D6: =IFERROR(D5/C5-1,"-") | E6: =IFERROR(E5/D5-1,"-") | F6: =IFERROR(F5/E5-1,"-") | G6: =IFERROR(G5/F5-1,"-") | H6: =IFERROR(H5/G5-1,"-") | I6: =IFERROR(I5/H5-1,"-")
B7: COGS | F7: =F5*(1-Assumptions!C6) | G7: =G5*(1-Assumptions!D6) | H7: =H5*(1-Assumptions!E6) | I7: =I5*(1-Assumptions!F6)
B8: Gross profit | D8: =D5-D7 | E8: =E5-E7 | F8: =F5-F7 | G8: =G5-G7 | H8: =H5-H7 | I8: =I5-I7
B9: Gross margin % | D9: =IFERROR(D8/D5,"-") | E9: =IFERROR(E8/E5,"-") | F9: =IFERROR(F8/F5,"-") | G9: =IFERROR(G8/G5,"-") | H9: =IFERROR(H8/H5,"-") | I9: =IFERROR(I8/I5,"-")
B10: Opex | F10: =F5*Assumptions!C7 | G10: =G5*Assumptions!D7 | H10: =H5*Assumptions!E7 | I10: =I5*Assumptions!F7
B11: EBITDA | F11: =F8-F10 | G11: =G8-G10 | H11: =H8-H10 | I11: =I8-I10
B12: EBITDA margin % | F12: =IFERROR(F11/F5,"-") | G12: =IFERROR(G11/G5,"-") | H12: =IFERROR(H11/H5,"-") | I12: =IFERROR(I11/I5,"-")
B13: D&A | F13: =F5*Assumptions!C10*Assumptions!C9 | G13: =G5*Assumptions!D10*Assumptions!D9 | H13: =H5*Assumptions!E10*Assumptions!E9 | I13: =I5*Assumptions!F10*Assumptions!F9
B14: EBIT | F14: =F11-F13 | G14: =G11-G13 | H14: =H11-H13 | I14: =I11-I13
B15: Interest expense | F15: =$E$15 | G15: =$E$15 | H15: =$E$15 | I15: =$E$15
B16: Pre-tax income | F16: =F14-F15 | G16: =G14-G15 | H16: =H14-H15 | I16: =I14-I15
B17: Tax | F17: =F16*Assumptions!C8 | G17: =G16*Assumptions!D8 | H17: =H16*Assumptions!E8 | I17: =I16*Assumptions!F8
B18: Net income | F18: =F16-F17 | G18: =G16-G17 | H18: =H16-H17 | I18: =I16-I17
B19: Diluted shares | F19: =Assumptions!C12 | G19: =Assumptions!D12 | H19: =Assumptions!E12 | I19: =Assumptions!F12
B20: Diluted EPS | F20: =IFERROR(F18/F19,"-") | G20: =IFERROR(G18/G19,"-") | H20: =IFERROR(H18/H19,"-") | I20: =IFERROR(I18/I19,"-")

Sheet BS
B2: Balance Sheet ($mm)
B4: Line item | C4: FY-1A | D4: FY0A | E4: FY1E | F4: FY2E | G4: FY3E
B5: Cash & equivalents
B6: Accounts receivable
B7: Inventory
B8: Total current assets | C8: =C5+C6+C7 | D8: =D5+D6+D7 | E8: =E5+E6+E7 | F8: =F5+F6+F7 | G8: =G5+G6+G7
B9: PP&E net
B10: Goodwill & intangibles
B11: Total assets | C11: =C8+C9+C10 | D11: =D8+D9+D10 | E11: =E8+E9+E10 | F11: =F8+F9+F10 | G11: =G8+G9+G10
B12: Accounts payable
B13: Debt (current)
B14: Total current liabilities | C14: =C12+C13 | D14: =D12+D13 | E14: =E12+E13 | F14: =F12+F13 | G14: =G12+G13
B15: Long-term debt
B16: Total liabilities | C16: =C14+C15 | D16: =D14+D15 | E16: =E14+E15 | F16: =F14+F15 | G16: =G14+G15
B17: Total equity
B19: Balance check (Total assets - Total liabilities - Total equity, should = 0) | C19: =C11-C16-C17 | D19: =D11-D16-D17 | E19: =E11-E16-E17 | F19: =F11-F16-F17 | G19: =G11-G16-G17

Sheet CF
B2: Cash Flow ($mm)
B4: Line item | C4: FY-1A | D4: FY0A | E4: FY1E | F4: FY2E | G4: FY3E
B5: Net income | E5: =IS!F18 | F5: =IS!G18 | G5: =IS!H18
B6: + D&A | E6: =IS!F13 | F6: =IS!G13 | G6: =IS!H13
B7: +/- Change in NWC
B8: Cash flow from operations | C8: =C5+C6+C7 | D8: =D5+D6+D7 | E8: =E5+E6+E7 | F8: =F5+F6+F7 | G8: =G5+G6+G7
B9: Capex
B10: Free cash flow | C10: =C8+C9 | D10: =D8+D9 | E10: =E8+E9 | F10: =F8+F9 | G10: =G8+G9
B11: Debt issuance/(repayment)
B12: Dividends/buybacks
B13: Net change in cash | C13: =C10+C11+C12 | D13: =D10+D11+D12 | E13: =E10+E11+E12 | F13: =F10+F11+F12 | G13: =G10+G11+G12

Sheet DCF
B2: DCF Valuation
C4: FY1E | D4: FY2E | E4: FY3E | F4: FY4E | G4: FY5E | H4: Key outputs
B5: Unlevered FCF | C5: =IS!F14*(1-Assumptions!C8)+IS!F13-IS!F5*Assumptions!C10 | D5: =IS!G14*(1-Assumptions!D8)+IS!G13-IS!G5*Assumptions!D10 | E5: =IS!H14*(1-Assumptions!E8)+IS!H13-IS!H5*Assumptions!E10 | F5: =IS!I14*(1-Assumptions!F8)+IS!I13-IS!I5*Assumptions!F10 | G5: =F5*(1+Assumptions!G5) | H5: WACC | I5: 0.1
B6: Discount factor | C6: =1/(1+$I$5)^(1) | D6: =1/(1+$I$5)^(2) | E6: =1/(1+$I$5)^(3) | F6: =1/(1+$I$5)^(4) | G6: =1/(1+$I$5)^(5) | H6: Terminal growth | I6: 0.025
B7: PV of FCF | C7: =C5*C6 | D7: =D5*D6 | E7: =E5*E6 | F7: =F5*F6 | G7: =G5*G6 | H7: Terminal value | I7: =G5*(1+I6)/(I5-I6)
H8: PV of terminal value | I8: =I7*G6
H9: Sum PV of FCF | I9: =SUM(C7:G7)
H10: Enterprise value | I10: =I8+I9
H11: Less: net debt | I11: 0
H12: Equity value | I12: =I10-I11
H13: Diluted shares (mm) | I13: 1
H14: Implied value/share | I14: =I12/I13

Sheet Comps
B2: Comparable Companies
B4: Ticker | C4: Price | D4: Mkt Cap | E4: EV | F4: EV/Rev | G4: EV/EBITDA | H4: P/E
B5: [TICKER] | C5: 0 | D5: 0 | E5: 0 | F5: 0 | G5: 0 | H5: 0
B6: [TICKER] | C6: 0 | D6: 0 | E6: 0 | F6: 0 | G6: 0 | H6: 0
B7: [TICKER] | C7: 0 | D7: 0 | E7: 0 | F7: 0 | G7: 0 | H7: 0
B8: [TICKER] | C8: 0 | D8: 0 | E8: 0 | F8: 0 | G8: 0 | H8: 0
B9: [TICKER] | C9: 0 | D9: 0 | E9: 0 | F9: 0 | G9: 0 | H9: 0
B10: [TICKER] | C10: 0 | D10: 0 | E10: 0 | F10: 0 | G10: 0 | H10: 0
B11: [TICKER] | C11: 0 | D11: 0 | E11: 0 | F11: 0 | G11: 0 | H11: 0
B13: Median | C13: =MEDIAN(C5:C12) | D13: =MEDIAN(D5:D12) | E13: =MEDIAN(E5:E12) | F13: =MEDIAN(F5:F12) | G13: =MEDIAN(G5:G12) | H13: =MEDIAN(H5:H12)

Sheet Sensitivity
B2: Sensitivity — Implied Value/Share
B4: WACC \ Term. growth | C4: 0.015 | D4: 0.02 | E4: 0.025 | F4: 0.03 | G4: 0.035
B5: 0.08 | C5: [data table — Excel What-If Analysis] | D5: [data table — Excel What-If Analysis] | E5: [data table — Excel What-If Analysis] | F5: [data table — Excel What-If Analysis] | G5: [data table — Excel What-If Analysis]
B6: 0.09 | C6: [data table — Excel What-If Analysis] | D6: [data table — Excel What-If Analysis] | E6: [data table — Excel What-If Analysis] | F6: [data table — Excel What-If Analysis] | G6: [data table — Excel What-If Analysis]
B7: 0.1 | C7: [data table — Excel What-If Analysis] | D7: [data table — Excel What-If Analysis] | E7: [data table — Excel What-If Analysis] | F7: [data table — Excel What-If Analysis] | G7: [data table — Excel What-If Analysis]
B8: 0.11 | C8: [data table — Excel What-If Analysis] | D8: [data table — Excel What-If Analysis] | E8: [data table — Excel What-If Analysis] | F8: [data table — Excel What-If Analysis] | G8: [data table — Excel What-If Analysis]
B9: 0.12 | C9: [data table — Excel What-If Analysis] | D9: [data table — Excel What-If Analysis] | E9: [data table — Excel What-If Analysis] | F9: [data table — Excel What-If Analysis] | G9: [data table — Excel What-If Analysis]

Sheet RefreshLog
B2: Refresh Log
B4: Date | C4: Trigger | D4: What changed | E4: Reviewer notes | F4: Next check

Sheet Treasury & Liquidity
B2: Cash, Debt, Minimum Liquidity, and Financing Capacity
B4: Metric | C4: Base | D4: Adversarial | E4: Units / control
B5: Opening cash | C5: 100 | D5: 50
B6: Operating cash flow | C6: 150 | D6: 30
B7: Capital expenditure | C7: 50 | D7: 60
B8: Dividends | C8: 20 | D8: 20
B9: Buybacks | C9: 10 | D9: 30
B10: Debt issuance | C10: 0 | D10: 80
B11: Debt repayment | C11: 30 | D11: 0
B12: Opening debt | C12: 200 | D12: 300
B13: EBITDA | C13: 120 | D13: 60
B14: Cash interest | C14: 10 | D14: 40
B15: Minimum cash | C15: 50 | D15: 80
B16: Maximum net leverage | C16: 3.5 | D16: 3.5
B17: Minimum interest coverage | C17: 2 | D17: 2
B21: Ending cash | C21: =C5+C6-C7-C8-C9+C10-C11 | D21: =D5+D6-D7-D8-D9+D10-D11
B22: Ending debt | C22: =C12+C10-C11 | D22: =D12+D10-D11
B23: Net debt | C23: =C22-C21 | D23: =D22-D21
B24: Net leverage | C24: =IFERROR(C23/C13,0) | D24: =IFERROR(D23/D13,0)
B25: Interest coverage | C25: =IFERROR(C13/C14,0) | D25: =IFERROR(D13/D14,0)
B26: Financing gap | C26: =MAX(0,C15-C21) | D26: =MAX(0,D15-D21)
B27: Post-capex free cash flow | C27: =C6-C7 | D27: =D6-D7
B28: Shareholder distributions | C28: =C8+C9 | D28: =D8+D9

Sheet Capital Allocation
B2: Capital Allocation Sources, Uses, and Distribution Funding
B4: Capital use | C4: Base | D4: Adversarial | E4: Decision rule
B5: Operating cash flow | C5: ='Treasury & Liquidity'!C6 | D5: ='Treasury & Liquidity'!D6 | E5: internal funding source
B6: Capital expenditure | C6: ='Treasury & Liquidity'!C7 | D6: ='Treasury & Liquidity'!D7 | E6: maintenance and growth investment
B7: Dividends | C7: ='Treasury & Liquidity'!C8 | D7: ='Treasury & Liquidity'!D8 | E7: fund only after minimum liquidity
B8: Buybacks | C8: ='Treasury & Liquidity'!C9 | D8: ='Treasury & Liquidity'!D9 | E8: fund only after minimum liquidity
B9: Debt repayment | C9: ='Treasury & Liquidity'!C11 | D9: ='Treasury & Liquidity'!D11 | E9: deleveraging use
B10: Debt issuance | C10: ='Treasury & Liquidity'!C10 | D10: ='Treasury & Liquidity'!D10 | E10: external funding source
B13: Distribution funding residual | C13: =MAX(0,C7+C8-C5+C6) | D13: =MAX(0,D7+D8-D5+D6)
B14: Cash rollforward residual | C14: ='Treasury & Liquidity'!C21-('Treasury & Liquidity'!C5+'Treasury & Liquidity'!C6-'Treasury & Liquidity'!C7-'Treasury & Liquidity'!C8-'Treasury & Liquidity'!C9+'Treasury & Liquidity'!C10-'Treasury & Liquidity'!C11) | D14: ='Treasury & Liquidity'!D21-('Treasury & Liquidity'!D5+'Treasury & Liquidity'!D6-'Treasury & Liquidity'!D7-'Treasury & Liquidity'!D8-'Treasury & Liquidity'!D9+'Treasury & Liquidity'!D10-'Treasury & Liquidity'!D11)

Sheet Credit Metrics
B2: Leverage, Coverage, Liquidity, and Distribution Capacity
B4: Metric | C4: Base | D4: Adversarial | E4: Threshold / interpretation
B5: Ending cash | C5: ='Treasury & Liquidity'!C21 | D5: ='Treasury & Liquidity'!D21 | E5: must exceed minimum cash
B6: Net leverage | C6: ='Treasury & Liquidity'!C24 | D6: ='Treasury & Liquidity'!D24 | E6: must remain below maximum
B7: Interest coverage | C7: ='Treasury & Liquidity'!C25 | D7: ='Treasury & Liquidity'!D25 | E7: must remain above minimum
B8: Financing gap | C8: ='Treasury & Liquidity'!C26 | D8: ='Treasury & Liquidity'!D26 | E8: must equal zero
B9: Distribution funding residual | C9: ='Capital Allocation'!C13 | D9: ='Capital Allocation'!D13 | E9: must equal zero

Sheet Decision & Checks
B2: Corporate Finance Decision Dashboard and Independent Checks
B4: Check / decision | C4: Metric | D4: Status | E4: Interpretation / action
B5: Cash rollforward residual | C5: ='Capital Allocation'!D14 | D5: =IF(ABS(C5)<0.01,"PASS","FAIL") | E5: Cash sources and uses must conserve.
B6: Debt rollforward residual | C6: ='Treasury & Liquidity'!D22-('Treasury & Liquidity'!D12+'Treasury & Liquidity'!D10-'Treasury & Liquidity'!D11) | D6: =IF(ABS(C6)<0.01,"PASS","FAIL") | E6: Ending debt must reconcile to issuance and repayment.
B7: Minimum cash | C7: ='Treasury & Liquidity'!D21-'Treasury & Liquidity'!D15 | D7: =IF(C7>=0,"PASS","BREACH") | E7: Escalate funding if ending cash falls below the minimum buffer.
B8: Net leverage | C8: ='Treasury & Liquidity'!D24 | D8: =IF(C8<='Treasury & Liquidity'!D16,"PASS","BREACH") | E8: Leverage must remain within the approved capital-structure limit.
B9: Interest coverage | C9: ='Treasury & Liquidity'!D25 | D9: =IF(C9>='Treasury & Liquidity'!D17,"PASS","BREACH") | E9: Cash interest must remain covered by operating earnings.
B10: Distribution funding | C10: ='Capital Allocation'!D13 | D10: =IF(C10<0.01,"PASS","BREACH") | E10: Dividends and buybacks cannot rely on uncovered liquidity.
B12: Overall model status | C12: =IF(COUNTIF(D5:D10,"FAIL")+COUNTIF(D5:D10,"BREACH")>0,"BREACH",IF(COUNTIF(D5:D10,"REVIEW")>0,"REVIEW","PASS"))
