Workbook
Name FS_MODEL_ID: 'Institutional Surface'!$C$4
Name FS_DOMAIN: 'Institutional Surface'!$C$5
Name FS_MATURITY: 'Institutional Surface'!$C$6

Sheet Cover
B2: [ISSUER] — Debt Finance & Refinancing
B4: Issuer: | C4: [Name]
B5: Transaction: | C5: Refinancing / acquisition / general corporate
B6: Last refreshed: | C6: [date]
B7: Next maturity / launch: | C7: [date]
B8: Refresh cadence: | C8: Weekly
B9: Active scenario: | C9: Base
B10: Units: | C10: $ in millions
B13: Modeling conventions
B14: Blue text / yellow fill | C14: Hardcoded input or selected scenario
B15: Black text | C15: Formula / same-sheet calculation
B16: Green text | C16: Cross-sheet formula / link
B17: Checks | C17: PASS / REVIEW / FAIL must remain visible

Sheet Institutional Surface
B2: Debt Finance — Institutional Decision Surface
B4: Model ID | C4: 06
B5: Domain | C5: Debt Finance
B6: Declared maturity | C6: M2
B7: Canonical builder | C7: tools/builders/build_debt_finance_release.py
B8: Decision arena | C8: issuer treasury, syndicate desk, rating agencies and board finance committee
B9: Committee artifact | C9: financing alternatives and execution memo
B10: Operating cadence | C10: daily during execution; monthly treasury
B12: Key decision outputs
B13: # | C13: Requirement | D13: Owner | E13: Evidence / location | F13: Status
B14: 1 | C14: all-in cost and break-even | F14: OPEN
B15: 2 | C15: maturity and refinancing profile | F15: OPEN
B16: 3 | C16: ratings and covenant capacity | F16: OPEN
B17: 4 | C17: base, downside and break-even outputs | F17: OPEN
B18: 5 | C18: liquidity / funding requirement and binding constraint | F18: OPEN
B20: Insider questions
B21: # | C21: Requirement | D21: Owner | E21: Evidence / location | F21: Status
B22: 1 | C22: Where is the break-even between fixed and floating? | F22: OPEN
B23: 2 | C23: What flex can arrangers exercise? | F23: OPEN
B24: 3 | C24: Which maturities cluster under the downside? | F24: OPEN
B25: 4 | C25: Which assumption is owner-approved versus modeler judgement? | F25: OPEN
B26: 5 | C26: What fails first and who must act? | F26: OPEN
B28: Scenario families
B29: # | C29: Requirement | D29: Owner | E29: Evidence / location | F29: Status
B30: 1 | C30: base-rate and spread widening | F30: OPEN
B31: 2 | C31: failed syndication / flex | F31: OPEN
B32: 3 | C32: ratings downgrade | F32: OPEN
B33: 4 | C33: data freshness / source failure | F33: OPEN
B34: 5 | C34: combined severe-but-plausible downside | F34: OPEN
B36: Primary diligence documents
B37: # | C37: Requirement | D37: Owner | E37: Evidence / location | F37: Status
B38: 1 | C38: bank proposals and commitment letters | F38: OPEN
B39: 2 | C39: indentures / credit agreements | F39: OPEN
B40: 3 | C40: rating-agency feedback | F40: OPEN
B41: 4 | C41: approved model card and assumption register | F41: OPEN
B42: 5 | C42: independent validation and challenge record | F42: OPEN
B44: Challenge tests
B45: # | C45: Requirement | D45: Owner | E45: Evidence / location | F45: Status
B46: 1 | C46: sources and uses balance | F46: OPEN
B47: 2 | C47: all-in yield includes fees and OID | F47: OPEN
...

Sheet Challenge Log
B2: Independent Challenge, Override and Closure Log
B4: Date | C4: Reviewer | D4: Challenge | E4: Owner response | F4: Evidence | G4: Impact | H4: Status | I4: Closure
D5: sources and uses balance | H5: OPEN
D6: all-in yield includes fees and OID | H6: OPEN
D7: maturity ladder equals debt ledger | H7: OPEN
D8: source-to-model lineage is reproducible | H8: OPEN
D9: units, signs, dates and legal definitions reconcile | H9: OPEN

Sheet Lineage Map
B2: Source, Transformation, Ownership and Refresh Map
B4: Source class | C4: Cadence | D4: Control | E4: System / provider | F4: As-of | G4: Owner | H4: Transform | I4: Downstream | J4: Status
B5: debt ledger | C5: daily/weekly | D5: principal and legal-entity reconciliation | J5: TO MAP
B6: curves and spreads | C6: daily | D6: timestamped executable levels | J6: TO MAP
B7: model governance evidence | C7: per release | D7: version, reviewer, sign-off and change log | J7: TO MAP
B8: decision-use snapshot | C8: per decision | D8: immutable as-of date and source receipt | J8: TO MAP

Sheet Assumptions
B2: Issuance & Capital Structure Assumptions
B4: Assumption | C4: Base | D4: Downside | E4: Active | F4: Note
B5: EBITDA | C5: 120 | D5: 95 | E5: =IF(Cover!$C$9="Downside",D5,C5)
B6: Cash | C6: 40 | D6: 25 | E6: =IF(Cover!$C$9="Downside",D6,C6)
B7: Revolver drawn | C7: 25 | D7: 75 | E7: =IF(Cover!$C$9="Downside",D7,C7)
B8: Term loan | C8: 300 | D8: 300 | E8: =IF(Cover!$C$9="Downside",D8,C8)
B9: Senior notes | C9: 250 | D9: 250 | E9: =IF(Cover!$C$9="Downside",D9,C9)
B10: Other debt | C10: 50 | D10: 50 | E10: =IF(Cover!$C$9="Downside",D10,C10)
B11: Base rate | C11: 0.045 | D11: 0.06 | E11: =IF(Cover!$C$9="Downside",D11,C11)
B12: Revolver spread | C12: 0.025 | D12: 0.04 | E12: =IF(Cover!$C$9="Downside",D12,C12)
B13: Term loan spread | C13: 0.04 | D13: 0.06 | E13: =IF(Cover!$C$9="Downside",D13,C13)
B14: Senior notes coupon | C14: 0.055 | D14: 0.07 | E14: =IF(Cover!$C$9="Downside",D14,C14)
B15: New issue spread | C15: 0.045 | D15: 0.075 | E15: =IF(Cover!$C$9="Downside",D15,C15)
B16: OID / fees | C16: 0.02 | D16: 0.03 | E16: =IF(Cover!$C$9="Downside",D16,C16)
... B21: EV haircut | C21: 0.2 | D21: 0.35 | E21: =IF(Cover!$C$9="Downside",D21,C21)

Sheet Capital Structure
B2: Current Capital Structure
B4: Instrument | C4: Balance | D4: Rate | E4: Annual interest | F4: Seniority | G4: Secured?
B5: Revolver | C5: =Assumptions!E7 | D5: =Assumptions!E12 | E5: =C5*D5 | F5: 1 | G5: Yes
B6: Term loan | C6: =Assumptions!E8 | D6: =Assumptions!E11+Assumptions!E13 | E6: =C6*D6 | F6: 2 | G6: Yes
B7: Senior notes | C7: =Assumptions!E9 | D7: =Assumptions!E14 | E7: =C7*D7 | F7: 3 | G7: No
B8: Other debt | C8: =Assumptions!E10 | D8: =Assumptions!E14 | E8: =C8*D8 | F8: 4 | G8: Varies
B10: Gross debt | C10: =SUM(C5:C8)
B11: Net debt | C11: =C10-Assumptions!E6
B12: Cash interest | C12: =SUM(E5:E8)
B13: Gross leverage | C13: =IFERROR(C10/Assumptions!E5,0)
B14: Net leverage | C14: =IFERROR(C11/Assumptions!E5,0)
B15: Interest coverage | C15: =IFERROR(Assumptions!E5/C12,0)

Sheet Maturity Ladder
B2: Contractual Maturity Ladder
B4: Instrument | C4: Year 1 | D4: Year 2 | E4: Year 3 | F4: Year 4 | G4: Year 5 | H4: Beyond
B5: Revolver | C5: 0 | D5: 0 | E5: 25 | F5: 0 | G5: 0 | H5: 0
B6: Term loan | C6: 3 | D6: 3 | E6: 3 | F6: 3 | G6: 288 | H6: 0
B7: Senior notes | C7: 0 | D7: 0 | E7: 0 | F7: 0 | G7: 0 | H7: 250
B8: Other debt | C8: 10 | D8: 10 | E8: 10 | F8: 10 | G8: 10 | H8: 0
B10: Total maturities | C10: =SUM(C5:C8) | D10: =SUM(D5:D8) | E10: =SUM(E5:E8) | F10: =SUM(F5:F8) | G10: =SUM(G5:G8) | H10: =SUM(H5:H8)
B12: Cumulative maturities / gross debt | C12: =IFERROR(SUM($C$10:C10)/'Capital Structure'!$C$10,0) | D12: =IFERROR(SUM($C$10:D10)/'Capital Structure'!$C$10,0) | E12: =IFERROR(SUM($C$10:E10)/'Capital Structure'!$C$10,0) | F12: =IFERROR(SUM($C$10:F10)/'Capital Structure'!$C$10,0) | G12: =IFERROR(SUM($C$10:G10)/'Capital Structure'!$C$10,0) | H12: =IFERROR(SUM($C$10:H10)/'Capital Structure'!$C$10,0)
B15: Near-term maturities (Years 1-2) | C15: =SUM(C10:D10)
B16: Available cash and committed lines | C16: 150
B17: Refinancing gap | C17: =MAX(0,C15-C16)
B18: Largest maturity / total | C18: =IFERROR(MAX(C10:H10)/SUM(C10:H10),0)

Sheet Refinancing
B2: Refinancing Sources & Uses
B4: Uses | C4: Amount | D4: Sources | E4: Amount | F4: Pricing / note | G4: Status
B5: Refinance current debt | C5: ='Capital Structure'!C10 | D5: New term debt | E5: =SUM(C5:C7) | F5: =Assumptions!E15+Assumptions!E16/7
B6: Minimum cash funding | C6: =MAX(0,Assumptions!E17-Assumptions!E6) | D6: Existing cash | E6: =MAX(0,Assumptions!E6-Assumptions!E17)
B7: Fees / OID | C7: =C5*Assumptions!E16 | D7: Equity / other | E7: =MAX(0,C8-E5-E6)
B8: Total uses | C8: =SUM(C5:C7) | D8: Total sources | E8: =SUM(E5:E7) | G8: =IF(ABS(C8-E8)<0.01,"PASS","FAIL")
B10: Pro forma gross leverage | C10: =IFERROR(E5/Assumptions!E5,0)
B11: Pro forma annual cash interest | C11: =E5*F5
B12: Pro forma interest coverage | C12: =IFERROR(Assumptions!E5/C11,0)

Sheet Interest Rate Risk
B2: Interest Rate & Spread Sensitivity
B4: Base-rate shock / spread shock | C4: -100 | D4: 0 | E4: 100 | F4: 200 | G4: 300
B5: -100 | C5: ='Capital Structure'!$C$5*MAX(0,Assumptions!$E$11+Assumptions!$E$12+($B5+C$4)/10000)+'Capital Structure'!$C$6*MAX(0,Assumptions!$E$11+Assumptions!$E$13+($B5+C$4)/10000)+'Capital Structure'!$E$7+'Capital Structure'!$E$8 | D5: ='Capital Structure'!$C$5*MAX(0,Assumptions!$E$11+Assumptions!$E$12+($B5+D$4)/10000)+'Capital Structure'!$C$6*MAX(0,Assumptions!$E$11+Assumptions!$E$13+($B5+D$4)/10000)+'Capital Structure'!$E$7+'Capital Structure'!$E$8 | E5: ='Capital Structure'!$C$5*MAX(0,Assumptions!$E$11+Assumptions!$E$12+($B5+E$4)/10000)+'Capital Structure'!$C$6*MAX(0,Assumptions!$E$11+Assumptions!$E$13+($B5+E$4)/10000)+'Capital Structure'!$E$7+'Capital Structure'!$E$8 | F5: ='Capital Structure'!$C$5*MAX(0,Assumptions!$E$11+Assumptions!$E$12+($B5+F$4)/10000)+'Capital Structure'!$C$6*MAX(0,Assumptions!$E$11+Assumptions!$E$13+($B5+F$4)/10000)+'Capital Structure'!$E$7+'Capital Structure'!$E$8 | G5: ='Capital Structure'!$C$5*MAX(0,Assumptions!$E$11+Assumptions!$E$12+($B5+G$4)/10000)+'Capital Structure'!$C$6*MAX(0,Assumptions!$E$11+Assumptions!$E$13+($B5+G$4)/10000)+'Capital Structure'!$E$7+'Capital Structure'!$E$8
B6: 0 | C6: ='Capital Structure'!$C$5*MAX(0,Assumptions!$E$11+Assumptions!$E$12+($B6+C$4)/10000)+'Capital Structure'!$C$6*MAX(0,Assumptions!$E$11+Assumptions!$E$13+($B6+C$4)/10000)+'Capital Structure'!$E$7+'Capital Structure'!$E$8 | D6: ='Capital Structure'!$C$5*MAX(0,Assumptions!$E$11+Assumptions!$E$12+($B6+D$4)/10000)+'Capital Structure'!$C$6*MAX(0,Assumptions!$E$11+Assumptions!$E$13+($B6+D$4)/10000)+'Capital Structure'!$E$7+'Capital Structure'!$E$8 | E6: ='Capital Structure'!$C$5*MAX(0,Assumptions!$E$11+Assumptions!$E$12+($B6+E$4)/10000)+'Capital Structure'!$C$6*MAX(0,Assumptions!$E$11+Assumptions!$E$13+($B6+E$4)/10000)+'Capital Structure'!$E$7+'Capital Structure'!$E$8 | F6: ='Capital Structure'!$C$5*MAX(0,Assumptions!$E$11+Assumptions!$E$12+($B6+F$4)/10000)+'Capital Structure'!$C$6*MAX(0,Assumptions!$E$11+Assumptions!$E$13+($B6+F$4)/10000)+'Capital Structure'!$E$7+'Capital Structure'!$E$8 | G6: ='Capital Structure'!$C$5*MAX(0,Assumptions!$E$11+Assumptions!$E$12+($B6+G$4)/10000)+'Capital Structure'!$C$6*MAX(0,Assumptions!$E$11+Assumptions!$E$13+($B6+G$4)/10000)+'Capital Structure'!$E$7+'Capital Structure'!$E$8
B7: 100 | C7: ='Capital Structure'!$C$5*MAX(0,Assumptions!$E$11+Assumptions!$E$12+($B7+C$4)/10000)+'Capital Structure'!$C$6*MAX(0,Assumptions!$E$11+Assumptions!$E$13+($B7+C$4)/10000)+'Capital Structure'!$E$7+'Capital Structure'!$E$8 | D7: ='Capital Structure'!$C$5*MAX(0,Assumptions!$E$11+Assumptions!$E$12+($B7+D$4)/10000)+'Capital Structure'!$C$6*MAX(0,Assumptions!$E$11+Assumptions!$E$13+($B7+D$4)/10000)+'Capital Structure'!$E$7+'Capital Structure'!$E$8 | E7: ='Capital Structure'!$C$5*MAX(0,Assumptions!$E$11+Assumptions!$E$12+($B7+E$4)/10000)+'Capital Structure'!$C$6*MAX(0,Assumptions!$E$11+Assumptions!$E$13+($B7+E$4)/10000)+'Capital Structure'!$E$7+'Capital Structure'!$E$8 | F7: ='Capital Structure'!$C$5*MAX(0,Assumptions!$E$11+Assumptions!$E$12+($B7+F$4)/10000)+'Capital Structure'!$C$6*MAX(0,Assumptions!$E$11+Assumptions!$E$13+($B7+F$4)/10000)+'Capital Structure'!$E$7+'Capital Structure'!$E$8 | G7: ='Capital Structure'!$C$5*MAX(0,Assumptions!$E$11+Assumptions!$E$12+($B7+G$4)/10000)+'Capital Structure'!$C$6*MAX(0,Assumptions!$E$11+Assumptions!$E$13+($B7+G$4)/10000)+'Capital Structure'!$E$7+'Capital Structure'!$E$8
B8: 200 | C8: ='Capital Structure'!$C$5*MAX(0,Assumptions!$E$11+Assumptions!$E$12+($B8+C$4)/10000)+'Capital Structure'!$C$6*MAX(0,Assumptions!$E$11+Assumptions!$E$13+($B8+C$4)/10000)+'Capital Structure'!$E$7+'Capital Structure'!$E$8 | D8: ='Capital Structure'!$C$5*MAX(0,Assumptions!$E$11+Assumptions!$E$12+($B8+D$4)/10000)+'Capital Structure'!$C$6*MAX(0,Assumptions!$E$11+Assumptions!$E$13+($B8+D$4)/10000)+'Capital Structure'!$E$7+'Capital Structure'!$E$8 | E8: ='Capital Structure'!$C$5*MAX(0,Assumptions!$E$11+Assumptions!$E$12+($B8+E$4)/10000)+'Capital Structure'!$C$6*MAX(0,Assumptions!$E$11+Assumptions!$E$13+($B8+E$4)/10000)+'Capital Structure'!$E$7+'Capital Structure'!$E$8 | F8: ='Capital Structure'!$C$5*MAX(0,Assumptions!$E$11+Assumptions!$E$12+($B8+F$4)/10000)+'Capital Structure'!$C$6*MAX(0,Assumptions!$E$11+Assumptions!$E$13+($B8+F$4)/10000)+'Capital Structure'!$E$7+'Capital Structure'!$E$8 | G8: ='Capital Structure'!$C$5*MAX(0,Assumptions!$E$11+Assumptions!$E$12+($B8+G$4)/10000)+'Capital Structure'!$C$6*MAX(0,Assumptions!$E$11+Assumptions!$E$13+($B8+G$4)/10000)+'Capital Structure'!$E$7+'Capital Structure'!$E$8
B9: 300 | C9: ='Capital Structure'!$C$5*MAX(0,Assumptions!$E$11+Assumptions!$E$12+($B9+C$4)/10000)+'Capital Structure'!$C$6*MAX(0,Assumptions!$E$11+Assumptions!$E$13+($B9+C$4)/10000)+'Capital Structure'!$E$7+'Capital Structure'!$E$8 | D9: ='Capital Structure'!$C$5*MAX(0,Assumptions!$E$11+Assumptions!$E$12+($B9+D$4)/10000)+'Capital Structure'!$C$6*MAX(0,Assumptions!$E$11+Assumptions!$E$13+($B9+D$4)/10000)+'Capital Structure'!$E$7+'Capital Structure'!$E$8 | E9: ='Capital Structure'!$C$5*MAX(0,Assumptions!$E$11+Assumptions!$E$12+($B9+E$4)/10000)+'Capital Structure'!$C$6*MAX(0,Assumptions!$E$11+Assumptions!$E$13+($B9+E$4)/10000)+'Capital Structure'!$E$7+'Capital Structure'!$E$8 | F9: ='Capital Structure'!$C$5*MAX(0,Assumptions!$E$11+Assumptions!$E$12+($B9+F$4)/10000)+'Capital Structure'!$C$6*MAX(0,Assumptions!$E$11+Assumptions!$E$13+($B9+F$4)/10000)+'Capital Structure'!$E$7+'Capital Structure'!$E$8 | G9: ='Capital Structure'!$C$5*MAX(0,Assumptions!$E$11+Assumptions!$E$12+($B9+G$4)/10000)+'Capital Structure'!$C$6*MAX(0,Assumptions!$E$11+Assumptions!$E$13+($B9+G$4)/10000)+'Capital Structure'!$E$7+'Capital Structure'!$E$8

Sheet Covenants
B2: Covenant & Rating Screens
B4: Metric | C4: Actual | D4: Threshold | E4: Headroom / status
B5: Gross leverage | C5: ='Capital Structure'!C13 | D5: =Assumptions!E18 | E5: =D5-C5
B6: Interest coverage | C6: ='Capital Structure'!C15 | D6: =Assumptions!E19 | E6: =C6-D6
B7: Near-term maturities / debt | C7: =IFERROR(SUM('Maturity Ladder'!C10:E10)/'Capital Structure'!C10,0) | D7: 0.35 | E7: =D7-C7
B8: Refinancing status | C8: =Refinancing!G8 | D8: PASS | E8: =IF(C8=D8,"PASS","FAIL")

Sheet Recovery
B2: Claim Recovery Waterfall
B4: Metric | C4: Base | D4: Downside | E4: Note
B5: Stressed EBITDA | C5: =Assumptions!C5 | D5: =Assumptions!D5
B6: Recovery multiple | C6: =Assumptions!C20 | D6: =Assumptions!D20
B7: Enterprise value | C7: =C5*C6 | D7: =D5*D6
B8: EV haircut | C8: =C7*Assumptions!C21 | D8: =D7*Assumptions!D21
B9: Distributable value | C9: =C7-C8 | D9: =D7-D8
B10: Gross debt | C10: ='Capital Structure'!C10 | D10: ='Capital Structure'!C10
B11: Recovery value | C11: =MIN(C9,C10) | D11: =MIN(D9,D10)
B12: Recovery rate | C12: =IFERROR(C11/C10,0) | D12: =IFERROR(D11/D10,0)
B13: LGD | C13: =1-C12 | D13: =1-D12

Sheet Checks
B2: Model Checks
B4: Check | C4: Status
B5: Sources equal uses | C5: =IF(Refinancing!G8="PASS","PASS","FAIL")
B6: Debt nonnegative | C6: =IF('Capital Structure'!C10>=0,"PASS","FAIL")
B7: Maturities reconcile | C7: =IF(ABS(SUM('Maturity Ladder'!C10:H10)-'Capital Structure'!C10)<0.01,"PASS","REVIEW")
B8: Recovery bounded | C8: =IF(AND(MIN(Recovery!C12:D12)>=0,MAX(Recovery!C12:D12)<=1),"PASS","FAIL")
B9: Overall | C9: =IF(COUNTIF(C5:C8,"FAIL")+COUNTIF(C5:C8,"REVIEW")=0,"PASS","REVIEW")

Sheet Sources
B2: Source Register
B4: Input / dataset | C4: Source URL or document | D4: As-of | E4: Notes / transformation
B5: Debt instruments | C5: Credit agreements, indentures, or filings | D5: [date] | E5: Balance, rate, maturity, collateral and covenants
B6: Market pricing | C6: Treasury / swap curve and comparable new issues | D6: [date] | E6: Freeze base-rate and spread assumptions
B7: Financial statements | C7: Audited statements or filing | D7: [period] | E7: EBITDA, cash and debt reconciliation
B8: Recovery methodology | C8: Documented enterprise-value and priority assumptions | D8: [date] | E8: Claim-level recovery bridge

Sheet RefreshLog
B2: Refresh Log
B4: Date | C4: Trigger | D4: Source snapshot | E4: What changed | F4: Reviewer / challenge | G4: Next check

Sheet Refinancing & Rates
B2: Debt Rollforward, Maturity Wall, Weighted Cost, and Coverage
B4: Metric | C4: Base | D4: Adversarial | E4: Units / control
B5: Opening debt | C5: 500 | D5: 500
B6: Issuance | C6: 100 | D6: 300
B7: Repayments | C7: 150 | D7: 50
B8: Year 1 maturity | C8: 50 | D8: 300
B9: Year 2 maturity | C9: 75 | D9: 250
B10: Year 3 maturity | C10: 100 | D10: 100
B11: Year 4 maturity | C11: 100 | D11: 50
B12: Year 5 maturity | C12: 125 | D12: 50
B13: Liquidity | C13: 100 | D13: 50
B14: Committed lines | C14: 50 | D14: 50
B15: Tranche 1 amount | C15: 300 | D15: 500
B16: Tranche 1 rate | C16: 0.06 | D16: 0.12
... B22: Maximum weighted cost | C22: 0.1 | D22: 0.1
B26: Ending debt | C26: =MAX(0,C5+C6-C7) | D26: =MAX(0,D5+D6-D7)
B27: Near-term maturities | C27: =C8+C9 | D27: =D8+D9
B28: Refinancing gap | C28: =MAX(0,C27-C13-C14) | D28: =MAX(0,D27-D13-D14)
B29: Maturity concentration | C29: =IFERROR(MAX(C8:C12)/SUM(C8:C12),0) | D29: =IFERROR(MAX(D8:D12)/SUM(D8:D12),0)
B30: Weighted cost | C30: =IFERROR((C15*C16+C17*C18)/(C15+C17),0) | D30: =IFERROR((D15*D16+D17*D18)/(D15+D17),0)
B31: Cash interest | C31: =C26*C30 | D31: =D26*D30
B32: Interest coverage | C32: =IFERROR(C19/C31,0) | D32: =IFERROR(D19/D31,0)

Sheet Decision & Checks
B2: Debt Finance Decision Dashboard and Independent Checks
B4: Check / decision | C4: Metric | D4: Status | E4: Interpretation / action
B5: Debt rollforward residual | C5: ='Refinancing & Rates'!D26-MAX(0,'Refinancing & Rates'!D5+'Refinancing & Rates'!D6-'Refinancing & Rates'!D7) | D5: =IF(ABS(C5)<0.01,"PASS","FAIL") | E5: Debt must reconcile to issuance and repayment.
B6: Weighted-cost residual | C6: ='Refinancing & Rates'!D30*('Refinancing & Rates'!D15+'Refinancing & Rates'!D17)-('Refinancing & Rates'!D15*'Refinancing & Rates'!D16+'Refinancing & Rates'!D17*'Refinancing & Rates'!D18) | D6: =IF(ABS(C6)<0.01,"PASS","FAIL") | E6: Weighted pricing must reconcile to tranche balances and rates.
B7: Refinancing gap | C7: ='Refinancing & Rates'!D28 | D7: =IF(C7=0,"PASS","BREACH") | E7: Near-term maturities must be covered by liquidity and committed facilities.
B8: Maturity concentration | C8: ='Refinancing & Rates'!D29 | D8: =IF(C8<='Refinancing & Rates'!D20,"PASS","BREACH") | E8: Escalate concentrated maturity walls.
B9: Interest coverage | C9: ='Refinancing & Rates'!D32 | D9: =IF(C9>='Refinancing & Rates'!D21,"PASS","BREACH") | E9: EBITDA must cover pro forma cash interest.
B10: Weighted refinancing cost | C10: ='Refinancing & Rates'!D30 | D10: =IF(C10<='Refinancing & Rates'!D22,"PASS","BREACH") | E10: Escalate expensive issuance and rate-reset risk.
B12: Overall model status | C12: =IF(COUNTIF(D5:D10,"FAIL")+COUNTIF(D5:D10,"BREACH")>0,"BREACH",IF(COUNTIF(D5:D10,"REVIEW")>0,"REVIEW","PASS"))
