Workbook
Name FS_MODEL_ID: 'Institutional Surface'!$C$4
Name FS_DOMAIN: 'Institutional Surface'!$C$5
Name FS_MATURITY: 'Institutional Surface'!$C$6

Sheet Cover
B2: [PORTFOLIO] — Multi-Asset Risk Model
B4: Portfolio / desk: | C4: [Name]
B5: Risk horizon: | C5: 1-day and stressed liquidation
B6: Last refreshed: | C6: [timestamp]
B7: Next limit review: | C7: [date]
B8: Refresh cadence: | C8: Intraday / daily
B9: Active scenario: | C9: Base
B10: Units: | C10: $ in millions unless noted
B13: Modeling conventions
B14: Blue text / yellow fill | C14: Hardcoded input or selected scenario
B15: Black text | C15: Formula / same-sheet calculation
B16: Green text | C16: Cross-sheet formula / link
B17: Checks | C17: PASS / REVIEW / FAIL must remain visible

Sheet Institutional Surface
B2: Risk Management — Institutional Decision Surface
B4: Model ID | C4: 09
B5: Domain | C5: Risk Management
B6: Declared maturity | C6: M2
B7: Canonical builder | C7: tools/builders/build_risk_release.py
B8: Decision arena | C8: trading desk, independent risk, model validation, senior risk committee and regulator
B9: Committee artifact | C9: daily risk and limit pack
B10: Operating cadence | C10: intraday monitoring; daily sign-off; monthly committee
B12: Key decision outputs
B13: # | C13: Requirement | D13: Owner | E13: Evidence / location | F13: Status
B14: 1 | C14: VaR / ES and stress loss | F14: OPEN
B15: 2 | C15: factor and component risk | F15: OPEN
B16: 3 | C16: liquidity horizon and liquidation cost | F16: OPEN
B17: 4 | C17: base, downside and break-even outputs | F17: OPEN
B18: 5 | C18: liquidity / funding requirement and binding constraint | F18: OPEN
B20: Insider questions
B21: # | C21: Requirement | D21: Owner | E21: Evidence / location | F21: Status
B22: 1 | C22: What risk is missing from the factor map? | F22: OPEN
B23: 2 | C23: Where does diversification disappear under stress? | F23: OPEN
B24: 3 | C24: Which desk would fail model eligibility? | F24: OPEN
B25: 4 | C25: Which assumption is owner-approved versus modeler judgement? | F25: OPEN
B26: 5 | C26: What fails first and who must act? | F26: OPEN
B28: Scenario families
B29: # | C29: Requirement | D29: Owner | E29: Evidence / location | F29: Status
B30: 1 | C30: historical and hypothetical stress | F30: OPEN
B31: 2 | C31: correlation break | F31: OPEN
B32: 3 | C32: basis and spread dislocation | F32: OPEN
B33: 4 | C33: data freshness / source failure | F33: OPEN
B34: 5 | C34: combined severe-but-plausible downside | F34: OPEN
B36: Primary diligence documents
B37: # | C37: Requirement | D37: Owner | E37: Evidence / location | F37: Status
B38: 1 | C38: risk appetite and limits | F38: OPEN
B39: 2 | C39: product control P&L | F39: OPEN
B40: 3 | C40: market data hierarchy | F40: OPEN
B41: 4 | C41: approved model card and assumption register | F41: OPEN
B42: 5 | C42: independent validation and challenge record | F42: OPEN
B44: Challenge tests
B45: # | C45: Requirement | D45: Owner | E45: Evidence / location | F45: Status
B46: 1 | C46: component risk reconciles to total | F46: OPEN
B47: 2 | C47: ES not below VaR at same confidence | F47: OPEN
...

Sheet Challenge Log
B2: Independent Challenge, Override and Closure Log
B4: Date | C4: Reviewer | D4: Challenge | E4: Owner response | F4: Evidence | G4: Impact | H4: Status | I4: Closure
D5: component risk reconciles to total | H5: OPEN
D6: ES not below VaR at same confidence | H6: OPEN
D7: stress loss sign conventions consistent | H7: OPEN
D8: source-to-model lineage is reproducible | H8: OPEN
D9: units, signs, dates and legal definitions reconcile | H9: OPEN

Sheet Lineage Map
B2: Source, Transformation, Ownership and Refresh Map
B4: Source class | C4: Cadence | D4: Control | E4: System / provider | F4: As-of | G4: Owner | H4: Transform | I4: Downstream | J4: Status
B5: positions | C5: intraday/daily | D5: front-to-back reconciliation | J5: TO MAP
B6: market data | C6: intraday/daily | D6: source and stale-point controls | J6: TO MAP
B7: model governance evidence | C7: per release | D7: version, reviewer, sign-off and change log | J7: TO MAP
B8: decision-use snapshot | C8: per decision | D8: immutable as-of date and source receipt | J8: TO MAP

Sheet Assumptions
B2: Risk and Liquidity Assumptions
B4: Assumption | C4: Base | D4: Downside | E4: Active | F4: Units / note
B5: VaR confidence | C5: 0.99 | D5: 0.995 | E5: =IF(Cover!$C$9="Downside",D5,C5) | F5: %
B6: Trading days per year | C6: 252 | D6: 252 | E6: =IF(Cover!$C$9="Downside",D6,C6) | F6: days
B7: Equity annual volatility | C7: 0.22 | D7: 0.35 | E7: =IF(Cover!$C$9="Downside",D7,C7) | F7: %
B8: Rates annual volatility | C8: 0.012 | D8: 0.025 | E8: =IF(Cover!$C$9="Downside",D8,C8) | F8: yield change
B9: Credit annual volatility | C9: 0.015 | D9: 0.035 | E9: =IF(Cover!$C$9="Downside",D9,C9) | F9: spread change
B10: FX annual volatility | C10: 0.12 | D10: 0.2 | E10: =IF(Cover!$C$9="Downside",D10,C10) | F10: %
B11: Volatility-factor annual volatility | C11: 0.3 | D11: 0.5 | E11: =IF(Cover!$C$9="Downside",D11,C11) | F11: %
B12: Maximum portfolio VaR | C12: 12 | D12: 10 | E12: =IF(Cover!$C$9="Downside",D12,C12) | F12: $mm
B13: Maximum stress loss | C13: 40 | D13: 30 | E13: =IF(Cover!$C$9="Downside",D13,C13) | F13: $mm
B14: Maximum illiquid NAV | C14: 0.25 | D14: 0.2 | E14: =IF(Cover!$C$9="Downside",D14,C14) | F14: %
B15: Maximum single-name concentration | C15: 0.2 | D15: 0.15 | E15: =IF(Cover!$C$9="Downside",D15,C15) | F15: %
B16: Maximum gross leverage | C16: 4 | D16: 3 | E16: =IF(Cover!$C$9="Downside",D16,C16) | F16: x
... B18: Available capital / NAV | C18: 250 | D18: 250 | E18: =IF(Cover!$C$9="Downside",D18,C18) | F18: $mm

Sheet Positions
B2: Position-Level Risk Inventory
B4: Instrument | C4: Asset class | D4: Market value | E4: Gross notional | F4: Delta | G4: Beta | H4: Duration | I4: Spread duration | J4: DV01 | K4: Vega | L4: FX delta | M4: Days to liquidate | N4: Equity | O4: Rates | P4: Credit | Q4: FX | R4: Volatility | S4: Weighted risk exposure
B5: Equity Index Future | C5: Equity | D5: 45 | E5: 120 | F5: 1 | G5: 1 | H5: 0 | I5: 0 | J5: 0 | K5: 0 | L5: 0 | M5: 0.2 | N5: 1 | O5: 0 | P5: 0 | Q5: 0 | R5: 0 | S5: =SUMPRODUCT(C5:Q5,C5:Q5)^0.5
B6: Single Name A | C6: Equity | D6: 35 | E6: 35 | F6: 1 | G6: 1.2 | H6: 0 | I6: 0 | J6: 0 | K6: 0 | L6: 0 | M6: 1 | N6: 1.2 | O6: 0 | P6: 0.1 | Q6: 0 | R6: 0.1 | S6: =SUMPRODUCT(C6:Q6,C6:Q6)^0.5
B7: Single Name Put | C7: Option | D7: 8 | E7: 25 | F7: -0.35 | G7: -0.4 | H7: 0 | I7: 0 | J7: 0 | K7: 0.18 | L7: 0 | M7: 1.5 | N7: -0.4 | O7: 0 | P7: 0 | Q7: 0 | R7: 0.8 | S7: =SUMPRODUCT(C7:Q7,C7:Q7)^0.5
B8: 10Y Treasury | C8: Rates | D8: 50 | E8: 50 | F8: 1 | G8: 0 | H8: 8.2 | I8: 0 | J8: 0.041 | K8: 0 | L8: 0 | M8: 0.5 | N8: 0 | O8: -8.2 | P8: 0 | Q8: 0 | R8: 0 | S8: =SUMPRODUCT(C8:Q8,C8:Q8)^0.5
B9: IG Credit ETF | C9: Credit | D9: 32 | E9: 50 | F9: 1 | G9: 0.35 | H9: 5.5 | I9: 5 | J9: 0.018 | K9: 0 | L9: 0 | M9: 1 | N9: 0.35 | O9: -2 | P9: -5 | Q9: 0 | R9: 0 | S9: =SUMPRODUCT(C9:Q9,C9:Q9)^0.5
B10: HY Bond | C10: Credit | D10: 28 | E10: 40 | F10: 1 | G10: 0.55 | H10: 4 | I10: 3.8 | J10: 0.011 | K10: 0 | L10: 0 | M10: 4 | N10: 0.55 | O10: -1 | P10: -3.8 | Q10: 0 | R10: 0 | S10: =SUMPRODUCT(C10:Q10,C10:Q10)^0.5
B11: EURUSD Forward | C11: FX | D11: 5 | E11: 80 | F11: 1 | G11: 0 | H11: 0 | I11: 0 | J11: 0 | K11: 0 | L11: 80 | M11: 0.3 | N11: 0 | O11: 0 | P11: 0 | Q11: 1 | R11: 0 | S11: =SUMPRODUCT(C11:Q11,C11:Q11)^0.5
B12: Commodity Future | C12: Commodity | D12: 20 | E12: 65 | F12: 1 | G12: 0.25 | H12: 0 | I12: 0 | J12: 0 | K12: 0 | L12: 0 | M12: 0.5 | N12: 0.25 | O12: 0 | P12: 0.2 | Q12: 0.1 | R12: 0.1 | S12: =SUMPRODUCT(C12:Q12,C12:Q12)^0.5
B13: Variance Swap | C13: Volatility | D13: 6 | E13: 30 | F13: 0 | G13: 0 | H13: 0 | I13: 0 | J13: 0 | K13: 0.45 | L13: 0 | M13: 2 | N13: 0 | O13: 0 | P13: 0 | Q13: 0 | R13: 1 | S13: =SUMPRODUCT(C13:Q13,C13:Q13)^0.5
B14: Private Credit Position | C14: Private | D14: 40 | E14: 40 | F14: 1 | G14: 0.2 | H14: 2 | I14: 2.5 | J14: 0.008 | K14: 0 | L14: 0 | M14: 20 | N14: 0.2 | O14: -0.5 | P14: -2.5 | Q14: 0 | R14: 0 | S14: =SUMPRODUCT(C14:Q14,C14:Q14)^0.5
B15: Cash | C15: Cash | D15: 25 | E15: 25 | F15: 1 | G15: 0 | H15: 0 | I15: 0 | J15: 0 | K15: 0 | L15: 0 | M15: 0 | N15: 0 | O15: 0 | P15: 0 | Q15: 0 | R15: 0 | S15: =SUMPRODUCT(C15:Q15,C15:Q15)^0.5
B16: Short Equity Basket | C16: Equity | D16: -18 | E16: 60 | F16: -1 | G16: -0.9 | H16: 0 | I16: 0 | J16: 0 | K16: 0 | L16: 0 | M16: 0.5 | N16: -0.9 | O16: 0 | P16: -0.1 | Q16: 0 | R16: 0 | S16: =SUMPRODUCT(C16:Q16,C16:Q16)^0.5
B18: Portfolio total | D18: =SUM(D5:D16) | E18: =SUM(E5:E16) | J18: =SUM(J5:J16) | K18: =SUM(K5:K16) | L18: =SUM(L5:L16) | S18: =SUM(S5:S16)

Sheet Factors
B2: Factor Exposure and Covariance
B4: Factor | C4: Exposure | D4: Annual vol | E4: Equity | F4: Rates | G4: Credit | H4: FX | I4: Volatility
B5: Equity | C5: =SUMPRODUCT(Positions!$D$5:$D$16,Positions!$N$5:$N$16) | D5: =Assumptions!E7 | E5: 1 | F5: -0.2 | G5: 0.35 | H5: 0.1 | I5: 0.45
B6: Rates | C6: =SUMPRODUCT(Positions!$D$5:$D$16,Positions!$O$5:$O$16) | D6: =Assumptions!E8 | E6: -0.2 | F6: 1 | G6: -0.25 | H6: 0.05 | I6: -0.1
B7: Credit | C7: =SUMPRODUCT(Positions!$D$5:$D$16,Positions!$P$5:$P$16) | D7: =Assumptions!E9 | E7: 0.35 | F7: -0.25 | G7: 1 | H7: 0.1 | I7: 0.3
B8: FX | C8: =SUMPRODUCT(Positions!$D$5:$D$16,Positions!$Q$5:$Q$16) | D8: =Assumptions!E10 | E8: 0.1 | F8: 0.05 | G8: 0.1 | H8: 1 | I8: 0.1
B9: Volatility | C9: =SUMPRODUCT(Positions!$D$5:$D$16,Positions!$R$5:$R$16) | D9: =Assumptions!E11 | E9: 0.45 | F9: -0.1 | G9: 0.3 | H9: 0.1 | I9: 1
B12: Annual portfolio variance | C12: =$C$5*$C$5*$D$5*$D$5*E5+$C$5*$C$6*$D$5*$D$6*F5+$C$5*$C$7*$D$5*$D$7*G5+$C$5*$C$8*$D$5*$D$8*H5+$C$5*$C$9*$D$5*$D$9*I5+$C$6*$C$5*$D$6*$D$5*E6+$C$6*$C$6*$D$6*$D$6*F6+$C$6*$C$7*$D$6*$D$7*G6+$C$6*$C$8*$D$6*$D$8*H6+$C$6*$C$9*$D$6*$D$9*I6+$C$7*$C$5*$D$7*$D$5*E7+$C$7*$C$6*$D$7*$D$6*F7+$C$7*$C$7*$D$7*$D$7*G7+$C$7*$C$8*$D$7*$D$8*H7+$C$7*$C$9*$D$7*$D$9*I7+$C$8*$C$5*$D$8*$D$5*E8+$C$8*$C$6*$D$8*$D$6*F8+$C$8*$C$7*$D$8*$D$7*G8+$C$8*$C$8*$D$8*$D$8*H8+$C$8*$C$9*$D$8*$D$9*I8+$C$9*$C$5*$D$9*$D$5*E9+$C$9*$C$6*$D$9*$D$6*F9+$C$9*$C$7*$D$9*$D$7*G9+$C$9*$C$8*$D$9*$D$8*H9+$C$9*$C$9*$D$9*$D$9*I9
B13: Annual portfolio volatility | C13: =SQRT(MAX(0,C12))

Sheet VaR & ES
B2: Parametric VaR and Expected Shortfall
B4: Metric | C4: Value | D4: Units | E4: Method
B5: Annual portfolio volatility | C5: =Factors!C13 | D5: $mm | E5: factor covariance
B6: Daily portfolio volatility | C6: =C5/SQRT(Assumptions!E6) | D6: $mm | E6: annual / sqrt(days)
B7: Normal quantile | C7: =-NORMSINV(1-Assumptions!E5) | D7: z | E7: confidence quantile
B8: One-day VaR | C8: =C6*C7 | D8: $mm | E8: sigma x z
B9: One-day expected shortfall | C9: =C6*(EXP(-((C7)^2)/2)/SQRT(2*PI()))/(1-Assumptions!E5) | D9: $mm | E9: normal tail expectation
B10: VaR / NAV | C10: =C8/Assumptions!E18 | D10: % | E10: capital consumption
B11: Diversification benefit | C11: =1-C5/SUMPRODUCT(ABS(Factors!C5:C9),Factors!D5:D9) | D11: % | E11: 1 - portfolio / standalone

Sheet Risk Contributions
B2: Position-Level VaR, Stress, and Liquidity Contributions
B4: Instrument | C4: Gross notional | D4: Standalone VaR | E4: Component VaR | F4: % portfolio VaR | G4: Worst stress loss | H4: Liquidation loss | I4: Liquidity-adjusted risk | J4: Risk concentration
B5: =Positions!B5 | C5: =ABS(Positions!E5) | D5: ='VaR & ES'!$C$7*SQRT(MAX(0,((Positions!$E$5*Positions!$N$5)*(Positions!$E$5*Positions!$N$5)*Factors!$D$5*Factors!$D$5*Factors!$E$5+(Positions!$E$5*Positions!$N$5)*(Positions!$E$5*Positions!$O$5)*Factors!$D$5*Factors!$D$6*Factors!$F$5+(Positions!$E$5*Positions!$N$5)*(Positions!$E$5*Positions!$P$5)*Factors!$D$5*Factors!$D$7*Factors!$G$5+(Positions!$E$5*Positions!$N$5)*(Positions!$E$5*Positions!$Q$5)*Factors!$D$5*Factors!$D$8*Factors!$H$5+(Positions!$E$5*Positions!$N$5)*(Positions!$E$5*Positions!$R$5)*Factors!$D$5*Factors!$D$9*Factors!$I$5+(Positions!$E$5*Positions!$O$5)*(Positions!$E$5*Positions!$N$5)*Factors!$D$6*Factors!$D$5*Factors!$E$6+(Positions!$E$5*Positions!$O$5)*(Positions!$E$5*Positions!$O$5)*Factors!$D$6*Factors!$D$6*Factors!$F$6+(Positions!$E$5*Positions!$O$5)*(Positions!$E$5*Positions!$P$5)*Factors!$D$6*Factors!$D$7*Factors!$G$6+(Positions!$E$5*Positions!$O$5)*(Positions!$E$5*Positions!$Q$5)*Factors!$D$6*Factors!$D$8*Factors!$H$6+(Positions!$E$5*Positions!$O$5)*(Positions!$E$5*Positions!$R$5)*Factors!$D$6*Factors!$D$9*Factors!$I$6+(Positions!$E$5*Positions!$P$5)*(Positions!$E$5*Positions!$N$5)*Factors!$D$7*Factors!$D$5*Factors!$E$7+(Positions!$E$5*Positions!$P$5)*(Positions!$E$5*Positions!$O$5)*Factors!$D$7*Factors!$D$6*Factors!$F$7+(Positions!$E$5*Positions!$P$5)*(Positions!$E$5*Positions!$P$5)*Factors!$D$7*Factors!$D$7*Factors!$G$7+(Positions!$E$5*Positions!$P$5)*(Positions!$E$5*Positions!$Q$5)*Factors!$D$7*Factors!$D$8*Factors!$H$7+(Positions!$E$5*Positions!$P$5)*(Positions!$E$5*Positions!$R$5)*Factors!$D$7*Factors!$D$9*Factors!$I$7+(Positions!$E$5*Positions!$Q$5)*(Positions!$E$5*Positions!$N$5)*Factors!$D$8*Factors!$D$5*Factors!$E$8+(Positions!$E$5*Positions!$Q$5)*(Positions!$E$5*Positions!$O$5)*Factors!$D$8*Factors!$D$6*Factors!$F$8+(Positions!$E$5*Positions!$Q$5)*(Positions!$E$5*Positions!$P$5)*Factors!$D$8*Factors!$D$7*Factors!$G$8+(Positions!$E$5*Positions!$Q$5)*(Positions!$E$5*Positions!$Q$5)*Factors!$D$8*Factors!$D$8*Factors!$H$8+(Positions!$E$5*Positions!$Q$5)*(Positions!$E$5*Positions!$R$5)*Factors!$D$8*Factors!$D$9*Factors!$I$8+(Positions!$E$5*Positions!$R$5)*(Positions!$E$5*Positions!$N$5)*Factors!$D$9*Factors!$D$5*Factors!$E$9+(Positions!$E$5*Positions!$R$5)*(Positions!$E$5*Positions!$O$5)*Factors!$D$9*Factors!$D$6*Factors!$F$9+(Positions!$E$5*Positions!$R$5)*(Positions!$E$5*Positions!$P$5)*Factors!$D$9*Factors!$D$7*Factors!$G$9+(Positions!$E$5*Positions!$R$5)*(Positions!$E$5*Positions!$Q$5)*Factors!$D$9*Factors!$D$8*Factors!$H$9+(Positions!$E$5*Positions!$R$5)*(Positions!$E$5*Positions!$R$5)*Factors!$D$9*Factors!$D$9*Factors!$I$9)/Assumptions!$E$6)) | E5: =IFERROR('VaR & ES'!$C$7*((Positions!$E$5*Positions!$N$5)*Factors!$D$5*Factors!$C$5*Factors!$D$5*Factors!$E$5+(Positions!$E$5*Positions!$N$5)*Factors!$D$5*Factors!$C$6*Factors!$D$6*Factors!$F$5+(Positions!$E$5*Positions!$N$5)*Factors!$D$5*Factors!$C$7*Factors!$D$7*Factors!$G$5+(Positions!$E$5*Positions!$N$5)*Factors!$D$5*Factors!$C$8*Factors!$D$8*Factors!$H$5+(Positions!$E$5*Positions!$N$5)*Factors!$D$5*Factors!$C$9*Factors!$D$9*Factors!$I$5+(Positions!$E$5*Positions!$O$5)*Factors!$D$6*Factors!$C$5*Factors!$D$5*Factors!$E$6+(Positions!$E$5*Positions!$O$5)*Factors!$D$6*Factors!$C$6*Factors!$D$6*Factors!$F$6+(Positions!$E$5*Positions!$O$5)*Factors!$D$6*Factors!$C$7*Factors!$D$7*Factors!$G$6+(Positions!$E$5*Positions!$O$5)*Factors!$D$6*Factors!$C$8*Factors!$D$8*Factors!$H$6+(Positions!$E$5*Positions!$O$5)*Factors!$D$6*Factors!$C$9*Factors!$D$9*Factors!$I$6+(Positions!$E$5*Positions!$P$5)*Factors!$D$7*Factors!$C$5*Factors!$D$5*Factors!$E$7+(Positions!$E$5*Positions!$P$5)*Factors!$D$7*Factors!$C$6*Factors!$D$6*Factors!$F$7+(Positions!$E$5*Positions!$P$5)*Factors!$D$7*Factors!$C$7*Factors!$D$7*Factors!$G$7+(Positions!$E$5*Positions!$P$5)*Factors!$D$7*Factors!$C$8*Factors!$D$8*Factors!$H$7+(Positions!$E$5*Positions!$P$5)*Factors!$D$7*Factors!$C$9*Factors!$D$9*Factors!$I$7+(Positions!$E$5*Positions!$Q$5)*Factors!$D$8*Factors!$C$5*Factors!$D$5*Factors!$E$8+(Positions!$E$5*Positions!$Q$5)*Factors!$D$8*Factors!$C$6*Factors!$D$6*Factors!$F$8+(Positions!$E$5*Positions!$Q$5)*Factors!$D$8*Factors!$C$7*Factors!$D$7*Factors!$G$8+(Positions!$E$5*Positions!$Q$5)*Factors!$D$8*Factors!$C$8*Factors!$D$8*Factors!$H$8+(Positions!$E$5*Positions!$Q$5)*Factors!$D$8*Factors!$C$9*Factors!$D$9*Factors!$I$8+(Positions!$E$5*Positions!$R$5)*Factors!$D$9*Factors!$C$5*Factors!$D$5*Factors!$E$9+(Positions!$E$5*Positions!$R$5)*Factors!$D$9*Factors!$C$6*Factors!$D$6*Factors!$F$9+(Positions!$E$5*Positions!$R$5)*Factors!$D$9*Factors!$C$7*Factors!$D$7*Factors!$G$9+(Positions!$E$5*Positions!$R$5)*Factors!$D$9*Factors!$C$8*Factors!$D$8*Factors!$H$9+(Positions!$E$5*Positions!$R$5)*Factors!$D$9*Factors!$C$9*Factors!$D$9*Factors!$I$9)/(Factors!$C$13*SQRT(Assumptions!$E$6)),0) | F5: =IFERROR(E5/'VaR & ES'!$C$8,0) | G5: =-MIN((Positions!$E$5*Positions!$N$5*Stress!$C$5+Positions!$E$5*Positions!$O$5*Stress!$D$5+Positions!$E$5*Positions!$P$5*Stress!$E$5+Positions!$E$5*Positions!$Q$5*Stress!$F$5+Positions!$E$5*Positions!$R$5*Stress!$G$5),(Positions!$E$5*Positions!$N$5*Stress!$C$6+Positions!$E$5*Positions!$O$5*Stress!$D$6+Positions!$E$5*Positions!$P$5*Stress!$E$6+Positions!$E$5*Positions!$Q$5*Stress!$F$6+Positions!$E$5*Positions!$R$5*Stress!$G$6),(Positions!$E$5*Positions!$N$5*Stress!$C$7+Positions!$E$5*Positions!$O$5*Stress!$D$7+Positions!$E$5*Positions!$P$5*Stress!$E$7+Positions!$E$5*Positions!$Q$5*Stress!$F$7+Positions!$E$5*Positions!$R$5*Stress!$G$7),(Positions!$E$5*Positions!$N$5*Stress!$C$8+Positions!$E$5*Positions!$O$5*Stress!$D$8+Positions!$E$5*Positions!$P$5*Stress!$E$8+Positions!$E$5*Positions!$Q$5*Stress!$F$8+Positions!$E$5*Positions!$R$5*Stress!$G$8),(Positions!$E$5*Positions!$N$5*Stress!$C$9+Positions!$E$5*Positions!$O$5*Stress!$D$9+Positions!$E$5*Positions!$P$5*Stress!$E$9+Positions!$E$5*Positions!$Q$5*Stress!$F$9+Positions!$E$5*Positions!$R$5*Stress!$G$9),(Positions!$E$5*Positions!$N$5*Stress!$C$10+Positions!$E$5*Positions!$O$5*Stress!$D$10+Positions!$E$5*Positions!$P$5*Stress!$E$10+Positions!$E$5*Positions!$Q$5*Stress!$F$10+Positions!$E$5*Positions!$R$5*Stress!$G$10)) | H5: =Liquidity!G5 | I5: =ABS(E5)+G5+H5 | J5: =IFERROR(I5/SUM($I$5:$I$16),0)
B6: =Positions!B6 | C6: =ABS(Positions!E6) | D6: ='VaR & ES'!$C$7*SQRT(MAX(0,((Positions!$E$6*Positions!$N$6)*(Positions!$E$6*Positions!$N$6)*Factors!$D$5*Factors!$D$5*Factors!$E$5+(Positions!$E$6*Positions!$N$6)*(Positions!$E$6*Positions!$O$6)*Factors!$D$5*Factors!$D$6*Factors!$F$5+(Positions!$E$6*Positions!$N$6)*(Positions!$E$6*Positions!$P$6)*Factors!$D$5*Factors!$D$7*Factors!$G$5+(Positions!$E$6*Positions!$N$6)*(Positions!$E$6*Positions!$Q$6)*Factors!$D$5*Factors!$D$8*Factors!$H$5+(Positions!$E$6*Positions!$N$6)*(Positions!$E$6*Positions!$R$6)*Factors!$D$5*Factors!$D$9*Factors!$I$5+(Positions!$E$6*Positions!$O$6)*(Positions!$E$6*Positions!$N$6)*Factors!$D$6*Factors!$D$5*Factors!$E$6+(Positions!$E$6*Positions!$O$6)*(Positions!$E$6*Positions!$O$6)*Factors!$D$6*Factors!$D$6*Factors!$F$6+(Positions!$E$6*Positions!$O$6)*(Positions!$E$6*Positions!$P$6)*Factors!$D$6*Factors!$D$7*Factors!$G$6+(Positions!$E$6*Positions!$O$6)*(Positions!$E$6*Positions!$Q$6)*Factors!$D$6*Factors!$D$8*Factors!$H$6+(Positions!$E$6*Positions!$O$6)*(Positions!$E$6*Positions!$R$6)*Factors!$D$6*Factors!$D$9*Factors!$I$6+(Positions!$E$6*Positions!$P$6)*(Positions!$E$6*Positions!$N$6)*Factors!$D$7*Factors!$D$5*Factors!$E$7+(Positions!$E$6*Positions!$P$6)*(Positions!$E$6*Positions!$O$6)*Factors!$D$7*Factors!$D$6*Factors!$F$7+(Positions!$E$6*Positions!$P$6)*(Positions!$E$6*Positions!$P$6)*Factors!$D$7*Factors!$D$7*Factors!$G$7+(Positions!$E$6*Positions!$P$6)*(Positions!$E$6*Positions!$Q$6)*Factors!$D$7*Factors!$D$8*Factors!$H$7+(Positions!$E$6*Positions!$P$6)*(Positions!$E$6*Positions!$R$6)*Factors!$D$7*Factors!$D$9*Factors!$I$7+(Positions!$E$6*Positions!$Q$6)*(Positions!$E$6*Positions!$N$6)*Factors!$D$8*Factors!$D$5*Factors!$E$8+(Positions!$E$6*Positions!$Q$6)*(Positions!$E$6*Positions!$O$6)*Factors!$D$8*Factors!$D$6*Factors!$F$8+(Positions!$E$6*Positions!$Q$6)*(Positions!$E$6*Positions!$P$6)*Factors!$D$8*Factors!$D$7*Factors!$G$8+(Positions!$E$6*Positions!$Q$6)*(Positions!$E$6*Positions!$Q$6)*Factors!$D$8*Factors!$D$8*Factors!$H$8+(Positions!$E$6*Positions!$Q$6)*(Positions!$E$6*Positions!$R$6)*Factors!$D$8*Factors!$D$9*Factors!$I$8+(Positions!$E$6*Positions!$R$6)*(Positions!$E$6*Positions!$N$6)*Factors!$D$9*Factors!$D$5*Factors!$E$9+(Positions!$E$6*Positions!$R$6)*(Positions!$E$6*Positions!$O$6)*Factors!$D$9*Factors!$D$6*Factors!$F$9+(Positions!$E$6*Positions!$R$6)*(Positions!$E$6*Positions!$P$6)*Factors!$D$9*Factors!$D$7*Factors!$G$9+(Positions!$E$6*Positions!$R$6)*(Positions!$E$6*Positions!$Q$6)*Factors!$D$9*Factors!$D$8*Factors!$H$9+(Positions!$E$6*Positions!$R$6)*(Positions!$E$6*Positions!$R$6)*Factors!$D$9*Factors!$D$9*Factors!$I$9)/Assumptions!$E$6)) | E6: =IFERROR('VaR & ES'!$C$7*((Positions!$E$6*Positions!$N$6)*Factors!$D$5*Factors!$C$5*Factors!$D$5*Factors!$E$5+(Positions!$E$6*Positions!$N$6)*Factors!$D$5*Factors!$C$6*Factors!$D$6*Factors!$F$5+(Positions!$E$6*Positions!$N$6)*Factors!$D$5*Factors!$C$7*Factors!$D$7*Factors!$G$5+(Positions!$E$6*Positions!$N$6)*Factors!$D$5*Factors!$C$8*Factors!$D$8*Factors!$H$5+(Positions!$E$6*Positions!$N$6)*Factors!$D$5*Factors!$C$9*Factors!$D$9*Factors!$I$5+(Positions!$E$6*Positions!$O$6)*Factors!$D$6*Factors!$C$5*Factors!$D$5*Factors!$E$6+(Positions!$E$6*Positions!$O$6)*Factors!$D$6*Factors!$C$6*Factors!$D$6*Factors!$F$6+(Positions!$E$6*Positions!$O$6)*Factors!$D$6*Factors!$C$7*Factors!$D$7*Factors!$G$6+(Positions!$E$6*Positions!$O$6)*Factors!$D$6*Factors!$C$8*Factors!$D$8*Factors!$H$6+(Positions!$E$6*Positions!$O$6)*Factors!$D$6*Factors!$C$9*Factors!$D$9*Factors!$I$6+(Positions!$E$6*Positions!$P$6)*Factors!$D$7*Factors!$C$5*Factors!$D$5*Factors!$E$7+(Positions!$E$6*Positions!$P$6)*Factors!$D$7*Factors!$C$6*Factors!$D$6*Factors!$F$7+(Positions!$E$6*Positions!$P$6)*Factors!$D$7*Factors!$C$7*Factors!$D$7*Factors!$G$7+(Positions!$E$6*Positions!$P$6)*Factors!$D$7*Factors!$C$8*Factors!$D$8*Factors!$H$7+(Positions!$E$6*Positions!$P$6)*Factors!$D$7*Factors!$C$9*Factors!$D$9*Factors!$I$7+(Positions!$E$6*Positions!$Q$6)*Factors!$D$8*Factors!$C$5*Factors!$D$5*Factors!$E$8+(Positions!$E$6*Positions!$Q$6)*Factors!$D$8*Factors!$C$6*Factors!$D$6*Factors!$F$8+(Positions!$E$6*Positions!$Q$6)*Factors!$D$8*Factors!$C$7*Factors!$D$7*Factors!$G$8+(Positions!$E$6*Positions!$Q$6)*Factors!$D$8*Factors!$C$8*Factors!$D$8*Factors!$H$8+(Positions!$E$6*Positions!$Q$6)*Factors!$D$8*Factors!$C$9*Factors!$D$9*Factors!$I$8+(Positions!$E$6*Positions!$R$6)*Factors!$D$9*Factors!$C$5*Factors!$D$5*Factors!$E$9+(Positions!$E$6*Positions!$R$6)*Factors!$D$9*Factors!$C$6*Factors!$D$6*Factors!$F$9+(Positions!$E$6*Positions!$R$6)*Factors!$D$9*Factors!$C$7*Factors!$D$7*Factors!$G$9+(Positions!$E$6*Positions!$R$6)*Factors!$D$9*Factors!$C$8*Factors!$D$8*Factors!$H$9+(Positions!$E$6*Positions!$R$6)*Factors!$D$9*Factors!$C$9*Factors!$D$9*Factors!$I$9)/(Factors!$C$13*SQRT(Assumptions!$E$6)),0) | F6: =IFERROR(E6/'VaR & ES'!$C$8,0) | G6: =-MIN((Positions!$E$6*Positions!$N$6*Stress!$C$5+Positions!$E$6*Positions!$O$6*Stress!$D$5+Positions!$E$6*Positions!$P$6*Stress!$E$5+Positions!$E$6*Positions!$Q$6*Stress!$F$5+Positions!$E$6*Positions!$R$6*Stress!$G$5),(Positions!$E$6*Positions!$N$6*Stress!$C$6+Positions!$E$6*Positions!$O$6*Stress!$D$6+Positions!$E$6*Positions!$P$6*Stress!$E$6+Positions!$E$6*Positions!$Q$6*Stress!$F$6+Positions!$E$6*Positions!$R$6*Stress!$G$6),(Positions!$E$6*Positions!$N$6*Stress!$C$7+Positions!$E$6*Positions!$O$6*Stress!$D$7+Positions!$E$6*Positions!$P$6*Stress!$E$7+Positions!$E$6*Positions!$Q$6*Stress!$F$7+Positions!$E$6*Positions!$R$6*Stress!$G$7),(Positions!$E$6*Positions!$N$6*Stress!$C$8+Positions!$E$6*Positions!$O$6*Stress!$D$8+Positions!$E$6*Positions!$P$6*Stress!$E$8+Positions!$E$6*Positions!$Q$6*Stress!$F$8+Positions!$E$6*Positions!$R$6*Stress!$G$8),(Positions!$E$6*Positions!$N$6*Stress!$C$9+Positions!$E$6*Positions!$O$6*Stress!$D$9+Positions!$E$6*Positions!$P$6*Stress!$E$9+Positions!$E$6*Positions!$Q$6*Stress!$F$9+Positions!$E$6*Positions!$R$6*Stress!$G$9),(Positions!$E$6*Positions!$N$6*Stress!$C$10+Positions!$E$6*Positions!$O$6*Stress!$D$10+Positions!$E$6*Positions!$P$6*Stress!$E$10+Positions!$E$6*Positions!$Q$6*Stress!$F$10+Positions!$E$6*Positions!$R$6*Stress!$G$10)) | H6: =Liquidity!G6 | I6: =ABS(E6)+G6+H6 | J6: =IFERROR(I6/SUM($I$5:$I$16),0)
B7: =Positions!B7 | C7: =ABS(Positions!E7) | D7: ='VaR & ES'!$C$7*SQRT(MAX(0,((Positions!$E$7*Positions!$N$7)*(Positions!$E$7*Positions!$N$7)*Factors!$D$5*Factors!$D$5*Factors!$E$5+(Positions!$E$7*Positions!$N$7)*(Positions!$E$7*Positions!$O$7)*Factors!$D$5*Factors!$D$6*Factors!$F$5+(Positions!$E$7*Positions!$N$7)*(Positions!$E$7*Positions!$P$7)*Factors!$D$5*Factors!$D$7*Factors!$G$5+(Positions!$E$7*Positions!$N$7)*(Positions!$E$7*Positions!$Q$7)*Factors!$D$5*Factors!$D$8*Factors!$H$5+(Positions!$E$7*Positions!$N$7)*(Positions!$E$7*Positions!$R$7)*Factors!$D$5*Factors!$D$9*Factors!$I$5+(Positions!$E$7*Positions!$O$7)*(Positions!$E$7*Positions!$N$7)*Factors!$D$6*Factors!$D$5*Factors!$E$6+(Positions!$E$7*Positions!$O$7)*(Positions!$E$7*Positions!$O$7)*Factors!$D$6*Factors!$D$6*Factors!$F$6+(Positions!$E$7*Positions!$O$7)*(Positions!$E$7*Positions!$P$7)*Factors!$D$6*Factors!$D$7*Factors!$G$6+(Positions!$E$7*Positions!$O$7)*(Positions!$E$7*Positions!$Q$7)*Factors!$D$6*Factors!$D$8*Factors!$H$6+(Positions!$E$7*Positions!$O$7)*(Positions!$E$7*Positions!$R$7)*Factors!$D$6*Factors!$D$9*Factors!$I$6+(Positions!$E$7*Positions!$P$7)*(Positions!$E$7*Positions!$N$7)*Factors!$D$7*Factors!$D$5*Factors!$E$7+(Positions!$E$7*Positions!$P$7)*(Positions!$E$7*Positions!$O$7)*Factors!$D$7*Factors!$D$6*Factors!$F$7+(Positions!$E$7*Positions!$P$7)*(Positions!$E$7*Positions!$P$7)*Factors!$D$7*Factors!$D$7*Factors!$G$7+(Positions!$E$7*Positions!$P$7)*(Positions!$E$7*Positions!$Q$7)*Factors!$D$7*Factors!$D$8*Factors!$H$7+(Positions!$E$7*Positions!$P$7)*(Positions!$E$7*Positions!$R$7)*Factors!$D$7*Factors!$D$9*Factors!$I$7+(Positions!$E$7*Positions!$Q$7)*(Positions!$E$7*Positions!$N$7)*Factors!$D$8*Factors!$D$5*Factors!$E$8+(Positions!$E$7*Positions!$Q$7)*(Positions!$E$7*Positions!$O$7)*Factors!$D$8*Factors!$D$6*Factors!$F$8+(Positions!$E$7*Positions!$Q$7)*(Positions!$E$7*Positions!$P$7)*Factors!$D$8*Factors!$D$7*Factors!$G$8+(Positions!$E$7*Positions!$Q$7)*(Positions!$E$7*Positions!$Q$7)*Factors!$D$8*Factors!$D$8*Factors!$H$8+(Positions!$E$7*Positions!$Q$7)*(Positions!$E$7*Positions!$R$7)*Factors!$D$8*Factors!$D$9*Factors!$I$8+(Positions!$E$7*Positions!$R$7)*(Positions!$E$7*Positions!$N$7)*Factors!$D$9*Factors!$D$5*Factors!$E$9+(Positions!$E$7*Positions!$R$7)*(Positions!$E$7*Positions!$O$7)*Factors!$D$9*Factors!$D$6*Factors!$F$9+(Positions!$E$7*Positions!$R$7)*(Positions!$E$7*Positions!$P$7)*Factors!$D$9*Factors!$D$7*Factors!$G$9+(Positions!$E$7*Positions!$R$7)*(Positions!$E$7*Positions!$Q$7)*Factors!$D$9*Factors!$D$8*Factors!$H$9+(Positions!$E$7*Positions!$R$7)*(Positions!$E$7*Positions!$R$7)*Factors!$D$9*Factors!$D$9*Factors!$I$9)/Assumptions!$E$6)) | E7: =IFERROR('VaR & ES'!$C$7*((Positions!$E$7*Positions!$N$7)*Factors!$D$5*Factors!$C$5*Factors!$D$5*Factors!$E$5+(Positions!$E$7*Positions!$N$7)*Factors!$D$5*Factors!$C$6*Factors!$D$6*Factors!$F$5+(Positions!$E$7*Positions!$N$7)*Factors!$D$5*Factors!$C$7*Factors!$D$7*Factors!$G$5+(Positions!$E$7*Positions!$N$7)*Factors!$D$5*Factors!$C$8*Factors!$D$8*Factors!$H$5+(Positions!$E$7*Positions!$N$7)*Factors!$D$5*Factors!$C$9*Factors!$D$9*Factors!$I$5+(Positions!$E$7*Positions!$O$7)*Factors!$D$6*Factors!$C$5*Factors!$D$5*Factors!$E$6+(Positions!$E$7*Positions!$O$7)*Factors!$D$6*Factors!$C$6*Factors!$D$6*Factors!$F$6+(Positions!$E$7*Positions!$O$7)*Factors!$D$6*Factors!$C$7*Factors!$D$7*Factors!$G$6+(Positions!$E$7*Positions!$O$7)*Factors!$D$6*Factors!$C$8*Factors!$D$8*Factors!$H$6+(Positions!$E$7*Positions!$O$7)*Factors!$D$6*Factors!$C$9*Factors!$D$9*Factors!$I$6+(Positions!$E$7*Positions!$P$7)*Factors!$D$7*Factors!$C$5*Factors!$D$5*Factors!$E$7+(Positions!$E$7*Positions!$P$7)*Factors!$D$7*Factors!$C$6*Factors!$D$6*Factors!$F$7+(Positions!$E$7*Positions!$P$7)*Factors!$D$7*Factors!$C$7*Factors!$D$7*Factors!$G$7+(Positions!$E$7*Positions!$P$7)*Factors!$D$7*Factors!$C$8*Factors!$D$8*Factors!$H$7+(Positions!$E$7*Positions!$P$7)*Factors!$D$7*Factors!$C$9*Factors!$D$9*Factors!$I$7+(Positions!$E$7*Positions!$Q$7)*Factors!$D$8*Factors!$C$5*Factors!$D$5*Factors!$E$8+(Positions!$E$7*Positions!$Q$7)*Factors!$D$8*Factors!$C$6*Factors!$D$6*Factors!$F$8+(Positions!$E$7*Positions!$Q$7)*Factors!$D$8*Factors!$C$7*Factors!$D$7*Factors!$G$8+(Positions!$E$7*Positions!$Q$7)*Factors!$D$8*Factors!$C$8*Factors!$D$8*Factors!$H$8+(Positions!$E$7*Positions!$Q$7)*Factors!$D$8*Factors!$C$9*Factors!$D$9*Factors!$I$8+(Positions!$E$7*Positions!$R$7)*Factors!$D$9*Factors!$C$5*Factors!$D$5*Factors!$E$9+(Positions!$E$7*Positions!$R$7)*Factors!$D$9*Factors!$C$6*Factors!$D$6*Factors!$F$9+(Positions!$E$7*Positions!$R$7)*Factors!$D$9*Factors!$C$7*Factors!$D$7*Factors!$G$9+(Positions!$E$7*Positions!$R$7)*Factors!$D$9*Factors!$C$8*Factors!$D$8*Factors!$H$9+(Positions!$E$7*Positions!$R$7)*Factors!$D$9*Factors!$C$9*Factors!$D$9*Factors!$I$9)/(Factors!$C$13*SQRT(Assumptions!$E$6)),0) | F7: =IFERROR(E7/'VaR & ES'!$C$8,0) | G7: =-MIN((Positions!$E$7*Positions!$N$7*Stress!$C$5+Positions!$E$7*Positions!$O$7*Stress!$D$5+Positions!$E$7*Positions!$P$7*Stress!$E$5+Positions!$E$7*Positions!$Q$7*Stress!$F$5+Positions!$E$7*Positions!$R$7*Stress!$G$5),(Positions!$E$7*Positions!$N$7*Stress!$C$6+Positions!$E$7*Positions!$O$7*Stress!$D$6+Positions!$E$7*Positions!$P$7*Stress!$E$6+Positions!$E$7*Positions!$Q$7*Stress!$F$6+Positions!$E$7*Positions!$R$7*Stress!$G$6),(Positions!$E$7*Positions!$N$7*Stress!$C$7+Positions!$E$7*Positions!$O$7*Stress!$D$7+Positions!$E$7*Positions!$P$7*Stress!$E$7+Positions!$E$7*Positions!$Q$7*Stress!$F$7+Positions!$E$7*Positions!$R$7*Stress!$G$7),(Positions!$E$7*Positions!$N$7*Stress!$C$8+Positions!$E$7*Positions!$O$7*Stress!$D$8+Positions!$E$7*Positions!$P$7*Stress!$E$8+Positions!$E$7*Positions!$Q$7*Stress!$F$8+Positions!$E$7*Positions!$R$7*Stress!$G$8),(Positions!$E$7*Positions!$N$7*Stress!$C$9+Positions!$E$7*Positions!$O$7*Stress!$D$9+Positions!$E$7*Positions!$P$7*Stress!$E$9+Positions!$E$7*Positions!$Q$7*Stress!$F$9+Positions!$E$7*Positions!$R$7*Stress!$G$9),(Positions!$E$7*Positions!$N$7*Stress!$C$10+Positions!$E$7*Positions!$O$7*Stress!$D$10+Positions!$E$7*Positions!$P$7*Stress!$E$10+Positions!$E$7*Positions!$Q$7*Stress!$F$10+Positions!$E$7*Positions!$R$7*Stress!$G$10)) | H7: =Liquidity!G7 | I7: =ABS(E7)+G7+H7 | J7: =IFERROR(I7/SUM($I$5:$I$16),0)
B8: =Positions!B8 | C8: =ABS(Positions!E8) | D8: ='VaR & ES'!$C$7*SQRT(MAX(0,((Positions!$E$8*Positions!$N$8)*(Positions!$E$8*Positions!$N$8)*Factors!$D$5*Factors!$D$5*Factors!$E$5+(Positions!$E$8*Positions!$N$8)*(Positions!$E$8*Positions!$O$8)*Factors!$D$5*Factors!$D$6*Factors!$F$5+(Positions!$E$8*Positions!$N$8)*(Positions!$E$8*Positions!$P$8)*Factors!$D$5*Factors!$D$7*Factors!$G$5+(Positions!$E$8*Positions!$N$8)*(Positions!$E$8*Positions!$Q$8)*Factors!$D$5*Factors!$D$8*Factors!$H$5+(Positions!$E$8*Positions!$N$8)*(Positions!$E$8*Positions!$R$8)*Factors!$D$5*Factors!$D$9*Factors!$I$5+(Positions!$E$8*Positions!$O$8)*(Positions!$E$8*Positions!$N$8)*Factors!$D$6*Factors!$D$5*Factors!$E$6+(Positions!$E$8*Positions!$O$8)*(Positions!$E$8*Positions!$O$8)*Factors!$D$6*Factors!$D$6*Factors!$F$6+(Positions!$E$8*Positions!$O$8)*(Positions!$E$8*Positions!$P$8)*Factors!$D$6*Factors!$D$7*Factors!$G$6+(Positions!$E$8*Positions!$O$8)*(Positions!$E$8*Positions!$Q$8)*Factors!$D$6*Factors!$D$8*Factors!$H$6+(Positions!$E$8*Positions!$O$8)*(Positions!$E$8*Positions!$R$8)*Factors!$D$6*Factors!$D$9*Factors!$I$6+(Positions!$E$8*Positions!$P$8)*(Positions!$E$8*Positions!$N$8)*Factors!$D$7*Factors!$D$5*Factors!$E$7+(Positions!$E$8*Positions!$P$8)*(Positions!$E$8*Positions!$O$8)*Factors!$D$7*Factors!$D$6*Factors!$F$7+(Positions!$E$8*Positions!$P$8)*(Positions!$E$8*Positions!$P$8)*Factors!$D$7*Factors!$D$7*Factors!$G$7+(Positions!$E$8*Positions!$P$8)*(Positions!$E$8*Positions!$Q$8)*Factors!$D$7*Factors!$D$8*Factors!$H$7+(Positions!$E$8*Positions!$P$8)*(Positions!$E$8*Positions!$R$8)*Factors!$D$7*Factors!$D$9*Factors!$I$7+(Positions!$E$8*Positions!$Q$8)*(Positions!$E$8*Positions!$N$8)*Factors!$D$8*Factors!$D$5*Factors!$E$8+(Positions!$E$8*Positions!$Q$8)*(Positions!$E$8*Positions!$O$8)*Factors!$D$8*Factors!$D$6*Factors!$F$8+(Positions!$E$8*Positions!$Q$8)*(Positions!$E$8*Positions!$P$8)*Factors!$D$8*Factors!$D$7*Factors!$G$8+(Positions!$E$8*Positions!$Q$8)*(Positions!$E$8*Positions!$Q$8)*Factors!$D$8*Factors!$D$8*Factors!$H$8+(Positions!$E$8*Positions!$Q$8)*(Positions!$E$8*Positions!$R$8)*Factors!$D$8*Factors!$D$9*Factors!$I$8+(Positions!$E$8*Positions!$R$8)*(Positions!$E$8*Positions!$N$8)*Factors!$D$9*Factors!$D$5*Factors!$E$9+(Positions!$E$8*Positions!$R$8)*(Positions!$E$8*Positions!$O$8)*Factors!$D$9*Factors!$D$6*Factors!$F$9+(Positions!$E$8*Positions!$R$8)*(Positions!$E$8*Positions!$P$8)*Factors!$D$9*Factors!$D$7*Factors!$G$9+(Positions!$E$8*Positions!$R$8)*(Positions!$E$8*Positions!$Q$8)*Factors!$D$9*Factors!$D$8*Factors!$H$9+(Positions!$E$8*Positions!$R$8)*(Positions!$E$8*Positions!$R$8)*Factors!$D$9*Factors!$D$9*Factors!$I$9)/Assumptions!$E$6)) | E8: =IFERROR('VaR & ES'!$C$7*((Positions!$E$8*Positions!$N$8)*Factors!$D$5*Factors!$C$5*Factors!$D$5*Factors!$E$5+(Positions!$E$8*Positions!$N$8)*Factors!$D$5*Factors!$C$6*Factors!$D$6*Factors!$F$5+(Positions!$E$8*Positions!$N$8)*Factors!$D$5*Factors!$C$7*Factors!$D$7*Factors!$G$5+(Positions!$E$8*Positions!$N$8)*Factors!$D$5*Factors!$C$8*Factors!$D$8*Factors!$H$5+(Positions!$E$8*Positions!$N$8)*Factors!$D$5*Factors!$C$9*Factors!$D$9*Factors!$I$5+(Positions!$E$8*Positions!$O$8)*Factors!$D$6*Factors!$C$5*Factors!$D$5*Factors!$E$6+(Positions!$E$8*Positions!$O$8)*Factors!$D$6*Factors!$C$6*Factors!$D$6*Factors!$F$6+(Positions!$E$8*Positions!$O$8)*Factors!$D$6*Factors!$C$7*Factors!$D$7*Factors!$G$6+(Positions!$E$8*Positions!$O$8)*Factors!$D$6*Factors!$C$8*Factors!$D$8*Factors!$H$6+(Positions!$E$8*Positions!$O$8)*Factors!$D$6*Factors!$C$9*Factors!$D$9*Factors!$I$6+(Positions!$E$8*Positions!$P$8)*Factors!$D$7*Factors!$C$5*Factors!$D$5*Factors!$E$7+(Positions!$E$8*Positions!$P$8)*Factors!$D$7*Factors!$C$6*Factors!$D$6*Factors!$F$7+(Positions!$E$8*Positions!$P$8)*Factors!$D$7*Factors!$C$7*Factors!$D$7*Factors!$G$7+(Positions!$E$8*Positions!$P$8)*Factors!$D$7*Factors!$C$8*Factors!$D$8*Factors!$H$7+(Positions!$E$8*Positions!$P$8)*Factors!$D$7*Factors!$C$9*Factors!$D$9*Factors!$I$7+(Positions!$E$8*Positions!$Q$8)*Factors!$D$8*Factors!$C$5*Factors!$D$5*Factors!$E$8+(Positions!$E$8*Positions!$Q$8)*Factors!$D$8*Factors!$C$6*Factors!$D$6*Factors!$F$8+(Positions!$E$8*Positions!$Q$8)*Factors!$D$8*Factors!$C$7*Factors!$D$7*Factors!$G$8+(Positions!$E$8*Positions!$Q$8)*Factors!$D$8*Factors!$C$8*Factors!$D$8*Factors!$H$8+(Positions!$E$8*Positions!$Q$8)*Factors!$D$8*Factors!$C$9*Factors!$D$9*Factors!$I$8+(Positions!$E$8*Positions!$R$8)*Factors!$D$9*Factors!$C$5*Factors!$D$5*Factors!$E$9+(Positions!$E$8*Positions!$R$8)*Factors!$D$9*Factors!$C$6*Factors!$D$6*Factors!$F$9+(Positions!$E$8*Positions!$R$8)*Factors!$D$9*Factors!$C$7*Factors!$D$7*Factors!$G$9+(Positions!$E$8*Positions!$R$8)*Factors!$D$9*Factors!$C$8*Factors!$D$8*Factors!$H$9+(Positions!$E$8*Positions!$R$8)*Factors!$D$9*Factors!$C$9*Factors!$D$9*Factors!$I$9)/(Factors!$C$13*SQRT(Assumptions!$E$6)),0) | F8: =IFERROR(E8/'VaR & ES'!$C$8,0) | G8: =-MIN((Positions!$E$8*Positions!$N$8*Stress!$C$5+Positions!$E$8*Positions!$O$8*Stress!$D$5+Positions!$E$8*Positions!$P$8*Stress!$E$5+Positions!$E$8*Positions!$Q$8*Stress!$F$5+Positions!$E$8*Positions!$R$8*Stress!$G$5),(Positions!$E$8*Positions!$N$8*Stress!$C$6+Positions!$E$8*Positions!$O$8*Stress!$D$6+Positions!$E$8*Positions!$P$8*Stress!$E$6+Positions!$E$8*Positions!$Q$8*Stress!$F$6+Positions!$E$8*Positions!$R$8*Stress!$G$6),(Positions!$E$8*Positions!$N$8*Stress!$C$7+Positions!$E$8*Positions!$O$8*Stress!$D$7+Positions!$E$8*Positions!$P$8*Stress!$E$7+Positions!$E$8*Positions!$Q$8*Stress!$F$7+Positions!$E$8*Positions!$R$8*Stress!$G$7),(Positions!$E$8*Positions!$N$8*Stress!$C$8+Positions!$E$8*Positions!$O$8*Stress!$D$8+Positions!$E$8*Positions!$P$8*Stress!$E$8+Positions!$E$8*Positions!$Q$8*Stress!$F$8+Positions!$E$8*Positions!$R$8*Stress!$G$8),(Positions!$E$8*Positions!$N$8*Stress!$C$9+Positions!$E$8*Positions!$O$8*Stress!$D$9+Positions!$E$8*Positions!$P$8*Stress!$E$9+Positions!$E$8*Positions!$Q$8*Stress!$F$9+Positions!$E$8*Positions!$R$8*Stress!$G$9),(Positions!$E$8*Positions!$N$8*Stress!$C$10+Positions!$E$8*Positions!$O$8*Stress!$D$10+Positions!$E$8*Positions!$P$8*Stress!$E$10+Positions!$E$8*Positions!$Q$8*Stress!$F$10+Positions!$E$8*Positions!$R$8*Stress!$G$10)) | H8: =Liquidity!G8 | I8: =ABS(E8)+G8+H8 | J8: =IFERROR(I8/SUM($I$5:$I$16),0)
B9: =Positions!B9 | C9: =ABS(Positions!E9) | D9: ='VaR & ES'!$C$7*SQRT(MAX(0,((Positions!$E$9*Positions!$N$9)*(Positions!$E$9*Positions!$N$9)*Factors!$D$5*Factors!$D$5*Factors!$E$5+(Positions!$E$9*Positions!$N$9)*(Positions!$E$9*Positions!$O$9)*Factors!$D$5*Factors!$D$6*Factors!$F$5+(Positions!$E$9*Positions!$N$9)*(Positions!$E$9*Positions!$P$9)*Factors!$D$5*Factors!$D$7*Factors!$G$5+(Positions!$E$9*Positions!$N$9)*(Positions!$E$9*Positions!$Q$9)*Factors!$D$5*Factors!$D$8*Factors!$H$5+(Positions!$E$9*Positions!$N$9)*(Positions!$E$9*Positions!$R$9)*Factors!$D$5*Factors!$D$9*Factors!$I$5+(Positions!$E$9*Positions!$O$9)*(Positions!$E$9*Positions!$N$9)*Factors!$D$6*Factors!$D$5*Factors!$E$6+(Positions!$E$9*Positions!$O$9)*(Positions!$E$9*Positions!$O$9)*Factors!$D$6*Factors!$D$6*Factors!$F$6+(Positions!$E$9*Positions!$O$9)*(Positions!$E$9*Positions!$P$9)*Factors!$D$6*Factors!$D$7*Factors!$G$6+(Positions!$E$9*Positions!$O$9)*(Positions!$E$9*Positions!$Q$9)*Factors!$D$6*Factors!$D$8*Factors!$H$6+(Positions!$E$9*Positions!$O$9)*(Positions!$E$9*Positions!$R$9)*Factors!$D$6*Factors!$D$9*Factors!$I$6+(Positions!$E$9*Positions!$P$9)*(Positions!$E$9*Positions!$N$9)*Factors!$D$7*Factors!$D$5*Factors!$E$7+(Positions!$E$9*Positions!$P$9)*(Positions!$E$9*Positions!$O$9)*Factors!$D$7*Factors!$D$6*Factors!$F$7+(Positions!$E$9*Positions!$P$9)*(Positions!$E$9*Positions!$P$9)*Factors!$D$7*Factors!$D$7*Factors!$G$7+(Positions!$E$9*Positions!$P$9)*(Positions!$E$9*Positions!$Q$9)*Factors!$D$7*Factors!$D$8*Factors!$H$7+(Positions!$E$9*Positions!$P$9)*(Positions!$E$9*Positions!$R$9)*Factors!$D$7*Factors!$D$9*Factors!$I$7+(Positions!$E$9*Positions!$Q$9)*(Positions!$E$9*Positions!$N$9)*Factors!$D$8*Factors!$D$5*Factors!$E$8+(Positions!$E$9*Positions!$Q$9)*(Positions!$E$9*Positions!$O$9)*Factors!$D$8*Factors!$D$6*Factors!$F$8+(Positions!$E$9*Positions!$Q$9)*(Positions!$E$9*Positions!$P$9)*Factors!$D$8*Factors!$D$7*Factors!$G$8+(Positions!$E$9*Positions!$Q$9)*(Positions!$E$9*Positions!$Q$9)*Factors!$D$8*Factors!$D$8*Factors!$H$8+(Positions!$E$9*Positions!$Q$9)*(Positions!$E$9*Positions!$R$9)*Factors!$D$8*Factors!$D$9*Factors!$I$8+(Positions!$E$9*Positions!$R$9)*(Positions!$E$9*Positions!$N$9)*Factors!$D$9*Factors!$D$5*Factors!$E$9+(Positions!$E$9*Positions!$R$9)*(Positions!$E$9*Positions!$O$9)*Factors!$D$9*Factors!$D$6*Factors!$F$9+(Positions!$E$9*Positions!$R$9)*(Positions!$E$9*Positions!$P$9)*Factors!$D$9*Factors!$D$7*Factors!$G$9+(Positions!$E$9*Positions!$R$9)*(Positions!$E$9*Positions!$Q$9)*Factors!$D$9*Factors!$D$8*Factors!$H$9+(Positions!$E$9*Positions!$R$9)*(Positions!$E$9*Positions!$R$9)*Factors!$D$9*Factors!$D$9*Factors!$I$9)/Assumptions!$E$6)) | E9: =IFERROR('VaR & ES'!$C$7*((Positions!$E$9*Positions!$N$9)*Factors!$D$5*Factors!$C$5*Factors!$D$5*Factors!$E$5+(Positions!$E$9*Positions!$N$9)*Factors!$D$5*Factors!$C$6*Factors!$D$6*Factors!$F$5+(Positions!$E$9*Positions!$N$9)*Factors!$D$5*Factors!$C$7*Factors!$D$7*Factors!$G$5+(Positions!$E$9*Positions!$N$9)*Factors!$D$5*Factors!$C$8*Factors!$D$8*Factors!$H$5+(Positions!$E$9*Positions!$N$9)*Factors!$D$5*Factors!$C$9*Factors!$D$9*Factors!$I$5+(Positions!$E$9*Positions!$O$9)*Factors!$D$6*Factors!$C$5*Factors!$D$5*Factors!$E$6+(Positions!$E$9*Positions!$O$9)*Factors!$D$6*Factors!$C$6*Factors!$D$6*Factors!$F$6+(Positions!$E$9*Positions!$O$9)*Factors!$D$6*Factors!$C$7*Factors!$D$7*Factors!$G$6+(Positions!$E$9*Positions!$O$9)*Factors!$D$6*Factors!$C$8*Factors!$D$8*Factors!$H$6+(Positions!$E$9*Positions!$O$9)*Factors!$D$6*Factors!$C$9*Factors!$D$9*Factors!$I$6+(Positions!$E$9*Positions!$P$9)*Factors!$D$7*Factors!$C$5*Factors!$D$5*Factors!$E$7+(Positions!$E$9*Positions!$P$9)*Factors!$D$7*Factors!$C$6*Factors!$D$6*Factors!$F$7+(Positions!$E$9*Positions!$P$9)*Factors!$D$7*Factors!$C$7*Factors!$D$7*Factors!$G$7+(Positions!$E$9*Positions!$P$9)*Factors!$D$7*Factors!$C$8*Factors!$D$8*Factors!$H$7+(Positions!$E$9*Positions!$P$9)*Factors!$D$7*Factors!$C$9*Factors!$D$9*Factors!$I$7+(Positions!$E$9*Positions!$Q$9)*Factors!$D$8*Factors!$C$5*Factors!$D$5*Factors!$E$8+(Positions!$E$9*Positions!$Q$9)*Factors!$D$8*Factors!$C$6*Factors!$D$6*Factors!$F$8+(Positions!$E$9*Positions!$Q$9)*Factors!$D$8*Factors!$C$7*Factors!$D$7*Factors!$G$8+(Positions!$E$9*Positions!$Q$9)*Factors!$D$8*Factors!$C$8*Factors!$D$8*Factors!$H$8+(Positions!$E$9*Positions!$Q$9)*Factors!$D$8*Factors!$C$9*Factors!$D$9*Factors!$I$8+(Positions!$E$9*Positions!$R$9)*Factors!$D$9*Factors!$C$5*Factors!$D$5*Factors!$E$9+(Positions!$E$9*Positions!$R$9)*Factors!$D$9*Factors!$C$6*Factors!$D$6*Factors!$F$9+(Positions!$E$9*Positions!$R$9)*Factors!$D$9*Factors!$C$7*Factors!$D$7*Factors!$G$9+(Positions!$E$9*Positions!$R$9)*Factors!$D$9*Factors!$C$8*Factors!$D$8*Factors!$H$9+(Positions!$E$9*Positions!$R$9)*Factors!$D$9*Factors!$C$9*Factors!$D$9*Factors!$I$9)/(Factors!$C$13*SQRT(Assumptions!$E$6)),0) | F9: =IFERROR(E9/'VaR & ES'!$C$8,0) | G9: =-MIN((Positions!$E$9*Positions!$N$9*Stress!$C$5+Positions!$E$9*Positions!$O$9*Stress!$D$5+Positions!$E$9*Positions!$P$9*Stress!$E$5+Positions!$E$9*Positions!$Q$9*Stress!$F$5+Positions!$E$9*Positions!$R$9*Stress!$G$5),(Positions!$E$9*Positions!$N$9*Stress!$C$6+Positions!$E$9*Positions!$O$9*Stress!$D$6+Positions!$E$9*Positions!$P$9*Stress!$E$6+Positions!$E$9*Positions!$Q$9*Stress!$F$6+Positions!$E$9*Positions!$R$9*Stress!$G$6),(Positions!$E$9*Positions!$N$9*Stress!$C$7+Positions!$E$9*Positions!$O$9*Stress!$D$7+Positions!$E$9*Positions!$P$9*Stress!$E$7+Positions!$E$9*Positions!$Q$9*Stress!$F$7+Positions!$E$9*Positions!$R$9*Stress!$G$7),(Positions!$E$9*Positions!$N$9*Stress!$C$8+Positions!$E$9*Positions!$O$9*Stress!$D$8+Positions!$E$9*Positions!$P$9*Stress!$E$8+Positions!$E$9*Positions!$Q$9*Stress!$F$8+Positions!$E$9*Positions!$R$9*Stress!$G$8),(Positions!$E$9*Positions!$N$9*Stress!$C$9+Positions!$E$9*Positions!$O$9*Stress!$D$9+Positions!$E$9*Positions!$P$9*Stress!$E$9+Positions!$E$9*Positions!$Q$9*Stress!$F$9+Positions!$E$9*Positions!$R$9*Stress!$G$9),(Positions!$E$9*Positions!$N$9*Stress!$C$10+Positions!$E$9*Positions!$O$9*Stress!$D$10+Positions!$E$9*Positions!$P$9*Stress!$E$10+Positions!$E$9*Positions!$Q$9*Stress!$F$10+Positions!$E$9*Positions!$R$9*Stress!$G$10)) | H9: =Liquidity!G9 | I9: =ABS(E9)+G9+H9 | J9: =IFERROR(I9/SUM($I$5:$I$16),0)
B10: =Positions!B10 | C10: =ABS(Positions!E10) | D10: ='VaR & ES'!$C$7*SQRT(MAX(0,((Positions!$E$10*Positions!$N$10)*(Positions!$E$10*Positions!$N$10)*Factors!$D$5*Factors!$D$5*Factors!$E$5+(Positions!$E$10*Positions!$N$10)*(Positions!$E$10*Positions!$O$10)*Factors!$D$5*Factors!$D$6*Factors!$F$5+(Positions!$E$10*Positions!$N$10)*(Positions!$E$10*Positions!$P$10)*Factors!$D$5*Factors!$D$7*Factors!$G$5+(Positions!$E$10*Positions!$N$10)*(Positions!$E$10*Positions!$Q$10)*Factors!$D$5*Factors!$D$8*Factors!$H$5+(Positions!$E$10*Positions!$N$10)*(Positions!$E$10*Positions!$R$10)*Factors!$D$5*Factors!$D$9*Factors!$I$5+(Positions!$E$10*Positions!$O$10)*(Positions!$E$10*Positions!$N$10)*Factors!$D$6*Factors!$D$5*Factors!$E$6+(Positions!$E$10*Positions!$O$10)*(Positions!$E$10*Positions!$O$10)*Factors!$D$6*Factors!$D$6*Factors!$F$6+(Positions!$E$10*Positions!$O$10)*(Positions!$E$10*Positions!$P$10)*Factors!$D$6*Factors!$D$7*Factors!$G$6+(Positions!$E$10*Positions!$O$10)*(Positions!$E$10*Positions!$Q$10)*Factors!$D$6*Factors!$D$8*Factors!$H$6+(Positions!$E$10*Positions!$O$10)*(Positions!$E$10*Positions!$R$10)*Factors!$D$6*Factors!$D$9*Factors!$I$6+(Positions!$E$10*Positions!$P$10)*(Positions!$E$10*Positions!$N$10)*Factors!$D$7*Factors!$D$5*Factors!$E$7+(Positions!$E$10*Positions!$P$10)*(Positions!$E$10*Positions!$O$10)*Factors!$D$7*Factors!$D$6*Factors!$F$7+(Positions!$E$10*Positions!$P$10)*(Positions!$E$10*Positions!$P$10)*Factors!$D$7*Factors!$D$7*Factors!$G$7+(Positions!$E$10*Positions!$P$10)*(Positions!$E$10*Positions!$Q$10)*Factors!$D$7*Factors!$D$8*Factors!$H$7+(Positions!$E$10*Positions!$P$10)*(Positions!$E$10*Positions!$R$10)*Factors!$D$7*Factors!$D$9*Factors!$I$7+(Positions!$E$10*Positions!$Q$10)*(Positions!$E$10*Positions!$N$10)*Factors!$D$8*Factors!$D$5*Factors!$E$8+(Positions!$E$10*Positions!$Q$10)*(Positions!$E$10*Positions!$O$10)*Factors!$D$8*Factors!$D$6*Factors!$F$8+(Positions!$E$10*Positions!$Q$10)*(Positions!$E$10*Positions!$P$10)*Factors!$D$8*Factors!$D$7*Factors!$G$8+(Positions!$E$10*Positions!$Q$10)*(Positions!$E$10*Positions!$Q$10)*Factors!$D$8*Factors!$D$8*Factors!$H$8+(Positions!$E$10*Positions!$Q$10)*(Positions!$E$10*Positions!$R$10)*Factors!$D$8*Factors!$D$9*Factors!$I$8+(Positions!$E$10*Positions!$R$10)*(Positions!$E$10*Positions!$N$10)*Factors!$D$9*Factors!$D$5*Factors!$E$9+(Positions!$E$10*Positions!$R$10)*(Positions!$E$10*Positions!$O$10)*Factors!$D$9*Factors!$D$6*Factors!$F$9+(Positions!$E$10*Positions!$R$10)*(Positions!$E$10*Positions!$P$10)*Factors!$D$9*Factors!$D$7*Factors!$G$9+(Positions!$E$10*Positions!$R$10)*(Positions!$E$10*Positions!$Q$10)*Factors!$D$9*Factors!$D$8*Factors!$H$9+(Positions!$E$10*Positions!$R$10)*(Positions!$E$10*Positions!$R$10)*Factors!$D$9*Factors!$D$9*Factors!$I$9)/Assumptions!$E$6)) | E10: =IFERROR('VaR & ES'!$C$7*((Positions!$E$10*Positions!$N$10)*Factors!$D$5*Factors!$C$5*Factors!$D$5*Factors!$E$5+(Positions!$E$10*Positions!$N$10)*Factors!$D$5*Factors!$C$6*Factors!$D$6*Factors!$F$5+(Positions!$E$10*Positions!$N$10)*Factors!$D$5*Factors!$C$7*Factors!$D$7*Factors!$G$5+(Positions!$E$10*Positions!$N$10)*Factors!$D$5*Factors!$C$8*Factors!$D$8*Factors!$H$5+(Positions!$E$10*Positions!$N$10)*Factors!$D$5*Factors!$C$9*Factors!$D$9*Factors!$I$5+(Positions!$E$10*Positions!$O$10)*Factors!$D$6*Factors!$C$5*Factors!$D$5*Factors!$E$6+(Positions!$E$10*Positions!$O$10)*Factors!$D$6*Factors!$C$6*Factors!$D$6*Factors!$F$6+(Positions!$E$10*Positions!$O$10)*Factors!$D$6*Factors!$C$7*Factors!$D$7*Factors!$G$6+(Positions!$E$10*Positions!$O$10)*Factors!$D$6*Factors!$C$8*Factors!$D$8*Factors!$H$6+(Positions!$E$10*Positions!$O$10)*Factors!$D$6*Factors!$C$9*Factors!$D$9*Factors!$I$6+(Positions!$E$10*Positions!$P$10)*Factors!$D$7*Factors!$C$5*Factors!$D$5*Factors!$E$7+(Positions!$E$10*Positions!$P$10)*Factors!$D$7*Factors!$C$6*Factors!$D$6*Factors!$F$7+(Positions!$E$10*Positions!$P$10)*Factors!$D$7*Factors!$C$7*Factors!$D$7*Factors!$G$7+(Positions!$E$10*Positions!$P$10)*Factors!$D$7*Factors!$C$8*Factors!$D$8*Factors!$H$7+(Positions!$E$10*Positions!$P$10)*Factors!$D$7*Factors!$C$9*Factors!$D$9*Factors!$I$7+(Positions!$E$10*Positions!$Q$10)*Factors!$D$8*Factors!$C$5*Factors!$D$5*Factors!$E$8+(Positions!$E$10*Positions!$Q$10)*Factors!$D$8*Factors!$C$6*Factors!$D$6*Factors!$F$8+(Positions!$E$10*Positions!$Q$10)*Factors!$D$8*Factors!$C$7*Factors!$D$7*Factors!$G$8+(Positions!$E$10*Positions!$Q$10)*Factors!$D$8*Factors!$C$8*Factors!$D$8*Factors!$H$8+(Positions!$E$10*Positions!$Q$10)*Factors!$D$8*Factors!$C$9*Factors!$D$9*Factors!$I$8+(Positions!$E$10*Positions!$R$10)*Factors!$D$9*Factors!$C$5*Factors!$D$5*Factors!$E$9+(Positions!$E$10*Positions!$R$10)*Factors!$D$9*Factors!$C$6*Factors!$D$6*Factors!$F$9+(Positions!$E$10*Positions!$R$10)*Factors!$D$9*Factors!$C$7*Factors!$D$7*Factors!$G$9+(Positions!$E$10*Positions!$R$10)*Factors!$D$9*Factors!$C$8*Factors!$D$8*Factors!$H$9+(Positions!$E$10*Positions!$R$10)*Factors!$D$9*Factors!$C$9*Factors!$D$9*Factors!$I$9)/(Factors!$C$13*SQRT(Assumptions!$E$6)),0) | F10: =IFERROR(E10/'VaR & ES'!$C$8,0) | G10: =-MIN((Positions!$E$10*Positions!$N$10*Stress!$C$5+Positions!$E$10*Positions!$O$10*Stress!$D$5+Positions!$E$10*Positions!$P$10*Stress!$E$5+Positions!$E$10*Positions!$Q$10*Stress!$F$5+Positions!$E$10*Positions!$R$10*Stress!$G$5),(Positions!$E$10*Positions!$N$10*Stress!$C$6+Positions!$E$10*Positions!$O$10*Stress!$D$6+Positions!$E$10*Positions!$P$10*Stress!$E$6+Positions!$E$10*Positions!$Q$10*Stress!$F$6+Positions!$E$10*Positions!$R$10*Stress!$G$6),(Positions!$E$10*Positions!$N$10*Stress!$C$7+Positions!$E$10*Positions!$O$10*Stress!$D$7+Positions!$E$10*Positions!$P$10*Stress!$E$7+Positions!$E$10*Positions!$Q$10*Stress!$F$7+Positions!$E$10*Positions!$R$10*Stress!$G$7),(Positions!$E$10*Positions!$N$10*Stress!$C$8+Positions!$E$10*Positions!$O$10*Stress!$D$8+Positions!$E$10*Positions!$P$10*Stress!$E$8+Positions!$E$10*Positions!$Q$10*Stress!$F$8+Positions!$E$10*Positions!$R$10*Stress!$G$8),(Positions!$E$10*Positions!$N$10*Stress!$C$9+Positions!$E$10*Positions!$O$10*Stress!$D$9+Positions!$E$10*Positions!$P$10*Stress!$E$9+Positions!$E$10*Positions!$Q$10*Stress!$F$9+Positions!$E$10*Positions!$R$10*Stress!$G$9),(Positions!$E$10*Positions!$N$10*Stress!$C$10+Positions!$E$10*Positions!$O$10*Stress!$D$10+Positions!$E$10*Positions!$P$10*Stress!$E$10+Positions!$E$10*Positions!$Q$10*Stress!$F$10+Positions!$E$10*Positions!$R$10*Stress!$G$10)) | H10: =Liquidity!G10 | I10: =ABS(E10)+G10+H10 | J10: =IFERROR(I10/SUM($I$5:$I$16),0)
B11: =Positions!B11 | C11: =ABS(Positions!E11) | D11: ='VaR & ES'!$C$7*SQRT(MAX(0,((Positions!$E$11*Positions!$N$11)*(Positions!$E$11*Positions!$N$11)*Factors!$D$5*Factors!$D$5*Factors!$E$5+(Positions!$E$11*Positions!$N$11)*(Positions!$E$11*Positions!$O$11)*Factors!$D$5*Factors!$D$6*Factors!$F$5+(Positions!$E$11*Positions!$N$11)*(Positions!$E$11*Positions!$P$11)*Factors!$D$5*Factors!$D$7*Factors!$G$5+(Positions!$E$11*Positions!$N$11)*(Positions!$E$11*Positions!$Q$11)*Factors!$D$5*Factors!$D$8*Factors!$H$5+(Positions!$E$11*Positions!$N$11)*(Positions!$E$11*Positions!$R$11)*Factors!$D$5*Factors!$D$9*Factors!$I$5+(Positions!$E$11*Positions!$O$11)*(Positions!$E$11*Positions!$N$11)*Factors!$D$6*Factors!$D$5*Factors!$E$6+(Positions!$E$11*Positions!$O$11)*(Positions!$E$11*Positions!$O$11)*Factors!$D$6*Factors!$D$6*Factors!$F$6+(Positions!$E$11*Positions!$O$11)*(Positions!$E$11*Positions!$P$11)*Factors!$D$6*Factors!$D$7*Factors!$G$6+(Positions!$E$11*Positions!$O$11)*(Positions!$E$11*Positions!$Q$11)*Factors!$D$6*Factors!$D$8*Factors!$H$6+(Positions!$E$11*Positions!$O$11)*(Positions!$E$11*Positions!$R$11)*Factors!$D$6*Factors!$D$9*Factors!$I$6+(Positions!$E$11*Positions!$P$11)*(Positions!$E$11*Positions!$N$11)*Factors!$D$7*Factors!$D$5*Factors!$E$7+(Positions!$E$11*Positions!$P$11)*(Positions!$E$11*Positions!$O$11)*Factors!$D$7*Factors!$D$6*Factors!$F$7+(Positions!$E$11*Positions!$P$11)*(Positions!$E$11*Positions!$P$11)*Factors!$D$7*Factors!$D$7*Factors!$G$7+(Positions!$E$11*Positions!$P$11)*(Positions!$E$11*Positions!$Q$11)*Factors!$D$7*Factors!$D$8*Factors!$H$7+(Positions!$E$11*Positions!$P$11)*(Positions!$E$11*Positions!$R$11)*Factors!$D$7*Factors!$D$9*Factors!$I$7+(Positions!$E$11*Positions!$Q$11)*(Positions!$E$11*Positions!$N$11)*Factors!$D$8*Factors!$D$5*Factors!$E$8+(Positions!$E$11*Positions!$Q$11)*(Positions!$E$11*Positions!$O$11)*Factors!$D$8*Factors!$D$6*Factors!$F$8+(Positions!$E$11*Positions!$Q$11)*(Positions!$E$11*Positions!$P$11)*Factors!$D$8*Factors!$D$7*Factors!$G$8+(Positions!$E$11*Positions!$Q$11)*(Positions!$E$11*Positions!$Q$11)*Factors!$D$8*Factors!$D$8*Factors!$H$8+(Positions!$E$11*Positions!$Q$11)*(Positions!$E$11*Positions!$R$11)*Factors!$D$8*Factors!$D$9*Factors!$I$8+(Positions!$E$11*Positions!$R$11)*(Positions!$E$11*Positions!$N$11)*Factors!$D$9*Factors!$D$5*Factors!$E$9+(Positions!$E$11*Positions!$R$11)*(Positions!$E$11*Positions!$O$11)*Factors!$D$9*Factors!$D$6*Factors!$F$9+(Positions!$E$11*Positions!$R$11)*(Positions!$E$11*Positions!$P$11)*Factors!$D$9*Factors!$D$7*Factors!$G$9+(Positions!$E$11*Positions!$R$11)*(Positions!$E$11*Positions!$Q$11)*Factors!$D$9*Factors!$D$8*Factors!$H$9+(Positions!$E$11*Positions!$R$11)*(Positions!$E$11*Positions!$R$11)*Factors!$D$9*Factors!$D$9*Factors!$I$9)/Assumptions!$E$6)) | E11: =IFERROR('VaR & ES'!$C$7*((Positions!$E$11*Positions!$N$11)*Factors!$D$5*Factors!$C$5*Factors!$D$5*Factors!$E$5+(Positions!$E$11*Positions!$N$11)*Factors!$D$5*Factors!$C$6*Factors!$D$6*Factors!$F$5+(Positions!$E$11*Positions!$N$11)*Factors!$D$5*Factors!$C$7*Factors!$D$7*Factors!$G$5+(Positions!$E$11*Positions!$N$11)*Factors!$D$5*Factors!$C$8*Factors!$D$8*Factors!$H$5+(Positions!$E$11*Positions!$N$11)*Factors!$D$5*Factors!$C$9*Factors!$D$9*Factors!$I$5+(Positions!$E$11*Positions!$O$11)*Factors!$D$6*Factors!$C$5*Factors!$D$5*Factors!$E$6+(Positions!$E$11*Positions!$O$11)*Factors!$D$6*Factors!$C$6*Factors!$D$6*Factors!$F$6+(Positions!$E$11*Positions!$O$11)*Factors!$D$6*Factors!$C$7*Factors!$D$7*Factors!$G$6+(Positions!$E$11*Positions!$O$11)*Factors!$D$6*Factors!$C$8*Factors!$D$8*Factors!$H$6+(Positions!$E$11*Positions!$O$11)*Factors!$D$6*Factors!$C$9*Factors!$D$9*Factors!$I$6+(Positions!$E$11*Positions!$P$11)*Factors!$D$7*Factors!$C$5*Factors!$D$5*Factors!$E$7+(Positions!$E$11*Positions!$P$11)*Factors!$D$7*Factors!$C$6*Factors!$D$6*Factors!$F$7+(Positions!$E$11*Positions!$P$11)*Factors!$D$7*Factors!$C$7*Factors!$D$7*Factors!$G$7+(Positions!$E$11*Positions!$P$11)*Factors!$D$7*Factors!$C$8*Factors!$D$8*Factors!$H$7+(Positions!$E$11*Positions!$P$11)*Factors!$D$7*Factors!$C$9*Factors!$D$9*Factors!$I$7+(Positions!$E$11*Positions!$Q$11)*Factors!$D$8*Factors!$C$5*Factors!$D$5*Factors!$E$8+(Positions!$E$11*Positions!$Q$11)*Factors!$D$8*Factors!$C$6*Factors!$D$6*Factors!$F$8+(Positions!$E$11*Positions!$Q$11)*Factors!$D$8*Factors!$C$7*Factors!$D$7*Factors!$G$8+(Positions!$E$11*Positions!$Q$11)*Factors!$D$8*Factors!$C$8*Factors!$D$8*Factors!$H$8+(Positions!$E$11*Positions!$Q$11)*Factors!$D$8*Factors!$C$9*Factors!$D$9*Factors!$I$8+(Positions!$E$11*Positions!$R$11)*Factors!$D$9*Factors!$C$5*Factors!$D$5*Factors!$E$9+(Positions!$E$11*Positions!$R$11)*Factors!$D$9*Factors!$C$6*Factors!$D$6*Factors!$F$9+(Positions!$E$11*Positions!$R$11)*Factors!$D$9*Factors!$C$7*Factors!$D$7*Factors!$G$9+(Positions!$E$11*Positions!$R$11)*Factors!$D$9*Factors!$C$8*Factors!$D$8*Factors!$H$9+(Positions!$E$11*Positions!$R$11)*Factors!$D$9*Factors!$C$9*Factors!$D$9*Factors!$I$9)/(Factors!$C$13*SQRT(Assumptions!$E$6)),0) | F11: =IFERROR(E11/'VaR & ES'!$C$8,0) | G11: =-MIN((Positions!$E$11*Positions!$N$11*Stress!$C$5+Positions!$E$11*Positions!$O$11*Stress!$D$5+Positions!$E$11*Positions!$P$11*Stress!$E$5+Positions!$E$11*Positions!$Q$11*Stress!$F$5+Positions!$E$11*Positions!$R$11*Stress!$G$5),(Positions!$E$11*Positions!$N$11*Stress!$C$6+Positions!$E$11*Positions!$O$11*Stress!$D$6+Positions!$E$11*Positions!$P$11*Stress!$E$6+Positions!$E$11*Positions!$Q$11*Stress!$F$6+Positions!$E$11*Positions!$R$11*Stress!$G$6),(Positions!$E$11*Positions!$N$11*Stress!$C$7+Positions!$E$11*Positions!$O$11*Stress!$D$7+Positions!$E$11*Positions!$P$11*Stress!$E$7+Positions!$E$11*Positions!$Q$11*Stress!$F$7+Positions!$E$11*Positions!$R$11*Stress!$G$7),(Positions!$E$11*Positions!$N$11*Stress!$C$8+Positions!$E$11*Positions!$O$11*Stress!$D$8+Positions!$E$11*Positions!$P$11*Stress!$E$8+Positions!$E$11*Positions!$Q$11*Stress!$F$8+Positions!$E$11*Positions!$R$11*Stress!$G$8),(Positions!$E$11*Positions!$N$11*Stress!$C$9+Positions!$E$11*Positions!$O$11*Stress!$D$9+Positions!$E$11*Positions!$P$11*Stress!$E$9+Positions!$E$11*Positions!$Q$11*Stress!$F$9+Positions!$E$11*Positions!$R$11*Stress!$G$9),(Positions!$E$11*Positions!$N$11*Stress!$C$10+Positions!$E$11*Positions!$O$11*Stress!$D$10+Positions!$E$11*Positions!$P$11*Stress!$E$10+Positions!$E$11*Positions!$Q$11*Stress!$F$10+Positions!$E$11*Positions!$R$11*Stress!$G$10)) | H11: =Liquidity!G11 | I11: =ABS(E11)+G11+H11 | J11: =IFERROR(I11/SUM($I$5:$I$16),0)
