Workbook
Name FS_MODEL_ID: 'Institutional Surface'!$C$4
Name FS_DOMAIN: 'Institutional Surface'!$C$5
Name FS_MATURITY: 'Institutional Surface'!$C$6

Sheet Cover
B2: [COUNTERPARTY] — Trade Finance Model
B4: Counterparty: | C4: [fill in]
B5: Trade corridor: | C5: [e.g. exporter-importer country pair]
B6: Last refreshed: | C6: [date]
B7: Refresh cadence: | C7: Weekly

Sheet Institutional Surface
B2: Trade Finance — Institutional Decision Surface
B4: Model ID | C4: 10
B5: Domain | C5: Trade Finance
B6: Declared maturity | C6: M2
B7: Canonical builder | C7: tools/builders/build_trade_finance_release.py
B8: Decision arena | C8: trade desk, credit, operations, sanctions and country-risk committee
B9: Committee artifact | C9: transaction approval and exception pack
B10: Operating cadence | C10: daily transaction monitoring; weekly exceptions
B12: Key decision outputs
B13: # | C13: Requirement | D13: Owner | E13: Evidence / location | F13: Status
B14: 1 | C14: self-liquidating cash cycle | F14: OPEN
B15: 2 | C15: facility utilization and borrowing base | F15: OPEN
B16: 3 | C16: LC / guarantee cost | F16: OPEN
B17: 4 | C17: base, downside and break-even outputs | F17: OPEN
B18: 5 | C18: liquidity / funding requirement and binding constraint | F18: OPEN
B20: Insider questions
B21: # | C21: Requirement | D21: Owner | E21: Evidence / location | F21: Status
B22: 1 | C22: Who controls title at each stage? | F22: OPEN
B23: 2 | C23: What document discrepancy prevents payment? | F23: OPEN
B24: 3 | C24: Which bank and country risks are correlated? | F24: OPEN
B25: 4 | C25: Which assumption is owner-approved versus modeler judgement? | F25: OPEN
B26: 5 | C26: What fails first and who must act? | F26: OPEN
B28: Scenario families
B29: # | C29: Requirement | D29: Owner | E29: Evidence / location | F29: Status
B30: 1 | C30: shipment delay | F30: OPEN
B31: 2 | C31: document discrepancy | F31: OPEN
B32: 3 | C32: buyer default | F32: OPEN
B33: 4 | C33: data freshness / source failure | F33: OPEN
B34: 5 | C34: combined severe-but-plausible downside | F34: OPEN
B36: Primary diligence documents
B37: # | C37: Requirement | D37: Owner | E37: Evidence / location | F37: Status
B38: 1 | C38: commercial invoice and purchase order | F38: OPEN
B39: 2 | C39: bill of lading / warehouse receipt | F39: OPEN
B40: 3 | C40: letter of credit or guarantee | F40: OPEN
B41: 4 | C41: approved model card and assumption register | F41: OPEN
B42: 5 | C42: independent validation and challenge record | F42: OPEN
B44: Challenge tests
B45: # | C45: Requirement | D45: Owner | E45: Evidence / location | F45: Status
B46: 1 | C46: cash conversion closes | F46: OPEN
B47: 2 | C47: exposure follows goods and documents | F47: OPEN
...

Sheet Challenge Log
B2: Independent Challenge, Override and Closure Log
B4: Date | C4: Reviewer | D4: Challenge | E4: Owner response | F4: Evidence | G4: Impact | H4: Status | I4: Closure
D5: cash conversion closes | H5: OPEN
D6: exposure follows goods and documents | H6: OPEN
D7: fees reflect tenor and utilization | H7: OPEN
D8: source-to-model lineage is reproducible | H8: OPEN
D9: units, signs, dates and legal definitions reconcile | H9: OPEN

Sheet Lineage Map
B2: Source, Transformation, Ownership and Refresh Map
B4: Source class | C4: Cadence | D4: Control | E4: System / provider | F4: As-of | G4: Owner | H4: Transform | I4: Downstream | J4: Status
B5: shipment events | C5: event-driven | D5: document and logistics match | J5: TO MAP
B6: facility usage | C6: daily | D6: transaction-level utilization | J6: TO MAP
B7: model governance evidence | C7: per release | D7: version, reviewer, sign-off and change log | J7: TO MAP
B8: decision-use snapshot | C8: per decision | D8: immutable as-of date and source receipt | J8: TO MAP

Sheet Working Capital Cycle
B2: Cash Conversion Cycle
B4: Inputs
B5: Revenue ($, annual) | C5: 0
B6: COGS ($, annual) | C6: 0
B7: Average accounts receivable ($) | C7: 0
B8: Average inventory ($) | C8: 0
B9: Average accounts payable ($) | C9: 0
B11: Outputs
B12: DSO (Days Sales Outstanding) | C12: =IFERROR(C7/C5*365,"-")
B13: DIO (Days Inventory Outstanding) | C13: =IFERROR(C8/C6*365,"-")
B14: DPO (Days Payable Outstanding) | C14: =IFERROR(C9/C6*365,"-")
B15: Cash Conversion Cycle (DSO+DIO-DPO) | C15: =IFERROR(C12+C13-C14,"-") | D15: Days cash tied up per cycle — lower/negative is better (supplier financing your growth)
B16: Working capital required ($, approx.) | C16: =IFERROR(C15/365*C6,"-")

Sheet Credit & Facility
B2: Counterparty Credit, Country Risk, and Facility Utilization
B3: Active scenario | C3: Base
B4: Metric | C4: Base | D4: Downside | E4: Active | F4: Owner / interpretation
B5: Facility limit | C5: 100 | D5: 100 | E5: =IF($C$3="Downside",D5,C5) | F5: approved committed amount
B6: Drawn amount | C6: 60 | D6: 120 | E6: =IF($C$3="Downside",D6,C6) | F6: current and stress utilization
B7: Exposure at default | C7: 60 | D7: 120 | E7: =IF($C$3="Downside",D7,C7) | F7: drawn plus applicable contingent exposure
B8: Probability of default | C8: 0.02 | D8: 0.2 | E8: =IF($C$3="Downside",D8,C8) | F8: point-in-time or approved stress PD
B9: Loss given default | C9: 0.4 | D9: 0.7 | E9: =IF($C$3="Downside",D9,C9) | F9: net of collateral and recoveries
B10: Gross transaction margin | C10: 8 | D10: 10 | E10: =IF($C$3="Downside",D10,C10) | F10: before credit and country risk
B11: Country / transfer-risk cost | C11: 0.5 | D11: 5 | E11: =IF($C$3="Downside",D11,C11) | F11: approved economic charge
B12: Maximum utilization | C12: 0.9 | D12: 0.9 | E12: =IF($C$3="Downside",D12,C12) | F12: warning threshold
B13: Maximum cash-conversion days | C13: 120 | D13: 120 | E13: =IF($C$3="Downside",D13,C13) | F13: working-capital warning threshold
B16: Derived outputs
B17: Facility utilization | E17: =IFERROR(E6/E5,0)
B18: Expected loss | E18: =E7*E8*E9
B19: Risk-adjusted margin | E19: =E10-E18-E11
B20: Cash conversion days | E20: ='Working Capital Cycle'!C15
B21: Approximate working capital need | E21: ='Working Capital Cycle'!C16

Sheet LC & Factoring Cost
B2: Letter of Credit & Factoring Cost Model
B4: Letter of Credit
B5: LC face value ($) | C5: 0
B6: Issuance fee % | C6: 0.015
B7: Confirmation fee % | C7: 0.01
B8: Tenor (days) | C8: 90
B9: Total LC cost ($) | C9: =C5*(C6+C7)*(C8/365)
B10: Annualized LC cost % | C10: =IFERROR(C9/C5/(C8/365),"-")
B13: Factoring / Invoice Discounting
B14: Invoice face value ($) | C14: 0
B15: Advance rate % | C15: 0.85
B16: Discount/factor fee % | C16: 0.02
B17: Days to collection | C17: 60
B18: Cash advanced immediately ($) | C18: =C14*C15
B19: Factoring fee ($) | C19: =C14*C16
B20: Net proceeds after collection ($) | C20: =C14-C19
B21: Effective annualized cost of factoring % | C21: =IFERROR(C19/C20*365/C17,"-") | D21: Effective cost uses the fee divided by net proceeds and annualizes by the collection period.

Sheet Documentary Controls
B2: Documentary Credit Examination and Exception Register
B4: Control | C4: Input / metric | D4: Status | E4: Evidence / action
B5: Days from shipment to presentation | C5: 10 | D5: =IF(C5<=21,"PASS","REVIEW") | E5: compare against credit terms and applicable presentation period
B6: Document discrepancies identified | C6: 0 | D6: =IF(C6=0,"PASS","REVIEW") | E6: retain discrepancy list, waiver, refusal, or cure evidence
B7: Sanctions / restricted-party screening complete | C7: 1 | D7: =IF(C7=1,"PASS","BREACH") | E7: 1=yes; evidence must be dated and corridor-specific
B8: Transport / title document matched | C8: 1 | D8: =IF(C8=1,"PASS","BREACH") | E8: 1=yes; verify issuer, consignee, dates, quantity, and goods description
B9: Insurance document matched where required | C9: 1 | D9: =IF(C9=1,"PASS","REVIEW") | E9: 1=yes; review insured amount, risks, currency, and date
B10: Refusal / discrepancy notice within required period | C10: 1 | D10: =IF(C10=1,"PASS","BREACH") | E10: 1=yes; retain timestamp and complete discrepancy statement
B11: Counterparty waiver documented | C11: 1 | D11: =IF(OR(C6=0,C11=1),"PASS","BREACH") | E11: 1=yes when discrepant documents are accepted
B12: Original documents / electronic presentation controlled | C12: 1 | D12: =IF(C12=1,"PASS","BREACH") | E12: 1=yes; preserve authenticity, version, and presentation evidence
B14: This register operationalizes documentary review but is not a substitute for legal advice or the controlling credit text.

Sheet Decision & Checks
B2: Trade Finance Decision Dashboard and Independent Checks
B4: Check / decision | C4: Metric | D4: Status | E4: Interpretation / action
B5: Cash-conversion identity residual | C5: =IF(AND(ISNUMBER('Working Capital Cycle'!C15),ISNUMBER('Working Capital Cycle'!C12),ISNUMBER('Working Capital Cycle'!C13),ISNUMBER('Working Capital Cycle'!C14)),'Working Capital Cycle'!C15-('Working Capital Cycle'!C12+'Working Capital Cycle'!C13-'Working Capital Cycle'!C14),0) | D5: =IF(AND(ISNUMBER('Working Capital Cycle'!C15),ISNUMBER('Working Capital Cycle'!C12),ISNUMBER('Working Capital Cycle'!C13),ISNUMBER('Working Capital Cycle'!C14)),IF(ABS(C5)<0.000001,"PASS","FAIL"),"REVIEW") | E5: DSO plus DIO less DPO must equal the reported cash-conversion cycle.
B6: Facility utilization | C6: ='Credit & Facility'!E17 | D6: =IF(C6<='Credit & Facility'!E12,"PASS",IF(C6<=1,"REVIEW","BREACH")) | E6: Escalate excess utilization and contingent-exposure conversion.
B7: Expected loss residual | C7: ='Credit & Facility'!E18-'Credit & Facility'!E7*'Credit & Facility'!E8*'Credit & Facility'!E9 | D7: =IF(ABS(C7)<0.000001,"PASS","FAIL") | E7: Expected loss must equal EAD multiplied by PD and LGD.
B8: Risk-adjusted margin | C8: ='Credit & Facility'!E19 | D8: =IF(C8>=0,"PASS","BREACH") | E8: A transaction that loses money after credit and country risk should not be approved on nominal margin.
B9: Cash-conversion days | C9: ='Credit & Facility'!E20 | D9: =IF(NOT(ISNUMBER(C9)),"REVIEW",IF(C9<='Credit & Facility'!E13,"PASS","REVIEW")) | E9: Longer cycles increase funding and performance risk.
B10: Annualized LC cost | C10: ='LC & Factoring Cost'!C10 | D10: =IF(ISNUMBER(C10),"PASS","REVIEW") | E10: Confirm tenor, issuance, confirmation, amendment, and discrepancy fees.
B11: Effective factoring APR | C11: ='LC & Factoring Cost'!C21 | D11: =IF(ISNUMBER(C11),"PASS","REVIEW") | E11: Compare fee to net proceeds and actual collection period.
B12: Documentary-control exceptions | C12: =COUNTIF('Documentary Controls'!D5:D12,"<>PASS") | D12: =IF(C12=0,"PASS","REVIEW") | E12: No financing-cost comparison overrides unresolved documentary or sanctions controls.
B14: Overall model status | C14: =IF(COUNTIF(D5:D12,"FAIL")+COUNTIF(D5:D12,"BREACH")>0,"BREACH",IF(COUNTIF(D5:D12,"REVIEW")>0,"REVIEW","PASS"))
B16: Primary decision outputs
B17: Cash conversion days | C17: ='Working Capital Cycle'!C15
B18: Working capital required | C18: ='Working Capital Cycle'!C16
B19: Facility utilization | C19: ='Credit & Facility'!E17
B20: Expected loss | C20: ='Credit & Facility'!E18
B21: Risk-adjusted margin | C21: ='Credit & Facility'!E19
B22: Cheapest financing channel | C22: ='Financing Cost Comparison'!C19
B23: Cheapest annualized cost | C23: ='Financing Cost Comparison'!C20

Sheet Financing Cost Comparison
B2: Which Financing Channel Is Cheapest?
B4: Revolving credit line (alternative)
B5: Draw amount ($) | C5: 0
B6: Base rate + spread, all-in (%) | C6: 0.08
B7: Commitment fee on undrawn (%) | C7: 0.005
B8: Undrawn facility amount ($) | C8: 0
B9: Revolver interest cost ($) | C9: =C5*C6
B10: Revolver commitment fee ($) | C10: =C7*C8
B11: Revolver annualized all-in cost % | C11: =IFERROR((C9+C10)/C5,"-")
B13: Comparison
B14: Channel | C14: Annualized cost %
B15: Letter of credit | C15: ='LC & Factoring Cost'!C10
B16: Factoring / invoice discounting | C16: ='LC & Factoring Cost'!C21
B17: Revolving credit line | C17: =C11
B19: Cheapest channel | C19: =IF(COUNT(C15:C17)<3,"-",INDEX(B15:B17,MATCH(MIN(C15:C17),C15:C17,0))) | D19: Only declares a winner once all three channels have real numbers — one live rate shouldn't beat two blanks by default
B20: Cheapest annualized cost % | C20: =IF(COUNT(C15:C17)<3,"-",MIN(C15:C17)) | D20: Compares only financing cost — also weigh speed, collateral/covenant burden, and counterparty credit risk transfer (LC shifts payment risk to the issuing bank; factoring can be non-recourse)

Sheet RefreshLog
B2: Refresh Log
B4: Date | C4: Trigger | D4: What changed | E4: Reviewer notes | F4: Next check
