Workbook
Name FS_MODEL_ID: 'Institutional Surface'!$C$4
Name FS_DOMAIN: 'Institutional Surface'!$C$5
Name FS_MATURITY: 'Institutional Surface'!$C$6

Sheet Cover
B2: [MFI] — Microfinance Model
B4: Institution: | C4: [fill in]
B5: Region: | C5: [fill in]
B6: Last refreshed: | C6: [date]
B7: Refresh cadence: | C7: Weekly

Sheet Institutional Surface
B2: Microfinance — Institutional Decision Surface
B4: Model ID | C4: 11
B5: Domain | C5: Microfinance
B6: Declared maturity | C6: M2
B7: Canonical builder | C7: tools/builders/build_microfinance_release.py
B8: Decision arena | C8: credit, field operations, treasury, social-performance committee and regulator
B9: Committee artifact | C9: portfolio quality and sustainability pack
B10: Operating cadence | C10: weekly collections; monthly portfolio; quarterly board
B12: Key decision outputs
B13: # | C13: Requirement | D13: Owner | E13: Evidence / location | F13: Status
B14: 1 | C14: PAR30 / PAR90 and vintage loss | F14: OPEN
B15: 2 | C15: roll rates and cure | F15: OPEN
B16: 3 | C16: operational and financial self-sufficiency | F16: OPEN
B17: 4 | C17: base, downside and break-even outputs | F17: OPEN
B18: 5 | C18: liquidity / funding requirement and binding constraint | F18: OPEN
B20: Insider questions
B21: # | C21: Requirement | D21: Owner | E21: Evidence / location | F21: Status
B22: 1 | C22: What behavior signals rescheduling versus cure? | F22: OPEN
B23: 2 | C23: Which branches are growing faster than controls? | F23: OPEN
B24: 3 | C24: How much borrower debt sits outside the institution? | F24: OPEN
B25: 4 | C25: Which assumption is owner-approved versus modeler judgement? | F25: OPEN
B26: 5 | C26: What fails first and who must act? | F26: OPEN
B28: Scenario families
B29: # | C29: Requirement | D29: Owner | E29: Evidence / location | F29: Status
B30: 1 | C30: delinquency migration | F30: OPEN
B31: 2 | C31: collection disruption | F31: OPEN
B32: 3 | C32: currency devaluation | F32: OPEN
B33: 4 | C33: data freshness / source failure | F33: OPEN
B34: 5 | C34: combined severe-but-plausible downside | F34: OPEN
B36: Primary diligence documents
B37: # | C37: Requirement | D37: Owner | E37: Evidence / location | F37: Status
B38: 1 | C38: loan tape and repayment schedule | F38: OPEN
B39: 2 | C39: branch / officer performance reports | F39: OPEN
B40: 3 | C40: funding agreements | F40: OPEN
B41: 4 | C41: approved model card and assumption register | F41: OPEN
B42: 5 | C42: independent validation and challenge record | F42: OPEN
B44: Challenge tests
B45: # | C45: Requirement | D45: Owner | E45: Evidence / location | F45: Status
B46: 1 | C46: portfolio roll-forward balances | F46: OPEN
B47: 2 | C47: PAR denominators consistent | F47: OPEN
...

Sheet Challenge Log
B2: Independent Challenge, Override and Closure Log
B4: Date | C4: Reviewer | D4: Challenge | E4: Owner response | F4: Evidence | G4: Impact | H4: Status | I4: Closure
D5: portfolio roll-forward balances | H5: OPEN
D6: PAR denominators consistent | H6: OPEN
D7: write-offs do not erase vintage history | H7: OPEN
D8: source-to-model lineage is reproducible | H8: OPEN
D9: units, signs, dates and legal definitions reconcile | H9: OPEN

Sheet Lineage Map
B2: Source, Transformation, Ownership and Refresh Map
B4: Source class | C4: Cadence | D4: Control | E4: System / provider | F4: As-of | G4: Owner | H4: Transform | I4: Downstream | J4: Status
B5: loan-level collections | C5: daily/weekly | D5: cash and mobile-money reconciliation | J5: TO MAP
B6: portfolio tape | C6: monthly | D6: borrower and group identifiers | J6: TO MAP
B7: model governance evidence | C7: per release | D7: version, reviewer, sign-off and change log | J7: TO MAP
B8: decision-use snapshot | C8: per decision | D8: immutable as-of date and source receipt | J8: TO MAP

Sheet Loan Portfolio
B2: Loan Portfolio Overview
B5: Gross loan portfolio (GLP, $) | C5: 0
B6: Number of active borrowers | C6: 0
B7: Portfolio at risk >30 days ($) | C7: 0
B8: Portfolio at risk >90 days ($) | C8: 0
B9: Write-offs this period ($) | C9: 0
B10: Average loan balance ($) | C10: 0
B12: Portfolio Quality
B13: PAR 30 % | C13: =IFERROR(C7/C5,"-")
B14: PAR 90 % | C14: =IFERROR(C8/C5,"-")
B15: Write-off ratio (period) | C15: =IFERROR(C9/C5,"-")
B16: Avg loan / borrower check | C16: =IFERROR(C5/C6,"-")

Sheet Portfolio Rollforward
B2: Gross Loan Portfolio Rollforward and Restructuring
B3: Active scenario | C3: Base
B4: Metric | C4: Base | D4: Downside | E4: Active | F4: Interpretation
B5: Beginning gross loan portfolio | C5: 100 | D5: 100 | E5: =IF($C$3="Downside",D5,C5) | F5: opening principal balance
B6: Disbursements | C6: 50 | D6: 10 | E6: =IF($C$3="Downside",D6,C6) | F6: new principal advanced
B7: Principal collections | C7: 45 | D7: 20 | E7: =IF($C$3="Downside",D7,C7) | F7: cash principal received
B8: Write-offs | C8: 2 | D8: 8 | E8: =IF($C$3="Downside",D8,C8) | F8: principal removed under policy
B9: PAR >30 balance | C9: 5 | D9: 35 | E9: =IF($C$3="Downside",D9,C9) | F9: outstanding balance past due over 30 days
B10: PAR >90 balance | C10: 2 | D10: 20 | E10: =IF($C$3="Downside",D10,C10) | F10: subset past due over 90 days
B11: Restructured / rescheduled balance | C11: 1 | D11: 15 | E11: =IF($C$3="Downside",D11,C11) | F11: modified loans tracked separately
B12: Credit-risk warning ratio | C12: 0.15 | D12: 0.15 | E12: =IF($C$3="Downside",D12,C12) | F12: PAR30 + write-offs + restructures / portfolio
B15: Derived outputs
B16: Ending gross loan portfolio | E16: =E5+E6-E7-E8
B17: PAR 30 | E17: =IFERROR(E9/E16,0)
B18: PAR 90 | E18: =IFERROR(E10/E16,0)
B19: Write-off ratio | E19: =IFERROR(E8/AVERAGE(E5,E16),0)
B20: Restructured ratio | E20: =IFERROR(E11/E16,0)
B21: Composite credit-risk ratio | E21: =E17+E19+E20
B23: PAR and write-offs use outstanding balances and policy definitions; restructures remain visible rather than being treated as cured delinquency.

Sheet Sustainability
B2: Operational & Financial Self-Sufficiency (OSS/FSS)
B4: Inputs
B5: Financial revenue (interest + fees, $) | C5: 0
B6: Financial expense (cost of funds, $) | C6: 0
B7: Loan loss provision expense ($) | C7: 0
B8: Operating expense ($) | C8: 0
B9: Cost of capital at market rate (imputed, $) | C9: 0
B11: Outputs
B12: Operational Self-Sufficiency (OSS) = Rev / (Fin exp + Loss prov + Opex) | C12: =IFERROR(C5/(C6+C7+C8),"-") | D12: >100% = covering costs from operations, not subsidy-dependent
B13: Financial Self-Sufficiency (FSS) = Rev / (Fin exp + Loss prov + Opex + imputed cost of capital) | C13: =IFERROR(C5/(C6+C7+C8+C9),"-") | D13: Stricter than OSS — adjusts for subsidized funding cost vs. commercial rate
B14: Portfolio yield (Rev / avg GLP) | C14: =IFERROR(C5/'Loan Portfolio'!C5,"-")

Sheet Funding & Liquidity
B2: Funding Concentration, Maturity, and 30-Day Liquidity
B4: Metric | C4: Base | D4: Downside | E4: Control / interpretation
B5: Liquid assets | C5: 12 | D5: 4 | E5: unrestricted cash and near-cash assets
B6: Committed undrawn funding | C6: 8 | D6: 2 | E6: available under enforceable facilities
B7: Thirty-day contractual outflows | C7: 15 | D7: 18 | E7: debt, operating, and disbursement obligations
B8: Largest funding provider balance | C8: 20 | D8: 35 | E8: single-provider exposure
B9: Total wholesale / institutional funding | C9: 80 | D9: 70 | E9: denominator for concentration
B10: Minimum liquidity coverage | C10: 1.1 | D10: 1.1 | E10: liquid assets plus committed funding / outflows
B11: Maximum provider concentration | C11: 0.3 | D11: 0.3 | E11: largest provider / total institutional funding
B14: Liquidity coverage | C14: =IFERROR((C5+C6)/C7,0) | D14: =IFERROR((D5+D6)/D7,0)
B15: Funding gap | C15: =C5+C6-C7 | D15: =D5+D6-D7
B16: Largest provider concentration | C16: =IFERROR(C8/C9,0) | D16: =IFERROR(D8/D9,0)
B17: Base status | C17: =IF(AND(C14>=C10,C16<=C11),"PASS","BREACH")
B18: Downside status | C18: =IF(AND(D14>=D10,D16<=D11),"PASS","BREACH")

Sheet Client & Conduct
B2: Client Affordability, Pricing Transparency, and Conduct Controls
B4: Metric / control | C4: Input | D4: Status | E4: Evidence / action
B5: Median borrower monthly income | C5: 250 | D5: =IF(C5>0,"PASS","BREACH") | E5: document source and update cadence
B6: Median monthly debt service | C6: 35 | D6: =IF(C6/C5<=0.30,"PASS","REVIEW") | E6: review repayment capacity and household cash-flow volatility
B7: Effective annualized borrower cost | C7: 0.28 | D7: =IF(C7<=0.40,"PASS","REVIEW") | E7: include interest, compulsory savings, fees, insurance, and transaction costs
B8: Clients with multiple active lenders (%) | C8: 0.15 | D8: =IF(C8<=0.25,"PASS","REVIEW") | E8: monitor over-indebtedness and bureau/data limitations
B9: Complaints closed within approved SLA (%) | C9: 0.95 | D9: =IF(C9>=0.90,"PASS","REVIEW") | E9: retain complaint taxonomy, root cause, and remediation
B10: Restructures receiving affordability reassessment (%) | C10: 1 | D10: =IF(C10=1,"PASS","BREACH") | E10: 1.0 means every restructure is reassessed and documented
B12: These controls expose borrower harm and conduct risk; they are not a claim that a single universal affordability or pricing threshold applies across jurisdictions.

Sheet Decision & Checks
B2: Microfinance Decision Dashboard and Independent Checks
B4: Check / decision | C4: Metric | D4: Status | E4: Interpretation / action
B5: Portfolio rollforward residual | C5: ='Portfolio Rollforward'!E16-('Portfolio Rollforward'!E5+'Portfolio Rollforward'!E6-'Portfolio Rollforward'!E7-'Portfolio Rollforward'!E8) | D5: =IF(ABS(C5)<0.01,"PASS","FAIL") | E5: Ending portfolio must conserve across disbursements, collections, and write-offs.
B6: PAR ordering | C6: ='Portfolio Rollforward'!E17-'Portfolio Rollforward'!E18 | D6: =IF(C6>=-0.000001,"PASS","FAIL") | E6: PAR90 must remain a subset of PAR30.
B7: Composite credit-risk ratio | C7: ='Portfolio Rollforward'!E21 | D7: =IF(C7<='Portfolio Rollforward'!E12,"PASS","BREACH") | E7: Escalate delinquency, restructures, and write-offs together rather than separately.
B8: Reserve tie residual | C8: ='Provisioning'!C9-'Loan Portfolio'!C5 | D8: =IF(OR(NOT(ISNUMBER(C8)),ABS(C8)<0.01),"PASS","FAIL") | E8: Aging buckets must tie to the reported gross loan portfolio.
B9: Reserve adequacy | C9: ='Provisioning'!C13 | D9: =IF(NOT(ISNUMBER(C9)),"REVIEW",IF(C9>=1,"PASS","BREACH")) | E9: Actual reserves must cover the modeled policy requirement.
B10: Operational self-sufficiency | C10: ='Sustainability'!C12 | D10: =IF(NOT(ISNUMBER(C10)),"REVIEW",IF(C10>=1,"PASS","BREACH")) | E10: OSS below 100% indicates operating dependence on subsidy or capital support.
B11: Financial self-sufficiency | C11: ='Sustainability'!C13 | D11: =IF(NOT(ISNUMBER(C11)),"REVIEW",IF(C11>=1,"PASS","BREACH")) | E11: FSS also adjusts for subsidized funding and capital costs.
B12: Downside funding gap | C12: ='Funding & Liquidity'!D15 | D12: =IF(C12>=0,"PASS","BREACH") | E12: A negative 30-day gap requires committed funding, slower disbursement, or contingency liquidity.
B13: Conduct-control exceptions | C13: =COUNTIF('Client & Conduct'!D5:D10,"<>PASS") | D13: =IF(C13=0,"PASS","REVIEW") | E13: Growth and sustainability do not override affordability or conduct failures.
B15: Overall model status | C15: =IF(COUNTIF(D5:D13,"FAIL")+COUNTIF(D5:D13,"BREACH")>0,"BREACH",IF(COUNTIF(D5:D13,"REVIEW")>0,"REVIEW","PASS"))
B17: Primary decision outputs
B18: Ending gross loan portfolio | C18: ='Portfolio Rollforward'!E16
B19: PAR 30 | C19: ='Portfolio Rollforward'!E17
B20: Write-off ratio | C20: ='Portfolio Rollforward'!E19
B21: OSS | C21: ='Sustainability'!C12
B22: FSS | C22: ='Sustainability'!C13
B23: Downside funding gap | C23: ='Funding & Liquidity'!D15
B24: Reserve adequacy | C24: ='Provisioning'!C13

Sheet Provisioning
B2: Loan Loss Reserve Adequacy (days-past-due tiering)
B4: Aging bucket | C4: Outstanding balance ($) | D4: Reserve rate | E4: Required reserve ($)
B5: Current (0-30 days) | C5: 0 | D5: 0.01 | E5: =C5*D5
B6: 31-90 days | C6: 0 | D6: 0.1 | E6: =C6*D6
B7: 91-180 days | C7: 0 | D7: 0.5 | E7: =C7*D7
B8: 180+ days / written off pending | C8: 0 | D8: 1 | E8: =C8*D8
B9: Total outstanding portfolio | C9: =SUM(C5:C8)
B10: Total required reserve (sum of tiers) | E10: =SUM(E5:E8)
B12: Actual reserve held ($) | C12: 0
B13: Reserve adequacy (actual / required) | C13: =IFERROR(C12/E10,"-") | D13: <100% = under-reserved relative to portfolio risk profile — review provisioning policy
B14: Cross-check vs Loan Portfolio tab (should tie to GLP) | C14: =IFERROR(C9-'Loan Portfolio'!C5,"-")

Sheet Growth & Productivity
B2: Growth & Loan Officer Productivity
B4: Inputs
B5: Active borrowers — prior period | C5: 0
B6: Active borrowers — current period | C6: 0
B7: New disbursements this period ($) | C7: 0
B8: Number of loan officers | C8: 0
B10: Outputs
B11: Borrower growth rate (period over period) | C11: =IFERROR((C6-C5)/C5,"-")
B12: Borrowers per loan officer (caseload) | C12: =IFERROR(C6/C8,"-") | D12: Typical sustainable caseload benchmark: 250-400 borrowers/officer, group-lending-dependent
B13: Disbursement per active borrower ($, avg) | C13: =IFERROR(C7/C6,"-")

Sheet RefreshLog
B2: Refresh Log
B4: Date | C4: Trigger | D4: What changed | E4: Reviewer notes | F4: Next check
