Workbook
Name FS_MODEL_ID: 'Institutional Surface'!$C$4
Name FS_DOMAIN: 'Institutional Surface'!$C$5
Name FS_MATURITY: 'Institutional Surface'!$C$6

Sheet Cover
B2: [COMPANY] — Venture Capital Model
B4: Sector: | C4: [fill in]
B5: Current stage: | C5: Seed / A / B / C / Growth
B6: Last refreshed: | C6: [date]
B7: Next round expected: | C7: [date]
B8: Refresh cadence: | C8: Weekly

Sheet Institutional Surface
B2: Venture Capital — Institutional Decision Surface
B4: Model ID | C4: 13
B5: Domain | C5: Venture Capital
B6: Declared maturity | C6: M2
B7: Canonical builder | C7: tools/builders/build_venture_capital_release.py
B8: Decision arena | C8: investment team, partnership IC, board and portfolio finance
B9: Committee artifact | C9: investment and reserve-allocation memo
B10: Operating cadence | C10: monthly portfolio; event-driven financings; quarterly IC
B12: Key decision outputs
B13: # | C13: Requirement | D13: Owner | E13: Evidence / location | F13: Status
B14: 1 | C14: post-money ownership | F14: OPEN
B15: 2 | C15: SAFE / note conversion | F15: OPEN
B16: 3 | C16: preference and participation waterfall | F16: OPEN
B17: 4 | C17: base, downside and break-even outputs | F17: OPEN
B18: 5 | C18: liquidity / funding requirement and binding constraint | F18: OPEN
B20: Insider questions
B21: # | C21: Requirement | D21: Owner | E21: Evidence / location | F21: Status
B22: 1 | C22: Which security is actually senior? | F22: OPEN
B23: 2 | C23: Who can block the next financing? | F23: OPEN
B24: 3 | C24: What converts before the option-pool top-up? | F24: OPEN
B25: 4 | C25: Which assumption is owner-approved versus modeler judgement? | F25: OPEN
B26: 5 | C26: What fails first and who must act? | F26: OPEN
B28: Scenario families
B29: # | C29: Requirement | D29: Owner | E29: Evidence / location | F29: Status
B30: 1 | C30: down round | F30: OPEN
B31: 2 | C31: bridge with seniority | F31: OPEN
B32: 3 | C32: flat exit preference stack | F32: OPEN
B33: 4 | C33: data freshness / source failure | F33: OPEN
B34: 5 | C34: combined severe-but-plausible downside | F34: OPEN
B36: Primary diligence documents
B37: # | C37: Requirement | D37: Owner | E37: Evidence / location | F37: Status
B38: 1 | C38: charter and cap table | F38: OPEN
B39: 2 | C39: SAFE / note instruments | F39: OPEN
B40: 3 | C40: stock purchase agreement | F40: OPEN
B41: 4 | C41: approved model card and assumption register | F41: OPEN
B42: 5 | C42: independent validation and challenge record | F42: OPEN
B44: Challenge tests
B45: # | C45: Requirement | D45: Owner | E45: Evidence / location | F45: Status
B46: 1 | C46: waterfall conserves proceeds | F46: OPEN
B47: 2 | C47: share count reconciles | F47: OPEN
...

Sheet Challenge Log
B2: Independent Challenge, Override and Closure Log
B4: Date | C4: Reviewer | D4: Challenge | E4: Owner response | F4: Evidence | G4: Impact | H4: Status | I4: Closure
D5: waterfall conserves proceeds | H5: OPEN
D6: share count reconciles | H6: OPEN
D7: SAFE conversion follows instrument terms | H7: OPEN
D8: source-to-model lineage is reproducible | H8: OPEN
D9: units, signs, dates and legal definitions reconcile | H9: OPEN

Sheet Lineage Map
B2: Source, Transformation, Ownership and Refresh Map
B4: Source class | C4: Cadence | D4: Control | E4: System / provider | F4: As-of | G4: Owner | H4: Transform | I4: Downstream | J4: Status
B5: cap table | C5: event-driven | D5: fully diluted share reconciliation | J5: TO MAP
B6: financing instruments | C6: event-driven | D6: conversion and seniority map | J6: TO MAP
B7: model governance evidence | C7: per release | D7: version, reviewer, sign-off and change log | J7: TO MAP
B8: decision-use snapshot | C8: per decision | D8: immutable as-of date and source receipt | J8: TO MAP

Sheet Cap Table
B2: Capitalization Table
B4: Holder / Class | C4: Shares | D4: % Fully Diluted | E4: Price paid/sh | F4: Invested $ | G4: Security type | H4: Liq. pref (x) | I4: Participation | J4: Participation cap (x) | K4: Seniority | L4: Conversion ratio | M4: As-converted shares
B5: Founders (common) | C5: 0 | D5: =IFERROR(M5/$M$11,"-") | E5: 0 | F5: =C5*E5 | G5: Common | H5: 0 | I5: N/A | J5: 0 | K5: 0 | L5: 1 | M5: =C5*L5
B6: Employee option pool | C6: 0 | D6: =IFERROR(M6/$M$11,"-") | E6: 0 | F6: =C6*E6 | G6: Common | H6: 0 | I6: N/A | J6: 0 | K6: 0 | L6: 1 | M6: =C6*L6
B7: SAFE holders (pre-conversion) | C7: 0 | D7: =IFERROR(M7/$M$11,"-") | E7: 0 | F7: =C7*E7 | G7: SAFE — deal-specific | H7: 0 | I7: Deal-specific | J7: 0 | K7: 0 | L7: 0 | M7: =C7*L7
B8: Seed preferred | C8: 0 | D8: =IFERROR(M8/$M$11,"-") | E8: 0 | F8: =C8*E8 | G8: Preferred | H8: 1 | I8: Non-participating | J8: 0 | K8: 1 | L8: 1 | M8: =C8*L8
B9: Series A preferred | C9: 0 | D9: =IFERROR(M9/$M$11,"-") | E9: 0 | F9: =C9*E9 | G9: Preferred | H9: 1 | I9: Non-participating | J9: 0 | K9: 2 | L9: 1 | M9: =C9*L9
B10: Series B preferred | C10: 0 | D10: =IFERROR(M10/$M$11,"-") | E10: 0 | F10: =C10*E10 | G10: Preferred | H10: 1 | I10: Non-participating | J10: 0 | K10: 3 | L10: 1 | M10: =C10*L10
B11: Total | C11: =SUM(C5:C10) | F11: =SUM(F5:F10) | M11: =SUM(M5:M10)

Sheet Round Modeling
B2: New Round Modeling
B4: Inputs | E4: Outputs
B5: Pre-money valuation | C5: 0 | E5: Post-money valuation | F5: =C5+C6
B6: New money raised | C6: 0 | E6: Price per share | F6: =IFERROR(C5/C8,"-")
B7: New option pool top-up % | C7: 0 | E7: New shares issued (investor) | F7: =IFERROR(C6/F6,"-")
B8: Existing fully diluted shares | C8: 0 | E8: New pool shares (top-up) | F8: =IFERROR(C7*(C8+F7),"-")
E9: Total post-round shares | F9: =IFERROR(C8+F7+F8,"-")
E10: New investor ownership % | F10: =IFERROR(F7/F9,"-")
E11: Existing holder dilution % | F11: =IFERROR(1-C8/F9,"-")

Sheet SAFE Conversion
B2: SAFE / Convertible Note Conversion
B4: SAFE Terms | E4: At Priced Round
B5: SAFE investment amount | C5: 0 | E5: Priced round price/share | F5: ='Round Modeling'!F6
B6: Valuation cap | C6: 0 | E6: Cap price/share (cap / pre-round FD shares) | F6: =IFERROR(C6/'Round Modeling'!C8,"-")
B7: Discount % | C7: 0 | E7: Discount price/share | F7: =IFERROR(F5*(1-C7),"-")
E8: SAFE conversion price (lower of cap/discount/round) | F8: =IFERROR(MIN(IF(ISNUMBER(F5),F5,9E99),IF(ISNUMBER(F6),F6,9E99),IF(ISNUMBER(F7),F7,9E99)),"-")
E9: SAFE shares issued | F9: =IFERROR(C5/F8,"-")

Sheet Comparable Financings
B2: Comparable Financings
B4: Company | C4: Round | D4: Date | E4: Pre-money | F4: Amount raised | G4: Lead investor
B5: [fill in] | C5: [fill in] | D5: [fill in] | E5: 0 | F5: 0 | G5: [fill in]
B6: [fill in] | C6: [fill in] | D6: [fill in] | E6: 0 | F6: 0 | G6: [fill in]
B7: [fill in] | C7: [fill in] | D7: [fill in] | E7: 0 | F7: 0 | G7: [fill in]
B8: [fill in] | C8: [fill in] | D8: [fill in] | E8: 0 | F8: 0 | G8: [fill in]
B9: [fill in] | C9: [fill in] | D9: [fill in] | E9: 0 | F9: 0 | G9: [fill in]
B10: [fill in] | C10: [fill in] | D10: [fill in] | E10: 0 | F10: 0 | G10: [fill in]
B11: [fill in] | C11: [fill in] | D11: [fill in] | E11: 0 | F11: 0 | G11: [fill in]
B12: [fill in] | C12: [fill in] | D12: [fill in] | E12: 0 | F12: 0 | G12: [fill in]

Sheet RefreshLog
B2: Refresh Log
B4: Date | C4: Trigger | D4: What changed | E4: Reviewer notes | F4: Next check

Sheet Ownership & Dilution
B2: Post-Money Ownership, Option Pool, and Round Pricing
B4: Metric | C4: Base | D4: Adversarial | E4: Units / control
B5: Pre-money value | C5: 80 | D5: 100
B6: Investment | C6: 20 | D6: 20
B7: Existing shares | C7: 8 | D7: 10
B8: New investor shares | C8: 2 | D8: 4
B9: Option-pool expansion | C9: 0 | D9: 5
B10: Maximum investor ownership | C10: 0.4 | D10: 0.4
B11: Maximum option-pool dilution | C11: 0.2 | D11: 0.2
B15: Post-money value | C15: =C5+C6 | D15: =D5+D6
B16: Total post-money shares | C16: =C7+C8+C9 | D16: =D7+D8+D9
B17: Investor ownership | C17: =IFERROR(C8/C16,0) | D17: =IFERROR(D8/D16,0)
B18: Founder ownership | C18: =IFERROR(C7/C16,0) | D18: =IFERROR(D7/D16,0)
B19: Option-pool ownership | C19: =IFERROR(C9/C16,0) | D19: =IFERROR(D9/D16,0)
B20: Round price / share | C20: =IFERROR(C6/C8,0) | D20: =IFERROR(D6/D8,0)
B21: Pre-money implied price / share | C21: =IFERROR(C5/C7,0) | D21: =IFERROR(D5/D7,0)

Sheet Reserves & Follow-ons
B2: Follow-On Requirements, Reserves, and Ownership Defense
B4: Metric | C4: Base | D4: Adversarial | E4: Units / control
B5: Follow-on required | C5: 10 | D5: 30
B6: Available reserves | C6: 15 | D6: 5
B7: Pro rata ownership target | C7: 0.2 | D7: 0.2
B8: Next-round size | C8: 40 | D8: 60
B11: Reserve gap | C11: =MAX(0,C5-C6) | D11: =MAX(0,D5-D6)
B12: Pro rata capital required | C12: =C7*C8 | D12: =D7*D8
B13: Ownership-defense shortfall | C13: =MAX(0,C12-C6) | D13: =MAX(0,D12-D6)

Sheet Exit Waterfall
B2: Exit Proceeds, Investor MOIC, and Return Thresholds
B4: Metric | C4: Base | D4: Adversarial | E4: Units / control
B5: Exit equity value | C5: 500 | D5: 80
B6: Investment cost | C6: 20 | D6: 20
B7: Minimum gross MOIC | C7: 3 | D7: 3
B11: Investor ownership | C11: ='Ownership & Dilution'!C17 | D11: ='Ownership & Dilution'!D17
B12: Investor exit proceeds | C12: =C5*C11 | D12: =D5*D11
B13: Gross MOIC | C13: =IFERROR(C12/C6,0) | D13: =IFERROR(D12/D6,0)
B16: Liquidation Preference Waterfall — Holder Elections
B17: Terms / solver status | C17: =IF(AND(COUNT(C21:C24)=4,MIN(C21:C24)>=0,COUNT(D21:D23)=3,MIN(D21:D23)>=0,COUNT(E21:E23)=3,MIN(E21:E23)>0,E21<>E22,E21<>E23,E22<>E23,COUNTIF(F21:F23,"Non-participating")=3,COUNT(G21:G23)=3,MIN(G21:G23)=0,MAX(G21:G23)=0,COUNTIF('Cap Table'!G8:G10,"Preferred")=3,MIN('Cap Table'!L8:L10)>0,'Cap Table'!M7=0),"SUPPORTED","UNSUPPORTED / INCOMPLETE")
B18: Each preferred class independently retains its preference or converts. The selected state conserves proceeds and admits no profitable unilateral election change. Participating preferred, non-zero participation caps, duplicate seniority, and unconverted SAFEs fail closed for legal review.
B20: Class | C20: As-converted shares | D20: Preference claim | E20: Seniority | F20: Participation | G20: Cap (x) | H20: Base election | I20: Base payout | J20: Adverse election | K20: Adverse payout
B21: Series B preferred | C21: =IFERROR('Cap Table'!M10,0) | D21: =MAX(0,'Cap Table'!F10*'Cap Table'!H10) | E21: ='Cap Table'!K10 | F21: ='Cap Table'!I10 | G21: ='Cap Table'!J10 | H21: =IFERROR(IF(INDEX($C$32:$C$39,MATCH(1,$V$32:$V$39,0))=1,"CONVERT","PREFERENCE"),"NO EQUILIBRIUM") | I21: =IFERROR(INDEX($K$32:$K$39,MATCH(1,$V$32:$V$39,0)),0) | J21: =IFERROR(IF(INDEX($C$43:$C$50,MATCH(1,$V$43:$V$50,0))=1,"CONVERT","PREFERENCE"),"NO EQUILIBRIUM") | K21: =IFERROR(INDEX($K$43:$K$50,MATCH(1,$V$43:$V$50,0)),0)
B22: Series A preferred | C22: =IFERROR('Cap Table'!M9,0) | D22: =MAX(0,'Cap Table'!F9*'Cap Table'!H9) | E22: ='Cap Table'!K9 | F22: ='Cap Table'!I9 | G22: ='Cap Table'!J9 | H22: =IFERROR(IF(INDEX($D$32:$D$39,MATCH(1,$V$32:$V$39,0))=1,"CONVERT","PREFERENCE"),"NO EQUILIBRIUM") | I22: =IFERROR(INDEX($L$32:$L$39,MATCH(1,$V$32:$V$39,0)),0) | J22: =IFERROR(IF(INDEX($D$43:$D$50,MATCH(1,$V$43:$V$50,0))=1,"CONVERT","PREFERENCE"),"NO EQUILIBRIUM") | K22: =IFERROR(INDEX($L$43:$L$50,MATCH(1,$V$43:$V$50,0)),0)
B23: Seed preferred | C23: =IFERROR('Cap Table'!M8,0) | D23: =MAX(0,'Cap Table'!F8*'Cap Table'!H8) | E23: ='Cap Table'!K8 | F23: ='Cap Table'!I8 | G23: ='Cap Table'!J8 | H23: =IFERROR(IF(INDEX($E$32:$E$39,MATCH(1,$V$32:$V$39,0))=1,"CONVERT","PREFERENCE"),"NO EQUILIBRIUM") | I23: =IFERROR(INDEX($M$32:$M$39,MATCH(1,$V$32:$V$39,0)),0) | J23: =IFERROR(IF(INDEX($E$43:$E$50,MATCH(1,$V$43:$V$50,0))=1,"CONVERT","PREFERENCE"),"NO EQUILIBRIUM") | K23: =IFERROR(INDEX($M$43:$M$50,MATCH(1,$V$43:$V$50,0)),0)
B24: Common (founders + option pool) | C24: =IFERROR('Cap Table'!M5+'Cap Table'!M6,0) | D24: 0 | E24: 0 | F24: N/A | G24: 0 | H24: COMMON | I24: =IFERROR(INDEX($N$32:$N$39,MATCH(1,$V$32:$V$39,0)),0) | J24: COMMON | K24: =IFERROR(INDEX($N$43:$N$50,MATCH(1,$V$43:$V$50,0)),0)
B26: Total distributed | I26: =SUM(I21:I24) | K26: =SUM(K21:K24)
B27: Conservation residual | I27: =I26-$C$5 | K27: =K26-$D$5
B28: Selected stable election mask | I28: =IFERROR(INDEX($B$32:$B$39,MATCH(1,$V$32:$V$39,0)),"NONE") | K28: =IFERROR(INDEX($B$43:$B$50,MATCH(1,$V$43:$V$50,0)),"NONE")
B30: Base — exhaustive holder-election candidates
B31: Mask | C31: B converts | D31: A converts | E31: Seed converts | F31: B pref pay | G31: A pref pay | H31: Seed pref pay | I31: Residual | J31: Common-pool shares | K31: B payout | L31: A payout | M31: Seed payout | N31: Common payout | O31: Total | P31: B alt payout | Q31: A alt payout | R31: Seed alt payout | S31: B stable | T31: A stable | U31: Seed stable | V31: Stable candidate
B32: 0 | C32: 0 | D32: 0 | E32: 0 | F32: =IF(($C32)=1,0,MIN($D$21,MAX(0,$C$5-(IF($E$21>$E$21,(1-($C32))*$D$21,0)+IF($E$22>$E$21,(1-($D32))*$D$22,0)+IF($E$23>$E$21,(1-($E32))*$D$23,0))))) | G32: =IF(($D32)=1,0,MIN($D$22,MAX(0,$C$5-(IF($E$21>$E$22,(1-($C32))*$D$21,0)+IF($E$22>$E$22,(1-($D32))*$D$22,0)+IF($E$23>$E$22,(1-($E32))*$D$23,0))))) | H32: =IF(($E32)=1,0,MIN($D$23,MAX(0,$C$5-(IF($E$21>$E$23,(1-($C32))*$D$21,0)+IF($E$22>$E$23,(1-($D32))*$D$22,0)+IF($E$23>$E$23,(1-($E32))*$D$23,0))))) | I32: =MAX(0,$C$5-SUM(F32:H32)) | J32: =$C$24+C32*$C$21+D32*$C$22+E32*$C$23 | K32: =IF(C32=1,IFERROR(I32*$C$21/J32,0),F32) | L32: =IF(D32=1,IFERROR(I32*$C$22/J32,0),G32) | M32: =IF(E32=1,IFERROR(I32*$C$23/J32,0),H32) | N32: =IFERROR(I32*$C$24/J32,0) | O32: =SUM(K32:N32) | P32: =INDEX($K$32:$K$39,MATCH(IF(C32=1,B32-4,B32+4),$B$32:$B$39,0)) | Q32: =INDEX($L$32:$L$39,MATCH(IF(D32=1,B32-2,B32+2),$B$32:$B$39,0)) | R32: =INDEX($M$32:$M$39,MATCH(IF(E32=1,B32-1,B32+1),$B$32:$B$39,0)) | S32: =--(K32+0.000001>=P32) | T32: =--(L32+0.000001>=Q32) | U32: =--(M32+0.000001>=R32) | V32: =IFERROR(--(AND($C$17="SUPPORTED",S32=1,T32=1,U32=1,ABS(O32-$C$5)<=0.01)),0)
B33: 1 | C33: 0 | D33: 0 | E33: 1 | F33: =IF(($C33)=1,0,MIN($D$21,MAX(0,$C$5-(IF($E$21>$E$21,(1-($C33))*$D$21,0)+IF($E$22>$E$21,(1-($D33))*$D$22,0)+IF($E$23>$E$21,(1-($E33))*$D$23,0))))) | G33: =IF(($D33)=1,0,MIN($D$22,MAX(0,$C$5-(IF($E$21>$E$22,(1-($C33))*$D$21,0)+IF($E$22>$E$22,(1-($D33))*$D$22,0)+IF($E$23>$E$22,(1-($E33))*$D$23,0))))) | H33: =IF(($E33)=1,0,MIN($D$23,MAX(0,$C$5-(IF($E$21>$E$23,(1-($C33))*$D$21,0)+IF($E$22>$E$23,(1-($D33))*$D$22,0)+IF($E$23>$E$23,(1-($E33))*$D$23,0))))) | I33: =MAX(0,$C$5-SUM(F33:H33)) | J33: =$C$24+C33*$C$21+D33*$C$22+E33*$C$23 | K33: =IF(C33=1,IFERROR(I33*$C$21/J33,0),F33) | L33: =IF(D33=1,IFERROR(I33*$C$22/J33,0),G33) | M33: =IF(E33=1,IFERROR(I33*$C$23/J33,0),H33) | N33: =IFERROR(I33*$C$24/J33,0) | O33: =SUM(K33:N33) | P33: =INDEX($K$32:$K$39,MATCH(IF(C33=1,B33-4,B33+4),$B$32:$B$39,0)) | Q33: =INDEX($L$32:$L$39,MATCH(IF(D33=1,B33-2,B33+2),$B$32:$B$39,0)) | R33: =INDEX($M$32:$M$39,MATCH(IF(E33=1,B33-1,B33+1),$B$32:$B$39,0)) | S33: =--(K33+0.000001>=P33) | T33: =--(L33+0.000001>=Q33) | U33: =--(M33+0.000001>=R33) | V33: =IFERROR(--(AND($C$17="SUPPORTED",S33=1,T33=1,U33=1,ABS(O33-$C$5)<=0.01)),0)
B34: 2 | C34: 0 | D34: 1 | E34: 0 | F34: =IF(($C34)=1,0,MIN($D$21,MAX(0,$C$5-(IF($E$21>$E$21,(1-($C34))*$D$21,0)+IF($E$22>$E$21,(1-($D34))*$D$22,0)+IF($E$23>$E$21,(1-($E34))*$D$23,0))))) | G34: =IF(($D34)=1,0,MIN($D$22,MAX(0,$C$5-(IF($E$21>$E$22,(1-($C34))*$D$21,0)+IF($E$22>$E$22,(1-($D34))*$D$22,0)+IF($E$23>$E$22,(1-($E34))*$D$23,0))))) | H34: =IF(($E34)=1,0,MIN($D$23,MAX(0,$C$5-(IF($E$21>$E$23,(1-($C34))*$D$21,0)+IF($E$22>$E$23,(1-($D34))*$D$22,0)+IF($E$23>$E$23,(1-($E34))*$D$23,0))))) | I34: =MAX(0,$C$5-SUM(F34:H34)) | J34: =$C$24+C34*$C$21+D34*$C$22+E34*$C$23 | K34: =IF(C34=1,IFERROR(I34*$C$21/J34,0),F34) | L34: =IF(D34=1,IFERROR(I34*$C$22/J34,0),G34) | M34: =IF(E34=1,IFERROR(I34*$C$23/J34,0),H34) | N34: =IFERROR(I34*$C$24/J34,0) | O34: =SUM(K34:N34) | P34: =INDEX($K$32:$K$39,MATCH(IF(C34=1,B34-4,B34+4),$B$32:$B$39,0)) | Q34: =INDEX($L$32:$L$39,MATCH(IF(D34=1,B34-2,B34+2),$B$32:$B$39,0)) | R34: =INDEX($M$32:$M$39,MATCH(IF(E34=1,B34-1,B34+1),$B$32:$B$39,0)) | S34: =--(K34+0.000001>=P34) | T34: =--(L34+0.000001>=Q34) | U34: =--(M34+0.000001>=R34) | V34: =IFERROR(--(AND($C$17="SUPPORTED",S34=1,T34=1,U34=1,ABS(O34-$C$5)<=0.01)),0)
B35: 3 | C35: 0 | D35: 1 | E35: 1 | F35: =IF(($C35)=1,0,MIN($D$21,MAX(0,$C$5-(IF($E$21>$E$21,(1-($C35))*$D$21,0)+IF($E$22>$E$21,(1-($D35))*$D$22,0)+IF($E$23>$E$21,(1-($E35))*$D$23,0))))) | G35: =IF(($D35)=1,0,MIN($D$22,MAX(0,$C$5-(IF($E$21>$E$22,(1-($C35))*$D$21,0)+IF($E$22>$E$22,(1-($D35))*$D$22,0)+IF($E$23>$E$22,(1-($E35))*$D$23,0))))) | H35: =IF(($E35)=1,0,MIN($D$23,MAX(0,$C$5-(IF($E$21>$E$23,(1-($C35))*$D$21,0)+IF($E$22>$E$23,(1-($D35))*$D$22,0)+IF($E$23>$E$23,(1-($E35))*$D$23,0))))) | I35: =MAX(0,$C$5-SUM(F35:H35)) | J35: =$C$24+C35*$C$21+D35*$C$22+E35*$C$23 | K35: =IF(C35=1,IFERROR(I35*$C$21/J35,0),F35) | L35: =IF(D35=1,IFERROR(I35*$C$22/J35,0),G35) | M35: =IF(E35=1,IFERROR(I35*$C$23/J35,0),H35) | N35: =IFERROR(I35*$C$24/J35,0) | O35: =SUM(K35:N35) | P35: =INDEX($K$32:$K$39,MATCH(IF(C35=1,B35-4,B35+4),$B$32:$B$39,0)) | Q35: =INDEX($L$32:$L$39,MATCH(IF(D35=1,B35-2,B35+2),$B$32:$B$39,0)) | R35: =INDEX($M$32:$M$39,MATCH(IF(E35=1,B35-1,B35+1),$B$32:$B$39,0)) | S35: =--(K35+0.000001>=P35) | T35: =--(L35+0.000001>=Q35) | U35: =--(M35+0.000001>=R35) | V35: =IFERROR(--(AND($C$17="SUPPORTED",S35=1,T35=1,U35=1,ABS(O35-$C$5)<=0.01)),0)
B36: 4 | C36: 1 | D36: 0 | E36: 0 | F36: =IF(($C36)=1,0,MIN($D$21,MAX(0,$C$5-(IF($E$21>$E$21,(1-($C36))*$D$21,0)+IF($E$22>$E$21,(1-($D36))*$D$22,0)+IF($E$23>$E$21,(1-($E36))*$D$23,0))))) | G36: =IF(($D36)=1,0,MIN($D$22,MAX(0,$C$5-(IF($E$21>$E$22,(1-($C36))*$D$21,0)+IF($E$22>$E$22,(1-($D36))*$D$22,0)+IF($E$23>$E$22,(1-($E36))*$D$23,0))))) | H36: =IF(($E36)=1,0,MIN($D$23,MAX(0,$C$5-(IF($E$21>$E$23,(1-($C36))*$D$21,0)+IF($E$22>$E$23,(1-($D36))*$D$22,0)+IF($E$23>$E$23,(1-($E36))*$D$23,0))))) | I36: =MAX(0,$C$5-SUM(F36:H36)) | J36: =$C$24+C36*$C$21+D36*$C$22+E36*$C$23 | K36: =IF(C36=1,IFERROR(I36*$C$21/J36,0),F36) | L36: =IF(D36=1,IFERROR(I36*$C$22/J36,0),G36) | M36: =IF(E36=1,IFERROR(I36*$C$23/J36,0),H36) | N36: =IFERROR(I36*$C$24/J36,0) | O36: =SUM(K36:N36) | P36: =INDEX($K$32:$K$39,MATCH(IF(C36=1,B36-4,B36+4),$B$32:$B$39,0)) | Q36: =INDEX($L$32:$L$39,MATCH(IF(D36=1,B36-2,B36+2),$B$32:$B$39,0)) | R36: =INDEX($M$32:$M$39,MATCH(IF(E36=1,B36-1,B36+1),$B$32:$B$39,0)) | S36: =--(K36+0.000001>=P36) | T36: =--(L36+0.000001>=Q36) | U36: =--(M36+0.000001>=R36) | V36: =IFERROR(--(AND($C$17="SUPPORTED",S36=1,T36=1,U36=1,ABS(O36-$C$5)<=0.01)),0)
B37: 5 | C37: 1 | D37: 0 | E37: 1 | F37: =IF(($C37)=1,0,MIN($D$21,MAX(0,$C$5-(IF($E$21>$E$21,(1-($C37))*$D$21,0)+IF($E$22>$E$21,(1-($D37))*$D$22,0)+IF($E$23>$E$21,(1-($E37))*$D$23,0))))) | G37: =IF(($D37)=1,0,MIN($D$22,MAX(0,$C$5-(IF($E$21>$E$22,(1-($C37))*$D$21,0)+IF($E$22>$E$22,(1-($D37))*$D$22,0)+IF($E$23>$E$22,(1-($E37))*$D$23,0))))) | H37: =IF(($E37)=1,0,MIN($D$23,MAX(0,$C$5-(IF($E$21>$E$23,(1-($C37))*$D$21,0)+IF($E$22>$E$23,(1-($D37))*$D$22,0)+IF($E$23>$E$23,(1-($E37))*$D$23,0))))) | I37: =MAX(0,$C$5-SUM(F37:H37)) | J37: =$C$24+C37*$C$21+D37*$C$22+E37*$C$23 | K37: =IF(C37=1,IFERROR(I37*$C$21/J37,0),F37) | L37: =IF(D37=1,IFERROR(I37*$C$22/J37,0),G37) | M37: =IF(E37=1,IFERROR(I37*$C$23/J37,0),H37) | N37: =IFERROR(I37*$C$24/J37,0) | O37: =SUM(K37:N37) | P37: =INDEX($K$32:$K$39,MATCH(IF(C37=1,B37-4,B37+4),$B$32:$B$39,0)) | Q37: =INDEX($L$32:$L$39,MATCH(IF(D37=1,B37-2,B37+2),$B$32:$B$39,0)) | R37: =INDEX($M$32:$M$39,MATCH(IF(E37=1,B37-1,B37+1),$B$32:$B$39,0)) | S37: =--(K37+0.000001>=P37) | T37: =--(L37+0.000001>=Q37) | U37: =--(M37+0.000001>=R37) | V37: =IFERROR(--(AND($C$17="SUPPORTED",S37=1,T37=1,U37=1,ABS(O37-$C$5)<=0.01)),0)
B38: 6 | C38: 1 | D38: 1 | E38: 0 | F38: =IF(($C38)=1,0,MIN($D$21,MAX(0,$C$5-(IF($E$21>$E$21,(1-($C38))*$D$21,0)+IF($E$22>$E$21,(1-($D38))*$D$22,0)+IF($E$23>$E$21,(1-($E38))*$D$23,0))))) | G38: =IF(($D38)=1,0,MIN($D$22,MAX(0,$C$5-(IF($E$21>$E$22,(1-($C38))*$D$21,0)+IF($E$22>$E$22,(1-($D38))*$D$22,0)+IF($E$23>$E$22,(1-($E38))*$D$23,0))))) | H38: =IF(($E38)=1,0,MIN($D$23,MAX(0,$C$5-(IF($E$21>$E$23,(1-($C38))*$D$21,0)+IF($E$22>$E$23,(1-($D38))*$D$22,0)+IF($E$23>$E$23,(1-($E38))*$D$23,0))))) | I38: =MAX(0,$C$5-SUM(F38:H38)) | J38: =$C$24+C38*$C$21+D38*$C$22+E38*$C$23 | K38: =IF(C38=1,IFERROR(I38*$C$21/J38,0),F38) | L38: =IF(D38=1,IFERROR(I38*$C$22/J38,0),G38) | M38: =IF(E38=1,IFERROR(I38*$C$23/J38,0),H38) | N38: =IFERROR(I38*$C$24/J38,0) | O38: =SUM(K38:N38) | P38: =INDEX($K$32:$K$39,MATCH(IF(C38=1,B38-4,B38+4),$B$32:$B$39,0)) | Q38: =INDEX($L$32:$L$39,MATCH(IF(D38=1,B38-2,B38+2),$B$32:$B$39,0)) | R38: =INDEX($M$32:$M$39,MATCH(IF(E38=1,B38-1,B38+1),$B$32:$B$39,0)) | S38: =--(K38+0.000001>=P38) | T38: =--(L38+0.000001>=Q38) | U38: =--(M38+0.000001>=R38) | V38: =IFERROR(--(AND($C$17="SUPPORTED",S38=1,T38=1,U38=1,ABS(O38-$C$5)<=0.01)),0)
B39: 7 | C39: 1 | D39: 1 | E39: 1 | F39: =IF(($C39)=1,0,MIN($D$21,MAX(0,$C$5-(IF($E$21>$E$21,(1-($C39))*$D$21,0)+IF($E$22>$E$21,(1-($D39))*$D$22,0)+IF($E$23>$E$21,(1-($E39))*$D$23,0))))) | G39: =IF(($D39)=1,0,MIN($D$22,MAX(0,$C$5-(IF($E$21>$E$22,(1-($C39))*$D$21,0)+IF($E$22>$E$22,(1-($D39))*$D$22,0)+IF($E$23>$E$22,(1-($E39))*$D$23,0))))) | H39: =IF(($E39)=1,0,MIN($D$23,MAX(0,$C$5-(IF($E$21>$E$23,(1-($C39))*$D$21,0)+IF($E$22>$E$23,(1-($D39))*$D$22,0)+IF($E$23>$E$23,(1-($E39))*$D$23,0))))) | I39: =MAX(0,$C$5-SUM(F39:H39)) | J39: =$C$24+C39*$C$21+D39*$C$22+E39*$C$23 | K39: =IF(C39=1,IFERROR(I39*$C$21/J39,0),F39) | L39: =IF(D39=1,IFERROR(I39*$C$22/J39,0),G39) | M39: =IF(E39=1,IFERROR(I39*$C$23/J39,0),H39) | N39: =IFERROR(I39*$C$24/J39,0) | O39: =SUM(K39:N39) | P39: =INDEX($K$32:$K$39,MATCH(IF(C39=1,B39-4,B39+4),$B$32:$B$39,0)) | Q39: =INDEX($L$32:$L$39,MATCH(IF(D39=1,B39-2,B39+2),$B$32:$B$39,0)) | R39: =INDEX($M$32:$M$39,MATCH(IF(E39=1,B39-1,B39+1),$B$32:$B$39,0)) | S39: =--(K39+0.000001>=P39) | T39: =--(L39+0.000001>=Q39) | U39: =--(M39+0.000001>=R39) | V39: =IFERROR(--(AND($C$17="SUPPORTED",S39=1,T39=1,U39=1,ABS(O39-$C$5)<=0.01)),0)
B41: Adverse — exhaustive holder-election candidates
B42: Mask | C42: B converts | D42: A converts | E42: Seed converts | F42: B pref pay | G42: A pref pay | H42: Seed pref pay | I42: Residual | J42: Common-pool shares | K42: B payout | L42: A payout | M42: Seed payout | N42: Common payout | O42: Total | P42: B alt payout | Q42: A alt payout | R42: Seed alt payout | S42: B stable | T42: A stable | U42: Seed stable | V42: Stable candidate
B43: 0 | C43: 0 | D43: 0 | E43: 0 | F43: =IF(($C43)=1,0,MIN($D$21,MAX(0,$D$5-(IF($E$21>$E$21,(1-($C43))*$D$21,0)+IF($E$22>$E$21,(1-($D43))*$D$22,0)+IF($E$23>$E$21,(1-($E43))*$D$23,0))))) | G43: =IF(($D43)=1,0,MIN($D$22,MAX(0,$D$5-(IF($E$21>$E$22,(1-($C43))*$D$21,0)+IF($E$22>$E$22,(1-($D43))*$D$22,0)+IF($E$23>$E$22,(1-($E43))*$D$23,0))))) | H43: =IF(($E43)=1,0,MIN($D$23,MAX(0,$D$5-(IF($E$21>$E$23,(1-($C43))*$D$21,0)+IF($E$22>$E$23,(1-($D43))*$D$22,0)+IF($E$23>$E$23,(1-($E43))*$D$23,0))))) | I43: =MAX(0,$D$5-SUM(F43:H43)) | J43: =$C$24+C43*$C$21+D43*$C$22+E43*$C$23 | K43: =IF(C43=1,IFERROR(I43*$C$21/J43,0),F43) | L43: =IF(D43=1,IFERROR(I43*$C$22/J43,0),G43) | M43: =IF(E43=1,IFERROR(I43*$C$23/J43,0),H43) | N43: =IFERROR(I43*$C$24/J43,0) | O43: =SUM(K43:N43) | P43: =INDEX($K$43:$K$50,MATCH(IF(C43=1,B43-4,B43+4),$B$43:$B$50,0)) | Q43: =INDEX($L$43:$L$50,MATCH(IF(D43=1,B43-2,B43+2),$B$43:$B$50,0)) | R43: =INDEX($M$43:$M$50,MATCH(IF(E43=1,B43-1,B43+1),$B$43:$B$50,0)) | S43: =--(K43+0.000001>=P43) | T43: =--(L43+0.000001>=Q43) | U43: =--(M43+0.000001>=R43) | V43: =IFERROR(--(AND($C$17="SUPPORTED",S43=1,T43=1,U43=1,ABS(O43-$D$5)<=0.01)),0)
B44: 1 | C44: 0 | D44: 0 | E44: 1 | F44: =IF(($C44)=1,0,MIN($D$21,MAX(0,$D$5-(IF($E$21>$E$21,(1-($C44))*$D$21,0)+IF($E$22>$E$21,(1-($D44))*$D$22,0)+IF($E$23>$E$21,(1-($E44))*$D$23,0))))) | G44: =IF(($D44)=1,0,MIN($D$22,MAX(0,$D$5-(IF($E$21>$E$22,(1-($C44))*$D$21,0)+IF($E$22>$E$22,(1-($D44))*$D$22,0)+IF($E$23>$E$22,(1-($E44))*$D$23,0))))) | H44: =IF(($E44)=1,0,MIN($D$23,MAX(0,$D$5-(IF($E$21>$E$23,(1-($C44))*$D$21,0)+IF($E$22>$E$23,(1-($D44))*$D$22,0)+IF($E$23>$E$23,(1-($E44))*$D$23,0))))) | I44: =MAX(0,$D$5-SUM(F44:H44)) | J44: =$C$24+C44*$C$21+D44*$C$22+E44*$C$23 | K44: =IF(C44=1,IFERROR(I44*$C$21/J44,0),F44) | L44: =IF(D44=1,IFERROR(I44*$C$22/J44,0),G44) | M44: =IF(E44=1,IFERROR(I44*$C$23/J44,0),H44) | N44: =IFERROR(I44*$C$24/J44,0) | O44: =SUM(K44:N44) | P44: =INDEX($K$43:$K$50,MATCH(IF(C44=1,B44-4,B44+4),$B$43:$B$50,0)) | Q44: =INDEX($L$43:$L$50,MATCH(IF(D44=1,B44-2,B44+2),$B$43:$B$50,0)) | R44: =INDEX($M$43:$M$50,MATCH(IF(E44=1,B44-1,B44+1),$B$43:$B$50,0)) | S44: =--(K44+0.000001>=P44) | T44: =--(L44+0.000001>=Q44) | U44: =--(M44+0.000001>=R44) | V44: =IFERROR(--(AND($C$17="SUPPORTED",S44=1,T44=1,U44=1,ABS(O44-$D$5)<=0.01)),0)
B45: 2 | C45: 0 | D45: 1 | E45: 0 | F45: =IF(($C45)=1,0,MIN($D$21,MAX(0,$D$5-(IF($E$21>$E$21,(1-($C45))*$D$21,0)+IF($E$22>$E$21,(1-($D45))*$D$22,0)+IF($E$23>$E$21,(1-($E45))*$D$23,0))))) | G45: =IF(($D45)=1,0,MIN($D$22,MAX(0,$D$5-(IF($E$21>$E$22,(1-($C45))*$D$21,0)+IF($E$22>$E$22,(1-($D45))*$D$22,0)+IF($E$23>$E$22,(1-($E45))*$D$23,0))))) | H45: =IF(($E45)=1,0,MIN($D$23,MAX(0,$D$5-(IF($E$21>$E$23,(1-($C45))*$D$21,0)+IF($E$22>$E$23,(1-($D45))*$D$22,0)+IF($E$23>$E$23,(1-($E45))*$D$23,0))))) | I45: =MAX(0,$D$5-SUM(F45:H45)) | J45: =$C$24+C45*$C$21+D45*$C$22+E45*$C$23 | K45: =IF(C45=1,IFERROR(I45*$C$21/J45,0),F45) | L45: =IF(D45=1,IFERROR(I45*$C$22/J45,0),G45) | M45: =IF(E45=1,IFERROR(I45*$C$23/J45,0),H45) | N45: =IFERROR(I45*$C$24/J45,0) | O45: =SUM(K45:N45) | P45: =INDEX($K$43:$K$50,MATCH(IF(C45=1,B45-4,B45+4),$B$43:$B$50,0)) | Q45: =INDEX($L$43:$L$50,MATCH(IF(D45=1,B45-2,B45+2),$B$43:$B$50,0)) | R45: =INDEX($M$43:$M$50,MATCH(IF(E45=1,B45-1,B45+1),$B$43:$B$50,0)) | S45: =--(K45+0.000001>=P45) | T45: =--(L45+0.000001>=Q45) | U45: =--(M45+0.000001>=R45) | V45: =IFERROR(--(AND($C$17="SUPPORTED",S45=1,T45=1,U45=1,ABS(O45-$D$5)<=0.01)),0)
B46: 3 | C46: 0 | D46: 1 | E46: 1 | F46: =IF(($C46)=1,0,MIN($D$21,MAX(0,$D$5-(IF($E$21>$E$21,(1-($C46))*$D$21,0)+IF($E$22>$E$21,(1-($D46))*$D$22,0)+IF($E$23>$E$21,(1-($E46))*$D$23,0))))) | G46: =IF(($D46)=1,0,MIN($D$22,MAX(0,$D$5-(IF($E$21>$E$22,(1-($C46))*$D$21,0)+IF($E$22>$E$22,(1-($D46))*$D$22,0)+IF($E$23>$E$22,(1-($E46))*$D$23,0))))) | H46: =IF(($E46)=1,0,MIN($D$23,MAX(0,$D$5-(IF($E$21>$E$23,(1-($C46))*$D$21,0)+IF($E$22>$E$23,(1-($D46))*$D$22,0)+IF($E$23>$E$23,(1-($E46))*$D$23,0))))) | I46: =MAX(0,$D$5-SUM(F46:H46)) | J46: =$C$24+C46*$C$21+D46*$C$22+E46*$C$23 | K46: =IF(C46=1,IFERROR(I46*$C$21/J46,0),F46) | L46: =IF(D46=1,IFERROR(I46*$C$22/J46,0),G46) | M46: =IF(E46=1,IFERROR(I46*$C$23/J46,0),H46) | N46: =IFERROR(I46*$C$24/J46,0) | O46: =SUM(K46:N46) | P46: =INDEX($K$43:$K$50,MATCH(IF(C46=1,B46-4,B46+4),$B$43:$B$50,0)) | Q46: =INDEX($L$43:$L$50,MATCH(IF(D46=1,B46-2,B46+2),$B$43:$B$50,0)) | R46: =INDEX($M$43:$M$50,MATCH(IF(E46=1,B46-1,B46+1),$B$43:$B$50,0)) | S46: =--(K46+0.000001>=P46) | T46: =--(L46+0.000001>=Q46) | U46: =--(M46+0.000001>=R46) | V46: =IFERROR(--(AND($C$17="SUPPORTED",S46=1,T46=1,U46=1,ABS(O46-$D$5)<=0.01)),0)
B47: 4 | C47: 1 | D47: 0 | E47: 0 | F47: =IF(($C47)=1,0,MIN($D$21,MAX(0,$D$5-(IF($E$21>$E$21,(1-($C47))*$D$21,0)+IF($E$22>$E$21,(1-($D47))*$D$22,0)+IF($E$23>$E$21,(1-($E47))*$D$23,0))))) | G47: =IF(($D47)=1,0,MIN($D$22,MAX(0,$D$5-(IF($E$21>$E$22,(1-($C47))*$D$21,0)+IF($E$22>$E$22,(1-($D47))*$D$22,0)+IF($E$23>$E$22,(1-($E47))*$D$23,0))))) | H47: =IF(($E47)=1,0,MIN($D$23,MAX(0,$D$5-(IF($E$21>$E$23,(1-($C47))*$D$21,0)+IF($E$22>$E$23,(1-($D47))*$D$22,0)+IF($E$23>$E$23,(1-($E47))*$D$23,0))))) | I47: =MAX(0,$D$5-SUM(F47:H47)) | J47: =$C$24+C47*$C$21+D47*$C$22+E47*$C$23 | K47: =IF(C47=1,IFERROR(I47*$C$21/J47,0),F47) | L47: =IF(D47=1,IFERROR(I47*$C$22/J47,0),G47) | M47: =IF(E47=1,IFERROR(I47*$C$23/J47,0),H47) | N47: =IFERROR(I47*$C$24/J47,0) | O47: =SUM(K47:N47) | P47: =INDEX($K$43:$K$50,MATCH(IF(C47=1,B47-4,B47+4),$B$43:$B$50,0)) | Q47: =INDEX($L$43:$L$50,MATCH(IF(D47=1,B47-2,B47+2),$B$43:$B$50,0)) | R47: =INDEX($M$43:$M$50,MATCH(IF(E47=1,B47-1,B47+1),$B$43:$B$50,0)) | S47: =--(K47+0.000001>=P47) | T47: =--(L47+0.000001>=Q47) | U47: =--(M47+0.000001>=R47) | V47: =IFERROR(--(AND($C$17="SUPPORTED",S47=1,T47=1,U47=1,ABS(O47-$D$5)<=0.01)),0)
B48: 5 | C48: 1 | D48: 0 | E48: 1 | F48: =IF(($C48)=1,0,MIN($D$21,MAX(0,$D$5-(IF($E$21>$E$21,(1-($C48))*$D$21,0)+IF($E$22>$E$21,(1-($D48))*$D$22,0)+IF($E$23>$E$21,(1-($E48))*$D$23,0))))) | G48: =IF(($D48)=1,0,MIN($D$22,MAX(0,$D$5-(IF($E$21>$E$22,(1-($C48))*$D$21,0)+IF($E$22>$E$22,(1-($D48))*$D$22,0)+IF($E$23>$E$22,(1-($E48))*$D$23,0))))) | H48: =IF(($E48)=1,0,MIN($D$23,MAX(0,$D$5-(IF($E$21>$E$23,(1-($C48))*$D$21,0)+IF($E$22>$E$23,(1-($D48))*$D$22,0)+IF($E$23>$E$23,(1-($E48))*$D$23,0))))) | I48: =MAX(0,$D$5-SUM(F48:H48)) | J48: =$C$24+C48*$C$21+D48*$C$22+E48*$C$23 | K48: =IF(C48=1,IFERROR(I48*$C$21/J48,0),F48) | L48: =IF(D48=1,IFERROR(I48*$C$22/J48,0),G48) | M48: =IF(E48=1,IFERROR(I48*$C$23/J48,0),H48) | N48: =IFERROR(I48*$C$24/J48,0) | O48: =SUM(K48:N48) | P48: =INDEX($K$43:$K$50,MATCH(IF(C48=1,B48-4,B48+4),$B$43:$B$50,0)) | Q48: =INDEX($L$43:$L$50,MATCH(IF(D48=1,B48-2,B48+2),$B$43:$B$50,0)) | R48: =INDEX($M$43:$M$50,MATCH(IF(E48=1,B48-1,B48+1),$B$43:$B$50,0)) | S48: =--(K48+0.000001>=P48) | T48: =--(L48+0.000001>=Q48) | U48: =--(M48+0.000001>=R48) | V48: =IFERROR(--(AND($C$17="SUPPORTED",S48=1,T48=1,U48=1,ABS(O48-$D$5)<=0.01)),0)
B49: 6 | C49: 1 | D49: 1 | E49: 0 | F49: =IF(($C49)=1,0,MIN($D$21,MAX(0,$D$5-(IF($E$21>$E$21,(1-($C49))*$D$21,0)+IF($E$22>$E$21,(1-($D49))*$D$22,0)+IF($E$23>$E$21,(1-($E49))*$D$23,0))))) | G49: =IF(($D49)=1,0,MIN($D$22,MAX(0,$D$5-(IF($E$21>$E$22,(1-($C49))*$D$21,0)+IF($E$22>$E$22,(1-($D49))*$D$22,0)+IF($E$23>$E$22,(1-($E49))*$D$23,0))))) | H49: =IF(($E49)=1,0,MIN($D$23,MAX(0,$D$5-(IF($E$21>$E$23,(1-($C49))*$D$21,0)+IF($E$22>$E$23,(1-($D49))*$D$22,0)+IF($E$23>$E$23,(1-($E49))*$D$23,0))))) | I49: =MAX(0,$D$5-SUM(F49:H49)) | J49: =$C$24+C49*$C$21+D49*$C$22+E49*$C$23 | K49: =IF(C49=1,IFERROR(I49*$C$21/J49,0),F49) | L49: =IF(D49=1,IFERROR(I49*$C$22/J49,0),G49) | M49: =IF(E49=1,IFERROR(I49*$C$23/J49,0),H49) | N49: =IFERROR(I49*$C$24/J49,0) | O49: =SUM(K49:N49) | P49: =INDEX($K$43:$K$50,MATCH(IF(C49=1,B49-4,B49+4),$B$43:$B$50,0)) | Q49: =INDEX($L$43:$L$50,MATCH(IF(D49=1,B49-2,B49+2),$B$43:$B$50,0)) | R49: =INDEX($M$43:$M$50,MATCH(IF(E49=1,B49-1,B49+1),$B$43:$B$50,0)) | S49: =--(K49+0.000001>=P49) | T49: =--(L49+0.000001>=Q49) | U49: =--(M49+0.000001>=R49) | V49: =IFERROR(--(AND($C$17="SUPPORTED",S49=1,T49=1,U49=1,ABS(O49-$D$5)<=0.01)),0)
B50: 7 | C50: 1 | D50: 1 | E50: 1 | F50: =IF(($C50)=1,0,MIN($D$21,MAX(0,$D$5-(IF($E$21>$E$21,(1-($C50))*$D$21,0)+IF($E$22>$E$21,(1-($D50))*$D$22,0)+IF($E$23>$E$21,(1-($E50))*$D$23,0))))) | G50: =IF(($D50)=1,0,MIN($D$22,MAX(0,$D$5-(IF($E$21>$E$22,(1-($C50))*$D$21,0)+IF($E$22>$E$22,(1-($D50))*$D$22,0)+IF($E$23>$E$22,(1-($E50))*$D$23,0))))) | H50: =IF(($E50)=1,0,MIN($D$23,MAX(0,$D$5-(IF($E$21>$E$23,(1-($C50))*$D$21,0)+IF($E$22>$E$23,(1-($D50))*$D$22,0)+IF($E$23>$E$23,(1-($E50))*$D$23,0))))) | I50: =MAX(0,$D$5-SUM(F50:H50)) | J50: =$C$24+C50*$C$21+D50*$C$22+E50*$C$23 | K50: =IF(C50=1,IFERROR(I50*$C$21/J50,0),F50) | L50: =IF(D50=1,IFERROR(I50*$C$22/J50,0),G50) | M50: =IF(E50=1,IFERROR(I50*$C$23/J50,0),H50) | N50: =IFERROR(I50*$C$24/J50,0) | O50: =SUM(K50:N50) | P50: =INDEX($K$43:$K$50,MATCH(IF(C50=1,B50-4,B50+4),$B$43:$B$50,0)) | Q50: =INDEX($L$43:$L$50,MATCH(IF(D50=1,B50-2,B50+2),$B$43:$B$50,0)) | R50: =INDEX($M$43:$M$50,MATCH(IF(E50=1,B50-1,B50+1),$B$43:$B$50,0)) | S50: =--(K50+0.000001>=P50) | T50: =--(L50+0.000001>=Q50) | U50: =--(M50+0.000001>=R50) | V50: =IFERROR(--(AND($C$17="SUPPORTED",S50=1,T50=1,U50=1,ABS(O50-$D$5)<=0.01)),0)

Sheet Decision & Checks
B2: Venture Capital Decision Dashboard and Independent Checks
B4: Check / decision | C4: Metric | D4: Status | E4: Interpretation / action
B5: Post-money identity residual | C5: ='Ownership & Dilution'!D15-'Ownership & Dilution'!D5-'Ownership & Dilution'!D6 | D5: =IF(ABS(C5)<0.01,"PASS","FAIL") | E5: Post-money value must equal pre-money value plus new investment.
B6: Ownership conservation residual | C6: ='Ownership & Dilution'!D17+'Ownership & Dilution'!D18+'Ownership & Dilution'!D19-1 | D6: =IF(ABS(C6)<0.000001,"PASS","FAIL") | E6: Investor, founder, and option-pool ownership must sum to one.
B7: Follow-on reserve gap | C7: ='Reserves & Follow-ons'!D11 | D7: =IF(C7=0,"PASS","BREACH") | E7: Reserves must cover approved follow-on requirements.
B8: Investor ownership | C8: ='Ownership & Dilution'!D17 | D8: =IF(C8<='Ownership & Dilution'!D10,"PASS","BREACH") | E8: Escalate ownership concentration and governance terms.
B9: Option-pool dilution | C9: ='Ownership & Dilution'!D19 | D9: =IF(C9<='Ownership & Dilution'!D11,"PASS","BREACH") | E9: Pool expansion must remain within the approved dilution boundary.
B10: Round pricing | C10: ='Ownership & Dilution'!D20-'Ownership & Dilution'!D21 | D10: =IF(C10>=0,"PASS","BREACH") | E10: A negative price delta indicates a down round.
B11: Gross MOIC | C11: ='Exit Waterfall'!D13 | D11: =IF(C11>='Exit Waterfall'!D7,"PASS","BREACH") | E11: Exit proceeds must clear the approved return threshold.
B12: Liquidation terms supported | C12: ='Exit Waterfall'!C17 | D12: =IF(C12="SUPPORTED","PASS","REVIEW") | E12: Participating preferred, caps, duplicate seniority, or incomplete conversion terms require a dedicated legal waterfall.
B13: Base holder-election equilibrium | C13: ='Exit Waterfall'!I28 | D13: =IF(C13="NONE","FAIL","PASS") | E13: The selected base election must admit no profitable unilateral conversion change.
B14: Adverse holder-election equilibrium | C14: ='Exit Waterfall'!K28 | D14: =IF(C14="NONE","FAIL","PASS") | E14: The selected adverse election must admit no profitable unilateral conversion change.
B15: Base liquidation conservation | C15: ='Exit Waterfall'!I27 | D15: =IF(ABS(C15)<0.01,"PASS","FAIL") | E15: Base preferred and common payouts must equal total exit proceeds.
B16: Adverse liquidation conservation | C16: ='Exit Waterfall'!K27 | D16: =IF(ABS(C16)<0.01,"PASS","FAIL") | E16: Adverse preferred and common payouts must equal total exit proceeds.
B18: Overall model status | C18: =IF(COUNTIF(D5:D16,"FAIL")+COUNTIF(D5:D16,"BREACH")>0,"BREACH",IF(COUNTIF(D5:D16,"REVIEW")>0,"REVIEW","PASS"))
