Workbook
Name FS_MODEL_ID: 'Institutional Surface'!$C$4
Name FS_DOMAIN: 'Institutional Surface'!$C$5
Name FS_MATURITY: 'Institutional Surface'!$C$6

Sheet Cover
B2: [UNDERLYING] — Options & Derivatives Model
B4: Underlying: | C4: [Ticker / index / FX / commodity]
B5: Use case: | C5: Pricing / volatility / portfolio risk
B6: Last refreshed: | C6: [date]
B7: Next expiry / event: | C7: [date]
B8: Refresh cadence: | C8: Daily near expiry; weekly otherwise
B9: Active scenario: | C9: Base
B10: Units: | C10: Per option unless noted
B13: Modeling conventions
B14: Blue text / yellow fill | C14: Hardcoded input or selected scenario
B15: Black text | C15: Formula / same-sheet calculation
B16: Green text | C16: Cross-sheet formula / link
B17: Checks | C17: PASS / REVIEW / FAIL must remain visible

Sheet Institutional Surface
B2: Options & Derivatives — Institutional Decision Surface
B4: Model ID | C4: 14
B5: Domain | C5: Options & Derivatives
B6: Declared maturity | C6: M2
B7: Canonical builder | C7: tools/builders/build_options_release.py
B8: Decision arena | C8: trading desk, market making, independent risk and model validation
B9: Committee artifact | C9: volatility and Greeks risk pack
B10: Operating cadence | C10: intraday desk; daily risk and margin
B12: Key decision outputs
B13: # | C13: Requirement | D13: Owner | E13: Evidence / location | F13: Status
B14: 1 | C14: fair value and implied volatility | F14: OPEN
B15: 2 | C15: surface and skew | F15: OPEN
B16: 3 | C16: portfolio Greeks | F16: OPEN
B17: 4 | C17: base, downside and break-even outputs | F17: OPEN
B18: 5 | C18: liquidity / funding requirement and binding constraint | F18: OPEN
B20: Insider questions
B21: # | C21: Requirement | D21: Owner | E21: Evidence / location | F21: Status
B22: 1 | C22: What surface convention drives the hedge? | F22: OPEN
B23: 2 | C23: Where is the wing marked by model, not market? | F23: OPEN
B24: 3 | C24: Which Greeks are unstable near expiry? | F24: OPEN
B25: 4 | C25: Which assumption is owner-approved versus modeler judgement? | F25: OPEN
B26: 5 | C26: What fails first and who must act? | F26: OPEN
B28: Scenario families
B29: # | C29: Requirement | D29: Owner | E29: Evidence / location | F29: Status
B30: 1 | C30: spot jump | F30: OPEN
B31: 2 | C31: parallel and localized vol shock | F31: OPEN
B32: 3 | C32: skew twist | F32: OPEN
B33: 4 | C33: data freshness / source failure | F33: OPEN
B34: 5 | C34: combined severe-but-plausible downside | F34: OPEN
B36: Primary diligence documents
B37: # | C37: Requirement | D37: Owner | E37: Evidence / location | F37: Status
B38: 1 | C38: confirmations and master agreements | F38: OPEN
B39: 2 | C39: exchange specifications | F39: OPEN
B40: 3 | C40: volatility and market-data policy | F40: OPEN
B41: 4 | C41: approved model card and assumption register | F41: OPEN
B42: 5 | C42: independent validation and challenge record | F42: OPEN
B44: Challenge tests
B45: # | C45: Requirement | D45: Owner | E45: Evidence / location | F45: Status
B46: 1 | C46: put-call parity | F46: OPEN
B47: 2 | C47: price bounds | F47: OPEN
...

Sheet Challenge Log
B2: Independent Challenge, Override and Closure Log
B4: Date | C4: Reviewer | D4: Challenge | E4: Owner response | F4: Evidence | G4: Impact | H4: Status | I4: Closure
D5: put-call parity | H5: OPEN
D6: price bounds | H6: OPEN
D7: surface calendar and butterfly arbitrage | H7: OPEN
D8: source-to-model lineage is reproducible | H8: OPEN
D9: units, signs, dates and legal definitions reconcile | H9: OPEN

Sheet Lineage Map
B2: Source, Transformation, Ownership and Refresh Map
B4: Source class | C4: Cadence | D4: Control | E4: System / provider | F4: As-of | G4: Owner | H4: Transform | I4: Downstream | J4: Status
B5: spot / forwards / rates | C5: intraday | D5: timestamp and market hierarchy | J5: TO MAP
B6: volatility surface | C6: intraday/daily | D6: arbitrage and stale-point controls | J6: TO MAP
B7: model governance evidence | C7: per release | D7: version, reviewer, sign-off and change log | J7: TO MAP
B8: decision-use snapshot | C8: per decision | D8: immutable as-of date and source receipt | J8: TO MAP

Sheet Assumptions
B2: Pricing and Risk Assumptions
B4: Assumption | C4: Base | D4: Downside | E4: Active | F4: Units / note
B5: Spot price | C5: 100 | D5: 80 | E5: =IF(Cover!$C$9="Downside",D5,C5) | F5: currency
B6: Strike price | C6: 100 | D6: 100 | E6: =IF(Cover!$C$9="Downside",D6,C6) | F6: currency
B7: Time to expiry | C7: 0.5 | D7: 0.5 | E7: =IF(Cover!$C$9="Downside",D7,C7) | F7: years
B8: Risk-free rate | C8: 0.04 | D8: 0.03 | E8: =IF(Cover!$C$9="Downside",D8,C8) | F8: %
B9: Dividend yield | C9: 0.01 | D9: 0.01 | E9: =IF(Cover!$C$9="Downside",D9,C9) | F9: %
B10: Implied volatility | C10: 0.25 | D10: 0.45 | E10: =IF(Cover!$C$9="Downside",D10,C10) | F10: %
B11: Observed call price | C11: 8.25 | D11: 15 | E11: =IF(Cover!$C$9="Downside",D11,C11) | F11: currency
B12: Contract multiplier | C12: 100 | D12: 100 | E12: =IF(Cover!$C$9="Downside",D12,C12) | F12: units
B13: Position count | C13: 10 | D13: 10 | E13: =IF(Cover!$C$9="Downside",D13,C13) | F13: contracts
B14: Strike skew slope | C14: -0.2 | D14: -0.3 | E14: =IF(Cover!$C$9="Downside",D14,C14) | F14: vol per moneyness
B15: Term-vol slope | C15: 0.02 | D15: 0.04 | E15: =IF(Cover!$C$9="Downside",D15,C15) | F15: vol per log-year

Sheet European Pricer
B2: European Black-Scholes Pricer
B4: Metric | C4: Value | D4: Units | E4: Formula role | F4: Control
B5: d1 | C5: =(LN(Assumptions!E5/Assumptions!E6)+(Assumptions!E8-Assumptions!E9+0.5*Assumptions!E10^2)*Assumptions!E7)/(Assumptions!E10*SQRT(Assumptions!E7)) | D5: z | E5: standardized moneyness
B6: d2 | C6: =C5-Assumptions!E10*SQRT(Assumptions!E7) | D6: z | E6: d1 less volatility-time
B7: Call price | C7: =Assumptions!E5*EXP(-Assumptions!E9*Assumptions!E7)*NORMSDIST(C5)-Assumptions!E6*EXP(-Assumptions!E8*Assumptions!E7)*NORMSDIST(C6) | D7: currency | E7: discounted expected payoff
B8: Put price | C8: =Assumptions!E6*EXP(-Assumptions!E8*Assumptions!E7)*NORMSDIST(-C6)-Assumptions!E5*EXP(-Assumptions!E9*Assumptions!E7)*NORMSDIST(-C5) | D8: currency | E8: discounted expected payoff
B9: Call intrinsic value | C9: =MAX(0,Assumptions!E5-Assumptions!E6) | D9: currency | E9: spot intrinsic
B10: Put intrinsic value | C10: =MAX(0,Assumptions!E6-Assumptions!E5) | D10: currency | E10: spot intrinsic
B11: Call time value | C11: =C7-C9 | D11: currency | E11: price less intrinsic
B12: Put time value | C12: =C8-C10 | D12: currency | E12: price less intrinsic
B13: Put-call parity residual | C13: =C7-C8-(Assumptions!E5*EXP(-Assumptions!E9*Assumptions!E7)-Assumptions!E6*EXP(-Assumptions!E8*Assumptions!E7)) | D13: currency | E13: must equal zero | F13: =IF(ABS(C13)<0.000001,"PASS","FAIL")

Sheet Implied Vol
B2: Newton-Raphson Implied Volatility
B4: Iteration | C4: Volatility | D4: Model call | E4: Observed call | F4: Price error | G4: Vega
B5: 0 | C5: 0.2 | D5: =Assumptions!$E$5*EXP(-Assumptions!$E$9*Assumptions!$E$7)*NORMSDIST((LN(Assumptions!$E$5/Assumptions!$E$6)+(Assumptions!$E$8-Assumptions!$E$9+0.5*C5^2)*Assumptions!$E$7)/(C5*SQRT(Assumptions!$E$7)))-Assumptions!$E$6*EXP(-Assumptions!$E$8*Assumptions!$E$7)*NORMSDIST(((LN(Assumptions!$E$5/Assumptions!$E$6)+(Assumptions!$E$8-Assumptions!$E$9+0.5*C5^2)*Assumptions!$E$7)/(C5*SQRT(Assumptions!$E$7)))-C5*SQRT(Assumptions!$E$7)) | E5: =Assumptions!$E$11 | F5: =D5-E5 | G5: =Assumptions!$E$5*EXP(-Assumptions!$E$9*Assumptions!$E$7)*(EXP(-(((LN(Assumptions!$E$5/Assumptions!$E$6)+(Assumptions!$E$8-Assumptions!$E$9+0.5*C5^2)*Assumptions!$E$7)/(C5*SQRT(Assumptions!$E$7)))^2)/2)/SQRT(2*PI()))*SQRT(Assumptions!$E$7)
B6: 1 | C6: =MAX(0.0001,C5-F5/MAX(0.000001,G5)) | D6: =Assumptions!$E$5*EXP(-Assumptions!$E$9*Assumptions!$E$7)*NORMSDIST((LN(Assumptions!$E$5/Assumptions!$E$6)+(Assumptions!$E$8-Assumptions!$E$9+0.5*C6^2)*Assumptions!$E$7)/(C6*SQRT(Assumptions!$E$7)))-Assumptions!$E$6*EXP(-Assumptions!$E$8*Assumptions!$E$7)*NORMSDIST(((LN(Assumptions!$E$5/Assumptions!$E$6)+(Assumptions!$E$8-Assumptions!$E$9+0.5*C6^2)*Assumptions!$E$7)/(C6*SQRT(Assumptions!$E$7)))-C6*SQRT(Assumptions!$E$7)) | E6: =Assumptions!$E$11 | F6: =D6-E6 | G6: =Assumptions!$E$5*EXP(-Assumptions!$E$9*Assumptions!$E$7)*(EXP(-(((LN(Assumptions!$E$5/Assumptions!$E$6)+(Assumptions!$E$8-Assumptions!$E$9+0.5*C6^2)*Assumptions!$E$7)/(C6*SQRT(Assumptions!$E$7)))^2)/2)/SQRT(2*PI()))*SQRT(Assumptions!$E$7)
B7: 2 | C7: =MAX(0.0001,C6-F6/MAX(0.000001,G6)) | D7: =Assumptions!$E$5*EXP(-Assumptions!$E$9*Assumptions!$E$7)*NORMSDIST((LN(Assumptions!$E$5/Assumptions!$E$6)+(Assumptions!$E$8-Assumptions!$E$9+0.5*C7^2)*Assumptions!$E$7)/(C7*SQRT(Assumptions!$E$7)))-Assumptions!$E$6*EXP(-Assumptions!$E$8*Assumptions!$E$7)*NORMSDIST(((LN(Assumptions!$E$5/Assumptions!$E$6)+(Assumptions!$E$8-Assumptions!$E$9+0.5*C7^2)*Assumptions!$E$7)/(C7*SQRT(Assumptions!$E$7)))-C7*SQRT(Assumptions!$E$7)) | E7: =Assumptions!$E$11 | F7: =D7-E7 | G7: =Assumptions!$E$5*EXP(-Assumptions!$E$9*Assumptions!$E$7)*(EXP(-(((LN(Assumptions!$E$5/Assumptions!$E$6)+(Assumptions!$E$8-Assumptions!$E$9+0.5*C7^2)*Assumptions!$E$7)/(C7*SQRT(Assumptions!$E$7)))^2)/2)/SQRT(2*PI()))*SQRT(Assumptions!$E$7)
B8: 3 | C8: =MAX(0.0001,C7-F7/MAX(0.000001,G7)) | D8: =Assumptions!$E$5*EXP(-Assumptions!$E$9*Assumptions!$E$7)*NORMSDIST((LN(Assumptions!$E$5/Assumptions!$E$6)+(Assumptions!$E$8-Assumptions!$E$9+0.5*C8^2)*Assumptions!$E$7)/(C8*SQRT(Assumptions!$E$7)))-Assumptions!$E$6*EXP(-Assumptions!$E$8*Assumptions!$E$7)*NORMSDIST(((LN(Assumptions!$E$5/Assumptions!$E$6)+(Assumptions!$E$8-Assumptions!$E$9+0.5*C8^2)*Assumptions!$E$7)/(C8*SQRT(Assumptions!$E$7)))-C8*SQRT(Assumptions!$E$7)) | E8: =Assumptions!$E$11 | F8: =D8-E8 | G8: =Assumptions!$E$5*EXP(-Assumptions!$E$9*Assumptions!$E$7)*(EXP(-(((LN(Assumptions!$E$5/Assumptions!$E$6)+(Assumptions!$E$8-Assumptions!$E$9+0.5*C8^2)*Assumptions!$E$7)/(C8*SQRT(Assumptions!$E$7)))^2)/2)/SQRT(2*PI()))*SQRT(Assumptions!$E$7)
B9: 4 | C9: =MAX(0.0001,C8-F8/MAX(0.000001,G8)) | D9: =Assumptions!$E$5*EXP(-Assumptions!$E$9*Assumptions!$E$7)*NORMSDIST((LN(Assumptions!$E$5/Assumptions!$E$6)+(Assumptions!$E$8-Assumptions!$E$9+0.5*C9^2)*Assumptions!$E$7)/(C9*SQRT(Assumptions!$E$7)))-Assumptions!$E$6*EXP(-Assumptions!$E$8*Assumptions!$E$7)*NORMSDIST(((LN(Assumptions!$E$5/Assumptions!$E$6)+(Assumptions!$E$8-Assumptions!$E$9+0.5*C9^2)*Assumptions!$E$7)/(C9*SQRT(Assumptions!$E$7)))-C9*SQRT(Assumptions!$E$7)) | E9: =Assumptions!$E$11 | F9: =D9-E9 | G9: =Assumptions!$E$5*EXP(-Assumptions!$E$9*Assumptions!$E$7)*(EXP(-(((LN(Assumptions!$E$5/Assumptions!$E$6)+(Assumptions!$E$8-Assumptions!$E$9+0.5*C9^2)*Assumptions!$E$7)/(C9*SQRT(Assumptions!$E$7)))^2)/2)/SQRT(2*PI()))*SQRT(Assumptions!$E$7)
B10: 5 | C10: =MAX(0.0001,C9-F9/MAX(0.000001,G9)) | D10: =Assumptions!$E$5*EXP(-Assumptions!$E$9*Assumptions!$E$7)*NORMSDIST((LN(Assumptions!$E$5/Assumptions!$E$6)+(Assumptions!$E$8-Assumptions!$E$9+0.5*C10^2)*Assumptions!$E$7)/(C10*SQRT(Assumptions!$E$7)))-Assumptions!$E$6*EXP(-Assumptions!$E$8*Assumptions!$E$7)*NORMSDIST(((LN(Assumptions!$E$5/Assumptions!$E$6)+(Assumptions!$E$8-Assumptions!$E$9+0.5*C10^2)*Assumptions!$E$7)/(C10*SQRT(Assumptions!$E$7)))-C10*SQRT(Assumptions!$E$7)) | E10: =Assumptions!$E$11 | F10: =D10-E10 | G10: =Assumptions!$E$5*EXP(-Assumptions!$E$9*Assumptions!$E$7)*(EXP(-(((LN(Assumptions!$E$5/Assumptions!$E$6)+(Assumptions!$E$8-Assumptions!$E$9+0.5*C10^2)*Assumptions!$E$7)/(C10*SQRT(Assumptions!$E$7)))^2)/2)/SQRT(2*PI()))*SQRT(Assumptions!$E$7)
B11: 6 | C11: =MAX(0.0001,C10-F10/MAX(0.000001,G10)) | D11: =Assumptions!$E$5*EXP(-Assumptions!$E$9*Assumptions!$E$7)*NORMSDIST((LN(Assumptions!$E$5/Assumptions!$E$6)+(Assumptions!$E$8-Assumptions!$E$9+0.5*C11^2)*Assumptions!$E$7)/(C11*SQRT(Assumptions!$E$7)))-Assumptions!$E$6*EXP(-Assumptions!$E$8*Assumptions!$E$7)*NORMSDIST(((LN(Assumptions!$E$5/Assumptions!$E$6)+(Assumptions!$E$8-Assumptions!$E$9+0.5*C11^2)*Assumptions!$E$7)/(C11*SQRT(Assumptions!$E$7)))-C11*SQRT(Assumptions!$E$7)) | E11: =Assumptions!$E$11 | F11: =D11-E11 | G11: =Assumptions!$E$5*EXP(-Assumptions!$E$9*Assumptions!$E$7)*(EXP(-(((LN(Assumptions!$E$5/Assumptions!$E$6)+(Assumptions!$E$8-Assumptions!$E$9+0.5*C11^2)*Assumptions!$E$7)/(C11*SQRT(Assumptions!$E$7)))^2)/2)/SQRT(2*PI()))*SQRT(Assumptions!$E$7)
B12: 7 | C12: =MAX(0.0001,C11-F11/MAX(0.000001,G11)) | D12: =Assumptions!$E$5*EXP(-Assumptions!$E$9*Assumptions!$E$7)*NORMSDIST((LN(Assumptions!$E$5/Assumptions!$E$6)+(Assumptions!$E$8-Assumptions!$E$9+0.5*C12^2)*Assumptions!$E$7)/(C12*SQRT(Assumptions!$E$7)))-Assumptions!$E$6*EXP(-Assumptions!$E$8*Assumptions!$E$7)*NORMSDIST(((LN(Assumptions!$E$5/Assumptions!$E$6)+(Assumptions!$E$8-Assumptions!$E$9+0.5*C12^2)*Assumptions!$E$7)/(C12*SQRT(Assumptions!$E$7)))-C12*SQRT(Assumptions!$E$7)) | E12: =Assumptions!$E$11 | F12: =D12-E12 | G12: =Assumptions!$E$5*EXP(-Assumptions!$E$9*Assumptions!$E$7)*(EXP(-(((LN(Assumptions!$E$5/Assumptions!$E$6)+(Assumptions!$E$8-Assumptions!$E$9+0.5*C12^2)*Assumptions!$E$7)/(C12*SQRT(Assumptions!$E$7)))^2)/2)/SQRT(2*PI()))*SQRT(Assumptions!$E$7)
B13: 8 | C13: =MAX(0.0001,C12-F12/MAX(0.000001,G12)) | D13: =Assumptions!$E$5*EXP(-Assumptions!$E$9*Assumptions!$E$7)*NORMSDIST((LN(Assumptions!$E$5/Assumptions!$E$6)+(Assumptions!$E$8-Assumptions!$E$9+0.5*C13^2)*Assumptions!$E$7)/(C13*SQRT(Assumptions!$E$7)))-Assumptions!$E$6*EXP(-Assumptions!$E$8*Assumptions!$E$7)*NORMSDIST(((LN(Assumptions!$E$5/Assumptions!$E$6)+(Assumptions!$E$8-Assumptions!$E$9+0.5*C13^2)*Assumptions!$E$7)/(C13*SQRT(Assumptions!$E$7)))-C13*SQRT(Assumptions!$E$7)) | E13: =Assumptions!$E$11 | F13: =D13-E13 | G13: =Assumptions!$E$5*EXP(-Assumptions!$E$9*Assumptions!$E$7)*(EXP(-(((LN(Assumptions!$E$5/Assumptions!$E$6)+(Assumptions!$E$8-Assumptions!$E$9+0.5*C13^2)*Assumptions!$E$7)/(C13*SQRT(Assumptions!$E$7)))^2)/2)/SQRT(2*PI()))*SQRT(Assumptions!$E$7)
B14: 9 | C14: =MAX(0.0001,C13-F13/MAX(0.000001,G13)) | D14: =Assumptions!$E$5*EXP(-Assumptions!$E$9*Assumptions!$E$7)*NORMSDIST((LN(Assumptions!$E$5/Assumptions!$E$6)+(Assumptions!$E$8-Assumptions!$E$9+0.5*C14^2)*Assumptions!$E$7)/(C14*SQRT(Assumptions!$E$7)))-Assumptions!$E$6*EXP(-Assumptions!$E$8*Assumptions!$E$7)*NORMSDIST(((LN(Assumptions!$E$5/Assumptions!$E$6)+(Assumptions!$E$8-Assumptions!$E$9+0.5*C14^2)*Assumptions!$E$7)/(C14*SQRT(Assumptions!$E$7)))-C14*SQRT(Assumptions!$E$7)) | E14: =Assumptions!$E$11 | F14: =D14-E14 | G14: =Assumptions!$E$5*EXP(-Assumptions!$E$9*Assumptions!$E$7)*(EXP(-(((LN(Assumptions!$E$5/Assumptions!$E$6)+(Assumptions!$E$8-Assumptions!$E$9+0.5*C14^2)*Assumptions!$E$7)/(C14*SQRT(Assumptions!$E$7)))^2)/2)/SQRT(2*PI()))*SQRT(Assumptions!$E$7)
B17: Converged implied volatility | C17: =C14 | D17: Final absolute price error | E17: =ABS(F14)

Sheet Greeks
B2: European Greeks
B4: Greek | C4: Call | D4: Put | E4: Interpretation
B5: Delta | C5: =EXP(-Assumptions!$E$9*Assumptions!$E$7)*NORMSDIST('European Pricer'!$C$5) | D5: =EXP(-Assumptions!$E$9*Assumptions!$E$7)*(NORMSDIST('European Pricer'!$C$5)-1) | E5: first-order spot exposure
B6: Gamma | C6: =EXP(-Assumptions!$E$9*Assumptions!$E$7)*(EXP(-(('European Pricer'!$C$5)^2)/2)/SQRT(2*PI()))/(Assumptions!$E$5*Assumptions!$E$10*SQRT(Assumptions!$E$7)) | D6: =C6 | E6: delta curvature
B7: Vega | C7: =Assumptions!$E$5*EXP(-Assumptions!$E$9*Assumptions!$E$7)*(EXP(-(('European Pricer'!$C$5)^2)/2)/SQRT(2*PI()))*SQRT(Assumptions!$E$7) | D7: =C7 | E7: P&L per 100 vol points
B8: Theta / year | C8: =-Assumptions!$E$5*EXP(-Assumptions!$E$9*Assumptions!$E$7)*(EXP(-(('European Pricer'!$C$5)^2)/2)/SQRT(2*PI()))*Assumptions!$E$10/(2*SQRT(Assumptions!$E$7))-Assumptions!$E$8*Assumptions!$E$6*EXP(-Assumptions!$E$8*Assumptions!$E$7)*NORMSDIST('European Pricer'!$C$6)+Assumptions!$E$9*Assumptions!$E$5*EXP(-Assumptions!$E$9*Assumptions!$E$7)*NORMSDIST('European Pricer'!$C$5) | D8: =-Assumptions!$E$5*EXP(-Assumptions!$E$9*Assumptions!$E$7)*(EXP(-(('European Pricer'!$C$5)^2)/2)/SQRT(2*PI()))*Assumptions!$E$10/(2*SQRT(Assumptions!$E$7))+Assumptions!$E$8*Assumptions!$E$6*EXP(-Assumptions!$E$8*Assumptions!$E$7)*NORMSDIST(-'European Pricer'!$C$6)-Assumptions!$E$9*Assumptions!$E$5*EXP(-Assumptions!$E$9*Assumptions!$E$7)*NORMSDIST(-'European Pricer'!$C$5) | E8: annual time decay
B9: Rho | C9: =Assumptions!$E$7*Assumptions!$E$6*EXP(-Assumptions!$E$8*Assumptions!$E$7)*NORMSDIST('European Pricer'!$C$6) | D9: =-Assumptions!$E$7*Assumptions!$E$6*EXP(-Assumptions!$E$8*Assumptions!$E$7)*NORMSDIST(-'European Pricer'!$C$6) | E9: rate exposure

Sheet Vol Surface
B2: Illustrative Volatility Surface
B4: Maturity / Strike | C4: 80 | D4: 90 | E4: 100 | F4: 110 | G4: 120
B5: 0.25 | C5: =MAX(0.01,Assumptions!$E$10+Assumptions!$E$14*(C$4/Assumptions!$E$5-1)+Assumptions!$E$15*LN($B5/Assumptions!$E$7)) | D5: =MAX(0.01,Assumptions!$E$10+Assumptions!$E$14*(D$4/Assumptions!$E$5-1)+Assumptions!$E$15*LN($B5/Assumptions!$E$7)) | E5: =MAX(0.01,Assumptions!$E$10+Assumptions!$E$14*(E$4/Assumptions!$E$5-1)+Assumptions!$E$15*LN($B5/Assumptions!$E$7)) | F5: =MAX(0.01,Assumptions!$E$10+Assumptions!$E$14*(F$4/Assumptions!$E$5-1)+Assumptions!$E$15*LN($B5/Assumptions!$E$7)) | G5: =MAX(0.01,Assumptions!$E$10+Assumptions!$E$14*(G$4/Assumptions!$E$5-1)+Assumptions!$E$15*LN($B5/Assumptions!$E$7))
B6: 0.5 | C6: =MAX(0.01,Assumptions!$E$10+Assumptions!$E$14*(C$4/Assumptions!$E$5-1)+Assumptions!$E$15*LN($B6/Assumptions!$E$7)) | D6: =MAX(0.01,Assumptions!$E$10+Assumptions!$E$14*(D$4/Assumptions!$E$5-1)+Assumptions!$E$15*LN($B6/Assumptions!$E$7)) | E6: =MAX(0.01,Assumptions!$E$10+Assumptions!$E$14*(E$4/Assumptions!$E$5-1)+Assumptions!$E$15*LN($B6/Assumptions!$E$7)) | F6: =MAX(0.01,Assumptions!$E$10+Assumptions!$E$14*(F$4/Assumptions!$E$5-1)+Assumptions!$E$15*LN($B6/Assumptions!$E$7)) | G6: =MAX(0.01,Assumptions!$E$10+Assumptions!$E$14*(G$4/Assumptions!$E$5-1)+Assumptions!$E$15*LN($B6/Assumptions!$E$7))
B7: 1 | C7: =MAX(0.01,Assumptions!$E$10+Assumptions!$E$14*(C$4/Assumptions!$E$5-1)+Assumptions!$E$15*LN($B7/Assumptions!$E$7)) | D7: =MAX(0.01,Assumptions!$E$10+Assumptions!$E$14*(D$4/Assumptions!$E$5-1)+Assumptions!$E$15*LN($B7/Assumptions!$E$7)) | E7: =MAX(0.01,Assumptions!$E$10+Assumptions!$E$14*(E$4/Assumptions!$E$5-1)+Assumptions!$E$15*LN($B7/Assumptions!$E$7)) | F7: =MAX(0.01,Assumptions!$E$10+Assumptions!$E$14*(F$4/Assumptions!$E$5-1)+Assumptions!$E$15*LN($B7/Assumptions!$E$7)) | G7: =MAX(0.01,Assumptions!$E$10+Assumptions!$E$14*(G$4/Assumptions!$E$5-1)+Assumptions!$E$15*LN($B7/Assumptions!$E$7))
B8: 2 | C8: =MAX(0.01,Assumptions!$E$10+Assumptions!$E$14*(C$4/Assumptions!$E$5-1)+Assumptions!$E$15*LN($B8/Assumptions!$E$7)) | D8: =MAX(0.01,Assumptions!$E$10+Assumptions!$E$14*(D$4/Assumptions!$E$5-1)+Assumptions!$E$15*LN($B8/Assumptions!$E$7)) | E8: =MAX(0.01,Assumptions!$E$10+Assumptions!$E$14*(E$4/Assumptions!$E$5-1)+Assumptions!$E$15*LN($B8/Assumptions!$E$7)) | F8: =MAX(0.01,Assumptions!$E$10+Assumptions!$E$14*(F$4/Assumptions!$E$5-1)+Assumptions!$E$15*LN($B8/Assumptions!$E$7)) | G8: =MAX(0.01,Assumptions!$E$10+Assumptions!$E$14*(G$4/Assumptions!$E$5-1)+Assumptions!$E$15*LN($B8/Assumptions!$E$7))

Sheet Portfolio
B2: Options Portfolio Greeks
B4: Leg | C4: Type | D4: Quantity | E4: Strike | F4: Maturity | G4: Vol | H4: Price | I4: Delta | J4: Gamma | K4: Vega | L4: Theta | M4: Market value
B5: Core call | C5: Call | D5: 10 | E5: 100 | F5: 0.5 | G5: 0.25 | H5: =IF($C5="Call",Assumptions!$E$5*EXP(-Assumptions!$E$9*F5)*NORMSDIST((LN(Assumptions!$E$5/E5)+(Assumptions!$E$8-Assumptions!$E$9+0.5*G5^2)*F5)/(G5*SQRT(F5)))-E5*EXP(-Assumptions!$E$8*F5)*NORMSDIST(((LN(Assumptions!$E$5/E5)+(Assumptions!$E$8-Assumptions!$E$9+0.5*G5^2)*F5)/(G5*SQRT(F5)))-G5*SQRT(F5)),E5*EXP(-Assumptions!$E$8*F5)*NORMSDIST(-(((LN(Assumptions!$E$5/E5)+(Assumptions!$E$8-Assumptions!$E$9+0.5*G5^2)*F5)/(G5*SQRT(F5)))-G5*SQRT(F5)))-Assumptions!$E$5*EXP(-Assumptions!$E$9*F5)*NORMSDIST(-((LN(Assumptions!$E$5/E5)+(Assumptions!$E$8-Assumptions!$E$9+0.5*G5^2)*F5)/(G5*SQRT(F5))))) | I5: =IF($C5="Call",EXP(-Assumptions!$E$9*F5)*NORMSDIST((LN(Assumptions!$E$5/E5)+(Assumptions!$E$8-Assumptions!$E$9+0.5*G5^2)*F5)/(G5*SQRT(F5))),EXP(-Assumptions!$E$9*F5)*(NORMSDIST((LN(Assumptions!$E$5/E5)+(Assumptions!$E$8-Assumptions!$E$9+0.5*G5^2)*F5)/(G5*SQRT(F5)))-1))*D5 | J5: =EXP(-Assumptions!$E$9*F5)*(EXP(-(((LN(Assumptions!$E$5/E5)+(Assumptions!$E$8-Assumptions!$E$9+0.5*G5^2)*F5)/(G5*SQRT(F5)))^2)/2)/SQRT(2*PI()))/(Assumptions!$E$5*G5*SQRT(F5))*D5 | K5: =Assumptions!$E$5*EXP(-Assumptions!$E$9*F5)*(EXP(-(((LN(Assumptions!$E$5/E5)+(Assumptions!$E$8-Assumptions!$E$9+0.5*G5^2)*F5)/(G5*SQRT(F5)))^2)/2)/SQRT(2*PI()))*SQRT(F5)*D5 | L5: =-Assumptions!$E$5*EXP(-Assumptions!$E$9*F5)*(EXP(-(((LN(Assumptions!$E$5/E5)+(Assumptions!$E$8-Assumptions!$E$9+0.5*G5^2)*F5)/(G5*SQRT(F5)))^2)/2)/SQRT(2*PI()))*G5/(2*SQRT(F5))*D5 | M5: =H5*D5*Assumptions!$E$12
B6: Protective put | C6: Put | D6: 10 | E6: 90 | F6: 0.5 | G6: 0.3 | H6: =IF($C6="Call",Assumptions!$E$5*EXP(-Assumptions!$E$9*F6)*NORMSDIST((LN(Assumptions!$E$5/E6)+(Assumptions!$E$8-Assumptions!$E$9+0.5*G6^2)*F6)/(G6*SQRT(F6)))-E6*EXP(-Assumptions!$E$8*F6)*NORMSDIST(((LN(Assumptions!$E$5/E6)+(Assumptions!$E$8-Assumptions!$E$9+0.5*G6^2)*F6)/(G6*SQRT(F6)))-G6*SQRT(F6)),E6*EXP(-Assumptions!$E$8*F6)*NORMSDIST(-(((LN(Assumptions!$E$5/E6)+(Assumptions!$E$8-Assumptions!$E$9+0.5*G6^2)*F6)/(G6*SQRT(F6)))-G6*SQRT(F6)))-Assumptions!$E$5*EXP(-Assumptions!$E$9*F6)*NORMSDIST(-((LN(Assumptions!$E$5/E6)+(Assumptions!$E$8-Assumptions!$E$9+0.5*G6^2)*F6)/(G6*SQRT(F6))))) | I6: =IF($C6="Call",EXP(-Assumptions!$E$9*F6)*NORMSDIST((LN(Assumptions!$E$5/E6)+(Assumptions!$E$8-Assumptions!$E$9+0.5*G6^2)*F6)/(G6*SQRT(F6))),EXP(-Assumptions!$E$9*F6)*(NORMSDIST((LN(Assumptions!$E$5/E6)+(Assumptions!$E$8-Assumptions!$E$9+0.5*G6^2)*F6)/(G6*SQRT(F6)))-1))*D6 | J6: =EXP(-Assumptions!$E$9*F6)*(EXP(-(((LN(Assumptions!$E$5/E6)+(Assumptions!$E$8-Assumptions!$E$9+0.5*G6^2)*F6)/(G6*SQRT(F6)))^2)/2)/SQRT(2*PI()))/(Assumptions!$E$5*G6*SQRT(F6))*D6 | K6: =Assumptions!$E$5*EXP(-Assumptions!$E$9*F6)*(EXP(-(((LN(Assumptions!$E$5/E6)+(Assumptions!$E$8-Assumptions!$E$9+0.5*G6^2)*F6)/(G6*SQRT(F6)))^2)/2)/SQRT(2*PI()))*SQRT(F6)*D6 | L6: =-Assumptions!$E$5*EXP(-Assumptions!$E$9*F6)*(EXP(-(((LN(Assumptions!$E$5/E6)+(Assumptions!$E$8-Assumptions!$E$9+0.5*G6^2)*F6)/(G6*SQRT(F6)))^2)/2)/SQRT(2*PI()))*G6/(2*SQRT(F6))*D6 | M6: =H6*D6*Assumptions!$E$12
B7: Short call | C7: Call | D7: -5 | E7: 110 | F7: 0.5 | G7: 0.24 | H7: =IF($C7="Call",Assumptions!$E$5*EXP(-Assumptions!$E$9*F7)*NORMSDIST((LN(Assumptions!$E$5/E7)+(Assumptions!$E$8-Assumptions!$E$9+0.5*G7^2)*F7)/(G7*SQRT(F7)))-E7*EXP(-Assumptions!$E$8*F7)*NORMSDIST(((LN(Assumptions!$E$5/E7)+(Assumptions!$E$8-Assumptions!$E$9+0.5*G7^2)*F7)/(G7*SQRT(F7)))-G7*SQRT(F7)),E7*EXP(-Assumptions!$E$8*F7)*NORMSDIST(-(((LN(Assumptions!$E$5/E7)+(Assumptions!$E$8-Assumptions!$E$9+0.5*G7^2)*F7)/(G7*SQRT(F7)))-G7*SQRT(F7)))-Assumptions!$E$5*EXP(-Assumptions!$E$9*F7)*NORMSDIST(-((LN(Assumptions!$E$5/E7)+(Assumptions!$E$8-Assumptions!$E$9+0.5*G7^2)*F7)/(G7*SQRT(F7))))) | I7: =IF($C7="Call",EXP(-Assumptions!$E$9*F7)*NORMSDIST((LN(Assumptions!$E$5/E7)+(Assumptions!$E$8-Assumptions!$E$9+0.5*G7^2)*F7)/(G7*SQRT(F7))),EXP(-Assumptions!$E$9*F7)*(NORMSDIST((LN(Assumptions!$E$5/E7)+(Assumptions!$E$8-Assumptions!$E$9+0.5*G7^2)*F7)/(G7*SQRT(F7)))-1))*D7 | J7: =EXP(-Assumptions!$E$9*F7)*(EXP(-(((LN(Assumptions!$E$5/E7)+(Assumptions!$E$8-Assumptions!$E$9+0.5*G7^2)*F7)/(G7*SQRT(F7)))^2)/2)/SQRT(2*PI()))/(Assumptions!$E$5*G7*SQRT(F7))*D7 | K7: =Assumptions!$E$5*EXP(-Assumptions!$E$9*F7)*(EXP(-(((LN(Assumptions!$E$5/E7)+(Assumptions!$E$8-Assumptions!$E$9+0.5*G7^2)*F7)/(G7*SQRT(F7)))^2)/2)/SQRT(2*PI()))*SQRT(F7)*D7 | L7: =-Assumptions!$E$5*EXP(-Assumptions!$E$9*F7)*(EXP(-(((LN(Assumptions!$E$5/E7)+(Assumptions!$E$8-Assumptions!$E$9+0.5*G7^2)*F7)/(G7*SQRT(F7)))^2)/2)/SQRT(2*PI()))*G7/(2*SQRT(F7))*D7 | M7: =H7*D7*Assumptions!$E$12
B8: Long-dated call | C8: Call | D8: 4 | E8: 105 | F8: 1 | G8: 0.27 | H8: =IF($C8="Call",Assumptions!$E$5*EXP(-Assumptions!$E$9*F8)*NORMSDIST((LN(Assumptions!$E$5/E8)+(Assumptions!$E$8-Assumptions!$E$9+0.5*G8^2)*F8)/(G8*SQRT(F8)))-E8*EXP(-Assumptions!$E$8*F8)*NORMSDIST(((LN(Assumptions!$E$5/E8)+(Assumptions!$E$8-Assumptions!$E$9+0.5*G8^2)*F8)/(G8*SQRT(F8)))-G8*SQRT(F8)),E8*EXP(-Assumptions!$E$8*F8)*NORMSDIST(-(((LN(Assumptions!$E$5/E8)+(Assumptions!$E$8-Assumptions!$E$9+0.5*G8^2)*F8)/(G8*SQRT(F8)))-G8*SQRT(F8)))-Assumptions!$E$5*EXP(-Assumptions!$E$9*F8)*NORMSDIST(-((LN(Assumptions!$E$5/E8)+(Assumptions!$E$8-Assumptions!$E$9+0.5*G8^2)*F8)/(G8*SQRT(F8))))) | I8: =IF($C8="Call",EXP(-Assumptions!$E$9*F8)*NORMSDIST((LN(Assumptions!$E$5/E8)+(Assumptions!$E$8-Assumptions!$E$9+0.5*G8^2)*F8)/(G8*SQRT(F8))),EXP(-Assumptions!$E$9*F8)*(NORMSDIST((LN(Assumptions!$E$5/E8)+(Assumptions!$E$8-Assumptions!$E$9+0.5*G8^2)*F8)/(G8*SQRT(F8)))-1))*D8 | J8: =EXP(-Assumptions!$E$9*F8)*(EXP(-(((LN(Assumptions!$E$5/E8)+(Assumptions!$E$8-Assumptions!$E$9+0.5*G8^2)*F8)/(G8*SQRT(F8)))^2)/2)/SQRT(2*PI()))/(Assumptions!$E$5*G8*SQRT(F8))*D8 | K8: =Assumptions!$E$5*EXP(-Assumptions!$E$9*F8)*(EXP(-(((LN(Assumptions!$E$5/E8)+(Assumptions!$E$8-Assumptions!$E$9+0.5*G8^2)*F8)/(G8*SQRT(F8)))^2)/2)/SQRT(2*PI()))*SQRT(F8)*D8 | L8: =-Assumptions!$E$5*EXP(-Assumptions!$E$9*F8)*(EXP(-(((LN(Assumptions!$E$5/E8)+(Assumptions!$E$8-Assumptions!$E$9+0.5*G8^2)*F8)/(G8*SQRT(F8)))^2)/2)/SQRT(2*PI()))*G8/(2*SQRT(F8))*D8 | M8: =H8*D8*Assumptions!$E$12
B10: Portfolio total | I10: =SUM(I5:I8) | J10: =SUM(J5:J8) | K10: =SUM(K5:K8) | L10: =SUM(L5:L8) | M10: =SUM(M5:M8)

Sheet Scenario P&L
B2: Delta-Gamma-Vega Scenario P&L
B4: Spot shock / Vol shock | C4: -0.1 | D4: -0.05 | E4: 0 | F4: 0.05 | G4: 0.1
B5: -0.2 | C5: =Portfolio!$I$10*(Assumptions!$E$5*$B5)+0.5*Portfolio!$J$10*(Assumptions!$E$5*$B5)^2+Portfolio!$K$10*C$4 | D5: =Portfolio!$I$10*(Assumptions!$E$5*$B5)+0.5*Portfolio!$J$10*(Assumptions!$E$5*$B5)^2+Portfolio!$K$10*D$4 | E5: =Portfolio!$I$10*(Assumptions!$E$5*$B5)+0.5*Portfolio!$J$10*(Assumptions!$E$5*$B5)^2+Portfolio!$K$10*E$4 | F5: =Portfolio!$I$10*(Assumptions!$E$5*$B5)+0.5*Portfolio!$J$10*(Assumptions!$E$5*$B5)^2+Portfolio!$K$10*F$4 | G5: =Portfolio!$I$10*(Assumptions!$E$5*$B5)+0.5*Portfolio!$J$10*(Assumptions!$E$5*$B5)^2+Portfolio!$K$10*G$4
B6: -0.1 | C6: =Portfolio!$I$10*(Assumptions!$E$5*$B6)+0.5*Portfolio!$J$10*(Assumptions!$E$5*$B6)^2+Portfolio!$K$10*C$4 | D6: =Portfolio!$I$10*(Assumptions!$E$5*$B6)+0.5*Portfolio!$J$10*(Assumptions!$E$5*$B6)^2+Portfolio!$K$10*D$4 | E6: =Portfolio!$I$10*(Assumptions!$E$5*$B6)+0.5*Portfolio!$J$10*(Assumptions!$E$5*$B6)^2+Portfolio!$K$10*E$4 | F6: =Portfolio!$I$10*(Assumptions!$E$5*$B6)+0.5*Portfolio!$J$10*(Assumptions!$E$5*$B6)^2+Portfolio!$K$10*F$4 | G6: =Portfolio!$I$10*(Assumptions!$E$5*$B6)+0.5*Portfolio!$J$10*(Assumptions!$E$5*$B6)^2+Portfolio!$K$10*G$4
B7: 0 | C7: =Portfolio!$I$10*(Assumptions!$E$5*$B7)+0.5*Portfolio!$J$10*(Assumptions!$E$5*$B7)^2+Portfolio!$K$10*C$4 | D7: =Portfolio!$I$10*(Assumptions!$E$5*$B7)+0.5*Portfolio!$J$10*(Assumptions!$E$5*$B7)^2+Portfolio!$K$10*D$4 | E7: =Portfolio!$I$10*(Assumptions!$E$5*$B7)+0.5*Portfolio!$J$10*(Assumptions!$E$5*$B7)^2+Portfolio!$K$10*E$4 | F7: =Portfolio!$I$10*(Assumptions!$E$5*$B7)+0.5*Portfolio!$J$10*(Assumptions!$E$5*$B7)^2+Portfolio!$K$10*F$4 | G7: =Portfolio!$I$10*(Assumptions!$E$5*$B7)+0.5*Portfolio!$J$10*(Assumptions!$E$5*$B7)^2+Portfolio!$K$10*G$4
B8: 0.1 | C8: =Portfolio!$I$10*(Assumptions!$E$5*$B8)+0.5*Portfolio!$J$10*(Assumptions!$E$5*$B8)^2+Portfolio!$K$10*C$4 | D8: =Portfolio!$I$10*(Assumptions!$E$5*$B8)+0.5*Portfolio!$J$10*(Assumptions!$E$5*$B8)^2+Portfolio!$K$10*D$4 | E8: =Portfolio!$I$10*(Assumptions!$E$5*$B8)+0.5*Portfolio!$J$10*(Assumptions!$E$5*$B8)^2+Portfolio!$K$10*E$4 | F8: =Portfolio!$I$10*(Assumptions!$E$5*$B8)+0.5*Portfolio!$J$10*(Assumptions!$E$5*$B8)^2+Portfolio!$K$10*F$4 | G8: =Portfolio!$I$10*(Assumptions!$E$5*$B8)+0.5*Portfolio!$J$10*(Assumptions!$E$5*$B8)^2+Portfolio!$K$10*G$4
B9: 0.2 | C9: =Portfolio!$I$10*(Assumptions!$E$5*$B9)+0.5*Portfolio!$J$10*(Assumptions!$E$5*$B9)^2+Portfolio!$K$10*C$4 | D9: =Portfolio!$I$10*(Assumptions!$E$5*$B9)+0.5*Portfolio!$J$10*(Assumptions!$E$5*$B9)^2+Portfolio!$K$10*D$4 | E9: =Portfolio!$I$10*(Assumptions!$E$5*$B9)+0.5*Portfolio!$J$10*(Assumptions!$E$5*$B9)^2+Portfolio!$K$10*E$4 | F9: =Portfolio!$I$10*(Assumptions!$E$5*$B9)+0.5*Portfolio!$J$10*(Assumptions!$E$5*$B9)^2+Portfolio!$K$10*F$4 | G9: =Portfolio!$I$10*(Assumptions!$E$5*$B9)+0.5*Portfolio!$J$10*(Assumptions!$E$5*$B9)^2+Portfolio!$K$10*G$4

Sheet Checks
B2: Model Checks
B4: Check | C4: Status
B5: Put-call parity | C5: =IF(ABS('European Pricer'!C13)<0.000001,"PASS","FAIL")
B6: Implied volatility convergence | C6: =IF('Implied Vol'!E17<0.0001,"PASS","REVIEW")
B7: Gamma positive | C7: =IF(AND(Greeks!C6>0,Greeks!D6>0),"PASS","FAIL")
B8: Call price within bounds | C8: =IF(AND('European Pricer'!C7>=MAX(0,Assumptions!E5*EXP(-Assumptions!E9*Assumptions!E7)-Assumptions!E6*EXP(-Assumptions!E8*Assumptions!E7)),'European Pricer'!C7<=Assumptions!E5*EXP(-Assumptions!E9*Assumptions!E7)),"PASS","FAIL")
B9: Portfolio formulas populated | C9: =IF(COUNT(Portfolio!H5:M8)=24,"PASS","FAIL")
B10: Overall | C10: =IF(COUNTIF(C5:C9,"FAIL")=0,"PASS","FAIL")

Sheet Sources
B2: Source Register
B4: Input / dataset | C4: Source URL or document | D4: As-of | E4: Notes / transformation
B5: Option contract specification | C5: [exchange / broker URL] | D5: [date] | E5: Multiplier, expiry, settlement, exercise style
B6: Underlying and option market data | C6: [market data URL] | D6: [timestamp] | E6: Spot, bid/ask, implied volatility
B7: Risk-free curve | C7: https://home.treasury.gov/resource-center/data-chart-center/interest-rates | D7: [date] | E7: Document interpolation and currency basis
B8: Dividend / carry assumption | C8: [issuer or market source] | D8: [date] | E8: Expected dividends or foreign rates

Sheet RefreshLog
B2: Refresh Log
B4: Date | C4: Trigger | D4: Source snapshot | E4: What changed | F4: Reviewer / challenge | G4: Next check
