Workbook
Name FS_MODEL_ID: 'Institutional Surface'!$C$4
Name FS_DOMAIN: 'Institutional Surface'!$C$5
Name FS_MATURITY: 'Institutional Surface'!$C$6

Sheet Cover
B2: [PROPERTY/REIT] — Real Estate Model
B4: Property type: | C4: Office / Multifamily / Industrial / Retail
B5: Location: | C5: [fill in]
B6: Last refreshed: | C6: [date]
B7: Refresh cadence: | C7: Weekly

Sheet Institutional Surface
B2: Real Estate & REIT — Institutional Decision Surface
B4: Model ID | C4: 17
B5: Domain | C5: Real Estate & REIT
B6: Declared maturity | C6: M2
B7: Canonical builder | C7: tools/builders/build_real_estate_release.py
B8: Decision arena | C8: acquisitions, asset management, leasing, lender and investment committee
B9: Committee artifact | C9: asset underwriting and business-plan pack
B10: Operating cadence | C10: monthly asset management; quarterly valuation; annual plan
B12: Key decision outputs
B13: # | C13: Requirement | D13: Owner | E13: Evidence / location | F13: Status
B14: 1 | C14: NOI and cash flow | F14: OPEN
B15: 2 | C15: lease rollover and mark-to-market | F15: OPEN
B16: 3 | C16: tenant improvements / leasing commissions | F16: OPEN
B17: 4 | C17: base, downside and break-even outputs | F17: OPEN
B18: 5 | C18: liquidity / funding requirement and binding constraint | F18: OPEN
B20: Insider questions
B21: # | C21: Requirement | D21: Owner | E21: Evidence / location | F21: Status
B22: 1 | C22: Which leases drive the next two years of cash? | F22: OPEN
B23: 2 | C23: What downtime and TI/LC are required to re-lease? | F23: OPEN
B24: 3 | C24: What NOI is truly stabilized? | F24: OPEN
B25: 4 | C25: Which assumption is owner-approved versus modeler judgement? | F25: OPEN
B26: 5 | C26: What fails first and who must act? | F26: OPEN
B28: Scenario families
B29: # | C29: Requirement | D29: Owner | E29: Evidence / location | F29: Status
B30: 1 | C30: occupancy and rent decline | F30: OPEN
B31: 2 | C31: lease rollover concentration | F31: OPEN
B32: 3 | C32: cap-rate expansion | F32: OPEN
B33: 4 | C33: data freshness / source failure | F33: OPEN
B34: 5 | C34: combined severe-but-plausible downside | F34: OPEN
B36: Primary diligence documents
B37: # | C37: Requirement | D37: Owner | E37: Evidence / location | F37: Status
B38: 1 | C38: rent roll and leases | F38: OPEN
B39: 2 | C39: property operating statements | F39: OPEN
B40: 3 | C40: engineering / PCA report | F40: OPEN
B41: 4 | C41: approved model card and assumption register | F41: OPEN
B42: 5 | C42: independent validation and challenge record | F42: OPEN
B44: Challenge tests
B45: # | C45: Requirement | D45: Owner | E45: Evidence / location | F45: Status
B46: 1 | C46: rent roll ties to revenue | F46: OPEN
B47: 2 | C47: lease expirations reconcile | F47: OPEN
...

Sheet Challenge Log
B2: Independent Challenge, Override and Closure Log
B4: Date | C4: Reviewer | D4: Challenge | E4: Owner response | F4: Evidence | G4: Impact | H4: Status | I4: Closure
D5: rent roll ties to revenue | H5: OPEN
D6: lease expirations reconcile | H6: OPEN
D7: NOI excludes capital items consistently | H7: OPEN
D8: source-to-model lineage is reproducible | H8: OPEN
D9: units, signs, dates and legal definitions reconcile | H9: OPEN

Sheet Lineage Map
B2: Source, Transformation, Ownership and Refresh Map
B4: Source class | C4: Cadence | D4: Control | E4: System / provider | F4: As-of | G4: Owner | H4: Transform | I4: Downstream | J4: Status
B5: rent roll | C5: monthly | D5: lease-to-ledger tie | J5: TO MAP
B6: operating actuals | C6: monthly | D6: property and GL mapping | J6: TO MAP
B7: model governance evidence | C7: per release | D7: version, reviewer, sign-off and change log | J7: TO MAP
B8: decision-use snapshot | C8: per decision | D8: immutable as-of date and source receipt | J8: TO MAP

Sheet Property Pro Forma
B2: Property Pro Forma (annual, $)
B5: Gross potential rent | C5: 0
B6: Vacancy & credit loss | C6: 0
B7: Effective gross income | C7: =C5-C6
B8: + Other income (parking, fees) | C8: 0
B9: Total revenue | C9: =C7+C8
B10: Operating expenses (taxes, insurance, management, R&M) | C10: 0
B11: Net Operating Income (NOI) | C11: =C9-C10
B12: Recurring capex reserve | C12: 0
B13: Debt service (P&I) | C13: ='Debt Schedule'!E8
B14: Cash flow before tax | C14: =C11-C12-C13

Sheet Lease Roll
B2: Lease Expiration, Renewal, Downtime, and Occupancy Roll
B4: Year | C4: Beginning annual rent | D4: Expiring rent % | E4: Renewal probability | F4: Renewal spread | G4: Downtime months | H4: Lost rent | I4: Renewed rent | J4: Ending annual rent | K4: Economic occupancy
B5: 1 | C5: ='Property Pro Forma'!C5 | D5: 0.18 | E5: 0.75 | F5: 0.03 | G5: 3 | H5: =C5*D5*(1-E5)*G5/12 | I5: =C5*D5*E5*(1+F5) | J5: =C5*(1-D5)+I5 | K5: =IFERROR(1-H5/C5,0)
B6: 2 | C6: =J5 | D6: 0.2 | E6: 0.72 | F6: 0.03 | G6: 3 | H6: =C6*D6*(1-E6)*G6/12 | I6: =C6*D6*E6*(1+F6) | J6: =C6*(1-D6)+I6 | K6: =IFERROR(1-H6/C6,0)
B7: 3 | C7: =J6 | D7: 0.22 | E7: 0.7 | F7: 0.025 | G7: 4 | H7: =C7*D7*(1-E7)*G7/12 | I7: =C7*D7*E7*(1+F7) | J7: =C7*(1-D7)+I7 | K7: =IFERROR(1-H7/C7,0)
B8: 4 | C8: =J7 | D8: 0.18 | E8: 0.68 | F8: 0.02 | G8: 4 | H8: =C8*D8*(1-E8)*G8/12 | I8: =C8*D8*E8*(1+F8) | J8: =C8*(1-D8)+I8 | K8: =IFERROR(1-H8/C8,0)
B9: 5 | C9: =J8 | D9: 0.25 | E9: 0.65 | F9: 0.02 | G9: 5 | H9: =C9*D9*(1-E9)*G9/12 | I9: =C9*D9*E9*(1+F9) | J9: =C9*(1-D9)+I9 | K9: =IFERROR(1-H9/C9,0)
B12: This roll deliberately separates contractual expiration, renewal probability, spread, and downtime; new-leasing assumptions must be added explicitly rather than hidden in rent growth.

Sheet Cap Rate & Valuation
B2: Cap Rate Valuation
B4: NOI (from pro forma) | C4: ='Property Pro Forma'!C11
B5: Market cap rate % | C5: 0.06
B6: Implied value (NOI / cap rate) | C6: =IFERROR(C4/C5,"-")
B8: Purchase price ($) | C8: 0
B9: Going-in cap rate (NOI / price) | C9: =IFERROR(C4/C8,"-")
B10: Debt amount | C10: 0
B11: Cash-on-cash return | C11: =IFERROR('Property Pro Forma'!C14/(C8-C10),"-")

Sheet Debt Schedule
B2: Property Debt Amortization and Coverage
B3: Interest rate | C3: 0.06
B4: Amortization term (years) | C4: 25
B5: Minimum DSCR | C5: 1.25
B7: Year | C7: Beginning debt | D7: Interest | E7: Principal | F7: Debt service | G7: Ending debt | H7: NOI | I7: DSCR | J7: Headroom
B8: 1 | C8: ='Cap Rate & Valuation'!C10 | D8: =C8*$C$3 | E8: =D8+F8 | F8: =MIN(C8,MAX(0,-PMT($C$3,$C$4,'Cap Rate & Valuation'!$C$10)-D8)) | G8: =MAX(0,C8-F8) | H8: ='5-Year Hold & IRR'!C13 | I8: =IFERROR(H8/E8,0) | J8: =I8-$C$5
B9: 2 | C9: =G8 | D9: =C9*$C$3 | E9: =D9+F9 | F9: =MIN(C9,MAX(0,-PMT($C$3,$C$4,'Cap Rate & Valuation'!$C$10)-D9)) | G9: =MAX(0,C9-F9) | H9: ='5-Year Hold & IRR'!D13 | I9: =IFERROR(H9/E9,0) | J9: =I9-$C$5
B10: 3 | C10: =G9 | D10: =C10*$C$3 | E10: =D10+F10 | F10: =MIN(C10,MAX(0,-PMT($C$3,$C$4,'Cap Rate & Valuation'!$C$10)-D10)) | G10: =MAX(0,C10-F10) | H10: ='5-Year Hold & IRR'!E13 | I10: =IFERROR(H10/E10,0) | J10: =I10-$C$5
B11: 4 | C11: =G10 | D11: =C11*$C$3 | E11: =D11+F11 | F11: =MIN(C11,MAX(0,-PMT($C$3,$C$4,'Cap Rate & Valuation'!$C$10)-D11)) | G11: =MAX(0,C11-F11) | H11: ='5-Year Hold & IRR'!F13 | I11: =IFERROR(H11/E11,0) | J11: =I11-$C$5
B12: 5 | C12: =G11 | D12: =C12*$C$3 | E12: =D12+F12 | F12: =MIN(C12,MAX(0,-PMT($C$3,$C$4,'Cap Rate & Valuation'!$C$10)-D12)) | G12: =MAX(0,C12-F12) | H12: ='5-Year Hold & IRR'!G13 | I12: =IFERROR(H12/E12,0) | J12: =I12-$C$5

Sheet REIT FFO-AFFO
B2: REIT FFO / AFFO
B4: Net income (GAAP) | C4: 0
B5: + Real estate depreciation & amortization | C5: 0
B6: Gains on property sales | C6: 0
B7: FFO (Funds From Operations) | C7: =C4+C5-C6
B9: Recurring capex / leasing costs | C9: 0
B10: Straight-line rent adjustment | C10: 0
B11: AFFO (Adjusted FFO) | C11: =C7-C9-C10 | D11: AFFO is non-GAAP and must disclose its definition and reconciliation; this implementation deducts recurring capex and straight-line rent.
B13: Shares/units outstanding | C13: 1
B14: FFO / share | C14: =IFERROR(C7/C13,"-")
B15: AFFO / share | C15: =IFERROR(C11/C13,"-")

Sheet Decision & Checks
B2: Real Estate / REIT Decision Dashboard and Independent Checks
B4: Check / decision | C4: Metric | D4: Status | E4: Interpretation / action
B5: NOI identity residual | C5: ='Property Pro Forma'!C11-('Property Pro Forma'!C5-'Property Pro Forma'!C6+'Property Pro Forma'!C8-'Property Pro Forma'!C10) | D5: =IF(ABS(C5)<0.01,"PASS","FAIL") | E5: NOI must reconcile from gross rent through vacancy, other income, and operating expenses.
B6: FFO bridge residual | C6: ='REIT FFO-AFFO'!C7-('REIT FFO-AFFO'!C4+'REIT FFO-AFFO'!C5-'REIT FFO-AFFO'!C6) | D6: =IF(ABS(C6)<0.01,"PASS","FAIL") | E6: FFO must reconcile from GAAP net income under the disclosed Nareit-style definition.
B7: AFFO bridge residual | C7: ='REIT FFO-AFFO'!C11-('REIT FFO-AFFO'!C7-'REIT FFO-AFFO'!C9-'REIT FFO-AFFO'!C10) | D7: =IF(ABS(C7)<0.01,"PASS","FAIL") | E7: AFFO is non-GAAP; recurring capex and straight-line rent adjustments must be explicit.
B8: Minimum five-year DSCR | C8: =MIN('Debt Schedule'!I8:I12) | D8: =IF(C8>='Debt Schedule'!C5,"PASS",IF(C8>=1,"REVIEW","BREACH")) | E8: Escalate covenant pressure and refinance dependency.
B9: Loan-to-value | C9: =IFERROR('Cap Rate & Valuation'!C10/'Cap Rate & Valuation'!C8,0) | D9: =IF(C9<=0.75,"PASS",IF(C9<=0.85,"REVIEW","BREACH")) | E9: High leverage magnifies cap-rate and NOI shocks.
B10: Minimum economic occupancy | C10: =MIN('Lease Roll'!K5:K9) | D10: =IF(C10>=0.90,"PASS",IF(C10>=0.80,"REVIEW","BREACH")) | E10: Review tenant rollover, downtime, leasing costs, and concentration.
B11: Year-one levered cash flow | C11: ='Property Pro Forma'!C14 | D11: =IF(C11>=0,"PASS","BREACH") | E11: Negative cash flow requires funded reserves or a restructuring plan.
B12: Exit cap spread vs going-in | C12: =IF(AND(ISNUMBER('5-Year Hold & IRR'!C6),ISNUMBER('Cap Rate & Valuation'!C9)),'5-Year Hold & IRR'!C6-'Cap Rate & Valuation'!C9,0) | D12: =IF(AND(ISNUMBER('5-Year Hold & IRR'!C6),ISNUMBER('Cap Rate & Valuation'!C9)),IF(C12>=0,"PASS","REVIEW"),"REVIEW") | E12: Cap-rate compression should never be an unchallenged base-case return driver.
B14: Overall model status | C14: =IF(COUNTIF(D5:D12,"FAIL")+COUNTIF(D5:D12,"BREACH")>0,"BREACH",IF(COUNTIF(D5:D12,"REVIEW")>0,"REVIEW","PASS"))
B16: Primary decision outputs
B17: NOI | C17: ='Property Pro Forma'!C11
B18: Going-in cap rate | C18: ='Cap Rate & Valuation'!C9
B19: Levered IRR | C19: ='5-Year Hold & IRR'!C27
B20: Equity MOIC | C20: ='5-Year Hold & IRR'!C28
B21: FFO | C21: ='REIT FFO-AFFO'!C7
B22: AFFO | C22: ='REIT FFO-AFFO'!C11
B23: Ending debt | C23: ='Debt Schedule'!G12

Sheet 5-Year Hold & IRR
B2: 5-Year Hold — Levered Cash Flow & IRR
B4: Assumptions
B5: NOI growth rate (%/yr) | C5: 0.02
B6: Exit cap rate (%) | C6: 0.065
B7: Selling costs (% of exit value) | C7: 0.02
B8: Annual debt service ($, assumed constant / interest-only) | C8: =IFERROR(ABS('Property Pro Forma'!C13),"-")
B9: Initial equity (purchase price - debt) | C9: =IFERROR('Cap Rate & Valuation'!C8-'Cap Rate & Valuation'!C10,"-")
C12: Yr1 | D12: Yr2 | E12: Yr3 | F12: Yr4 | G12: Yr5
B13: NOI | C13: ='Property Pro Forma'!C11 | D13: =C13*(1+$C$5) | E13: =D13*(1+$C$5) | F13: =E13*(1+$C$5) | G13: =F13*(1+$C$5)
B14: Debt service | C14: ='Debt Schedule'!E8 | D14: ='Debt Schedule'!E9 | E14: ='Debt Schedule'!E10 | F14: ='Debt Schedule'!E11 | G14: ='Debt Schedule'!E12
B15: Levered cash flow | C15: =C13-C14 | D15: =D13-D14 | E15: =E13-E14 | F15: =F13-F14 | G15: =G13-G14
B16: DSCR (NOI / debt service) | C16: =IFERROR(C13/C14,0) | D16: =IFERROR(D13/D14,0) | E16: =IFERROR(E13/E14,0) | F16: =IFERROR(F13/F14,0) | G16: =IFERROR(G13/G14,0)
B18: Exit (end of Yr5)
B19: Forward NOI (Yr6, for exit cap) | C19: =G13*(1+$C$5)
B20: Exit value (forward NOI / exit cap rate) | C20: =IFERROR(C19/C6,"-")
B21: Less: selling costs | C21: =-C20*C7
B22: Less: debt payoff (assumed interest-only, balance unchanged) | C22: =-'Debt Schedule'!G12
B23: Net exit equity proceeds | C23: =C20+C21+C22
C25: Yr0 | D25: Yr1 | E25: Yr2 | F25: Yr3 | G25: Yr4 | H25: Yr5
B26: Equity cash flow | C26: =-C9 | D26: =C15 | E26: =D15 | F26: =E15 | G26: =F15 | H26: =G15+C23
B27: Levered IRR | C27: =IFERROR(IRR(C26:H26),"-")
B28: Equity multiple (MOIC) | C28: =IFERROR(SUM(D26:H26)/C9,"-")

Sheet RefreshLog
B2: Refresh Log
B4: Date | C4: Trigger | D4: What changed | E4: Reviewer notes | F4: Next check
