Workbook
Name FS_MODEL_ID: 'Institutional Surface'!$C$4
Name FS_DOMAIN: 'Institutional Surface'!$C$5
Name FS_MATURITY: 'Institutional Surface'!$C$6

Sheet Cover
B2: [INSURER / BOOK] — Insurance & Actuarial Model
B4: Entity / line of business: | C4: [Name / LOB]
B5: Valuation date: | C5: [date]
B6: Last refreshed: | C6: [date]
B7: Next reserve / capital review: | C7: [date]
B8: Refresh cadence: | C8: Quarterly and on material claims events
B9: Active scenario: | C9: Base
B10: Units: | C10: $ in millions unless noted
B13: Modeling conventions
B14: Blue text / yellow fill | C14: Hardcoded input or selected scenario
B15: Black text | C15: Formula / same-sheet calculation
B16: Green text | C16: Cross-sheet formula / link
B17: Checks | C17: PASS / REVIEW / FAIL must remain visible

Sheet Institutional Surface
B2: Insurance & Actuarial — Institutional Decision Surface
B4: Model ID | C4: 18
B5: Domain | C5: Insurance & Actuarial
B6: Declared maturity | C6: M2
B7: Canonical builder | C7: tools/builders/build_insurance_release.py
B8: Decision arena | C8: actuarial, underwriting, finance, capital committee and regulator
B9: Committee artifact | C9: reserve, profitability and capital pack
B10: Operating cadence | C10: monthly reserve monitoring; quarterly close; annual assumption review
B12: Key decision outputs
B13: # | C13: Requirement | D13: Owner | E13: Evidence / location | F13: Status
B14: 1 | C14: ultimate loss and reserve | F14: OPEN
B15: 2 | C15: loss ratio and combined ratio | F15: OPEN
B16: 3 | C16: new-business and embedded value | F16: OPEN
B17: 4 | C17: base, downside and break-even outputs | F17: OPEN
B18: 5 | C18: liquidity / funding requirement and binding constraint | F18: OPEN
B20: Insider questions
B21: # | C21: Requirement | D21: Owner | E21: Evidence / location | F21: Status
B22: 1 | C22: Which accident years are driving development? | F22: OPEN
B23: 2 | C23: What operational change broke historical comparability? | F23: OPEN
B24: 3 | C24: How collectible are reinsurance balances? | F24: OPEN
B25: 4 | C25: Which assumption is owner-approved versus modeler judgement? | F25: OPEN
B26: 5 | C26: What fails first and who must act? | F26: OPEN
B28: Scenario families
B29: # | C29: Requirement | D29: Owner | E29: Evidence / location | F29: Status
B30: 1 | C30: reserve deterioration | F30: OPEN
B31: 2 | C31: frequency / severity inflation | F31: OPEN
B32: 3 | C32: catastrophe event | F32: OPEN
B33: 4 | C33: data freshness / source failure | F33: OPEN
B34: 5 | C34: combined severe-but-plausible downside | F34: OPEN
B36: Primary diligence documents
B37: # | C37: Requirement | D37: Owner | E37: Evidence / location | F37: Status
B38: 1 | C38: policy and claims triangles | F38: OPEN
B39: 2 | C39: actuarial methods and assumptions | F39: OPEN
B40: 3 | C40: reinsurance treaties | F40: OPEN
B41: 4 | C41: approved model card and assumption register | F41: OPEN
B42: 5 | C42: independent validation and challenge record | F42: OPEN
B44: Challenge tests
B45: # | C45: Requirement | D45: Owner | E45: Evidence / location | F45: Status
B46: 1 | C46: triangle monotonicity where appropriate | F46: OPEN
B47: 2 | C47: development factors bounded and explained | F47: OPEN
...

Sheet Challenge Log
B2: Independent Challenge, Override and Closure Log
B4: Date | C4: Reviewer | D4: Challenge | E4: Owner response | F4: Evidence | G4: Impact | H4: Status | I4: Closure
D5: triangle monotonicity where appropriate | H5: OPEN
D6: development factors bounded and explained | H6: OPEN
D7: reserve roll-forward reconciles | H7: OPEN
D8: source-to-model lineage is reproducible | H8: OPEN
D9: units, signs, dates and legal definitions reconcile | H9: OPEN

Sheet Lineage Map
B2: Source, Transformation, Ownership and Refresh Map
B4: Source class | C4: Cadence | D4: Control | E4: System / provider | F4: As-of | G4: Owner | H4: Transform | I4: Downstream | J4: Status
B5: claims transactions | C5: monthly | D5: paid/incurred and claim-id reconciliation | J5: TO MAP
B6: exposure and premium | C6: monthly | D6: earned/written definition | J6: TO MAP
B7: model governance evidence | C7: per release | D7: version, reviewer, sign-off and change log | J7: TO MAP
B8: decision-use snapshot | C8: per decision | D8: immutable as-of date and source receipt | J8: TO MAP

Sheet Assumptions
B2: Actuarial, Underwriting, and Capital Assumptions
B4: Assumption | C4: Base | D4: Downside | E4: Active | F4: Units / note
B5: Expected loss ratio | C5: 0.62 | D5: 0.78 | E5: =IF(Cover!$C$9="Downside",D5,C5) | F5: %
B6: Expense ratio | C6: 0.28 | D6: 0.32 | E6: =IF(Cover!$C$9="Downside",D6,C6) | F6: %
B7: Annual premium growth | C7: 0.05 | D7: -0.05 | E7: =IF(Cover!$C$9="Downside",D7,C7) | F7: %
B8: Claims inflation | C8: 0.035 | D8: 0.075 | E8: =IF(Cover!$C$9="Downside",D8,C8) | F8: %
B9: Discount rate | C9: 0.045 | D9: 0.035 | E9: =IF(Cover!$C$9="Downside",D9,C9) | F9: %
B10: Risk margin / reserve | C10: 0.08 | D10: 0.15 | E10: =IF(Cover!$C$9="Downside",D10,C10) | F10: %
B11: Opening earned premium | C11: 500 | D11: 500 | E11: =IF(Cover!$C$9="Downside",D11,C11) | F11: $mm
B12: Opening invested assets | C12: 900 | D12: 900 | E12: =IF(Cover!$C$9="Downside",D12,C12) | F12: $mm
B13: Investment yield | C13: 0.04 | D13: 0.025 | E13: =IF(Cover!$C$9="Downside",D13,C13) | F13: %
B14: Opening available capital | C14: 350 | D14: 350 | E14: =IF(Cover!$C$9="Downside",D14,C14) | F14: $mm
B15: Premium risk factor | C15: 0.18 | D15: 0.24 | E15: =IF(Cover!$C$9="Downside",D15,C15) | F15: % premium
B16: Reserve risk factor | C16: 0.12 | D16: 0.18 | E16: =IF(Cover!$C$9="Downside",D16,C16) | F16: % reserve
... B20: Projection horizon | C20: 5 | D20: 5 | E20: =IF(Cover!$C$9="Downside",D20,C20) | F20: years

Sheet Paid Triangle
B2: Cumulative Paid Loss Triangle
B4: Accident year | C4: 12m | D4: 24m | E4: 36m | F4: 48m | G4: 60m | H4: 72m | I4: 84m | J4: 96m | K4: 108m | L4: 120m
B5: 2017 | C5: 64.4 | D5: 110.4 | E5: 144.9 | F5: 167.9 | G5: 186.3 | H5: 200.1 | I5: 209.3 | J5: 216.2 | K5: 223.1 | L5: 230
B6: 2018 | C6: 68.6 | D6: 117.6 | E6: 154.35 | F6: 178.85 | G6: 198.45 | H6: 213.15 | I6: 222.95 | J6: 230.3 | K6: 237.65
B7: 2019 | C7: 71.4 | D7: 122.4 | E7: 160.65 | F7: 186.15 | G7: 206.55 | H7: 221.85 | I7: 232.05 | J7: 239.7
B8: 2020 | C8: 75.6 | D8: 129.6 | E8: 170.1 | F8: 197.1 | G8: 218.7 | H8: 234.9 | I8: 245.7
B9: 2021 | C9: 79.8 | D9: 136.8 | E9: 179.55 | F9: 208.05 | G9: 230.85 | H9: 247.95
B10: 2022 | C10: 84 | D10: 144 | E10: 189 | F10: 219 | G10: 243
B11: 2023 | C11: 89.6 | D11: 153.6 | E11: 201.6 | F11: 233.6
B12: 2024 | C12: 93.8 | D12: 160.8 | E12: 211.05
B13: 2025 | C13: 99.4 | D13: 170.4
B14: 2026 | C14: 105

Sheet Chain Ladder
B2: Chain-Ladder Reserve Development
B4: Metric | C4: 12m | D4: 24m | E4: 36m | F4: 48m | G4: 60m | H4: 72m | I4: 84m | J4: 96m | K4: 108m | L4: 120m | M4: Ultimate | N4: Reserve
B5: Selected age-to-age factor | C5: =IFERROR(SUM('Paid Triangle'!D5:D13)/SUM('Paid Triangle'!C5:C13),1) | D5: =IFERROR(SUM('Paid Triangle'!E5:E12)/SUM('Paid Triangle'!D5:D12),1) | E5: =IFERROR(SUM('Paid Triangle'!F5:F11)/SUM('Paid Triangle'!E5:E11),1) | F5: =IFERROR(SUM('Paid Triangle'!G5:G10)/SUM('Paid Triangle'!F5:F10),1) | G5: =IFERROR(SUM('Paid Triangle'!H5:H9)/SUM('Paid Triangle'!G5:G9),1) | H5: =IFERROR(SUM('Paid Triangle'!I5:I8)/SUM('Paid Triangle'!H5:H8),1) | I5: =IFERROR(SUM('Paid Triangle'!J5:J7)/SUM('Paid Triangle'!I5:I7),1) | J5: =IFERROR(SUM('Paid Triangle'!K5:K6)/SUM('Paid Triangle'!J5:J6),1) | K5: =IFERROR(SUM('Paid Triangle'!L5:L5)/SUM('Paid Triangle'!K5:K5),1) | L5: 1
B6: Cumulative development factor | C6: =PRODUCT(C$5:$K$5) | D6: =PRODUCT(D$5:$K$5) | E6: =PRODUCT(E$5:$K$5) | F6: =PRODUCT(F$5:$K$5) | G6: =PRODUCT(G$5:$K$5) | H6: =PRODUCT(H$5:$K$5) | I6: =PRODUCT(I$5:$K$5) | J6: =PRODUCT(J$5:$K$5) | K6: =PRODUCT(K$5:$K$5) | L6: 1
B8: ='Paid Triangle'!B5 | C8: ='Paid Triangle'!C5 | D8: ='Paid Triangle'!D5 | E8: ='Paid Triangle'!E5 | F8: ='Paid Triangle'!F5 | G8: ='Paid Triangle'!G5 | H8: ='Paid Triangle'!H5 | I8: ='Paid Triangle'!I5 | ... L8: ='Paid Triangle'!L5 | M8: ='Paid Triangle'!L5*L$6 | N8: =M8-'Paid Triangle'!L5
B9: ='Paid Triangle'!B6 | C9: ='Paid Triangle'!C6 | D9: ='Paid Triangle'!D6 | E9: ='Paid Triangle'!E6 | F9: ='Paid Triangle'!F6 | G9: ='Paid Triangle'!G6 | H9: ='Paid Triangle'!H6 | I9: ='Paid Triangle'!I6 | ... K9: ='Paid Triangle'!K6 | M9: ='Paid Triangle'!K6*K$6 | N9: =M9-'Paid Triangle'!K6
B10: ='Paid Triangle'!B7 | C10: ='Paid Triangle'!C7 | D10: ='Paid Triangle'!D7 | E10: ='Paid Triangle'!E7 | F10: ='Paid Triangle'!F7 | G10: ='Paid Triangle'!G7 | H10: ='Paid Triangle'!H7 | I10: ='Paid Triangle'!I7 | J10: ='Paid Triangle'!J7 | M10: ='Paid Triangle'!J7*J$6 | N10: =M10-'Paid Triangle'!J7
B11: ='Paid Triangle'!B8 | C11: ='Paid Triangle'!C8 | D11: ='Paid Triangle'!D8 | E11: ='Paid Triangle'!E8 | F11: ='Paid Triangle'!F8 | G11: ='Paid Triangle'!G8 | H11: ='Paid Triangle'!H8 | I11: ='Paid Triangle'!I8 | M11: ='Paid Triangle'!I8*I$6 | N11: =M11-'Paid Triangle'!I8
B12: ='Paid Triangle'!B9 | C12: ='Paid Triangle'!C9 | D12: ='Paid Triangle'!D9 | E12: ='Paid Triangle'!E9 | F12: ='Paid Triangle'!F9 | G12: ='Paid Triangle'!G9 | H12: ='Paid Triangle'!H9 | M12: ='Paid Triangle'!H9*H$6 | N12: =M12-'Paid Triangle'!H9
B13: ='Paid Triangle'!B10 | C13: ='Paid Triangle'!C10 | D13: ='Paid Triangle'!D10 | E13: ='Paid Triangle'!E10 | F13: ='Paid Triangle'!F10 | G13: ='Paid Triangle'!G10 | M13: ='Paid Triangle'!G10*G$6 | N13: =M13-'Paid Triangle'!G10
B14: ='Paid Triangle'!B11 | C14: ='Paid Triangle'!C11 | D14: ='Paid Triangle'!D11 | E14: ='Paid Triangle'!E11 | F14: ='Paid Triangle'!F11 | M14: ='Paid Triangle'!F11*F$6 | N14: =M14-'Paid Triangle'!F11
B15: ='Paid Triangle'!B12 | C15: ='Paid Triangle'!C12 | D15: ='Paid Triangle'!D12 | E15: ='Paid Triangle'!E12 | M15: ='Paid Triangle'!E12*E$6 | N15: =M15-'Paid Triangle'!E12
B16: ='Paid Triangle'!B13 | C16: ='Paid Triangle'!C13 | D16: ='Paid Triangle'!D13 | M16: ='Paid Triangle'!D13*D$6 | N16: =M16-'Paid Triangle'!D13
B17: ='Paid Triangle'!B14 | C17: ='Paid Triangle'!C14 | M17: ='Paid Triangle'!C14*C$6 | N17: =M17-'Paid Triangle'!C14
B18: Total | M18: =SUM(M8:M17) | N18: =SUM(N8:N17)

Sheet Bornhuetter-Ferguson
B2: Bornhuetter-Ferguson Reserve Estimate
B4: Accident year | C4: Earned premium | D4: Expected loss | E4: % paid | F4: Paid to date | G4: BF ultimate | H4: BF reserve
B5: ='Chain Ladder'!B8 | C5: 400 | D5: =C5*Assumptions!$E$5*(1+Assumptions!$E$8)^0 | E5: =1/'Chain Ladder'!L$6 | F5: ='Paid Triangle'!L5 | G5: =F5+D5*(1-E5) | H5: =G5-F5
B6: ='Chain Ladder'!B9 | C6: 425 | D6: =C6*Assumptions!$E$5*(1+Assumptions!$E$8)^1 | E6: =1/'Chain Ladder'!K$6 | F6: ='Paid Triangle'!K6 | G6: =F6+D6*(1-E6) | H6: =G6-F6
B7: ='Chain Ladder'!B10 | C7: 450 | D7: =C7*Assumptions!$E$5*(1+Assumptions!$E$8)^2 | E7: =1/'Chain Ladder'!J$6 | F7: ='Paid Triangle'!J7 | G7: =F7+D7*(1-E7) | H7: =G7-F7
B8: ='Chain Ladder'!B11 | C8: 475 | D8: =C8*Assumptions!$E$5*(1+Assumptions!$E$8)^3 | E8: =1/'Chain Ladder'!I$6 | F8: ='Paid Triangle'!I8 | G8: =F8+D8*(1-E8) | H8: =G8-F8
B9: ='Chain Ladder'!B12 | C9: 500 | D9: =C9*Assumptions!$E$5*(1+Assumptions!$E$8)^4 | E9: =1/'Chain Ladder'!H$6 | F9: ='Paid Triangle'!H9 | G9: =F9+D9*(1-E9) | H9: =G9-F9
B10: ='Chain Ladder'!B13 | C10: 525 | D10: =C10*Assumptions!$E$5*(1+Assumptions!$E$8)^5 | E10: =1/'Chain Ladder'!G$6 | F10: ='Paid Triangle'!G10 | G10: =F10+D10*(1-E10) | H10: =G10-F10
B11: ='Chain Ladder'!B14 | C11: 550 | D11: =C11*Assumptions!$E$5*(1+Assumptions!$E$8)^6 | E11: =1/'Chain Ladder'!F$6 | F11: ='Paid Triangle'!F11 | G11: =F11+D11*(1-E11) | H11: =G11-F11
B12: ='Chain Ladder'!B15 | C12: 575 | D12: =C12*Assumptions!$E$5*(1+Assumptions!$E$8)^7 | E12: =1/'Chain Ladder'!E$6 | F12: ='Paid Triangle'!E12 | G12: =F12+D12*(1-E12) | H12: =G12-F12
B13: ='Chain Ladder'!B16 | C13: 600 | D13: =C13*Assumptions!$E$5*(1+Assumptions!$E$8)^8 | E13: =1/'Chain Ladder'!D$6 | F13: ='Paid Triangle'!D13 | G13: =F13+D13*(1-E13) | H13: =G13-F13
B14: ='Chain Ladder'!B17 | C14: 625 | D14: =C14*Assumptions!$E$5*(1+Assumptions!$E$8)^9 | E14: =1/'Chain Ladder'!C$6 | F14: ='Paid Triangle'!C14 | G14: =F14+D14*(1-E14) | H14: =G14-F14
B15: Total | C15: =SUM(C5:C14) | D15: =SUM(D5:D14) | F15: =SUM(F5:F14) | G15: =SUM(G5:G14) | H15: =SUM(H5:H14)

Sheet Underwriting
B2: Five-Year Underwriting Forecast
B4: $mm / % | C4: Year 1 | D4: Year 2 | E4: Year 3 | F4: Year 4 | G4: Year 5
B5: Earned premium | C5: =Assumptions!E11 | D5: =C5*(1+Assumptions!$E$7) | E5: =D5*(1+Assumptions!$E$7) | F5: =E5*(1+Assumptions!$E$7) | G5: =F5*(1+Assumptions!$E$7)
B6: Incurred losses | C6: =C5*Assumptions!$E$5*(1+Assumptions!$E$8)^0 | D6: =D5*Assumptions!$E$5*(1+Assumptions!$E$8)^1 | E6: =E5*Assumptions!$E$5*(1+Assumptions!$E$8)^2 | F6: =F5*Assumptions!$E$5*(1+Assumptions!$E$8)^3 | G6: =G5*Assumptions!$E$5*(1+Assumptions!$E$8)^4
B7: Underwriting expenses | C7: =C5*Assumptions!$E$6 | D7: =D5*Assumptions!$E$6 | E7: =E5*Assumptions!$E$6 | F7: =F5*Assumptions!$E$6 | G7: =G5*Assumptions!$E$6
B8: Underwriting result | C8: =C5-C6-C7 | D8: =D5-D6-D7 | E8: =E5-E6-E7 | F8: =F5-F6-F7 | G8: =G5-G6-G7
B9: Loss ratio | C9: =IFERROR(C6/C5,0) | D9: =IFERROR(D6/D5,0) | E9: =IFERROR(E6/E5,0) | F9: =IFERROR(F6/F5,0) | G9: =IFERROR(G6/G5,0)
B10: Expense ratio | C10: =IFERROR(C7/C5,0) | D10: =IFERROR(D7/D5,0) | E10: =IFERROR(E7/E5,0) | F10: =IFERROR(F7/F5,0) | G10: =IFERROR(G7/G5,0)
B11: Combined ratio | C11: =C9+C10 | D11: =D9+D10 | E11: =E9+E10 | F11: =F9+F10 | G11: =G9+G10
B12: Investment income | C12: =Assumptions!$E$12*Assumptions!$E$13 | D12: =Assumptions!$E$12*Assumptions!$E$13 | E12: =Assumptions!$E$12*Assumptions!$E$13 | F12: =Assumptions!$E$12*Assumptions!$E$13 | G12: =Assumptions!$E$12*Assumptions!$E$13
B13: Pre-tax operating income | C13: =C8+C12 | D13: =D8+D12 | E13: =E8+E12 | F13: =F8+F12 | G13: =G8+G12

Sheet Embedded Value
B2: Simplified Embedded Value
B4: Metric | C4: Year 1 | D4: Year 2 | E4: Year 3 | F4: Year 4 | G4: Year 5
B5: Pre-tax operating income | C5: =Underwriting!C13 | D5: =Underwriting!D13 | E5: =Underwriting!E13 | F5: =Underwriting!F13 | G5: =Underwriting!G13
B6: Tax at 25% | C6: =MAX(0,C5*0.25) | D6: =MAX(0,D5*0.25) | E6: =MAX(0,E5*0.25) | F6: =MAX(0,F5*0.25) | G6: =MAX(0,G5*0.25)
B7: After-tax distributable earnings | C7: =C5-C6 | D7: =D5-D6 | E7: =E5-E6 | F7: =F5-F6 | G7: =G5-G6
B8: Risk margin charge | C8: ='Bornhuetter-Ferguson'!$H$15*Assumptions!$E$10*Assumptions!$E$19 | D8: ='Bornhuetter-Ferguson'!$H$15*Assumptions!$E$10*Assumptions!$E$19 | E8: ='Bornhuetter-Ferguson'!$H$15*Assumptions!$E$10*Assumptions!$E$19 | F8: ='Bornhuetter-Ferguson'!$H$15*Assumptions!$E$10*Assumptions!$E$19 | G8: ='Bornhuetter-Ferguson'!$H$15*Assumptions!$E$10*Assumptions!$E$19
B9: Economic earnings | C9: =C7-C8 | D9: =D7-D8 | E9: =E7-E8 | F9: =F7-F8 | G9: =G7-G8
B10: Discount factor | C10: =1/(1+Assumptions!$E$9)^1 | D10: =1/(1+Assumptions!$E$9)^2 | E10: =1/(1+Assumptions!$E$9)^3 | F10: =1/(1+Assumptions!$E$9)^4 | G10: =1/(1+Assumptions!$E$9)^5
B11: PV economic earnings | C11: =C9*C10 | D11: =D9*D10 | E11: =E9*E10 | F11: =F9*F10 | G11: =G9*G10
B13: Adjusted net asset value | C13: =Assumptions!E14-'Bornhuetter-Ferguson'!H15*(1+Assumptions!E10)
B14: Present value of future economic earnings | C14: =SUM(C11:G11)
B15: Embedded value | C15: =C13+C14

Sheet Capital
B2: Economic and Regulatory Capital Screen
B4: Capital component | C4: Exposure | D4: Factor | E4: Requirement
B5: Premium risk | C5: =Underwriting!C5 | D5: =Assumptions!E15 | E5: =C5*D5
B6: Reserve risk | C6: ='Bornhuetter-Ferguson'!H15 | D6: =Assumptions!E16 | E6: =C6*D6
B7: Asset risk | C7: =Assumptions!E12 | D7: =Assumptions!E17 | E7: =C7*D7
B9: Diversified capital requirement | E9: =SQRT(SUMSQ(E5:E7)+2*0.25*(E5*E6+E5*E7+E6*E7))
B10: Available capital | E10: =Assumptions!E14
B11: Capital coverage | E11: =IFERROR(E10/E9,0)
B12: Minimum coverage | E12: =Assumptions!E18
B13: Capital status | E13: =IF(E11>=E12,"PASS","BREACH")

Sheet Stress
B2: Reserve and Capital Stress Matrix
B4: Loss ratio / Asset shock | C4: -0.2 | D4: -0.1 | E4: 0 | F4: 0.1 | G4: 0.2
B5: 0 | C5: =(Assumptions!$E$14*(1+C$4)-'Bornhuetter-Ferguson'!$H$15*(1+$B5))/Capital!$E$9 | D5: =(Assumptions!$E$14*(1+D$4)-'Bornhuetter-Ferguson'!$H$15*(1+$B5))/Capital!$E$9 | E5: =(Assumptions!$E$14*(1+E$4)-'Bornhuetter-Ferguson'!$H$15*(1+$B5))/Capital!$E$9 | F5: =(Assumptions!$E$14*(1+F$4)-'Bornhuetter-Ferguson'!$H$15*(1+$B5))/Capital!$E$9 | G5: =(Assumptions!$E$14*(1+G$4)-'Bornhuetter-Ferguson'!$H$15*(1+$B5))/Capital!$E$9
B6: 0.05 | C6: =(Assumptions!$E$14*(1+C$4)-'Bornhuetter-Ferguson'!$H$15*(1+$B6))/Capital!$E$9 | D6: =(Assumptions!$E$14*(1+D$4)-'Bornhuetter-Ferguson'!$H$15*(1+$B6))/Capital!$E$9 | E6: =(Assumptions!$E$14*(1+E$4)-'Bornhuetter-Ferguson'!$H$15*(1+$B6))/Capital!$E$9 | F6: =(Assumptions!$E$14*(1+F$4)-'Bornhuetter-Ferguson'!$H$15*(1+$B6))/Capital!$E$9 | G6: =(Assumptions!$E$14*(1+G$4)-'Bornhuetter-Ferguson'!$H$15*(1+$B6))/Capital!$E$9
B7: 0.1 | C7: =(Assumptions!$E$14*(1+C$4)-'Bornhuetter-Ferguson'!$H$15*(1+$B7))/Capital!$E$9 | D7: =(Assumptions!$E$14*(1+D$4)-'Bornhuetter-Ferguson'!$H$15*(1+$B7))/Capital!$E$9 | E7: =(Assumptions!$E$14*(1+E$4)-'Bornhuetter-Ferguson'!$H$15*(1+$B7))/Capital!$E$9 | F7: =(Assumptions!$E$14*(1+F$4)-'Bornhuetter-Ferguson'!$H$15*(1+$B7))/Capital!$E$9 | G7: =(Assumptions!$E$14*(1+G$4)-'Bornhuetter-Ferguson'!$H$15*(1+$B7))/Capital!$E$9
B8: 0.15 | C8: =(Assumptions!$E$14*(1+C$4)-'Bornhuetter-Ferguson'!$H$15*(1+$B8))/Capital!$E$9 | D8: =(Assumptions!$E$14*(1+D$4)-'Bornhuetter-Ferguson'!$H$15*(1+$B8))/Capital!$E$9 | E8: =(Assumptions!$E$14*(1+E$4)-'Bornhuetter-Ferguson'!$H$15*(1+$B8))/Capital!$E$9 | F8: =(Assumptions!$E$14*(1+F$4)-'Bornhuetter-Ferguson'!$H$15*(1+$B8))/Capital!$E$9 | G8: =(Assumptions!$E$14*(1+G$4)-'Bornhuetter-Ferguson'!$H$15*(1+$B8))/Capital!$E$9
B9: 0.2 | C9: =(Assumptions!$E$14*(1+C$4)-'Bornhuetter-Ferguson'!$H$15*(1+$B9))/Capital!$E$9 | D9: =(Assumptions!$E$14*(1+D$4)-'Bornhuetter-Ferguson'!$H$15*(1+$B9))/Capital!$E$9 | E9: =(Assumptions!$E$14*(1+E$4)-'Bornhuetter-Ferguson'!$H$15*(1+$B9))/Capital!$E$9 | F9: =(Assumptions!$E$14*(1+F$4)-'Bornhuetter-Ferguson'!$H$15*(1+$B9))/Capital!$E$9 | G9: =(Assumptions!$E$14*(1+G$4)-'Bornhuetter-Ferguson'!$H$15*(1+$B9))/Capital!$E$9

Sheet Checks
B2: Actuarial Model Checks
B4: Check | C4: Status
B5: Paid triangle cumulative | C5: =IF(MIN('Paid Triangle'!D5-'Paid Triangle'!C5,'Paid Triangle'!E5-'Paid Triangle'!D5,'Paid Triangle'!F5-'Paid Triangle'!E5,'Paid Triangle'!G5-'Paid Triangle'!F5,'Paid Triangle'!H5-'Paid Triangle'!G5,'Paid Triangle'!I5-'Paid Triangle'!H5,'Paid Triangle'!J5-'Paid Triangle'!I5,'Paid Triangle'!K5-'Paid Triangle'!J5,'Paid Triangle'!L5-'Paid Triangle'!K5,'Paid Triangle'!D6-'Paid Triangle'!C6,'Paid Triangle'!E6-'Paid Triangle'!D6,'Paid Triangle'!F6-'Paid Triangle'!E6,'Paid Triangle'!G6-'Paid Triangle'!F6,'Paid Triangle'!H6-'Paid Triangle'!G6,'Paid Triangle'!I6-'Paid Triangle'!H6,'Paid Triangle'!J6-'Paid Triangle'!I6,'Paid Triangle'!K6-'Paid Triangle'!J6,'Paid Triangle'!D7-'Paid Triangle'!C7,'Paid Triangle'!E7-'Paid Triangle'!D7,'Paid Triangle'!F7-'Paid Triangle'!E7,'Paid Triangle'!G7-'Paid Triangle'!F7,'Paid Triangle'!H7-'Paid Triangle'!G7,'Paid Triangle'!I7-'Paid Triangle'!H7,'Paid Triangle'!J7-'Paid Triangle'!I7,'Paid Triangle'!D8-'Paid Triangle'!C8,'Paid Triangle'!E8-'Paid Triangle'!D8,'Paid Triangle'!F8-'Paid Triangle'!E8,'Paid Triangle'!G8-'Paid Triangle'!F8,'Paid Triangle'!H8-'Paid Triangle'!G8,'Paid Triangle'!I8-'Paid Triangle'!H8,'Paid Triangle'!D9-'Paid Triangle'!C9,'Paid Triangle'!E9-'Paid Triangle'!D9,'Paid Triangle'!F9-'Paid Triangle'!E9,'Paid Triangle'!G9-'Paid Triangle'!F9,'Paid Triangle'!H9-'Paid Triangle'!G9,'Paid Triangle'!D10-'Paid Triangle'!C10,'Paid Triangle'!E10-'Paid Triangle'!D10,'Paid Triangle'!F10-'Paid Triangle'!E10,'Paid Triangle'!G10-'Paid Triangle'!F10,'Paid Triangle'!D11-'Paid Triangle'!C11,'Paid Triangle'!E11-'Paid Triangle'!D11,'Paid Triangle'!F11-'Paid Triangle'!E11,'Paid Triangle'!D12-'Paid Triangle'!C12,'Paid Triangle'!E12-'Paid Triangle'!D12,'Paid Triangle'!D13-'Paid Triangle'!C13)>=0,"PASS","FAIL")
B6: Development factors at least one | C6: =IF(MIN('Chain Ladder'!C5:L5)>=1,"PASS","FAIL")
B7: Chain-ladder reserve nonnegative | C7: =IF(MIN('Chain Ladder'!N8:N17)>=0,"PASS","FAIL")
B8: BF reserve nonnegative | C8: =IF(MIN('Bornhuetter-Ferguson'!H5:H14)>=0,"PASS","FAIL")
B9: Combined ratio finite | C9: =IF(AND(MIN(Underwriting!C11:G11)>=0,MAX(Underwriting!C11:G11)<3),"PASS","FAIL")
B10: Capital requirement positive | C10: =IF(Capital!E9>0,"PASS","FAIL")
B11: Capital coverage | C11: =IF(Capital!E13="PASS","PASS","REVIEW")
B12: Embedded value finite | C12: =IF(ABS('Embedded Value'!C15)<1000000,"PASS","FAIL")
B13: Overall | C13: =IF(COUNTIF(C5:C12,"FAIL")=0,"PASS","FAIL")

Sheet Sources
B2: Source Register
B4: Input / dataset | C4: Source URL or document | D4: As-of | E4: Notes / transformation
B5: Actuarial loss data | C5: [claims system / public filing] | D5: [valuation date] | E5: Paid, incurred, case reserve, claim counts
B6: Premium and exposure data | C6: [policy administration source] | D6: [period] | E6: Earned premium, rate, mix, exposure
B7: Reinsurance contracts | C7: [treaty / facultative documentation] | D7: [date] | E7: Limits, attachment, reinstatements, credit risk
B8: Capital methodology | C8: [regulator / internal methodology URL] | D8: [effective date] | E8: Risk factors, diversification, management actions
B9: Investment portfolio | C9: [asset ledger / filing] | D9: [date] | E9: Yield, duration, credit, liquidity, unrealized gains

Sheet RefreshLog
B2: Refresh Log
B4: Date | C4: Trigger | D4: Source snapshot | E4: What changed | F4: Reviewer / challenge | G4: Next check
