Workbook
Name FS_MODEL_ID: 'Institutional Surface'!$C$4
Name FS_DOMAIN: 'Institutional Surface'!$C$5
Name FS_MATURITY: 'Institutional Surface'!$C$6

Sheet Cover
B2: [STRATEGY] — Systematic Research Model
B4: Strategy / universe: | C4: [Name and investable universe]
B5: Data vintage / point-in-time policy: | C5: [policy]
B6: Last refreshed: | C6: [date]
B7: Next rebalance / review: | C7: [date]
B8: Refresh cadence: | C8: Daily or per rebalance
B9: Active scenario: | C9: Base
B10: Units: | C10: Periodic returns unless noted
B13: Modeling conventions
B14: Blue text / yellow fill | C14: Hardcoded input or selected scenario
B15: Black text | C15: Formula / same-sheet calculation
B16: Green text | C16: Cross-sheet formula / link
B17: Checks | C17: PASS / REVIEW / FAIL must remain visible

Sheet Institutional Surface
B2: Quantitative & Systematic — Institutional Decision Surface
B4: Model ID | C4: 22
B5: Domain | C5: Quantitative & Systematic
B6: Declared maturity | C6: M2
B7: Canonical builder | C7: tools/builders/build_quant_release.py
B8: Decision arena | C8: research, portfolio construction, execution, risk and model validation
B9: Committee artifact | C9: research approval and live-monitoring pack
B10: Operating cadence | C10: per research run; daily live; monthly model committee
B12: Key decision outputs
B13: # | C13: Requirement | D13: Owner | E13: Evidence / location | F13: Status
B14: 1 | C14: gross and net performance | F14: OPEN
B15: 2 | C15: capacity and market impact | F15: OPEN
B16: 3 | C16: walk-forward stability | F16: OPEN
B17: 4 | C17: base, downside and break-even outputs | F17: OPEN
B18: 5 | C18: liquidity / funding requirement and binding constraint | F18: OPEN
B20: Insider questions
B21: # | C21: Requirement | D21: Owner | E21: Evidence / location | F21: Status
B22: 1 | C22: What data was knowable at decision time? | F22: OPEN
B23: 2 | C23: Which result survives alternate costs and universes? | F23: OPEN
B24: 3 | C24: Where is capacity constrained—signal or execution? | F24: OPEN
B25: 4 | C25: Which assumption is owner-approved versus modeler judgement? | F25: OPEN
B26: 5 | C26: What fails first and who must act? | F26: OPEN
B28: Scenario families
B29: # | C29: Requirement | D29: Owner | E29: Evidence / location | F29: Status
B30: 1 | C30: cost and impact inflation | F30: OPEN
B31: 2 | C31: regime break | F31: OPEN
B32: 3 | C32: crowding and correlation | F32: OPEN
B33: 4 | C33: data freshness / source failure | F33: OPEN
B34: 5 | C34: combined severe-but-plausible downside | F34: OPEN
B36: Primary diligence documents
B37: # | C37: Requirement | D37: Owner | E37: Evidence / location | F37: Status
B38: 1 | C38: research specification | F38: OPEN
B39: 2 | C39: data dictionary and licenses | F39: OPEN
B40: 3 | C40: experiment and code version | F40: OPEN
B41: 4 | C41: approved model card and assumption register | F41: OPEN
B42: 5 | C42: independent validation and challenge record | F42: OPEN
B44: Challenge tests
B45: # | C45: Requirement | D45: Owner | E45: Evidence / location | F45: Status
B46: 1 | C46: no look-ahead or survivorship bias | F46: OPEN
B47: 2 | C47: walk-forward partitions do not overlap improperly | F47: OPEN
...

Sheet Challenge Log
B2: Independent Challenge, Override and Closure Log
B4: Date | C4: Reviewer | D4: Challenge | E4: Owner response | F4: Evidence | G4: Impact | H4: Status | I4: Closure
D5: no look-ahead or survivorship bias | H5: OPEN
D6: walk-forward partitions do not overlap improperly | H6: OPEN
D7: gross return exceeds net by explicit costs | H7: OPEN
D8: source-to-model lineage is reproducible | H8: OPEN
D9: units, signs, dates and legal definitions reconcile | H9: OPEN

Sheet Lineage Map
B2: Source, Transformation, Ownership and Refresh Map
B4: Source class | C4: Cadence | D4: Control | E4: System / provider | F4: As-of | G4: Owner | H4: Transform | I4: Downstream | J4: Status
B5: research data | C5: per dataset | D5: point-in-time and survivorship controls | J5: TO MAP
B6: signals | C6: daily/intraday | D6: versioned feature lineage | J6: TO MAP
B7: model governance evidence | C7: per release | D7: version, reviewer, sign-off and change log | J7: TO MAP
B8: decision-use snapshot | C8: per decision | D8: immutable as-of date and source receipt | J8: TO MAP

Sheet Assumptions
B2: Backtest, Cost, and Capacity Assumptions
B4: Assumption | C4: Base | D4: Downside | E4: Active | F4: Units / note
B5: Periods per year | C5: 12 | D5: 12 | E5: =IF(Cover!$C$9="Downside",D5,C5) | F5: periods
B6: Risk-free return per period | C6: 0.002 | D6: 0.002 | E6: =IF(Cover!$C$9="Downside",D6,C6) | F6: %
B7: Linear transaction cost | C7: 8 | D7: 15 | E7: =IF(Cover!$C$9="Downside",D7,C7) | F7: bps per unit turnover
B8: Impact coefficient | C8: 0.002 | D8: 0.008 | E8: =IF(Cover!$C$9="Downside",D8,C8) | F8: return units
B9: Capital deployed | C9: 50 | D9: 150 | E9: =IF(Cover!$C$9="Downside",D9,C9) | F9: $mm
B10: Average daily volume | C10: 500 | D10: 250 | E10: =IF(Cover!$C$9="Downside",D10,C10) | F10: $mm
B11: Maximum participation | C11: 0.1 | D11: 0.08 | E11: =IF(Cover!$C$9="Downside",D11,C11) | F11: % ADV
B12: Training periods | C12: 24 | D12: 24 | E12: =IF(Cover!$C$9="Downside",D12,C12) | F12: periods
B13: Testing periods | C13: 6 | D13: 6 | E13: =IF(Cover!$C$9="Downside",D13,C13) | F13: periods
B14: Walk-forward step | C14: 6 | D14: 6 | E14: =IF(Cover!$C$9="Downside",D14,C14) | F14: periods
B15: VaR confidence | C15: 0.95 | D15: 0.99 | E15: =IF(Cover!$C$9="Downside",D15,C15) | F15: %
B16: Target volatility | C16: 0.12 | D16: 0.1 | E16: =IF(Cover!$C$9="Downside",D16,C16) | F16: % annual
... B19: Data publication lag enforced | C19: 1 | D19: 1 | E19: =IF(Cover!$C$9="Downside",D19,C19) | F19: 1=yes

Sheet Backtest
B2: Point-in-Time Backtest
B4: Period | C4: Gross return | D4: Turnover | E4: Signal available? | F4: Linear cost | G4: Impact cost | H4: Net return | I4: Cumulative wealth | J4: Running peak | K4: Drawdown | L4: Participation
B5: 1 | C5: 0.011865216 | D5: 0.2798004 | E5: =IF(AND(Assumptions!$E$18>=1,Assumptions!$E$19=1),1,0) | F5: =ABS(D5)*Assumptions!$E$7/10000 | G5: =Assumptions!$E$8*(ABS(D5)*Assumptions!$E$9/Assumptions!$E$10)^1.5 | H5: =IF(E5=1,C5-F5-G5,0) | I5: =1+H5 | J5: =I5 | K5: =IFERROR(I5/J5-1,0) | L5: =ABS(D5)*Assumptions!$E$9/Assumptions!$E$10
B6: 2 | C6: 0.015177201 | D6: 0.30841275 | E6: =IF(AND(Assumptions!$E$18>=1,Assumptions!$E$19=1),1,0) | F6: =ABS(D6)*Assumptions!$E$7/10000 | G6: =Assumptions!$E$8*(ABS(D6)*Assumptions!$E$9/Assumptions!$E$10)^1.5 | H6: =IF(E6=1,C6-F6-G6,0) | I6: =I5*(1+H6) | J6: =MAX(J5,I6) | K6: =IFERROR(I6/J6-1,0) | L6: =ABS(D6)*Assumptions!$E$9/Assumptions!$E$10
B7: 3 | C7: 0.017555014 | D7: 0.33469637 | E7: =IF(AND(Assumptions!$E$18>=1,Assumptions!$E$19=1),1,0) | F7: =ABS(D7)*Assumptions!$E$7/10000 | G7: =Assumptions!$E$8*(ABS(D7)*Assumptions!$E$9/Assumptions!$E$10)^1.5 | H7: =IF(E7=1,C7-F7-G7,0) | I7: =I6*(1+H7) | J7: =MAX(J6,I7) | K7: =IFERROR(I7/J7-1,0) | L7: =ABS(D7)*Assumptions!$E$9/Assumptions!$E$10
B8: 4 | C8: 0.01871003 | D8: 0.35760341 | E8: =IF(AND(Assumptions!$E$18>=1,Assumptions!$E$19=1),1,0) | F8: =ABS(D8)*Assumptions!$E$7/10000 | G8: =Assumptions!$E$8*(ABS(D8)*Assumptions!$E$9/Assumptions!$E$10)^1.5 | H8: =IF(E8=1,C8-F8-G8,0) | I8: =I7*(1+H8) | J8: =MAX(J7,I8) | K8: =IFERROR(I8/J8-1,0) | L8: =ABS(D8)*Assumptions!$E$9/Assumptions!$E$10
B9: 5 | C9: 0.0084782636 | D9: 0.37622065 | E9: =IF(AND(Assumptions!$E$18>=1,Assumptions!$E$19=1),1,0) | F9: =ABS(D9)*Assumptions!$E$7/10000 | G9: =Assumptions!$E$8*(ABS(D9)*Assumptions!$E$9/Assumptions!$E$10)^1.5 | H9: =IF(E9=1,C9-F9-G9,0) | I9: =I8*(1+H9) | J9: =MAX(J8,I9) | K9: =IFERROR(I9/J9-1,0) | L9: =ABS(D9)*Assumptions!$E$9/Assumptions!$E$10
B10: 6 | C10: 0.01683917 | D10: 0.38980586 | E10: =IF(AND(Assumptions!$E$18>=1,Assumptions!$E$19=1),1,0) | F10: =ABS(D10)*Assumptions!$E$7/10000 | G10: =Assumptions!$E$8*(ABS(D10)*Assumptions!$E$9/Assumptions!$E$10)^1.5 | H10: =IF(E10=1,C10-F10-G10,0) | I10: =I9*(1+H10) | J10: =MAX(J9,I10) | K10: =IFERROR(I10/J10-1,0) | L10: =ABS(D10)*Assumptions!$E$9/Assumptions!$E$10
B11: 7 | C11: 0.013918844 | D11: 0.39781746 | E11: =IF(AND(Assumptions!$E$18>=1,Assumptions!$E$19=1),1,0) | F11: =ABS(D11)*Assumptions!$E$7/10000 | G11: =Assumptions!$E$8*(ABS(D11)*Assumptions!$E$9/Assumptions!$E$10)^1.5 | H11: =IF(E11=1,C11-F11-G11,0) | I11: =I10*(1+H11) | J11: =MAX(J10,I11) | K11: =IFERROR(I11/J11-1,0) | L11: =ABS(D11)*Assumptions!$E$9/Assumptions!$E$10
B12: 8 | C12: 0.0099772518 | D12: 0.39993604 | E12: =IF(AND(Assumptions!$E$18>=1,Assumptions!$E$19=1),1,0) | F12: =ABS(D12)*Assumptions!$E$7/10000 | G12: =Assumptions!$E$8*(ABS(D12)*Assumptions!$E$9/Assumptions!$E$10)^1.5 | H12: =IF(E12=1,C12-F12-G12,0) | I12: =I11*(1+H12) | J12: =MAX(J11,I12) | K12: =IFERROR(I12/J12-1,0) | L12: =ABS(D12)*Assumptions!$E$9/Assumptions!$E$10
B13: 9 | C13: 0.0053808572 | D13: 0.39607714 | E13: =IF(AND(Assumptions!$E$18>=1,Assumptions!$E$19=1),1,0) | F13: =ABS(D13)*Assumptions!$E$7/10000 | G13: =Assumptions!$E$8*(ABS(D13)*Assumptions!$E$9/Assumptions!$E$10)^1.5 | H13: =IF(E13=1,C13-F13-G13,0) | I13: =I12*(1+H13) | J13: =MAX(J12,I13) | K13: =IFERROR(I13/J13-1,0) | L13: =ABS(D13)*Assumptions!$E$9/Assumptions!$E$10
B14: 10 | C14: -0.0094363402 | D14: 0.38639461 | E14: =IF(AND(Assumptions!$E$18>=1,Assumptions!$E$19=1),1,0) | F14: =ABS(D14)*Assumptions!$E$7/10000 | G14: =Assumptions!$E$8*(ABS(D14)*Assumptions!$E$9/Assumptions!$E$10)^1.5 | H14: =IF(E14=1,C14-F14-G14,0) | I14: =I13*(1+H14) | J14: =MAX(J13,I14) | K14: =IFERROR(I14/J14-1,0) | L14: =ABS(D14)*Assumptions!$E$9/Assumptions!$E$10
B15: 11 | C15: -0.0040191181 | D15: 0.37127446 | E15: =IF(AND(Assumptions!$E$18>=1,Assumptions!$E$19=1),1,0) | F15: =ABS(D15)*Assumptions!$E$7/10000 | G15: =Assumptions!$E$8*(ABS(D15)*Assumptions!$E$9/Assumptions!$E$10)^1.5 | H15: =IF(E15=1,C15-F15-G15,0) | I15: =I14*(1+H15) | J15: =MAX(J14,I15) | K15: =IFERROR(I15/J15-1,0) | L15: =ABS(D15)*Assumptions!$E$9/Assumptions!$E$10
B16: 12 | C16: -0.007939615 | D16: 0.35131948 | E16: =IF(AND(Assumptions!$E$18>=1,Assumptions!$E$19=1),1,0) | F16: =ABS(D16)*Assumptions!$E$7/10000 | G16: =Assumptions!$E$8*(ABS(D16)*Assumptions!$E$9/Assumptions!$E$10)^1.5 | H16: =IF(E16=1,C16-F16-G16,0) | I16: =I15*(1+H16) | J16: =MAX(J15,I16) | K16: =IFERROR(I16/J16-1,0) | L16: =ABS(D16)*Assumptions!$E$9/Assumptions!$E$10
B17: 13 | C17: -0.01084287 | D17: 0.32732521 | E17: =IF(AND(Assumptions!$E$18>=1,Assumptions!$E$19=1),1,0) | F17: =ABS(D17)*Assumptions!$E$7/10000 | G17: =Assumptions!$E$8*(ABS(D17)*Assumptions!$E$9/Assumptions!$E$10)^1.5 | H17: =IF(E17=1,C17-F17-G17,0) | I17: =I16*(1+H17) | J17: =MAX(J16,I17) | K17: =IFERROR(I17/J17-1,0) | L17: =ABS(D17)*Assumptions!$E$9/Assumptions!$E$10
... B64: 60 | C64: -0.0009894357 | D64: 0.33048594 | E64: =IF(AND(Assumptions!$E$18>=1,Assumptions!$E$19=1),1,0) | F64: =ABS(D64)*Assumptions!$E$7/10000 | G64: =Assumptions!$E$8*(ABS(D64)*Assumptions!$E$9/Assumptions!$E$10)^1.5 | H64: =IF(E64=1,C64-F64-G64,0) | I64: =I63*(1+H64) | J64: =MAX(J63,I64) | K64: =IFERROR(I64/J64-1,0) | L64: =ABS(D64)*Assumptions!$E$9/Assumptions!$E$10

Sheet Performance
B2: Gross, Net, and Risk-Adjusted Performance
B4: Metric | C4: Gross | D4: Net | E4: Interpretation
B5: Annualized arithmetic return | C5: =AVERAGE(Backtest!C5:C64)*Assumptions!E5 | D5: =AVERAGE(Backtest!H5:H64)*Assumptions!E5 | E5: mean periodic return annualized
B6: Annualized volatility | C6: =STDEVP(Backtest!C5:C64)*SQRT(Assumptions!E5) | D6: =STDEVP(Backtest!H5:H64)*SQRT(Assumptions!E5) | E6: population volatility
B7: Sharpe ratio | C7: =IFERROR((AVERAGE(Backtest!C5:C64)-Assumptions!E6)/STDEVP(Backtest!C5:C64)*SQRT(Assumptions!E5),0) | D7: =IFERROR((AVERAGE(Backtest!H5:H64)-Assumptions!E6)/STDEVP(Backtest!H5:H64)*SQRT(Assumptions!E5),0) | E7: excess return / volatility
B8: Sortino ratio | C8: =IFERROR((AVERAGE(Backtest!C5:C64)-Assumptions!E6)/SQRT(SUMPRODUCT((Backtest!C5:C64<Assumptions!E6)*(Backtest!C5:C64-Assumptions!E6)^2)/COUNT(Backtest!C5:C64))*SQRT(Assumptions!E5),0) | D8: =IFERROR((AVERAGE(Backtest!H5:H64)-Assumptions!E6)/SQRT(SUMPRODUCT((Backtest!H5:H64<Assumptions!E6)*(Backtest!H5:H64-Assumptions!E6)^2)/COUNT(Backtest!H5:H64))*SQRT(Assumptions!E5),0) | E8: downside-risk adjusted
B9: Maximum drawdown | C9: =MIN(Backtest!K5:K64) | D9: =MIN(Backtest!K5:K64) | E9: peak-to-trough
B10: Hit rate | C10: =COUNTIF(Backtest!C5:C64,">0")/COUNT(Backtest!C5:C64) | D10: =COUNTIF(Backtest!H5:H64,">0")/COUNT(Backtest!H5:H64) | E10: positive periods
B11: Ending wealth multiple | C11: =PRODUCT(1+Backtest!C5:C64) | D11: =Backtest!I64 | E11: growth of one unit
B12: Annual cost drag | C12: =C5-D5 | D12: =C5-D5 | E12: gross less net annualized return

Sheet Walk Forward
B2: Walk-Forward Validation Folds
B4: Fold | C4: Train start | D4: Train end | E4: Test start | F4: Test end | G4: Train Sharpe | H4: Test Sharpe | I4: Test net return | J4: Degradation
B5: 1 | C5: 1 | D5: 24 | E5: 25 | F5: 30 | G5: =IFERROR(AVERAGE(INDEX(Backtest!$H$5:$H$64,C5):INDEX(Backtest!$H$5:$H$64,D5))/STDEVP(INDEX(Backtest!$H$5:$H$64,C5):INDEX(Backtest!$H$5:$H$64,D5))*SQRT(Assumptions!$E$5),0) | H5: =IFERROR(AVERAGE(INDEX(Backtest!$H$5:$H$64,E5):INDEX(Backtest!$H$5:$H$64,F5))/STDEVP(INDEX(Backtest!$H$5:$H$64,E5):INDEX(Backtest!$H$5:$H$64,F5))*SQRT(Assumptions!$E$5),0) | I5: =(1+INDEX(Backtest!$H$5:$H$64,E5+0))*(1+INDEX(Backtest!$H$5:$H$64,E5+1))*(1+INDEX(Backtest!$H$5:$H$64,E5+2))*(1+INDEX(Backtest!$H$5:$H$64,E5+3))*(1+INDEX(Backtest!$H$5:$H$64,E5+4))*(1+INDEX(Backtest!$H$5:$H$64,E5+5))-1 | J5: =H5-G5
B6: 2 | C6: 7 | D6: 30 | E6: 31 | F6: 36 | G6: =IFERROR(AVERAGE(INDEX(Backtest!$H$5:$H$64,C6):INDEX(Backtest!$H$5:$H$64,D6))/STDEVP(INDEX(Backtest!$H$5:$H$64,C6):INDEX(Backtest!$H$5:$H$64,D6))*SQRT(Assumptions!$E$5),0) | H6: =IFERROR(AVERAGE(INDEX(Backtest!$H$5:$H$64,E6):INDEX(Backtest!$H$5:$H$64,F6))/STDEVP(INDEX(Backtest!$H$5:$H$64,E6):INDEX(Backtest!$H$5:$H$64,F6))*SQRT(Assumptions!$E$5),0) | I6: =(1+INDEX(Backtest!$H$5:$H$64,E6+0))*(1+INDEX(Backtest!$H$5:$H$64,E6+1))*(1+INDEX(Backtest!$H$5:$H$64,E6+2))*(1+INDEX(Backtest!$H$5:$H$64,E6+3))*(1+INDEX(Backtest!$H$5:$H$64,E6+4))*(1+INDEX(Backtest!$H$5:$H$64,E6+5))-1 | J6: =H6-G6
B7: 3 | C7: 13 | D7: 36 | E7: 37 | F7: 42 | G7: =IFERROR(AVERAGE(INDEX(Backtest!$H$5:$H$64,C7):INDEX(Backtest!$H$5:$H$64,D7))/STDEVP(INDEX(Backtest!$H$5:$H$64,C7):INDEX(Backtest!$H$5:$H$64,D7))*SQRT(Assumptions!$E$5),0) | H7: =IFERROR(AVERAGE(INDEX(Backtest!$H$5:$H$64,E7):INDEX(Backtest!$H$5:$H$64,F7))/STDEVP(INDEX(Backtest!$H$5:$H$64,E7):INDEX(Backtest!$H$5:$H$64,F7))*SQRT(Assumptions!$E$5),0) | I7: =(1+INDEX(Backtest!$H$5:$H$64,E7+0))*(1+INDEX(Backtest!$H$5:$H$64,E7+1))*(1+INDEX(Backtest!$H$5:$H$64,E7+2))*(1+INDEX(Backtest!$H$5:$H$64,E7+3))*(1+INDEX(Backtest!$H$5:$H$64,E7+4))*(1+INDEX(Backtest!$H$5:$H$64,E7+5))-1 | J7: =H7-G7
B8: 4 | C8: 19 | D8: 42 | E8: 43 | F8: 48 | G8: =IFERROR(AVERAGE(INDEX(Backtest!$H$5:$H$64,C8):INDEX(Backtest!$H$5:$H$64,D8))/STDEVP(INDEX(Backtest!$H$5:$H$64,C8):INDEX(Backtest!$H$5:$H$64,D8))*SQRT(Assumptions!$E$5),0) | H8: =IFERROR(AVERAGE(INDEX(Backtest!$H$5:$H$64,E8):INDEX(Backtest!$H$5:$H$64,F8))/STDEVP(INDEX(Backtest!$H$5:$H$64,E8):INDEX(Backtest!$H$5:$H$64,F8))*SQRT(Assumptions!$E$5),0) | I8: =(1+INDEX(Backtest!$H$5:$H$64,E8+0))*(1+INDEX(Backtest!$H$5:$H$64,E8+1))*(1+INDEX(Backtest!$H$5:$H$64,E8+2))*(1+INDEX(Backtest!$H$5:$H$64,E8+3))*(1+INDEX(Backtest!$H$5:$H$64,E8+4))*(1+INDEX(Backtest!$H$5:$H$64,E8+5))-1 | J8: =H8-G8
B9: 5 | C9: 25 | D9: 48 | E9: 49 | F9: 54 | G9: =IFERROR(AVERAGE(INDEX(Backtest!$H$5:$H$64,C9):INDEX(Backtest!$H$5:$H$64,D9))/STDEVP(INDEX(Backtest!$H$5:$H$64,C9):INDEX(Backtest!$H$5:$H$64,D9))*SQRT(Assumptions!$E$5),0) | H9: =IFERROR(AVERAGE(INDEX(Backtest!$H$5:$H$64,E9):INDEX(Backtest!$H$5:$H$64,F9))/STDEVP(INDEX(Backtest!$H$5:$H$64,E9):INDEX(Backtest!$H$5:$H$64,F9))*SQRT(Assumptions!$E$5),0) | I9: =(1+INDEX(Backtest!$H$5:$H$64,E9+0))*(1+INDEX(Backtest!$H$5:$H$64,E9+1))*(1+INDEX(Backtest!$H$5:$H$64,E9+2))*(1+INDEX(Backtest!$H$5:$H$64,E9+3))*(1+INDEX(Backtest!$H$5:$H$64,E9+4))*(1+INDEX(Backtest!$H$5:$H$64,E9+5))-1 | J9: =H9-G9
B10: 6 | C10: 31 | D10: 54 | E10: 55 | F10: 60 | G10: =IFERROR(AVERAGE(INDEX(Backtest!$H$5:$H$64,C10):INDEX(Backtest!$H$5:$H$64,D10))/STDEVP(INDEX(Backtest!$H$5:$H$64,C10):INDEX(Backtest!$H$5:$H$64,D10))*SQRT(Assumptions!$E$5),0) | H10: =IFERROR(AVERAGE(INDEX(Backtest!$H$5:$H$64,E10):INDEX(Backtest!$H$5:$H$64,F10))/STDEVP(INDEX(Backtest!$H$5:$H$64,E10):INDEX(Backtest!$H$5:$H$64,F10))*SQRT(Assumptions!$E$5),0) | I10: =(1+INDEX(Backtest!$H$5:$H$64,E10+0))*(1+INDEX(Backtest!$H$5:$H$64,E10+1))*(1+INDEX(Backtest!$H$5:$H$64,E10+2))*(1+INDEX(Backtest!$H$5:$H$64,E10+3))*(1+INDEX(Backtest!$H$5:$H$64,E10+4))*(1+INDEX(Backtest!$H$5:$H$64,E10+5))-1 | J10: =H10-G10

Sheet Costs & Capacity
B2: Cost and Capacity Sensitivity
B4: Capital / Turnover | C4: 0.1 | D4: 0.25 | E4: 0.5 | F4: 0.75 | G4: 1
B5: 10 | C5: =C$4*Assumptions!$E$7/10000+Assumptions!$E$8*(C$4*$B5/Assumptions!$E$10)^1.5 | D5: =D$4*Assumptions!$E$7/10000+Assumptions!$E$8*(D$4*$B5/Assumptions!$E$10)^1.5 | E5: =E$4*Assumptions!$E$7/10000+Assumptions!$E$8*(E$4*$B5/Assumptions!$E$10)^1.5 | F5: =F$4*Assumptions!$E$7/10000+Assumptions!$E$8*(F$4*$B5/Assumptions!$E$10)^1.5 | G5: =G$4*Assumptions!$E$7/10000+Assumptions!$E$8*(G$4*$B5/Assumptions!$E$10)^1.5
B6: 25 | C6: =C$4*Assumptions!$E$7/10000+Assumptions!$E$8*(C$4*$B6/Assumptions!$E$10)^1.5 | D6: =D$4*Assumptions!$E$7/10000+Assumptions!$E$8*(D$4*$B6/Assumptions!$E$10)^1.5 | E6: =E$4*Assumptions!$E$7/10000+Assumptions!$E$8*(E$4*$B6/Assumptions!$E$10)^1.5 | F6: =F$4*Assumptions!$E$7/10000+Assumptions!$E$8*(F$4*$B6/Assumptions!$E$10)^1.5 | G6: =G$4*Assumptions!$E$7/10000+Assumptions!$E$8*(G$4*$B6/Assumptions!$E$10)^1.5
B7: 50 | C7: =C$4*Assumptions!$E$7/10000+Assumptions!$E$8*(C$4*$B7/Assumptions!$E$10)^1.5 | D7: =D$4*Assumptions!$E$7/10000+Assumptions!$E$8*(D$4*$B7/Assumptions!$E$10)^1.5 | E7: =E$4*Assumptions!$E$7/10000+Assumptions!$E$8*(E$4*$B7/Assumptions!$E$10)^1.5 | F7: =F$4*Assumptions!$E$7/10000+Assumptions!$E$8*(F$4*$B7/Assumptions!$E$10)^1.5 | G7: =G$4*Assumptions!$E$7/10000+Assumptions!$E$8*(G$4*$B7/Assumptions!$E$10)^1.5
B8: 100 | C8: =C$4*Assumptions!$E$7/10000+Assumptions!$E$8*(C$4*$B8/Assumptions!$E$10)^1.5 | D8: =D$4*Assumptions!$E$7/10000+Assumptions!$E$8*(D$4*$B8/Assumptions!$E$10)^1.5 | E8: =E$4*Assumptions!$E$7/10000+Assumptions!$E$8*(E$4*$B8/Assumptions!$E$10)^1.5 | F8: =F$4*Assumptions!$E$7/10000+Assumptions!$E$8*(F$4*$B8/Assumptions!$E$10)^1.5 | G8: =G$4*Assumptions!$E$7/10000+Assumptions!$E$8*(G$4*$B8/Assumptions!$E$10)^1.5
B9: 250 | C9: =C$4*Assumptions!$E$7/10000+Assumptions!$E$8*(C$4*$B9/Assumptions!$E$10)^1.5 | D9: =D$4*Assumptions!$E$7/10000+Assumptions!$E$8*(D$4*$B9/Assumptions!$E$10)^1.5 | E9: =E$4*Assumptions!$E$7/10000+Assumptions!$E$8*(E$4*$B9/Assumptions!$E$10)^1.5 | F9: =F$4*Assumptions!$E$7/10000+Assumptions!$E$8*(F$4*$B9/Assumptions!$E$10)^1.5 | G9: =G$4*Assumptions!$E$7/10000+Assumptions!$E$8*(G$4*$B9/Assumptions!$E$10)^1.5
B12: Current maximum participation | C12: =MAX(Backtest!L5:L64)
B13: Participation limit | C13: =Assumptions!E11
B14: Capacity status | C14: =IF(C12<=C13,"PASS","BREACH")

Sheet Risk
B2: Distribution and Tail Risk
B4: Metric | C4: Value | D4: Units | E4: Method
B5: Historical VaR | C5: =-PERCENTILE(Backtest!H5:H64,1-Assumptions!E15) | D5: % | E5: empirical left-tail quantile
B6: Historical expected shortfall | C6: =IFERROR(-AVERAGEIF(Backtest!H5:H64,"<="&-C5,Backtest!H5:H64),0) | D6: % | E6: mean return beyond VaR
B7: Parametric VaR | C7: =-(AVERAGE(Backtest!H5:H64)+NORMSINV(1-Assumptions!E15)*STDEVP(Backtest!H5:H64)) | D7: % | E7: normal approximation
B8: Maximum drawdown | C8: =Performance!D9 | D8: % | E8: realized peak-to-trough
B9: Drawdown limit | C9: =ABS(Assumptions!E17) | D9: % | E9: approved risk limit
B10: Drawdown status | C10: =IF(C8<=C9,"PASS","BREACH") | D10: status | E10: limit test
B11: Annualized net volatility | C11: =Performance!D6 | D11: % | E11: realized
B12: Volatility target | C12: =Assumptions!E16 | D12: % | E12: approved target
B13: Volatility scaling | C13: =IFERROR(C12/C11,0) | D13: x | E13: target / realized

Sheet Stress
B2: Strategy Stress Scenarios
B4: Scenario | C4: Return shock | D4: Turnover multiplier | E4: Liquidity multiplier | F4: Cost shock | G4: Estimated P&L
B5: Equity selloff / beta shock | C5: -0.12 | D5: 1.5 | E5: 0.6 | F5: =AVERAGE(Backtest!D5:D64)*D5*Assumptions!$E$7/10000+Assumptions!$E$8*(AVERAGE(Backtest!D5:D64)*D5*Assumptions!$E$9/(Assumptions!$E$10*E5))^1.5 | G5: =C5-F5
B6: Volatility spike | C6: -0.06 | D6: 2 | E6: 0.5 | F6: =AVERAGE(Backtest!D5:D64)*D6*Assumptions!$E$7/10000+Assumptions!$E$8*(AVERAGE(Backtest!D5:D64)*D6*Assumptions!$E$9/(Assumptions!$E$10*E6))^1.5 | G6: =C6-F6
B7: Crowded unwind | C7: -0.1 | D7: 3 | E7: 0.3 | F7: =AVERAGE(Backtest!D5:D64)*D7*Assumptions!$E$7/10000+Assumptions!$E$8*(AVERAGE(Backtest!D5:D64)*D7*Assumptions!$E$9/(Assumptions!$E$10*E7))^1.5 | G7: =C7-F7
B8: Liquidity freeze | C8: -0.04 | D8: 1.5 | E8: 0.15 | F8: =AVERAGE(Backtest!D5:D64)*D8*Assumptions!$E$7/10000+Assumptions!$E$8*(AVERAGE(Backtest!D5:D64)*D8*Assumptions!$E$9/(Assumptions!$E$10*E8))^1.5 | G8: =C8-F8
B9: Model decay | C9: -0.03 | D9: 1 | E9: 1 | F9: =AVERAGE(Backtest!D5:D64)*D9*Assumptions!$E$7/10000+Assumptions!$E$8*(AVERAGE(Backtest!D5:D64)*D9*Assumptions!$E$9/(Assumptions!$E$10*E9))^1.5 | G9: =C9-F9

Sheet Checks
B2: Research and Model Checks
B4: Check | C4: Status
B5: Signal lag is positive | C5: =IF(Assumptions!E18>=1,"PASS","FAIL")
B6: Publication lag control enabled | C6: =IF(Assumptions!E19=1,"PASS","FAIL")
B7: Transaction costs included | C7: =IF(AND(Assumptions!E7>0,Assumptions!E8>0),"PASS","FAIL")
B8: No participation breach | C8: =IF('Costs & Capacity'!C14="PASS","PASS","BREACH")
B9: Gross return exceeds or equals net | C9: =IF(Performance!C5>=Performance!D5,"PASS","FAIL")
B10: Walk-forward tests populated | C10: =IF(COUNT('Walk Forward'!H5:H10)=6,"PASS","FAIL")
B11: No drawdown breach | C11: =IF(Risk!C10="PASS","PASS","REVIEW")
B12: All returns finite | C12: =IF(COUNT(Backtest!H5:H64)=60,"PASS","FAIL")
B13: Overall | C13: =IF(COUNTIF(C5:C12,"FAIL")=0,"PASS","FAIL")

Sheet Sources
B2: Source Register
B4: Input / dataset | C4: Source URL or document | D4: As-of | E4: Notes / transformation
B5: Point-in-time market and fundamental data | C5: [dataset URL / manifest] | D5: [as-of] | E5: Document revisions, survivorship, and publication lag
B6: Corporate actions and universe membership | C6: [dataset URL] | D6: [as-of] | E6: Split, dividend, delisting, and constituent history
B7: Execution and transaction-cost data | C7: [broker / venue source] | D7: [period] | E7: Spreads, fees, impact, and borrow
B8: Risk-free benchmark | C8: https://fred.stlouisfed.org/ | D8: [period] | E8: Record series ID and compounding
B9: Live-monitoring comparison | C9: [production report URL] | D9: [period] | E9: Backtest-to-live degradation and incidents

Sheet RefreshLog
B2: Refresh Log
B4: Date | C4: Trigger | D4: Source snapshot | E4: What changed | F4: Reviewer / challenge | G4: Next check
