Workbook

Sheet Cover
B2: [PROJECT] — Project Finance Model
B4: Project / concession: | C4: Adversarial Delay and Availability Case
B5: Sector / jurisdiction: | C5: Power / transport / digital / PPP
B6: Financial close / COD: | C6: [dates]
B7: Last refreshed: | C7: 2026-08-03
B8: Refresh cadence: | C8: Weekly construction; monthly operations
B9: Active scenario: | C9: Downside
B10: Units: | C10: $ in millions unless noted
B13: Modeling conventions
B14: Blue text / yellow fill | C14: Hardcoded input or selected scenario
B15: Black text | C15: Formula / same-sheet calculation
B16: Green text | C16: Cross-sheet formula / link
B17: Checks | C17: PASS / REVIEW / FAIL must remain visible

Sheet Institutional Surface
B2: Project Finance — Institutional Decision Surface
B4: Model ID | C4: 20
B5: Domain | C5: Project Finance
B6: Declared maturity | C6: M2
B7: Canonical builder | C7: tools/builders/build_project_finance_release.py
B8: Decision arena | C8: sponsor, lender, technical adviser, offtaker, insurer and investment committee
B9: Committee artifact | C9: bank case, downside case and financing base-case pack
B10: Operating cadence | C10: monthly construction/operations; quarterly lender; annual model audit
B12: Key decision outputs
B13: # | C13: Requirement | D13: Owner | E13: Evidence / location | F13: Status
B14: 1 | C14: construction funding and IDC | F14: OPEN
B15: 2 | C15: operating CFADS | F15: OPEN
B16: 3 | C16: debt sculpting and DSRA | F16: OPEN
B17: 4 | C17: base, downside and break-even outputs | F17: OPEN
B18: 5 | C18: liquidity / funding requirement and binding constraint | F18: OPEN
B20: Insider questions
B21: # | C21: Requirement | D21: Owner | E21: Evidence / location | F21: Status
B22: 1 | C22: What is the lender's base case versus sponsor case? | F22: OPEN
B23: 2 | C23: Which completion tests release support? | F23: OPEN
B24: 3 | C24: What cash is trapped before distributions? | F24: OPEN
B25: 4 | C25: Which assumption is owner-approved versus modeler judgement? | F25: OPEN
B26: 5 | C26: What fails first and who must act? | F26: OPEN
B28: Scenario families
B29: # | C29: Requirement | D29: Owner | E29: Evidence / location | F29: Status
B30: 1 | C30: delay and cost overrun | F30: OPEN
B31: 2 | C31: volume / resource shortfall | F31: OPEN
B32: 3 | C32: price / offtaker stress | F32: OPEN
B33: 4 | C33: data freshness / source failure | F33: OPEN
B34: 5 | C34: combined severe-but-plausible downside | F34: OPEN
B36: Primary diligence documents
B37: # | C37: Requirement | D37: Owner | E37: Evidence / location | F37: Status
B38: 1 | C38: EPC and O&M contracts | F38: OPEN
B39: 2 | C39: offtake / concession agreement | F39: OPEN
B40: 3 | C40: independent engineer report | F40: OPEN
B41: 4 | C41: approved model card and assumption register | F41: OPEN
B42: 5 | C42: independent validation and challenge record | F42: OPEN
B44: Challenge tests
B45: # | C45: Requirement | D45: Owner | E45: Evidence / location | F45: Status
B46: 1 | C46: sources equal uses | F46: OPEN
B47: 2 | C47: construction draws conserve cost | F47: OPEN
...

Sheet Challenge Log
B2: Independent Challenge, Override and Closure Log
B4: Date | C4: Reviewer | D4: Challenge | E4: Owner response | F4: Evidence | G4: Impact | H4: Status | I4: Closure
D5: sources equal uses | H5: OPEN
D6: construction draws conserve cost | H6: OPEN
D7: IDC follows funded debt timing | H7: OPEN
D8: source-to-model lineage is reproducible | H8: OPEN
D9: units, signs, dates and legal definitions reconcile | H9: OPEN

Sheet Lineage Map
B2: Source, Transformation, Ownership and Refresh Map
B4: Source class | C4: Cadence | D4: Control | E4: System / provider | F4: As-of | G4: Owner | H4: Transform | I4: Downstream | J4: Status
B5: construction progress | C5: monthly | D5: engineer-certified progress and cost | J5: TO MAP
B6: operating data | C6: monthly | D6: meter / volume and invoice tie | J6: TO MAP
B7: model governance evidence | C7: per release | D7: version, reviewer, sign-off and change log | J7: TO MAP
B8: decision-use snapshot | C8: per decision | D8: immutable as-of date and source receipt | J8: TO MAP

Sheet Assumptions
B2: Project Assumptions
B4: Assumption | C4: Base | D4: Downside | E4: Active | F4: Units / note
B5: EPC / hard construction cost | C5: 800 | D5: 1100 | E5: =IF(Cover!$C$9="Downside",D5,C5) -> 1100 | F5: $mm
B6: Development and owner costs | C6: 80 | D6: 95 | E6: =IF(Cover!$C$9="Downside",D6,C6) -> 95 | F6: $mm
B7: Contingency / hard cost | C7: 0.08 | D7: 0.12 | E7: =IF(Cover!$C$9="Downside",D7,C7) -> 0.12 | F7: %
B8: Debt share of pre-IDC cost | C8: 0.7 | D8: 0.65 | E8: =IF(Cover!$C$9="Downside",D8,C8) -> 0.65 | F8: %
B9: Construction quarters | C9: 8 | D9: 10 | E9: =IF(Cover!$C$9="Downside",D9,C9) -> 10 | F9: quarters
B10: Annual construction debt rate | C10: 0.075 | D10: 0.09 | E10: =IF(Cover!$C$9="Downside",D10,C10) -> 0.09 | F10: %
B11: Year 1 contracted / merchant revenue | C11: 180 | D11: 135 | E11: =IF(Cover!$C$9="Downside",D11,C11) -> 135 | F11: $mm
B12: Annual revenue growth | C12: 0.025 | D12: 0 | E12: =IF(Cover!$C$9="Downside",D12,C12) -> 0 | F12: %
B13: Operating cost / revenue | C13: 0.28 | D13: 0.36 | E13: =IF(Cover!$C$9="Downside",D13,C13) -> 0.36 | F13: %
B14: Maintenance capex / revenue | C14: 0.035 | D14: 0.05 | E14: =IF(Cover!$C$9="Downside",D14,C14) -> 0.05 | F14: %
B15: Cash tax / EBITDA | C15: 0.15 | D15: 0.1 | E15: =IF(Cover!$C$9="Downside",D15,C15) -> 0.1 | F15: %
B16: Target DSCR | C16: 1.35 | D16: 1.45 | E16: =IF(Cover!$C$9="Downside",D16,C16) -> 1.45 | F16: x
... B24: Inflation escalation | C24: 0.02 | D24: 0.03 | E24: =IF(Cover!$C$9="Downside",D24,C24) -> 0.03 | F24: %

Sheet Construction
B2: Quarterly Construction Funding and IDC
B4: $mm | C4: Q1 | D4: Q2 | E4: Q3 | F4: Q4 | G4: Q5 | H4: Q6 | I4: Q7 | J4: Q8 | K4: Q9 | L4: Q10 | M4: Total
B5: Spend curve | C5: 0.05 | D5: 0.1 | E5: 0.15 | F5: 0.18 | G5: 0.18 | H5: 0.14 | I5: 0.12 | J5: 0.08 | K5: 0 | L5: 0 | M5: =SUM(C5:L5) -> 1
B6: Hard construction cost | C6: =IF(1<=Assumptions!$E$9,Assumptions!$E$5*C$5,0) -> 55 | D6: =IF(2<=Assumptions!$E$9,Assumptions!$E$5*D$5,0) -> 110 | E6: =IF(3<=Assumptions!$E$9,Assumptions!$E$5*E$5,0) -> 165 | F6: =IF(4<=Assumptions!$E$9,Assumptions!$E$5*F$5,0) -> 198 | G6: =IF(5<=Assumptions!$E$9,Assumptions!$E$5*G$5,0) -> 198 | H6: =IF(6<=Assumptions!$E$9,Assumptions!$E$5*H$5,0) -> 154 | I6: =IF(7<=Assumptions!$E$9,Assumptions!$E$5*I$5,0) -> 132 | J6: =IF(8<=Assumptions!$E$9,Assumptions!$E$5*J$5,0) -> 88 | K6: =IF(9<=Assumptions!$E$9,Assumptions!$E$5*K$5,0) -> 0 | L6: =IF(10<=Assumptions!$E$9,Assumptions!$E$5*L$5,0) -> 0 | M6: =SUM(C6:L6) -> 1100
B7: Development / owner costs | C7: =IF(1<=Assumptions!$E$9,Assumptions!$E$6/Assumptions!$E$9,0) -> 9.5 | D7: =IF(2<=Assumptions!$E$9,Assumptions!$E$6/Assumptions!$E$9,0) -> 9.5 | E7: =IF(3<=Assumptions!$E$9,Assumptions!$E$6/Assumptions!$E$9,0) -> 9.5 | F7: =IF(4<=Assumptions!$E$9,Assumptions!$E$6/Assumptions!$E$9,0) -> 9.5 | G7: =IF(5<=Assumptions!$E$9,Assumptions!$E$6/Assumptions!$E$9,0) -> 9.5 | H7: =IF(6<=Assumptions!$E$9,Assumptions!$E$6/Assumptions!$E$9,0) -> 9.5 | I7: =IF(7<=Assumptions!$E$9,Assumptions!$E$6/Assumptions!$E$9,0) -> 9.5 | J7: =IF(8<=Assumptions!$E$9,Assumptions!$E$6/Assumptions!$E$9,0) -> 9.5 | K7: =IF(9<=Assumptions!$E$9,Assumptions!$E$6/Assumptions!$E$9,0) -> 9.5 | L7: =IF(10<=Assumptions!$E$9,Assumptions!$E$6/Assumptions!$E$9,0) -> 9.5 | M7: =SUM(C7:L7) -> 95
B8: Contingency | C8: =C6*Assumptions!$E$7 -> 6.6 | D8: =D6*Assumptions!$E$7 -> 13.2 | E8: =E6*Assumptions!$E$7 -> 19.8 | F8: =F6*Assumptions!$E$7 -> 23.76 | G8: =G6*Assumptions!$E$7 -> 23.76 | H8: =H6*Assumptions!$E$7 -> 18.48 | I8: =I6*Assumptions!$E$7 -> 15.84 | J8: =J6*Assumptions!$E$7 -> 10.56 | ... L8: =L6*Assumptions!$E$7 -> 0 | M8: =SUM(C8:L8) -> 132
B9: Total pre-IDC spend | C9: =SUM(C6:C8) -> 71.1 | D9: =SUM(D6:D8) -> 132.7 | E9: =SUM(E6:E8) -> 194.3 | F9: =SUM(F6:F8) -> 231.26 | G9: =SUM(G6:G8) -> 231.26 | H9: =SUM(H6:H8) -> 181.98 | I9: =SUM(I6:I8) -> 157.34 | J9: =SUM(J6:J8) -> 108.06 | ... L9: =SUM(L6:L8) -> 9.5 | M9: =SUM(C9:L9) -> 1327
B10: Equity draw | C10: =C9*(1-Assumptions!$E$8) -> 24.885 | D10: =D9*(1-Assumptions!$E$8) -> 46.445 | E10: =E9*(1-Assumptions!$E$8) -> 68.005 | F10: =F9*(1-Assumptions!$E$8) -> 80.941 | G10: =G9*(1-Assumptions!$E$8) -> 80.941 | H10: =H9*(1-Assumptions!$E$8) -> 63.693 | I10: =I9*(1-Assumptions!$E$8) -> 55.069 | J10: =J9*(1-Assumptions!$E$8) -> 37.821 | ... L10: =L9*(1-Assumptions!$E$8) -> 3.325 | M10: =SUM(C10:L10) -> 464.45
B11: Debt draw | C11: =C9*Assumptions!$E$8 -> 46.215 | D11: =D9*Assumptions!$E$8 -> 86.255 | E11: =E9*Assumptions!$E$8 -> 126.295 | F11: =F9*Assumptions!$E$8 -> 150.319 | G11: =G9*Assumptions!$E$8 -> 150.319 | H11: =H9*Assumptions!$E$8 -> 118.287 | I11: =I9*Assumptions!$E$8 -> 102.271 | J11: =J9*Assumptions!$E$8 -> 70.239 | ... L11: =L9*Assumptions!$E$8 -> 6.175 | M11: =SUM(C11:L11) -> 862.55
B12: Beginning construction debt | C12: 0 | D12: =C14 -> 46.734919 | E12: =D14 -> 135.01182 | F12: =E14 -> 265.76541 | G12: =F14 -> 423.75522 | H12: =G14 -> 585.2998 | I12: =H14 -> 718.08677 | J12: =I14 -> 837.66527 | K12: =J14 -> 927.54193 | L12: =K14 -> 954.65609 | M12: =SUM(C12:L12) -> 4894.5172
B13: Interest during construction | C13: =(C12+0.5*C11)*Assumptions!$E$10/4 -> 0.51991875 | D13: =(D12+0.5*D11)*Assumptions!$E$10/4 -> 2.0219044 | E13: =(E12+0.5*E11)*Assumptions!$E$10/4 -> 4.4585848 | F13: =(F12+0.5*F11)*Assumptions!$E$10/4 -> 7.6708104 | G13: =(G12+0.5*G11)*Assumptions!$E$10/4 -> 11.225581 | H13: =(H12+0.5*H11)*Assumptions!$E$10/4 -> 14.499974 | I13: =(I12+0.5*I11)*Assumptions!$E$10/4 -> 17.307501 | J13: =(J12+0.5*J11)*Assumptions!$E$10/4 -> 19.637657 | ... L13: =(L12+0.5*L11)*Assumptions!$E$10/4 -> 21.549231 | M13: =SUM(C13:L13) -> 119.83033
B14: Ending construction debt | C14: =C12+C11+C13 -> 46.734919 | D14: =D12+D11+D13 -> 135.01182 | E14: =E12+E11+E13 -> 265.76541 | F14: =F12+F11+F13 -> 423.75522 | G14: =G12+G11+G13 -> 585.2998 | H14: =H12+H11+H13 -> 718.08677 | I14: =I12+I11+I13 -> 837.66527 | J14: =J12+J11+J13 -> 927.54193 | ... L14: =L12+L11+L13 -> 982.38033 | M14: =L14 -> 982.38033
B15: Cumulative project spend | C15: =C9 -> 71.1 | D15: =C15+D9 -> 203.8 | E15: =D15+E9 -> 398.1 | F15: =E15+F9 -> 629.36 | G15: =F15+G9 -> 860.62 | H15: =G15+H9 -> 1042.6 | I15: =H15+I9 -> 1199.94 | J15: =I15+J9 -> 1308 | K15: =J15+K9 -> 1317.5 | L15: =K15+L9 -> 1327 | M15: =L15 -> 1327

Sheet Sources & Uses
B2: Sources & Uses at Financial Close
B4: Uses | C4: Amount | E4: Sources | F4: Amount
B5: Hard construction cost | C5: =Construction!M6 -> 1100 | E5: Construction / term debt | F5: =Construction!M14 -> 982.38033
B6: Development / owner costs | C6: =Construction!M7 -> 95 | E6: Sponsor equity | F6: =MAX(0,C10-F5) -> 523.39282
B7: Contingency | C7: =Construction!M8 -> 132 | E7: Grants / subordinated support | F7: 0
B8: Interest during construction | C8: =Construction!M13 -> 119.83033 | E8: Total sources | F8: =SUM(F5:F7) -> 1505.7731
B9: Initial DSRA funding | C9: =DSRA!C7 -> 58.94282 | E9: Sources less uses | F9: =F8-C10 -> 0
B10: Total uses | C10: =SUM(C5:C9) -> 1505.7731

Sheet Operations
B2: Ten-Year Operating Forecast and CFADS
B4: $mm | C4: Year 1 | D4: Year 2 | E4: Year 3 | F4: Year 4 | G4: Year 5 | H4: Year 6 | I4: Year 7 | J4: Year 8 | K4: Year 9 | L4: Year 10
B5: Nominal contracted / merchant revenue | C5: =Assumptions!E11 -> 135 | D5: =C5*(1+Assumptions!$E$12+Assumptions!$E$24) -> 139.05 | E5: =D5*(1+Assumptions!$E$12+Assumptions!$E$24) -> 143.2215 | F5: =E5*(1+Assumptions!$E$12+Assumptions!$E$24) -> 147.51815 | G5: =F5*(1+Assumptions!$E$12+Assumptions!$E$24) -> 151.94369 | H5: =G5*(1+Assumptions!$E$12+Assumptions!$E$24) -> 156.502 | I5: =H5*(1+Assumptions!$E$12+Assumptions!$E$24) -> 161.19706 | J5: =I5*(1+Assumptions!$E$12+Assumptions!$E$24) -> 166.03297 | K5: =J5*(1+Assumptions!$E$12+Assumptions!$E$24) -> 171.01396 | L5: =K5*(1+Assumptions!$E$12+Assumptions!$E$24) -> 176.14438
B6: Availability-adjusted revenue | C6: =C5*Assumptions!$E$23 -> 97.2 | D6: =D5*Assumptions!$E$23 -> 100.116 | E6: =E5*Assumptions!$E$23 -> 103.11948 | F6: =F5*Assumptions!$E$23 -> 106.21306 | G6: =G5*Assumptions!$E$23 -> 109.39946 | H6: =H5*Assumptions!$E$23 -> 112.68144 | I6: =I5*Assumptions!$E$23 -> 116.06188 | J6: =J5*Assumptions!$E$23 -> 119.54374 | ... L6: =L5*Assumptions!$E$23 -> 126.82395
B7: Operating cost | C7: =C6*Assumptions!$E$13 -> 34.992 | D7: =D6*Assumptions!$E$13 -> 36.04176 | E7: =E6*Assumptions!$E$13 -> 37.123013 | F7: =F6*Assumptions!$E$13 -> 38.236703 | G7: =G6*Assumptions!$E$13 -> 39.383804 | H7: =H6*Assumptions!$E$13 -> 40.565318 | I7: =I6*Assumptions!$E$13 -> 41.782278 | J7: =J6*Assumptions!$E$13 -> 43.035746 | ... L7: =L6*Assumptions!$E$13 -> 45.656623
B8: EBITDA | C8: =C6-C7 -> 62.208 | D8: =D6-D7 -> 64.07424 | E8: =E6-E7 -> 65.996467 | F8: =F6-F7 -> 67.976361 | G8: =G6-G7 -> 70.015652 | H8: =H6-H7 -> 72.116122 | I8: =I6-I7 -> 74.279605 | J8: =J6-J7 -> 76.507993 | ... L8: =L6-L7 -> 81.16733
B9: Cash taxes | C9: =MAX(0,C8*Assumptions!$E$15) -> 6.2208 | D9: =MAX(0,D8*Assumptions!$E$15) -> 6.407424 | E9: =MAX(0,E8*Assumptions!$E$15) -> 6.5996467 | F9: =MAX(0,F8*Assumptions!$E$15) -> 6.7976361 | G9: =MAX(0,G8*Assumptions!$E$15) -> 7.0015652 | H9: =MAX(0,H8*Assumptions!$E$15) -> 7.2116122 | I9: =MAX(0,I8*Assumptions!$E$15) -> 7.4279605 | J9: =MAX(0,J8*Assumptions!$E$15) -> 7.6507993 | ... L9: =MAX(0,L8*Assumptions!$E$15) -> 8.116733
B10: Maintenance capex | C10: =C6*Assumptions!$E$14 -> 4.86 | D10: =D6*Assumptions!$E$14 -> 5.0058 | E10: =E6*Assumptions!$E$14 -> 5.155974 | F10: =F6*Assumptions!$E$14 -> 5.3106532 | G10: =G6*Assumptions!$E$14 -> 5.4699728 | H10: =H6*Assumptions!$E$14 -> 5.634072 | I10: =I6*Assumptions!$E$14 -> 5.8030942 | J10: =J6*Assumptions!$E$14 -> 5.977187 | ... L10: =L6*Assumptions!$E$14 -> 6.3411977
B11: Decommissioning / lifecycle reserve | C11: =Assumptions!$E$22 -> 4 | D11: =Assumptions!$E$22 -> 4 | E11: =Assumptions!$E$22 -> 4 | F11: =Assumptions!$E$22 -> 4 | G11: =Assumptions!$E$22 -> 4 | H11: =Assumptions!$E$22 -> 4 | I11: =Assumptions!$E$22 -> 4 | J11: =Assumptions!$E$22 -> 4 | ... L11: =Assumptions!$E$22 -> 4
B12: CFADS | C12: =C8-C9-C10-C11 -> 47.1272 | D12: =D8-D9-D10-D11 -> 48.661016 | E12: =E8-E9-E10-E11 -> 50.240846 | F12: =F8-F9-F10-F11 -> 51.868072 | G12: =G8-G9-G10-G11 -> 53.544114 | H12: =H8-H9-H10-H11 -> 55.270437 | I12: =I8-I9-I10-I11 -> 57.048551 | J12: =J8-J9-J10-J11 -> 58.880007 | ... L12: =L8-L9-L10-L11 -> 62.7094

Sheet Debt Sculpting
B2: Sculpted Term Debt Schedule
B4: $mm / x | C4: Year 1 | D4: Year 2 | E4: Year 3 | F4: Year 4 | G4: Year 5 | H4: Year 6 | I4: Year 7 | J4: Year 8 | K4: Year 9 | L4: Year 10
B5: Beginning debt | C5: =Construction!M14 -> 982.38033 | D5: =C9 -> 982.38033 | E5: =D9 -> 982.38033 | F5: =E9 -> 982.38033 | G5: =F9 -> 982.38033 | H5: =G9 -> 982.38033 | I5: =H9 -> 982.38033 | J5: =I9 -> 982.38033 | K5: =J9 -> 982.38033 | L5: =K9 -> 982.38033
B6: Cash interest | C6: =C5*Assumptions!$E$18 -> 78.590426 | D6: =D5*Assumptions!$E$18 -> 78.590426 | E6: =E5*Assumptions!$E$18 -> 78.590426 | F6: =F5*Assumptions!$E$18 -> 78.590426 | G6: =G5*Assumptions!$E$18 -> 78.590426 | H6: =H5*Assumptions!$E$18 -> 78.590426 | I6: =I5*Assumptions!$E$18 -> 78.590426 | J6: =J5*Assumptions!$E$18 -> 78.590426 | ... L6: =L5*Assumptions!$E$18 -> 78.590426
B7: Maximum debt service at target DSCR | C7: =Operations!C12/Assumptions!$E$16 -> 32.501517 | D7: =Operations!D12/Assumptions!$E$16 -> 33.559321 | E7: =Operations!E12/Assumptions!$E$16 -> 34.64886 | F7: =Operations!F12/Assumptions!$E$16 -> 35.771084 | G7: =Operations!G12/Assumptions!$E$16 -> 36.926975 | H7: =Operations!H12/Assumptions!$E$16 -> 38.117543 | I7: =Operations!I12/Assumptions!$E$16 -> 39.343828 | J7: =Operations!J12/Assumptions!$E$16 -> 40.606901 | ... L7: =Operations!L12/Assumptions!$E$16 -> 43.247862
B8: Scheduled principal | C8: =MIN(C5,MAX(0,MAX(0,C7-C6))) -> 0 | D8: =MIN(D5,MAX(0,MAX(0,D7-D6))) -> 0 | E8: =MIN(E5,MAX(0,MAX(0,E7-E6))) -> 0 | F8: =MIN(F5,MAX(0,MAX(0,F7-F6))) -> 0 | G8: =MIN(G5,MAX(0,MAX(0,G7-G6))) -> 0 | H8: =MIN(H5,MAX(0,MAX(0,H7-H6))) -> 0 | I8: =MIN(I5,MAX(0,MAX(0,I7-I6))) -> 0 | J8: =MIN(J5,MAX(0,MAX(0,J7-J6))) -> 0 | K8: =MIN(K5,MAX(0,MAX(0,K7-K6))) -> 0 | L8: =MIN(L5,MAX(L5,MAX(0,L7-L6))) -> 982.38033
B9: Ending debt | C9: =MAX(0,C5-C8) -> 982.38033 | D9: =MAX(0,D5-D8) -> 982.38033 | E9: =MAX(0,E5-E8) -> 982.38033 | F9: =MAX(0,F5-F8) -> 982.38033 | G9: =MAX(0,G5-G8) -> 982.38033 | H9: =MAX(0,H5-H8) -> 982.38033 | I9: =MAX(0,I5-I8) -> 982.38033 | J9: =MAX(0,J5-J8) -> 982.38033 | ... L9: =MAX(0,L5-L8) -> 0
B10: Actual debt service | C10: =C6+C8 -> 78.590426 | D10: =D6+D8 -> 78.590426 | E10: =E6+E8 -> 78.590426 | F10: =F6+F8 -> 78.590426 | G10: =G6+G8 -> 78.590426 | H10: =H6+H8 -> 78.590426 | I10: =I6+I8 -> 78.590426 | J10: =J6+J8 -> 78.590426 | ... L10: =L6+L8 -> 1060.9708
B11: CFADS | C11: =Operations!C12 -> 47.1272 | D11: =Operations!D12 -> 48.661016 | E11: =Operations!E12 -> 50.240846 | F11: =Operations!F12 -> 51.868072 | G11: =Operations!G12 -> 53.544114 | H11: =Operations!H12 -> 55.270437 | I11: =Operations!I12 -> 57.048551 | J11: =Operations!J12 -> 58.880007 | ... L11: =Operations!L12 -> 62.7094
B12: DSCR | C12: =IFERROR(C11/C10,0) -> 0.59965574 | D12: =IFERROR(D11/D10,0) -> 0.61917231 | E12: =IFERROR(E11/E10,0) -> 0.63927439 | F12: =IFERROR(F11/F10,0) -> 0.65997952 | G12: =IFERROR(G11/G10,0) -> 0.68130581 | H12: =IFERROR(H11/H10,0) -> 0.70327189 | I12: =IFERROR(I11/I10,0) -> 0.72589695 | J12: =IFERROR(J11/J10,0) -> 0.74920076 | ... L12: =IFERROR(L11/L10,0) -> 0.059105682
B13: Discount factor | C13: =1/(1+Assumptions!$E$21)^1 -> 0.92165899 | D13: =1/(1+Assumptions!$E$21)^2 -> 0.84945529 | E13: =1/(1+Assumptions!$E$21)^3 -> 0.7829081 | F13: =1/(1+Assumptions!$E$21)^4 -> 0.72157428 | G13: =1/(1+Assumptions!$E$21)^5 -> 0.66504542 | H13: =1/(1+Assumptions!$E$21)^6 -> 0.61294509 | I13: =1/(1+Assumptions!$E$21)^7 -> 0.56492635 | J13: =1/(1+Assumptions!$E$21)^8 -> 0.52066945 | K13: =1/(1+Assumptions!$E$21)^9 -> 0.47987968 | L13: =1/(1+Assumptions!$E$21)^10 -> 0.44228542
B14: PV of CFADS | C14: =C11*C13 -> 43.435207 | D14: =D11*D13 -> 41.335357 | E14: =E11*E13 -> 39.333966 | F14: =F11*F13 -> 37.426667 | G14: =G11*G13 -> 35.609268 | H14: =H11*H13 -> 33.877743 | I14: =I11*I13 -> 32.228229 | J14: =J11*J13 -> 30.657021 | ... L14: =L11*L13 -> 27.735453
B15: LLCR from each year | C15: =IFERROR(SUM(C14:$L$14)/C5,0) -> 0.35709131 | D15: =IFERROR(SUM(D14:$L$14)/D5,0) -> 0.31287706 | E15: =IFERROR(SUM(E14:$L$14)/E5,0) -> 0.27080032 | F15: =IFERROR(SUM(F14:$L$14)/F5,0) -> 0.23076088 | G15: =IFERROR(SUM(G14:$L$14)/G5,0) -> 0.19266294 | H15: =IFERROR(SUM(H14:$L$14)/H5,0) -> 0.15641499 | I15: =IFERROR(SUM(I14:$L$14)/I5,0) -> 0.12192963 | J15: =IFERROR(SUM(J14:$L$14)/J5,0) -> 0.089123362 | ... L15: =IFERROR(SUM(L14:$L$14)/L5,0) -> 0.028232907

Sheet DSRA
B2: Debt Service Reserve Account
B4: $mm | C4: Year 1 | D4: Year 2 | E4: Year 3 | F4: Year 4 | G4: Year 5 | H4: Year 6 | I4: Year 7 | J4: Year 8 | K4: Year 9 | L4: Year 10
B5: Forward debt service | C5: ='Debt Sculpting'!D10 -> 78.590426 | D5: ='Debt Sculpting'!E10 -> 78.590426 | E5: ='Debt Sculpting'!F10 -> 78.590426 | F5: ='Debt Sculpting'!G10 -> 78.590426 | G5: ='Debt Sculpting'!H10 -> 78.590426 | H5: ='Debt Sculpting'!I10 -> 78.590426 | I5: ='Debt Sculpting'!J10 -> 78.590426 | J5: ='Debt Sculpting'!K10 -> 78.590426 | K5: ='Debt Sculpting'!L10 -> 1060.9708 | L5: ='Debt Sculpting'!L10 -> 1060.9708
B6: Required DSRA | C6: =C5*Assumptions!$E$20/12 -> 58.94282 | D6: =D5*Assumptions!$E$20/12 -> 58.94282 | E6: =E5*Assumptions!$E$20/12 -> 58.94282 | F6: =F5*Assumptions!$E$20/12 -> 58.94282 | G6: =G5*Assumptions!$E$20/12 -> 58.94282 | H6: =H5*Assumptions!$E$20/12 -> 58.94282 | I6: =I5*Assumptions!$E$20/12 -> 58.94282 | J6: =J5*Assumptions!$E$20/12 -> 58.94282 | ... L6: =L5*Assumptions!$E$20/12 -> 795.72806
B7: Beginning DSRA | C7: =C6 -> 58.94282 | D7: =C9 -> 58.94282 | E7: =D9 -> 58.94282 | F7: =E9 -> 58.94282 | G7: =F9 -> 58.94282 | H7: =G9 -> 58.94282 | I7: =H9 -> 58.94282 | J7: =I9 -> 58.94282 | K7: =J9 -> 58.94282 | L7: =K9 -> 795.72806
B8: Funding / (release) | C8: =C6-C7 -> 0 | D8: =D6-D7 -> 0 | E8: =E6-E7 -> 0 | F8: =F6-F7 -> 0 | G8: =G6-G7 -> 0 | H8: =H6-H7 -> 0 | I8: =I6-I7 -> 0 | J8: =J6-J7 -> 0 | ... L8: =L6-L7 -> 0
B9: Ending DSRA | C9: =C7+C8 -> 58.94282 | D9: =D7+D8 -> 58.94282 | E9: =E7+E8 -> 58.94282 | F9: =F7+F8 -> 58.94282 | G9: =G7+G8 -> 58.94282 | H9: =H7+H8 -> 58.94282 | I9: =I7+I8 -> 58.94282 | J9: =J7+J8 -> 58.94282 | ... L9: =L7+L8 -> 795.72806
B10: DSRA funding at close | C10: =IF(COLUMN()=3,C7,0) -> 58.94282 | D10: =IF(COLUMN()=3,D7,0) -> 0 | E10: =IF(COLUMN()=3,E7,0) -> 0 | F10: =IF(COLUMN()=3,F7,0) -> 0 | G10: =IF(COLUMN()=3,G7,0) -> 0 | H10: =IF(COLUMN()=3,H7,0) -> 0 | I10: =IF(COLUMN()=3,I7,0) -> 0 | J10: =IF(COLUMN()=3,J7,0) -> 0 | ... L10: =IF(COLUMN()=3,L7,0) -> 0

Sheet Coverage
B2: Coverage, Liquidity, and Tail Risk
B4: Metric | C4: Year 1 | D4: Year 2 | E4: Year 3 | F4: Year 4 | G4: Year 5 | H4: Year 6 | I4: Year 7 | J4: Year 8 | K4: Year 9 | L4: Year 10
B5: DSCR | C5: ='Debt Sculpting'!C12 -> 0.59965574 | D5: ='Debt Sculpting'!D12 -> 0.61917231 | E5: ='Debt Sculpting'!E12 -> 0.63927439 | F5: ='Debt Sculpting'!F12 -> 0.65997952 | G5: ='Debt Sculpting'!G12 -> 0.68130581 | H5: ='Debt Sculpting'!H12 -> 0.70327189 | I5: ='Debt Sculpting'!I12 -> 0.72589695 | J5: ='Debt Sculpting'!J12 -> 0.74920076 | ... L5: ='Debt Sculpting'!L12 -> 0.059105682
B6: Minimum DSCR | C6: =Assumptions!$E$17 -> 1.2 | D6: =Assumptions!$E$17 -> 1.2 | E6: =Assumptions!$E$17 -> 1.2 | F6: =Assumptions!$E$17 -> 1.2 | G6: =Assumptions!$E$17 -> 1.2 | H6: =Assumptions!$E$17 -> 1.2 | I6: =Assumptions!$E$17 -> 1.2 | J6: =Assumptions!$E$17 -> 1.2 | ... L6: =Assumptions!$E$17 -> 1.2
B7: DSCR headroom | C7: =C5-C6 -> -0.60034426 | D7: =D5-D6 -> -0.58082769 | E7: =E5-E6 -> -0.56072561 | F7: =F5-F6 -> -0.54002048 | G7: =G5-G6 -> -0.51869419 | H7: =H5-H6 -> -0.49672811 | I7: =I5-I6 -> -0.47410305 | J7: =J5-J6 -> -0.45079924 | ... L7: =L5-L6 -> -1.1408943
B8: LLCR | C8: ='Debt Sculpting'!C15 -> 0.35709131 | D8: ='Debt Sculpting'!D15 -> 0.31287706 | E8: ='Debt Sculpting'!E15 -> 0.27080032 | F8: ='Debt Sculpting'!F15 -> 0.23076088 | G8: ='Debt Sculpting'!G15 -> 0.19266294 | H8: ='Debt Sculpting'!H15 -> 0.15641499 | I8: ='Debt Sculpting'!I15 -> 0.12192963 | J8: ='Debt Sculpting'!J15 -> 0.089123362 | ... L8: ='Debt Sculpting'!L15 -> 0.028232907
B9: PLCR | C9: =IFERROR(SUM('Debt Sculpting'!C14:$L$14)/'Debt Sculpting'!C5,0) -> 0.35709131 | D9: =IFERROR(SUM('Debt Sculpting'!D14:$L$14)/'Debt Sculpting'!D5,0) -> 0.31287706 | E9: =IFERROR(SUM('Debt Sculpting'!E14:$L$14)/'Debt Sculpting'!E5,0) -> 0.27080032 | F9: =IFERROR(SUM('Debt Sculpting'!F14:$L$14)/'Debt Sculpting'!F5,0) -> 0.23076088 | G9: =IFERROR(SUM('Debt Sculpting'!G14:$L$14)/'Debt Sculpting'!G5,0) -> 0.19266294 | H9: =IFERROR(SUM('Debt Sculpting'!H14:$L$14)/'Debt Sculpting'!H5,0) -> 0.15641499 | I9: =IFERROR(SUM('Debt Sculpting'!I14:$L$14)/'Debt Sculpting'!I5,0) -> 0.12192963 | J9: =IFERROR(SUM('Debt Sculpting'!J14:$L$14)/'Debt Sculpting'!J5,0) -> 0.089123362 | ... L9: =IFERROR(SUM('Debt Sculpting'!L14:$L$14)/'Debt Sculpting'!L5,0) -> 0.028232907
B10: Debt / EBITDA | C10: =IFERROR('Debt Sculpting'!C9/Operations!C8,0) -> 15.791865 | D10: =IFERROR('Debt Sculpting'!D9/Operations!D8,0) -> 15.331908 | E10: =IFERROR('Debt Sculpting'!E9/Operations!E8,0) -> 14.885347 | F10: =IFERROR('Debt Sculpting'!F9/Operations!F8,0) -> 14.451793 | G10: =IFERROR('Debt Sculpting'!G9/Operations!G8,0) -> 14.030867 | H10: =IFERROR('Debt Sculpting'!H9/Operations!H8,0) -> 13.622201 | I10: =IFERROR('Debt Sculpting'!I9/Operations!I8,0) -> 13.225438 | J10: =IFERROR('Debt Sculpting'!J9/Operations!J8,0) -> 12.840231 | ... L10: =IFERROR('Debt Sculpting'!L9/Operations!L8,0) -> 0
B11: DSRA coverage | C11: =IFERROR(DSRA!C9/DSRA!C6,0) -> 1 | D11: =IFERROR(DSRA!D9/DSRA!D6,0) -> 1 | E11: =IFERROR(DSRA!E9/DSRA!E6,0) -> 1 | F11: =IFERROR(DSRA!F9/DSRA!F6,0) -> 1 | G11: =IFERROR(DSRA!G9/DSRA!G6,0) -> 1 | H11: =IFERROR(DSRA!H9/DSRA!H6,0) -> 1 | I11: =IFERROR(DSRA!I9/DSRA!I6,0) -> 1 | J11: =IFERROR(DSRA!J9/DSRA!J6,0) -> 1 | ... L11: =IFERROR(DSRA!L9/DSRA!L6,0) -> 1
B12: Covenant status | C12: =IF(AND(C7>=0,C8>=1,C11>=1),"PASS","BREACH") -> BREACH | D12: =IF(AND(D7>=0,D8>=1,D11>=1),"PASS","BREACH") -> BREACH | E12: =IF(AND(E7>=0,E8>=1,E11>=1),"PASS","BREACH") -> BREACH | F12: =IF(AND(F7>=0,F8>=1,F11>=1),"PASS","BREACH") -> BREACH | G12: =IF(AND(G7>=0,G8>=1,G11>=1),"PASS","BREACH") -> BREACH | H12: =IF(AND(H7>=0,H8>=1,H11>=1),"PASS","BREACH") -> BREACH | I12: =IF(AND(I7>=0,I8>=1,I11>=1),"PASS","BREACH") -> BREACH | J12: =IF(AND(J7>=0,J8>=1,J11>=1),"PASS","BREACH") -> BREACH | ... L12: =IF(AND(L7>=0,L8>=1,L11>=1),"PASS","BREACH") -> BREACH

Sheet Sensitivity
B2: Minimum DSCR Sensitivity
B4: Revenue haircut / Operating cost | C4: 0.22 | D4: 0.28 | E4: 0.34 | F4: 0.4 | G4: 0.46
B5: 0 | C5: =MIN(MAX(0,Operations!C5*(1-$B5)*(1-C$4)-Operations!C9-Operations!C10-Operations!C11)/MAX(0.000001,'Debt Sculpting'!C10),MAX(0,Operations!D5*(1-$B5)*(1-C$4)-Operations!D9-Operations!D10-Operations!D11)/MAX(0.000001,'Debt Sculpting'!D10),MAX(0,Operations!E5*(1-$B5)*(1-C$4)-Operations!E9-Operations!E10-Operations!E11)/MAX(0.000001,'Debt Sculpting'!E10),MAX(0,Operations!F5*(1-$B5)*(1-C$4)-Operations!F9-Operations!F10-Operations!F11)/MAX(0.000001,'Debt Sculpting'!F10),MAX(0,Operations!G5*(1-$B5)*(1-C$4)-Operations!G9-Operations!G10-Operations!G11)/MAX(0.000001,'Debt Sculpting'!G10),MAX(0,Operations!H5*(1-$B5)*(1-C$4)-Operations!H9-Operations!H10-Operations!H11)/MAX(0.000001,'Debt Sculpting'!H10),MAX(0,Operations!I5*(1-$B5)*(1-C$4)-Operations!I9-Operations!I10-Operations!I11)/MAX(0.000001,'Debt Sculpting'!I10),MAX(0,Operations!J5*(1-$B5)*(1-C$4)-Operations!J9-Operations!J10-Operations!J11)/MAX(0.000001,'Debt Sculpting'!J10),MAX(0,Operations!K5*(1-$B5)*(1-C$4)-Operations!K9-Operations!K10-Operations!K11)/MAX(0.000001,'Debt Sculpting'!K10),MAX(0,Operations!L5*(1-$B5)*(1-C$4)-Operations!L9-Operations!L10-Operations!L11)/MAX(0.000001,'Debt Sculpting'!L10)) -> 0.11209987 | D5: =MIN(MAX(0,Operations!C5*(1-$B5)*(1-D$4)-Operations!C9-Operations!C10-Operations!C11)/MAX(0.000001,'Debt Sculpting'!C10),MAX(0,Operations!D5*(1-$B5)*(1-D$4)-Operations!D9-Operations!D10-Operations!D11)/MAX(0.000001,'Debt Sculpting'!D10),MAX(0,Operations!E5*(1-$B5)*(1-D$4)-Operations!E9-Operations!E10-Operations!E11)/MAX(0.000001,'Debt Sculpting'!E10),MAX(0,Operations!F5*(1-$B5)*(1-D$4)-Operations!F9-Operations!F10-Operations!F11)/MAX(0.000001,'Debt Sculpting'!F10),MAX(0,Operations!G5*(1-$B5)*(1-D$4)-Operations!G9-Operations!G10-Operations!G11)/MAX(0.000001,'Debt Sculpting'!G10),MAX(0,Operations!H5*(1-$B5)*(1-D$4)-Operations!H9-Operations!H10-Operations!H11)/MAX(0.000001,'Debt Sculpting'!H10),MAX(0,Operations!I5*(1-$B5)*(1-D$4)-Operations!I9-Operations!I10-Operations!I11)/MAX(0.000001,'Debt Sculpting'!I10),MAX(0,Operations!J5*(1-$B5)*(1-D$4)-Operations!J9-Operations!J10-Operations!J11)/MAX(0.000001,'Debt Sculpting'!J10),MAX(0,Operations!K5*(1-$B5)*(1-D$4)-Operations!K9-Operations!K10-Operations!K11)/MAX(0.000001,'Debt Sculpting'!K10),MAX(0,Operations!L5*(1-$B5)*(1-D$4)-Operations!L9-Operations!L10-Operations!L11)/MAX(0.000001,'Debt Sculpting'!L10)) -> 0.10213856 | E5: =MIN(MAX(0,Operations!C5*(1-$B5)*(1-E$4)-Operations!C9-Operations!C10-Operations!C11)/MAX(0.000001,'Debt Sculpting'!C10),MAX(0,Operations!D5*(1-$B5)*(1-E$4)-Operations!D9-Operations!D10-Operations!D11)/MAX(0.000001,'Debt Sculpting'!D10),MAX(0,Operations!E5*(1-$B5)*(1-E$4)-Operations!E9-Operations!E10-Operations!E11)/MAX(0.000001,'Debt Sculpting'!E10),MAX(0,Operations!F5*(1-$B5)*(1-E$4)-Operations!F9-Operations!F10-Operations!F11)/MAX(0.000001,'Debt Sculpting'!F10),MAX(0,Operations!G5*(1-$B5)*(1-E$4)-Operations!G9-Operations!G10-Operations!G11)/MAX(0.000001,'Debt Sculpting'!G10),MAX(0,Operations!H5*(1-$B5)*(1-E$4)-Operations!H9-Operations!H10-Operations!H11)/MAX(0.000001,'Debt Sculpting'!H10),MAX(0,Operations!I5*(1-$B5)*(1-E$4)-Operations!I9-Operations!I10-Operations!I11)/MAX(0.000001,'Debt Sculpting'!I10),MAX(0,Operations!J5*(1-$B5)*(1-E$4)-Operations!J9-Operations!J10-Operations!J11)/MAX(0.000001,'Debt Sculpting'!J10),MAX(0,Operations!K5*(1-$B5)*(1-E$4)-Operations!K9-Operations!K10-Operations!K11)/MAX(0.000001,'Debt Sculpting'!K10),MAX(0,Operations!L5*(1-$B5)*(1-E$4)-Operations!L9-Operations!L10-Operations!L11)/MAX(0.000001,'Debt Sculpting'!L10)) -> 0.092177244 | F5: =MIN(MAX(0,Operations!C5*(1-$B5)*(1-F$4)-Operations!C9-Operations!C10-Operations!C11)/MAX(0.000001,'Debt Sculpting'!C10),MAX(0,Operations!D5*(1-$B5)*(1-F$4)-Operations!D9-Operations!D10-Operations!D11)/MAX(0.000001,'Debt Sculpting'!D10),MAX(0,Operations!E5*(1-$B5)*(1-F$4)-Operations!E9-Operations!E10-Operations!E11)/MAX(0.000001,'Debt Sculpting'!E10),MAX(0,Operations!F5*(1-$B5)*(1-F$4)-Operations!F9-Operations!F10-Operations!F11)/MAX(0.000001,'Debt Sculpting'!F10),MAX(0,Operations!G5*(1-$B5)*(1-F$4)-Operations!G9-Operations!G10-Operations!G11)/MAX(0.000001,'Debt Sculpting'!G10),MAX(0,Operations!H5*(1-$B5)*(1-F$4)-Operations!H9-Operations!H10-Operations!H11)/MAX(0.000001,'Debt Sculpting'!H10),MAX(0,Operations!I5*(1-$B5)*(1-F$4)-Operations!I9-Operations!I10-Operations!I11)/MAX(0.000001,'Debt Sculpting'!I10),MAX(0,Operations!J5*(1-$B5)*(1-F$4)-Operations!J9-Operations!J10-Operations!J11)/MAX(0.000001,'Debt Sculpting'!J10),MAX(0,Operations!K5*(1-$B5)*(1-F$4)-Operations!K9-Operations!K10-Operations!K11)/MAX(0.000001,'Debt Sculpting'!K10),MAX(0,Operations!L5*(1-$B5)*(1-F$4)-Operations!L9-Operations!L10-Operations!L11)/MAX(0.000001,'Debt Sculpting'!L10)) -> 0.08221593 | G5: =MIN(MAX(0,Operations!C5*(1-$B5)*(1-G$4)-Operations!C9-Operations!C10-Operations!C11)/MAX(0.000001,'Debt Sculpting'!C10),MAX(0,Operations!D5*(1-$B5)*(1-G$4)-Operations!D9-Operations!D10-Operations!D11)/MAX(0.000001,'Debt Sculpting'!D10),MAX(0,Operations!E5*(1-$B5)*(1-G$4)-Operations!E9-Operations!E10-Operations!E11)/MAX(0.000001,'Debt Sculpting'!E10),MAX(0,Operations!F5*(1-$B5)*(1-G$4)-Operations!F9-Operations!F10-Operations!F11)/MAX(0.000001,'Debt Sculpting'!F10),MAX(0,Operations!G5*(1-$B5)*(1-G$4)-Operations!G9-Operations!G10-Operations!G11)/MAX(0.000001,'Debt Sculpting'!G10),MAX(0,Operations!H5*(1-$B5)*(1-G$4)-Operations!H9-Operations!H10-Operations!H11)/MAX(0.000001,'Debt Sculpting'!H10),MAX(0,Operations!I5*(1-$B5)*(1-G$4)-Operations!I9-Operations!I10-Operations!I11)/MAX(0.000001,'Debt Sculpting'!I10),MAX(0,Operations!J5*(1-$B5)*(1-G$4)-Operations!J9-Operations!J10-Operations!J11)/MAX(0.000001,'Debt Sculpting'!J10),MAX(0,Operations!K5*(1-$B5)*(1-G$4)-Operations!K9-Operations!K10-Operations!K11)/MAX(0.000001,'Debt Sculpting'!K10),MAX(0,Operations!L5*(1-$B5)*(1-G$4)-Operations!L9-Operations!L10-Operations!L11)/MAX(0.000001,'Debt Sculpting'!L10)) -> 0.072254616
B6: 0.05 | C6: =MIN(MAX(0,Operations!C5*(1-$B6)*(1-C$4)-Operations!C9-Operations!C10-Operations!C11)/MAX(0.000001,'Debt Sculpting'!C10),MAX(0,Operations!D5*(1-$B6)*(1-C$4)-Operations!D9-Operations!D10-Operations!D11)/MAX(0.000001,'Debt Sculpting'!D10),MAX(0,Operations!E5*(1-$B6)*(1-C$4)-Operations!E9-Operations!E10-Operations!E11)/MAX(0.000001,'Debt Sculpting'!E10),MAX(0,Operations!F5*(1-$B6)*(1-C$4)-Operations!F9-Operations!F10-Operations!F11)/MAX(0.000001,'Debt Sculpting'!F10),MAX(0,Operations!G5*(1-$B6)*(1-C$4)-Operations!G9-Operations!G10-Operations!G11)/MAX(0.000001,'Debt Sculpting'!G10),MAX(0,Operations!H5*(1-$B6)*(1-C$4)-Operations!H9-Operations!H10-Operations!H11)/MAX(0.000001,'Debt Sculpting'!H10),MAX(0,Operations!I5*(1-$B6)*(1-C$4)-Operations!I9-Operations!I10-Operations!I11)/MAX(0.000001,'Debt Sculpting'!I10),MAX(0,Operations!J5*(1-$B6)*(1-C$4)-Operations!J9-Operations!J10-Operations!J11)/MAX(0.000001,'Debt Sculpting'!J10),MAX(0,Operations!K5*(1-$B6)*(1-C$4)-Operations!K9-Operations!K10-Operations!K11)/MAX(0.000001,'Debt Sculpting'!K10),MAX(0,Operations!L5*(1-$B6)*(1-C$4)-Operations!L9-Operations!L10-Operations!L11)/MAX(0.000001,'Debt Sculpting'!L10)) -> 0.10562502 | D6: =MIN(MAX(0,Operations!C5*(1-$B6)*(1-D$4)-Operations!C9-Operations!C10-Operations!C11)/MAX(0.000001,'Debt Sculpting'!C10),MAX(0,Operations!D5*(1-$B6)*(1-D$4)-Operations!D9-Operations!D10-Operations!D11)/MAX(0.000001,'Debt Sculpting'!D10),MAX(0,Operations!E5*(1-$B6)*(1-D$4)-Operations!E9-Operations!E10-Operations!E11)/MAX(0.000001,'Debt Sculpting'!E10),MAX(0,Operations!F5*(1-$B6)*(1-D$4)-Operations!F9-Operations!F10-Operations!F11)/MAX(0.000001,'Debt Sculpting'!F10),MAX(0,Operations!G5*(1-$B6)*(1-D$4)-Operations!G9-Operations!G10-Operations!G11)/MAX(0.000001,'Debt Sculpting'!G10),MAX(0,Operations!H5*(1-$B6)*(1-D$4)-Operations!H9-Operations!H10-Operations!H11)/MAX(0.000001,'Debt Sculpting'!H10),MAX(0,Operations!I5*(1-$B6)*(1-D$4)-Operations!I9-Operations!I10-Operations!I11)/MAX(0.000001,'Debt Sculpting'!I10),MAX(0,Operations!J5*(1-$B6)*(1-D$4)-Operations!J9-Operations!J10-Operations!J11)/MAX(0.000001,'Debt Sculpting'!J10),MAX(0,Operations!K5*(1-$B6)*(1-D$4)-Operations!K9-Operations!K10-Operations!K11)/MAX(0.000001,'Debt Sculpting'!K10),MAX(0,Operations!L5*(1-$B6)*(1-D$4)-Operations!L9-Operations!L10-Operations!L11)/MAX(0.000001,'Debt Sculpting'!L10)) -> 0.09616177 | E6: =MIN(MAX(0,Operations!C5*(1-$B6)*(1-E$4)-Operations!C9-Operations!C10-Operations!C11)/MAX(0.000001,'Debt Sculpting'!C10),MAX(0,Operations!D5*(1-$B6)*(1-E$4)-Operations!D9-Operations!D10-Operations!D11)/MAX(0.000001,'Debt Sculpting'!D10),MAX(0,Operations!E5*(1-$B6)*(1-E$4)-Operations!E9-Operations!E10-Operations!E11)/MAX(0.000001,'Debt Sculpting'!E10),MAX(0,Operations!F5*(1-$B6)*(1-E$4)-Operations!F9-Operations!F10-Operations!F11)/MAX(0.000001,'Debt Sculpting'!F10),MAX(0,Operations!G5*(1-$B6)*(1-E$4)-Operations!G9-Operations!G10-Operations!G11)/MAX(0.000001,'Debt Sculpting'!G10),MAX(0,Operations!H5*(1-$B6)*(1-E$4)-Operations!H9-Operations!H10-Operations!H11)/MAX(0.000001,'Debt Sculpting'!H10),MAX(0,Operations!I5*(1-$B6)*(1-E$4)-Operations!I9-Operations!I10-Operations!I11)/MAX(0.000001,'Debt Sculpting'!I10),MAX(0,Operations!J5*(1-$B6)*(1-E$4)-Operations!J9-Operations!J10-Operations!J11)/MAX(0.000001,'Debt Sculpting'!J10),MAX(0,Operations!K5*(1-$B6)*(1-E$4)-Operations!K9-Operations!K10-Operations!K11)/MAX(0.000001,'Debt Sculpting'!K10),MAX(0,Operations!L5*(1-$B6)*(1-E$4)-Operations!L9-Operations!L10-Operations!L11)/MAX(0.000001,'Debt Sculpting'!L10)) -> 0.086698521 | F6: =MIN(MAX(0,Operations!C5*(1-$B6)*(1-F$4)-Operations!C9-Operations!C10-Operations!C11)/MAX(0.000001,'Debt Sculpting'!C10),MAX(0,Operations!D5*(1-$B6)*(1-F$4)-Operations!D9-Operations!D10-Operations!D11)/MAX(0.000001,'Debt Sculpting'!D10),MAX(0,Operations!E5*(1-$B6)*(1-F$4)-Operations!E9-Operations!E10-Operations!E11)/MAX(0.000001,'Debt Sculpting'!E10),MAX(0,Operations!F5*(1-$B6)*(1-F$4)-Operations!F9-Operations!F10-Operations!F11)/MAX(0.000001,'Debt Sculpting'!F10),MAX(0,Operations!G5*(1-$B6)*(1-F$4)-Operations!G9-Operations!G10-Operations!G11)/MAX(0.000001,'Debt Sculpting'!G10),MAX(0,Operations!H5*(1-$B6)*(1-F$4)-Operations!H9-Operations!H10-Operations!H11)/MAX(0.000001,'Debt Sculpting'!H10),MAX(0,Operations!I5*(1-$B6)*(1-F$4)-Operations!I9-Operations!I10-Operations!I11)/MAX(0.000001,'Debt Sculpting'!I10),MAX(0,Operations!J5*(1-$B6)*(1-F$4)-Operations!J9-Operations!J10-Operations!J11)/MAX(0.000001,'Debt Sculpting'!J10),MAX(0,Operations!K5*(1-$B6)*(1-F$4)-Operations!K9-Operations!K10-Operations!K11)/MAX(0.000001,'Debt Sculpting'!K10),MAX(0,Operations!L5*(1-$B6)*(1-F$4)-Operations!L9-Operations!L10-Operations!L11)/MAX(0.000001,'Debt Sculpting'!L10)) -> 0.077235273 | G6: =MIN(MAX(0,Operations!C5*(1-$B6)*(1-G$4)-Operations!C9-Operations!C10-Operations!C11)/MAX(0.000001,'Debt Sculpting'!C10),MAX(0,Operations!D5*(1-$B6)*(1-G$4)-Operations!D9-Operations!D10-Operations!D11)/MAX(0.000001,'Debt Sculpting'!D10),MAX(0,Operations!E5*(1-$B6)*(1-G$4)-Operations!E9-Operations!E10-Operations!E11)/MAX(0.000001,'Debt Sculpting'!E10),MAX(0,Operations!F5*(1-$B6)*(1-G$4)-Operations!F9-Operations!F10-Operations!F11)/MAX(0.000001,'Debt Sculpting'!F10),MAX(0,Operations!G5*(1-$B6)*(1-G$4)-Operations!G9-Operations!G10-Operations!G11)/MAX(0.000001,'Debt Sculpting'!G10),MAX(0,Operations!H5*(1-$B6)*(1-G$4)-Operations!H9-Operations!H10-Operations!H11)/MAX(0.000001,'Debt Sculpting'!H10),MAX(0,Operations!I5*(1-$B6)*(1-G$4)-Operations!I9-Operations!I10-Operations!I11)/MAX(0.000001,'Debt Sculpting'!I10),MAX(0,Operations!J5*(1-$B6)*(1-G$4)-Operations!J9-Operations!J10-Operations!J11)/MAX(0.000001,'Debt Sculpting'!J10),MAX(0,Operations!K5*(1-$B6)*(1-G$4)-Operations!K9-Operations!K10-Operations!K11)/MAX(0.000001,'Debt Sculpting'!K10),MAX(0,Operations!L5*(1-$B6)*(1-G$4)-Operations!L9-Operations!L10-Operations!L11)/MAX(0.000001,'Debt Sculpting'!L10)) -> 0.067772025
B7: 0.1 | C7: =MIN(MAX(0,Operations!C5*(1-$B7)*(1-C$4)-Operations!C9-Operations!C10-Operations!C11)/MAX(0.000001,'Debt Sculpting'!C10),MAX(0,Operations!D5*(1-$B7)*(1-C$4)-Operations!D9-Operations!D10-Operations!D11)/MAX(0.000001,'Debt Sculpting'!D10),MAX(0,Operations!E5*(1-$B7)*(1-C$4)-Operations!E9-Operations!E10-Operations!E11)/MAX(0.000001,'Debt Sculpting'!E10),MAX(0,Operations!F5*(1-$B7)*(1-C$4)-Operations!F9-Operations!F10-Operations!F11)/MAX(0.000001,'Debt Sculpting'!F10),MAX(0,Operations!G5*(1-$B7)*(1-C$4)-Operations!G9-Operations!G10-Operations!G11)/MAX(0.000001,'Debt Sculpting'!G10),MAX(0,Operations!H5*(1-$B7)*(1-C$4)-Operations!H9-Operations!H10-Operations!H11)/MAX(0.000001,'Debt Sculpting'!H10),MAX(0,Operations!I5*(1-$B7)*(1-C$4)-Operations!I9-Operations!I10-Operations!I11)/MAX(0.000001,'Debt Sculpting'!I10),MAX(0,Operations!J5*(1-$B7)*(1-C$4)-Operations!J9-Operations!J10-Operations!J11)/MAX(0.000001,'Debt Sculpting'!J10),MAX(0,Operations!K5*(1-$B7)*(1-C$4)-Operations!K9-Operations!K10-Operations!K11)/MAX(0.000001,'Debt Sculpting'!K10),MAX(0,Operations!L5*(1-$B7)*(1-C$4)-Operations!L9-Operations!L10-Operations!L11)/MAX(0.000001,'Debt Sculpting'!L10)) -> 0.099150164 | D7: =MIN(MAX(0,Operations!C5*(1-$B7)*(1-D$4)-Operations!C9-Operations!C10-Operations!C11)/MAX(0.000001,'Debt Sculpting'!C10),MAX(0,Operations!D5*(1-$B7)*(1-D$4)-Operations!D9-Operations!D10-Operations!D11)/MAX(0.000001,'Debt Sculpting'!D10),MAX(0,Operations!E5*(1-$B7)*(1-D$4)-Operations!E9-Operations!E10-Operations!E11)/MAX(0.000001,'Debt Sculpting'!E10),MAX(0,Operations!F5*(1-$B7)*(1-D$4)-Operations!F9-Operations!F10-Operations!F11)/MAX(0.000001,'Debt Sculpting'!F10),MAX(0,Operations!G5*(1-$B7)*(1-D$4)-Operations!G9-Operations!G10-Operations!G11)/MAX(0.000001,'Debt Sculpting'!G10),MAX(0,Operations!H5*(1-$B7)*(1-D$4)-Operations!H9-Operations!H10-Operations!H11)/MAX(0.000001,'Debt Sculpting'!H10),MAX(0,Operations!I5*(1-$B7)*(1-D$4)-Operations!I9-Operations!I10-Operations!I11)/MAX(0.000001,'Debt Sculpting'!I10),MAX(0,Operations!J5*(1-$B7)*(1-D$4)-Operations!J9-Operations!J10-Operations!J11)/MAX(0.000001,'Debt Sculpting'!J10),MAX(0,Operations!K5*(1-$B7)*(1-D$4)-Operations!K9-Operations!K10-Operations!K11)/MAX(0.000001,'Debt Sculpting'!K10),MAX(0,Operations!L5*(1-$B7)*(1-D$4)-Operations!L9-Operations!L10-Operations!L11)/MAX(0.000001,'Debt Sculpting'!L10)) -> 0.090184981 | E7: =MIN(MAX(0,Operations!C5*(1-$B7)*(1-E$4)-Operations!C9-Operations!C10-Operations!C11)/MAX(0.000001,'Debt Sculpting'!C10),MAX(0,Operations!D5*(1-$B7)*(1-E$4)-Operations!D9-Operations!D10-Operations!D11)/MAX(0.000001,'Debt Sculpting'!D10),MAX(0,Operations!E5*(1-$B7)*(1-E$4)-Operations!E9-Operations!E10-Operations!E11)/MAX(0.000001,'Debt Sculpting'!E10),MAX(0,Operations!F5*(1-$B7)*(1-E$4)-Operations!F9-Operations!F10-Operations!F11)/MAX(0.000001,'Debt Sculpting'!F10),MAX(0,Operations!G5*(1-$B7)*(1-E$4)-Operations!G9-Operations!G10-Operations!G11)/MAX(0.000001,'Debt Sculpting'!G10),MAX(0,Operations!H5*(1-$B7)*(1-E$4)-Operations!H9-Operations!H10-Operations!H11)/MAX(0.000001,'Debt Sculpting'!H10),MAX(0,Operations!I5*(1-$B7)*(1-E$4)-Operations!I9-Operations!I10-Operations!I11)/MAX(0.000001,'Debt Sculpting'!I10),MAX(0,Operations!J5*(1-$B7)*(1-E$4)-Operations!J9-Operations!J10-Operations!J11)/MAX(0.000001,'Debt Sculpting'!J10),MAX(0,Operations!K5*(1-$B7)*(1-E$4)-Operations!K9-Operations!K10-Operations!K11)/MAX(0.000001,'Debt Sculpting'!K10),MAX(0,Operations!L5*(1-$B7)*(1-E$4)-Operations!L9-Operations!L10-Operations!L11)/MAX(0.000001,'Debt Sculpting'!L10)) -> 0.081219799 | F7: =MIN(MAX(0,Operations!C5*(1-$B7)*(1-F$4)-Operations!C9-Operations!C10-Operations!C11)/MAX(0.000001,'Debt Sculpting'!C10),MAX(0,Operations!D5*(1-$B7)*(1-F$4)-Operations!D9-Operations!D10-Operations!D11)/MAX(0.000001,'Debt Sculpting'!D10),MAX(0,Operations!E5*(1-$B7)*(1-F$4)-Operations!E9-Operations!E10-Operations!E11)/MAX(0.000001,'Debt Sculpting'!E10),MAX(0,Operations!F5*(1-$B7)*(1-F$4)-Operations!F9-Operations!F10-Operations!F11)/MAX(0.000001,'Debt Sculpting'!F10),MAX(0,Operations!G5*(1-$B7)*(1-F$4)-Operations!G9-Operations!G10-Operations!G11)/MAX(0.000001,'Debt Sculpting'!G10),MAX(0,Operations!H5*(1-$B7)*(1-F$4)-Operations!H9-Operations!H10-Operations!H11)/MAX(0.000001,'Debt Sculpting'!H10),MAX(0,Operations!I5*(1-$B7)*(1-F$4)-Operations!I9-Operations!I10-Operations!I11)/MAX(0.000001,'Debt Sculpting'!I10),MAX(0,Operations!J5*(1-$B7)*(1-F$4)-Operations!J9-Operations!J10-Operations!J11)/MAX(0.000001,'Debt Sculpting'!J10),MAX(0,Operations!K5*(1-$B7)*(1-F$4)-Operations!K9-Operations!K10-Operations!K11)/MAX(0.000001,'Debt Sculpting'!K10),MAX(0,Operations!L5*(1-$B7)*(1-F$4)-Operations!L9-Operations!L10-Operations!L11)/MAX(0.000001,'Debt Sculpting'!L10)) -> 0.072254616 | G7: =MIN(MAX(0,Operations!C5*(1-$B7)*(1-G$4)-Operations!C9-Operations!C10-Operations!C11)/MAX(0.000001,'Debt Sculpting'!C10),MAX(0,Operations!D5*(1-$B7)*(1-G$4)-Operations!D9-Operations!D10-Operations!D11)/MAX(0.000001,'Debt Sculpting'!D10),MAX(0,Operations!E5*(1-$B7)*(1-G$4)-Operations!E9-Operations!E10-Operations!E11)/MAX(0.000001,'Debt Sculpting'!E10),MAX(0,Operations!F5*(1-$B7)*(1-G$4)-Operations!F9-Operations!F10-Operations!F11)/MAX(0.000001,'Debt Sculpting'!F10),MAX(0,Operations!G5*(1-$B7)*(1-G$4)-Operations!G9-Operations!G10-Operations!G11)/MAX(0.000001,'Debt Sculpting'!G10),MAX(0,Operations!H5*(1-$B7)*(1-G$4)-Operations!H9-Operations!H10-Operations!H11)/MAX(0.000001,'Debt Sculpting'!H10),MAX(0,Operations!I5*(1-$B7)*(1-G$4)-Operations!I9-Operations!I10-Operations!I11)/MAX(0.000001,'Debt Sculpting'!I10),MAX(0,Operations!J5*(1-$B7)*(1-G$4)-Operations!J9-Operations!J10-Operations!J11)/MAX(0.000001,'Debt Sculpting'!J10),MAX(0,Operations!K5*(1-$B7)*(1-G$4)-Operations!K9-Operations!K10-Operations!K11)/MAX(0.000001,'Debt Sculpting'!K10),MAX(0,Operations!L5*(1-$B7)*(1-G$4)-Operations!L9-Operations!L10-Operations!L11)/MAX(0.000001,'Debt Sculpting'!L10)) -> 0.063289434
B8: 0.15 | C8: =MIN(MAX(0,Operations!C5*(1-$B8)*(1-C$4)-Operations!C9-Operations!C10-Operations!C11)/MAX(0.000001,'Debt Sculpting'!C10),MAX(0,Operations!D5*(1-$B8)*(1-C$4)-Operations!D9-Operations!D10-Operations!D11)/MAX(0.000001,'Debt Sculpting'!D10),MAX(0,Operations!E5*(1-$B8)*(1-C$4)-Operations!E9-Operations!E10-Operations!E11)/MAX(0.000001,'Debt Sculpting'!E10),MAX(0,Operations!F5*(1-$B8)*(1-C$4)-Operations!F9-Operations!F10-Operations!F11)/MAX(0.000001,'Debt Sculpting'!F10),MAX(0,Operations!G5*(1-$B8)*(1-C$4)-Operations!G9-Operations!G10-Operations!G11)/MAX(0.000001,'Debt Sculpting'!G10),MAX(0,Operations!H5*(1-$B8)*(1-C$4)-Operations!H9-Operations!H10-Operations!H11)/MAX(0.000001,'Debt Sculpting'!H10),MAX(0,Operations!I5*(1-$B8)*(1-C$4)-Operations!I9-Operations!I10-Operations!I11)/MAX(0.000001,'Debt Sculpting'!I10),MAX(0,Operations!J5*(1-$B8)*(1-C$4)-Operations!J9-Operations!J10-Operations!J11)/MAX(0.000001,'Debt Sculpting'!J10),MAX(0,Operations!K5*(1-$B8)*(1-C$4)-Operations!K9-Operations!K10-Operations!K11)/MAX(0.000001,'Debt Sculpting'!K10),MAX(0,Operations!L5*(1-$B8)*(1-C$4)-Operations!L9-Operations!L10-Operations!L11)/MAX(0.000001,'Debt Sculpting'!L10)) -> 0.09267531 | D8: =MIN(MAX(0,Operations!C5*(1-$B8)*(1-D$4)-Operations!C9-Operations!C10-Operations!C11)/MAX(0.000001,'Debt Sculpting'!C10),MAX(0,Operations!D5*(1-$B8)*(1-D$4)-Operations!D9-Operations!D10-Operations!D11)/MAX(0.000001,'Debt Sculpting'!D10),MAX(0,Operations!E5*(1-$B8)*(1-D$4)-Operations!E9-Operations!E10-Operations!E11)/MAX(0.000001,'Debt Sculpting'!E10),MAX(0,Operations!F5*(1-$B8)*(1-D$4)-Operations!F9-Operations!F10-Operations!F11)/MAX(0.000001,'Debt Sculpting'!F10),MAX(0,Operations!G5*(1-$B8)*(1-D$4)-Operations!G9-Operations!G10-Operations!G11)/MAX(0.000001,'Debt Sculpting'!G10),MAX(0,Operations!H5*(1-$B8)*(1-D$4)-Operations!H9-Operations!H10-Operations!H11)/MAX(0.000001,'Debt Sculpting'!H10),MAX(0,Operations!I5*(1-$B8)*(1-D$4)-Operations!I9-Operations!I10-Operations!I11)/MAX(0.000001,'Debt Sculpting'!I10),MAX(0,Operations!J5*(1-$B8)*(1-D$4)-Operations!J9-Operations!J10-Operations!J11)/MAX(0.000001,'Debt Sculpting'!J10),MAX(0,Operations!K5*(1-$B8)*(1-D$4)-Operations!K9-Operations!K10-Operations!K11)/MAX(0.000001,'Debt Sculpting'!K10),MAX(0,Operations!L5*(1-$B8)*(1-D$4)-Operations!L9-Operations!L10-Operations!L11)/MAX(0.000001,'Debt Sculpting'!L10)) -> 0.084208193 | E8: =MIN(MAX(0,Operations!C5*(1-$B8)*(1-E$4)-Operations!C9-Operations!C10-Operations!C11)/MAX(0.000001,'Debt Sculpting'!C10),MAX(0,Operations!D5*(1-$B8)*(1-E$4)-Operations!D9-Operations!D10-Operations!D11)/MAX(0.000001,'Debt Sculpting'!D10),MAX(0,Operations!E5*(1-$B8)*(1-E$4)-Operations!E9-Operations!E10-Operations!E11)/MAX(0.000001,'Debt Sculpting'!E10),MAX(0,Operations!F5*(1-$B8)*(1-E$4)-Operations!F9-Operations!F10-Operations!F11)/MAX(0.000001,'Debt Sculpting'!F10),MAX(0,Operations!G5*(1-$B8)*(1-E$4)-Operations!G9-Operations!G10-Operations!G11)/MAX(0.000001,'Debt Sculpting'!G10),MAX(0,Operations!H5*(1-$B8)*(1-E$4)-Operations!H9-Operations!H10-Operations!H11)/MAX(0.000001,'Debt Sculpting'!H10),MAX(0,Operations!I5*(1-$B8)*(1-E$4)-Operations!I9-Operations!I10-Operations!I11)/MAX(0.000001,'Debt Sculpting'!I10),MAX(0,Operations!J5*(1-$B8)*(1-E$4)-Operations!J9-Operations!J10-Operations!J11)/MAX(0.000001,'Debt Sculpting'!J10),MAX(0,Operations!K5*(1-$B8)*(1-E$4)-Operations!K9-Operations!K10-Operations!K11)/MAX(0.000001,'Debt Sculpting'!K10),MAX(0,Operations!L5*(1-$B8)*(1-E$4)-Operations!L9-Operations!L10-Operations!L11)/MAX(0.000001,'Debt Sculpting'!L10)) -> 0.075741076 | F8: =MIN(MAX(0,Operations!C5*(1-$B8)*(1-F$4)-Operations!C9-Operations!C10-Operations!C11)/MAX(0.000001,'Debt Sculpting'!C10),MAX(0,Operations!D5*(1-$B8)*(1-F$4)-Operations!D9-Operations!D10-Operations!D11)/MAX(0.000001,'Debt Sculpting'!D10),MAX(0,Operations!E5*(1-$B8)*(1-F$4)-Operations!E9-Operations!E10-Operations!E11)/MAX(0.000001,'Debt Sculpting'!E10),MAX(0,Operations!F5*(1-$B8)*(1-F$4)-Operations!F9-Operations!F10-Operations!F11)/MAX(0.000001,'Debt Sculpting'!F10),MAX(0,Operations!G5*(1-$B8)*(1-F$4)-Operations!G9-Operations!G10-Operations!G11)/MAX(0.000001,'Debt Sculpting'!G10),MAX(0,Operations!H5*(1-$B8)*(1-F$4)-Operations!H9-Operations!H10-Operations!H11)/MAX(0.000001,'Debt Sculpting'!H10),MAX(0,Operations!I5*(1-$B8)*(1-F$4)-Operations!I9-Operations!I10-Operations!I11)/MAX(0.000001,'Debt Sculpting'!I10),MAX(0,Operations!J5*(1-$B8)*(1-F$4)-Operations!J9-Operations!J10-Operations!J11)/MAX(0.000001,'Debt Sculpting'!J10),MAX(0,Operations!K5*(1-$B8)*(1-F$4)-Operations!K9-Operations!K10-Operations!K11)/MAX(0.000001,'Debt Sculpting'!K10),MAX(0,Operations!L5*(1-$B8)*(1-F$4)-Operations!L9-Operations!L10-Operations!L11)/MAX(0.000001,'Debt Sculpting'!L10)) -> 0.067273959 | G8: =MIN(MAX(0,Operations!C5*(1-$B8)*(1-G$4)-Operations!C9-Operations!C10-Operations!C11)/MAX(0.000001,'Debt Sculpting'!C10),MAX(0,Operations!D5*(1-$B8)*(1-G$4)-Operations!D9-Operations!D10-Operations!D11)/MAX(0.000001,'Debt Sculpting'!D10),MAX(0,Operations!E5*(1-$B8)*(1-G$4)-Operations!E9-Operations!E10-Operations!E11)/MAX(0.000001,'Debt Sculpting'!E10),MAX(0,Operations!F5*(1-$B8)*(1-G$4)-Operations!F9-Operations!F10-Operations!F11)/MAX(0.000001,'Debt Sculpting'!F10),MAX(0,Operations!G5*(1-$B8)*(1-G$4)-Operations!G9-Operations!G10-Operations!G11)/MAX(0.000001,'Debt Sculpting'!G10),MAX(0,Operations!H5*(1-$B8)*(1-G$4)-Operations!H9-Operations!H10-Operations!H11)/MAX(0.000001,'Debt Sculpting'!H10),MAX(0,Operations!I5*(1-$B8)*(1-G$4)-Operations!I9-Operations!I10-Operations!I11)/MAX(0.000001,'Debt Sculpting'!I10),MAX(0,Operations!J5*(1-$B8)*(1-G$4)-Operations!J9-Operations!J10-Operations!J11)/MAX(0.000001,'Debt Sculpting'!J10),MAX(0,Operations!K5*(1-$B8)*(1-G$4)-Operations!K9-Operations!K10-Operations!K11)/MAX(0.000001,'Debt Sculpting'!K10),MAX(0,Operations!L5*(1-$B8)*(1-G$4)-Operations!L9-Operations!L10-Operations!L11)/MAX(0.000001,'Debt Sculpting'!L10)) -> 0.058806842
B9: 0.2 | C9: =MIN(MAX(0,Operations!C5*(1-$B9)*(1-C$4)-Operations!C9-Operations!C10-Operations!C11)/MAX(0.000001,'Debt Sculpting'!C10),MAX(0,Operations!D5*(1-$B9)*(1-C$4)-Operations!D9-Operations!D10-Operations!D11)/MAX(0.000001,'Debt Sculpting'!D10),MAX(0,Operations!E5*(1-$B9)*(1-C$4)-Operations!E9-Operations!E10-Operations!E11)/MAX(0.000001,'Debt Sculpting'!E10),MAX(0,Operations!F5*(1-$B9)*(1-C$4)-Operations!F9-Operations!F10-Operations!F11)/MAX(0.000001,'Debt Sculpting'!F10),MAX(0,Operations!G5*(1-$B9)*(1-C$4)-Operations!G9-Operations!G10-Operations!G11)/MAX(0.000001,'Debt Sculpting'!G10),MAX(0,Operations!H5*(1-$B9)*(1-C$4)-Operations!H9-Operations!H10-Operations!H11)/MAX(0.000001,'Debt Sculpting'!H10),MAX(0,Operations!I5*(1-$B9)*(1-C$4)-Operations!I9-Operations!I10-Operations!I11)/MAX(0.000001,'Debt Sculpting'!I10),MAX(0,Operations!J5*(1-$B9)*(1-C$4)-Operations!J9-Operations!J10-Operations!J11)/MAX(0.000001,'Debt Sculpting'!J10),MAX(0,Operations!K5*(1-$B9)*(1-C$4)-Operations!K9-Operations!K10-Operations!K11)/MAX(0.000001,'Debt Sculpting'!K10),MAX(0,Operations!L5*(1-$B9)*(1-C$4)-Operations!L9-Operations!L10-Operations!L11)/MAX(0.000001,'Debt Sculpting'!L10)) -> 0.086200456 | D9: =MIN(MAX(0,Operations!C5*(1-$B9)*(1-D$4)-Operations!C9-Operations!C10-Operations!C11)/MAX(0.000001,'Debt Sculpting'!C10),MAX(0,Operations!D5*(1-$B9)*(1-D$4)-Operations!D9-Operations!D10-Operations!D11)/MAX(0.000001,'Debt Sculpting'!D10),MAX(0,Operations!E5*(1-$B9)*(1-D$4)-Operations!E9-Operations!E10-Operations!E11)/MAX(0.000001,'Debt Sculpting'!E10),MAX(0,Operations!F5*(1-$B9)*(1-D$4)-Operations!F9-Operations!F10-Operations!F11)/MAX(0.000001,'Debt Sculpting'!F10),MAX(0,Operations!G5*(1-$B9)*(1-D$4)-Operations!G9-Operations!G10-Operations!G11)/MAX(0.000001,'Debt Sculpting'!G10),MAX(0,Operations!H5*(1-$B9)*(1-D$4)-Operations!H9-Operations!H10-Operations!H11)/MAX(0.000001,'Debt Sculpting'!H10),MAX(0,Operations!I5*(1-$B9)*(1-D$4)-Operations!I9-Operations!I10-Operations!I11)/MAX(0.000001,'Debt Sculpting'!I10),MAX(0,Operations!J5*(1-$B9)*(1-D$4)-Operations!J9-Operations!J10-Operations!J11)/MAX(0.000001,'Debt Sculpting'!J10),MAX(0,Operations!K5*(1-$B9)*(1-D$4)-Operations!K9-Operations!K10-Operations!K11)/MAX(0.000001,'Debt Sculpting'!K10),MAX(0,Operations!L5*(1-$B9)*(1-D$4)-Operations!L9-Operations!L10-Operations!L11)/MAX(0.000001,'Debt Sculpting'!L10)) -> 0.078231405 | E9: =MIN(MAX(0,Operations!C5*(1-$B9)*(1-E$4)-Operations!C9-Operations!C10-Operations!C11)/MAX(0.000001,'Debt Sculpting'!C10),MAX(0,Operations!D5*(1-$B9)*(1-E$4)-Operations!D9-Operations!D10-Operations!D11)/MAX(0.000001,'Debt Sculpting'!D10),MAX(0,Operations!E5*(1-$B9)*(1-E$4)-Operations!E9-Operations!E10-Operations!E11)/MAX(0.000001,'Debt Sculpting'!E10),MAX(0,Operations!F5*(1-$B9)*(1-E$4)-Operations!F9-Operations!F10-Operations!F11)/MAX(0.000001,'Debt Sculpting'!F10),MAX(0,Operations!G5*(1-$B9)*(1-E$4)-Operations!G9-Operations!G10-Operations!G11)/MAX(0.000001,'Debt Sculpting'!G10),MAX(0,Operations!H5*(1-$B9)*(1-E$4)-Operations!H9-Operations!H10-Operations!H11)/MAX(0.000001,'Debt Sculpting'!H10),MAX(0,Operations!I5*(1-$B9)*(1-E$4)-Operations!I9-Operations!I10-Operations!I11)/MAX(0.000001,'Debt Sculpting'!I10),MAX(0,Operations!J5*(1-$B9)*(1-E$4)-Operations!J9-Operations!J10-Operations!J11)/MAX(0.000001,'Debt Sculpting'!J10),MAX(0,Operations!K5*(1-$B9)*(1-E$4)-Operations!K9-Operations!K10-Operations!K11)/MAX(0.000001,'Debt Sculpting'!K10),MAX(0,Operations!L5*(1-$B9)*(1-E$4)-Operations!L9-Operations!L10-Operations!L11)/MAX(0.000001,'Debt Sculpting'!L10)) -> 0.070262353 | F9: =MIN(MAX(0,Operations!C5*(1-$B9)*(1-F$4)-Operations!C9-Operations!C10-Operations!C11)/MAX(0.000001,'Debt Sculpting'!C10),MAX(0,Operations!D5*(1-$B9)*(1-F$4)-Operations!D9-Operations!D10-Operations!D11)/MAX(0.000001,'Debt Sculpting'!D10),MAX(0,Operations!E5*(1-$B9)*(1-F$4)-Operations!E9-Operations!E10-Operations!E11)/MAX(0.000001,'Debt Sculpting'!E10),MAX(0,Operations!F5*(1-$B9)*(1-F$4)-Operations!F9-Operations!F10-Operations!F11)/MAX(0.000001,'Debt Sculpting'!F10),MAX(0,Operations!G5*(1-$B9)*(1-F$4)-Operations!G9-Operations!G10-Operations!G11)/MAX(0.000001,'Debt Sculpting'!G10),MAX(0,Operations!H5*(1-$B9)*(1-F$4)-Operations!H9-Operations!H10-Operations!H11)/MAX(0.000001,'Debt Sculpting'!H10),MAX(0,Operations!I5*(1-$B9)*(1-F$4)-Operations!I9-Operations!I10-Operations!I11)/MAX(0.000001,'Debt Sculpting'!I10),MAX(0,Operations!J5*(1-$B9)*(1-F$4)-Operations!J9-Operations!J10-Operations!J11)/MAX(0.000001,'Debt Sculpting'!J10),MAX(0,Operations!K5*(1-$B9)*(1-F$4)-Operations!K9-Operations!K10-Operations!K11)/MAX(0.000001,'Debt Sculpting'!K10),MAX(0,Operations!L5*(1-$B9)*(1-F$4)-Operations!L9-Operations!L10-Operations!L11)/MAX(0.000001,'Debt Sculpting'!L10)) -> 0.062293302 | G9: =MIN(MAX(0,Operations!C5*(1-$B9)*(1-G$4)-Operations!C9-Operations!C10-Operations!C11)/MAX(0.000001,'Debt Sculpting'!C10),MAX(0,Operations!D5*(1-$B9)*(1-G$4)-Operations!D9-Operations!D10-Operations!D11)/MAX(0.000001,'Debt Sculpting'!D10),MAX(0,Operations!E5*(1-$B9)*(1-G$4)-Operations!E9-Operations!E10-Operations!E11)/MAX(0.000001,'Debt Sculpting'!E10),MAX(0,Operations!F5*(1-$B9)*(1-G$4)-Operations!F9-Operations!F10-Operations!F11)/MAX(0.000001,'Debt Sculpting'!F10),MAX(0,Operations!G5*(1-$B9)*(1-G$4)-Operations!G9-Operations!G10-Operations!G11)/MAX(0.000001,'Debt Sculpting'!G10),MAX(0,Operations!H5*(1-$B9)*(1-G$4)-Operations!H9-Operations!H10-Operations!H11)/MAX(0.000001,'Debt Sculpting'!H10),MAX(0,Operations!I5*(1-$B9)*(1-G$4)-Operations!I9-Operations!I10-Operations!I11)/MAX(0.000001,'Debt Sculpting'!I10),MAX(0,Operations!J5*(1-$B9)*(1-G$4)-Operations!J9-Operations!J10-Operations!J11)/MAX(0.000001,'Debt Sculpting'!J10),MAX(0,Operations!K5*(1-$B9)*(1-G$4)-Operations!K9-Operations!K10-Operations!K11)/MAX(0.000001,'Debt Sculpting'!K10),MAX(0,Operations!L5*(1-$B9)*(1-G$4)-Operations!L9-Operations!L10-Operations!L11)/MAX(0.000001,'Debt Sculpting'!L10)) -> 0.054324251

Sheet Checks
B2: Model Checks
B4: Check | C4: Status
B5: Construction spend curve totals 100% | C5: =IF(ABS(Construction!M5-1)<0.000001,"PASS","FAIL") -> PASS
B6: Sources equal uses | C6: =IF(ABS('Sources & Uses'!F9)<0.000001,"PASS","FAIL") -> PASS
B7: Debt never negative | C7: =IF(MIN('Debt Sculpting'!C9:L9)>=0,"PASS","FAIL") -> PASS
B8: No DSCR covenant breach | C8: =IF(MIN(Coverage!C7:L7)>=0,"PASS","REVIEW") -> REVIEW
B9: DSRA fully funded | C9: =IF(MIN(Coverage!C11:L11)>=1,"PASS","REVIEW") -> PASS
B10: LLCR positive | C10: =IF(MIN(Coverage!C8:L8)>0,"PASS","FAIL") -> PASS
B11: Debt repaid or balloon disclosed | C11: =IF('Debt Sculpting'!L9<0.000001,"PASS","REVIEW") -> PASS
B12: Overall model status | C12: =IF(COUNTIF(C5:C11,"FAIL")=0,"PASS","FAIL") -> PASS

Sheet Sources
B2: Source Register
B4: Input / dataset | C4: Source URL or document | D4: As-of | E4: Notes / transformation
B5: EPC and construction budget | C5: [data room / contract URL] | D5: [date] | E5: Cost, timing, contingency, liquidated damages
B6: Concession / offtake agreement | C6: [public filing / contract URL] | D6: [date] | E6: Tariff, availability, escalation, termination
B7: Debt term sheet and common terms | C7: [data room URL] | D7: [date] | E7: Rates, tenor, sculpting, covenants, reserves
B8: Independent engineer report | C8: [advisor URL] | D8: [date] | E8: Construction and operating assumptions
B9: Market / resource study | C9: [consultant or public source] | D9: [date] | E9: Demand, irradiation, wind, traffic, throughput
B10: Discount and benchmark rates | C10: https://home.treasury.gov/resource-center/data-chart-center/interest-rates | D10: [date] | E10: Document currency and tenor mapping
B11: Finance-Segway benchmark fixture project-adversarial-delay | C11: repo://standards/benchmark_cases/project-adversarial-delay.json | D11: 2026-08-03 | E11: Synthetic engineering fixture; not investment evidence

Sheet RefreshLog
B2: Refresh Log
B4: Date | C4: Trigger | D4: Source snapshot | E4: What changed | F4: Reviewer / challenge | G4: Next check
B5: 2026-08-03 | C5: Synthetic benchmark generation | D5: repo://standards/benchmark_cases/project-adversarial-delay.json | E5: Generated project-adversarial-delay from canonical release template | F5: Engineering fixture only; not public underwriting or M4 evidence | G5: On builder, formula, or contract change
