Workbook

Sheet Cover
B2: [BORROWER] — Private Credit Underwriting
B4: Borrower / issuer: | C4: [Name]
B5: Facility: | C5: Unitranche / TLB / revolver / notes
B6: Last refreshed: | C6: [date]
B7: Next test / maturity: | C7: [date]
B8: Refresh cadence: | C8: Weekly
B9: Active scenario: | C9: Base
B10: Units: | C10: $ in millions unless noted
B13: Modeling conventions
B14: Blue text / yellow fill | C14: Hardcoded input or selected scenario
B15: Black text | C15: Formula / same-sheet calculation
B16: Green text | C16: Cross-sheet formula / link
B17: Checks | C17: PASS / REVIEW / FAIL must remain visible

Sheet Institutional Surface
B2: Private Credit — Institutional Decision Surface
B4: Model ID | C4: 05
B5: Domain | C5: Private Credit
B6: Declared maturity | C6: M2
B7: Canonical builder | C7: tools/builders/build_private_credit_release.py
B8: Decision arena | C8: origination, underwriting, portfolio management, workout and credit committee
B9: Committee artifact | C9: credit approval memorandum
B10: Operating cadence | C10: weekly watchlist; monthly portfolio; event-driven amendments
B12: Key decision outputs
B13: # | C13: Requirement | D13: Owner | E13: Evidence / location | F13: Status
B14: 1 | C14: cash yield, OID and all-in return | F14: OPEN
B15: 2 | C15: fixed-charge and interest coverage | F15: OPEN
B16: 3 | C16: liquidity runway and revolver use | F16: OPEN
B17: 4 | C17: base, downside and break-even outputs | F17: OPEN
B18: 5 | C18: liquidity / funding requirement and binding constraint | F18: OPEN
B20: Insider questions
B21: # | C21: Requirement | D21: Owner | E21: Evidence / location | F21: Status
B22: 1 | C22: What add-backs are capped or time-limited? | F22: OPEN
B23: 2 | C23: Where can new money prime us? | F23: OPEN
B24: 3 | C24: What is the first liquidity date, not the maturity date? | F24: OPEN
B25: 4 | C25: Which assumption is owner-approved versus modeler judgement? | F25: OPEN
B26: 5 | C26: What fails first and who must act? | F26: OPEN
B28: Scenario families
B29: # | C29: Requirement | D29: Owner | E29: Evidence / location | F29: Status
B30: 1 | C30: EBITDA miss and add-back rejection | F30: OPEN
B31: 2 | C31: liquidity draw and revolver block | F31: OPEN
B32: 3 | C32: rate shock | F32: OPEN
B33: 4 | C33: data freshness / source failure | F33: OPEN
B34: 5 | C34: combined severe-but-plausible downside | F34: OPEN
B36: Primary diligence documents
B37: # | C37: Requirement | D37: Owner | E37: Evidence / location | F37: Status
B38: 1 | C38: credit agreement and schedules | F38: OPEN
B39: 2 | C39: QoE and borrowing-base reports | F39: OPEN
B40: 3 | C40: sponsor model and lender case | F40: OPEN
B41: 4 | C41: approved model card and assumption register | F41: OPEN
B42: 5 | C42: independent validation and challenge record | F42: OPEN
B44: Challenge tests
B45: # | C45: Requirement | D45: Owner | E45: Evidence / location | F45: Status
B46: 1 | C46: debt cash schedule conserves | F46: OPEN
B47: 2 | C47: yield includes OID and fees | F47: OPEN
...

Sheet Challenge Log
B2: Independent Challenge, Override and Closure Log
B4: Date | C4: Reviewer | D4: Challenge | E4: Owner response | F4: Evidence | G4: Impact | H4: Status | I4: Closure
D5: debt cash schedule conserves | H5: OPEN
D6: yield includes OID and fees | H6: OPEN
D7: recovery cannot exceed collateral after costs | H7: OPEN
D8: source-to-model lineage is reproducible | H8: OPEN
D9: units, signs, dates and legal definitions reconcile | H9: OPEN

Sheet Lineage Map
B2: Source, Transformation, Ownership and Refresh Map
B4: Source class | C4: Cadence | D4: Control | E4: System / provider | F4: As-of | G4: Owner | H4: Transform | I4: Downstream | J4: Status
B5: borrower reporting | C5: monthly/quarterly | D5: covenant-definition normalization | J5: TO MAP
B6: agent notices | C6: event-driven | D6: principal, interest and amendment log | J6: TO MAP
B7: model governance evidence | C7: per release | D7: version, reviewer, sign-off and change log | J7: TO MAP
B8: decision-use snapshot | C8: per decision | D8: immutable as-of date and source receipt | J8: TO MAP

Sheet Assumptions
B2: Underwriting Assumptions
B4: Assumption | C4: Base | D4: Downside | E4: Active | F4: Units / note
B5: Revenue (LTM) | C5: 500 | D5: 500 | E5: =IF(Cover!$C$9="Downside",D5,C5) -> 500 | F5: $mm
B6: EBITDA margin | C6: 0.2 | D6: 0.16 | E6: =IF(Cover!$C$9="Downside",D6,C6) -> 0.2 | F6: %
B7: Revenue growth | C7: 0.04 | D7: -0.05 | E7: =IF(Cover!$C$9="Downside",D7,C7) -> 0.04 | F7: %
B8: Maintenance capex / revenue | C8: 0.03 | D8: 0.035 | E8: =IF(Cover!$C$9="Downside",D8,C8) -> 0.03 | F8: %
B9: Cash taxes / EBITDA | C9: 0.15 | D9: 0.1 | E9: =IF(Cover!$C$9="Downside",D9,C9) -> 0.15 | F9: %
B10: Change in NWC / revenue change | C10: 0.08 | D10: 0.1 | E10: =IF(Cover!$C$9="Downside",D10,C10) -> 0.08 | F10: %
B11: Opening cash | C11: 25 | D11: 20 | E11: =IF(Cover!$C$9="Downside",D11,C11) -> 25 | F11: $mm
B12: Opening gross debt | C12: 350 | D12: 350 | E12: =IF(Cover!$C$9="Downside",D12,C12) -> 350 | F12: $mm
B13: Base rate | C13: 0.045 | D13: 0.055 | E13: =IF(Cover!$C$9="Downside",D13,C13) -> 0.045 | F13: %
B14: Cash spread | C14: 0.055 | D14: 0.07 | E14: =IF(Cover!$C$9="Downside",D14,C14) -> 0.055 | F14: %
B15: OID / upfront fee | C15: 0.02 | D15: 0.02 | E15: =IF(Cover!$C$9="Downside",D15,C15) -> 0.02 | F15: %
B16: PIK spread | C16: 0 | D16: 0.02 | E16: =IF(Cover!$C$9="Downside",D16,C16) -> 0 | F16: %
... B25: Maturity | C25: 7 | D25: 7 | E25: =IF(Cover!$C$9="Downside",D25,C25) -> 7 | F25: years

Sheet Operating Case
B2: Operating Case & CFADS
B4: $mm | C4: LTM | D4: Year 1 | E4: Year 2 | F4: Year 3 | G4: Year 4 | H4: Year 5
B5: Revenue | C5: =Assumptions!E5 -> 500 | D5: =C5*(1+Assumptions!$E$7) -> 520 | E5: =D5*(1+Assumptions!$E$7) -> 540.8 | F5: =E5*(1+Assumptions!$E$7) -> 562.432 | G5: =F5*(1+Assumptions!$E$7) -> 584.92928 | H5: =G5*(1+Assumptions!$E$7) -> 608.32645
B6: Growth | D6: =IFERROR(D5/C5-1,0) -> 0.04 | E6: =IFERROR(E5/D5-1,0) -> 0.04 | F6: =IFERROR(F5/E5-1,0) -> 0.04 | G6: =IFERROR(G5/F5-1,0) -> 0.04 | H6: =IFERROR(H5/G5-1,0) -> 0.04
B7: EBITDA | C7: =C5*Assumptions!E6 -> 100 | D7: =D5*Assumptions!$E$6 -> 104 | E7: =E5*Assumptions!$E$6 -> 108.16 | F7: =F5*Assumptions!$E$6 -> 112.4864 | G7: =G5*Assumptions!$E$6 -> 116.98586 | H7: =H5*Assumptions!$E$6 -> 121.66529
B8: EBITDA margin | C8: =IFERROR(C7/C5,0) -> 0.2 | D8: =IFERROR(D7/D5,0) -> 0.2 | E8: =IFERROR(E7/E5,0) -> 0.2 | F8: =IFERROR(F7/F5,0) -> 0.2 | G8: =IFERROR(G7/G5,0) -> 0.2 | H8: =IFERROR(H7/H5,0) -> 0.2
B9: Cash taxes | D9: =D7*Assumptions!$E$9 -> 15.6 | E9: =E7*Assumptions!$E$9 -> 16.224 | F9: =F7*Assumptions!$E$9 -> 16.87296 | G9: =G7*Assumptions!$E$9 -> 17.547878 | H9: =H7*Assumptions!$E$9 -> 18.249794
B10: Maintenance capex | D10: =D5*Assumptions!$E$8 -> 15.6 | E10: =E5*Assumptions!$E$8 -> 16.224 | F10: =F5*Assumptions!$E$8 -> 16.87296 | G10: =G5*Assumptions!$E$8 -> 17.547878 | H10: =H5*Assumptions!$E$8 -> 18.249794
B11: Change in NWC | D11: =MAX(0,(D5-C5)*Assumptions!$E$10) -> 1.6 | E11: =MAX(0,(E5-D5)*Assumptions!$E$10) -> 1.664 | F11: =MAX(0,(F5-E5)*Assumptions!$E$10) -> 1.73056 | G11: =MAX(0,(G5-F5)*Assumptions!$E$10) -> 1.7997824 | H11: =MAX(0,(H5-G5)*Assumptions!$E$10) -> 1.8717737
B12: CFADS before interest | D12: =D7-D9-D10-D11 -> 71.2 | E12: =E7-E9-E10-E11 -> 74.048 | F12: =F7-F9-F10-F11 -> 77.00992 | G12: =G7-G9-G10-G11 -> 80.090317 | H12: =H7-H9-H10-H11 -> 83.293929
B13: Cash interest | D13: ='Debt Schedule'!D13 -> 35 | E13: ='Debt Schedule'!E13 -> 32.515 | F13: ='Debt Schedule'!F13 -> 29.19585 | G13: ='Debt Schedule'!G13 -> 25.145571 | H13: ='Debt Schedule'!H13 -> 20.373195
B14: CFADS after interest | D14: =D12-D13 -> 36.2 | E14: =E12-E13 -> 41.533 | F14: =F12-F13 -> 47.81407 | G14: =G12-G13 -> 54.944745 | H14: =H12-H13 -> 62.920734

Sheet Debt Schedule
B2: Debt & Cash Schedule
B4: $mm | C4: Close | D4: Year 1 | E4: Year 2 | F4: Year 3 | G4: Year 4 | H4: Year 5
B5: Beginning cash | C5: =Assumptions!E11 -> 25 | D5: =C10 -> 25 | E5: =D10 -> 36.35 | F5: =E10 -> 44.6915 | G5: =F10 -> 52.002785 | H5: =G10 -> 59.223765
B6: CFADS after interest | D6: ='Operating Case'!D14 -> 36.2 | E6: ='Operating Case'!E14 -> 41.533 | F6: ='Operating Case'!F14 -> 47.81407 | G6: ='Operating Case'!G14 -> 54.944745 | H6: ='Operating Case'!H14 -> 62.920734
B7: Mandatory amortization | D7: =MIN(D11,Assumptions!$E$12*Assumptions!$E$17) -> 3.5 | E7: =MIN(E11,Assumptions!$E$12*Assumptions!$E$17) -> 3.5 | F7: =MIN(F11,Assumptions!$E$12*Assumptions!$E$17) -> 3.5 | G7: =MIN(G11,Assumptions!$E$12*Assumptions!$E$17) -> 3.5 | H7: =MIN(H11,Assumptions!$E$12*Assumptions!$E$17) -> 3.5
B8: Cash before sweep | D8: =D5+D6-D7 -> 57.7 | E8: =E5+E6-E7 -> 74.383 | F8: =F5+F6-F7 -> 89.00557 | G8: =G5+G6-G7 -> 103.44753 | H8: =H5+H6-H7 -> 118.6445
B9: Cash sweep | D9: =MIN(MAX(0,D11-D7),MAX(0,D8-Assumptions!$E$19)*Assumptions!$E$18) -> 21.35 | E9: =MIN(MAX(0,E11-E7),MAX(0,E8-Assumptions!$E$19)*Assumptions!$E$18) -> 29.6915 | F9: =MIN(MAX(0,F11-F7),MAX(0,F8-Assumptions!$E$19)*Assumptions!$E$18) -> 37.002785 | G9: =MIN(MAX(0,G11-G7),MAX(0,G8-Assumptions!$E$19)*Assumptions!$E$18) -> 44.223765 | H9: =MIN(MAX(0,H11-H7),MAX(0,H8-Assumptions!$E$19)*Assumptions!$E$18) -> 51.82225
B10: Ending cash | C10: =C5 -> 25 | D10: =D8-D9 -> 36.35 | E10: =E8-E9 -> 44.6915 | F10: =F8-F9 -> 52.002785 | G10: =G8-G9 -> 59.223765 | H10: =H8-H9 -> 66.82225
B11: Beginning debt | C11: =Assumptions!E12 -> 350 | D11: =C15 -> 350 | E11: =D15 -> 325.15 | F11: =E15 -> 291.9585 | G11: =F15 -> 251.45571 | H11: =G15 -> 203.73195
B12: Cash interest rate | C12: =Assumptions!E13+Assumptions!E14 -> 0.1 | D12: =Assumptions!$E$13+Assumptions!$E$14 -> 0.1 | E12: =Assumptions!$E$13+Assumptions!$E$14 -> 0.1 | F12: =Assumptions!$E$13+Assumptions!$E$14 -> 0.1 | G12: =Assumptions!$E$13+Assumptions!$E$14 -> 0.1 | H12: =Assumptions!$E$13+Assumptions!$E$14 -> 0.1
B13: Cash interest expense | D13: =D11*D12 -> 35 | E13: =E11*E12 -> 32.515 | F13: =F11*F12 -> 29.19585 | G13: =G11*G12 -> 25.145571 | H13: =H11*H12 -> 20.373195
B14: PIK accrual | D14: =MAX(0,D11-D7-D9)*Assumptions!$E$16 -> 0 | E14: =MAX(0,E11-E7-E9)*Assumptions!$E$16 -> 0 | F14: =MAX(0,F11-F7-F9)*Assumptions!$E$16 -> 0 | G14: =MAX(0,G11-G7-G9)*Assumptions!$E$16 -> 0 | H14: =MAX(0,H11-H7-H9)*Assumptions!$E$16 -> 0
B15: Ending debt | C15: =C11 -> 350 | D15: =MAX(0,D11-D7-D9+D14) -> 325.15 | E15: =MAX(0,E11-E7-E9+E14) -> 291.9585 | F15: =MAX(0,F11-F7-F9+F14) -> 251.45571 | G15: =MAX(0,G11-G7-G9+G14) -> 203.73195 | H15: =MAX(0,H11-H7-H9+H14) -> 148.4097
B16: Average debt | C16: =C11 -> 350 | D16: =AVERAGE(D11,D15) -> 337.575 | E16: =AVERAGE(E11,E15) -> 308.55425 | F16: =AVERAGE(F11,F15) -> 271.70711 | G16: =AVERAGE(G11,G15) -> 227.59383 | H16: =AVERAGE(H11,H15) -> 176.07082
B17: PIK interest expense | D17: =D11*Assumptions!$E$16 -> 0 | E17: =E11*Assumptions!$E$16 -> 0 | F17: =F11*Assumptions!$E$16 -> 0 | G17: =G11*Assumptions!$E$16 -> 0 | H17: =H11*Assumptions!$E$16 -> 0
B18: Total interest expense | D18: =D13+D17 -> 35 | E18: =E13+E17 -> 32.515 | F18: =F13+F17 -> 29.19585 | G18: =G13+G17 -> 25.145571 | H18: =H13+H17 -> 20.373195

Sheet Covenants
B2: Covenant Compliance
B4: Metric | C4: Year 1 | D4: Year 2 | E4: Year 3 | F4: Year 4 | G4: Year 5
B5: Gross leverage | C5: =IFERROR('Debt Schedule'!D15/'Operating Case'!D7,0) -> 3.1264423 | D5: =IFERROR('Debt Schedule'!E15/'Operating Case'!E7,0) -> 2.6993205 | E5: =IFERROR('Debt Schedule'!F15/'Operating Case'!F7,0) -> 2.2354322 | F5: =IFERROR('Debt Schedule'!G15/'Operating Case'!G7,0) -> 1.7415092 | G5: =IFERROR('Debt Schedule'!H15/'Operating Case'!H7,0) -> 1.2198196
B6: Maximum leverage | C6: =Assumptions!$E$20 -> 6 | D6: =Assumptions!$E$20 -> 6 | E6: =Assumptions!$E$20 -> 6 | F6: =Assumptions!$E$20 -> 6 | G6: =Assumptions!$E$20 -> 6
B7: Leverage headroom | C7: =C6-C5 -> 2.8735577 | D7: =D6-D5 -> 3.3006795 | E7: =E6-E5 -> 3.7645678 | F7: =F6-F5 -> 4.2584908 | G7: =G6-G5 -> 4.7801804
B8: Interest coverage | C8: =IFERROR('Operating Case'!D7/'Debt Schedule'!D18,0) -> 2.9714286 | D8: =IFERROR('Operating Case'!E7/'Debt Schedule'!E18,0) -> 3.3264647 | E8: =IFERROR('Operating Case'!F7/'Debt Schedule'!F18,0) -> 3.8528215 | F8: =IFERROR('Operating Case'!G7/'Debt Schedule'!G18,0) -> 4.6523443 | G8: =IFERROR('Operating Case'!H7/'Debt Schedule'!H18,0) -> 5.9718316
B9: Minimum coverage | C9: =Assumptions!$E$21 -> 1.75 | D9: =Assumptions!$E$21 -> 1.75 | E9: =Assumptions!$E$21 -> 1.75 | F9: =Assumptions!$E$21 -> 1.75 | G9: =Assumptions!$E$21 -> 1.75
B10: Coverage headroom | C10: =C8-C9 -> 1.2214286 | D10: =D8-D9 -> 1.5764647 | E10: =E8-E9 -> 2.1028215 | F10: =F8-F9 -> 2.9023443 | G10: =G8-G9 -> 4.2218316
B11: DSCR | C11: =IFERROR('Operating Case'!D12/('Debt Schedule'!D7+'Debt Schedule'!D13),0) -> 1.8493506 | D11: =IFERROR('Operating Case'!E12/('Debt Schedule'!E7+'Debt Schedule'!E13),0) -> 2.0560322 | E11: =IFERROR('Operating Case'!F12/('Debt Schedule'!F7+'Debt Schedule'!F13),0) -> 2.3553423 | F11: =IFERROR('Operating Case'!G12/('Debt Schedule'!G7+'Debt Schedule'!G13),0) -> 2.7959057 | G11: =IFERROR('Operating Case'!H12/('Debt Schedule'!H7+'Debt Schedule'!H13),0) -> 3.4890148
B12: Minimum DSCR | C12: =Assumptions!$E$22 -> 1 | D12: =Assumptions!$E$22 -> 1 | E12: =Assumptions!$E$22 -> 1 | F12: =Assumptions!$E$22 -> 1 | G12: =Assumptions!$E$22 -> 1
B13: DSCR headroom | C13: =C11-C12 -> 0.84935065 | D13: =D11-D12 -> 1.0560322 | E13: =E11-E12 -> 1.3553423 | F13: =F11-F12 -> 1.7959057 | G13: =G11-G12 -> 2.4890148
B14: Status | C14: =IF(AND(C7>=0,C10>=0,C13>=0),"PASS","BREACH") -> PASS | D14: =IF(AND(D7>=0,D10>=0,D13>=0),"PASS","BREACH") -> PASS | E14: =IF(AND(E7>=0,E10>=0,E13>=0),"PASS","BREACH") -> PASS | F14: =IF(AND(F7>=0,F10>=0,F13>=0),"PASS","BREACH") -> PASS | G14: =IF(AND(G7>=0,G10>=0,G13>=0),"PASS","BREACH") -> PASS

Sheet Yield & Spread
B2: Lender Yield & Spread
B4: Metric | C4: Value | D4: Units | E4: Method
B5: Cash coupon | C5: =Assumptions!E13+Assumptions!E14 -> 0.1 | D5: % | E5: Base rate + spread
B6: PIK rate | C6: =Assumptions!E16 -> 0 | D6: % | E6: PIK spread
B7: Issue price | C7: =100*(1-Assumptions!E15) -> 98 | D7: per 100 | E7: 100 less OID
B8: Maturity | C8: =Assumptions!E25 -> 7 | D8: years | E8: Contractual
B9: Approx. cash YTM | C9: =IFERROR((C5*100+(100-C7)/C8)/((100+C7)/2),0) -> 0.1038961 | D9: % | E9: Bond approximation
B10: Approx. all-in yield | C10: =C9+C6 -> 0.1038961 | D10: % | E10: Cash YTM + PIK
B11: Cash spread | C11: =Assumptions!E14*10000 -> 550 | D11: bps | E11: Spread × 10,000
B12: OID accretion / year | C12: =IFERROR(Assumptions!E15/Assumptions!E25*10000,0) -> 28.571429 | D12: bps | E12: OID ÷ maturity

Sheet Recovery
B2: Recovery & Loss Analysis
B4: Bridge | C4: Base | D4: Downside
B5: Stressed EBITDA | C5: ='Operating Case'!H7 -> 121.66529 | D5: ='Operating Case'!H7*(1+Assumptions!D7) -> 115.58203
B6: Recovery multiple | C6: =Assumptions!C23 -> 5 | D6: =Assumptions!D23 -> 4
B7: Gross enterprise value | C7: =C5*C6 -> 608.32645 | D7: =D5*D6 -> 462.3281
B8: EV haircut | C8: =C7*Assumptions!C24 -> 121.66529 | D8: =D7*Assumptions!D24 -> 161.81484
B9: Net distributable value | C9: =C7-C8 -> 486.66116 | D9: =D7-D8 -> 300.51327
B10: Debt claim | C10: ='Debt Schedule'!H15 -> 148.4097 | D10: ='Debt Schedule'!H15 -> 148.4097
B11: Recovery value | C11: =MIN(C9,C10) -> 148.4097 | D11: =MIN(D9,D10) -> 148.4097
B12: Recovery rate | C12: =IFERROR(C11/C10,0) -> 1 | D12: =IFERROR(D11/D10,0) -> 1
B13: LGD | C13: =1-C12 -> 0 | D13: =1-D12 -> 0

Sheet Sensitivity
B2: Recovery Sensitivity
B4: EBITDA haircut / multiple | C4: 3 | D4: 4 | E4: 5 | F4: 6 | G4: 7
B5: 0 | C5: =IFERROR(MIN(1,MAX(0,('Operating Case'!$H$7*(1-$B5)*C$4)/'Debt Schedule'!$H$15)),1) -> 1 | D5: =IFERROR(MIN(1,MAX(0,('Operating Case'!$H$7*(1-$B5)*D$4)/'Debt Schedule'!$H$15)),1) -> 1 | E5: =IFERROR(MIN(1,MAX(0,('Operating Case'!$H$7*(1-$B5)*E$4)/'Debt Schedule'!$H$15)),1) -> 1 | F5: =IFERROR(MIN(1,MAX(0,('Operating Case'!$H$7*(1-$B5)*F$4)/'Debt Schedule'!$H$15)),1) -> 1 | G5: =IFERROR(MIN(1,MAX(0,('Operating Case'!$H$7*(1-$B5)*G$4)/'Debt Schedule'!$H$15)),1) -> 1
B6: 0.1 | C6: =IFERROR(MIN(1,MAX(0,('Operating Case'!$H$7*(1-$B6)*C$4)/'Debt Schedule'!$H$15)),1) -> 1 | D6: =IFERROR(MIN(1,MAX(0,('Operating Case'!$H$7*(1-$B6)*D$4)/'Debt Schedule'!$H$15)),1) -> 1 | E6: =IFERROR(MIN(1,MAX(0,('Operating Case'!$H$7*(1-$B6)*E$4)/'Debt Schedule'!$H$15)),1) -> 1 | F6: =IFERROR(MIN(1,MAX(0,('Operating Case'!$H$7*(1-$B6)*F$4)/'Debt Schedule'!$H$15)),1) -> 1 | G6: =IFERROR(MIN(1,MAX(0,('Operating Case'!$H$7*(1-$B6)*G$4)/'Debt Schedule'!$H$15)),1) -> 1
B7: 0.2 | C7: =IFERROR(MIN(1,MAX(0,('Operating Case'!$H$7*(1-$B7)*C$4)/'Debt Schedule'!$H$15)),1) -> 1 | D7: =IFERROR(MIN(1,MAX(0,('Operating Case'!$H$7*(1-$B7)*D$4)/'Debt Schedule'!$H$15)),1) -> 1 | E7: =IFERROR(MIN(1,MAX(0,('Operating Case'!$H$7*(1-$B7)*E$4)/'Debt Schedule'!$H$15)),1) -> 1 | F7: =IFERROR(MIN(1,MAX(0,('Operating Case'!$H$7*(1-$B7)*F$4)/'Debt Schedule'!$H$15)),1) -> 1 | G7: =IFERROR(MIN(1,MAX(0,('Operating Case'!$H$7*(1-$B7)*G$4)/'Debt Schedule'!$H$15)),1) -> 1
B8: 0.3 | C8: =IFERROR(MIN(1,MAX(0,('Operating Case'!$H$7*(1-$B8)*C$4)/'Debt Schedule'!$H$15)),1) -> 1 | D8: =IFERROR(MIN(1,MAX(0,('Operating Case'!$H$7*(1-$B8)*D$4)/'Debt Schedule'!$H$15)),1) -> 1 | E8: =IFERROR(MIN(1,MAX(0,('Operating Case'!$H$7*(1-$B8)*E$4)/'Debt Schedule'!$H$15)),1) -> 1 | F8: =IFERROR(MIN(1,MAX(0,('Operating Case'!$H$7*(1-$B8)*F$4)/'Debt Schedule'!$H$15)),1) -> 1 | G8: =IFERROR(MIN(1,MAX(0,('Operating Case'!$H$7*(1-$B8)*G$4)/'Debt Schedule'!$H$15)),1) -> 1
B9: 0.4 | C9: =IFERROR(MIN(1,MAX(0,('Operating Case'!$H$7*(1-$B9)*C$4)/'Debt Schedule'!$H$15)),1) -> 1 | D9: =IFERROR(MIN(1,MAX(0,('Operating Case'!$H$7*(1-$B9)*D$4)/'Debt Schedule'!$H$15)),1) -> 1 | E9: =IFERROR(MIN(1,MAX(0,('Operating Case'!$H$7*(1-$B9)*E$4)/'Debt Schedule'!$H$15)),1) -> 1 | F9: =IFERROR(MIN(1,MAX(0,('Operating Case'!$H$7*(1-$B9)*F$4)/'Debt Schedule'!$H$15)),1) -> 1 | G9: =IFERROR(MIN(1,MAX(0,('Operating Case'!$H$7*(1-$B9)*G$4)/'Debt Schedule'!$H$15)),1) -> 1

Sheet Checks
B2: Model Checks
B4: Check | C4: Status
B5: Debt nonnegative | C5: =IF(MIN('Debt Schedule'!D15:H15)>=0,"PASS","FAIL") -> PASS
B6: Cash above minimum | C6: =IF(MIN('Debt Schedule'!D10:H10)>=Assumptions!E19,"PASS","REVIEW") -> PASS
B7: Recovery bounded | C7: =IF(AND(MIN(Recovery!C12:D12)>=0,MAX(Recovery!C12:D12)<=1),"PASS","FAIL") -> PASS
B8: No covenant breach | C8: =IF(COUNTIF(Covenants!C14:G14,"BREACH")=0,"PASS","REVIEW") -> PASS
B9: Overall | C9: =IF(COUNTIF(C5:C8,"FAIL")+COUNTIF(C5:C8,"REVIEW")=0,"PASS","REVIEW") -> PASS

Sheet Sources
B2: Source Register
B4: Input / dataset | C4: Source URL or document | D4: As-of | E4: Notes / transformation
B5: Financial statements | C5: SEC filing, audited report, or data room | D5: [period] | E5: Reconcile EBITDA, cash, debt and CFADS
B6: Base rate / benchmark | C6: Treasury, central bank, or contract reference | D6: [date] | E6: Freeze curve and floor assumptions
B7: Credit agreement / indenture | C7: Public filing or reviewed transaction document | D7: [date] | E7: Covenants, baskets, amortization and collateral
B8: Recovery methodology | C8: Documented valuation and waterfall assumptions | D8: [date] | E8: Bridge EV to claim-level recovery

Sheet RefreshLog
B2: Refresh Log
B4: Date | C4: Trigger | D4: Source snapshot | E4: What changed | F4: Reviewer / challenge | G4: Next check

Sheet Portfolio & Concentration
B2: Portfolio Exposure, Concentration, and Weighted Credit Metrics
B4: Borrower / segment | C4: Base exposure | D4: Downside exposure | E4: Base leverage | F4: Downside leverage
B5: Borrower A | C5: 35 | D5: 45 | E5: 4 | F5: 7
B6: Borrower B | C6: 25 | D6: 30 | E6: 4.5 | F6: 6.5
B7: Borrower C | C7: 20 | D7: 15 | E7: 3.5 | F7: 5
B8: Borrower D | C8: 12 | D8: 7 | E8: 3 | F8: 4
B9: Borrower E | C9: 8 | D9: 3 | E9: 2.5 | F9: 3.5
B12: Total exposure | C12: =SUM(C5:C9) -> 100 | D12: =SUM(D5:D9) -> 100
B13: Top-1 concentration | C13: =IFERROR(MAX(C5:C9)/C12,0) -> 0.35 | D13: =IFERROR(MAX(D5:D9)/D12,0) -> 0.45
B14: Weighted leverage | C14: =IFERROR(SUMPRODUCT(C5:C9,E5:E9)/C12,0) -> 3.785 | D14: =IFERROR(SUMPRODUCT(D5:D9,F5:F9)/D12,0) -> 6.235
B15: Maximum concentration | C15: 0.4 | D15: 0.4

Sheet Amendment Economics
B2: Debt Rollforward, PIK, DSCR, Leverage, and Recovery
B4: Metric | C4: Base | D4: Adversarial | E4: Units / control
B5: Opening debt | C5: 350 | D5: 350
B6: Mandatory amortization | C6: 10 | D6: 0
B7: Cash sweep | C7: 40 | D7: 0
B8: PIK interest | C8: 0 | D8: 30
B9: CFADS | C9: 80 | D9: 20
B10: Cash interest | C10: 25 | D10: 40
B11: EBITDA | C11: 100 | D11: 50
B12: Recovery enterprise value | C12: 500 | D12: 180
B13: Senior claims | C13: 50 | D13: 50
B14: Lender claim | C14: 300 | D14: 380
B15: Minimum DSCR | C15: 1 | D15: 1
B16: Maximum leverage | C16: 6 | D16: 6
... B19: Extension years | C19: 0 | D19: 2
B23: Ending debt | C23: =MAX(0,C5-C6-C7+C8) -> 300 | D23: =MAX(0,D5-D6-D7+D8) -> 380
B24: Debt service | C24: =C6+C10 -> 35 | D24: =D6+D10 -> 40
B25: DSCR | C25: =IFERROR(C9/C24,0) -> 2.2857143 | D25: =IFERROR(D9/D24,0) -> 0.5
B26: Leverage | C26: =IFERROR(C23/C11,0) -> 3 | D26: =IFERROR(D23/D11,0) -> 7.6
B27: Recovery value | C27: =MIN(C14,MAX(0,C12-C13)) -> 300 | D27: =MIN(D14,MAX(0,D12-D13)) -> 130
B28: Recovery rate | C28: =IFERROR(C27/C14,1) -> 1 | D28: =IFERROR(D27/D14,1) -> 0.34210526
B29: LGD | C29: =1-C28 -> 0 | D29: =1-D28 -> 0.65789474
B30: Amendment fee dollars | C30: =C5*C18 -> 3.5 | D30: =D5*D18 -> 10.5

Sheet Decision & Checks
B2: Private Credit Decision Dashboard and Independent Checks
B4: Check / decision | C4: Metric | D4: Status | E4: Interpretation / action
B5: Debt rollforward residual | C5: ='Amendment Economics'!D23-MAX(0,'Amendment Economics'!D5-'Amendment Economics'!D6-'Amendment Economics'!D7+'Amendment Economics'!D8) -> 0 | D5: =IF(ABS(C5)<0.01,"PASS","FAIL") -> PASS | E5: Ending debt must reconcile to amortization, sweep, and PIK.
B6: Recovery / LGD identity | C6: ='Amendment Economics'!D28+'Amendment Economics'!D29-1 -> 0 | D6: =IF(ABS(C6)<0.000001,"PASS","FAIL") -> PASS | E6: Recovery rate plus LGD must equal one.
B7: Downside DSCR | C7: ='Amendment Economics'!D25 -> 0.5 | D7: =IF(C7>='Amendment Economics'!D15,"PASS","BREACH") -> BREACH | E7: CFADS must cover cash interest and mandatory amortization.
B8: Downside leverage | C8: ='Amendment Economics'!D26 -> 7.6 | D8: =IF(C8<='Amendment Economics'!D16,"PASS","BREACH") -> BREACH | E8: Debt must remain within approved leverage.
B9: Downside recovery | C9: ='Amendment Economics'!D28 -> 0.34210526 | D9: =IF(C9>='Amendment Economics'!D17,"PASS","BREACH") -> BREACH | E9: Escalate impairment and amendment strategy.
B10: Debt compounding | C10: ='Amendment Economics'!D8-'Amendment Economics'!D6-'Amendment Economics'!D7 -> 30 | D10: =IF(C10<=0,"PASS","BREACH") -> BREACH | E10: PIK cannot exceed deleveraging without explicit escalation.
B11: Portfolio concentration | C11: ='Portfolio & Concentration'!D13 -> 0.45 | D11: =IF(C11<='Portfolio & Concentration'!D15,"PASS","BREACH") -> BREACH | E11: Single-name concentration must remain below the approved limit.
B13: Overall model status | C13: =IF(COUNTIF(D5:D11,"FAIL")+COUNTIF(D5:D11,"BREACH")>0,"BREACH",IF(COUNTIF(D5:D11,"REVIEW")>0,"REVIEW","PASS")) -> BREACH
