Workbook
Name FS_MODEL_ID: 'Institutional Surface'!$C$4
Name FS_DOMAIN: 'Institutional Surface'!$C$5
Name FS_MATURITY: 'Institutional Surface'!$C$6

Sheet Cover
B2: [COMPANY] — Fintech / Payments Model
B4: Business model: | C4: Payments / lending / neobank / infra
B5: Last refreshed: | C5: [date]
B6: Refresh cadence: | C6: Weekly

Sheet Institutional Surface
B2: Fintech & Payments — Institutional Decision Surface
B4: Model ID | C4: 23
B5: Domain | C5: Fintech & Payments
B6: Declared maturity | C6: M2
B7: Canonical builder | C7: tools/builders/build_fintech_release.py
B8: Decision arena | C8: product, finance, risk, treasury, operations and regulator
B9: Committee artifact | C9: unit economics, loss and settlement-risk pack
B10: Operating cadence | C10: daily operations and treasury; weekly risk; monthly product finance
B12: Key decision outputs
B13: # | C13: Requirement | D13: Owner | E13: Evidence / location | F13: Status
B14: 1 | C14: TPV / volume and take rate | F14: OPEN
B15: 2 | C15: contribution margin and cohort economics | F15: OPEN
B16: 3 | C16: fraud and credit losses | F16: OPEN
B17: 4 | C17: base, downside and break-even outputs | F17: OPEN
B18: 5 | C18: liquidity / funding requirement and binding constraint | F18: OPEN
B20: Insider questions
B21: # | C21: Requirement | D21: Owner | E21: Evidence / location | F21: Status
B22: 1 | C22: Where does settlement risk sit overnight? | F22: OPEN
B23: 2 | C23: Which partner can reprice or terminate? | F23: OPEN
B24: 3 | C24: What losses are fraud versus credit? | F24: OPEN
B25: 4 | C25: Which assumption is owner-approved versus modeler judgement? | F25: OPEN
B26: 5 | C26: What fails first and who must act? | F26: OPEN
B28: Scenario families
B29: # | C29: Requirement | D29: Owner | E29: Evidence / location | F29: Status
B30: 1 | C30: volume and take-rate compression | F30: OPEN
B31: 2 | C31: fraud / chargeback spike | F31: OPEN
B32: 3 | C32: partner-bank failure | F32: OPEN
B33: 4 | C33: data freshness / source failure | F33: OPEN
B34: 5 | C34: combined severe-but-plausible downside | F34: OPEN
B36: Primary diligence documents
B37: # | C37: Requirement | D37: Owner | E37: Evidence / location | F37: Status
B38: 1 | C38: processor / network agreements | F38: OPEN
B39: 2 | C39: bank partnership and program agreements | F39: OPEN
B40: 3 | C40: settlement reports | F40: OPEN
B41: 4 | C41: approved model card and assumption register | F41: OPEN
B42: 5 | C42: independent validation and challenge record | F42: OPEN
B44: Challenge tests
B45: # | C45: Requirement | D45: Owner | E45: Evidence / location | F45: Status
B46: 1 | C46: TPV reconciles to transactions | F46: OPEN
B47: 2 | C47: gross-to-net revenue bridge | F47: OPEN
...

Sheet Challenge Log
B2: Independent Challenge, Override and Closure Log
B4: Date | C4: Reviewer | D4: Challenge | E4: Owner response | F4: Evidence | G4: Impact | H4: Status | I4: Closure
D5: TPV reconciles to transactions | H5: OPEN
D6: gross-to-net revenue bridge | H6: OPEN
D7: loss vintage and cohort denominators consistent | H7: OPEN
D8: source-to-model lineage is reproducible | H8: OPEN
D9: units, signs, dates and legal definitions reconcile | H9: OPEN

Sheet Lineage Map
B2: Source, Transformation, Ownership and Refresh Map
B4: Source class | C4: Cadence | D4: Control | E4: System / provider | F4: As-of | G4: Owner | H4: Transform | I4: Downstream | J4: Status
B5: transactions | C5: intraday/daily | D5: processor-to-ledger reconciliation | J5: TO MAP
B6: settlement | C6: daily | D6: network, bank and cash tie | J6: TO MAP
B7: model governance evidence | C7: per release | D7: version, reviewer, sign-off and change log | J7: TO MAP
B8: decision-use snapshot | C8: per decision | D8: immutable as-of date and source receipt | J8: TO MAP

Sheet Unit Economics
B2: Unit Economics
B5: Total payment volume, TPV ($/mo) | C5: 0
B6: Take rate (%) | C6: 0.025
B7: Interchange/processing cost (% of TPV) | C7: 0.015
B8: CAC ($ per customer) | C8: 0
B9: Avg monthly revenue per customer ($) | C9: 0
B10: Monthly gross margin per customer (%) | C10: 0.6
B11: Monthly churn rate (%) | C11: 0.03
B13: Outputs
B14: Revenue (take rate x TPV) | C14: =C5*C6
B15: Processing cost ($) | C15: =C5*C7
B16: Net revenue after processing cost | C16: =C14-C15
B17: Customer lifetime (months) = 1/churn | C17: =IFERROR(1/C11,"-")
B18: LTV = monthly rev x gross margin x lifetime | C18: =C9*C10*C17
B19: LTV / CAC ratio | C19: =IFERROR(C18/C8,"-") | D19: Rule of thumb: >3x is healthy, <1x means losing money per customer
B20: CAC payback period (months) | C20: =IFERROR(C8/(C9*C10),"-")

Sheet Cohort Retention
B2: Cohort Retention (% of cohort still active)
B4: Cohort | C4: M0 | D4: M1 | E4: M2 | F4: M3 | G4: M4 | H4: M5 | I4: M6 | J4: M7
B5: Jan cohort | C5: 1 | D5: 0 | E5: 0 | F5: 0 | G5: 0 | H5: 0 | I5: 0 | J5: 0
B6: Feb cohort | C6: 1 | D6: 0 | E6: 0 | F6: 0 | G6: 0 | H6: 0 | I6: 0 | J6: 0
B7: Mar cohort | C7: 1 | D7: 0 | E7: 0 | F7: 0 | G7: 0 | H7: 0 | I7: 0 | J7: 0
B8: Apr cohort | C8: 1 | D8: 0 | E8: 0 | F8: 0 | G8: 0 | H8: 0 | I8: 0 | J8: 0
B9: Average retention | C9: =AVERAGE(C5:C8) | D9: =AVERAGE(D5:D8) | E9: =AVERAGE(E5:E8) | F9: =AVERAGE(F5:F8) | G9: =AVERAGE(G5:G8) | H9: =AVERAGE(H5:H8) | I9: =AVERAGE(I5:I8) | J9: =AVERAGE(J5:J8)
B10: Curve-implied LTV multiplier (sum of avg retention, M0-M7) | C10: =SUM(C9:J9)
B11: M0 always = 100% by definition. Fill subsequent months as cohorts age.
B12: Retention-curve LTV = monthly rev x gross margin x this multiplier — compare to the steady-state 1/churn LTV on Unit Economics; a big gap means churn isn't actually constant month to month (usually front-loaded), and the curve number is the more honest one.

Sheet Network & Cohorts
B2: Customer, Merchant, and Network Activity Rollforward
B3: Active scenario | C3: Base
B4: Metric | C4: Base | D4: Downside | E4: Active | F4: Interpretation
B5: Starting active users | C5: 100000 | D5: 100000 | E5: =IF($C$3="Downside",D5,C5) | F5: beginning-of-period active customers
B6: Retention rate | C6: 0.9 | D6: 0.55 | E6: =IF($C$3="Downside",D6,C6) | F6: same-period active retention
B7: New users | C7: 20000 | D7: 5000 | E7: =IF($C$3="Downside",D7,C7) | F7: newly activated customers
B8: Starting active merchants | C8: 5000 | D8: 5000 | E8: =IF($C$3="Downside",D8,C8) | F8: beginning merchant base
B9: Merchant retention rate | C9: 0.94 | D9: 0.7 | E9: =IF($C$3="Downside",D9,C9) | F9: merchant-side retention
B10: New merchants | C10: 750 | D10: 100 | E10: =IF($C$3="Downside",D10,C10) | F10: newly activated merchants
B11: Transactions | C11: 1500000 | D11: 300000 | E11: =IF($C$3="Downside",D11,C11) | F11: successful transactions in period
B12: Failed / reversed transactions | C12: 15000 | D12: 45000 | E12: =IF($C$3="Downside",D12,C12) | F12: operational and risk failures
B15: Derived outputs
B16: Ending active users | E16: =E5*E6+E7
B17: Ending active merchants | E17: =E8*E9+E10
B18: Transactions per active user | E18: =IFERROR(E11/E16,0)
B19: Transactions per active merchant | E19: =IFERROR(E11/E17,0)
B20: Transaction failure rate | E20: =IFERROR(E12/(E11+E12),0)
B21: Cross-side network density | E21: =IFERROR(E11/(E16*E17),0)

Sheet Fraud & Risk
B2: Fraud, Chargeback & Credit Loss
B4: Inputs
B5: Total payment volume, TPV ($/mo) | C5: 0
B6: Fraud loss rate (bps of TPV) | C6: 8
B7: Chargeback count (this period) | C7: 0
B8: Chargeback cost per incident ($, fee + lost goods) | C8: 25
B9: Credit losses — lending book only, if applicable ($) | C9: 0
B10: Fraud warning threshold (bps of TPV) | C10: 50
B11: Outputs
B12: Fraud loss ($) | C12: =C5*C6/10000 | D12: bps convention: 8 bps = 0.08%
B13: Chargeback cost ($) | C13: =C7*C8
B14: Total risk-related loss ($) | C14: =C12+C13+C9
B15: Total loss as % of net revenue | C15: =IFERROR(C14/'Unit Economics'!C16,"-") | D15: Threshold is model-owned and must be approved for the product, channel, geography, and control environment.
B16: Fraud threshold status | C16: =IF(C6<=C10,"PASS","BREACH")

Sheet Capital & Liquidity
B2: Capital, Settlement, and Liquidity Coverage
B4: Metric | C4: Base | D4: Downside | E4: Units / control
B5: Available regulatory / loss-absorbing capital | C5: 20 | D5: 5 | E5: approved eligible capital
B6: Required capital | C6: 10 | D6: 20 | E6: regulatory or internal risk requirement
B7: Unrestricted cash and liquid investments | C7: 25 | D7: 8 | E7: same-day or near-cash liquidity
B8: Thirty-day settlement and operating obligations | C8: 15 | D8: 25 | E8: cash outflows under stress
B9: Restricted customer / safeguarding funds | C9: 30 | D9: 30 | E9: not available for corporate liquidity
B10: Minimum capital coverage | C10: 1.2 | D10: 1.2 | E10: available / required
B11: Minimum liquidity coverage | C11: 1.1 | D11: 1.1 | E11: unrestricted liquidity / obligations
B14: Capital coverage | C14: =IFERROR(C5/C6,0) | D14: =IFERROR(D5/D6,0)
B15: Liquidity coverage | C15: =IFERROR(C7/C8,0) | D15: =IFERROR(D7/D8,0)
B16: Capital headroom | C16: =C5-C6 | D16: =D5-D6
B17: Liquidity headroom | C17: =C7-C8 | D17: =D7-D8
B18: Base status | C18: =IF(AND(C14>=C10,C15>=C11),"PASS","BREACH")
B19: Downside status | C19: =IF(AND(D14>=D10,D15>=D11),"PASS","BREACH")

Sheet Operational Controls
B2: Payments Endpoint Security and Fraud-Control Register
B4: Control | C4: Owner | D4: Type | E4: Metric | F4: Threshold | G4: Retained evidence
B5: Strong authentication and privileged access | C5: Security | D5: Prevent | E5: Privileged-access exceptions | F5: 0 unresolved | G5: access review and exception log
B6: Payment instruction integrity | C6: Payments Ops | D6: Prevent | E6: Unauthorized instruction rate | F6: approved threshold | G6: signed instruction and change history
B7: Real-time fraud detection | C7: Risk | D7: Detect | E7: Fraud bps / TPV | F7: Fraud & Risk!C10 | G7: alert, decision, and loss record
B8: Settlement reconciliation | C8: Finance Ops | D8: Detect | E8: Unreconciled settlement items | F8: 0 material | G8: daily reconciliation evidence
B9: Incident response and customer protection | C9: Operations | D9: Respond | E9: Time to contain | F9: approved SLA | G9: incident timeline and remediation
B10: Recovery and continuity | C10: Engineering | D10: Recover | E10: Recovery test result | F10: PASS | G10: dated recovery exercise
B11: Third-party endpoint governance | C11: Vendor Risk | D11: Govern | E11: Critical vendors overdue | F11: 0 | G11: assessment and remediation record
B14: Controls are an operating register, not a claim of compliance. Owners must replace illustrative thresholds with approved product-specific limits.

Sheet Decision & Checks
B2: Fintech / Payments Decision Dashboard and Independent Checks
B4: Check / decision | C4: Metric | D4: Status | E4: Interpretation / action
B5: Revenue identity residual | C5: ='Unit Economics'!C14-'Unit Economics'!C5*'Unit Economics'!C6 | D5: =IF(ABS(C5)<0.01,"PASS","FAIL") | E5: Revenue must equal TPV multiplied by take rate.
B6: Processing-cost residual | C6: ='Unit Economics'!C15-'Unit Economics'!C5*'Unit Economics'!C7 | D6: =IF(ABS(C6)<0.01,"PASS","FAIL") | E6: Network and processing costs must reconcile to volume and rate.
B7: Fraud-loss residual | C7: ='Fraud & Risk'!C12-'Fraud & Risk'!C5*'Fraud & Risk'!C6/10000 | D7: =IF(ABS(C7)<0.01,"PASS","FAIL") | E7: Fraud loss must reconcile from TPV and the bps convention.
B8: LTV / CAC | C8: ='Unit Economics'!C19 | D8: =IF(ISNUMBER(C8),IF(C8>=3,"PASS",IF(C8>=1,"REVIEW","BREACH")),"REVIEW") | E8: Low unit economics require pricing, retention, channel, or cost remediation.
B9: Contribution after risk losses | C9: ='Unit Economics'!C16-'Fraud & Risk'!C14 | D9: =IF(C9>=0,"PASS","BREACH") | E9: Volume growth is not valuable when processing, fraud, chargeback, and credit losses consume net revenue.
B10: Maximum retention increase | C10: =MAX('Cohort Retention'!D9-'Cohort Retention'!C9,'Cohort Retention'!E9-'Cohort Retention'!D9,'Cohort Retention'!F9-'Cohort Retention'!E9,'Cohort Retention'!G9-'Cohort Retention'!F9,'Cohort Retention'!H9-'Cohort Retention'!G9,'Cohort Retention'!I9-'Cohort Retention'!H9,'Cohort Retention'!J9-'Cohort Retention'!I9) | D10: =IF(C10<=0.000001,"PASS","REVIEW") | E10: Retention should not improve with age without an explicit reactivation or cohort-definition explanation.
B11: Fraud threshold | C11: ='Fraud & Risk'!C6 | D11: =IF(C11<='Fraud & Risk'!C10,"PASS","BREACH") | E11: Escalate fraud losses above the approved product threshold.
B12: Downside capital coverage | C12: ='Capital & Liquidity'!D14 | D12: =IF(C12>='Capital & Liquidity'!D10,"PASS","BREACH") | E12: Capital must remain above the approved requirement in downside conditions.
B13: Downside liquidity coverage | C13: ='Capital & Liquidity'!D15 | D13: =IF(C13>='Capital & Liquidity'!D11,"PASS","BREACH") | E13: Restricted customer funds may not be counted as corporate liquidity.
B14: Transaction failure rate | C14: ='Network & Cohorts'!E20 | D14: =IF(C14<=0.02,"PASS",IF(C14<=0.05,"REVIEW","BREACH")) | E14: Operational failure degrades retention, unit economics, and network trust.
B16: Overall model status | C16: =IF(COUNTIF(D5:D14,"FAIL")+COUNTIF(D5:D14,"BREACH")>0,"BREACH",IF(COUNTIF(D5:D14,"REVIEW")>0,"REVIEW","PASS"))
B18: Primary decision outputs
B19: TPV | C19: ='Unit Economics'!C5
B20: Net revenue after processing | C20: ='Unit Economics'!C16
B21: LTV | C21: ='Unit Economics'!C18
B22: LTV / CAC | C22: ='Unit Economics'!C19
B23: Total risk-related loss | C23: ='Fraud & Risk'!C14
B24: Ending active users | C24: ='Network & Cohorts'!E16
B25: Base capital coverage | C25: ='Capital & Liquidity'!C14

Sheet RefreshLog
B2: Refresh Log
B4: Date | C4: Trigger | D4: What changed | E4: Reviewer notes | F4: Next check
